Workbook

Sheet Acadia
J1: Acadia County 2013 Statement of Activities
J2: Issued: December 31, 2013
M4: NET (EXPENSE) REVENUE AND CHANGE IN NET ASSETS
J5: PROGRAM REVENUES | M5: PRIMARY GOVERNMENT
A6: FUNCTIONS/PROGRAMS | I6: Expenses | J6: Charges for Services | K6: Operating Grants and Contributions | L6: Capital Grants and Contributions | M6: Total Governmental Activities | N6: Component Units
A7: Primary Government:
B8: Government Activities:
C9: General government | I9: -3475315 | J9: 74560 | L9: 23340 | M9: =SUM(I9:L9) -> -3377415
C10: Public safety | I10: -2252548 | J10: 25010 | K10: 761554 | L10: 488909 | M10: =SUM(I10:L10) -> -977075
C11: Public works | I11: -5747372 | K11: 653955 | L11: 805163 | M11: =SUM(I11:L11) -> -4288254
C12: Economic development and assistance | I12: -530123 | J12: 8189 | K12: 9284 | L12: 740924 | M12: =SUM(I12:L12) -> 228274
C13: Health and welfare | I13: -7195864 | J13: 7940 | K13: 156381 | L13: 57397 | M13: =SUM(I13:L13) -> -6974146
C14: Culture and recreation | I14: -279572 | J14: 79085 | M14: =SUM(I14:L14) -> -200487
C15: Interest on long-term debt | I15: -472119 | M15: =SUM(I15:L15) -> -472119
E17: Total Government Activities | I17: =SUM(I9:I15) -> -19952913 | J17: =SUM(J9:J15) -> 194784 | K17: =SUM(K9:K15) -> 1581174 | L17: =SUM(L9:L15) -> 2115733 | M17: =SUM(M9:M15) -> -16061222
A19: Component units:
B20: Acadia Parish District Criminal Court | I20: -769154 | J20: 209708 | K20: 61151 | L20: 0 | N20: =SUM(I20:M20) -> -498295
G22: General Revenues:
H23: Taxes:
I24: Property | M24: 5081628
I25: Sales | M25: 11701851
I26: Severance | M26: 1010850
I27: Fire insurance premiums | M27: 252516
I28: Occupational and insurance | M28: 503125
I29: Other | M29: 292470
H30: Grants and contributions not restricted to specific programs | M30: 438274
H31: Investment income gains (losses) | M31: -48655
H32: Loss on disposal of capital assets | M32: -33534
H33: Miscellaneous | M33: 446277 | N33: 426
H34: Transfers | M34: -525290 | N34: 505290
H36: Total General Revenues | M36: =SUM(M24:M34) -> 19119512 | N36: =SUM(N24:N34) -> 505716
H38: Change in Net Assets | M38: =SUM(M17,M36) -> 3058290 | N38: =N36+N20 -> 7421
H40: Net position, beginning, as previously stated | M40: 49162484 | N40: 31388
H42: Cumulative effect of change in accounting principle | M42: -110785
H44: Prior period adjustment | M44: 511435
E46: Net Assets- Beginning, restated | M46: 49563134 | N46: 31388
E48: Net Assets- End of Year | M48: =M46+M38 -> 52621424 | N48: =N46+N38 -> 38809

Sheet Sheet3
J1: Calhoun County 2010 Statement of Activities
J2: Issued: December 23,2011
M4: NET (EXPENSES) REVENUES AND CHANGES IN NET ASSETS
J5: PROGRAM REVENUES | M5: PRIMARY GOVERNMENT
A6: FUNCTIONS/PROGRAMS | I6: Expenses | J6: Charges for Services | K6: Operating Grants and Contributions | L6: Capital Grants and Contributions | M6: Governmental Activities | N6: Business-type Activities | O6: Total
A7: Primary Government:
B8: Government Activities:
C9: General government | I9: -16401981 | J9: 4333438.1 | K9: 2704791.7 | M9: =SUM(I9:L9) -> -9363751 | O9: =SUM(M9:N9) -> -9363751
C10: Public safety | I10: -16556688 | J10: 1328868.3 | K10: 3765237.8 | M10: =SUM(I10:L10) -> -11462582 | O10: =SUM(M10:N10) -> -11462582
C11: Highways and roads | I11: -12309705 | J11: 133348.8 | K11: 3792599.2 | L11: 55534.45 | M11: =SUM(I11:L11) -> -8328222.9 | O11: =SUM(M11:N11) -> -8328222.9
C12: Sanitation | I12: -22409528 | K12: 22196827 | M12: =SUM(I12:L12) -> -212701.23 | O12: =SUM(M12:N12) -> -212701.23
C13: Health | I13: -384287.66 | J13: 93696 | K13: 7591.44 | M13: =SUM(I13:L13) -> -283000.22 | O13: =SUM(M13:N13) -> -283000.22
C14: Welfare | I14: -115639.57 | M14: =SUM(I14:L14) -> -115639.57 | O14: =SUM(M14:N14) -> -115639.57
C15: Culture and recreation | I15: -635743.2 | M15: =SUM(I15:L15) -> -635743.2 | O15: =SUM(M15:N15) -> -635743.2
C16: Education | I16: -73000 | M16: =SUM(I16:L16) -> -73000 | O16: =SUM(M16:N16) -> -73000
C17: Interest on long-term debt | I17: -622092.61 | M17: =SUM(I17:L17) -> -622092.61 | O17: =SUM(M17:N17) -> -622092.61
E19: Total Government Activities | I19: =SUM(I9:I17) -> -69508666 | J19: =SUM(J9:J17) -> 5889351.2 | K19: =SUM(K9:K17) -> 32467047 | L19: =SUM(L9:L17) -> 55534.45 | M19: =SUM(M9:M17) -> -31096733 | N19: =SUM(N9:N17) -> 0 | O19: =SUM(O9:O17) -> -31096733
B21: Business-Type Activities:
C22: Solid Waste | I22: -1744754.2 | J22: 2172224.4 | N22: 427470.13 | O22: 427470.13
E24: Total Business-Type Activities | I24: =SUM(I22:I22) -> -1744754.2 | J24: =SUM(J22:J22) -> 2172224.4 | K24: =SUM(K22:K22) -> 0 | L24: =SUM(L22:L22) -> 0 | M24: =SUM(M22:M22) -> 0 | N24: =SUM(N22:N22) -> 427470.13 | O24: =SUM(O22:O22) -> 427470.13
C26: Total Governmental Activities | I26: =SUM(I19+I24) -> -71253420 | J26: =SUM(J19+J24) -> 8061575.5 | K26: =SUM(K19+K24) -> 32467047 | L26: =SUM(L19+L24) -> 55534.45 | M26: =SUM(M19+M24) -> -31096733 | N26: =SUM(N19+N24) -> 427470.13 | O26: =SUM(O19+O24) -> -30669263
G28: General Revenues:
H29: Taxes:
I30: Property taxes for general purposes | M30: 6433134.9 | O30: =SUM(M30:N30) -> 6433134.9
I31: Property taxes for specific purposes | M31: 4562102.7 | O31: =SUM(M31:N31) -> 4562102.7
I32: General Sales Tax | M32: 4286349.5 | O32: =SUM(M32:N32) -> 4286349.5
I33: Other County Sales and Use Taxes | M33: 1673649.7 | O33: =SUM(M33:N33) -> 1673649.7
H34: Grants/contributions not restricted to specific programs | M34: 850414.01 | O34: =SUM(M34:N34) -> 850414.01
H35: Investment Income | M35: 274846.25 | N35: 6565.7 | O35: =SUM(M35:N35) -> 281411.95
H36: Miscellaneous | M36: 3718934.9 | N36: 64169.68 | O36: =SUM(M36:N36) -> 3783104.5
H37: Transfers | M37: 432773 | N37: -432773 | O37: =SUM(M37,N37) -> 0
H38: Extraordinary Item (Note 17) | M38: -73267927 | O38: =SUM(M38,N38) -> -73267927
H40: Total General Revenues and Transfers | M40: =SUM(M30:M38) -> -51035722 | N40: =SUM(N30:N38) -> -362037.62 | O40: =SUM(O30:O38) -> -51397760
H42: Change in Net Assets | M42: =SUM(M40,M26) -> -82132455 | N42: =SUM(N40,N26) -> 65432.51 | O42: =SUM(M42:N42) -> -82067023
E44: Net Assets- Beginning of Year | M44: 1.5180939e+08 | N44: 2795005.4 | O44: =SUM(M44:N44) -> 1.546044e+08
E46: Net Assets- End of Year | M46: =SUM(M42,M44) -> 69676935 | N46: =SUM(N42,N44) -> 2860437.9 | O46: =SUM(O42,O44) -> 72537373

Sheet Allen
J1: Allen County 2013 Statement of Activities
J2: Issued: December 31, 2013
M4: NET (EXPENSE) REVENUE AND CHANGE IN NET POSITIONS
J5: PROGRAM REVENUES | M5: PRIMARY GOVERNMENT
A6: FUNCTIONS/PROGRAMS | I6: Expenses | J6: Fees, Fines, and Charges for Services | K6: Operating Grants and Contributions | L6: Capital Grants and Contributions | M6: Total Governmental Activities
A7: Primary Government:
B8: Government Activities:
C9: General government | I9: -1828189 | J9: 201510 | K9: 13730 | M9: =SUM(I9:L9) -> -1612949
C10: Public safety | I10: -613949 | K10: 25419 | L10: 27776 | M10: =SUM(I10:L10) -> -560754
C11: Public works | I11: -6291960 | K11: 29509 | M11: =SUM(I11:L11) -> -6262451
C12: Economic development | I12: -322491 | J12: 92074 | K12: 96087 | L12: 54290 | M12: =SUM(I12:L12) -> -80040
C13: Other governments | I13: -516630 | K13: 495024 | M13: =SUM(I13:L13) -> -21606
C14: Interest on long-term debt | I14: -5262 | M14: =SUM(I14:L14) -> -5262
E16: Total Government Activities | I16: =SUM(I9:I14) -> -9578481 | J16: =SUM(J9:J14) -> 293584 | K16: =SUM(K9:K14) -> 659769 | L16: =SUM(L9:L14) -> 82066 | M16: =SUM(M9:M14) -> -8543062
G19: General Revenues:
H20: Taxes:
I21: Ad valorem | M21: 2978127
I22: Sales and use | M22: 1915340
I23: Severance | M23: 1165147
I24: Other | M24: 1652
H25: State revenue sharing | M25: 177544
H26: All other revenues | M26: 1340652
H27: Investment earnings | M27: 15570
H28: Special items:
I29: Gain on disposal of assets | M29: 41245
I30: Loss on disposal of assets | M30: -978399
H32: Total General Revenues | M32: =SUM(M21:M30) -> 6656878
H34: Change in Net Assets | M34: =SUM(M16,M32) -> -1886184
E36: Net Assets- Beginning of Year | M36: 32770564
E38: Net Assets- End of Year | M38: =SUM(M34,M36) -> 30884380

Sheet Ascension
J1: Ascension County 2013 Statement of Activities
J2: Issued: December 31, 2013
M4: NET (EXPENSE) REVENUE AND CHANGE IN NET ASSETS
J5: PROGRAM REVENUES | M5: PRIMARY GOVERNMENT | P5: COMPONENT UNITS
A6: FUNCTIONS/PROGRAMS | I6: Expenses | J6: Charges for Services | K6: Operating Grants and Contributions | L6: Capital Grants and Contributions | M6: Governmental Activities | N6: Business-type Activities | O6: Total | P6: Governmental Activities | Q6: Business-type Activities
A7: Primary Government:
B8: Government Activities:
C9: General government | I9: -14935768 | J9: 3911600 | K9: 256912 | L9: 633123 | M9: =SUM(I9:L9) -> -10134133 | O9: =SUM(M9:N9) -> -10134133
C10: Public safety | I10: -9548259 | J10: 552709 | K10: 1041074 | M10: =SUM(I10:L10) -> -7954476 | O10: =SUM(M10:N10) -> -7954476
C11: Public works | I11: -14605186 | K11: 1566915 | M11: =SUM(I11:L11) -> -13038271 | O11: =SUM(M11:N11) -> -13038271
C12: Health and welfare | I12: -5709382 | J12: 59619 | K12: 1684346 | M12: =SUM(I12:L12) -> -3965417 | O12: =SUM(M12:N12) -> -3965417
C13: Culture and recreation | I13: -7695027 | J13: 533345 | K13: 435102 | L13: 443112 | M13: =SUM(I13:L13) -> -6283468 | O13: =SUM(M13:N13) -> -6283468
C14: Transportation and development | I14: -10557421 | L14: 5569290 | M14: =SUM(I14:L14) -> -4988131 | O14: =SUM(M14:N14) -> -4988131
C15: Interest on long-term debt | I15: -3644962 | M15: =SUM(I15:L15) -> -3644962 | O15: =SUM(M15:N15) -> -3644962
E17: Total Government Activities | I17: =SUM(I9:I15) -> -66696005 | J17: =SUM(J9:J15) -> 5057273 | K17: =SUM(K9:K15) -> 4984349 | L17: =SUM(L9:L15) -> 6645525 | M17: =SUM(M9:M15) -> -50008858 | O17: =SUM(O9:O15) -> -50008858 | P17: =SUM(P9:P15) -> 0 | Q17: =SUM(Q9:Q15) -> 0
B19: Business-type Activities:
C20: Waste disposal facilities | I20: -1694248 | J20: 154083 | K20: 737 | L20: 881 | N20: =SUM(I20:L20) -> -1538547 | O20: =N20 -> -1538547
C21: Waterworks services | I21: -250905 | J21: 217437 | N21: =SUM(I21:L21) -> -33468 | O21: =N21 -> -33468
C22: Lamar Dixon Expo center | I22: -2261537 | J22: 1669187 | K22: 419063 | L22: 91592 | N22: =SUM(I22:L22) -> -81695 | O22: =N22 -> -81695
E24: Total business-type Activities | I24: =SUM(I20:I22) -> -4206690 | J24: =SUM(J20:J22) -> 2040707 | K24: =SUM(K20:K22) -> 419800 | L24: =SUM(L20:L22) -> 92473 | M24: =SUM(M20:M22) -> 0 | N24: =SUM(N20:N22) -> -1653710 | O24: =SUM(O20:O22) -> -1653710
E26: Total primary government | I26: =I24+I17 -> -70902695 | J26: =J24+J17 -> 7097980 | K26: =K24+K17 -> 5404149 | L26: =L24+L17 -> 6737998 | M26: =M24+M17 -> -50008858 | N26: =N24+N17 -> -1653710 | O26: =O24+O17 -> -51662568 | P26: =P24+P17 -> 0 | Q26: =Q24+Q17 -> 0
A28: Component units:
B29: Governmental activities | I29: -50001134 | J29: 17673716 | K29: 3785208 | P29: =SUM(I29:L29) -> -28542210
B30: Business-type activities | I30: -7713127 | J30: 6229842 | Q30: =SUM(I30:L30) -> -1483285
E32: Total component units | I32: =SUM(I29:I30) -> -57714261 | J32: =SUM(J29:J30) -> 23903558 | K32: =SUM(K29:K30) -> 3785208 | L32: =SUM(L29:L30) -> 0 | M32: =SUM(M29:M30) -> 0 | N32: =SUM(N29:N30) -> 0 | O32: =SUM(O29:O30) -> 0 | P32: =SUM(P29:P30) -> -28542210 | Q32: =SUM(Q29:Q30) -> -1483285
G34: General Revenues:
H35: Taxes:
I36: Ad valorem | M36: 26337905 | O36: =SUM(M36:N36) -> 26337905 | P36: 17194323 | Q36: 189710
I37: Sales | M37: 47074455 | O37: =SUM(M37:N37) -> 47074455 | P37: 10213682 | Q37: 1273033
I38: Franchise and other | M38: 1831140 | N38: 417113 | O38: =SUM(M38:N38) -> 2248253 | P38: 387957
H39: Grants and contributions not restricted to specific programs | M39: 673943 | O39: =SUM(M39:N39) -> 673943 | P39: 2183790 | Q39: 905000
H40: Investment earnings (loss) | M40: 436804 | N40: 36169 | O40: =SUM(M40:N40) -> 472973 | P40: 8589 | Q40: -667680
H41: Gain on sale of capital assets | M41: 398588 | N41: 4575 | O41: =SUM(M41:N41) -> 403163
G42: Transfers | M42: -1191000 | N42: 1191000 | O42: =SUM(M42:N42) -> 0
H44: Total General Revenues | M44: =SUM(M36:M42) -> 75561835 | N44: =SUM(N36:N42) -> 1648857 | O44: =SUM(O36:O42) -> 77210692 | P44: =SUM(P36:P42) -> 29988341 | Q44: =SUM(Q36:Q42) -> 1700063
H46: Change in Net Assets | M46: =M44+M26 -> 25552977 | N46: =N44+N26 -> -4853 | O46: =O44+O26 -> 25548124 | P46: =P44+P32 -> 1446131 | Q46: =Q44+Q32 -> 216778
E48: Net Assets- Beginning of Year | M48: 259286351 | N48: 18437522 | O48: =SUM(M48:N48) -> 277723873 | P48: 41726517 | Q48: 18505420
E50: Net Assets- End of Year | M50: =SUM(M46,M48) -> 284839328 | N50: =N48+N46 -> 18432669 | O50: =O48+O46 -> 303271997 | P50: =P48+P46 -> 43172648 | Q50: =Q48+Q46 -> 18722198

Sheet Assumption
J1: Assumption County 2013 Statement of Activities
J2: Issued: December 31, 2013
L4: NET (EXPENSE) REVENUE AND CHANGES IN NET ASSETS
J5: PROGRAM REVENUES | L5: PRIMARY GOVERNMENT
A6: FUNCTIONS/PROGRAMS | I6: Expenses | J6: Charges for Services | K6: Operating Grants and Contributions | L6: Governmental Unit | M6: Component Units
A7: Primary Government:
B8: Government Activities:
C9: General government
D10: Legislative | I10: -500036 | L10: =SUM(I10:K10) -> -500036
D11: Judicial | I11: -973086 | J11: 80459 | L11: =SUM(I11:K11) -> -892627
D12: Executive | I12: -41555 | L12: =SUM(I12:K12) -> -41555
D13: Elections | I13: -47260 | L13: =SUM(I13:K13) -> -47260
D14: Financial and administrative | I14: -341977 | L14: =SUM(I14:K14) -> -341977
D15: Other general administration | I15: -149648 | L15: =SUM(I15:K15) -> -149648
C16: Public safety | I16: -3129680 | J16: 713313 | K16: 546282 | L16: =SUM(I16:K16) -> -1870085
C17: Public works | I17: -5670444 | J17: 2211875 | K17: 252864 | L17: =SUM(I17:K17) -> -3205705
C18: Health and welfare | I18: -2903954 | J18: 197975 | K18: 3656931 | L18: =SUM(I18:K18) -> 950952
C19: Culture and recreation | I19: -1221329 | J19: 11198 | K19: 7950 | L19: =SUM(I19:K19) -> -1202181
C20: Economic development | I20: -179461 | J20: 2739 | L20: =SUM(I20:K20) -> -176722
C21: Debt service | I21: -461 | L21: =SUM(I21:K21) -> -461
E23: Total Government Activities | I23: =SUM(I10:I21) -> -15158891 | J23: =SUM(J10:J21) -> 3217559 | K23: =SUM(K10:K21) -> 4464027 | L23: =SUM(L10:L21) -> -7477305
A25: Component units:
B26: Waterworks District No. 1 | I26: -3508343 | J26: 4185201 | M26: =SUM(I26:L26) -> 676858
B27: Assumption parish assessor | I27: -827738 | M27: =SUM(I27:L27) -> -827738
B28: Assumption parish clerk of court | I28: -871957 | J28: 790096 | M28: =SUM(I28:L28) -> -81861
E30: Total component units | I30: =SUM(I26:I28) -> -5208038 | J30: =SUM(J26:J28) -> 4975297 | K30: =SUM(K26:K28) -> 0 | L30: =SUM(L26:L28) -> 0 | M30: =SUM(M26:M28) -> -232741
G32: General Revenues:
G33: Local sources
H34: Taxes:
I35: Ad valorem | L35: 3578953 | M35: 835517
I36: Sales and use taxes | L36: 4938431
I37: Other taxes | L37: 962612
H38: Other revenue | L38: 876717 | M38: 128219
G39: State sources
H40: Unrestricted revenue | L40: 809136 | M40: 36109
H42: Total General Revenues | L42: =SUM(L35:L40) -> 11165849 | M42: =SUM(M35:M40) -> 999845
H44: Change in Net Assets | L44: =L42+L23 -> 3688544 | M44: =M42+M30 -> 767104
E46: Net Assets- Beginning of Year | L46: 60909408 | M46: 17530322
E48: Net Assets- End of Year | L48: =SUM(L44,L46) -> 64597952 | M48: =M46+M44 -> 18297426

Sheet Avoyelles
J1: Avoyelles County 2013 Statement of Activities
J2: Issued: December 31, 2013
M4: NET (EXPENSE) REVENUE AND CHANGE IN NET ASSETS
J5: PROGRAM REVENUES | M5: PRIMARY GOVERNMENT
A6: FUNCTIONS/PROGRAMS | I6: Expenses | J6: Charges for Services | K6: Operating Grants and Contributions | L6: Capital Grants and Contributions | M6: Governmental Activities | N6: Component Units
A7: Primary Government:
B8: Government Activities:
C9: General government | I9: -1799591 | J9: 97332 | M9: =SUM(I9:L9) -> -1702259
C10: Public safety | I10: -851197 | J10: 421565 | K10: 17453 | M10: =SUM(I10:L10) -> -412179
C11: Public works | I11: -4483547 | J11: 1498 | K11: 551866 | L11: 1399959 | M11: =SUM(I11:L11) -> -2530224
C12: Health and welfare | I12: -923688 | K12: 651146 | M12: =SUM(I12:L12) -> -272542
C13: Culture and recreation | I13: -649782 | M13: =SUM(I13:L13) -> -649782
C14: Economic development | I14: -99146 | M14: =SUM(I14:L14) -> -99146
E16: Total Government Activities | I16: =SUM(I9:I14) -> -8806951 | J16: =SUM(J9:J14) -> 520395 | K16: =SUM(K9:K14) -> 1220465 | L16: =SUM(L9:L14) -> 1399959 | M16: =SUM(M9:M14) -> -5666132
A18: Component units:
B19: Governmental activities | I19: -394480 | J19: 158142 | K19: 87500 | N19: =SUM(I19:M19) -> -148838
G21: General Revenues:
H22: Taxes:
I23: Property taxes, levied for general purposes | M23: 2033687
I24: Sales and use taxes, levied for general purposes | M24: 4481433 | N24: 113357
H25: Grants and contributions not restricted to specific programs:
I26: State revenue sharing | M26: 173216
I27: Parish equalization | M27: 372408
I28: State grants | M28: 591608
I29: Casino revenue | M29: 112335
H30: Interest and investment earnings | M30: 23802 | N30: 669
H31: Miscellaneous | M31: 128711 | N31: 14194
H33: Total General Revenues | M33: =SUM(M23:M31) -> 7917200 | N33: =SUM(N23:N31) -> 128220
H35: Change in Net Assets | M35: =SUM(M16,M33) -> 2251068 | N35: =N33+N19 -> -20618
E37: Net Assets- Beginning of Year | M37: 12774390 | N37: 273206
E39: Net Assets- End of Year | M39: =SUM(M35,M37) -> 15025458 | N39: =N37+N35 -> 252588

Sheet Beauregard
J1: Beauregard County 2013 Statement of Activities
J2: Issued: December 31, 2013
M4: NET (EXPENSE) REVENUE AND CHANGES IN NET ASSETS
J5: PROGRAM REVENUES | M5: PRIMARY GOVERNMENT
A6: FUNCTIONS/PROGRAMS | I6: Expenses | J6: Charges for Services | K6: Operating Grants and Contributions | L6: Capital Grants and Contributions | M6: Governmental Unit
A7: Primary Government:
B8: Government Activities:
C9: General government
D10: Legislative | I10: -233073 | M10: =SUM(I10:L10) -> -233073
D11: Judicial | I11: -1228208 | J11: 894833 | K11: 9247 | M11: =SUM(I11:L11) -> -324128
D12: Elections | I12: -73428 | M12: =SUM(I12:L12) -> -73428
D13: Financial and administrative | I13: -883767 | J13: 203327 | M13: =SUM(I13:L13) -> -680440
D14: Other general government activities | I14: -641778 | J14: 171670 | K14: 52950 | M14: =SUM(I14:L14) -> -417158
C15: Public safety | I15: -1649102 | K15: 53092 | M15: =SUM(I15:L15) -> -1596010
C16: Public works | I16: -7046314 | J16: 18000 | K16: 662708 | L16: 359778 | M16: =SUM(I16:L16) -> -6005828
C17: Health and welfare | I17: -531255 | M17: =SUM(I17:L17) -> -531255
C18: Culture and recreation | I18: -1073277 | K18: 75691 | L18: 35000 | M18: =SUM(I18:L18) -> -962586
C19: Sanitation | I19: -1461093 | J19: 66138 | M19: =SUM(I19:L19) -> -1394955
C20: Other activities | I20: -78307 | M20: =SUM(I20:L20) -> -78307
C21: Interest on long-term debt | I21: -106427 | M21: =SUM(I21:L21) -> -106427
E23: Total Government Activities | I23: =SUM(I10:I21) -> -15006029 | J23: =SUM(J10:J21) -> 1353968 | K23: =SUM(K10:K21) -> 853688 | L23: =SUM(L10:L21) -> 394778 | M23: =SUM(M10:M21) -> -12403595
G25: General Revenues:
H26: Taxes:
I27: Ad valorem taxes | M27: 5473137
I28: Severance taxes | M28: 1596193
I29: Sales taxes | M29: 6529270
I30: State revenue sharing, unrestricted | M30: 129957
I31: Other taxes | M31: 178211
H32: Interest and investment earnings | M32: 30993
H33: Special items:
I34: Miscellaneous | M34: 280384
I35: Gain on disposal of assets | M35: 292128
H37: Total General Revenues | M37: =SUM(M27:M35) -> 14510273
H39: Change in Net Assets | M39: =M37+M23 -> 2106678
E41: Net Assets- Beginning of Year | M41: 45699042
E43: Net Assets- End of Year | M43: =SUM(M39,M41) -> 47805720

Sheet Bienville
J1: Bienville County 2013 Statement of Activities
J2: Issued: December 31, 2013
M4: NET (EXPENSE) REVENUE AND CHANGE IN NET ASSETS
J5: PROGRAM REVENUES
A6: FUNCTIONS/PROGRAMS | I6: Expenses | J6: Charges for Services | K6: Operating Grants and Contributions | L6: Capital Grants and Contributions
A7: Primary Government:
B8: Government Activities:
C9: General government | I9: -2274040 | J9: 21531 | K9: 117418 | M9: =SUM(I9:L9) -> -2135091
C10: Public safety | I10: -589526 | M10: =SUM(I10:L10) -> -589526
C11: Public works | I11: -6911006 | K11: 315519 | L11: 933040 | M11: =SUM(I11:L11) -> -5662447
C12: Health and welfare | I12: -366113 | K12: 389793 | M12: =SUM(I12:L12) -> 23680
C13: Conservation of natural resources | I13: -37414 | M13: =SUM(I13:L13) -> -37414
C14: Economic development and assistance | I14: -380167 | K14: 80704 | M14: =SUM(I14:L14) -> -299463
C15: Debt service | I15: -409519 | M15: =SUM(I15:L15) -> -409519
E17: Total Government Activities | I17: =SUM(I9:I15) -> -10967785 | J17: =SUM(J9:J15) -> 21531 | K17: =SUM(K9:K15) -> 903434 | L17: =SUM(L9:L15) -> 933040 | M17: =SUM(M9:M15) -> -9109780
G19: General Revenues:
H20: Taxes:
I21: Property taxes levied for general purposes | M21: 1645255
I22: Property taxes levied for public works | M22: 1942336
I23: Property taxes levied for debt service | M23: 1142496
I24: Sales and use taxes levied for public works | M24: 2259144
H25: Other taxes, penalties, and interest | M25: 32045
H26: Grants and contributions not restricted to specific programs | M26: 1530570
H27: Licenses and permits | M27: 52840
H28: Unrestricted investment earnings | M28: 262524
H29: Special item - Gain (loss) on disposal of assets | M29: 22700
H31: Total General Revenues | M31: =SUM(M21:M29) -> 8889910
H33: Change in Net Assets | M33: =SUM(M17,M31) -> -219870
E35: Net Assets- Beginning of Year | M35: 32795084
E37: Net Assets- End of Year | M37: =SUM(M33,M35) -> 32575214

Sheet Bossier
J1: Bossier County 2013 Statement of Activities
J2: Issued: December 31, 2013
M4: NET (EXPENSE) REVENUE AND CHANGES IN NET ASSETS
J5: PROGRAM REVENUES | M5: PRIMARY GOVERNMENT
A6: FUNCTIONS/PROGRAMS | I6: Expenses | J6: Charges for Services | K6: Operating Grants and Contributions | L6: Capital Grants and Contributions | M6: Governmental Activities | N6: Business-type Activities | O6: Total
A7: Primary Government:
B8: Government Activities:
C9: General government:
D10: Zoning and planning | I10: -6106 | M10: =SUM(I10:L10) -> -6106 | O10: =SUM(M10:N10) -> -6106
D11: Legislative | I11: -349570 | M11: =SUM(I11:L11) -> -349570 | O11: =SUM(M11:N11) -> -349570
D12: Judicial | I12: -2792610 | J12: 1141917 | M12: =SUM(I12:L12) -> -1650693 | O12: =SUM(M12:N12) -> -1650693
D13: Elections | I13: -126899 | M13: =SUM(I13:L13) -> -126899 | O13: =SUM(M13:N13) -> -126899
D14: Finance and administrative | I14: -1726144 | J14: 20700 | M14: =SUM(I14:L14) -> -1705444 | O14: =SUM(M14:N14) -> -1705444
D15: Other | I15: -3196970 | J15: 299550 | K15: 359 | M15: =SUM(I15:L15) -> -2897061 | O15: =SUM(M15:N15) -> -2897061
C16: Public safety | I16: -5059208 | J16: 242010 | M16: =SUM(I16:L16) -> -4817198 | O16: =SUM(M16:N16) -> -4817198
C17: Public works | I17: -16834285 | J17: 251723 | K17: 146235 | L17: 7904940 | M17: =SUM(I17:L17) -> -8531387 | O17: =SUM(M17:N17) -> -8531387
C18: Public utilities | I18: -149734 | L18: 69792 | M18: =SUM(I18:L18) -> -79942 | O18: =SUM(M18:N18) -> -79942
C19: Health and welfare | I19: -3852114 | K19: 3679953 | M19: =SUM(I19:L19) -> -172161 | O19: =SUM(M19:N19) -> -172161
C20: Culture and recreation | I20: -5397105 | J20: 71519 | M20: =SUM(I20:L20) -> -5325586 | O20: =SUM(M20:N20) -> -5325586
C21: Economic development | I21: -2202272 | M21: =SUM(I21:L21) -> -2202272 | O21: =SUM(M21:N21) -> -2202272
C22: Interest on long-term debt | I22: -2194004 | M22: =SUM(I22:L22) -> -2194004 | O22: =SUM(M22:N22) -> -2194004
E24: Total Government Activities | I24: =SUM(I10:I22) -> -43887021 | J24: =SUM(J10:J22) -> 2027419 | K24: =SUM(K10:K22) -> 3826547 | L24: =SUM(L10:L22) -> 7974732 | M24: =SUM(M10:M22) -> -30058323 | O24: =SUM(O10:O22) -> -30058323
B26: Business-type Activities:
C27: Sewer and water | I27: -815573 | J27: 1758109 | N27: =SUM(I27:M27) -> 942536 | O27: =N27 -> 942536
E29: Total business-type Activities | I29: =SUM(I27:I27) -> -815573 | J29: =SUM(J27:J27) -> 1758109 | K29: =SUM(K27:K27) -> 0 | L29: =SUM(L27:L27) -> 0 | M29: =SUM(M27:M27) -> 0 | N29: =SUM(N27:N27) -> 942536 | O29: =SUM(O27:O27) -> 942536
E31: Total government | I31: =I29+I24 -> -44702594 | J31: =J29+J24 -> 3785528 | K31: =K29+K24 -> 3826547 | L31: =L29+L24 -> 7974732 | M31: =M29+M24 -> -30058323 | N31: =N29+N24 -> 942536 | O31: =O29+O24 -> -29115787
G33: General Revenues:
H34: Taxes:
I35: Ad valorem | M35: 14172204 | O35: =SUM(M35:N35) -> 14172204
I36: Sales taxes | M36: 15605483 | O36: =SUM(M36:N36) -> 15605483
I37: Gaming tax revenues | M37: 4207854 | O37: =SUM(M37:N37) -> 4207854
I38: Franchise taxes | M38: 406106 | O38: =SUM(M38:N38) -> 406106
I39: Other taxes | M39: 1164826 | O39: =SUM(M39:N39) -> 1164826
H40: Investment earnings | M40: 39676 | N40: 855 | O40: =SUM(M40:N40) -> 40531
H41: State revenue sharing | M41: 650991 | O41: =SUM(M41:N41) -> 650991
H42: Miscellaneous | M42: 2562419 | N42: 2879 | O42: =SUM(M42:N42) -> 2565298
H43: Transfers | M43: 161824 | N43: -161824 | O43: =SUM(M43:N43) -> 0
H45: Total General Revenues | M45: 38691383 | N45: =SUM(N35:N43) -> -158090 | O45: =SUM(O35:O43) -> 38813293
H47: Change in Net Assets | M47: =M45+M31 -> 8633060 | N47: =N45+N31 -> 784446 | O47: =SUM(M47:N47) -> 9417506
E49: Net Assets- Beginning of Year | M49: 273279268 | N49: 1951163 | O49: =SUM(M49:N49) -> 275230431
...

Sheet Caddo
J1: Caddo County 2013 Statement of Activities
J2: Issued: December 31, 2013
M4: NET (EXPENSE) REVENUE AND CHANGES IN NET ASSETS
J5: PROGRAM REVENUES
A6: FUNCTIONS/PROGRAMS | I6: Expenses | J6: Charges for Services | K6: Operating Grants and Contributions | L6: Capital Grants and Contributions | M6: Primary Government | N6: Component Units
A7: Primary Government:
B8: Government Activities:
C9: General government | I9: -16327879 | J9: 2657856 | K9: 109667 | L9: 28220 | M9: =SUM(I9:L9) -> -13532136
C10: Criminal justice | I10: -21190633 | J10: 31019 | K10: 1335382 | M10: =SUM(I10:L10) -> -19824232
C11: Health and welfare | I11: -14409692 | J11: 162137 | K11: 11280586 | M11: =SUM(I11:L11) -> -2966969
C12: Highways, streets, and drainage | I12: -25884621 | J12: 572258 | K12: 2180422 | L12: 835032 | M12: =SUM(I12:L12) -> -22296909
C13: Building facilities | I13: -6222969 | K13: 114800 | M13: =SUM(I13:K13) -> -6108169
C14: Sanitation | I14: -2290081 | M14: =SUM(I14:K14) -> -2290081
C15: Culture and recreation | I15: -15171125 | J15: 102387 | K15: 425638 | M15: =SUM(I15:K15) -> -14643100
C16: Economic development | I16: -4153012 | K16: 73955 | M16: =SUM(I16:K16) -> -4079057
C17: Interest and fees on long-term debt | I17: -1515768 | M17: =SUM(I17:K17) -> -1515768
E19: Total Government Activities | I19: =SUM(I9:I17) -> -107165780 | J19: =SUM(J9:J17) -> 3525657 | K19: =SUM(K9:K17) -> 15520450 | L19: =SUM(L9:L17) -> 863252 | M19: =SUM(M9:M17) -> -87256421
A21: Component units:
B22: Judicial services | I22: -8462144 | J22: 1539156 | K22: 6584270 | N22: =SUM(I22:M22) -> -338718
B23: Economic development | I23: -6975 | L23: 7500000 | N23: =SUM(I23:M23) -> 7493025
B24: Public safety | I24: -38053859 | J24: 12294218 | N24: =SUM(I24:M24) -> -25759641
B25: Fire protection services | I25: -10980607 | J25: 3013946 | K25: 261553 | L25: 212526 | N25: =SUM(I25:M25) -> -7492582
B26: Sewerage services | I26: -1207390 | J26: 947869 | N26: =SUM(I26:M26) -> -259521
B27: Water services | I27: -1901688 | J27: 2000218 | N27: =SUM(I27:M27) -> 98530
B28: Hospital services | I28: -16701576 | J28: 14603792 | K28: 1377931 | L28: 296277 | N28: =SUM(I28:M28) -> -423576
E30: Total component units | I30: =SUM(I22:I28) -> -77314239 | J30: =SUM(J22:J28) -> 34399199 | K30: =SUM(K22:K28) -> 8223754 | L30: =SUM(L22:L28) -> 8008803 | M30: =SUM(M22:M28) -> 0 | N30: =SUM(N22:N28) -> -26682483
G32: General Revenues:
H33: Taxes:
I34: Property taxes levied for general purposes | M34: 55858768 | N34: 7938894
I35: Property taxes levied for debt service | M35: 2883688
I36: Sales taxes | M36: 9544058 | N36: 15696184
I37: Franchise taxes | M37: 213429
I38: Telephone tariff | N38: 3873072
H39: State revenue sharing and supplemental pay | N39: 522585
H40: Gaming | M40: 1924061
H41: Grants and contributions not restricted to specific programs | M41: 1310860
H42: Oil and gas leases | M42: 1187767
H43: Investment earnings | M43: 175458 | N43: 137926
H44: Inmate work release revenue | N44: 1731328
H45: Fire insurance rebate | N45: 214324
...

Sheet Calcasieu
J1: Calcasieu County 2013 Statement of Activities
J2: Issued: December 31, 2013
M4: NET (EXPENSE) REVENUE AND CHANGE IN NET ASSETS
J5: PROGRAM REVENUES | M5: PRIMARY GOVERNMENT
A6: FUNCTIONS/PROGRAMS | I6: Expenses | J6: Charges for Services | K6: Operating Grants and Contributions | L6: Capital Grants and Contributions | M6: Governmental Activities | N6: Business-type Activities | O6: Total | P6: Component Units
A7: Primary Government:
B8: Government Activities:
C9: General government | I9: -26708294 | J9: 10909651 | K9: 1697421 | L9: 893024 | M9: =SUM(I9:L9) -> -13208198 | O9: =SUM(M9:N9) -> -13208198
C10: Public safety | I10: -14697518 | J10: 1164201 | K10: 2515578 | M10: =SUM(I10:L10) -> -11017739 | O10: =SUM(M10:N10) -> -11017739
C11: Public works | I11: -36610516 | J11: 218293 | K11: 4188992 | L11: 2805046 | M11: =SUM(I11:L11) -> -29398185 | O11: =SUM(M11:N11) -> -29398185
C12: Sanitation | I12: -6166860 | J12: 240 | M12: =SUM(I12:L12) -> -6166620 | O12: =SUM(M12:N12) -> -6166620
C13: Health and welfare | I13: -14842859 | J13: 171434 | K13: 7723418 | L13: 37210 | M13: =SUM(I13:L13) -> -6910797 | O13: =SUM(M13:N13) -> -6910797
C14: Culture and recreation | I14: -13726013 | J14: 511155 | K14: 32730 | L14: 2176242 | M14: =SUM(I14:L14) -> -11005886 | O14: =SUM(M14:N14) -> -11005886
C15: Economic development | I15: -16911643 | J15: 794458 | K15: 87505 | L15: 501988 | M15: =SUM(I15:L15) -> -15527692 | O15: =SUM(M15:N15) -> -15527692
E17: Total Government Activities | I17: =SUM(I9:I15) -> -129663703 | J17: =SUM(J9:J15) -> 13769432 | K17: =SUM(K9:K15) -> 16245644 | L17: =SUM(L9:L15) -> 6413510 | M17: =SUM(M9:M15) -> -93235117 | O17: =SUM(O9:O15) -> -93235117 | P17: =SUM(P9:P15) -> 0
B19: Business-type Activities:
C20: Water | I20: -1173252 | J20: 972811 | N20: =SUM(I20:L20) -> -200441 | O20: =SUM(M20:N20) -> -200441
C21: Sewer | I21: -984594 | J21: 303496 | N21: =SUM(I21:L21) -> -681098 | O21: =SUM(M21:N21) -> -681098
E23: Total Business-type Activities | I23: =SUM(I20:I21) -> -2157846 | J23: =SUM(J20:J21) -> 1276307 | K23: =SUM(K20:K21) -> 0 | L23: =SUM(L20:L21) -> 0 | M23: =SUM(M20:M21) -> 0 | N23: =SUM(N20:N21) -> -881539 | O23: =SUM(O20:O21) -> -881539 | P23: =SUM(P15:P21) -> 0
E25: Total primary government | I25: =I23+I17 -> -131821549 | J25: =J23+J17 -> 15045739 | K25: =SUM(K17+K23) -> 16245644 | L25: =SUM(L17+L23) -> 6413510 | M25: =M23+M17 -> -93235117 | N25: =N23+N17 -> -881539 | O25: =O23+O17 -> -94116656 | P25: =SUM(P16:P23) -> 0
A27: Component units:
B28: Calcasieu Parish public trust authority | I28: -677888 | J28: 524104 | P28: =SUM(I28:M28) -> -153784
B29: West Calcasieu Cameron Hospital | I29: -70501459 | J29: 62399171 | K29: 23240 | P29: =SUM(I29:L29) -> -8079048
B30: Sulfur parks and recreation | I30: -5389452 | J30: 2059927 | P30: =SUM(I30:L30) -> -3329525
B31: Gravity drainage District 4 of Ward 3 | I31: -2568122 | L31: 168820 | P31: =SUM(I31:L31) -> -2399302
B32: Airport authority District No. 1 | I32: -3844490 | J32: 1660328 | K32: 381325 | L32: 3288118 | P32: =SUM(I32:L32) -> 1485281
B33: Other component units | I33: -40655166 | J33: 15439370 | K33: 7198453 | L33: 3190023 | P33: =SUM(I33:L33) -> -14827320
E35: Total component units | I35: =SUM(I28:I33) -> -123636577 | J35: =SUM(J28:J33) -> 82082900 | K35: =SUM(K28:K33) -> 7603018 | L35: =SUM(L28:L33) -> 6646961 | M35: =SUM(M28:M33) -> 0 | N35: =SUM(N28:N33) -> 0 | O35: =SUM(O28:O33) -> 0 | P35: =SUM(P28:P33) -> -27303698
G37: General Revenues:
H38: Taxes:
I39: Property | M39: 47011753 | N39: 339531 | O39: =SUM(M39:N39) -> 47351284 | P39: 41602575
I40: Sales | M40: 38649679 | O40: =SUM(M40:N40) -> 38649679
I41: Franchise | M41: 957265 | O41: =SUM(M41:N41) -> 957265
H42: Gaming revenues | M42: 11424986 | O42: =SUM(M42:N42) -> 11424986
H43: Grants and contributions not restricted to specific programs | M43: 2654935 | O43: =SUM(M43:N43) -> 2654935 | P43: 726870
H44: Investment earnings | M44: 49857 | N44: 8615 | O44: =SUM(M44:N44) -> 58472 | P44: 132952
H45: Gain on sale of capital assets | M45: 229681 | O45: =SUM(M45:N45) -> 229681 | P45: 44048
H46: Miscellaneous | M46: 82419 | N46: 22002 | O46: =SUM(M46:N46) -> 104421 | P46: 4126937
H47: Transfers | M47: -263947 | N47: 263947 | O47: =SUM(M47:N47) -> 0
H49: Total General Revenues | M49: =SUM(M39:M47) -> 100796628 | N49: =SUM(N39:N47) -> 634095 | O49: =SUM(O39:O47) -> 101430723 | P49: =SUM(P39:P46) -> 46633382
...

Sheet Caldwell
J1: Caldwell County 2013 Statement of Activities
J2: Issued: December 31, 2013
J5: PROGRAM REVENUES
A6: FUNCTIONS/PROGRAMS | I6: Expenses | J6: Charges for Services | K6: Operating Grants and Contributions | L6: Capital Grants and Contributions | M6: NET (EXPENSE) REVENUE AND CHANGES IN NET ASSETS
A7: Primary Government:
B8: Government Activities:
C9: General government | I9: -1723572 | J9: 173733 | K9: 264518 | M9: =SUM(I9:L9) -> -1285321
C10: Public safety | I10: -543904 | J10: 68978 | K10: 222356 | L10: 46980 | M10: =SUM(I10:L10) -> -205590
C11: Public works | I11: -2752221 | K11: 1524970 | L11: 578014 | M11: =SUM(I11:L11) -> -649237
C12: Health and welfare | I12: -195994 | M12: =SUM(I12:L12) -> -195994
C13: Culture and recreation | I13: -207512 | J13: 16469 | K13: 15399 | L13: 20670 | M13: =SUM(I13:L13) -> -154974
C14: Economic development and assistance | I14: -238412 | M14: =SUM(I14:L14) -> -238412
C15: Transportation | I15: -27853 | J15: 3841 | K15: 69176 | M15: =SUM(I15:L15) -> 45164
E17: Total Government Activities | I17: =SUM(I9:I15) -> -5689468 | J17: =SUM(J9:J15) -> 263021 | K17: =SUM(K9:K15) -> 2096419 | L17: =SUM(L9:L15) -> 645664 | M17: =SUM(M9:M15) -> -2684364
G19: General Revenues:
H20: Property taxes levied for:
I21: General purposes | M21: 449958
I22: Public works | M22: 510292
I23: Health and welfare | M23: 126841
I24: Culture and recreation | M24: 322042
I25: Economic development and assistance | M25: 326059
H26: Sales and use taxes levied for:
I27: General purposes | M27: 252837
I28: Public works | M28: 1603585
H29: Other taxes, penalties and interest | M29: 11854
H30: Unrestricted investment earnings | M30: 26586
H31: Other revenues | M31: 9807
H33: Total General Revenues | M33: =SUM(M21:M31) -> 3639861
H35: Change in Net Assets | M35: =SUM(M17,M33) -> 955497
E37: Net Assets- Beginning of Year | M37: 18894603
E39: Net Assets- End of Year | M39: =SUM(M35,M37) -> 19850100

Sheet Cameron
I1: Cameron County 2013 Statement of Activities
J2: Issued: December 31, 2013
L5: NET (EXPENSES) REVENUES AND CHANGES IN NET ASSETS
A6: FUNCTIONS/PROGRAMS | I6: Expenses | J6: Operating Grants and Contributions | K6: Capital Grants and Contributions | L6: Governmental Activities
A7: Primary Government:
B8: Government Activities:
B9: General government:
C10: Legislative | I10: -204907 | L10: =SUM(I10:K10) -> -204907
C11: Judicial | I11: -1395672 | L11: =SUM(I11:K11) -> -1395672
C12: Elections | I12: -222 | L12: =SUM(I12:K12) -> -222
C13: Finance and administrative | I13: -1795846 | J13: 124586 | L13: =SUM(I13:K13) -> -1671260
C14: Other general government | I14: -6103072 | L14: =SUM(I14:K14) -> -6103072
C15: Interest on long-term debt | I15: -328311 | L15: =SUM(I15:K15) -> -328311
C16: Public safety | I16: -1288757 | J16: 204251 | K16: 4319561 | L16: =SUM(I16:K16) -> 3235055
C17: Public works | I17: -4883639 | J17: 100943 | K17: 251906 | L17: =SUM(I17:K17) -> -4530790
C18: Culture and recreation | I18: -1289236 | L18: =SUM(I18:K18) -> -1289236
C19: Health and welfare | I19: -395890 | L19: =SUM(I19:K19) -> -395890
C20: Economic development | I20: -2866511 | J20: 13635190 | L20: =SUM(I20:K20) -> 10768679
E22: Total Government Activities | I22: =SUM(I10:I20) -> -20552063 | J22: =SUM(J10:J20) -> 14064970 | K22: =SUM(K10:K20) -> 4571467 | L22: =SUM(L10:L20) -> -1915626
G24: General Revenues:
H25: Taxes:
I26: Property taxes, levied for general purposes | L26: 6689108
I27: Other taxes for general purposes | L27: 1099003
H28: Licenses and permits | L28: 399674
H29: Fines, forfeitures, and court costs | L29: 187131
H30: Intergovernmental:
I31: State | L31: 5939885
I32: Local | L32: -639
H33: Gain (loss) on disposal of capital assets | L33: 151221
H34: Interest earnings | L34: 21036
H35: Other | L35: 451353
H37: Total General Revenues | L37: =SUM(L26:L35) -> 14937772
H39: Change in Net Assets | L39: =SUM(L22,L37) -> 13022146
H41: Net position - beginning | L41: 146125596
H43: Prior period adjustment | L43: -12953737
E45: Net Assets- Beginning of Year | L45: 133171859
E47: Net Assets- End of Year | L47: =SUM(L39,L45) -> 146194005

Sheet Catahoula
J1: Catahoula County 2013 Statement of Activities
J2: Issued: December 31, 2013
J5: PROGRAM REVENUES
A6: FUNCTIONS/PROGRAMS | I6: Expenses | J6: Charges for Services | K6: Operating Grants and Contributions | L6: Capital Grants and Contributions | M6: NET (EXPENSE) REVENUE AND CHANGES IN NET ASSETS
A7: Primary Government:
B8: Government Activities:
C9: General government | I9: -680369 | J9: 113760 | K9: 3293 | M9: =SUM(I9:L9) -> -563316
C10: Public safety | I10: -512635 | J10: 75120 | K10: 171908 | M10: =SUM(I10:L10) -> -265607
C11: Public works | I11: -2382377 | J11: 2365 | K11: 760794 | L11: 60650 | M11: =SUM(I11:L11) -> -1558568
C12: Health and welfare | I12: -242320 | K12: 350621 | M12: =SUM(I12:L12) -> 108301
C13: Culture and recreation | I13: -361409 | J13: 6187 | K13: 26195 | M13: =SUM(I13:L13) -> -329027
C14: Economic development and assistance | I14: -2249 | M14: =SUM(I14:L14) -> -2249
C15: Interest expense | I15: -9343 | M15: =SUM(I15:L15) -> -9343
E17: Total Government Activities | I17: =SUM(I9:I15) -> -4190702 | J17: =SUM(J9:J15) -> 197432 | K17: =SUM(K9:K15) -> 1312811 | L17: =SUM(L9:L15) -> 60650 | M17: =SUM(M9:M15) -> -2619809
G19: General Revenues:
H20: Property taxes | M20: 827325
H21: Sales and use taxes | M21: 1635040
H22: Other taxes, penalties and interest | M22: 5639
H23: Grants and contributions not restricted to specific programs | M23: 324352
H24: Unrestricted investment earnings | M24: 5485
H25: Gain (loss) on sale of capital assets | M25: 18118
H26: Proceeds from insurance | M26: 12050
H27: Other | M27: 28240
H29: Total General Revenues | M29: =SUM(M20:M27) -> 2856249
H31: Change in Net Assets | M31: =SUM(M17,M29) -> 236440
E33: Net Assets- Beginning of Year | M33: 8289746
E35: Net Assets- End of Year | M35: =SUM(M31,M33) -> 8526186

Sheet Claiborne
J1: Claiborne County 2013 Statement of Activities
J2: Issued: December 31, 2013
J5: PROGRAM REVENUES
A6: FUNCTIONS/PROGRAMS | I6: Expenses | J6: Charges for Services | K6: Operating Grants and Contributions | L6: Capital Grants and Contributions | M6: NET (EXPENSE) REVENUE AND CHANGES IN NET ASSETS
A7: Primary Government:
B8: Government Activities:
C9: General government | I9: -1518254 | J9: 402549 | M9: =SUM(I9:L9) -> -1115705
C10: Public safety | I10: -376302 | K10: 110377 | L10: 49781 | M10: =SUM(I10:L10) -> -216144
C11: Public works | I11: -3221702 | K11: 448932 | L11: 130201 | M11: =SUM(I11:L11) -> -2642569
C12: Health and welfare | I12: -875416 | J12: 8533 | K12: 639375 | M12: =SUM(I12:L12) -> -227508
C13: Culture and recreation | I13: -539041 | J13: 1983 | K13: 2438 | M13: =SUM(I13:L13) -> -534620
C14: Economic development and assistance | I14: -60016 | M14: =SUM(I14:L14) -> -60016
C15: Conservation | I15: -5200 | M15: =SUM(I15:L15) -> -5200
C16: Interest expense | I16: -43230 | M16: =SUM(I16:L16) -> -43230
E18: Total Government Activities | I18: =SUM(I9:I16) -> -6639161 | J18: =SUM(J9:J16) -> 413065 | K18: =SUM(K9:K16) -> 1201122 | L18: =SUM(L9:L16) -> 179982 | M18: =SUM(M9:M16) -> -4844992
G20: General Revenues:
H21: Property taxes levied for:
I22: General purposes | M22: 907751
I23: Public works | M23: 1358920
I24: Culture and recreation | M24: 782665
H25: Sales and use taxes levied for public works | M25: 941476
H26: Other taxes, penalties and interest | M26: 12275
H27: Grants and contributions not restricted to specific programs | M27: 1507924
H28: Unrestricted investment earnings | M28: 175700
H29: Gain on sale of capital assets | M29: 37908
H30: Other | M30: 69090
H32: Total General Revenues | M32: =SUM(M22:M30) -> 5793709
H34: Change in Net Assets | M34: =SUM(M18,M32) -> 948717
E36: Net Assets- Beginning of Year | M36: 14433436
E38: Net Assets- End of Year | M38: =SUM(M34,M36) -> 15382153

Sheet Concordia
J1: Concordia County 2013 Statement of Activities
J2: Issued: December 31, 2013
J5: PROGRAM REVENUES
A6: FUNCTIONS/PROGRAMS | I6: Expenses | J6: Charges for Services | K6: Operating Grants and Contributions | L6: Capital Grants and Contributions | M6: NET (EXPENSE) REVENUE AND CHANGES IN NET ASSETS
A7: Primary Government:
B8: Government Activities:
B9: General government:
C10: Legislative | I10: -231502 | M10: =SUM(I10:L10) -> -231502
C11: Judicial | I11: -614792 | M11: =SUM(I11:L11) -> -614792
C12: Elections | I12: -40450 | M12: =SUM(I12:L12) -> -40450
C13: Finance | I13: -348180 | M13: =SUM(I13:L13) -> -348180
C14: Other general | I14: -876320 | K14: 54243 | L14: 171774 | M14: =SUM(I14:L14) -> -650303
B15: Public safety | I15: -230232 | J15: 148144 | K15: 140704 | M15: =SUM(I15:L15) -> 58616
B16: Public works | I16: -2920856 | M16: =SUM(I16:L16) -> -2920856
B17: Health and welfare | I17: -138664 | K17: 2189 | M17: =SUM(I17:L17) -> -136475
B18: Culture and recreation | I18: -31153 | M18: =SUM(I18:L18) -> -31153
B19: Economic development | I19: -188191 | K19: 120413 | M19: =SUM(I19:L19) -> -67778
B20: Transportation | I20: -33545 | M20: =SUM(I20:L20) -> -33545
B21: Interest on long-term debt | I21: -433026 | M21: =SUM(I21:L21) -> -433026
E23: Total Government Activities | I23: =SUM(I10:I21) -> -6086911 | J23: =SUM(J10:J21) -> 148144 | K23: =SUM(K10:K21) -> 317549 | L23: =SUM(L10:L21) -> 171774 | M23: =SUM(M10:M21) -> -5449444
G25: General Revenues:
H26: Taxes:
I27: Property taxes | M27: 1752385
I28: Sales taxes | M28: 2864419
I29: Other taxes | M29: 13437
H30: Licenses and permits | M30: 244385
H31: State funds:
I32: Parish transportation | M32: 274906
I33: State revenue sharing | M33: 66922
I34: Severance | M34: 1032251
H35: Investment income | M35: 22857
H36: Other | M36: 553171
H38: Total General Revenues | M38: =SUM(M27:M36) -> 6824733
H40: Change in Net Assets | M40: =SUM(M23,M38) -> 1375289
E42: Net Assets- Beginning of Year | M42: 9542811
E44: Net Assets- End of Year | M44: =SUM(M40,M42) -> 10918100

Sheet Desoto
J1: Desoto County 2013 Statement of Activities
J2: Issued: December 31, 2013
M4: NET (EXPENSE) REVENUE AND CHANGE IN NET ASSETS
J5: PROGRAM REVENUES | M5: PRIMARY GOVERNMENT
A6: FUNCTIONS/PROGRAMS | I6: Expenses | J6: Charges for Services | K6: Operating Grants and Contributions | L6: Capital Grants and Contributions | M6: Governmental Activities | N6: Business-type Activities | O6: Total
A7: Primary Government:
B8: Government Activities:
B9: General government:
C10: Legislative | I10: -371189 | M10: =SUM(I10:L10) -> -371189 | O10: =SUM(M10:N10) -> -371189
C11: Judicial | I11: -2401455 | J11: 1080171 | M11: =SUM(I11:L11) -> -1321284 | O11: =SUM(M11:N11) -> -1321284
C12: Elections | I12: -46958 | M12: =SUM(I12:L12) -> -46958 | O12: =SUM(M12:N12) -> -46958
C13: Finance and administration | I13: -1317624 | J13: 319261 | K13: 56347 | M13: =SUM(I13:L13) -> -942016 | O13: =SUM(M13:N13) -> -942016
C14: Other | I14: -1492190 | M14: =SUM(I14:L14) -> -1492190 | O14: =SUM(M14:N14) -> -1492190
C15: Public safety | I15: -1012619 | K15: 110561 | M15: =SUM(I15:L15) -> -902058 | O15: =SUM(M15:N15) -> -902058
C16: Public works | I16: -8949274 | J16: 304845 | L16: 442442 | M16: =SUM(I16:L16) -> -8201987 | O16: =SUM(M16:N16) -> -8201987
C17: Sanitation | I17: -3857649 | J17: 1179593 | L17: 20000 | M17: =SUM(I17:L17) -> -2658056 | O17: =SUM(M17:N17) -> -2658056
C18: Culture and recreation | I18: -342350 | M18: =SUM(I18:L18) -> -342350 | O18: =SUM(M18:N18) -> -342350
C19: Health and welfare | I19: -1423093 | K19: 2880298 | M19: =SUM(I19:L19) -> 1457205 | O19: =SUM(M19:N19) -> 1457205
C20: Community development | I20: -2054244 | M20: =SUM(I20:L20) -> -2054244 | O20: =SUM(M20:N20) -> -2054244
C21: Economic development | I21: -3278177 | K21: 2701472 | M21: =SUM(I21:L21) -> -576705 | O21: =SUM(M21:N21) -> -576705
C22: Transportation | I22: -764110 | J22: 243905 | K22: 158838 | M22: =SUM(I22:L22) -> -361367 | O22: =SUM(M22:N22) -> -361367
C23: Animal control | I23: -411754 | J23: 26019 | K23: 5542 | M23: =SUM(I23:L23) -> -380193 | O23: =SUM(M23:N23) -> -380193
C24: Interest on long-term debt | I24: -241 | M24: =SUM(I24:L24) -> -241 | O24: =SUM(M24:N24) -> -241
E26: Total Government Activities | I26: =SUM(I10:I24) -> -27722927 | J26: =SUM(J10:J24) -> 3153794 | K26: =SUM(K10:K24) -> 5913058 | L26: =SUM(L10:L24) -> 462442 | M26: =SUM(M10:M24) -> -18193633 | O26: =SUM(O10:O24) -> -18193633
B28: Business-type Activities:
C29: Eastside sewer | I29: -32468 | J29: 11667 | N29: =SUM(I29:L29) -> -20801 | O29: =N29 -> -20801
E31: Total primary government | I31: =I29+I26 -> -27755395 | J31: =J29+J26 -> 3165461 | K31: =K29+K26 -> 5913058 | L31: =L29+L26 -> 462442 | M31: =M29+M26 -> -18193633 | N31: =N29+N26 -> -20801 | O31: =O29+O26 -> -18214434
G33: General Revenues:
H34: Ad valorem taxes | M34: 11903890 | O34: =SUM(M34:N34) -> 11903890
H35: Sales taxes | M35: 7022500 | O35: =SUM(M35:N35) -> 7022500
H36: Severance taxes | M36: 1412788 | O36: =SUM(M36:N36) -> 1412788
H37: Tourism taxes | M37: 144811 | O37: =SUM(M37:N37) -> 144811
H38: Video poker | M38: 128344 | O38: =SUM(M38:N38) -> 128344
H39: Investment earnings | M39: -79777 | O39: =SUM(M39:N39) -> -79777
H40: State revenue sharing | M40: 56559 | O40: =SUM(M40:N40) -> 56559
H41: Gain on disposal of capital assets | M41: 13390 | O41: =SUM(M41:N41) -> 13390
H42: Rentals, leases and royalties | M42: 731230 | O42: =SUM(M42:N42) -> 731230
H43: Other miscellaneous | M43: 253944 | O43: =SUM(M43:N43) -> 253944
G44: Transfers:
H45: Interfund | M45: -21150 | N45: 21150 | O45: =SUM(M45:N45) -> 0
...

Sheet East Baton Rouge
J1: East Baton Rouge County 2013 Statement of Activities
J2: Issued: December 31, 2013
M4: NET (EXPENSE) REVENUE AND CHANGE IN NET ASSETS
J5: PROGRAM REVENUES | M5: PRIMARY GOVERNMENT
A6: FUNCTIONS/PROGRAMS | I6: Expenses | J6: Charges for Services | K6: Operating Grants and Contributions | L6: Capital Grants and Contributions | M6: Governmental Activities | N6: Business-type Activities | O6: Total | P6: Component Units
A7: Primary Government:
B8: Government Activities:
C9: General government | I9: -97833150 | J9: 22638870 | K9: 294653 | M9: =SUM(I9:L9) -> -74899627 | O9: =SUM(M9:N9) -> -74899627
C10: Public safety | I10: -237028010 | J10: 28032000 | K10: 10591272 | L10: 301660 | M10: =SUM(I10:L10) -> -198103078 | O10: =SUM(M10:N10) -> -198103078
C11: Transportation | I11: -68812076 | J11: 269248 | K11: 610377 | L11: 12571646 | M11: =SUM(I11:L11) -> -55360805 | O11: =SUM(M11:N11) -> -55360805
C12: Sanitation | I12: -5791 | J12: 54389 | M12: =SUM(I12:L12) -> 48598 | O12: =SUM(M12:N12) -> 48598
C13: Health and welfare | I13: -9499922 | J13: 798229 | K13: 604950 | M13: =SUM(I13:L13) -> -8096743 | O13: =SUM(M13:N13) -> -8096743
C14: Culture and recreation | I14: -38171468 | J14: 320831 | K14: 966897 | M14: =SUM(I14:L14) -> -36883740 | O14: =SUM(M14:N14) -> -36883740
C15: Conservation and development | I15: -50034044 | J15: 3555210 | K15: 35143291 | L15: 254986 | M15: =SUM(I15:L15) -> -11080557 | O15: =SUM(M15:N15) -> -11080557
C16: Interest and fiscal charges on long-term debt | I16: -15625052 | M16: =SUM(I16:L16) -> -15625052 | O16: =SUM(M16:N16) -> -15625052
E18: Total Government Activities | I18: =SUM(I9:I16) -> -517009513 | J18: =SUM(J9:J16) -> 55668777 | K18: =SUM(K9:K16) -> 48211440 | L18: =SUM(L9:L16) -> 13128292 | M18: =SUM(M9:M16) -> -400001004 | O18: =SUM(O9:O16) -> -400001004 | P18: =SUM(P9:P16) -> 0
B20: Business-type Activities:
C21: Airport | I21: -28608472 | J21: 17581662 | K21: 705204 | L21: 5293273 | N21: =SUM(I21:L21) -> -5028333 | O21: =SUM(M21:N21) -> -5028333
C22: Sewer | I22: -131780088 | J22: 74404748 | K22: 6847548 | L22: 2862431 | N22: =SUM(I22:L22) -> -47665361 | O22: =SUM(M22:N22) -> -47665361
C23: Solid waste collection and disposal | I23: -37196266 | J23: 36332687 | N23: =SUM(I23:L23) -> -863579 | O23: =SUM(M23:N23) -> -863579
C24: Convention center | I24: -13305252 | J24: 6459913 | K24: 59498 | L24: 1470739 | N24: =SUM(I24:L24) -> -5315102 | O24: =SUM(M24:N24) -> -5315102
C25: Parking facilities | I25: -1110612 | J25: 1091019 | N25: =SUM(I25:L25) -> -19593 | O25: =SUM(M25:N25) -> -19593
E27: Total Business-type Activities | I27: =SUM(I21:I25) -> -212000690 | J27: =SUM(J21:J25) -> 135870029 | K27: =SUM(K21:K25) -> 7612250 | L27: =SUM(L21:L25) -> 9626443 | M27: =SUM(M21:M25) -> 0 | N27: =SUM(N21:N25) -> -58891968 | O27: =SUM(O21:O25) -> -58891968 | P27: =SUM(P15:P25) -> 0
E29: Total primary government | I29: =I27+I18 -> -729010203 | J29: =J27+J18 -> 191538806 | K29: =SUM(K18+K27) -> 55823690 | L29: =SUM(L18+L27) -> 22754735 | M29: =M27+M18 -> -400001004 | N29: =N27+N18 -> -58891968 | O29: =O27+O18 -> -458892972 | P29: =SUM(P17:P27) -> 0
A31: Component units:
B32: Judicial court services | I32: -56432777 | J32: 25651979 | K32: 23396868 | P32: =SUM(I32:M32) -> -7383930
B33: Economic development districts | I33: -4029211 | J33: 211925 | K33: 2840925 | P33: =SUM(I33:L33) -> -976361
B34: Mass transit | I34: -19426686 | J34: 2186502 | L34: 2830311 | P34: =SUM(I34:L34) -> -14409873
E36: Total component units | I36: =SUM(I32:I34) -> -79888674 | J36: =SUM(J32:J34) -> 28050406 | K36: =SUM(K32:K34) -> 26237793 | L36: =SUM(L32:L34) -> 2830311 | M36: =SUM(M32:M34) -> 0 | N36: =SUM(N32:N34) -> 0 | O36: =SUM(O32:O34) -> 0 | P36: =SUM(P32:P34) -> -22770164
G38: General Revenues:
H39: Taxes:
I40: Property | M40: 94352140 | O40: =SUM(M40:N40) -> 94352140 | P40: 14612939
I41: Gross receipts business | M41: 23093005 | O41: =SUM(M41:N41) -> 23093005
I42: Sales | M42: 219609518 | N42: 42996932 | O42: =SUM(M42:N42) -> 262606450
I43: Occupancy | M43: 2200681 | O43: =SUM(M43:N43) -> 2200681 | P43: 2085006
I44: Occupational | M44: 10382634 | O44: =SUM(M44:N44) -> 10382634
I45: Insurance premium | M45: 3774099 | O45: =SUM(M45:N45) -> 3774099
I46: Gaming admissions | M46: 9438267 | O46: =SUM(M46:N46) -> 9438267
I47: Interest and penalties - delinquent taxes | M47: 2524919 | O47: =SUM(M47:N47) -> 2524919
H48: Miscellaneous | M48: 11040 | N48: 75000 | O48: =SUM(M48:N48) -> 86040 | P48: 274166
...

Sheet East Carroll
J1: East Carroll County 2013 Statement of Activities
J2: Issued: December 31, 2013
M4: NET (EXPENSE) REVENUE AND CHANGES IN NET ASSETS
J5: PROGRAM REVENUES | M5: PRIMARY GOVERNMENT
A6: FUNCTIONS/PROGRAMS | I6: Expenses | J6: Charges for Services | K6: Operating Grants and Contributions | L6: Capital Grants and Contributions | M6: Governmental Activities | N6: Business-type Activities | O6: Total
A7: Primary Government:
B8: Government Activities:
C9: General government:
D10: Legislative | I10: -76402 | M10: =SUM(I10:L10) -> -76402 | O10: =SUM(M10:N10) -> -76402
D11: Judicial | I11: -568012 | J11: 434404 | M11: =SUM(I11:L11) -> -133608 | O11: =SUM(M11:N11) -> -133608
D12: Elections | I12: -39899 | M12: =SUM(I12:L12) -> -39899 | O12: =SUM(M12:N12) -> -39899
D13: Finance and administrative | I13: -208877 | M13: =SUM(I13:L13) -> -208877 | O13: =SUM(M13:N13) -> -208877
D14: Other general government | I14: -578588 | M14: =SUM(I14:L14) -> -578588 | O14: =SUM(M14:N14) -> -578588
C15: Public safety | I15: -278827 | K15: 105136 | L15: 136513 | M15: =SUM(I15:L15) -> -37178 | O15: =SUM(M15:N15) -> -37178
C16: Public works | I16: -1324952 | J16: 106646 | K16: 362463 | L16: 25500 | M16: =SUM(I16:L16) -> -830343 | O16: =SUM(M16:N16) -> -830343
C17: Health and welfare | I17: -111144 | M17: =SUM(I17:L17) -> -111144 | O17: =SUM(M17:N17) -> -111144
C18: Culture and recreation | I18: -333558 | J18: 20571 | L18: 138391 | M18: =SUM(I18:L18) -> -174596 | O18: =SUM(M18:N18) -> -174596
C19: Economic development and assistance | I19: -5949 | M19: =SUM(I19:L19) -> -5949 | O19: =SUM(M19:N19) -> -5949
C20: Transportation | I20: -27398 | M20: =SUM(I20:L20) -> -27398 | O20: =SUM(M20:N20) -> -27398
C21: Interest on long-term debt | I21: -20928 | M21: =SUM(I21:L21) -> -20928 | O21: =SUM(M21:N21) -> -20928
E23: Total Government Activities | I23: =SUM(I10:I21) -> -3574534 | J23: =SUM(J10:J21) -> 561621 | K23: =SUM(K10:K21) -> 467599 | L23: =SUM(L10:L21) -> 300404 | M23: =SUM(M10:M21) -> -2244910 | O23: =SUM(O10:O21) -> -2244910
B25: Business-type Activities:
C26: Health and welfare | I26: -634697 | J26: 212 | K26: 581985 | L26: 0 | N26: =SUM(I26:L26) -> -52500 | O26: =SUM(M26:N26) -> -52500
E28: Total business-type Activities | I28: =SUM(I26:I26) -> -634697 | J28: =SUM(J26:J26) -> 212 | K28: =SUM(K26:K26) -> 581985 | L28: =SUM(L26:L26) -> 0 | M28: =SUM(M26:M26) -> 0 | N28: =SUM(N26:N26) -> -52500 | O28: =SUM(O26:O26) -> -52500
E30: Total government | I30: =I28+I23 -> -4209231 | J30: =J28+J23 -> 561833 | K30: =K28+K23 -> 1049584 | L30: =L28+L23 -> 300404 | M30: =M28+M23 -> -2244910 | N30: =N28+N23 -> -52500 | O30: =O28+O23 -> -2297410
G32: General Revenues:
H33: Taxes:
I34: Property taxes, levied for general purposes | M34: 2038944 | O34: =SUM(M34:N34) -> 2038944
I35: Property taxes, levied for debt services | M35: 74110 | O35: =SUM(M35:N35) -> 74110
I36: Sales taxes, levied for general purposes | M36: 758507 | O36: =SUM(M36:N36) -> 758507
H37: State revenue sharing | M37: 48848 | O37: =SUM(M37:N37) -> 48848
H38: Other taxes | M38: 41050 | O38: =SUM(M38:N38) -> 41050
H39: Grants and contributions not restricted to specific programs | M39: 61417 | O39: =SUM(M39:N39) -> 61417
H40: Licenses and permits | M40: 100927 | O40: =SUM(M40:N40) -> 100927
H41: Interest and investment earnings | M41: 4698 | O41: =SUM(M41:N41) -> 4698
H42: Miscellaneous | M42: 34260 | O42: =SUM(M42:N42) -> 34260
H44: Total General Revenues | M44: =SUM(M34:M42) -> 3162761 | N44: =SUM(N34:N42) -> 0 | O44: =SUM(O34:O42) -> 3162761
H46: Change in Net Assets | M46: =M44+M30 -> 917851 | N46: =N44+N30 -> -52500 | O46: =O44+O30 -> 865351
E48: Net Assets- Beginning of Year | M48: 9704474 | N48: 79839 | O48: =SUM(M48:N48) -> 9784313
E50: Net Assets- End of Year | M50: =SUM(M46,M48) -> 10622325 | N50: =N48+N46 -> 27339 | O50: =O48+O46 -> 10649664

Sheet East Feliciana
J1: East Feliciana County 2013 Statement of Activities
J2: Issued: December 31, 2013
J5: PROGRAM REVENUES
A6: FUNCTIONS/PROGRAMS | I6: Expenses | J6: Charges for Services | K6: Operating Grants and Contributions | L6: Capital Grants and Contributions | M6: NET (EXPENSE) REVENUE AND CHANGES IN NET ASSETS
A7: Primary Government:
B8: Government Activities:
C9: General government | I9: -710683.58 | J9: 191962.61 | K9: 20000 | M9: =SUM(I9:L9) -> -498720.97
C10: Culture and recreation | I10: -4219.33 | M10: =SUM(I10:L10) -> -4219.33
C11: Economic development | I11: -9208.32 | K11: 7250 | M11: =SUM(I11:L11) -> -1958.32
C12: Health and welfare | I12: -462121.51 | K12: 5610.08 | M12: =SUM(I12:L12) -> -456511.43
C13: Public safety | I13: -893111.69 | J13: 324360.27 | K13: 234703.28 | L13: 434068.7 | M13: =SUM(I13:L13) -> 100020.56
C14: Public works | I14: -3295452 | K14: 161713.9 | L14: 192415.13 | M14: =SUM(I14:L14) -> -2941322.9
E16: Total Government Activities | I16: =SUM(I9:I14) -> -5374796.4 | J16: =SUM(J9:J14) -> 516322.88 | K16: =SUM(K9:K14) -> 429277.26 | L16: =SUM(L9:L14) -> 626483.83 | M16: =SUM(M9:M14) -> -3802712.4
G18: General Revenues:
H19: Intergovernmental revenues | M19: 356476.28
H20: Taxes:
I21: Ad valorem | M21: 694605.02
I22: Severance | M22: 613694.88
I23: Sales | M23: 3192203.6
H24: Franchise fees | M24: 11441.73
H25: Insurance rebates | M25: 87634.83
H26: Licenses and permits | M26: 181394.25
H27: Fines and forfeitures | M27: 124880.51
H28: Interest earned | M28: 1604.01
H29: Other revenues | M29: 64680.75
H31: Total General Revenues | M31: =SUM(M19:M29) -> 5328615.9
H33: Change in Net Assets | M33: =SUM(M16,M31) -> 1525903.5
E35: Net Assets- Beginning of Year | M35: 13128810
E37: Net Assets- End of Year | M37: =SUM(M33,M35) -> 14654714

Sheet Evangeline
J1: Evangeline County 2013 Statement of Activities
J2: Issued: December 31, 2013
M4: NET (EXPENSE) REVENUE AND CHANGE IN NET ASSETS
J5: PROGRAM REVENUES | M5: PRIMARY GOVERNMENT | P5: COMPONENT UNITS
A6: FUNCTIONS/PROGRAMS | I6: Expenses | J6: Charges for Services | K6: Operating Grants and Contributions | L6: Capital Grants and Contributions | M6: Governmental Activities | N6: Business-type Activities | O6: Total | P6: Criminal Court Fund
A7: Primary Government:
B8: Government Activities:
C9: General government | I9: -2191744 | J9: 421870 | M9: =SUM(I9:L9) -> -1769874 | O9: =SUM(M9:N9) -> -1769874
C10: Public safety | I10: -797397 | K10: 79627 | M10: =SUM(I10:L10) -> -717770 | O10: =SUM(M10:N10) -> -717770
C11: Public works | I11: -3478839 | J11: 61665 | K11: 588312 | L11: 1699161 | M11: =SUM(I11:L11) -> -1129701 | O11: =SUM(M11:N11) -> -1129701
C12: Health and welfare | I12: -558793 | M12: =SUM(I12:L12) -> -558793 | O12: =SUM(M12:N12) -> -558793
C13: Culture and recreation | I13: -1104898 | J13: 238759 | K13: 26031 | M13: =SUM(I13:L13) -> -840108 | O13: =SUM(M13:N13) -> -840108
C14: Economic development | I14: -228270 | M14: =SUM(I14:L14) -> -228270 | O14: =SUM(M14:N14) -> -228270
C15: Interest on long-term debt | I15: -722085 | M15: =SUM(I15:L15) -> -722085 | O15: =SUM(M15:N15) -> -722085
E17: Total Government Activities | I17: =SUM(I9:I15) -> -9082026 | J17: =SUM(J9:J15) -> 722294 | K17: =SUM(K9:K15) -> 693970 | L17: =SUM(L9:L15) -> 1699161 | M17: =SUM(M9:M15) -> -5966601 | O17: =SUM(O9:O15) -> -5966601 | P17: =SUM(P9:P15) -> 0
B19: Business-type Activities:
C20: Ward One sewer system | I20: -69311 | J20: 38808 | N20: =SUM(I20:L20) -> -30503 | O20: =N20 -> -30503
C21: Section 8 housing program | I21: -521141 | K21: 495212 | N21: =SUM(I21:L21) -> -25929 | O21: =N21 -> -25929
E23: Total business-type Activities | I23: =SUM(I20:I21) -> -590452 | J23: =SUM(J20:J21) -> 38808 | K23: =SUM(K20:K21) -> 495212 | L23: =SUM(L20:L21) -> 0 | M23: =SUM(M20:M21) -> 0 | N23: =SUM(N20:N21) -> -56432 | O23: =SUM(O20:O21) -> -56432
E25: Total primary government | I25: =I23+I17 -> -9672478 | J25: =J23+J17 -> 761102 | K25: =K23+K17 -> 1189182 | L25: =L23+L17 -> 1699161 | M25: =M23+M17 -> -5966601 | N25: =N23+N17 -> -56432 | O25: =O23+O17 -> -6023033
A27: Component units:
B28: Criminal Court fund | I28: -499541 | J28: 382826 | K28: 115627 | P28: =SUM(I28:K28) -> -1088
E30: Total component units | I30: =SUM(I28:I28) -> -499541 | J30: =SUM(J28:J28) -> 382826 | K30: =SUM(K28:K28) -> 115627 | L30: =SUM(L28:L28) -> 0 | M30: =SUM(M28:M28) -> 0 | N30: =SUM(N28:N28) -> 0 | O30: =SUM(O28:O28) -> 0 | P30: =SUM(P28:P28) -> -1088
G32: General Revenues:
H33: Taxes:
I34: Property taxes, levied for general purposes | M34: 4911887 | O34: =SUM(M34:N34) -> 4911887
I35: Sales and use taxes, levied for general purposes | M35: 3115373 | O35: =SUM(M35:N35) -> 3115373
H36: Grants and contributions not restricted to specific programs:
I37: Beer taxes | M37: 5312 | O37: =SUM(M37:N37) -> 5312
I38: State revenue sharing | M38: 236314 | O38: =SUM(M38:N38) -> 236314
I39: Parish equalization | M39: 1167550 | O39: =SUM(M39:N39) -> 1167550
I40: Other state grants | M40: 318858 | O40: =SUM(M40:N40) -> 318858
H41: Interest and investment earnings | M41: 80003 | N41: 225 | O41: =SUM(M41:N41) -> 80228 | P41: 251
H42: Miscellaneous | M42: 547529 | O42: =SUM(M42:N42) -> 547529
