Workbook

Sheet Acadia
D1: Acadia Parish 2013 Statement of Net Assets
D2: Issued: December 31, 2013
H4: Primary Government
H5: Governmental Activities | I5: Component Unit
A6: ASSETS
B7: Current Assets
C8: Cash | H8: 6387055 | I8: 18001
C9: Investments | H9: 7359136
C10: Taxes receivable | H10: 412930
C11: Special assessments receivable | H11: 29556
C12: Other receivables | H12: 77797 | I12: 14656
C13: Due from other governmental entities | H13: 6687029 | I13: 31151
C14: Due from component units | H14: 20793
C15: Capital assets:
D16: Non-depreciable | H16: 11576953
D17: Depreciable, net | H17: 42893333 | I17: 376
C19: Total Assets | H19: =SUM(H8:H17) -> 75444582 | I19: =SUM(I8:I17) -> 64184
A21: DEFERRED OUTFLOWS OF RESOURCES
C22: Deferred loss on refunding | H22: 40499
A24: LIABILITIES
C25: Accounts payable | H25: 799857 | I25: 4582
C26: Retainage payable | H26: 30559
C27: Accrued liabilities and other payables | H27: 326235
C28: Unearned revenue | H28: 26500
C29: Accrued interest payable | H29: 79052
C30: Due to primary government | I30: 20793
C31: Long-term liabilities:
D32: Portion due or payable within one year:
E33: Bonds payable | H33: 1531435
E34: Compensated absences | H34: 185605
D35: Portion due or payable after one year:
E36: Bonds payable | H36: 12775783
E37: Compensated absences | H37: 185605
E38: Landfill closure and postclosure care costs liability | H38: 6893470
D40: Total Liabilities | H40: =SUM(H25:H38) -> 22834101 | I40: =SUM(I25:I38) -> 25375
A42: DEFERRED INFLOWS OF RESOURCES
C43: Unavailable revenue - special assessments | H43: 29556
A45: NET ASSETS
B46: Net investment in capital assets | H46: 40203566
B47: Restricted for:
...

Sheet Allen
C1: Allen Parish 2013 Statement of Net Assets
C2: Issued: December 31, 2013
G4: Governmental Activities
A5: ASSETS
B6: Cash | G6: 4518521
B7: Receivables | G7: 2958638
B8: Due from other governments | G8: 549380
B9: Inventory | G9: 25276
B10: Prepaid assets | G10: 4443
B11: Capital assets, net of accumulated depreciation | G11: 24665755
B13: Total Assets | G13: =SUM(G6:G11) -> 32722013
A15: LIABILITIES
B16: Accounts payable | G16: 486255
B17: Accrued interest payable | G17: 1691
B18: Unearned revenue | G18: 134467
B19: Bonds payable - due within one year | G19: 33000
B20: Compensated absences payable - due within one year | G20: 37649
B21: OPEB obligations - due in more than one year | G21: 989571
B22: Bonds payable - due in more than one year | G22: 155000
C24: Total Liabilities | G24: =SUM(G16:G22) -> 1837633
A26: NET ASSETS
B27: Net, investment in capital assets | G27: 24477755
B28: Restricted for:
C29: Inventory | G29: 25276
C30: Judicial | G30: 349325
C31: Other general government | G31: 644976
C32: Public safety | G32: 874
C33: Public works | G33: 4480460
C34: Economic development | G34: 37419
C35: Sanitation | G35: 575216
C36: Capital projects | G36: 300024
C37: Debt service | G37: 258
B38: Unrestricted | G38: -7203
B40: Total Net Assets | G40: =SUM(G27:G38) -> 30884380
B42: Total Liabilities and Net Assets | G42: =SUM(G24+G40) -> 32722013

Sheet Ascension
D1: Ascension Parish 2013 Statement of Net Assets
D2: Issued: December 31, 2013
I4: Primary Government | L4: Component Unit
I5: Governmental Activities | J5: Business-type Activities | K5: Total | L5: Governmental Activities | M5: Business-type Activities
A6: ASSETS
B7: Current Assets
C8: Cash and cash equivalents | I8: 42404828 | J8: 3686409 | K8: =SUM(I8:J8) -> 46091237 | L8: 30169983 | M8: 457571
C9: Investments | I9: 93691087 | J9: 4127466 | K9: =SUM(I9:J9) -> 97818553 | L9: 4943491 | M9: 9681370
C10: Accounts receivable, net | I10: 31751994 | J10: 211156 | K10: =SUM(I10:J10) -> 31963150 | L10: 3767692 | M10: 1153256
C11: Due from other governments | I11: 5021470 | J11: 104475 | K11: =SUM(I11:J11) -> 5125945 | L11: 1125619
C12: Internal balances | I12: 5 | J12: -5 | K12: =SUM(I12:J12) -> 0
C13: Prepaid assets | I13: 1008407 | J13: 281 | K13: =SUM(I13:J13) -> 1008688 | L13: 173484
C14: Inventory | J14: 22147 | K14: =SUM(I14:J14) -> 22147 | M14: 240233
C15: Restricted assets | J15: 36464 | K15: =SUM(I15:J15) -> 36464 | L15: 709316 | M15: 548502
C16: Other assets | I16: 97173 | K16: =SUM(I16:J16) -> 97173 | L16: 6681 | M16: 116241
C17: Capital assets:
E18: Nondepreciable | I18: 73100022 | J18: 941205 | K18: =SUM(I18:J18) -> 74041227 | L18: 1945991 | M18: 110902
E19: Depreciable, net | I19: 136464488 | J19: 9952083 | K19: =SUM(I19:J19) -> 146416571 | L19: 11921812 | M19: 11753708
C21: Total Assets | I21: =SUM(I8:I19) -> 383539474 | J21: =SUM(J8:J19) -> 19081681 | K21: =SUM(K8:K19) -> 402621155 | L21: =SUM(L8:L19) -> 54764069 | M21: =SUM(M7:M19) -> 24061783
A23: Deferred Outflows of Resources
B24: Deferred loss on refunding bonds, net | I24: 294404 | J24: 0 | K24: =SUM(I24:J24) -> 294404 | L24: 0 | M24: 0
C26: Total assets and deferred outflows of resources | I26: =SUM(I24+I21) -> 383833878 | J26: =J21 -> 19081681 | K26: =K24+K21 -> 402915559 | L26: =L21 -> 54764069 | M26: =M21 -> 24061783
A28: LIABILITIES
C29: Accounts payable and accrued liabilities | I29: 3198900 | J29: 565558 | K29: =SUM(I29:J29) -> 3764458 | L29: 3210186 | M29: 352605
C30: Contracts payable | I30: 3980044 | K30: =SUM(I30:J30) -> 3980044
C31: Due to other goevernments | I31: 269707 | K31: =SUM(I31:J31) -> 269707 | L31: 1136146
C32: Accrued payroll | I32: 540668 | J32: 28220 | K32: =SUM(I32:J32) -> 568888
C33: Customer deposits | J33: 36464 | K33: =SUM(I33:J33) -> 36464 | M33: 43501
C34: Sales tax rebate reserve | I34: 4524981 | K34: =SUM(I34:J34) -> 4524981
C35: Claims reserve | K35: =SUM(I35:J35) -> 0
D36: Due within one year | I36: 235409 | K36: =SUM(I36:J36) -> 235409
D37: Due in more than one year | I37: 667416 | K37: =SUM(I37:J37) -> 667416
C38: Long-term payable | K38: =SUM(I38:J38) -> 0
D39: Due within one year | I39: 4335000 | K39: =SUM(I39:J39) -> 4335000 | L39: 551031 | M39: 176485
D40: Due in more than one year | I40: 80612569 | K40: =SUM(I40:J40) -> 80612569 | L40: 6694058 | M40: 4766994
D42: Total Liabilities | I42: =SUM(I29:I40) -> 98364694 | J42: =SUM(J29:J40) -> 630242 | K42: =SUM(K29:K40) -> 98994936 | L42: =SUM(L29:L40) -> 11591421 | M42: =SUM(M29:M40) -> 5339585
A44: Deferred Inflows of Resources
B45: Grant Advances | I45: 629856 | J45: 0 | K45: =SUM(I45:J45) -> 629856 | L45: 0 | M45: 0
B46: Unearned Revenue | I46: 0 | J46: 18770 | K46: =SUM(I46:J46) -> 18770 | L46: 0 | M46: 0
D48: Total deferred inflows of resources | I48: =SUM(I45:I46) -> 629856 | J48: =SUM(J45:J46) -> 18770 | K48: =SUM(K45:K46) -> 648626 | L48: 0 | M48: 0
...

Sheet Assumption
D1: Assumption Parish 2013 Statement of Net Assets
D2: Issued: December 31, 2013
H4: 2013 | I4: 2012
A5: ASSETS
B6: Current Assets
C7: Cash and cash equivalents | H7: 3793804 | I7: 5837144
C8: Investments | H8: 13855799 | I8: 11713813
C9: Receivables | H9: 5121670 | I9: 5328610
C10: Other assets | H10: 27165 | I10: 619979
C11: Land, Building, and Equipment - net | H11: 43733131 | I11: 41316993
C13: Total Assets | H13: =SUM(H7:H11) -> 66531569 | I13: =SUM(I7:I11) -> 64816539
A15: LIABILITIES
C16: Accounts payable | H16: 677911 | I16: 1848741
C17: Salaries payable | H17: 139322 | I17: 146265
C18: Compensated absences payable | H18: 155373 | I18: 158422
C19: Other post-employment benefits payable | H19: 659785 | I19: 553095
C20: Other liabilities | H20: 301226 | I20: 1143608
C21: Long-term liabilities:
D22: Due within one year | I22: 57000
D23: Due in more than one year
D25: Total Liabilities | H25: =SUM(H16:H23) -> 1933617 | I25: =SUM(I16:I23) -> 3907131
A27: NET ASSETS
B28: Invested in capital assets, net of related debt | H28: 43733131 | I28: 41259993
B29: Unrestricted | H29: 20864821 | I29: 19649415
C31: Total Net Assets | H31: =SUM(H28:H29) -> 64597952 | I31: =SUM(I27:I29) -> 60909408
C33: Total Liabilities and Net Assets | H33: =SUM(H25+H31) -> 66531569 | I33: =SUM(I31+I25) -> 64816539

Sheet Avoyelles
D1: Avoyelles Parish 2013 Statement of Net Assets
D2: Issued: December 31, 2013
H4: Primary Government | I4: Component Units
A5: ASSETS
B6: Current Assets
C7: Cash and interest-bearing deposits | H7: 7808079 | I7: 226394
C8: Receivables, net | H8: 2186064 | I8: 17410
C9: Due from other governmental units | H9: 454661
C10: Other assets | H10: 104800 | I10: 5933
C12: Total Current Assets | H12: =SUM(H7:H10) -> 10553604 | I12: =SUM(I7:I11) -> 249737
B14: Non-current Assets:
C15: Land and construction in progress | H15: 1667856
C16: Capital assets, net | H16: 3564386 | I16: 24978
C18: Total Non-current Assets | H18: =SUM(H14:H16) -> 5232242 | I18: =SUM(I14:I16) -> 24978
C20: Total Assets | H20: =SUM(H12+H18) -> 15785846 | I20: =SUM(I12+I18) -> 274715
A22: LIABILITIES
B23: Current Liabilities:
C24: Accounts, salaries and other payables | H24: 588143 | I24: 22127
C25: Deferred revenue | H25: 36260
C26: Due to other governmental units | H26: 37903
C27: Compensated absences payable | H27: 32052
D29: Total Current Liabilities | H29: =SUM(H24:H27) -> 694358 | I29: =SUM(I24:I27) -> 22127
B31: Non-current Liabilities
C32: Compensated absences payable | H32: 66030
D34: Total Non-current Liabilities | H34: =SUM(H32:H32) -> 66030 | I34: =SUM(I32:I32) -> 0
D36: Total Liabilities | H36: =SUM(H29+H34) -> 760388 | I36: =SUM(I34+I29) -> 22127
A38: NET ASSETS
B39: Investment in capital assets | H39: 5232242 | I39: 24978
B40: Unrestricted net position | H40: 9793216 | I40: 227610
C42: Total Net Assets | H42: =SUM(H39:H40) -> 15025458 | I42: =SUM(I39:I40) -> 252588
C44: Total Liabilities and Net Assets | H44: =SUM(H36+H42) -> 15785846 | I44: =SUM(I42+I36) -> 274715

Sheet Beauregard
C1: Beauregard Parish 2013 Statement of Net Assets
C2: Issued: December 31, 2013
G4: Governmental Activities
A5: ASSETS
B6: Cash and cash equivalents | G6: 14858366
B7: Receivables | G7: 6484761
B8: Inventory | G8: 313803
B9: Capital assets (net of accumulated depreciation):
C10: Land | G10: 806735
C11: Buildings and improvements | G11: 9930994
C12: Furniture and equipment | G12: 3990003
C13: Infrastructure | G13: 15989047
C14: Construction in progress | G14: 790379
B16: Total Assets | G16: =SUM(G6:G14) -> 53164088
A18: LIABILITIES
B19: Accounts, salaries, and other payables | G19: 849191
B20: Interest payable | G20: 25658
B21: Long-term liabilities:
C22: Due within one year | G22: 1760644
C23: Due in more than one year | G23: 2722875
C25: Total Liabilities | G25: =SUM(G19:G23) -> 5358368
A27: NET ASSETS
B28: Invested in capital assets, net of related debt | G28: 27191700
B29: Restricted for:
C30: Inventory | G30: 313803
C31: Equipment purchases | G31: 324072
C32: Public safety | G32: 1810976
C33: Public works | G33: 6392675
C34: Health and welfare | G34: 2463098
C35: Culture and recreation | G35: 607692
C36: Sanitation | G36: 3275003
C37: Other general government | G37: 136917
C38: Capital projects | G38: 1275201
C39: Debt service | G39: 166216
B40: Unrestricted | G40: 3848367
B42: Total Net Assets | G42: =SUM(G28:G40) -> 47805720
B44: Total Liabilities and Net Assets | G44: =SUM(G25+G42) -> 53164088

Sheet Bienville
C1: Bienville Parish 2013 Statement of Net Assets
C2: Issued: December 31, 2013
G4: Governmental Activities
A5: ASSETS
B6: Cash and cash equivalents | G6: 17224341
B7: Receivables | G7: 5448406
B8: Capital assets, net | G8: 22814176
B10: Total Assets | G10: =SUM(G6:G8) -> 45486923
A12: LIABILITIES
B13: Accounts payable | G13: 249706
B14: Wages and related payable | G14: 22626
B15: Interest payable | G15: 141079
B16: Bonds payable | G16: 10820000
B17: Premium on bonds | G17: 290088
B18: Deferred revenues | G18: 70000
B19: Compensated absences payable | G19: 81369
B20: Other post-employment benefits | G20: 1236841
C22: Total Liabilities | G22: =SUM(G13:G20) -> 12911709
A24: NET ASSETS
B25: Invested in capital assets, net of related debt | G25: 11994176
B26: Unrestricted | G26: 20581038
B28: Total Net Assets | G28: =SUM(G25:G26) -> 32575214
B30: Total Liabilities and Net Assets | G30: =SUM(G22+G28) -> 45486923

Sheet Bossier
D1: Bossier Parish 2013 Statement of Net Assets
D2: Issued: December 31, 2013
H4: Primary Government
H5: Governmental Activities | I5: Business-Type Activities | J5: Total
A6: ASSETS
B7: Current Assets
C8: Cash and cash equivalents | H8: 36706356 | I8: 766450 | J8: =SUM(H8:I8) -> 37472806
C9: Restricted cash | H9: 5135344 | I9: 386253 | J9: =SUM(H9:I9) -> 5521597
C10: Receivables | H10: 17839886 | I10: 243838 | J10: =SUM(H10:I10) -> 18083724
C11: Prepaid expenses | H11: 964155 | I11: 39816 | J11: =SUM(H11:I11) -> 1003971
C12: Capital assets, net:
D13: Non-depreciable | H13: 18249363 | I13: 5807576 | J13: =SUM(H13:I13) -> 24056939
D14: Depreciable (net) | H14: 263054104 | I14: 4654569 | J14: =SUM(H14:I14) -> 267708673
C15: Internal balances | H15: 8185472 | I15: -8185472 | J15: =SUM(H15:I15) -> 0
C17: Total Assets | H17: =SUM(H8:H15) -> 350134680 | I17: =SUM(I8:I15) -> 3713030 | J17: =SUM(J8:J15) -> 353847710
A19: LIABILITIES
B20: Current liabilities
C21: Accounts payable and accrued expenses | H21: 3002767 | I21: 313454 | J21: =SUM(H21:I21) -> 3316221
C22: Payable from restricted assets:
D23: Customer deposits | I23: 91817 | J23: =SUM(H23:I23) -> 91817
D25: Total Current Liabilities | H25: =SUM(H21:H23) -> 3002767 | I25: =SUM(I21:I23) -> 405271 | J25: =SUM(J21:J23) -> 3408038
B27: Noncurrent liabilities
C28: Due within one year | H28: 4678377 | J28: =SUM(H28:I28) -> 4678377
C29: Due in more than one year | H29: 60341208 | I29: 572460 | J29: =SUM(H29:I29) -> 60913668
D31: Total Noncurrent Liabilities | H31: =SUM(H27:H29) -> 65019585 | I31: =SUM(I27:I29) -> 572460 | J31: =SUM(J27:J29) -> 65592045
D33: Total Liabilities | H33: =SUM(H25+H31) -> 68022352 | I33: =SUM(I31+I25) -> 977731 | J33: =SUM(J31+J25) -> 69000083
A35: NET ASSETS
B36: Net investment in capital assets | H36: 226860112 | I36: 1704213 | J36: =SUM(H36:I36) -> 228564325
B37: Restricted for:
C38: Capital projects | H38: 8902048 | J38: =SUM(H38:I38) -> 8902048
C39: Public works | H39: 541580 | J39: =SUM(H39:I39) -> 541580
C40: Public safety | H40: 3674946 | J40: =SUM(H40:I40) -> 3674946
C41: Economic development | H41: 159526 | J41: =SUM(H41) -> 159526
C42: Culture and recreation | H42: 11586703 | J42: =SUM(H42) -> 11586703
C43: Debt service | H43: 3467975 | J43: =SUM(H43) -> 3467975
C44: Health and welfare | H44: 3000381 | J44: =SUM(H44) -> 3000381
C45: Sewer operations | H45: 330557 | J45: =SUM(H45:I45) -> 330557
B46: Unrestricted | H46: 23588500 | I46: 1031086 | J46: =SUM(H46:I46) -> 24619586
C48: Total Net Assets | H48: =SUM(H36:H46) -> 282112328 | I48: =SUM(I36:I46) -> 2735299 | J48: =SUM(J36:J46) -> 284847627
C50: Total Liabilities and Net Assets | H50: =H33+H48 -> 350134680 | I50: =I33+I48 -> 3713030 | J50: =J33+J48 -> 353847710

Sheet Caddo
D1: Caddo Parish 2013 Statement of Net Assets
D2: Issued: December 31, 2013
H4: Primary Government
H5: Governmental Activities | I5: Component Units
A6: ASSETS
C7: Cash and cash equivalents | H7: 16689898 | I7: 14220362
C8: Investments | H8: 117520729 | I8: 5613349
C9: Receivables, net | H9: 57370497 | I9: 14484609
C10: Due from other governments | H10: 2164467 | I10: 642973
C11: Due from primary government | I11: 866635
C12: Inventories | H12: 82196 | I12: 390937
C13: Other assets | H13: 112394 | I13: 8614948
C14: Capital assets:
D15: Land and construction in progress | H15: 28561293 | I15: 2604168
D16: Other capital assets, net of depreciation | H16: 181707632 | I16: 38525961
C18: Total Assets | H18: =SUM(H7:H16) -> 404209106 | I18: =SUM(I7:I16) -> 85963942
A20: DEFERRED OUTFLOWS OF RESOURCES
C21: Deferred loss on refunding bonds, net | I21: 167647
E23: Total assets and deferred outlfows of resources | H23: =H21+H18 -> 404209106 | I23: =I21+I18 -> 86131589
A25: LIABILITIES
C26: Accounts payable | H26: 2761704 | I26: 2888481
C27: Accrued liabilities | H27: 897757 | I27: 1186374
C28: Accrued interest payable | H28: 548514 | I28: 36663
C29: Retainage payable | H29: 779557
C30: Accrued insurance claims payable | H30: 726491 | I30: 486000
C31: Due to component units | H31: 859366
C32: Due to other governmental agencies | H32: 554985 | I32: 28025
C33: Unearned revenue | H33: 82995 | I33: 181892
C34: Noncurrent liabilities:
D35: Due within one year | H35: 2989243 | I35: 3510509
D36: Due in more than one year | H36: 40233745 | I36: 21741649
D38: Total Liabilities | H38: =SUM(H26:H36) -> 50434357 | I38: =SUM(I26:I36) -> 30059593
A40: NET ASSETS
B41: Net investment in capital assets | H41: 180201711 | I41: 27322309
B42: Restricted for:
C43: Criminal justice | H43: 14820873
C44: Health and welfare | H44: 4403804
C45: Highways, streets and drainage | H45: 29075379
C46: Building facilities | H46: 8754267
C47: Sanitation | H47: 20167034
...

Sheet Calcasieu
D1: Calcasieu Parish 2013 Statement of Net Assets
D2: Issued: December 31, 2013
H4: Primary Government
H5: Governmental Activities | I5: Business-Type Activities | J5: Total | K5: Component Unit
A6: ASSETS
B7: Current Assets
C8: Cash and cash equivalents | H8: 61403447 | I8: 286431 | J8: =SUM(H8:I8) -> 61689878 | K8: 32642434
C9: Investments | H9: 193319389 | I9: 770334 | J9: =SUM(H9:I9) -> 194089723 | K9: 42289149
C10: Receivables (net of allowance for uncollectibles) | H10: 54312100 | I10: 631792 | J10: =SUM(H10:I10) -> 54943892 | K10: 56808950
C11: Intergovernmental receivable | H11: 5763494 | I11: 21180 | J11: =SUM(H11:I11) -> 5784674 | K11: 1140772
C12: Internal balances | H12: 43458 | I12: -43458 | J12: =SUM(H12:I12) -> 0
C13: Due from component units | H13: 222898 | J13: =SUM(H13:I13) -> 222898
C14: Due from primary government | J14: =SUM(H14:I14) -> 0 | K14: 458224
C15: Loan receivable | H15: 48138 | J15: =SUM(H15:I15) -> 48138
C16: Prepaid items | H16: 220683 | I16: 33427 | J16: =SUM(H16:I16) -> 254110 | K16: 1621791
C17: Inventory | H17: 1092701 | J17: =SUM(H17:I17) -> 1092701 | K17: 1957810
C18: Other assets | I18: 320 | J18: =SUM(H18:I18) -> 320 | K18: 500683
C19: Restricted assets:
D20: Cash and cash equivalents | I20: 13717 | J20: =SUM(H20:I20) -> 13717 | K20: 5461536
D21: Investments | I21: 199758 | J21: =SUM(H21:I21) -> 199758 | K21: 6924342
D22: Receivables - net | K22: 3027184
C23: Capital assets:
D24: Non-depreciable | H24: 417714348 | I24: 946740 | J24: =SUM(H24:I24) -> 418661088 | K24: 40031303
D25: Depreciable, net | H25: 92729097 | I25: 8300519 | J25: =SUM(H25:I25) -> 101029616 | K25: 205634180
C27: Total Assets | H27: =SUM(H8:H25) -> 826869753 | I27: =SUM(I8:I25) -> 11160760 | J27: =SUM(J8:J25) -> 838030513 | K27: =SUM(K8:K25) -> 398498358
A29: DEFERRED OUTFLOWS OF RESOURCES
C30: Deferred amount on refunding | K30: 346864
A32: LIABILITIES
C33: Accounts payable and other accrued liabilities | H33: 8484448 | I33: 176343 | J33: =SUM(H33:I33) -> 8660791 | K33: 9637074
C34: Intergovernmental payable | H34: 3403953 | J34: =SUM(H34:I34) -> 3403953 | K34: 1157830
C35: Due to primary government | J35: =SUM(H35:I35) -> 0 | K35: 222898
C36: Due to component units | H36: 458224 | J36: =SUM(H36:I36) -> 458224
C37: Unearned revenue | H37: 1102114 | J37: =SUM(H37:I37) -> 1102114 | K37: 100462
C38: Liabilities payable from restricted assets | I38: 114513 | J38: =SUM(H38:I38) -> 114513 | K38: 729820
C39: Other liabilities | H39: 532001 | J39: =SUM(H39:I39) -> 532001 | K39: 391374
C40: Noncurrent liabilities:
D41: Due within one year | H41: 2847845 | I41: 40835 | J41: =SUM(H41:I41) -> 2888680 | K41: 7644678
D42: Due in more than one year | H42: 6582203 | I42: 316086 | J42: =SUM(H42:I42) -> 6898289 | K42: 45777600
D44: Total Liabilities | H44: =SUM(H33:H42) -> 23410788 | I44: =SUM(I33:I42) -> 647777 | J44: =SUM(J33:J42) -> 24058565 | K44: =SUM(K33:K42) -> 65661736
A46: DEFERRED INFLOWS OF RESOURCES
...

Sheet Caldwell
C1: Caldwell Parish 2013 Statement of Net Assets
C2: Issued: December 31, 2013
G4: Governmental Activities
A5: ASSETS
B6: Cash and cash equivalents | G6: 6482087
B7: Receivables | G7: 1978585
B8: Capital assets, net of accumulated depreciation | G8: 11719166
B10: Total Assets | G10: =SUM(G6:G8) -> 20179838
A12: LIABILITIES
B13: Accounts, salaries, and other payables | G13: 152562
B14: Due to other agencies | G14: 57698
B15: Compensated absences payable | G15: 119478
C17: Total Liabilities | G17: =SUM(G13:G15) -> 329738
A19: NET ASSETS
B20: Net investment in capital assets | G20: 11719166
B21: Restricted | G21: 5837212
B22: Unrestricted | G22: 2293722
B24: Total Net Assets | G24: =SUM(G20:G22) -> 19850100
B26: Total Liabilities and Net Assets | G26: =SUM(G17+G24) -> 20179838

Sheet Cameron
C1: Cameron Parish 2013 Statement of Net Assets
C2: Issued: December 31, 2013
G4: Governmental Activities
A5: ASSETS
B6: Cash | G6: 28095654
B7: Receivables, net | G7: 19930829
B8: Inventory, at cost | G8: 1839555
B9: Other | G9: 85154
B10: Capital assets, net of accumulated depreciation | G10: 111753810
B12: Total Assets | G12: =SUM(G6:G10) -> 161705002
A14: LIABILITIES
B15: Accounts, salaries, and other payables | G15: 4610520
B16: Due to other agencies | G16: 3695066
B17: Unearned revenue | G17: 17231
B18: Interest payable | G18: 104867
B19: Long-term liabilities:
C20: Due within one year | G20: 1892917
C21: Due after one year | G21: 5190396
C23: Total Liabilities | G23: =SUM(G15:G21) -> 15510997
A25: NET ASSETS
B26: Invested in capital assets, net of related debt | G26: 104565630
B27: Net position - restricted for:
C28: Judicial | G28: 6377
C29: Debt service | G29: 1468574
C30: Tourism development | G30: 35404
C31: Inventories | G31: 1839555
C32: Prepaid expenses | G32: 64152
B33: Net position - unrestricted | G33: 38214313
B35: Total Net Assets | G35: =SUM(G26:G33) -> 146194005
B37: Total Liabilities and Net Assets | G37: =SUM(G23+G35) -> 161705002

Sheet Catahoula
D1: Catahoula Parish 2013 Statement of Net Assets
D2: Issued: December 31, 2013
H4: Primary Government
H5: Governmental Activities | I5: Component Units
A6: ASSETS
C7: Cash and cash equivalents | H7: 1908979 | I7: 131356
C8: Cash restricted for debt service | H8: 26325
C9: Receivables | H9: 1411486 | I9: 14280
C10: Other assets | H10: 81766
C11: Capital assets, net of accumulated depreciation | H11: 5862816 | I11: 88616
C13: Total Assets | H13: =SUM(H7:H11) -> 9291372 | I13: =SUM(I7:I11) -> 234252
A15: LIABILITIES
C16: Accounts, salaries, and other payables | H16: 551794 | I16: 490
C17: Compensated absences | H17: 27615
C18: Certificates of indebtedness due within one year | H18: 120000
C19: Certificates of indebtedness due in more than one | H19: 51000
D21: Total Liabilities | H21: =SUM(H16:H19) -> 750409 | I21: =SUM(I16:I19) -> 490
A23: DEFERRED INFLOWS
C24: Grant revenues pending | H24: 14777
A26: NET ASSETS
B27: Net investment in capital assets | H27: 5862816 | I27: 88616
B28: Unrestricted net position | H28: 2663370 | I28: 145146
C30: Total Net Assets | H30: =SUM(H27:H28) -> 8526186 | I30: =SUM(I27:I28) -> 233762
C32: Total Liabilities and Net Assets | H32: =SUM(H21+H30+H24) -> 9291372 | I32: =SUM(I30+I21) -> 234252

Sheet Claiborne
C1: Claiborne Parish 2013 Statement of Net Assets
C2: Issued: December 31, 2013
G4: Governmental Activities
A5: ASSETS
B6: Cash and cash equivalents | G6: 7547110
B7: Investments | G7: 28082
B8: Receivables | G8: 3215328
B9: Deferred charges | G9: 113163
B10: Capital assets, net of accumulated depreciation | G10: 7059807
B12: Total Assets | G12: =SUM(G6:G10) -> 17963490
A14: LIABILITIES
B15: Accounts, salaries, and other payables | G15: 643570
B16: Due to other agencies | G16: 16368
B17: Deferred revenue | G17: 15626
B18: Compensated absences payable | G18: 50773
B19: Bonds payable within one year | G19: 155000
B20: Bonds payable in more than one year | G20: 1700000
C22: Total Liabilities | G22: =SUM(G15:G20) -> 2581337
A24: NET ASSETS
B25: Net investment in capital assets | G25: 5048392
B26: Restricted for:
C27: General government | G27: 804147
C28: General government - judicial | G28: 1473326
C29: Public works | G29: 876596
C30: Public safety | G30: 256431
C31: Health and welfare | G31: 253852
C32: Culture and recreation | G32: 995881
B33: Unrestricted | G33: 5673528
B35: Total Net Assets | G35: =SUM(G25:G33) -> 15382153
B37: Total Liabilities and Net Assets | G37: =SUM(G22+G35) -> 17963490

Sheet Concordia
C1: Concordia Parish 2013 Statement of Net Assets
C2: Issued: December 31, 2013
G4: Governmental Activities
A5: ASSETS
B6: Cash | G6: 5653482
B7: Cash - restricted | G7: 2396243
B8: Receivables | G8: 2125063
B9: Accrued interest | G9: 2658
B10: Capital assets (net) | G10: 10920531
B12: Total Assets | G12: =SUM(G6:G10) -> 21097977
A14: LIABILITIES
B15: Current liabilities:
C16: Accounts payable | G16: 102093
C17: Interest payable | G17: 277708
C18: Long-term liabilities due in one year | G18: 395818
B19: Noncurrent liabilities:
C20: Long-term liabilities due in more than one year | G20: 9404258
C22: Total Liabilities | G22: =SUM(G15:G20) -> 10179877
A24: NET ASSETS
B25: Invested in capital assets, net of related debt | G25: 1120455
B26: Restricted for:
C27: Debt service | G27: 2396243
C28: Special revenue projects | G28: 4394633
B29: Unrestricted | G29: 3006769
B31: Total Net Assets | G31: =SUM(G25:G29) -> 10918100
B33: Total Liabilities and Net Assets | G33: =SUM(G22+G31) -> 21097977

Sheet DeSoto
D1: DeSoto Parish 2013 Statement of Net Assets
D2: Issued: December 31, 2013
H4: Primary Government
H5: Governmental Activities | I5: Business-Type Activities | J5: Total
A6: ASSETS
C7: Cash and cash equivalents | H7: 9790825 | I7: 265 | J7: =SUM(H7:I7) -> 9791090
C8: Investments | H8: 19901346 | J8: =SUM(H8:I8) -> 19901346
C9: Receivables (net of allowance for uncollectibles) | H9: 13582980 | I9: 4072 | J9: =SUM(H9:I9) -> 13587052
C10: Due from other governments | H10: 2650 | J10: =SUM(H10:I10) -> 2650
C11: Inventory | H11: 40185 | J11: =SUM(H11:I11) -> 40185
C12: Capital assets, net | H12: 75371606 | I12: 10175 | J12: =SUM(H12:I12) -> 75381781
C14: Total Assets | H14: =SUM(H7:H12) -> 118689592 | I14: =SUM(I7:I12) -> 14512 | J14: =SUM(J7:J12) -> 118704104
A16: LIABILITIES
C17: Accounts payable | H17: 1173758 | I17: 2331 | J17: =SUM(H17:I17) -> 1176089
C18: Deposit balances | H18: 1100 | I18: 270 | J18: =SUM(H18:I18) -> 1370
C19: Advance from grantors | H19: 67825 | J19: =SUM(H19:I19) -> 67825
C20: Due to other governments | H20: 260166 | J20: =SUM(H20:I20) -> 260166
C21: Landfill post closure liability | H21: 2165606 | J21: =SUM(H21:I21) -> 2165606
C22: Compensated absences | H22: 284258 | J22: =SUM(H22:I22) -> 284258
C23: Other postemployment benefit obligation | H23: 2466192 | J23: =SUM(H23:I23) -> 2466192
C24: Long-term liabilities:
D25: Due within one year | H25: 5641 | J25: =SUM(H25:I25) -> 5641
D26: Due in more than one year | H26: 5280 | J26: =SUM(H26:I26) -> 5280
D28: Total Liabilities | H28: =SUM(H17:H26) -> 6429826 | I28: =SUM(I17:I26) -> 2601 | J28: =SUM(J17:J26) -> 6432427
A30: NET ASSETS
B31: Net investment in capital assets | H31: 75360685 | I31: 10175 | J31: =SUM(H31:I31) -> 75370860
B32: Restricted for:
C33: Airport | H33: 7402456 | J33: =SUM(H33:I33) -> 7402456
C34: District court | H34: 98450 | J34: =SUM(H34:I34) -> 98450
C35: Public safety | H35: 4730847 | J35: =SUM(H35:I35) -> 4730847
C36: Roads | H36: 4233180 | J36: =SUM(H36) -> 4233180
C37: Sanitation | H37: 12418900 | J37: =SUM(H37) -> 12418900
C38: Health and welfare | H38: 6995 | J38: =SUM(H38) -> 6995
C39: Witness and juror fees | H39: 394991 | J39: =SUM(H39:I39) -> 394991
B40: Unrestricted | H40: 7613262 | I40: 1736 | J40: =SUM(H40:I40) -> 7614998
C42: Total Net Assets | H42: =SUM(H31:H40) -> 112259766 | I42: =SUM(I31:I40) -> 11911 | J42: =SUM(J31:J40) -> 112271677
C44: Total Liabilities and Net Assets | H44: =SUM(H42+H28) -> 118689592 | I44: =SUM(I42+I28) -> 14512 | J44: =SUM(J42+J28) -> 118704104

Sheet East Baton Rouge
D1: East Baton Rouge Parish 2013 Statement of Net Assets
D2: Issued: December 31, 2013
H4: Primary Government
H5: Governmental Activities | I5: Business-Type Activities | J5: Total | K5: Component Unit
A6: ASSETS
B7: Current Assets
C8: Cash and cash equivalents (note 3) | H8: 201411313 | I8: 117820392 | J8: =SUM(H8:I8) -> 319231705 | K8: 25523322
C9: Investments (note 3) | H9: 180338007 | I9: 121601048 | J9: =SUM(H9:I9) -> 301939055
C10: Receivables--net (note 13) | H10: 51943230 | I10: 16302378 | J10: =SUM(H10:I10) -> 68245608 | K10: 15586464
C11: Due from other governments (note 11) | H11: 83097626 | I11: 5285858 | J11: =SUM(H11:I11) -> 88383484 | K11: 1552267
C12: Prepaid items | H12: 767695 | I12: 209424 | J12: =SUM(H12:I12) -> 977119 | K12: 531507
C13: Loans receivable | H13: 3530623 | J13: =SUM(H13:I13) -> 3530623 | K13: 1243278
C14: Inventory | H14: 846296 | I14: 51347 | J14: =SUM(H14:I14) -> 897643 | K14: 3020853
C15: Net pension asset | K15: 1590755
C16: Other assets | K16: 599504
C17: Restricted assets:
D18: Cash and cash equivalents (note 3) | I18: 171497464 | J18: =SUM(H18:I18) -> 171497464 | K18: 12012409
D19: Investments (note 3) | I19: 215767910 | J19: =SUM(H19:I19) -> 215767910
D20: Receivables--net (note 13) | I20: 328901 | J20: =SUM(H20:I20) -> 328901
D21: Prepaid items | I21: 434949 | J21: =SUM(H21:I21) -> 434949
C22: Investment in joint venture (note 19) | I22: 1973958 | J22: =SUM(H22:I22) -> 1973958
C23: Capital assets:
D24: Non-depreciable | H24: 193385057 | I24: 254999935 | J24: =SUM(H24:I24) -> 448384992
D25: Depreciable, net | H25: 666566380 | I25: 1405099819 | J25: =SUM(H25:I25) -> 2071666199 | K25: 110619580
C27: Total Assets | H27: =SUM(H8:H25) -> 1381886227 | I27: =SUM(I8:I25) -> 2311373383 | J27: =SUM(J8:J25) -> 3693259610 | K27: =SUM(K8:K25) -> 172279939
A29: Deferred Outflows of Resources
B30: Deferred amount on refunding | H30: 6298894 | I30: 3831563 | J30: =SUM(H30:I30) -> 10130457 | K30: 0
B31: Deferred outflows on derivative instruments | H31: 10609916 | I31: 41015560 | J31: =SUM(H31:I31) -> 51625476 | K31: 0
C33: Total deferred outflows of resources | H33: =SUM(H30:H31) -> 16908810 | I33: =SUM(I30:I31) -> 44847123 | J33: =SUM(J30:J31) -> 61755933 | K33: =SUM(K30:K31) -> 0
A35: LIABILITIES
C36: Accounts payable and other current liabilities | H36: 37439384 | I36: 50703777 | J36: =SUM(H36:I36) -> 88143161 | K36: 1930897
C37: Due to other governments | H37: 7390530 | J37: =SUM(H37:I37) -> 7390530 | K37: 375598
C38: Accrued payables | H38: 15541911 | I38: 26034074 | J38: =SUM(H38:I38) -> 41575985 | K38: 1345157
C39: Unearned revenue | H39: 1709094 | I39: 1224069 | J39: =SUM(H39:I39) -> 2933163
C40: Deposits and escrow accounts | H40: 22503554 | J40: 22503554
C41: Other liabilities | K41: 420865
C42: Noncurrent liabilities (note 10): | J42: =SUM(H42:I42) -> 0
D43: Due within one year | H43: 33495310 | I43: 18764052 | J43: =SUM(H43:I43) -> 52259362 | K43: 3270518
D44: Due in more than one year | H44: 665555682 | I44: 1333967445 | J44: =SUM(H44:I44) -> 1999523127 | K44: 117232768
D46: Total Liabilities | H46: =SUM(H36:H44) -> 783635465 | I46: =SUM(I36:I44) -> 1430693417 | J46: =SUM(J36:J44) -> 2214328882 | K46: =SUM(K36:K44) -> 124575803
...

Sheet East Carroll
D1: East Carroll Parish 2013 Statement of Net Assets
D2: Issued: December 31, 2013
H4: Primary Government
H5: Governmental Activities | I5: Business-Type Activities | J5: Total
A6: ASSETS
C7: Cash and cash equivalents | H7: 2754931 | I7: 15702 | J7: =SUM(H7:I7) -> 2770633
C8: Investments | H8: 836856 | J8: =SUM(H8:I8) -> 836856
C9: Receivables | H9: 2244765 | J9: =SUM(H9:I9) -> 2244765
C10: Prepaid items | I10: 3090 | J10: =SUM(H10:I10) -> 3090
C11: Cash and cash equivalents - restricted | I11: 15218 | J11: =SUM(H11:I11) -> 15218
C12: Capital assets not being depreciated | H12: 637429 | J12: =SUM(H12:I12) -> 637429
C13: Capital assets, net of accumulated depreciation | H13: 4917326 | J13: =SUM(H13:I13) -> 4917326
C15: Total Assets | H15: =SUM(H7:H13) -> 11391307 | I15: =SUM(I7:I13) -> 34010 | J15: =SUM(J7:J13) -> 11425317
A17: LIABILITIES
C18: Accounts payable | H18: 218903 | I18: 5776 | J18: =SUM(H18:I18) -> 224679
C19: Interest payable | H19: 5987 | J19: =SUM(H19:I19) -> 5987
C20: Unearned revenue | I20: 151 | J20: =SUM(H20:I20) -> 151
C21: Long-term liabilities:
D22: Due within one year | H22: 120776 | I22: 744 | J22: =SUM(H22:I22) -> 121520
D23: Due in more than one year | H23: 423316 | J23: =SUM(H23:I23) -> 423316
D25: Total Liabilities | H25: =SUM(H18:H23) -> 768982 | I25: =SUM(I18:I23) -> 6671 | J25: =SUM(J18:J23) -> 775653
A27: NET ASSETS
B28: Net investment in capital assets | H28: 5017234 | J28: =SUM(H28:I28) -> 5017234
B29: Restricted for:
C30: Debt service | H30: 96497 | J30: =SUM(H30:I30) -> 96497
C31: Road maintenance | H31: 1440460 | J31: =SUM(H31:I31) -> 1440460
C32: Garbage | H32: 791427 | J32: =SUM(H32:I32) -> 791427
C33: Library | H33: 590967 | J33: =SUM(H33:I33) -> 590967
C34: Drainage | H34: 795219 | J34: =SUM(H34:I34) -> 795219
C35: Airport hangar | H35: 3057 | J35: =SUM(H35:I35) -> 3057
C36: Rural fire protection | H36: 380303 | J36: =SUM(H36:I36) -> 380303
C37: LSU/SU Extension | H37: 181990 | J37: =SUM(H37:I37) -> 181990
C38: Health unit | H38: 512372 | J38: =SUM(H38:I38) -> 512372
C39: Housing assistance payments | I39: 15218 | J39: =SUM(H39:I39) -> 15218
B40: Unrestricted | H40: 812799 | I40: 12121 | J40: =SUM(H40:I40) -> 824920
C42: Total Net Assets | H42: =SUM(H28:H40) -> 10622325 | I42: =SUM(I28:I40) -> 27339 | J42: =SUM(J28:J40) -> 10649664
C44: Total Liabilities and Net Assets | H44: =SUM(H42+H25) -> 11391307 | I44: =SUM(I42+I25) -> 34010 | J44: =SUM(J42+J25) -> 11425317

Sheet East Feliciana
C1: East Feliciana Parish 2013 Statement of Net Assets
C2: Issued: December 31, 2013
G4: Governmental Activities
A5: ASSETS
B6: Cash and cash equivalents | G6: 5513411.8
B7: Receivables, net | G7: 838202.1
B8: Due from other funds | G8: 1597760
B9: Due from other governmental agencies | G9: 122932.96
B10: Capital assets, net | G10: 8313076.6
B12: Total Assets | G12: =SUM(G6:G10) -> 16385383
A14: LIABILITIES
B15: Accounts payable | G15: 235942.02
B16: Due to other funds | G16: 1452400.9
B17: Due to other governmental agencies | G17: 12350.44
B18: Notes payable | G18: 16548.42
B19: Compensated absences | G19: 13428
C21: Total Liabilities | G21: =SUM(G15:G19) -> 1730669.8
A23: NET ASSETS
B24: Net investment in capital assets | G24: 8313076.6
B25: Restricted for:
C26: Health unit operations/maintenance | G26: 532497.89
C27: Homeland security | G27: 49454.42
C28: Solid waste management | G28: 3333393
B29: Unrestricted | G29: 2426291.7
B31: Total Net Assets | G31: =SUM(G24:G29) -> 14654714
B33: Total Liabilities and Net Assets | G33: =G31+G21 -> 16385383

Sheet Evangeline
D1: Evangeline Parish 2013 Statement of Net Assets
D2: Issued: December 31, 2013
H4: Primary Government | K4: Component Unit
H5: Governmental Activities | I5: Business-Type Activities | J5: Total | K5: Criminal Court Fund
A6: ASSETS
C7: Cash and interest-bearing deposits | H7: 9772120 | I7: 100123 | J7: =SUM(H7:I7) -> 9872243
C8: Receivables, net | H8: 5534711 | I8: 14143 | J8: =SUM(H8:I8) -> 5548854 | K8: 84972
C9: Due from other governmental units | H9: 372502 | J9: =SUM(H9:I9) -> 372502 | K9: 6141
C10: Other assets | H10: 20960 | J10: =SUM(H10:I10) -> 20960
C11: Restricted assets:
D12: Cash and interest-bearing deposits | I12: 20831 | J12: =SUM(I12) -> 20831
D13: Investments | H13: 28970121 | J13: =SUM(H13:I13) -> 28970121
C14: Capital assets, net | H14: 24663497 | I14: 291100 | J14: =SUM(H14:I14) -> 24954597
C16: Total Assets | H16: =SUM(H7:H14) -> 69333911 | I16: =SUM(I7:I14) -> 426197 | J16: =SUM(J7:J14) -> 69760108 | K16: =SUM(K7:K14) -> 91113
A18: LIABILITIES
C19: Cash overdraft | H19: 44286 | J19: =SUM(H19:I19) -> 44286 | K19: 112041
C20: Accounts and other payables | H20: 453124 | I20: 1476 | J20: =SUM(H20:I20) -> 454600 | K20: 1159
C21: Accrued interest | H21: 94056 | J21: =SUM(H21:I21) -> 94056
C22: Performance bonds payable | H22: 300318 | J22: =SUM(H22:I22) -> 300318
C23: Unearned revenue | H23: 69456 | I23: 1175 | J23: =SUM(H23:I23) -> 70631
C24: Noncurrent liabilities:
D25: Portion due within one year:
E26: Compensated absences payable | H26: 8669 | J26: =SUM(H26:I26) -> 8669
E27: Capital lease payable | H27: 27459 | J27: =SUM(H27:I27) -> 27459
E28: Bonds and certificates payable | H28: 222000 | I28: 1819 | J28: =SUM(H28:I28) -> 223819
D29: Portion due after one year:
E30: Sewer deposits payable | H30: 10182 | I30: 11191 | J30: =SUM(H30:I30) -> 21373
E31: Compensated absences payable | H31: 52810 | J31: =SUM(H31:I31) -> 52810
E32: Capital lease payable | H32: 2338 | J32: =SUM(H32:I32) -> 2338
E33: Bonds and certificates payable | H33: 31902009 | I33: 59732 | J33: =SUM(H33:I33) -> 31961741
D35: Total Liabilities | H35: =SUM(H19:H33) -> 33186707 | I35: =SUM(I19:I33) -> 75393 | J35: =SUM(J19:J33) -> 33262100 | K35: =SUM(K19:K33) -> 113200
A37: DEFERRED INFLOWS OF RESOURCES
C38: Unearned rent | H38: 271333 | J38: =SUM(H38:I38) -> 271333
A40: NET ASSETS
B41: Net investment in capital assets | H41: 22524204 | I41: 231368 | J41: =SUM(H41:I41) -> 22755572
B42: Restricted for debt service | H42: 3177 | I42: 7821 | J42: =SUM(H42:I42) -> 10998
B43: Restricted for housing purposes | I43: 9853 | J43: =SUM(H43:I43) -> 9853
B44: Unrestricted (deficit) | H44: 13348490 | I44: 101762 | J44: =SUM(H44:I44) -> 13450252 | K44: -22086
C46: Total Net Assets | H46: =SUM(H41:H44) -> 35875871 | I46: =SUM(I41:I44) -> 350804 | J46: =SUM(J41:J44) -> 36226675 | K46: =SUM(K40:K44) -> -22086
C48: Total Liabilities and Net Assets | H48: =SUM(H46+H35+H38) -> 69333911 | I48: =SUM(I46+I35+I38) -> 426197 | J48: =SUM(J46+J35+J38) -> 69760108 | K48: =SUM(K46+K35+K38) -> 91114

Sheet Franklin
C1: Franklin Parish 2013 Statement of Net Assets
C2: Issued: December 31, 2013
G4: Governmental Activities
A5: ASSETS
B6: Cash and cash equivalents | G6: 7269664
B7: Receivables | G7: 3659846
B8: Prepaid assets | G8: 4140
B9: Capital assets (net) | G9: 17836416
B11: Total Assets | G11: =SUM(G6:G9) -> 28770066
A13: LIABILITIES
B14: Accounts payable | G14: 382154
B15: Payroll withholding payable | G15: 66963
B16: Compensated absences payable | G16: 131420
B17: Capital leases payable | G17: 49970
B18: Due to others (damage deposit) | G18: 20000
B19: Net OPEB obligation | G19: 1337359
C21: Total Liabilities | G21: =SUM(G14:G19) -> 1987866
A23: NET ASSETS
B24: Invested in capital assets, net of related debt | G24: 17786447
B25: Unrestricted | G25: 8995753
B27: Total Net Assets | G27: =SUM(G24:G25) -> 26782200
B29: Total Liabilities and Net Assets | G29: =SUM(G21+G27) -> 28770066

Sheet Grant
D1: Grant Parish 2013 Statement of Net Assets
D2: Issued: December 31, 2013
H4: Primary Government
H5: Governmental Activities | I5: Business-Type Activities | J5: Total
A6: ASSETS
C7: Cash and cash equivalents | H7: 1681553 | I7: 363999 | J7: =SUM(H7:I7) -> 2045552
C8: Receivables (net) | H8: 1486129 | I8: 105407 | J8: =SUM(H8:I8) -> 1591536
C9: Capital assets:
D10: Non depreciable capital assets
E11: Construction in progress | H11: 37900 | J11: =SUM(H11:I11) -> 37900
E12: Land | H12: 203250 | J12: =SUM(H12:I12) -> 203250
D13: Depreciable capital assets, net | H13: 5842328 | I13: 357194 | J13: =SUM(H13:I13) -> 6199522
C15: Total Assets | H15: =SUM(H7:H13) -> 9251160 | I15: =SUM(I7:I13) -> 826600 | J15: =SUM(J7:J13) -> 10077760
A17: LIABILITIES
C18: Accounts and other payables | H18: 379081 | I18: 33092 | J18: =SUM(H18:I18) -> 412173
C19: Deposits due others | I19: 76433 | J19: =SUM(H19:I19) -> 76433
C20: Unearned revenues | H20: 2266 | J20: =SUM(H20:I20) -> 2266
C21: Long-term liabilities:
D22: Compensated absences | H22: 42221 | I22: 9025 | J22: =SUM(H22:I22) -> 51246
D23: Notes payable:
E24: Due within one year | H24: 92877 | J24: =SUM(H24:I24) -> 92877
E25: Due in more than one year | H25: 339716 | J25: =SUM(H25:I25) -> 339716
D27: Total Liabilities | H27: =SUM(H18:H25) -> 856161 | I27: =SUM(I18:I25) -> 118550 | J27: =SUM(J18:J25) -> 974711
A29: NET ASSETS
B30: Invested in capital assets, net of related debt | H30: 5650885 | I30: 357194 | J30: =SUM(H30:I30) -> 6008079
B31: Restricted:
C32: Maintenance | H32: 1893524 | J32: =SUM(H32:I32) -> 1893524
C33: Judicial | H33: 24781 | J33: =SUM(H33:I33) -> 24781
C34: Construction | H34: 51625 | J34: =SUM(H34:I34) -> 51625
B35: Unrestricted | H35: 774184 | I35: 350856 | J35: =SUM(H35:I35) -> 1125040
C37: Total Net Assets | H37: =SUM(H30:H35) -> 8394999 | I37: =SUM(I30:I35) -> 708050 | J37: =SUM(J30:J35) -> 9103049
C39: Total Liabilities and Net Assets | H39: =SUM(H37+H27) -> 9251160 | I39: =SUM(I37+I27) -> 826600 | J39: =SUM(J37+J27) -> 10077760

Sheet Iberia
D1: Iberia Parish 2013 Statement of Net Assets
D2: Issued: December 31, 2013
H4: Primary Government
H5: Governmental Activities | I5: Component Units
A6: ASSETS
C7: Cash and interest-bearing deposits | H7: 39934830 | I7: 39091186
C8: Investments | H8: 83378
C9: Receivables, net | H9: 8030264 | I9: 10729454
C10: Advance to component unit | H10: 1416411
C11: Due from other governmental agencies | H11: 5793561 | I11: 925334
C12: Due from primary government | I12: 627437
C13: Inventories | I13: 1951088
C14: Prepaid items | I14: 667027
C15: Investments in joint ventures | I15: 375146
C16: Restricted assets | I16: 3633711
C17: Capital assets:
D18: Non-depreciable | H18: 5456279 | I18: 13538519
D19: Depreciable, net | H19: 90480984 | I19: 60219171
C21: Total Assets | H21: =SUM(H7:H19) -> 151195707 | I21: =SUM(I7:I19) -> 131758073
A23: LIABILITIES
C24: Accounts payable | H24: 1802114 | I24: 3237190
C25: Accrued expenses | H25: 181539 | I25: 6909924
C26: Contracts and retainage payable | H26: 604712 | I26: 732472
C27: Due to other governmental agencies | H27: 337184 | I27: 91132
C28: Due to component unit | H28: 627437
C29: Advance from primary government | I29: 1416411
C30: Advances from grantors and others | H30: 171235 | I30: 110549
C31: Deposits | I31: 270125
C32: Accrued interest payable | H32: 42018 | I32: 126013
C33: Long-term liabilities:
D34: Other post employment benefits payable | H34: 3453813 | I34: 1514778
D35: Due within one year | H35: 1464872 | I35: 3107445
D36: Due in more than one year | H36: 9078674 | I36: 32542923
D38: Total Liabilities | H38: =SUM(H24:H36) -> 17763598 | I38: =SUM(I24:I36) -> 50058962
A40: NET ASSETS
B41: Net investment in capital assets | H41: 86345332 | I41: 52359053
B42: Restricted | H42: 564816 | I42: 12300232
B43: Unrestricted | H43: 46521961 | I43: 17039826
C45: Total Net Assets | H45: =SUM(H41:H43) -> 133432109 | I45: =SUM(I41:I43) -> 81699111
C47: Total Liabilities and Net Assets | H47: =SUM(H38+H45) -> 151195707 | I47: =SUM(I45+I38) -> 131758073

Sheet Iberville
D1: Iberville Parish 2013 Statement of Net Assets
D2: Issued: December 31, 2013
H4: Primary Government | K4: Total Component Units
H5: Governmental Activities | I5: Business-Type Activities | J5: Total | K5: Governmental Activities | L5: Business-type Activities
A6: ASSETS
B7: Current Assets
C8: Cash and cash equivalents | H8: 16410571 | I8: 1795376 | J8: =SUM(H8:I8) -> 18205947 | K8: 1177559 | L8: 712715
C9: Receivables (net of allowance for uncollectibles) | H9: 9074534 | I9: 995840 | J9: =SUM(H9:I9) -> 10070374 | K9: 3439297 | L9: 202002
C10: Inventories | I10: 132465 | J10: =SUM(H10:I10) -> 132465
C11: Prepaid items | H11: 870703 | J11: =SUM(H11:I11) -> 870703 | L11: 14931
C12: Other assets | H12: 100000 | I12: 348456 | J12: =SUM(H12:I12) -> 448456 | K12: 103972 | L12: 260524
C13: Restricted assets
D14: Cash and cash equivalents | I14: 882151 | J14: =SUM(H14:I14) -> 882151 | L14: 767572
C15: Capital assets (net of accumulated depreciation)
D16: Land | H16: 2975825 | I16: 193511 | J16: =SUM(H16:I16) -> 3169336 | K16: 435740
D17: Building and system | H17: 31725027 | I17: 10071429 | J17: =SUM(H17:I17) -> 41796456 | K17: 999067 | L17: 3405591
D18: Improvemetns other than building | H18: 55243002 | J18: =SUM(H18:I18) -> 55243002 | K18: 331118 | L18: 1757047
D19: Machinery and equipment | H19: 4023678 | I19: 154513 | J19: =SUM(H19:I19) -> 4178191 | K19: 368125 | L19: 1277720
D20: Construction in progress | H20: 6218861 | I20: 156733 | J20: =SUM(H20:I20) -> 6375594
C22: Total Assets | H22: =SUM(H8:H20) -> 126642201 | I22: =SUM(I8:I20) -> 14730474 | J22: =SUM(J8:J20) -> 141372675 | K22: =SUM(K8:K20) -> 6854878 | L22: =SUM(L8:L20) -> 8398102
A24: LIABILITIES
C25: Accounts payable and other current liabilities | H25: 2043820 | I25: 520051 | J25: =SUM(H25:I25) -> 2563871 | K25: 28218 | L25: 74793
C26: Matured bonds and interest payable | J26: =SUM(H26:I26) -> 0
C27: Accrued interest payable | J27: =SUM(H27:I27) -> 0
C28: Bank overdraft liability | J28: =SUM(H28:I28) -> 0
C29: Other payables | H29: 795376 | J29: =SUM(H29:I29) -> 795376 | K29: 159045
C30: Liabilities payable from restricted assets | I30: 279573 | J30: =SUM(H30:I30) -> 279573 | L30: 122661
C31: Noncurrent liabilities:
D32: Other post employment benefits | H32: 485401 | J32: =SUM(H32:I32) -> 485401 | K32: 69779
D33: Due in one year | H33: 1091504 | I33: 55000 | J33: =SUM(H33:I33) -> 1146504 | K33: 9000 | L33: 73441
D34: Due in more than one year | H34: 17258488 | I34: 545000 | J34: =SUM(H34:I34) -> 17803488 | K34: 320458 | L34: 3337547
D36: Total Liabilities | H36: =SUM(H25:H34) -> 21674589 | I36: =SUM(I25:I34) -> 1399624 | J36: =SUM(J25:J34) -> 23074213 | K36: =SUM(K25:K34) -> 586500 | L36: =SUM(L25:L34) -> 3608442
A38: Deferred Inflows (Outflows)
B39: Prepaid rental fees | H39: 0 | I39: 0 | J39: 0 | K39: 12809 | L39: 0
D41: Total deferred inflows (outflows) | H41: 0 | I41: 0 | J41: 0 | K41: 12809 | L41: 0
A43: NET ASSETS
B44: Invested in capital assets, net of related debt | H44: 84078829 | I44: 10031185 | J44: =SUM(H44:I44) -> 94110014 | K44: 2066050 | L44: 3064555
B45: Restricted for:
C46: Public building maintenance | H46: 1087400 | J46: =SUM(H46:I46) -> 1087400
C47: Drainage | H47: 2465926 | J47: =SUM(H47:I47) -> 2465926
...

Sheet Jackson
C1: Jackson Parish 2013 Statement of Net Assets
C2: Issued: December 31, 2013
G4: Governmental Activities
A5: ASSETS
B6: Cash and cash equivalents | G6: 9622291
B7: Receivables | G7: 4755981
B8: Prepaid items | G8: 70256
B9: Capital assets:
C10: Land and construction in progress | G10: 1117140
C11: Capital assets, net of depreciation | G11: 15282488
B13: Total Assets | G13: =SUM(G6:G11) -> 30848156
A15: LIABILITIES
B16: Accounts, salaries, and other payables | G16: 342065
B17: Security deposits | G17: 31249
B18: Long-term liabilities:
C19: Due within one year | G19: 139468
C20: Due in more than one year | G20: 443412
C22: Total Liabilities | G22: =SUM(G16:G20) -> 956194
A24: NET ASSETS
B25: Net investment in capital assets | G25: 16399628
B26: Restricted for:
C27: Road maintenance (Road, Sales tax and asphalt funds) | G27: 4726132
C28: Waste management | G28: 1518466
C29: Library | G29: 3226859
C30: Health unit | G30: 152363
C31: Tourism | G31: 45549
C32: Landfill closure | G32: 547090
C33: Industrial district | G33: 252644
C34: Grant funds | G34: 19871
C35: Grand jury and witness fees | G35: 13023
B36: Unrestricted | G36: 2990337
B38: Total Net Assets | G38: =SUM(G25:G36) -> 29891962
B40: Total Liabilities and Net Assets | G40: =SUM(G22+G38) -> 30848156

Sheet Jefferson Davis
C1: Jefferson Davis Parish 2013 Statement of Net Assets
C2: Issued: December 31, 2013
G4: Governmental Activities
A5: ASSETS
B6: Cash and cash equivalents | G6: 17705770
B7: Investments | G7: 2101032
B8: Receivables | G8: 799744
B9: Prepaid items | G9: 68433
B10: Restricted cash and cash equivalents | G10: 2695412
B11: Capital assets (net) | G11: 33564914
B13: Total Assets | G13: =SUM(G6:G11) -> 56935305
A15: DEFERRED OUTFLOWS OF RESOURCES
B16: Deferred bond issuance costs | G16: 84323
A18: LIABILITIES
B19: Accounts, salaries, and other payables | G19: 827133
B20: Contracts payable | G20: 31096
B21: Deposits due others | G21: 368500
B22: Other liabilities | G22: 140
B23: Accrued interest payable | G23: 301928
B24: Liability for other post-employment benefits | G24: 1732554
B25: Current portion of bonds payable | G25: 1000000
B26: Current portion of capital leases payable | G26: 112761
B27: Capital leases payable | G27: 645690
B28: Bonds payable | G28: 15670000
C30: Total Liabilities | G30: =SUM(G19:G28) -> 20689802
A32: DEFERRED INFLOWS OF RESOURCES
B33: Deferred revenues | G33: 46979
A35: NET ASSETS
B36: Net investment in capital assets | G36: 15843535
B37: Restricted for:
C38: Public safety | G38: 3901978
C39: Public works | G39: 7087706
C40: Health and welfare | G40: 366708
C41: Debt service | G41: 2652177
C42: Capital projects | G42: 2477
C43: Other general government | G43: 1251900
B44: Unrestricted | G44: 5176366
B46: Total Net Assets | G46: =SUM(G36:G44) -> 36282847
B48: Total Liabilities and Net Assets | G48: =SUM(G30+G46+G33) -> 57019628

Sheet Jefferson
D1: Jefferson Parish 2013 Statement of Net Assets
D2: Issued: December 31, 2013
G3: (amounts in thousands)
H5: Primary Government
H6: Governmental Activities | I6: Business-Type Activities | J6: Total | K6: Component Unit
A7: ASSETS
B8: Current Assets
C9: Cash and cash equivalents | H9: 18642000 | I9: 4829000 | J9: =SUM(H9:I9) -> 23471000 | K9: 26503000
C10: Investments | H10: 75588000 | J10: =SUM(H10:I10) -> 75588000 | K10: 87829000
C11: Share of pooled assets | H11: 470672000 | I11: 20780000 | J11: =SUM(H11:I11) -> 491452000
C12: Receivables, net of allowances for
D13: estimated uncollectibles:
D14: Interest | H14: 107000 | J14: =SUM(H14:I14) -> 107000 | K14: 298000
D15: Ad valorem tax | H15: 176257000 | I15: 9065000 | J15: =SUM(H15:I15) -> 185322000
D16: Accounts | H16: 5215000 | I16: 6071000 | J16: =SUM(H16:I16) -> 11286000 | K16: 82451000
D17: Notes | K17: 6587000
D18: Mortgage loans
D19: Intergovernmental | H19: 65745000 | I19: 28000 | J19: =SUM(H19:I19) -> 65773000 | K19: 1578000
D20: Other | K20: 10645000
C21: Inventories | H21: 3077000 | I21: 8250000 | J21: =SUM(H21:I21) -> 11327000 | K21: 15636000
C22: Prepaid items | K22: 19270000
C23: Restricted assets:
D24: Cash and cash equivalents | I24: 82000 | J24: =SUM(I24) -> 82000
D25: Investments | I25: 15681000 | J25: =SUM(H25:I25) -> 15681000 | K25: 247889000
D26: Share of pooled assets | I26: 44315000 | J26: =SUM(H26:I26) -> 44315000
D27: Receivables | I27: 5227000 | J27: =SUM(H27:I27) -> 5227000
C29: Total Current Assets | H29: =SUM(H9:H27) -> 815303000 | I29: =SUM(I9:I27) -> 114328000 | J29: =SUM(J9:J27) -> 929631000 | K29: =SUM(K9:K27) -> 498686000
B31: Noncurrent Assets
C32: Restricted assets:
D33: Deposits and other assets | H33: 7938000 | J33: =SUM(H33:I33) -> 7938000 | K33: 28679000
C34: Mortgage loans receivable | K34: 70850000
C35: Capital assets not being depreciated | H35: 243181000 | I35: 16703000 | J35: =SUM(H35:I35) -> 259884000
C36: Capital assets being depreciated, net | H36: 930821000 | I36: 529954000 | J36: =SUM(H36:I36) -> 1460775000 | K36: 378862000
C38: Total Noncurrent Assets | H38: =SUM(H31:H36) -> 1181940000 | I38: =SUM(I31:I36) -> 546657000 | J38: =SUM(J31:J36) -> 1728597000 | K38: =SUM(K31:K36) -> 478391000
C40: Total Assets | H40: =SUM(H38+H29) -> 1997243000 | I40: =SUM(I38+I29) -> 660985000 | J40: =SUM(J29+J38) -> 2658228000 | K40: =SUM(K29+K38) -> 977077000
B42: Deferred outflows of resources
C43: Deferred charges on bond issuance costs | H43: 7537000 | J43: =SUM(H43:I43) -> 7537000
C45: Total Deferred Outflows of Resources | H45: =H43 -> 7537000 | I45: =I43 -> 0 | J45: =J43 -> 7537000 | K45: =K43 -> 0
A47: LIABILITIES
B48: Current liabilities
...

Sheet LaSalle
C1: LaSalle Parish 2013 Statement of Net Assets
C2: Issued: December 31, 2013
G4: Governmental Activities
A5: ASSETS
B6: Cash and cash equivalents | G6: 2504699
B7: Receivables | G7: 3366905
B8: Prepaid lease payments | G8: 7476
B9: Capital assets (net) | G9: 5846162
B11: Total Assets | G11: =SUM(G6:G9) -> 11725242
A13: LIABILITIES
B14: Cash overdraft | G14: 216358
B15: Accounts payable | G15: 275032
B16: Payroll payable | G16: 37855
B17: Net OPEB obligations | G17: 69188
B18: Long term liabilities:
C19: Due within one year | G19: 221535
C20: Due in more than one year | G20: 125749
C22: Total Liabilities | G22: =SUM(G14:G20) -> 945717
A24: NET ASSETS
B25: Invested in capital assets, net of related debt | G25: 5498878
B26: Unrestricted | G26: 5280647
B28: Total Net Assets | G28: =SUM(G25:G26) -> 10779525
B30: Total Liabilities and Net Assets | G30: =SUM(G22+G28) -> 11725242

Sheet Lafayette
D1: Lafayete Parish 2013 Statement of Net Assets
D2: Issued: December 31, 2013
H4: Primary Government
H5: Governmental Activities | I5: Business-Type Activities | J5: Total | K5: Component Unit
A6: ASSETS
B7: Current Assets
C8: Cash and interest-bearing deposits | H8: 7721845 | I8: 2848461 | J8: =SUM(H8:I8) -> 10570306 | K8: 50132926
C9: Investments | H9: 278852022 | I9: 16027117 | J9: =SUM(H9:I9) -> 294879139 | K9: 16338139
C10: Accounts receivable, net | H10: 2270885 | I10: 27658362 | J10: =SUM(H10:I10) -> 29929247 | K10: 2002495
C11: Loans receivable, net | H11: 2140411 | J11: =SUM(H11:I11) -> 2140411 | K11: 6171947
C12: Taxes receivable | J12: =SUM(H12:I12) -> 0 | K12: 1371542
C13: Assessments receivable | H13: 273120 | J13: =SUM(H13:I13) -> 273120
C14: Accrued interest receivable | H14: 310013 | I14: 1099 | J14: =SUM(H14:I14) -> 311112 | K14: 93598
C15: Internal balances | H15: 3559213 | I15: -3559213 | J15: =SUM(H15:I15) -> 0
C16: Due from primary government | J16: =SUM(H16:I16) -> 0 | K16: 73188
C17: Due from component units | H17: 177735 | I17: 1879 | J17: =SUM(H17:I17) -> 179614
C18: Due from other governmental agencies | H18: 18499918 | I18: 3456198 | J18: =SUM(H18:I18) -> 21956116 | K18: 7986272
C19: Other receivables | J19: =SUM(H19:I19) -> 0 | K19: 15000
C20: Inventories, net | H20: 419825 | I20: 31932260 | J20: =SUM(H20:I20) -> 32352085 | K20: 218586
C21: Prepaid items | H21: 149592 | I21: 293411 | J21: =SUM(H21:I21) -> 443003 | K21: 378702
C22: Other assets | K22: 1346182
C23: Restricted assets:
D24: Cash | I24: 8101700 | J24: =SUM(H24:I24) -> 8101700 | K24: 3981944
D25: Investments | I25: 209339409 | J25: 209339409 | K25: 20708601
D26: Receivables | I26: 111938 | J26: =SUM(H26:I26) -> 111938 | K26: 44820
C27: Unamortized bond issuance costs | H27: 4415993 | I27: 5108695 | J27: =SUM(H27:I27) -> 9524688
C28: Unamortized start-up costs | I28: 1960661 | J28: =SUM(H28:I28) -> 1960661
C29: Capital assets:
D30: Non-depreciable | H30: 70197995 | I30: 66232170 | J30: =SUM(H30:I30) -> 136430165 | K30: 29146560
D31: Depreciable,net | H31: 517241758 | I31: 662632316 | J31: =SUM(H31:I31) -> 1179874074 | K31: 90812166
C33: Total Assets | H33: =SUM(H8:H31) -> 906230325 | I33: =SUM(I8:I31) -> 1032146463 | J33: =SUM(J8:J31) -> 1938376788 | K33: =SUM(K8:K31) -> 230822668
A35: LIABILITIES
C36: Cash overdraft | I36: 2167552 | J36: =SUM(H36:I36) -> 2167552 | K36: 173447
C37: Accounts payable | H37: 3505182 | I37: 6433320 | J37: =SUM(H37:I37) -> 9938502 | K37: 4651833
C38: Accrued liabilities | H38: 4204230 | I38: 1831756 | J38: =SUM(H38:I38) -> 6035986 | K38: 834353
C39: Contracts payable | H39: 2352712 | I39: 4514145 | J39: =SUM(H39:I39) -> 6866857
C40: Retainage payable | H40: 2067414 | I40: 1452778 | J40: =SUM(H40:I40) -> 3520192
C41: Other payables | H41: 444275 | J41: =SUM(H41:I41) -> 444275
C42: Due to primary government | J42: =SUM(H42:I42) -> 0 | K42: 179614
C43: Due to component units | H43: 73188 | J43: =SUM(H43:I43) -> 73188
...

Sheet Lafourche
D1: Lafourche Parish 2013 Statement of Net Assets
D2: Issued: December 31, 2013
H4: Primary Government | K4: Component Unit
H5: Governmental Activities | I5: Business-Type Activities | J5: Total | K5: Total
A6: ASSETS
C7: Cash | H7: 28390862 | J7: =SUM(H7:I7) -> 28390862 | K7: 198057510
C8: Investments | H8: 19417222 | J8: =SUM(H8:I8) -> 19417222 | K8: 24203089
C9: Receivables | H9: 2513853 | I9: 17430 | J9: =SUM(H9:I9) -> 2531283 | K9: 36021414
C10: Due from other governmental units | H10: 32644660 | J10: =SUM(H10:I10) -> 32644660
C11: Prepaids and other assets | H11: 1525426 | J11: =SUM(H11:I11) -> 1525426 | K11: 21575554
C12: Capital assets:
D13: Non-depreciable | H13: 25100579 | J13: =SUM(H13:I13) -> 25100579 | K13: 29927075
D14: Depreciable | H14: 57951906 | I14: 3062776 | J14: =SUM(H14:I14) -> 61014682 | K14: 198267967
C16: Total Assets | H16: =SUM(H7:H14) -> 167544508 | I16: =SUM(I7:I14) -> 3080206 | J16: =SUM(J7:J14) -> 170624714 | K16: =SUM(K7:K14) -> 508052609
B18: Deferred outflows of resources
C19: Deferred charge on refunding | H19: 1077879 | J19: =SUM(H19:I19) -> 1077879
C21: Total Deferred Outflows of Resources | H21: =H19 -> 1077879 | I21: =I19 -> 0 | J21: =J19 -> 1077879 | K21: =K19 -> 0
A23: LIABILITIES
C24: Accounts payable and accrued expenses | H24: 7236302 | I24: 16352 | J24: =SUM(H24:I24) -> 7252654 | K24: 18038291
C25: Other current liabilities | H25: 517734 | J25: =SUM(H25:I25) -> 517734 | K25: 5286633
C26: Accrued interest payable | H26: 664933 | J26: =SUM(H26:I26) -> 664933
C27: Due to other governmental units | H27: 383924 | I27: 199494 | J27: =SUM(H27:I27) -> 583418
C28: Long-term liabilities | J28: =SUM(H28:I28) -> 0
D29: Due within one year | H29: 8630887 | J29: =SUM(H29:I29) -> 8630887 | K29: 4017837
D30: Due in more than one year | H30: 46541145 | J30: =SUM(H30:I30) -> 46541145 | K30: 26224316
D32: Total Liabilities | H32: =SUM(H24:H30) -> 63974925 | I32: =SUM(I24:I30) -> 215846 | J32: =SUM(J24:J30) -> 64190771 | K32: =SUM(K24:K30) -> 53567077
A34: NET ASSETS
B35: Net invested in capital assets | H35: 34851386 | I35: 3062776 | J35: =SUM(H35:I35) -> 37914162 | K35: 199214122
B36: Restricted for:
C37: Capital projects | H37: 31251705 | J37: =SUM(H37:I37) -> 31251705 | K37: 1653013
C38: Debt service | H38: 6243097 | J38: =SUM(H38:I38) -> 6243097 | K38: 3694956
B39: Unrestricted (deficit) | H39: 32301274 | I39: -198416 | J39: =SUM(H39:I39) -> 32102858 | K39: 249923441
C41: Total Net Assets | H41: =SUM(H35:H39) -> 104647462 | I41: =SUM(I35:I39) -> 2864360 | J41: =SUM(J35:J39) -> 107511822 | K41: =SUM(K34:K39) -> 454485532
C43: Total Liabilities and Net Assets | H43: =SUM(H41+H32) -> 168622387 | I43: =SUM(I32+I41) -> 3080206 | J43: =SUM(J32+J41) -> 171702593 | K43: =SUM(K41+K32) -> 508052609

Sheet Lincoln
C1: Lincoln Parish 2013 Statement of Net Assets
C2: Issued: December 31, 2013
G4: Governmental Activities
A5: ASSETS
B6: Cash | G6: 9270701
B7: Investments | G7: 22426630
B8: Accounts receivable | G8: 7709169
B9: Due from other entities | G9: 236078
B10: Inventory | G10: 11582
B11: Capital assets:
C12: Non-Depreciable | G12: 1775786
C13: Depreciable | G13: 22094399
B15: Total Assets | G15: =SUM(G6:G13) -> 63524345
A17: DEFERRED OUTFLOWS OF RESOURCES
B18: Prepaid expenses | G18: 3008
A20: LIABILITIES
B21: Accounts payable | G21: 1372481
B22: Due to other entities | G22: 1330002
B23: Noncurrent liabilities:
C24: Due within one year:
D25: Bonds payable | G25: 466000
C26: Due in more than one year:
D27: Compensated absences | G27: 114162
D28: Bonds payable | G28: 3476000
C29: Unfunded postretirement:
D30: Benefit plan obligations | G30: 1605571
C32: Total Liabilities | G32: =SUM(G21:G30) -> 8364216
A34: NET ASSETS
B35: Net investment in capital assets | G35: 23870185
B36: Restricted for:
C37: Capital projects | G37: 1998577
C38: Debt service | G38: 990393
B39: Unrestricted | G39: 28303982
B41: Total Net Assets | G41: =SUM(G35:G39) -> 55163137
B43: Total Liabilities and Net Assets | G43: =SUM(G32+G41) -> 63527353

Sheet Livingston
D1: Livingston Parish 2013 Statement of Net Assets
D2: Issued: December 31, 2013
H4: Primary Government
H5: Governmental Activities | I5: Business-Type Activities | J5: Total
A6: ASSETS
B7: Current Assets
C8: Cash and cash equivalents | H8: 5509530 | I8: 325932 | J8: =SUM(H8:I8) -> 5835462
C9: Investments | H9: 3407261 | J9: =SUM(H9:I9) -> 3407261
C10: Receivables, Net of Allowance | H10: 1643857 | I10: 125158 | J10: =SUM(H10:I10) -> 1769015
C11: Inventory | H11: 186604 | J11: =SUM(H11:I11) -> 186604
C12: Internal balances | H12: 222383 | I12: -222383 | J12: =SUM(H12:I12) -> 0
C13: Due from other governments | H13: 12320275 | J13: =SUM(H13:I13) -> 12320275
