Workbook

Sheet Acadia
D1: ACADIA PARISH POLICE JURY
D2: Capital Assets
D3: For the Year Ended December 31, 2013
I5: Beginning Balance | J5: Increases | K5: Decreases | L5: Ending Balance | M5: Cross Sectional
A7: Primary Government
A8: Government Activities:
A9: Capital assets, not being depreciated:
B10: Land | I10: 1172249 | J10: 210643 | K10: -53884 | L10: =SUM(I10:K10) -> 1329008 | M10: =SUM(L10) -> 1329008
B11: Construction in progress | I11: 3168467 | J11: 9240635 | K11: -2161157 | L11: =SUM(I11:K11) -> 10247945 | M11: =SUM(L11) -> 10247945
C12: Total assets not being depreciated | I12: =SUM(I10:I11) -> 4340716 | J12: =SUM(J10:J11) -> 9451278 | K12: =SUM(K10:K11) -> -2215041 | L12: =SUM(L10:L11) -> 11576953
A14: Capital assets being depreciated:
B15: Buildings and improvements | I15: 22193080 | J15: 2231588 | K15: 0 | L15: =SUM(I15:K15) -> 24424668
B16: Machinery and equipment | I16: 11766135 | J16: 261410 | K16: 0 | L16: =SUM(I16:K16) -> 12027545
B17: Improvements, other than buildings | I17: 748499 | J17: 16078 | L17: =SUM(I17:K17) -> 764577
B18: Infrastructure | I18: 36944045 | J18: 926083 | K18: -68500 | L18: =SUM(I18:K18) -> 37801628
C19: Total capital assets being depreciated | I19: =SUM(I15:I18) -> 71651759 | J19: =SUM(J15:J18) -> 3435159 | K19: =SUM(K15:K18) -> -68500 | L19: =SUM(L15:L18) -> 75018418
A21: Less accumulated depreciation for:
B22: Buildings and improvements | I22: -5958982 | J22: -771222 | K22: 0 | L22: =SUM(I22:K22) -> -6730204 | M22: =SUM(L22,L15) -> 17694464
B23: Machinery and equipment | I23: -5627631 | J23: -946670 | K23: 0 | L23: =SUM(I23:K23) -> -6574301 | M23: =SUM(L23,L16) -> 5453244
B24: Improvements, other than buildings | I24: -396486 | J24: -8734 | L24: =SUM(I24:K24) -> -405220 | M24: =SUM(L24,L17) -> 359357
B25: Infrastructure | I25: -17105170 | J25: -1378690 | K25: 68500 | L25: =SUM(I25:K25) -> -18415360 | M25: =SUM(L25,L18) -> 19386268
C26: Total accumulated depreciation | I26: =SUM(I22:I25) -> -29088269 | J26: =SUM(J22:J25) -> -3105316 | K26: =SUM(K22:K25) -> 68500 | L26: =SUM(L22:L25) -> -32125085
B27: Total capital assets being depreciated, net | I27: =I26+I19 -> 42563490 | J27: =J26+J19 -> 329843 | K27: =K26+K19 -> 0 | L27: =L26+L19 -> 42893333
B28: Governmental activities capital assets, net | I28: =I12+I27 -> 46904206 | J28: =J12+J27 -> 9781121 | K28: =K12+K27 -> -2215041 | L28: =L12+L27 -> 54470286 | M28: =SUM(M22:M25,M10:M11) -> 54470286

Sheet Allen
D1: ALLEN PARISH POLICE JURY
D2: Capital Assets
D3: For the Year Ended December 31, 2013
G5: Beginning Balance | H5: Increases | I5: Decreases | J5: Ending Balance | K5: Cross Sectional
A7: Governmental Activities:
B8: Capital assets, not being depreciated:
C9: Construction in progress | G9: 273169 | I9: -273169 | J9: =SUM(G9:I9) -> 0 | K9: =SUM(J9) -> 0
C10: Land | G10: 572300 | J10: =SUM(G10:I10) -> 572300 | K10: =SUM(J10) -> 572300
D12: Total capital assets, not being depreciated | G12: =SUM(G8:G11) -> 845469 | H12: =SUM(H8:H11) -> 0 | I12: =SUM(I8:I11) -> -273169 | J12: =SUM(J8:J11) -> 572300
A14: Capital assets being depreciated:
B15: Buildings | G15: 4488374 | H15: 58965 | I15: 0 | J15: =SUM(G15:I15) -> 4547339
B16: Improvements other than buildings | G16: 5851280 | H16: 1775 | J16: =SUM(G16:I16) -> 5853055
B17: Furniture and fixtures | G17: 405550 | H17: 3899 | I17: -19416 | J17: =SUM(G17:I17) -> 390033
B18: Vehicles | G18: 804226 | H18: 55832 | I18: -40609 | J18: =SUM(G18:I18) -> 819449
B19: Machinery and equipment | G19: 4520910 | H19: 306084 | I19: -1572772 | J19: =SUM(G19:I19) -> 3254222
B20: Infrastructure | G20: 28219912 | I20: 0 | J20: =SUM(G20:I20) -> 28219912
D22: Total capital assets being depreciated | G22: =SUM(G15:G21) -> 44290252 | H22: =SUM(H15:H21) -> 426555 | I22: =SUM(I15:I21) -> -1632797 | J22: =SUM(J15:J20) -> 43084010
A24: Less accumulated depreciation for:
B25: Buildings | G25: 1686529 | H25: 100580 | I25: 0 | J25: =SUM(G25:I25) -> 1787109 | K25: =J15-J25 -> 2760230
B26: Improvements other than buildings | G26: 1980497 | H26: 200716 | J26: =SUM(G26:I26) -> 2181213 | K26: =J16-J26 -> 3671842
B27: Furniture and fixtures | G27: 297147 | H27: 27444 | I27: -12961 | J27: =SUM(G27:I27) -> 311630 | K27: =J17-J27 -> 78403
B28: Vehicles | G28: 613540 | H28: 46028 | I28: -40609 | J28: =SUM(G28:I28) -> 618959 | K28: =J18-J28 -> 200490
B29: Machinery and equipment | G29: 2893539 | H29: 209343 | I29: -872988 | J29: =SUM(G29:I29) -> 2229894 | K29: =J19-J29 -> 1024328
B30: Infrastructure | G30: 11277335 | H30: 584415 | I30: 0 | J30: =SUM(G30:I30) -> 11861750 | K30: =J20-J30 -> 16358162
D32: Total accumulated depreciation | G32: =SUM(G25:G31) -> 18748587 | H32: =SUM(H25:H31) -> 1168526 | I32: =SUM(I25:I31) -> -926558 | J32: =SUM(J25:J31) -> 18990555
B34: Total capital assets being depreciated, net | G34: =G22-G32 -> 25541665 | H34: =H22-H32 -> -741971 | I34: =I22-I32 -> -706239 | J34: =J22-J32 -> 24093455
B36: Governmental activities capital assets, net | G36: =G34+G12 -> 26387134 | H36: =H34+H12 -> -741971 | I36: =I34+I12 -> -979408 | J36: =J34+J12 -> 24665755 | K36: =SUM(K25:K30,K9:K10) -> 24665755

Sheet Ascension
D1: ASCENSION PARISH POLICE JURY
D2: Capital Assets
D3: For the Year Ended December 31, 2013
I5: Beginning Balance | J5: Increases | K5: Decreases | L5: Ending Balance | M5: Cross Sectional
A7: Governmental Activities:
B8: Capital assets, not being depreciated:
C9: Land | I9: 16585 | J9: 728 | K9: 0 | L9: =SUM(I9:K9) -> 17313 | M9: =SUM(L9) -> 17313
C10: Construction in progress | I10: 32839 | J10: 23212 | K10: -264 | L10: =SUM(I10:K10) -> 55787 | M10: =SUM(L10) -> 55787
D12: Total capital assets, not being depreciated | I12: =SUM(I8:I11) -> 49424 | J12: =SUM(J8:J11) -> 23940 | K12: =SUM(K8:K11) -> -264 | L12: =SUM(L8:L11) -> 73100
A14: Capital assets being depreciated:
B15: Buildings | I15: 62442 | J15: 256 | K15: 0 | L15: =SUM(I15:K15) -> 62698
B16: Vehicles | I16: 13147 | J16: 544 | K16: -529 | L16: =SUM(I16:K16) -> 13162
B17: Equipment | I17: 12549 | J17: 840 | K17: -1303 | L17: =SUM(I17:K17) -> 12086
B18: Furniture and fixtures | I18: 1100 | J18: 32 | K18: -5 | L18: =SUM(I18:K18) -> 1127
B19: Library materials | I19: 2882 | J19: 417 | K19: -507 | L19: =SUM(I19:K19) -> 2792
B20: Infrastructure | I20: 210670 | J20: 5615 | K20: 0 | L20: =SUM(I20:K20) -> 216285
D22: Total capital assets being depreciated | I22: =SUM(I15:I21) -> 302790 | J22: =SUM(J15:J21) -> 7704 | K22: =SUM(K15:K21) -> -2344 | L22: =SUM(L15:L20) -> 308150
A24: Less accumulated depreciation for:
B25: Buildings | I25: -19199 | J25: -1697 | K25: 0 | L25: =SUM(I25:K25) -> -20896 | M25: =SUM(L25,L15) -> 41802
B26: Vehicles | I26: -8800 | J26: -697 | K26: 510 | L26: =SUM(I26:K26) -> -8987 | M26: =SUM(L26,L16) -> 4175
B27: Equipment | I27: -9796 | J27: -935 | K27: 1322 | L27: =SUM(I27:K27) -> -9409 | M27: =SUM(L27,L17) -> 2677
B28: Furniture and fixtures | I28: -568 | J28: -82 | K28: 5 | L28: =SUM(I28:K28) -> -645 | M28: =SUM(L28,L18) -> 482
B29: Library materials | I29: -1774 | J29: -558 | K29: 507 | L29: =SUM(I29:K29) -> -1825 | M29: =SUM(L29,L19) -> 967
B30: Infrastructure | I30: -119227 | J30: -10696 | K30: 0 | L30: =SUM(I30:K30) -> -129923 | M30: =SUM(L30,L20) -> 86362
D32: Total accumulated depreciation | I32: =SUM(I25:I31) -> -159364 | J32: =SUM(J25:J31) -> -14665 | K32: =SUM(K25:K31) -> 2344 | L32: =SUM(L25:L31) -> -171685
B34: Total capital assets being depreciated, net | I34: =I22+I32 -> 143426 | J34: =J22+J32 -> -6961 | K34: =K22+K32 -> 0 | L34: =L22+L32 -> 136465
B36: Governmental activities capital assets, net | I36: =I32+I22+I12 -> 192850 | J36: =J32+J22+J12 -> 16979 | K36: =K32+K22+K12 -> -264 | L36: =L32+L22+L12 -> 209565 | M36: =SUM(M25:M30,M9:M10) -> 209565
I39: Beginning Balance | J39: Increases | K39: Decreases | L39: Ending Balance
A40: Business-Type Activities:
B41: Capital assets, not being depreciated:
C42: Land | I42: 670 | J42: 0 | K42: 0 | L42: =SUM(I42:K42) -> 670 | M42: =SUM(L42) -> 670
C43: Construction in progress | I43: 98 | J43: 173 | K43: 0 | L43: =SUM(I43:K43) -> 271 | M43: =SUM(L43) -> 271
D45: Total capital assets, not being depreciated | I45: =SUM(I41:I44) -> 768 | J45: =SUM(J41:J44) -> 173 | K45: =SUM(K41:K44) -> 0 | L45: =SUM(L41:L44) -> 941
B47: Capital assets, depreciable:
C48: Sewer systems | I48: 5911 | J48: 0 | K48: 0 | L48: =SUM(I48:K48) -> 5911
C49: Water systems | I49: 766 | J49: 9 | K49: 0 | L49: =SUM(I49:K49) -> 775
C50: Lamar Dixon Expo Center | I50: 7127 | J50: 171 | K50: 0 | L50: =SUM(I50:K50) -> 7298
D52: Total capital assets, depreciable | I52: =SUM(I47:I50) -> 13804 | J52: =SUM(J47:J50) -> 180 | K52: =SUM(K47:K50) -> 0 | L52: =SUM(L47:L50) -> 13984
B54: Less accumulated depreciation for:
C55: Sewer systems | I55: -1793 | J55: -302 | L55: =SUM(I55:K55) -> -2095 | M55: =SUM(L55,L48) -> 3816
...

Sheet Assumption
D1: ASSUMPTION PARISH POLICE JURY
D2: Capital Assets
D3: For the Year Ended December 31, 2013
H6: Balance 12/31/2012 | I6: 2013 Additions | J6: 2013 Deletions | K6: 2013 Reclassifications | L6: Balance 12/31/2013 | M6: Cross Sectional
N7: Net Depreciation
C8: Land | H8: 2210258 | I8: 3123 | J8: 0 | K8: 0 | L8: =SUM(H8:K8) -> 2213381 | M8: =SUM(L8) -> 2213381 | N8: =SUM(H8:K8) -> 2213381 | O8: Depreciation
C9: Buildings | H9: 11414215 | I9: 723095 | J9: 0 | K9: 11579849 | L9: =SUM(H9:K9) -> 23717159 | M9: =L9 -> 23717159 | N9: =M9-O9 -> 16396346 | O9: =(M9/P9)*M17 -> 7320812.6 | P9: =SUM(M9:M13) -> 59351210 | Q9: Total capital assets being depreeciated
C10: Improvements other than buildings | H10: 9600524 | I10: 112916 | J10: 133 | K10: 1971576 | L10: =+H10+I10-J10+K10 -> 11684883 | M10: =L10 -> 11684883 | N10: =M10-O10 -> 8078091.9 | O10: =(M10/P9)*M17 -> 3606791.1
C11: Roads | H11: 14256123 | I11: 930212 | J11: 0 | K11: 923067 | L11: =SUM(H11:K11) -> 16109402 | M11: =L11 -> 16109402 | N11: =M11-O11 -> 11136888 | O11: =(M11/P9)*M17 -> 4972514.4
C12: Bridges | H12: 588844 | I12: 0 | J12: 0 | K12: 0 | L12: =SUM(H12:K12) -> 588844 | M12: =L12 -> 588844 | N12: =M12-O12 -> 407084.6 | O12: =(M12/P9)*M17 -> 181759.4
C13: Equipment & other | H13: 6669216 | I13: 576282 | J13: 129654 | K13: 135078 | L13: =+H13+I13-J13+K13 -> 7250922 | M13: =L13 -> 7250922 | N13: =M13-O13 -> 5012768.5 | O13: =(M13/P9)*M17 -> 2238153.5
C14: Construction in progress | H14: 12616148 | I14: 2481993 | J14: 0 | K14: -14609570 | L14: =SUM(H14:K14) -> 488571 | M14: =SUM(L14) -> 488571 | N14: =SUM(H14:K14) -> 488571
H15: =SUM(H8:H14) -> 57355328 | I15: =SUM(I8:I14) -> 4827621 | J15: =SUM(J8:J14) -> 129787 | K15: =SUM(K8:K14) -> 0 | L15: =SUM(L8:L14) -> 62053162 | O15: =SUM(O9:O13) -> 18320031
C17: Accumulated Depreciation | H17: 16038335 | I17: 2334670 | J17: 52974 | K17: 0 | L17: =+H17+I17-J17 -> 18320031 | M17: =SUM(L17) -> 18320031
C19: Capital Assets, Net Depreciation | H19: =H15-H17 -> 41316993 | I19: =I15-J17 -> 4774647 | J19: =J15-J17 -> 76813 | K19: =K15+K17 -> 0 | L19: =L15-L17 -> 43733131 | M19: =SUM(M8:M14)-M17 -> 43733131 | N19: =SUM(N8:N16) -> 43733131

Sheet Avoyelles
D1: AVOYELLES PARISH POLICE JURY
D2: Capital Assets
D3: For the Year Ended December 31, 2013
G5: Beginning Balance | H5: Increases | I5: Decreases | J5: Ending Balance | K5: Cross Sectional
A7: Governmental Activities:
B8: Capital assets, not being depreciated:
C9: Land | G9: 584787 | J9: =SUM(G9:I9) -> 584787 | K9: =SUM(J9) -> 584787
C10: Construction in progress | G10: 492818 | H10: 590251 | J10: =SUM(G10:I10) -> 1083069 | K10: =SUM(J10) -> 1083069
D12: Total capital assets, not being depreciated | G12: =SUM(G8:G11) -> 1077605 | H12: =SUM(H8:H11) -> 590251 | I12: =SUM(I8:I11) -> 0 | J12: =SUM(J8:J11) -> 1667856
A14: Capital assets being depreciated:
B15: Buildings and improvements | G15: 4168006 | H15: 9090 | I15: 0 | J15: =SUM(G15:I15) -> 4177096
B16: Equipment, furniture and fixtures | G16: 567578 | H16: 2899 | J16: =SUM(G16:I16) -> 570477
B17: Infrastructure | G17: 25000 | H17: 50128 | J17: =SUM(G17:I17) -> 75128
B18: Heavy equipment | G18: 3177605 | H18: 67404 | I18: 0 | J18: =SUM(G18:I18) -> 3245009
D20: Total capital assets being depreciated | G20: =SUM(G15:G19) -> 7938189 | H20: =SUM(H15:H18) -> 129521 | I20: =SUM(I15:I19) -> 0 | J20: =SUM(J15:J18) -> 8067710
A22: Less accumulated depreciation for:
B23: Buildings and improvements | G23: 1292488 | H23: 155643 | I23: 0 | J23: =SUM(G23:I23) -> 1448131 | K23: =J15-J23 -> 2728965
B24: Equipment, furniture and fixtures | G24: 456935 | H24: 33747 | J24: =SUM(G24:I24) -> 490682 | K24: =J16-J24 -> 79795
B25: Infrastructure | H25: 31327 | J25: =SUM(G25:I25) -> 31327 | K25: =J17-J25 -> 43801
B26: Heavy equipment | G26: 2377326 | H26: 155858 | I26: 0 | J26: =SUM(G26:I26) -> 2533184 | K26: =J18-J26 -> 711825
D28: Total accumulated depreciation | G28: =SUM(G23:G27) -> 4126749 | H28: =SUM(H23:H27) -> 376575 | I28: =SUM(I23:I27) -> 0 | J28: =SUM(J23:J27) -> 4503324
B30: Total capital assets being depreciated, net | G30: =G20-G28 -> 3811440 | H30: =H20-H28 -> -247054 | I30: =I20-I28 -> 0 | J30: =J20-J28 -> 3564386
B32: Governmental activities capital assets, net | G32: =G30+G12 -> 4889045 | H32: =H30+H12 -> 343197 | I32: =I30+I12 -> 0 | J32: =J30+J12 -> 5232242 | K32: =SUM(K23:K26,K9:K10) -> 5232242

Sheet Beauregard
D1: BEAUREGARD PARISH POLICE JURY
D2: Capital Assets
D3: For the Year Ended December 31, 2013
I5: Beginning Balance | J5: Additions | K5: Deletions | L5: Transfers | M5: Ending Balance | N5: Cross Sectional
A7: Primary Government
A8: Government Activities:
A9: Capital assets, not being depreciated:
B10: Land | I10: 786565 | J10: 20170 | M10: =SUM(I10:L10) -> 806735 | N10: =SUM(M10) -> 806735
B11: Construction in progress | I11: 539166 | J11: 790379 | L11: -539166 | M11: =SUM(I11:L11) -> 790379 | N11: =SUM(M11) -> 790379
C12: Total assets not being depreciated | I12: =SUM(I10:I11) -> 1325731 | J12: =SUM(J10:J11) -> 810549 | K12: =SUM(K10:K11) -> 0 | L12: =SUM(L10:L11) -> -539166 | M12: =SUM(M10:M11) -> 1597114
A14: Capital assets being depreciated:
B15: Buildings and improvements | I15: 16309487 | J15: 960000 | L15: 539166 | M15: =SUM(I15:L15) -> 17808653
B16: Infrastructure | I16: 43048502 | J16: 55622 | K16: -4218 | M16: =SUM(I16:L16) -> 43099906
B17: Furniture and equipment | I17: 11649469 | J17: 709008 | K17: -548344 | M17: =SUM(I17:L17) -> 11810133
C18: Total capital assets being depreciated | I18: =SUM(I15:I17) -> 71007458 | J18: =SUM(J15:J17) -> 1724630 | K18: =SUM(K15:K17) -> -552562 | L18: =SUM(L15:L17) -> 539166 | M18: =SUM(M15:M17) -> 72718692
A20: Less accumulated depreciation for:
B21: Buildings and improvements | I21: -7438986 | J21: -438673 | M21: =SUM(I21:L21) -> -7877659 | N21: =SUM(M21,M15) -> 9930994
B22: Infrastructure | I22: -26036207 | J22: -1078870 | K22: 4218 | M22: =SUM(I22:L22) -> -27110859 | N22: =SUM(M22,M16) -> 15989047
B23: Furniture and equipment | I23: -7538686 | J23: -777266 | K23: 495822 | L23: 0 | M23: =SUM(I23:L23) -> -7820130 | N23: =M17+M23 -> 3990003
C24: Total accumulated depreciation | I24: =SUM(I21:I23) -> -41013879 | J24: =SUM(J21:J23) -> -2294809 | K24: =SUM(K21:K23) -> 500040 | L24: =SUM(L21:L23) -> 0 | M24: =SUM(M21:M23) -> -42808648
B25: Total capital assets being depreciated, net | I25: =I24+I18 -> 29993579 | J25: =J24+J18 -> -570179 | K25: =K24+K18 -> -52522 | L25: =L24+L18 -> 539166 | M25: =M24+M18 -> 29910044
B26: Governmental activities capital assets, net | I26: =I12+I25 -> 31319310 | J26: =J12+J25 -> 240370 | K26: =K12+K25 -> -52522 | L26: =L12+L25 -> 0 | M26: =M12+M25 -> 31507158 | N26: =SUM(N21:N23,N10:N11) -> 31507158

Sheet Bienville
D1: BIENVILLE PARISH POLICE JURY
D2: Capital Assets
D3: For the Year Ended December 31, 2013
G5: Beginning Balance | H5: Increases | I5: Decreases | J5: Ending Balance | K5: Cross Sectional
A7: Governmental Activities:
B8: Capital assets, not being depreciated:
C9: Land | G9: 660250 | J9: =SUM(G9:I9) -> 660250 | K9: =SUM(J9) -> 660250
C10: Construction in progress | G10: 10196359 | H10: 1837952 | I10: -12034311 | J10: =SUM(G10:I10) -> 0 | K10: =SUM(J10) -> 0
D12: Total capital assets, not being depreciated | G12: =SUM(G8:G11) -> 10856609 | H12: =SUM(H8:H11) -> 1837952 | I12: =SUM(I8:I11) -> -12034311 | J12: =SUM(J8:J11) -> 660250
A14: Capital assets being depreciated:
B15: Infrastructure:
C16: Roads | G16: 19856904 | H16: 1167236 | J16: =SUM(G16:I16) -> 21024140
C17: Bridges | G17: 1973698 | H17: 564000 | J17: =SUM(G17:I17) -> 2537698
B18: Buildings and improvements | G18: 4817522 | H18: 12034311 | I18: 0 | J18: =SUM(G18:I18) -> 16851833
B19: Office furniture and equipment | G19: 22519 | H19: 519145 | J19: =SUM(G19:I19) -> 541664
B20: Heavy equipment | G20: 1545021 | H20: 45541 | I20: -12566 | J20: =SUM(G20:I20) -> 1577996
B21: Vehicles | G21: 1219091 | H21: 314967 | I21: -139288 | J21: =SUM(G21:I21) -> 1394770
B22: Miscellaneous equipment | G22: 523698 | I22: -8960 | J22: =SUM(G22:I22) -> 514738
D24: Total capital assets being depreciated | G24: =SUM(G16:G22) -> 29958453 | H24: =SUM(H16:H22) -> 14645200 | I24: =SUM(I16:I22) -> -160814 | J24: =SUM(J16:J22) -> 44442839
A26: Less accumulated depreciation for:
B27: Infrastructure:
C28: Roads | G28: -14811392 | H28: -874354 | J28: =SUM(G28:I28) -> -15685746 | K28: =J16+J28 -> 5338394
C29: Bridges | G29: -1279334 | H29: -39480 | J29: =SUM(G29:I29) -> -1318814 | K29: =J17+J29 -> 1218884
B30: Buildings and improvements | G30: -2565179 | H30: -365514 | I30: 0 | J30: =SUM(G30:I30) -> -2930693 | K30: =J18+J30 -> 13921140
B31: Office furniture and equipment | G31: -22189 | H31: -104159 | J31: =SUM(G31:I31) -> -126348 | K31: =J19+J31 -> 415316
B32: Heavy equipment | G32: -1091356 | H32: -71214 | I32: 12566 | J32: =SUM(G32:I32) -> -1150004 | K32: =J20+J32 -> 427992
B33: Vehicles | G33: -749219 | H33: -99765 | I33: 139058 | J33: =SUM(G33:I33) -> -709926 | K33: =J21+J33 -> 684844
B34: Miscellaneous equipment | G34: -352897 | H34: -23155 | I34: 8670 | J34: =SUM(G34:I34) -> -367382 | K34: =J22+J34 -> 147356
D36: Total accumulated depreciation | G36: =SUM(G28:G34) -> -20871566 | H36: =SUM(H28:H34) -> -1577641 | I36: =SUM(I28:I34) -> 160294 | J36: =SUM(J28:J34) -> -22288913
B38: Total capital assets being depreciated, net | G38: =G36+G24 -> 9086887 | H38: =H36+H24 -> 13067559 | I38: =I36+I24 -> -520 | J38: =J36+J24 -> 22153926
B40: Governmental activities capital assets, net | G40: =G38+G12 -> 19943496 | H40: =H38+H12 -> 14905511 | I40: =I38+I12 -> -12034831 | J40: =J38+J12 -> 22814176 | K40: =SUM(K9:K34) -> 22814176

Sheet Bossier
D1: BOSSIER PARISH POLICE JURY
D2: Capital Assets
D3: For the Year Ended December 31, 2013
I5: Beginning Balance | J5: Transfers | K5: Additions | L5: Deletions | M5: Ending Balance | N5: Cross Sectional
A7: Primary Government
A8: Government Activities:
A9: Capital assets, not being depreciated:
B10: Land | I10: 11633324 | J10: 0 | K10: 573760 | M10: =SUM(I10:L10) -> 12207084 | N10: =SUM(M10) -> 12207084
B11: Construction in progress | I11: 11307751 | J11: -7862502 | K11: 2597030 | M11: =SUM(I11:L11) -> 6042279 | N11: =SUM(M11) -> 6042279
C12: Total assets not being depreciated | I12: =SUM(I10:I11) -> 22941075 | J12: =SUM(J10:J11) -> -7862502 | K12: =SUM(K10:K11) -> 3170790 | L12: =SUM(L10:L11) -> 0 | M12: =SUM(M10:M11) -> 18249363
A14: Capital assets being depreciated:
B15: Buildings and improvements | I15: 107381194 | J15: 262706 | K15: 416159 | M15: =SUM(I15:L15) -> 108060059
B16: Infrastructure | I16: 201825504 | J16: 7599796 | K16: 10826090 | M16: =SUM(I16:L16) -> 220251390
B17: Furniture, equipment and vehicles | I17: 10240517 | K17: 613900 | L17: -278841 | M17: =SUM(I17:L17) -> 10575576
B18: Library books and information material | I18: 4156868 | K18: 474808 | M18: =SUM(I18:L18) -> 4631676
C19: Total capital assets being depreciated | I19: =SUM(I15:I18) -> 323604083 | J19: =SUM(J15:J18) -> 7862502 | K19: =SUM(K15:K18) -> 12330957 | L19: =SUM(L15:L18) -> -278841 | M19: =SUM(M15:M18) -> 343518701
A21: Less accumulated depreciation for:
B22: Buildings and improvements | I22: -21419002 | K22: -2606481 | L22: 0 | M22: =SUM(I22:L22) -> -24025483 | N22: =SUM(M22,M15) -> 84034576
B23: Infrastructure | I23: -41327651 | K23: -5376036 | L23: 0 | M23: =SUM(I23:L23) -> -46703687 | N23: =SUM(M23,M16) -> 173547703
B24: Furniture, equipment and vehicles | I24: -5797114 | K24: -685150 | L24: 273741 | M24: =SUM(I24:L24) -> -6208523 | N24: =SUM(M24,M17) -> 4367053
B25: Library books and information material | I25: -3163340 | K25: -363564 | L25: 0 | M25: =SUM(I25:L25) -> -3526904 | N25: =M18+M25 -> 1104772
C26: Total accumulated depreciation | I26: =SUM(I22:I25) -> -71707107 | J26: =SUM(J22:J25) -> 0 | K26: =SUM(K22:K25) -> -9031231 | L26: =SUM(L22:L25) -> 273741 | M26: =SUM(M22:M25) -> -80464597
B27: Total capital assets being depreciated, net | I27: =I26+I19 -> 251896976 | J27: =J26+J19 -> 7862502 | K27: =K26+K19 -> 3299726 | L27: =L26+L19 -> -5100 | M27: =M26+M19 -> 263054104
B28: Governmental activities capital assets, net | I28: =I12+I27 -> 274838051 | J28: =J12+J27 -> 0 | K28: =K12+K27 -> 6470516 | L28: =L12+L27 -> -5100 | M28: =M12+M27 -> 281303467 | N28: =SUM(N22:N25,N10:N11) -> 281303467
I31: Beginning Balance | J31: Transfers | K31: Additions | L31: Deletions | M31: Ending Balance
A33: Business-type Activities:
A34: Capital assets not being depreciated:
B35: Land | I35: 1261868 | J35: 0 | K35: 39910 | L35: 0 | M35: =SUM(I35:L35) -> 1301778 | N35: =SUM(M35) -> 1301778
B36: Goodwill | I36: 1226000 | M36: =SUM(I36:L36) -> 1226000 | N36: =M36 -> 1226000
B37: Construction in progress | I37: 2371730 | K37: 908068 | M37: =SUM(I37:L37) -> 3279798 | N37: =SUM(M37) -> 3279798
C38: Total assets not being depreciated | I38: =SUM(I35:I37) -> 4859598 | J38: =SUM(J35:J37) -> 0 | K38: =SUM(K35:K37) -> 947978 | L38: =SUM(L35:L37) -> 0 | M38: =SUM(M35:M37) -> 5807576
A40: Capital assets being depreciated:
B41: Furniture, equipment and vehicles | I41: 23293000 | J41: 0 | K41: 0 | L41: 0 | M41: =SUM(I41:L41) -> 23293000
B42: Buildings and improvements | I42: 11488000 | J42: 939000 | K42: -93000 | L42: 0 | M42: =SUM(I42:L42) -> 12334000
C43: Total capital assets being depreciated | I43: =SUM(I41:I42) -> 34781000 | J43: =SUM(J41:J42) -> 939000 | K43: =SUM(K41:K42) -> -93000 | L43: =SUM(L41:L42) -> 0 | M43: =SUM(M41:M42) -> 35627000
A45: Less accumulated depreciation for:
B46: Furniture, equipment and vehicles | I46: -9558000 | J46: -434000 | K46: 0 | L46: 0 | M46: =SUM(I46:L46) -> -9992000 | N46: =SUM(M46,M41) -> 13301000
B47: Buildings and improvements | I47: -8378000 | J47: -1186000 | K47: 93000 | L47: 0 | M47: =SUM(I47:L47) -> -9471000 | N47: =SUM(M47,M42) -> 2863000
C48: Total accumulated depreciation | I48: =SUM(I46:I47) -> -17936000 | J48: =SUM(J46:J47) -> -1620000 | K48: =SUM(K46:K47) -> 93000 | L48: =SUM(L46:L47) -> 0 | M48: =SUM(M46:M47) -> -19463000
B49: Total capital assets being depreciated, net | I49: =SUM(I48,I43) -> 16845000 | J49: =SUM(J48,J43) -> -681000 | K49: =SUM(K48,K43) -> 0 | L49: =SUM(L48,L43) -> 0 | M49: =SUM(M48,M43) -> 16164000
...

Sheet Caddo
D1: CADDO PARISH POLICE JURY
D2: Capital Assets
D3: For the Year Ended December 31, 2013
I5: Beginning Balance | J5: Prior Period Adjustment | K5: Additions | L5: Deletions | M5: Ending Balance | N5: Cross Sectional
A7: Primary Government
A8: Government Activities:
A9: Capital assets, not being depreciated:
B10: Land and land improvements | I10: 14587873 | J10: -10612 | K10: 8410 | L10: -7262 | M10: =SUM(I10:L10) -> 14578409 | N10: =SUM(M10) -> 14578409
B11: Construction in progress - Infrastructure | I11: 1490456 | K11: 3926421 | L11: -5206264 | M11: =SUM(I11:L11) -> 210613 | N11: =M11 -> 210613
B12: Construction in progress | I12: 11194813 | K12: 3654638 | L12: -1077180 | M12: =SUM(I12:L12) -> 13772271 | N12: =SUM(M12) -> 13772271
C13: Total assets not being depreciated | I13: =SUM(I10:I12) -> 27273142 | J13: =SUM(J10:J12) -> -10612 | K13: =SUM(K10:K12) -> 7589469 | L13: =SUM(L10:L12) -> -6290706 | M13: =SUM(M10:M12) -> 28561293
A15: Capital assets being depreciated:
B16: Buildings and structures | I16: 89670371 | K16: 209580 | L16: -14742 | M16: =SUM(I16:L16) -> 89865209
B17: Equipment and vehicles | I17: 36255276 | K17: 3680568 | L17: -1631252 | M17: =SUM(I17:L17) -> 38304592
B18: Infrastructure | I18: 377842136 | J18: -875719 | K18: 10230871 | L18: -555242 | M18: =SUM(I18:L18) -> 386642046
C19: Total capital assets being depreciated | I19: =SUM(I16:I18) -> 503767783 | J19: =SUM(J16:J18) -> -875719 | K19: =SUM(K16:K18) -> 14121019 | L19: =SUM(L16:L18) -> -2201236 | M19: =SUM(M16:M18) -> 514811847
A21: Less accumulated depreciation for:
B22: Buildings and structures | I22: -34803394 | K22: -2184659 | L22: 12531 | M22: =SUM(I22:L22) -> -36975522 | N22: =SUM(M22,M16) -> 52889687
B23: Equipment and vehicles | I23: -25304064 | K23: -2765310 | L23: 1616376 | M23: =SUM(I23:L23) -> -26452998 | N23: =SUM(M23,M17) -> 11851594
B24: Infrastructure | I24: -257070930 | J24: -1495833 | K24: -11108932 | L24: 0 | M24: =SUM(I24:L24) -> -269675695 | N24: =M18+M24 -> 116966351
C25: Total accumulated depreciation | I25: =SUM(I22:I24) -> -317178388 | J25: =SUM(J22:J24) -> -1495833 | K25: =SUM(K22:K24) -> -16058901 | L25: =SUM(L22:L24) -> 1628907 | M25: =SUM(M22:M24) -> -333104215
B26: Total capital assets being depreciated, net | I26: =I25+I19 -> 186589395 | J26: =J25+J19 -> -2371552 | K26: =K25+K19 -> -1937882 | L26: =L25+L19 -> -572329 | M26: =M25+M19 -> 181707632
B27: Governmental activities capital assets, net | I27: =I13+I26 -> 213862537 | J27: =J13+J26 -> -2382164 | K27: =K13+K26 -> 5651587 | L27: =L13+L26 -> -6863035 | M27: =M13+M26 -> 210268925 | N27: =SUM(N22:N24,N10:N12) -> 210268925

Sheet Calcasieu
D1: CALCASIEU PARISH POLICE JURY
D2: Capital Assets
D3: For the Year Ended December 31, 2013
I5: Balance 1/1/2013 | J5: Additions | K5: Deletions | L5: Balance 12/31/2013 | M5: Cross Sectional
A7: Governmental Activities:
B8: Capital assets, not being depreciated:
C9: Land and right-of-ways | I9: 16832923 | J9: 711623 | L9: =SUM(I9:K9) -> 17544546 | M9: =SUM(L9) -> 17544546
C10: Construction in progress | I10: 23845079 | J10: 12115481 | K10: -19108040 | L10: =SUM(I10:K10) -> 16852520 | M10: =SUM(L10) -> 16852520
C11: Roads | I11: 382296012 | J11: 1021270 | L11: =SUM(I11:K11) -> 383317282 | M11: =SUM(L11) -> 383317282
D12: Total capital assets, not being depreciated | I12: =SUM(I8:I11) -> 422974014 | J12: =SUM(J8:J11) -> 13848374 | K12: =SUM(K8:K11) -> -19108040 | L12: =SUM(L8:L11) -> 417714348
A14: Capital assets being depreciated:
B15: Buildings and improvements | I15: 122300990 | J15: 5892103 | K15: -411314 | L15: =SUM(I15:K15) -> 127781779
B16: Machinery and equipment | I16: 30856097 | J16: 4406050 | K16: -2193615 | L16: =SUM(I16:K16) -> 33068532
B17: Bridges | I17: 11887348 | L17: =SUM(I17:K17) -> 11887348
D18: Total capital assets being depreciated | I18: =SUM(I15:I17) -> 165044435 | J18: =SUM(J15:J17) -> 10298153 | K18: =SUM(K15:K17) -> -2604929 | L18: =SUM(L15:L17) -> 172737659
A20: Less accumulated depreciation for:
B21: Buildings and improvements | I21: -51800073 | J21: -3362407 | K21: 59555 | L21: =SUM(I21:K21) -> -55102925 | M21: =SUM(L21,L15) -> 72678854
B22: Machinery and equipment | I22: -20158778 | J22: -2976760 | K22: 2182803 | L22: =SUM(I22:K22) -> -20952735 | M22: =SUM(L22,L16) -> 12115797
B23: Bridges | I23: -3689827 | J23: -263075 | L23: =SUM(I23:K23) -> -3952902 | M23: =SUM(L23,L17) -> 7934446
D24: Total accumulated depreciation | I24: =SUM(I21:I23) -> -75648678 | J24: =SUM(J21:J23) -> -6602242 | K24: =SUM(K21:K23) -> 2242358 | L24: =SUM(L21:L23) -> -80008562
B25: Total capital assets being depreciated, net | I25: =I18+I24 -> 89395757 | J25: =J18+J24 -> 3695911 | K25: =K18+K24 -> -362571 | L25: =L18+L24 -> 92729097
B26: Total governmental activities capital assets, net | I26: =I24+I18+I12 -> 512369771 | J26: =J24+J18+J12 -> 17544285 | K26: =K24+K18+K12 -> -19470611 | L26: =L24+L18+L12 -> 510443445 | M26: =SUM(M21:M23,M9:M11) -> 510443445
I29: Balance 1/1/2013 | J29: Decreases | K29: Adjustments | L29: Balance 12/31/2013
A30: Business-Type Activities:
B31: Capital assets, not being depreciated:
C32: Land and right-of-ways | I32: 227920 | L32: =SUM(I32:K32) -> 227920 | M32: =SUM(L32) -> 227920
C33: Construction in progress | I33: 91303 | J33: 904198 | K33: -276681 | L33: =SUM(I33:K33) -> 718820 | M33: =SUM(L33) -> 718820
D34: Total capital assets, not being depreciated | I34: =SUM(I31:I33) -> 319223 | J34: =SUM(J31:J33) -> 904198 | K34: =SUM(K31:K33) -> -276681 | L34: =SUM(L31:L33) -> 946740
A36: Capital assets being depreciated:
B37: Non-Building improvements | I37: 10043068 | J37: 175351 | L37: =SUM(I37:K37) -> 10218419
B38: Building and improvements | I38: 100350 | J38: 3043 | L38: =SUM(I38:K38) -> 103393
B39: Infrastructure | I39: 3016772 | J39: 103515 | L39: =SUM(I39:K39) -> 3120287
B40: Machinery and equipment | I40: 512284 | J40: 5667 | K40: -274386 | L40: =SUM(I40:K40) -> 243565
D41: Total capital assets being depreciated | I41: =SUM(I37:I40) -> 13672474 | J41: =SUM(J37:J40) -> 287576 | K41: =SUM(K37:K40) -> -274386 | L41: =SUM(L37:L40) -> 13685664
A43: Less accumulated depreciation for:
B44: Non-Building improvements | I44: -3057985 | J44: -279601 | L44: =SUM(I44:K44) -> -3337586 | M44: =SUM(L44,L37) -> 6880833
B45: Building and improvements | I45: -81008 | J45: -2065 | L45: =SUM(I45:K45) -> -83073 | M45: =SUM(L45,L38) -> 20320
B46: Infrastructure | I46: -1634374 | J46: -125269 | L46: =SUM(I46:K46) -> -1759643 | M46: =SUM(L46,L39) -> 1360644
B47: Machinery and equipment | I47: -467117 | J47: -12112 | K47: 274386 | L47: =SUM(I47:K47) -> -204843 | M47: =SUM(L47,L40) -> 38722
D48: Total accumulated depreciation | I48: =SUM(I44:I47) -> -5240484 | J48: =SUM(J44:J47) -> -419047 | K48: =SUM(K44:K47) -> 274386 | L48: =SUM(L44:L47) -> -5385145
...

Sheet Caldwell
D1: CALDWELL PARISH POLICE JURY
D2: Capital Assets
D3: For the Year Ended December 31, 2013
G5: Beginning Balance | H5: Increases | I5: Decreases | J5: Ending Balance | K5: Cross Sectional
A7: Governmental Activities:
B8: Capital assets, not being depreciated:
C9: Land | G9: 420095 | J9: =SUM(G9:I9) -> 420095 | K9: =SUM(J9) -> 420095
C10: Construction in progress | G10: 7412928 | H10: 519426 | J10: =SUM(G10:I10) -> 7932354 | K10: =SUM(J10) -> 7932354
D12: Total capital assets, not being depreciated | G12: =SUM(G8:G11) -> 7833023 | H12: =SUM(H8:H11) -> 519426 | I12: =SUM(I8:I11) -> 0 | J12: =SUM(J8:J11) -> 8352449
A14: Capital assets being depreciated: | N14: =Caldwell!K30 -> 935
B15: Infrastructure:
C16: Roads | G16: 47897858 | J16: =SUM(G16:I16) -> 47897858
C17: Bridges | G17: 642997 | J17: =SUM(G17:I17) -> 642997
B18: Buildings and improvements | G18: 2914289 | H18: 63454 | I18: 0 | J18: =SUM(G18:I18) -> 2977743
B19: Land improvements | G19: 716214 | J19: =SUM(G19:I19) -> 716214
B20: Heavy equipment | G20: 1348353 | H20: 111861 | J20: =SUM(G20:I20) -> 1460214
B21: Vehicles | G21: 1158700 | H21: 28527 | J21: =SUM(G21:I21) -> 1187227
B22: Public works equipment | G22: 283107 | H22: 2599 | J22: =SUM(G22:I22) -> 285706
B23: Office furniture and equipment | G23: 577716 | J23: =SUM(G23:I23) -> 577716
D25: Total capital assets being depreciated | G25: =SUM(G16:G23) -> 55539234 | H25: =SUM(H16:H23) -> 206441 | I25: =SUM(I16:I23) -> 0 | J25: =SUM(J16:J23) -> 55745675
A27: Less accumulated depreciation for:
B28: Infrastructure:
C29: Roads | G29: -46001271 | H29: -149992 | J29: =SUM(G29:I29) -> -46151263 | K29: =J16+J29 -> 1746595
C30: Bridges | G30: -642014 | H30: -48 | J30: =SUM(G30:I30) -> -642062 | K30: =J17+J30 -> 935
B31: Buildings and improvements | G31: -2585383 | H31: -16226 | I31: 0 | J31: =SUM(G31:I31) -> -2601609 | K31: =J18+J31 -> 376134
B32: Land improvements | G32: -155374 | H32: -30960 | J32: =SUM(G32:I32) -> -186334 | K32: =J19+J32 -> 529880
B33: Heavy equipment | G33: -1122896 | H33: -46857 | J33: =SUM(G33:I33) -> -1169753 | K33: =J20+J33 -> 290461
B34: Vehicles | G34: -1008367 | H34: -65499 | J34: =SUM(G34:I34) -> -1073866 | K34: =J21+J34 -> 113361
B35: Public works equipment | G35: -80043 | H35: -25467 | J35: =SUM(G35:I35) -> -105510 | K35: =J22+J35 -> 180196
B36: Office furniture and equipment | G36: -413330 | H36: -35231 | J36: =SUM(G36:I36) -> -448561 | K36: =J23+J36 -> 129155
D38: Total accumulated depreciation | G38: =SUM(G29:G36) -> -52008678 | H38: =SUM(H29:H36) -> -370280 | I38: =SUM(I29:I36) -> 0 | J38: =SUM(J29:J36) -> -52378958
B40: Total capital assets being depreciated, net | G40: =G38+G25 -> 3530556 | H40: =H38+H25 -> -163839 | I40: =I38+I25 -> 0 | J40: =J38+J25 -> 3366717
B42: Governmental activities capital assets, net | G42: =G40+G12 -> 11363579 | H42: =H40+H12 -> 355587 | I42: =I40+I12 -> 0 | J42: =J40+J12 -> 11719166 | K42: =SUM(K9:K36) -> 11719166

Sheet Cameron
D1: CAMERON PARISH POLICE JURY
D2: Capital Assets
D3: For the Year Ended December 31, 2013
G5: Beginning Balance | H5: Increases | I5: Decreases | J5: Ending Balance | K5: Cross Sectional
C7: Land | G7: 1381390 | J7: =SUM(G7:I7) -> 1381390 | K7: =J7 -> 1381390
C8: Construction in progress | G8: 9198240 | H8: 15405895 | I8: -3808770 | J8: =SUM(G8:I8) -> 20795365 | K8: =J8 -> 20795365 | M8: Depreciation
B9: Buildings and improvements | G9: 35278285 | H9: 158249 | I9: 0 | J9: =SUM(G9:I9) -> 35436534 | K9: =J9-M9 -> 29213490 | L9: =J9/M14 -> 0.32612693 | M9: =J16*L9 -> 6223044.2
B10: Books and videos | G10: 702647 | J10: =SUM(G10:I10) -> 702647 | K10: =J10-M10 -> 579254.48 | L10: =J10/M14 -> 0.0064665497 | M10: =J16*L10 -> 123392.52
B11: Equipment and furniture | G11: 17493034 | H11: 1214585 | I11: -563297 | J11: =SUM(G11:I11) -> 18144322 | K11: =J11-M11 -> 14957980 | L11: =J11/M14 -> 0.1669845 | M11: =J16*L11 -> 3186342
B12: Infrastructure | G12: 50724694 | H12: 3650521 | I12: 0 | J12: =SUM(G12:I12) -> 54375215 | K12: =J12-M12 -> 44826331 | L12: =J12/M14 -> 0.50042202 | M12: =J16*L12 -> 9548884.3
M13: Total capital assets being depreciated
D14: Total capital assets being depreciated | G14: =SUM(G7:G12) -> 114778290 | H14: =SUM(H7:H12) -> 20429250 | I14: =SUM(I7:I12) -> -4372067 | J14: =SUM(J7:J12) -> 130835473 | L14: =SUM(L9:L12) -> 1 | M14: =+J9+J10+J11++J12 -> 108658718
A16: Less accumulated depreciation | G16: 15476036 | H16: 4168924 | I16: -563297 | J16: =SUM(G16:I16) -> 19081663
B18: Total capital assets being depreciated, net | G18: =G14-G16 -> 99302254 | H18: =H14-H16 -> 16260326 | I18: =I14-I16 -> -3808770 | J18: =J14-J16 -> 111753810 | K18: =SUM(K7:K12) -> 111753810

Sheet Catahoula
D1: CATAHOULA PARISH POLICE JURY
D2: Capital Assets
D3: For the Year Ended December 31, 2013
I5: Beginning Balance | J5: Increases | K5: Decreases | L5: Ending Balance | M5: Cross Sectional
A7: Governmental Activities:
B8: Capital assets, not being depreciated:
C9: Land | I9: 112200 | K9: 0 | L9: =SUM(I9:K9) -> 112200 | M9: =SUM(L9) -> 112200
C10: Construction in progress | L10: =SUM(I10:K10) -> 0 | M10: =SUM(L10) -> 0
D12: Total capital assets, not being depreciated | I12: =SUM(I8:I11) -> 112200 | J12: =SUM(J8:J11) -> 0 | K12: =SUM(K8:K11) -> 0 | L12: =SUM(L8:L11) -> 112200
A14: Capital assets being depreciated:
B15: Infrastructure - roads and bridges | I15: 11318548 | J15: 70926 | L15: =SUM(I15:K15) -> 11389474
B16: Buildings | I16: 2983414 | K16: 0 | L16: =SUM(I16:K16) -> 2983414
B17: Improvements | I17: 1558229 | L17: =SUM(I17:K17) -> 1558229
B18: Equipment | I18: 1464919 | J18: 87117 | K18: -80450 | L18: =SUM(I18:K18) -> 1471586
B19: Heavy equipment | I19: 892178 | J19: 33895 | L19: =SUM(I19:K19) -> 926073
B20: Vehicles | I20: 441923 | J20: 108476 | L20: =SUM(I20:K20) -> 550399
B21: Books and periodicals | I21: 669345 | J21: 38586 | K21: -17046 | L21: =SUM(I21:K21) -> 690885
D23: Total capital assets being depreciated | I23: =SUM(I15:I21) -> 19328556 | J23: =SUM(J15:J21) -> 339000 | K23: =SUM(K15:K21) -> -97496 | L23: =SUM(L15:L21) -> 19570060
A25: Less accumulated depreciation for:
B26: Infrastructure - roads and bridges | I26: 8256786 | J26: 111334 | L26: =SUM(I26:K26) -> 8368120 | M26: =L15-L26 -> 3021354
B27: Buildings | I27: 2531257 | J27: 22306 | K27: 0 | L27: =SUM(I27:K27) -> 2553563 | M27: =L16-L27 -> 429851
B28: Improvements | I28: 149509 | J28: 64696 | K28: -80450 | L28: =SUM(I28:K28) -> 133755 | M28: =L17-L28 -> 1424474
B29: Equipment | I29: 1140465 | J29: 80953 | L29: =SUM(I29:K29) -> 1221418 | M29: =L18-L29 -> 250168
B30: Heavy equipment | I30: 574687 | J30: 55392 | L30: =SUM(I30:K30) -> 630079 | M30: =L19-L30 -> 295994
B31: Vehicles | I31: 253712 | J31: 46489 | L31: =SUM(I31:K31) -> 300201 | M31: =L20-L31 -> 250198
B32: Books and periodicals | I32: 601853 | J32: 27501 | K32: -17046 | L32: =SUM(I32:K32) -> 612308 | M32: =L21-L32 -> 78577
D34: Total accumulated depreciation | I34: =SUM(I26:I32) -> 13508269 | J34: =SUM(J26:J32) -> 408671 | K34: =SUM(K26:K32) -> -97496 | L34: =SUM(L26:L32) -> 13819444
B36: Total capital assets being depreciated, net | I36: =I23-I34 -> 5820287 | J36: =J23-J34 -> -69671 | K36: =K23-K34 -> 0 | L36: =L23-L34 -> 5750616
B38: Governmental activities capital assets, net | I38: =I36+I12 -> 5932487 | J38: =J36+J12 -> -69671 | K38: =K36+K12 -> 0 | L38: =L36+L12 -> 5862816 | M38: =SUM(M9:M32,) -> 5862816
I41: Beginning Balance | J41: Increases | K41: Decreases | L41: Ending Balance
A42: Business-Type Activities:
B43: Capital assets, not being depreciated:
C44: Land | J44: 0 | K44: 0 | L44: =SUM(I44:K44) -> 0 | M44: =SUM(L44) -> 0
C45: Construction in progress | K45: 0 | L45: =SUM(I45:K45) -> 0 | M45: =SUM(L45) -> 0
D47: Total capital assets, not being depreciated | I47: =SUM(I43:I46) -> 0 | J47: =SUM(J43:J46) -> 0 | K47: =SUM(K43:K46) -> 0 | L47: =SUM(L43:L46) -> 0
B49: Capital assets, depreciable:
C50: Buildings and improvements | I50: 88375 | K50: 0 | L50: =SUM(I50:K50) -> 88375
C51: Office furniture and equipment | I51: 74150 | K51: 0 | L51: =SUM(I51:K51) -> 74150
D53: Total capital assets, depreciable | I53: =SUM(I49:I51) -> 162525 | J53: =SUM(J49:J51) -> 0 | K53: =SUM(K49:K51) -> 0 | L53: =SUM(L49:L51) -> 162525
B55: Less accumulated depreciation for:
...

Sheet Claiborne
D1: CLAIBORNE PARISH POLICE JURY
D2: Capital Assets
D3: For the Year Ended December 31, 2013
G5: Beginning Balance | H5: Adjustments | I5: Additions | J5: Deletions | K5: Ending Balance | L5: Cross Sectional
A7: Governmental Activities:
B8: Capital assets, not being depreciated:
C9: Land:
D10: Police jury | G10: 49900 | K10: =SUM(G10:J10) -> 49900 | L10: =SUM(K10) -> 49900
D11: Library | H11: 3580 | K11: =SUM(G11:J11) -> 3580 | L11: =SUM(K11) -> 3580
D12: Office of community services | G12: 30000 | K12: =SUM(G12:J12) -> 30000 | L12: =SUM(K12) -> 30000
D13: Adjudicated property | G13: 15360 | K13: =SUM(G13:J13) -> 15360 | L13: =SUM(K13) -> 15360
C14: Construction in progress | G14: 235496 | H14: -3580 | I14: 2109471 | K14: =SUM(G14:J14) -> 2341387 | L14: =SUM(K14) -> 2341387
D16: Total capital assets, not being depreciated | G16: =SUM(G10:G14) -> 330756 | H16: =SUM(H10:H14) -> 0 | I16: =SUM(I10:I14) -> 2109471 | J16: =SUM(J10:J14) -> 0 | K16: =SUM(K10:K14) -> 2440227
A18: Capital assets being depreciated: | O18: =Caldwell!K30 -> 935
B19: Infrastructure:
C20: Roads | G20: 15517189 | K20: =SUM(G20:J20) -> 15517189
C21: Bridges | G21: 1912668 | K21: =SUM(G21:J21) -> 1912668
B22: Land improvements | G22: 15995 | I22: 0 | K22: =SUM(G22:J22) -> 15995
B23: Buildings and improvements | G23: 2549623 | K23: =SUM(G23:J23) -> 2549623
B24: Public works heavy equipment | G24: 2705883 | I24: 225117 | J24: -81315 | K24: =SUM(G24:J24) -> 2849685
B25: Public works other equipment | G25: 82575 | K25: =SUM(G25:J25) -> 82575
B26: Vehicles | G26: 201599 | I26: 46198 | J26: -15350 | K26: =SUM(G26:J26) -> 232447
B27: Office furniture and equipment | G27: 249691 | K27: =SUM(G27:J27) -> 249691
B28: Office of emergency preparedness and homeland security:
C29: Vehicles | G29: 45517 | K29: =SUM(G29:J29) -> 45517
C30: Office furniture and equipment | G30: 50506 | K30: =SUM(G30:J30) -> 50506
C31: Buildings and improvements | G31: 13205 | K31: =SUM(G31:J31) -> 13205
B32: Office of community services:
C33: Land improvements | G33: 7800 | K33: =SUM(G33:J33) -> 7800
C34: Buildings and improvements | G34: 62156 | K34: =SUM(G34:J34) -> 62156
C35: Vehicles | G35: 430873 | I35: 44620 | J35: -22530 | K35: =SUM(G35:J35) -> 452963
C36: Office furniture and equipment | G36: 116327 | K36: =SUM(G36:J36) -> 116327
B37: Library:
C38: Buildings and improvements | G38: 797365 | J38: -6999 | K38: =SUM(G38:J38) -> 790366
C39: Vehicle | G39: 49901 | K39: =SUM(G39:J39) -> 49901
C40: Furniture and equipment | G40: 91746 | I40: 37009 | J40: -32601 | K40: =SUM(G40:J40) -> 96154
C41: Books and videos | G41: 771167 | I41: 29537 | J41: -40881 | K41: =SUM(G41:J41) -> 759823
D43: Total capital assets being depreciated | G43: =SUM(G20:G41) -> 25671786 | H43: =SUM(H20:H41) -> 0 | I43: =SUM(I20:I41) -> 382481 | J43: =SUM(J20:J41) -> -199676 | K43: =SUM(K20:K41) -> 25854591
A45: Less accumulated depreciation for:
B46: Infrastructure:
...

Sheet Concordia
D1: CONCORDIA PARISH POLICE JURY
D2: Capital Assets
D3: For the Year Ended December 31, 2013
G5: Balance at January 1, 2013 | H5: Reclassification | I5: Additions | J5: Retirements | K5: Balance December 12, 2013 | L5: Cross Sectional
A7: Governmental Activities:
B8: Land - nondepreciable | G8: 7038 | K8: =SUM(G8:J8) -> 7038 | L8: =K8 -> 7038
B9: Depreciable assets: | N9: % of Depreciable Assets | O9: Accumulated Depreciation
C10: Buildings | G10: 5522117 | H10: 23394 | I10: 383639 | K10: =SUM(G10:J10) -> 5929150 | N10: =K10/K16 -> 0.26803184 | O10: =K24*N10 -> -3003986.4
C11: Furniture and fixtures | G11: 441519 | K11: =SUM(G11:J11) -> 441519 | N11: =K11/K16 -> 0.01995921 | O11: =K24*N11 -> -223694.3
C12: Machinery and equipment | G12: 2416110 | I12: 89142 | K12: =SUM(G12:J12) -> 2505252 | N12: =K12/K16 -> 0.11325187 | O12: =K24*N12 -> -1269278.6
C13: Transportation equipment | G13: 1028979 | I13: 20708 | K13: =SUM(G13:J13) -> 1049687 | N13: =K13/K16 -> 0.047451918 | O13: =K24*N13 -> -531820.83
C14: Roads and bridges | G14: 12195458 | K14: =SUM(G14:J14) -> 12195458 | N14: =K14/K16 -> 0.55130517 | O14: =K24*N14 -> -6178792.9
C15: Construction in progress | G15: 23394 | H15: -23394 | K15: =SUM(G15:J15) -> 0 | N15: =K15/K27 -> 0
D16: Subtotal | G16: =SUM(G10:G15) -> 21627577 | H16: =SUM(H10:H15) -> 0 | I16: =SUM(I10:I15) -> 493489 | J16: =SUM(J10:J15) -> 0 | K16: =SUM(K10:K15) -> 22121066 | N16: =SUM(N10:N15) -> 1 | O16: =SUM(O10:O15) -> -11207573
C18: Buildings | K18: -3003986 | L18: =SUM(K10+K18) -> 2925164
C19: Furniture and fixtures | K19: -223694 | L19: =SUM(K11+K19) -> 217825
C20: Machinery and equipment | K20: -1269279 | L20: =SUM(K12+K20) -> 1235973
C21: Transportation equipment | K21: -531821 | L21: =SUM(K13+K21) -> 517866
C22: Roads and bridges | K22: -6178793 | L22: =SUM(K14+K22) -> 6016665
C23: Construction in progress | L23: =SUM(K15+K23) -> 0
D24: Less accumulated depreciation | G24: -10330886 | I24: -876687 | K24: =SUM(G24:J24) -> -11207573
C26: Net Police Jury fixed
D27: assets | G27: 11303729 | I27: -383198 | K27: =SUM(G27:J27) -> 10920531 | O27: =SUM(K8:K15)+K24 -> 10920531
C29: Total governmental activities capital assets, net | G29: =G16+G8+G24 -> 11303729 | H29: =H16+H8+H24 -> 0 | I29: =I16+I8+I24 -> -383198 | J29: =J16+J8+J24 -> 0 | K29: =K16+K8+K24 -> 10920531 | L29: =SUM(L8:L23) -> 10920531

Sheet DeSoto
D1: DESOTO PARISH POLICE JURY
D2: Capital Assets
D3: For the Year Ended December 31, 2013
I5: Balance 1/1/2013 | J5: Additions | K5: Deletions | L5: Balance 12/31/2013 | M5: Cross Sectional
A7: Governmental Activities:
B8: Capital assets, not being depreciated:
C9: Land | I9: 1980743 | J9: 20000 | K9: -20800 | L9: =SUM(I9:K9) -> 1979943 | M9: =SUM(L9) -> 1979943
C10: Construction in progress | I10: 2046951 | J10: 359254 | K10: -1907311 | L10: =SUM(I10:K10) -> 498894 | M10: =SUM(L10) -> 498894
D11: Total capital assets, not being depreciated | I11: =SUM(I8:I10) -> 4027694 | J11: =SUM(J8:J10) -> 379254 | K11: =SUM(K8:K10) -> -1928111 | L11: =SUM(L8:L10) -> 2478837
A13: Capital assets being depreciated:
B14: Buildings and improvements | I14: 26639391 | J14: 456368 | K14: -13331 | L14: =SUM(I14:K14) -> 27082428
B15: Land improvements - structures | I15: 2785535 | J15: 2407392 | L15: =SUM(I15:K15) -> 5192927
B16: Furniture and equipment | I16: 11864930 | J16: 566744 | K16: -40169 | L16: =SUM(I16:K16) -> 12391505
B17: Infrastructure | I17: 217009407 | J17: 1774323 | L17: =SUM(I17:J17) -> 218783730
D18: Total capital assets being depreciated | I18: =SUM(I14:I17) -> 258299263 | J18: =SUM(J14:J17) -> 5204827 | K18: =SUM(K14:K17) -> -53500 | L18: =SUM(L14:L17) -> 263450590
A20: Less accumulated depreciation for:
B21: Buildings and improvements | I21: 11112067 | J21: 663638 | K21: -7943 | L21: =SUM(I21:K21) -> 11767762 | M21: =L14-L21 -> 15314666
B22: Land improvements - structures | I22: 158146 | J22: 187507 | L22: =SUM(I22:K22) -> 345653 | M22: =L15-L22 -> 4847274
B23: Furniture and equipment | I23: 6830433 | J23: 1068469 | K23: -14175 | L23: =SUM(I23:K23) -> 7884727 | M23: =L16-L23 -> 4506778
B24: Infrastructure | I24: 168627234 | J24: 1932445 | L24: =SUM(I24:K24) -> 170559679 | M24: =L17-L24 -> 48224051
D25: Total accumulated depreciation | I25: =SUM(I21:I24) -> 186727880 | J25: =SUM(J21:J24) -> 3852059 | K25: =SUM(K21:K24) -> -22118 | L25: =SUM(L21:L24) -> 190557821
B26: Total capital assets being depreciated, net | I26: =I18-I25 -> 71571383 | J26: =J18-J25 -> 1352768 | K26: =K18-K25 -> -31382 | L26: =L18-L25 -> 72892769
B27: Total governmental activities capital assets, net | I27: =I26+I11 -> 75599077 | J27: =J26+J11 -> 1732022 | K27: =K26+K11 -> -1959493 | L27: =L26+L11 -> 75371606 | M27: =SUM(M21:M24,M9:M10) -> 75371606
I30: Balance 1/1/2013 | J30: Decreases | K30: Adjustments | L30: Balance 12/31/2013
A31: Business-Type Activities:
B32: Capital assets, not being depreciated:
C33: Land | I33: 10175 | L33: =SUM(I33:K33) -> 10175 | M33: =SUM(L33) -> 10175
D34: Total capital assets, not being depreciated | I34: =SUM(I32:I33) -> 10175 | J34: =SUM(J32:J33) -> 0 | K34: =SUM(K32:K33) -> 0 | L34: =SUM(L32:L33) -> 10175
A36: Capital assets being depreciated:
B37: Sewer system | I37: 373375 | L37: =SUM(I37:K37) -> 373375
B38: Treatment plant | I38: 101180 | K38: 0 | L38: =SUM(I38:K38) -> 101180
D39: Total capital assets being depreciated | I39: =SUM(I37:I38) -> 474555 | J39: =SUM(J37:J38) -> 0 | K39: =SUM(K37:K38) -> 0 | L39: =SUM(L37:L38) -> 474555
A41: Less accumulated depreciation for:
B42: Sewer system | I42: 373375 | L42: =SUM(I42:K42) -> 373375 | M42: =L37-L42 -> 0
B43: Treatment plant | I43: 101180 | L43: =SUM(I43:K43) -> 101180 | M43: =L38-L43 -> 0
D44: Total accumulated depreciation | I44: =SUM(I42:I43) -> 474555 | J44: =SUM(J42:J43) -> 0 | K44: =SUM(K42:K43) -> 0 | L44: =SUM(L42:L43) -> 474555
B45: Total capital assets being depreciated, net | I45: =I39-I44 -> 0 | J45: =J39+J44 -> 0 | K45: =K39+K44 -> 0 | L45: =L39-L44 -> 0
B46: Total business-type activities capital assets, net | I46: =I45+I34 -> 10175 | J46: =J45+J34 -> 0 | K46: =K45+K34 -> 0 | L46: =L45+L34 -> 10175 | M46: =SUM(M33:M43) -> 10175

Sheet East Baton Rouge
D1: EAST BATON ROUGE PARISH POLICE JURY
D2: Capital Assets
D3: For the Year Ended December 31, 2013
I5: Balance 1/1/2013 | J5: Transfers | K5: Additions | L5: Deletions | M5: Balance 12/31/2013 | N5: Cross Sectional
A7: Governmental Activities:
B8: Capital assets, not being depreciated:
C9: Land and right-of-way | I9: 11006200 | K9: 627124 | M9: =SUM(I9:K9) -> 11633324 | N9: =SUM(M9) -> 11633324
C10: Construction work in progress | I10: 9026422 | J10: -5977507 | K10: 8258836 | M10: =SUM(I10:K10) -> 11307751 | N10: =SUM(M10) -> 11307751
D11: Total capital assets, not being depreciated | I11: =SUM(I8:I10) -> 20032622 | J11: =SUM(J8:J10) -> -5977507 | K11: =SUM(K8:K10) -> 8885960 | M11: =SUM(M8:M10) -> 22941075
A13: Capital assets being depreciated:
B14: Buildings | I14: 107230589 | K14: 150605 | M14: =SUM(I14:K14) -> 107381194
B15: Improvements (other than buildings) and infrastructure | I15: 174611343 | J15: 5977507 | K15: 21236654 | M15: =SUM(I15:K15) -> 201825504
B16: Equipment and equipment under lease | I16: 3739203 | K16: 417665 | M16: =SUM(I16:K16) -> 4156868
D17: Total capital assets being depreciated | I17: =SUM(I14:I16) -> 285581135 | J17: =SUM(J14:J16) -> 5977507 | K17: =SUM(K14:K16) -> 21804924 | L17: =SUM(L14:L16) -> 0 | M17: =SUM(M14:M16) -> 313363566
A19: Less accumulated depreciation for:
B20: Buildings | I20: -18839429 | K20: -2579573 | M20: =SUM(I20:L20) -> -21419002 | N20: =SUM(M20,M14) -> 85962192
B21: Improvements (other than buildings) and infrastructure | I21: -36641632 | K21: -4686019 | M21: =SUM(I21:L21) -> -41327651 | N21: =SUM(M21,M15) -> 160497853
B22: Equipment and equipment under lease | I22: -2800310 | K22: -363030 | M22: =SUM(I22:L22) -> -3163340 | N22: =SUM(M22,M16) -> 993528
D23: Total accumulated depreciation | I23: =SUM(I20:I22) -> -58281371 | J23: =SUM(J20:J22) -> 0 | K23: =SUM(K20:K22) -> -7628622 | L23: =SUM(L20:L22) -> 0 | M23: =SUM(M20:M22) -> -65909993
B24: Total capital assets being depreciated, net | I24: =I17+I23 -> 227299764 | J24: =J17+J23 -> 5977507 | K24: =K17+K23 -> 14176302 | L24: =L17+L23 -> 0 | M24: =M17+M23 -> 247453573
B25: Total governmental activities capital assets, net | I25: =I23+I17+I11 -> 247332386 | J25: =J23+J17+J11 -> 0 | K25: =K23+K17+K11 -> 23062262 | L25: =L23+L17+L11 -> 0 | M25: =SUM(I25:L25) -> 270394648 | N25: =SUM(N20:N22,N9:N10) -> 270394648
I28: Balance 1/1/2013 | J28: Increases | K28: Decreases | L28: Adjustments | M28: Balance 12/31/2013
A29: Business-Type Activities:
B30: Capital assets, not being depreciated:
C31: Land and right-of-way | I31: 77556445 | J31: 4035196 | K31: -549917 | L31: -220441 | M31: =SUM(I31:L31) -> 80821283 | N31: =SUM(M31) -> 80821283
C32: Noise mitigation | I32: 57876615 | J32: 0 | K32: 0 | L32: 228103 | M32: =SUM(I32:L32) -> 58104718 | N32: =SUM(M32) -> 58104718
C33: Construction work in progress | I33: 211622261 | J33: 55345105 | K33: -371895 | L33: -150521537 | M33: =SUM(I33:L33) -> 116073934 | N33: =SUM(M33) -> 116073934
D34: Total capital assets, not being depreciated | I34: =SUM(I30:I33) -> 347055321 | J34: =SUM(J30:J33) -> 59380301 | K34: =SUM(K30:K33) -> -921812 | L34: =SUM(L30:L33) -> -150513875 | M34: =SUM(M30:M33) -> 254999935
A36: Capital assets being depreciated:
B37: Buildings | I37: 220610624 | J37: 4659163 | K37: 0 | L37: 9553872 | M37: =SUM(I37:L37) -> 234823659
B38: Improvements (other than buildings) and infrastructure | I38: 1536676864 | J38: 219826258 | K38: -10280399 | L38: 141207173 | M38: =SUM(I38:L38) -> 1887429896
B39: Equipment | I39: 11467460 | J39: 164403 | K39: -1055546 | L39: 0 | M39: =SUM(I39:L39) -> 10576317
D40: Total capital assets being depreciated | I40: =SUM(I37:I39) -> 1768754948 | J40: =SUM(J37:J39) -> 224649824 | K40: =SUM(K37:K39) -> -11335945 | L40: =SUM(L37:L39) -> 150761045 | M40: =SUM(M37:M39) -> 2132829872
A42: Less accumulated depreciation for:
B43: Buildings | I43: -100195132 | J43: -8368419 | K43: 0 | M43: =SUM(I43:L43) -> -108563551 | N43: =SUM(M43,M37) -> 126260108
B44: Improvements (other than buildings) and infrastructure | I44: -562556664 | J44: -56150837 | K44: 9252036 | M44: =SUM(I44:L44) -> -609455465 | N44: =SUM(M44,M38) -> 1277974431
B45: Equipment | I45: -10424064 | J45: -338853 | K45: 1051880 | M45: =SUM(I45:L45) -> -9711037 | N45: =SUM(M45,M39) -> 865280
D46: Total accumulated depreciation | I46: =SUM(I43:I45) -> -673175860 | J46: =SUM(J43:J45) -> -64858109 | K46: =SUM(K43:K45) -> 10303916 | L46: =SUM(L43:L45) -> 0 | M46: =SUM(M43:M45) -> -727730053
B47: Total capital assets being depreciated, net | I47: =I40+I46 -> 1095579088 | J47: =J40+J46 -> 159791715 | K47: =K40+K46 -> -1032029 | L47: =L40+L46 -> 150761045 | M47: =M40+M46 -> 1405099819
B48: Total business-type activities capital assets, net | I48: =I46+I40+I34 -> 1442634409 | J48: =J46+J40+J34 -> 219172016 | K48: =K46+K40+K34 -> -1953841 | L48: =L46+L40+L34 -> 247170 | M48: =SUM(I48:L48) -> 1660099754 | N48: =SUM(N43:N45,N31:N32,N33) -> 1660099754

Sheet East Carroll
D1: EAST CARROLL PARISH POLICE JURY
D2: Capital Assets
D3: For the Year Ended December 31, 2013
G5: Beginning Balance | H5: Additions | I5: Deletions | J5: Ending Balance | K5: Cross Sectional
A7: Governmental Activities:
B8: Capital assets, not being depreciated:
C9: Land | G9: 274665 | J9: =SUM(G9:I9) -> 274665 | K9: =SUM(J9) -> 274665
C10: Airport land | G10: 101000 | J10: =SUM(G10:I10) -> 101000 | K10: =SUM(J10) -> 101000
C11: Construction in progress | G11: 353730 | H11: 291155 | I11: -383121 | J11: =SUM(G11:I11) -> 261764 | K11: =SUM(J11) -> 261764
D12: Total capital assets, not being depreciated | G12: =SUM(G9:G11) -> 729395 | H12: =SUM(H9:H11) -> 291155 | I12: =SUM(I9:I11) -> -383121 | J12: =SUM(J9:J11) -> 637429
A14: Capital assets being depreciated: | N14: =Caldwell!K30 -> 935
B15: Buildings | G15: 2630747 | H15: 16081 | J15: =SUM(G15:I15) -> 2646828
B16: Office equipment | G16: 432022 | H16: 11948 | I16: 16888 | J16: =SUM(G16:I16) -> 460858
B17: Furniture and fixtures | G17: 105179 | H17: 14372 | J17: =SUM(G17:I17) -> 119551
B18: Construction equipment | G18: 1533590 | H18: 193895 | J18: =SUM(G18:I18) -> 1727485
B19: Vehicles | G19: 2292724 | H19: 106700 | J19: =SUM(G19:I19) -> 2399424
B20: Books, periodicals and law books | G20: 342548 | J20: =SUM(G20:I20) -> 342548
B21: Infrastructure:
C22: Airport hangars | G22: 25000 | J22: =SUM(G22:I22) -> 25000
C23: Airport runway | G23: 763626 | H23: 367040 | J23: =SUM(G23:I23) -> 1130666
C24: Road right-of-way | G24: 558234 | J24: =SUM(G24:I24) -> 558234 | K24: =J24 -> 558234
C25: Road surface | G25: 9140845 | J25: =SUM(G25:I25) -> 9140845
C26: Bridges | G26: 1759091 | J26: =SUM(G26:I26) -> 1759091
D27: Total capital assets being depreciated | G27: =SUM(G15:G26) -> 19583606 | H27: =SUM(H15:H26) -> 710036 | I27: =SUM(I15:I26) -> 16888 | J27: =SUM(J15:J26) -> 20310530
A29: Less accumulated depreciation:
B30: Buildings | G30: 1535390 | H30: 51129 | J30: =SUM(G30:I30) -> 1586519 | K30: =J15-J30 -> 1060309
B31: Office equipment | G31: 338093 | H31: 28604 | I31: -16888 | J31: =SUM(G31:I31) -> 349809 | K31: =J16-J31 -> 111049
B32: Furniture and fixtures | G32: 78239 | H32: 5834 | J32: =SUM(G32:I32) -> 84073 | K32: =J17-J32 -> 35478
B33: Construction equipment | G33: 1097614 | H33: 102043 | J33: =SUM(G33:I33) -> 1199657 | K33: =J18-J33 -> 527828
B34: Vehicles | G34: 1874824 | H34: 94659 | J34: =SUM(G34:I34) -> 1969483 | K34: =J19-J34 -> 429941
B35: Books, periodicals and law books | G35: 339855 | H35: 1795 | J35: =SUM(G35:I35) -> 341650 | K35: =J20-J35 -> 898
B36: Infrastructure:
C37: Airport hangars | G37: 23438 | H37: 625 | J37: =SUM(G37:I37) -> 24063 | K37: =J22-J37 -> 937
C38: Airport runway | G38: 181361 | H38: 23679 | J38: =SUM(G38:I38) -> 205040 | K38: =J23-J38 -> 925626
C39: Road surface | G39: 8397342 | H39: 35595 | J39: =SUM(G39:I39) -> 8432937 | K39: =J25-J39 -> 707908
C40: Bridges | G40: 1137577 | H40: 28620 | J40: =SUM(G40:I40) -> 1166197 | K40: =J26-J40 -> 592894
D42: Total accumulated depreciation | G42: =SUM(G30:G40) -> 15003733 | H42: =SUM(H30:H40) -> 372583 | J42: =SUM(J30:J40) -> 15359428
B44: Total capital assets being depreciated, net | G44: =G27-G42 -> 4579873 | H44: =H27-H42 -> 337453 | I44: =I27-I42 -> 16888 | J44: =J27-J42 -> 4951102
B46: Governmental activities capital assets, net | G46: =G44+G12 -> 5309268 | H46: =H44+H12 -> 628608 | J46: =J44+J12 -> 5588531 | K46: =SUM(K9:K40) -> 5588531

Sheet East Feliciana
D1: EAST FELICIANA PARISH POLICE JURY
D2: Capital Assets
D3: For the Year Ended December 31, 2013
I5: Beginning Balance | J5: Additions | K5: Deletions | L5: Ending Balance | M5: Cross Sectional
A7: Governmental Activities:
B8: Capital assets, not being depreciated:
C9: Land | I9: 259230 | L9: =SUM(I9:K9) -> 259230 | M9: =SUM(L9) -> 259230
D10: Total capital assets, not being depreciated | I10: =SUM(I8:I9) -> 259230 | J10: =SUM(J8:J9) -> 0 | K10: =SUM(K8:K9) -> 0 | L10: =SUM(L8:L9) -> 259230
A12: Capital assets being depreciated:
B13: Buildings | I13: 9627258.6 | L13: =SUM(I13:K13) -> 9627258.6
B14: Less: accumulated depreciation | I14: 4164529.8 | J14: 196840.7 | L14: =SUM(I14:J14) -> 4361370.5
D15: Net Buildings | I15: =I13-I14 -> 5462728.8 | J15: =J13-J14 -> -196840.7 | K15: =K13-K14 -> 0 | L15: =L13-L14 -> 5265888.1 | M15: =L13-L14 -> 5265888.1
B17: Equipment/Vehicles | I17: 3677798.9 | J17: 592096.43 | K17: -87400 | L17: =SUM(I17:K17) -> 4182495.3
B18: Less: accumulated depreciation | I18: 2273761.5 | J18: 164978.49 | K18: -87400 | L18: =SUM(I18:K18) -> 2351340
D19: Net Equipment/vehicles | I19: =I17-I18 -> 1404037.3 | J19: =J17-J18 -> 427117.94 | K19: =K17-K18 -> 0 | L19: =L17-L18 -> 1831155.3 | M19: =L17-L18 -> 1831155.3
B21: Streets/Bridges | I21: 1342103.2 | L21: =SUM(I21:K21) -> 1342103.2
B22: Less: accumulated depreciation | I22: 313695.63 | J22: 71604.32 | L22: =SUM(I22:K22) -> 385299.95
D23: Net Furniture and fixtures | I23: =I21-I22 -> 1028407.5 | J23: =J21-J22 -> -71604.32 | K23: =K21-K22 -> 0 | L23: =L21-L22 -> 956803.22 | M23: =L21-L22 -> 956803.22
B24: Capital assets, being depreciated, net | I24: =I23+I19+I15 -> 7895173.7 | J24: =J23+J19+J15 -> 158672.92 | K24: =K23+K19+K15 -> 0 | L24: =L23+L19+L15 -> 8053846.6
B25: Capital assets, net | I25: =I24+I10 -> 8154403.7 | J25: =J24+J10 -> 158672.92 | K25: =K24+K10 -> 0 | L25: =L24+L10 -> 8313076.6 | M25: =SUM(M9:M23) -> 8313076.6

Sheet Evangeline
D1: EVANGELINE PARISH POLICE JURY
D2: Capital Assets
D3: For the Year Ended December 31, 2013
I5: Beginning Balance | J5: Increases | K5: Decreases | L5: Ending Balance | M5: Cross Sectional
A7: Primary Government
A8: Government Activities:
A9: Capital assets, not being depreciated:
B10: Land | I10: 876298 | J10: 0 | K10: 0 | L10: =SUM(I10:K10) -> 876298 | M10: =SUM(L10) -> 876298
B11: Construction in progress | I11: 818496 | J11: 2647442 | K11: -1614513 | L11: =SUM(I11:K11) -> 1851425 | M11: =SUM(L11) -> 1851425
C12: Total assets not being depreciated | I12: =SUM(I10:I11) -> 1694794 | J12: =SUM(J10:J11) -> 2647442 | K12: =SUM(K10:K11) -> -1614513 | L12: =SUM(L10:L11) -> 2727723
A14: Capital assets being depreciated:
B15: Buildings and improvements | I15: 11360591 | J15: 197254 | K15: 0 | L15: =SUM(I15:K15) -> 11557845
B16: Infrastructure | I16: 19003541 | J16: 3376445 | K16: 0 | L16: =SUM(I16:K16) -> 22379986
B17: Vehicles | I17: 660291 | J17: 43985 | L17: =SUM(I17:K17) -> 704276
B18: Equipment, furniture and fixtures | I18: 5279409 | J18: 1204581 | K18: -100700 | L18: =SUM(I18:K18) -> 6383290
C19: Total capital assets being depreciated | I19: =SUM(I15:I18) -> 36303832 | J19: =SUM(J15:J18) -> 4822265 | K19: =SUM(K15:K18) -> -100700 | L19: =SUM(L15:L18) -> 41025397
A20: Less accumulated depreciation:
B21: Buildings | I21: 4177812 | J21: 303449 | K21: 0 | L21: =SUM(I21:K21) -> 4481261 | M21: =L15-L21 -> 7076584
B22: Infrastructure | I22: 9096921 | J22: 959297 | K22: 0 | L22: =SUM(I22:K22) -> 10056218 | M22: =L16-L22 -> 12323768
B23: Vehicles | I23: 520294 | J23: 58794 | L23: =SUM(I23:K23) -> 579088 | M23: =L17-L23 -> 125188
B24: Equipment, furniture and fixtures | I24: 3666099 | J24: 406557 | K24: -99600 | L24: =SUM(I24:K24) -> 3973056 | M24: =L18-L24 -> 2410234
C25: Total accumulated depreciation | I25: =SUM(I21:I24) -> 17461126 | J25: =SUM(J21:J24) -> 1728097 | K25: =SUM(K21:K24) -> -99600 | L25: =SUM(L21:L24) -> 19089623
B26: Total capital assets being depreciated, net | I26: =I19-I25 -> 18842706 | J26: =J19-J25 -> 3094168 | K26: =K19-K25 -> -1100 | L26: =L19-L25 -> 21935774
B27: Governmental activities capital assets, net | I27: =I12+I26 -> 20537500 | J27: =J12+J26 -> 5741610 | K27: =K12+K26 -> -1615613 | L27: =L12+L26 -> 24663497 | M27: =SUM(M21:M24,M10:M11) -> 24663497
I30: Beginning Balance | J30: Increases | K30: Decreases | L30: Ending Balance
A32: Business-type Activities:
A33: Capital assets being depreciated:
