Workbook

Sheet Acadia
D1: Acadia Combined Balance Sheet
D2: Issued: December 31, 2013
K4: General | L4: Parish Road Fund | M4: Sales Tax Fund | N4: 1% Sales Tax District No. 2 Fund | O4: Sales Tax Road Bond Construction Fund | P4: LCDBG Ike-Gustav Disaster Recovery Grant Fund | Q4: Other Governmental Funds | R4: Total Governmental Funds
A5: Assets:
B6: Cash | K6: 284024 | L6: 928317 | M6: 950888 | N6: 130207 | O6: 523402 | P6: 94 | Q6: 3570123 | R6: =SUM(K6:Q6) -> 6387055
B7: Investments | K7: 107505 | L7: 12732 | M7: 3954843 | N7: 136092 | Q7: 3147964 | R7: =SUM(K7:Q7) -> 7359136
B8: Taxes receivable | K8: 169205 | L8: 104453 | Q8: 139272 | R8: =SUM(K8:Q8) -> 412930
B9: Special assessments receivable | Q9: 29556 | R9: =SUM(K9:Q9) -> 29556
B10: Other receivables | K10: 70322 | L10: 2600 | Q10: 4875 | R10: =SUM(K10:Q10) -> 77797
B11: Due from other governmental entities, net of
C12: allowance for doubtful accounts | K12: 1989847 | L12: 1137887 | M12: 627654 | N12: 184794 | O12: 432 | P12: 134931 | Q12: 1533184 | R12: =SUM(K12:Q12) -> 5608729
B13: Due from other funds | K13: 87504 | R13: =SUM(K13:Q13) -> 87504
B14: Due from component units | K14: 20793 | R14: =SUM(K14:Q14) -> 20793
E16: Total assets: | K16: =SUM(K6:K14) -> 2729200 | L16: =SUM(L6:L14) -> 2185989 | M16: =SUM(M6:M14) -> 5533385 | N16: =SUM(N6:N14) -> 451093 | O16: =SUM(O6:O14) -> 523834 | P16: =SUM(P6:P14) -> 135025 | Q16: =SUM(Q6:Q14) -> 8424974 | R16: =SUM(R6:R14) -> 19983500
A18: LIABILITIES AND FUND BALANCES
B19: Liabilities:
C20: Accounts payable | K20: 153148 | L20: 23523 | M20: 263877 | N20: 2929 | O20: 127068 | P20: 134931 | Q20: 94381 | R20: =SUM(K20:Q20) -> 799857
C21: Retainage payable | O21: 30559 | R21: =SUM(K21:Q21) -> 30559
C22: Accrued liabilities and other payables | K22: 230524 | L22: 41019 | Q22: 54692 | R22: =SUM(K22:Q22) -> 326235
C23: Unearned revenue | L23: 26500 | R23: =SUM(K23:Q23) -> 26500
C24: Due to other funds | L24: 46135 | M24: 29407 | Q24: 11962 | R24: =SUM(K24:Q24) -> 87504
E26: Total liabilities: | K26: =SUM(K20:K24) -> 383672 | L26: =SUM(L20:L24) -> 137177 | M26: =SUM(M20:M24) -> 293284 | N26: =SUM(N20:N24) -> 2929 | O26: =SUM(O20:O24) -> 157627 | P26: =SUM(P20:P24) -> 134931 | Q26: =SUM(Q20:Q24) -> 161035 | R26: =SUM(R20:R24) -> 1270655
A28: DEFERRED INFLOWS OF RESOURCES
B29: Unavailable revenue - special assessments | Q29: 29556 | R29: =SUM(K29:Q29) -> 29556
B31: Fund Balances:
C32: Restricted for:
D33: Property tax dedication | K33: 547451 | L33: 2048812 | R33: =SUM(K33:Q33) -> 2596263
D34: Sales tax dedication | M34: 5240101 | N34: 448164 | R34: =SUM(K34:Q34) -> 5688265
D35: Debt retirement | Q35: 1587612 | R35: =SUM(K35:Q35) -> 1587612
D36: Mosquito control | Q36: 1541983 | R36: =SUM(K36:Q36) -> 1541983
D37: Cooperative extension operation and maintenance | Q37: 1361388 | R37: =SUM(K37:Q37) -> 1361388
C38: Committed to:
D39: Road maintenance and construction | Q39: 665302 | R39: =SUM(K39:Q39) -> 665302
D40: Health unit operation and maintenance | Q40: 1470338 | R40: =SUM(K40:Q40) -> 1470338
D41: Rice arena operation and maintenance | Q41: 726543 | R41: =SUM(K41:Q41) -> 726543
C42: Assigned to:
D43: Debt service | Q43: 3822 | R43: =SUM(K43:Q43) -> 3822
D44: Capital projects | O44: 366207 | P44: 94 | Q44: 8881 | R44: =SUM(K44:Q44) -> 375182
D45: Economic development | Q45: 658066 | R45: =SUM(K45:Q45) -> 658066
D46: Airport | Q46: 165470 | R46: =SUM(K46:Q46) -> 165470
...

Sheet Allen
D1: Allen Combined Balance Sheet
D2: Issued: December 31, 2013
K4: General Fund | L4: Solid Waste Fund | M4: Hospital Retrofit Fund | N4: Compact Fund | O4: Parish Road Fund | P4: Road District #2 MTC. Fund | Q4: Road District #3 MTC. Fund | R4: Nonmajor Governmental Funds | S4: Total Governmental Funds
A5: Assets:
B6: Cash | K6: 333065 | L6: 553695 | M6: 103600 | N6: 546048 | O6: 48 | P6: 606522 | Q6: 1397497 | R6: 978046 | S6: =SUM(K6:R6) -> 4518521
B7: Receivables | K7: 246603 | N7: 108339 | P7: 616160 | Q7: 636424 | R7: 1351112 | S7: =SUM(K7:R7) -> 2958638
B8: Due from other governments | K8: 333701 | L8: 139221 | O8: 64248 | R8: 12210 | S8: =SUM(K8:R8) -> 549380
B9: Inventory | R9: 25276 | S9: =SUM(K9:R9) -> 25276
B10: Due from other funds | K10: 37786 | P10: 224 | R10: 37065 | S10: =SUM(K10:R10) -> 75075
B11: Prepaid assets | K11: 4443 | S11: =SUM(K11:R11) -> 4443
E13: Total assets: | K13: =SUM(K6:K11) -> 955598 | L13: =SUM(L6:L11) -> 692916 | M13: =SUM(M6:M11) -> 103600 | N13: =SUM(N6:N11) -> 654387 | O13: =SUM(O6:O11) -> 64296 | P13: =SUM(P6:P11) -> 1222906 | Q13: =SUM(Q6:Q11) -> 2033921 | R13: =SUM(R6:R11) -> 2403709 | S13: =SUM(S6:S11) -> 8131333
A15: LIABILITIES AND FUND BALANCES
B16: Liabilities:
C17: Accounts payable | K17: 99341 | L17: 117700 | M17: 22888 | N17: 9411 | O17: 50034 | P17: 70560 | Q17: 31393 | R17: 84928 | S17: =SUM(K17:R17) -> 486255
C18: Unearned revenue | M18: 80554 | R18: 53913 | S18: =SUM(K18:R18) -> 134467
C19: Due to other funds | K19: 4923 | O19: 24829 | R19: 45323 | S19: =SUM(K19:R19) -> 75075
E21: Total liabilities: | K21: =SUM(K17:K19) -> 104264 | L21: =SUM(L17:L19) -> 117700 | M21: =SUM(M17:M19) -> 103442 | N21: =SUM(N17:N19) -> 9411 | O21: =SUM(O17:O19) -> 74863 | P21: =SUM(P17:P19) -> 70560 | Q21: =SUM(Q17:Q19) -> 31393 | R21: =SUM(R17:R19) -> 184164 | S21: =SUM(S17:S19) -> 695797
A23: DEFERRED INFLOWS OF RESOURCES
B24: Unavailable revenue | K24: 19870 | P24: 55725 | Q24: 33057 | R24: 124248 | S24: =SUM(K24:R24) -> 232900
B26: Fund Balances:
C27: Nonspendable - prepaids | K27: 4443 | S27: =SUM(K27:R27) -> 4443
C28: Nonspendable - inventory | R28: 25276 | S28: =SUM(K28:R28) -> 25276
C29: Restricted: | S29: =SUM(K29:R29) -> 0
D30: Judicial | R30: 349325 | S30: =SUM(K30:R30) -> 349325
D31: Other general government | N31: 644976 | S31: =SUM(K31:R31) -> 644976
D32: Public safety | R32: 874 | S32: =SUM(K32:R32) -> 874
D33: Public works | O33: 64248 | P33: 1096621 | Q33: 1969471 | R33: 1350120 | S33: =SUM(K33:R33) -> 4480460
D34: Economic development | R34: 37419 | S34: =SUM(K34:R34) -> 37419
D35: Sanitation | L35: 575216 | S35: =SUM(K35:R35) -> 575216
D36: Capital projects | M36: 158 | R36: 299866 | S36: =SUM(K36:R36) -> 300024
D37: Debt service | R37: 258 | S37: =SUM(K37:R37) -> 258
C38: Committed:
D39: Other general government | R39: 2041 | S39: =SUM(K39:R39) -> 2041
C40: Assigned:
D41: Other general government | R41: 28611 | S41: =SUM(K41:R41) -> 28611
D42: Public works | R42: 8696 | S42: =SUM(K42:R42) -> 8696
C43: Negative unassigned | O43: -74815 | R43: -7189 | S43: =SUM(K43:R43) -> -82004
C44: Unassigned | K44: 827021 | S44: =SUM(K44:R44) -> 827021
E46: Total fund balance: | K46: =SUM(K27:K44) -> 831464 | L46: =SUM(L27:L44) -> 575216 | M46: =SUM(M27:M44) -> 158 | N46: =SUM(N27:N44) -> 644976 | O46: =SUM(O27:O44) -> -10567 | P46: =SUM(P27:P44) -> 1096621 | Q46: =SUM(Q27:Q44) -> 1969471 | R46: =SUM(R27:R44) -> 2095297 | S46: =SUM(S27:S44) -> 7202636
E48: Total liabilities and fund balances: | K48: =K46+K24+K21 -> 955598 | L48: =L46+L24+L21 -> 692916 | M48: =M46+M24+M21 -> 103600 | N48: =N46+N24+N21 -> 654387 | O48: =O46+O24+O21 -> 64296 | P48: =P46+P24+P21 -> 1222906 | Q48: =Q46+Q24+Q21 -> 2033921 | R48: =R46+R24+R21 -> 2403709 | S48: =S46+S24+S21 -> 8131333

Sheet Ascension
D1: Ascension Combined Balance Sheet
D2: Issued: December 31, 2013
K4: General Fund | L4: East Ascension Frainage | M4: Road Project | N4: East Ascension Drainage Project | O4: Other Governmental Funds | P4: Total Governmental Funds
A5: Assets:
B6: Cash and Cash Equivalents | K6: 7650256 | L6: 10698675 | M6: 6271012 | N6: 2126894 | O6: 13491929 | P6: =SUM(K6:O6) -> 40238766
B7: Investments | K7: 13771194 | L7: 17691739 | M7: 10430652 | N7: 27003583 | O7: 20307033 | P7: =SUM(K7:O7) -> 89204201
B8: Accounts receivable, net:
C9: Ad valorem taxes | K9: 3836435 | L9: 4813187 | O9: 17811843 | P9: =SUM(K9:O9) -> 26461465
C10: Sales and use taxes | K10: 2542387 | L10: 1100217 | P10: =SUM(K10:O10) -> 3642604
C11: Other | K11: 729071 | L11: 30829 | M11: 18152 | N11: 53285 | O11: 796566 | P11: =SUM(K11:O11) -> 1627903
B12: Due from other governments:
C13: LA - State revenue sharing | K13: 85184 | L13: 148662 | O13: 705377 | P13: =SUM(K13:O13) -> 939223
C14: LA - Severance | K14: 26535 | P14: =SUM(K14:O14) -> 26535
C15: LA - Beer and Parish Transportation | K15: 17600 | O15: 227167 | P15: =SUM(K15:O15) -> 244767
C16: Grants | K16: 1333304 | L16: 652123 | O16: 1809555 | P16: =SUM(K16:O16) -> 3794982
B17: Due from other funds | K17: 3010 | L17: 117437 | M17: 430455 | O17: 592540 | P17: =SUM(K17:O17) -> 1143442
B18: Prepaid assets | O18: 43968 | P18: =SUM(K18:O18) -> 43968
B19: Other assets | K19: 54900 | L19: 42273 | P19: =SUM(K19:O19) -> 97173
E21: Total assets: | K21: =SUM(K6:K19) -> 30049876 | L21: =SUM(L6:L19) -> 35295142 | M21: =SUM(M6:M19) -> 17150271 | N21: =SUM(N6:N19) -> 29183762 | O21: =SUM(O6:O20) -> 55785978 | P21: =SUM(P6:P19) -> 167465029
A23: LIABILITIES AND FUND BALANCES
B24: Liabilities:
C25: Accounts payable and accrued liabilities | K25: 797442 | L25: 295446 | O25: 642993 | P25: =SUM(K25:O25) -> 1735881
C26: Contracts payable | K26: 22470 | L26: 48195 | M26: 614028 | N26: 2388718 | O26: 906633 | P26: =SUM(K26:O26) -> 3980044
C27: Accrued payroll | K27: 216728 | L27: 76127 | O27: 209360 | P27: =SUM(K27:O27) -> 502215
C28: Deductions from ad valorem taxes:
D29: Contribution to retirement system | K29: 121316 | L29: 159071 | O29: 591388 | P29: =SUM(K29:O29) -> 871775
C30: Due to Other Funds | K30: 1140432 | O30: 3005 | P30: =SUM(K30:O30) -> 1143437
C31: Due to other governments | L31: 269707 | P31: =SUM(K31:O31) -> 269707
C32: Sales tax rebate reserve | K32: 4524981 | P32: =SUM(K32:O32) -> 4524981
E34: Total liabilities: | K34: =SUM(K25:K32) -> 6823369 | L34: =SUM(L25:L32) -> 848546 | M34: =SUM(M25:M32) -> 614028 | N34: =SUM(N25:N32) -> 2388718 | O34: =SUM(O25:O33) -> 2353379 | P34: =SUM(P25:P32) -> 13028040
A36: DEFERRED INFLOWS OF RESOURCES
C37: Grant advances | K37: 133325 | O37: 496532 | P37: =SUM(K37:O37) -> 629857
C38: Unavailable revenues | K38: 13067 | L38: 50978 | O38: 1228120 | P38: =SUM(K38:O38) -> 1292165
E40: Total deferred inflows of resources | K40: =SUM(K37:K38) -> 146392 | L40: =SUM(L37:L38) -> 50978 | M40: =SUM(M37:M38) -> 0 | N40: =SUM(N37:N38) -> 0 | O40: =SUM(O37:O38) -> 1724652 | P40: =SUM(P37:P38) -> 1922022
B42: Fund Balances
C43: Nonspendable | O43: 43968 | P43: =SUM(K43:O43) -> 43968
C44: Restricted for:
D45: Construction of capital assets | N45: 26795044 | O45: 4741219 | P45: =SUM(K45:O45) -> 31536263
D46: Debt service | O46: 2137091 | P46: =SUM(K46:O46) -> 2137091
D47: Fire protection | O47: 13884329 | P47: =SUM(K47:O47) -> 13884329
...

Sheet Assumption
D1: Assumption Combined Balance Sheet
D2: Issued: December 31, 2013
K4: General | L4: Sales and Use Tax | M4: Solid Waste | N4: Section Eight Housing | O4: LCDBG Disaster Recovery | P4: Office of Emergency Preparedness | Q4: Other Governmental Funds | R4: Total Governmental Funds
A5: Assets:
B6: Cash and Cash Equivalents | K6: 1169651 | L6: 278184 | M6: 212663 | N6: 49165 | P6: 57492 | Q6: 2026649 | R6: =SUM(K6:Q6) -> 3793804
B7: Investments | K7: 4863676 | L7: 1191222 | M7: 905818 | P7: 202778 | Q7: 6692305 | R7: =SUM(K7:Q7) -> 13855799
B8: Receivables | K8: 1037836 | L8: 263060 | M8: 183707 | O8: 72263 | P8: 507955 | Q8: 3056849 | R8: =SUM(K8:Q8) -> 5121670
B9: Due from other funds | K9: 697185 | L9: 2848 | P9: 7724 | Q9: 33996 | R9: =SUM(K9:Q9) -> 741753
B10: Other assets | O10: 21100 | Q10: 6065 | R10: =SUM(K10:Q10) -> 27165
E12: Total assets: | K12: =SUM(K6:K10) -> 7768348 | L12: =SUM(L6:L10) -> 1735314 | M12: =SUM(M6:M10) -> 1302188 | N12: =SUM(N6:N10) -> 49165 | O12: =SUM(O6:O10) -> 93363 | P12: =SUM(P6:P10) -> 775949 | Q12: =SUM(Q6:Q10) -> 11815864 | R12: =SUM(R6:R10) -> 23540191
A14: LIABILITIES AND FUND BALANCES
B15: Liabilities:
C16: Accounts payable | K16: 28944 | L16: 28840 | M16: 272 | N16: 23 | O16: 31597 | P16: 274 | Q16: 587961 | R16: =SUM(K16:Q16) -> 677911
C17: Salaries payable | K17: 17481 | L17: 15698 | O17: 21100 | P17: 8539 | Q17: 76504 | R17: =SUM(K17:Q17) -> 139322
C18: Due to other funds | K18: 8766 | L18: 2371 | O18: 40666 | P18: 650013 | Q18: 39937 | R18: =SUM(K18:Q18) -> 741753
C19: Other liabilities | K19: 165591 | L19: 1703 | N19: 1238 | P19: 430 | Q19: 132264 | R19: =SUM(K19:Q19) -> 301226
E21: Total liabilities: | K21: =SUM(K16:K19) -> 220782 | L21: =SUM(L16:L19) -> 48612 | M21: =SUM(M16:M19) -> 272 | N21: =SUM(N16:N19) -> 1261 | O21: =SUM(O16:O19) -> 93363 | P21: =SUM(P16:P19) -> 659256 | Q21: =SUM(Q16:Q19) -> 836666 | R21: =SUM(R16:R19) -> 1860212
B23: Fund Balances
C24: Restricted | L24: 1686702 | N24: 40774 | Q24: 10503604 | R24: =SUM(K24:Q24) -> 12231080
C25: Assigned | K25: 19345 | M25: 1301916 | N25: 7130 | P25: 116693 | Q25: 475594 | R25: =SUM(K25:Q25) -> 1920678
C26: Unassigned | K26: 7528221 | R26: =SUM(K26:Q26) -> 7528221
E28: Total fund balance: | K28: =SUM(K24:K26) -> 7547566 | L28: =SUM(L24:L26) -> 1686702 | M28: =SUM(M24:M26) -> 1301916 | N28: =SUM(N24:N26) -> 47904 | O28: =SUM(O24:O26) -> 0 | P28: =SUM(P24:P26) -> 116693 | Q28: =SUM(Q24:Q26) -> 10979198 | R28: =SUM(R24:R26) -> 21679979
E30: Total liabilities and fund balances: | K30: =SUM(K28,K21) -> 7768348 | L30: =SUM(L28,L21) -> 1735314 | M30: =SUM(M28,M21) -> 1302188 | N30: =SUM(N28,N21) -> 49165 | O30: =SUM(O28,O21) -> 93363 | P30: =SUM(P21,P28) -> 775949 | Q30: =SUM(Q21,Q28) -> 11815864 | R30: =SUM(R21,R28) -> 23540191

Sheet Avoyelles
D1: Avoyelles Combined Balance Sheet
D2: Issued: December 31, 2013
K5: General | L5: Road & Bridge | M5: Solid Waste | N5: Drainage | O5: Health Unit | P5: Library | Q5: Section 8 | R5: Brudd Construction LCDBG | S5: Other Governmental Funds | T5: Total Governmental Funds
A6: Assets:
B7: Cash and interest-bearing deposits | K7: 666471 | L7: 1028187 | M7: 3132246 | N7: 426259 | O7: 1398435 | P7: 771760 | Q7: 233896 | S7: 150825 | T7: =SUM(K7:S7) -> 7808079
B8: Receivables | K8: 342206 | L8: 184936 | M8: 287174 | N8: 350440 | O8: 400149 | P8: 620385 | S8: 774 | T8: =SUM(K8:S8) -> 2186064
B9: Due from other governmental units | K9: 199650 | N9: 42822 | O9: 49559 | P9: 75840 | R9: 80073 | S9: 6717 | T9: =SUM(K9:S9) -> 454661
B10: Other assets | K10: 23691 | L10: 19602 | M10: 23953 | N10: 15559 | O10: 6465 | P10: 14414 | Q10: 1116 | T10: =SUM(K10:S10) -> 104800
E12: Total Assets: | K12: =SUM(K7:K10) -> 1232018 | L12: =SUM(L7:L10) -> 1232725 | M12: =SUM(M7:M10) -> 3443373 | N12: =SUM(N7:N10) -> 835080 | O12: =SUM(O7:O10) -> 1854608 | P12: =SUM(P7:P10) -> 1482399 | Q12: =SUM(Q7:Q10) -> 235012 | R12: =SUM(R7:R10) -> 80073 | ... T12: =SUM(T7:T10) -> 10553604
A14: DEFERRED OUTFLOWS OF RESOURCES
A16: LIABILITIES AND FUND BALANCES
B17: Liabilities:
C18: Accounts, salaries, and other payables | K18: 161498 | L18: 36204 | M18: 194682 | N18: 30154 | O18: 23931 | P18: 55804 | Q18: 1504 | R18: 75031 | S18: 9335 | T18: =SUM(K18:S18) -> 588143
C19: Deferred revenue | Q19: 36260 | T19: =SUM(K19:S19) -> 36260
C20: Due to other governmental units | Q20: 540 | R20: 5042 | S20: 32321 | T20: =SUM(K20:S20) -> 37903
E22: Total liabilities: | K22: =SUM(K18:K20) -> 161498 | L22: =SUM(L18:L20) -> 36204 | M22: =SUM(M18:M20) -> 194682 | N22: =SUM(N18:N21) -> 30154 | O22: =SUM(O18:O20) -> 23931 | P22: =SUM(P18:P20) -> 55804 | Q22: =SUM(Q18:Q20) -> 38304 | R22: =SUM(R18:R20) -> 80073 | S22: =SUM(S18:S20) -> 41656 | T22: =SUM(T18:T20) -> 662306
A24: DEFERRED INFLOWS OF RESOURCES
B26: Fund Balances
C27: Nonspendable | K27: 23691 | L27: 19602 | M27: 23953 | N27: 15559 | O27: 6465 | P27: 14414 | Q27: 1116 | T27: =SUM(K27:S27) -> 104800
C28: Restricted | L28: 1176919 | M28: 3224738 | N28: 789367 | O28: 1824212 | P28: 1412181 | Q28: 195592 | S28: 116660 | T28: =SUM(K28:S28) -> 8739669
C29: Unassigned | K29: 1046829 | T29: =SUM(K29:S29) -> 1046829
E31: Total fund balance: | K31: =SUM(K27:K30) -> 1070520 | L31: =SUM(L27:L29) -> 1196521 | M31: =SUM(M27:M29) -> 3248691 | N31: =SUM(N27:N29) -> 804926 | O31: =SUM(O27:O29) -> 1830677 | P31: =SUM(P27:P29) -> 1426595 | Q31: =SUM(Q27:Q29) -> 196708 | R31: =SUM(R27:R29) -> 0 | S31: =SUM(S27:S29) -> 116660 | T31: =SUM(T27:T29) -> 9891298
E33: Total liabilities and fund balances: | K33: =SUM(K31,K22) -> 1232018 | L33: =SUM(L22,L31) -> 1232725 | M33: =SUM(M22,M31) -> 3443373 | N33: =SUM(N22,N31) -> 835080 | O33: =SUM(O31+O22) -> 1854608 | P33: =SUM(P31+P22) -> 1482399 | Q33: =SUM(Q31+Q22) -> 235012 | R33: =SUM(R31+R22) -> 80073 | S33: =SUM(S31+S22) -> 158316 | T33: =SUM(T31+T22) -> 10553604

Sheet Beauregard
D1: Beauregard Combined Balance Sheet
D2: Issued: December 31, 2013
K4: General Fund | L4: Parishwide Road Special Revenue | M4: Road District No. 6 Special Revenue | N4: Sales Tax District No. 1 Special Revenue | O4: Health Unit Special Revenue | P4: Criminal Court Special Revenue | Q4: South Beau. Rec. Dist. No. 2 Special Revenue | R4: South Beau. Rec. Dist. No. 2 Capital Projects | S4: Nonmajor Governmental Funds | T4: Total Governmental Funds
A5: Assets:
B6: Equity in pooled cash | K6: 630917 | L6: 874419 | M6: 1310997 | N6: 3003371 | O6: 1952781 | P6: 1216 | Q6: 702741 | R6: 1350098 | S6: 5031826 | T6: =SUM(K6:S6) -> 14858366
B7: Receivables | K7: 1081445 | L7: 42651 | M7: 947010 | N7: 390403 | O7: 548293 | P7: 66507 | Q7: 540009 | S7: 2868443 | T7: =SUM(K7:S7) -> 6484761
B8: Interfund receivable | K8: 58266 | L8: 11404 | R8: 25603 | T8: =SUM(K8:S8) -> 95273
B9: Inventory | K9: 32875 | M9: 27795 | S9: 253133 | T9: =SUM(K9:S9) -> 313803
E11: Total assets: | K11: =SUM(K6:K9) -> 1803503 | L11: =SUM(L6:L9) -> 928474 | M11: =SUM(M6:M9) -> 2285802 | N11: =SUM(N6:N9) -> 3393774 | O11: =SUM(O6:O9) -> 2501074 | P11: =SUM(P6:P9) -> 67723 | Q11: =SUM(Q6:Q9) -> 1242750 | R11: =SUM(R6:R9) -> 1375701 | ... T11: =SUM(T6:T9) -> 21752203
A13: LIABILITIES AND FUND BALANCES
B14: Liabilities:
C15: Accounts payable | K15: 188832 | L15: 21559 | M15: 35677 | N15: 118771 | O15: 19707 | P15: 16838 | Q15: 82909 | R15: 39354 | S15: 160864 | T15: =SUM(K15:S15) -> 684511
C16: Payroll liabilities | K16: 164679 | T16: =SUM(K16:S16) -> 164679
C17: Interfund payable | P17: 39041 | Q17: 25603 | S17: 30629 | T17: =SUM(K17:S17) -> 95273
E19: Total liabilities: | K19: =SUM(K15:K17) -> 353511 | L19: =SUM(L15:L17) -> 21559 | M19: =SUM(M15:M17) -> 35677 | N19: =SUM(N15:N17) -> 118771 | O19: =SUM(O15:O17) -> 19707 | P19: =SUM(P15:P17) -> 55879 | Q19: =SUM(Q15:Q17) -> 108512 | R19: =SUM(R15:R17) -> 39354 | ... T19: =SUM(T15:T17) -> 944463
A21: DEFERRED INFLOWS OF RESOURCES
B22: Unavailable revenue | K22: 44721 | M22: 20738 | O22: 18269 | Q22: 8081 | S22: 103534 | T22: =SUM(K22:S22) -> 195343
B24: Fund Balances:
C25: Nonspendable - inventory | K25: 32875 | M25: 27795 | S25: 253133 | T25: =SUM(K25:S25) -> 313803
C26: Restricted:
D27: Purchases of equipment | L27: 324072 | T27: =SUM(K27:S27) -> 324072
D28: Public safety | S28: 1810976 | T28: =SUM(K28:S28) -> 1810976
D29: Public works | L29: 582843 | M29: 2201592 | S29: 3608240 | T29: =SUM(K29:S29) -> 6392675
D30: Health and welfare | O30: 2463098 | T30: =SUM(K30:S30) -> 2463098
D31: Culture and recreation | S31: 607692 | T31: =SUM(K31:S31) -> 607692
D32: Sanitation | N32: 3275003 | T32: =SUM(K32:S32) -> 3275003
D33: Other general government | S33: 136917 | T33: =SUM(K33:S33) -> 136917
D34: Capital projects | S34: 1275201 | T34: =SUM(K34:S34) -> 1275201
D35: Debt service | S35: 166216 | T35: =SUM(K35:S35) -> 166216
C36: Unassigned | K36: 1372396 | P36: 11844 | Q36: 1126157 | R36: 1336347 | T36: =SUM(K36:S36) -> 3846744
E38: Total fund balance: | K38: =SUM(K25:K36) -> 1405271 | L38: =SUM(L25:L36) -> 906915 | M38: =SUM(M25:M36) -> 2229387 | N38: =SUM(N25:N36) -> 3275003 | O38: =SUM(O25:O36) -> 2463098 | P38: =SUM(P25:P36) -> 11844 | Q38: =SUM(Q25:Q36) -> 1126157 | R38: =SUM(R25:R36) -> 1336347 | ... T38: =SUM(T25:T36) -> 20612397
E40: Total liabilities and fund balances: | K40: =K38+K22+K19 -> 1803503 | L40: =L38+L22+L19 -> 928474 | M40: =M38+M22+M19 -> 2285802 | N40: =N38+N22+N19 -> 3393774 | O40: =O38+O22+O19 -> 2501074 | P40: =P38+P22+P19 -> 67723 | Q40: =Q38+Q22+Q19 -> 1242750 | R40: =R38+R22+R19 -> 1375701 | ... T40: =T38+T22+T19 -> 21752203

Sheet Bienville
D1: Bienville Combined Balance Sheet
D2: Issued: December 31, 2013
K5: General | L5: Road Maintenance | M5: Solid Waste | N5: Construction Fund | O5: Debt Service Fund | P5: CDBG Fund | Q5: Other Governmental Funds | R5: Total Governmental Funds
A6: Assets:
B7: Cash and equivalents | K7: 4224843 | L7: 8417207 | M7: 3571253 | N7: 10786 | O7: 752937 | P7: 16 | Q7: 247299 | R7: =SUM(K7:Q7) -> 17224341
B8: Receivables | K8: 1912568 | L8: 2022233 | M8: 279239 | O8: 1182712 | P8: 44464 | Q8: 7190 | R8: =SUM(K8:Q8) -> 5448406
E10: Total Assets: | K10: =SUM(K7:K8) -> 6137411 | L10: =SUM(L7:L8) -> 10439440 | M10: =SUM(M7:M8) -> 3850492 | N10: =SUM(N7:N8) -> 10786 | O10: =SUM(O7:O8) -> 1935649 | P10: =SUM(P7:P8) -> 44480 | Q10: =SUM(Q7:Q8) -> 254489 | R10: =SUM(R7:R8) -> 22672747
A12: LIABILITIES AND FUND BALANCES
B13: Liabilities:
C14: Accounts payable | K14: 74312 | L14: 41142 | M14: 89788 | P14: 44464 | R14: =SUM(K14:Q14) -> 249706
C15: Salaries and related payable | K15: 4993 | L15: 17633 | R15: =SUM(K15:Q15) -> 22626
C16: Deferred revenues | K16: 70000 | R16: =SUM(K16:Q16) -> 70000
E18: Total liabilities: | K18: =SUM(K14:K16) -> 149305 | L18: =SUM(L14:L16) -> 58775 | M18: =SUM(M14:M16) -> 89788 | N18: =SUM(N14:N16) -> 0 | O18: =SUM(O14:O16) -> 0 | P18: =SUM(P14:P16) -> 44464 | Q18: =SUM(Q14:Q16) -> 0 | R18: =SUM(R14:R16) -> 342332
B20: Fund Balances
C21: Non Spendable | P21: 16 | R21: =SUM(K21:Q21) -> 16
C22: Restricted:
D23: Other general government | Q23: 124851 | R23: =SUM(K23:Q23) -> 124851
D24: Public works | L24: 10380665 | Q24: 14456 | R24: =SUM(K24:Q24) -> 10395121
D25: Health & welfare | Q25: 68320 | R25: =SUM(K25:Q25) -> 68320
D26: Economic development | Q26: 46862 | R26: =SUM(K26:Q26) -> 46862
C27: Assigned | M27: 3760704 | N27: 10786 | O27: 1935649 | R27: =SUM(K27:Q27) -> 5707139
C28: Unassigned | K28: 5988106 | R28: =SUM(K28:Q28) -> 5988106
E30: Total fund balance: | K30: =SUM(K21:K28) -> 5988106 | L30: =SUM(L21:L28) -> 10380665 | M30: =SUM(M21:M28) -> 3760704 | N30: =SUM(N21:N28) -> 10786 | O30: =SUM(O21:O28) -> 1935649 | P30: =SUM(P21:P28) -> 16 | Q30: =SUM(Q21:Q28) -> 254489 | R30: =SUM(R21:R28) -> 22330415
E32: Total liabilities and fund balances: | K32: =SUM(K30,K18) -> 6137411 | L32: =SUM(L18,L30) -> 10439440 | M32: =SUM(M18,M30) -> 3850492 | N32: =SUM(N18,N30) -> 10786 | O32: =SUM(O30+O18) -> 1935649 | P32: =SUM(P30+P18) -> 44480 | Q32: =SUM(Q30+Q18) -> 254489 | R32: =SUM(R30+R18) -> 22672747

Sheet Bossier
D1: Bossier Combined Balance Sheet
D2: Issued: December 31, 2013
K5: General | L5: Highway | M5: Library | N5: Capital Improvements | O5: LCDA Sewer Construction | P5: Other Governmental Funds | Q5: Total Governmental Funds
A6: Assets:
B7: Cash and cash equivalents | K7: 3553861 | L7: 3586860 | M7: 7489233 | N7: 6706530 | O7: 240534 | P7: 15129338 | Q7: =SUM(K7:P7) -> 36706356
B8: Receivables | K8: 2732041 | L8: 3144974 | M8: 6974940 | N8: 863968 | O8: 46698 | P8: 4077264 | Q8: =SUM(K8:P8) -> 17839885
B9: Restricted cash | O9: 3245700 | P9: 1889644 | Q9: =SUM(K9:P9) -> 5135344
B10: Due from other fund | K10: 129211 | P10: 6373 | Q10: =SUM(K10:P10) -> 135584
B11: Advance to Waterworks/Sewer District | O11: 8185472 | Q11: =SUM(K11:P11) -> 8185472
E13: Total Assets: | K13: =SUM(K7:K11) -> 6415113 | L13: =SUM(L7:L11) -> 6731834 | M13: =SUM(M7:M11) -> 14464173 | N13: =SUM(N7:N11) -> 7570498 | O13: =SUM(O7:O11) -> 11718404 | P13: =SUM(P7:P11) -> 21102619 | Q13: =SUM(Q7:Q11) -> 68002641
A15: LIABILITIES AND FUND BALANCES
B16: Liabilities:
C17: Accounts payable | K17: 309582 | L17: 681792 | M17: 413737 | N17: 57397 | O17: 134440 | P17: 808819 | Q17: =SUM(K17:P17) -> 2405767
C18: Due to other funds | K18: 6373 | L18: 55782 | N18: 11300 | P18: 62129 | Q18: =SUM(K18:P18) -> 135584
E20: Total liabilities: | K20: =SUM(K17:K18) -> 315955 | L20: =SUM(L17:L18) -> 737574 | M20: =SUM(M17:M18) -> 413737 | N20: =SUM(N17:N18) -> 68697 | O20: =SUM(O17:O18) -> 134440 | P20: =SUM(P17:P18) -> 870948 | Q20: =SUM(Q17:Q18) -> 2541351
A22: DEFERRED INFLOWS OF RESROUCES
B23: Unavailable revenue:
C24: Property taxes | K24: 89511 | L24: 110685 | M24: 416912 | P24: 210825 | Q24: =SUM(K24:P24) -> 827933
C25: Other | K25: 127732 | L25: 199365 | M25: 115229 | P25: 420391 | Q25: =SUM(K25:P25) -> 862717
E27: Total deferred inflows of resources: | K27: =SUM(K24:K25) -> 217243 | L27: =SUM(L24:L25) -> 310050 | M27: =SUM(M24:M25) -> 532141 | N27: =SUM(N24:N26) -> 0 | O27: =SUM(O24:O25) -> 0 | P27: =SUM(P24:P25) -> 631216 | Q27: =SUM(Q24:Q25) -> 1690650
B29: Fund Balances
C30: Nonspendable | O30: 8185472 | Q30: =SUM(K30:P30) -> 8185472
C31: Restricted | M31: 13233707 | N31: 7367576 | O31: 3398492 | P31: 10772365 | Q31: =SUM(K31:P31) -> 34772140
C32: Assigned | K32: 2285906 | L32: 5684210 | M32: 284588 | N32: 134226 | P32: 8889950 | Q32: =SUM(K32:P32) -> 17278880
C33: Unassigned | K33: 3596009 | P33: -61860 | Q33: =SUM(K33:P33) -> 3534149
E35: Total fund balance: | K35: =SUM(K30:K33) -> 5881915 | L35: =SUM(L30:L33) -> 5684210 | M35: =SUM(M30:M33) -> 13518295 | N35: =SUM(N30:N33) -> 7501802 | O35: =SUM(O30:O33) -> 11583964 | P35: =SUM(P30:P33) -> 19600455 | Q35: =SUM(Q30:Q33) -> 63770641
E37: Total liabilities and fund balances: | K37: =SUM(K35,K20,K27) -> 6415113 | L37: =SUM(L35,L20,L27) -> 6731834 | M37: =SUM(M35,M20,M27) -> 14464173 | N37: =SUM(N35,N20,N27) -> 7570499 | O37: =SUM(O35,O20,O27) -> 11718404 | P37: =SUM(P35,P20,P27) -> 21102619 | Q37: =SUM(Q35,Q20,Q27) -> 68002642

Sheet Caddo
D1: Caddo Combined Balance Sheet
D2: Issued: December 31, 2013
K4: General Fund | L4: Shreve Memorial Library Fund | M4: Detention Facilities Fund | N4: Solid Waste Disposal Fund | O4: Public Works Fund | P4: Head Start Fund | Q4: Biomedical Fund | R4: Capital Outlay Fund | S4: Criminal Justice Fund | T4: Other Governmental Funds | U4: Total Governmental Funds
A5: Assets:
B6: Cash and cash equivalents | K6: 4590414 | L6: 3286688 | M6: 64920 | N6: 1942202 | O6: 1145700 | R6: 1568910 | T6: 3319307 | U6: =SUM(K6:T6) -> 15918141
B7: Investments | K7: 41057969 | M7: 583805 | N7: 17369431 | O7: 10242821 | R7: 14025541 | T7: 29659730 | U7: =SUM(K7:T7) -> 112939297
B8: Receivables, net:
C9: Ad valorem taxes | K9: 6184670 | L9: 13778148 | M9: 7855428 | O9: 5773733 | Q9: 2604426 | S9: 5150541 | T9: 13965173 | U9: =SUM(K9:T9) -> 55312119
C10: Paving assessments | O10: 170000 | U10: =SUM(K10:T10) -> 170000
C11: Other | K11: 29642 | M11: 156 | N11: 211985 | O11: 455821 | T11: 437966 | U11: =SUM(K11:T11) -> 1135570
C12: Accrued interest | K12: 144136 | M12: 2037 | N12: 60984 | O12: 35970 | R12: 49263 | T12: 104216 | U12: =SUM(K12:T12) -> 396606
B13: Due from other funds | K13: 1136576 | L13: 200521 | M13: 109628 | N13: 409147 | O13: 448368 | R13: 627700 | T13: 1821958 | U13: =SUM(K13:T13) -> 4753898
B14: Due from other governments | K14: 212255 | L14: 258244 | M14: 161219 | N14: 179788 | O14: 705921 | Q14: 49004 | S14: 103002 | T14: 495034 | U14: =SUM(K14:T14) -> 2164467
B15: Inventories | O15: 82196 | U15: =SUM(K15:T15) -> 82196
B16: Other assets | L16: 112394 | U16: =SUM(K16:T16) -> 112394
E18: Total assets: | K18: =SUM(K6:K16) -> 53355662 | L18: =SUM(L6:L16) -> 17635995 | M18: =SUM(M6:M16) -> 8777193 | N18: =SUM(N6:N16) -> 20173537 | O18: =SUM(O6:O16) -> 19060530 | P18: =SUM(P6:P16) -> 0 | Q18: =SUM(Q6:Q16) -> 2653430 | R18: =SUM(R6:R16) -> 16271414 | ... U18: =SUM(U6:U16) -> 192984688
A20: LIABILITIES AND FUND BALANCES
B21: Liabilities:
C22: Accounts payable | K22: 130305 | L22: 412443 | M22: 181041 | N22: 163437 | O22: 258881 | R22: 1000244 | T22: 588645 | U22: =SUM(K22:T22) -> 2734996
C23: Accrued liabilities | K23: 139340 | L23: 219860 | M23: 25174 | N23: 44408 | O23: 136523 | T23: 330930 | U23: =SUM(K23:T23) -> 896235
C24: Retainage payable | R24: 779557 | U24: =SUM(K24:T24) -> 779557
C25: Due to other funds | Q25: 1913254 | S25: 2771732 | T25: 68912 | U25: =SUM(K25:T25) -> 4753898
C26: Unearned revenue | K26: 73941 | O26: 100 | T26: 8954 | U26: =SUM(K26:T26) -> 82995
C27: Due to component units | M27: 859366 | U27: =SUM(K27:T27) -> 859366
C28: Due to other governments | K28: 4906 | N28: 2596 | O28: 46297 | S28: 430133 | T28: 71053 | U28: =SUM(K28:T28) -> 554985
E30: Total liabilities: | K30: =SUM(K22:K28) -> 348492 | L30: =SUM(L22:L28) -> 632303 | M30: =SUM(M22:M28) -> 1065581 | N30: =SUM(N22:N28) -> 210441 | O30: =SUM(O22:O28) -> 441801 | P30: =SUM(P22:P28) -> 0 | Q30: =SUM(Q22:Q28) -> 1913254 | R30: =SUM(R22:R28) -> 1779801 | ... U30: =SUM(U22:U28) -> 10662032
A32: DEFERRED INFLOWS OF RESOURCES
B33: Unavailable revenue - property taxes | K33: 53502 | L33: 35574 | M33: 26261 | O33: 2234 | S33: 1663 | T33: 31830 | U33: =SUM(K33:T33) -> 151064
B34: Unavailable revenue - special assessments | O34: 62293 | U34: =SUM(K34:T34) -> 62293
E36: Total deferred inflows: | K36: =SUM(K33:K34) -> 53502 | L36: =SUM(L33:L34) -> 35574 | M36: =SUM(M33:M34) -> 26261 | N36: =SUM(N33:N34) -> 0 | O36: =SUM(O33:O34) -> 64527 | P36: =SUM(P33:P34) -> 0 | Q36: =SUM(Q33:Q34) -> 0 | R36: =SUM(R33:R34) -> 0 | ... U36: =SUM(U33:U34) -> 213357
B38: Fund Balances:
C39: Nonspendable:
D40: Prepaid expenses | L40: 112394 | U40: =SUM(K40:T40) -> 112394
C41: Restricted for:
D42: Criminal justice | M42: 7685351 | S42: 1953089 | T42: 3119183 | U42: =SUM(K42:T42) -> 12757623
D43: Health and welfare | T43: 4310288 | U43: =SUM(K43:T43) -> 4310288
D44: Highways, streets and drainage | O44: 18418298 | U44: =SUM(K44:T44) -> 18418298
D45: Building facilities | T45: 7551677 | U45: =SUM(K45:T45) -> 7551677
D46: Sanitation | N46: 19963096 | U46: =SUM(K46:T46) -> 19963096
D47: Culture and recreation | L47: 16855724 | T47: 2954148 | U47: =SUM(K47:T47) -> 19809872
...

Sheet Calcasieu
D1: Calcasieu Combined Balance Sheet
D2: Issued: December 31, 2013
K4: General Fund | L4: Public Works Operating Fund | M4: Calcasieu Parish Library Fund | N4: Road Capital Improvement Fund | O4: Other Governmental Funds | P4: Total Governmental Funds
A5: Assets:
B6: Cash and Cash Equivalents | K6: 14067607 | L6: 7166488 | M6: 1171331 | N6: 24479124 | O6: 12610292 | P6: =SUM(K6:O6) -> 59494842
B7: Investments | K7: 43137940 | L7: 23116500 | M7: 3780323 | N7: 78964727 | O7: 38215571 | P7: =SUM(K7:O7) -> 187215061
B8: Receivable (net of allowance for uncollectibles):
C9: Property taxes | K9: 10322837 | M9: 9388259 | N9: 4743635 | O9: 21860013 | P9: =SUM(K9:O9) -> 46314744
C10: Sales taxes | L10: 900763 | N10: 1697729 | O10: 623673 | P10: =SUM(K10:O10) -> 3222165
C11: Franchise taxes | K11: 303886 | P11: =SUM(K11:O11) -> 303886
B12: Interest receivable | K12: 86114 | L12: 41635 | M12: 8380 | N12: 142478 | O12: 69709 | P12: =SUM(K12:O12) -> 348316
B13: Intergovernmental receivable | K13: 290120 | L13: 47016 | N13: 149595 | O13: 5226734 | P13: =SUM(K13:O13) -> 5713465
B14: Due from other funds | K14: 1916165 | O14: 70691 | P14: =SUM(K14:O14) -> 1986856
B15: Due from component units | K15: 82064 | L15: 140834 | P15: =SUM(K15:O15) -> 222898
B16: Loans receivable | K16: 48138 | P16: =SUM(K16:O16) -> 48138
B17: Prepaid items | K17: 201 | O17: 64299 | P17: =SUM(K17:O17) -> 64500
B18: Other receivables | K18: 3439616 | L18: 4179 | M18: 25002 | O18: 467401 | P18: =SUM(K18:O18) -> 3936198
B19: Inventory | L19: 726865 | O19: 365836 | P19: =SUM(K19:O19) -> 1092701
E21: Total assets: | K21: =SUM(K6:K19) -> 73694688 | L21: =SUM(L6:L19) -> 32144280 | M21: =SUM(M6:M19) -> 14373295 | N21: =SUM(N6:N19) -> 110177288 | O21: =SUM(O6:O19) -> 79574219 | P21: =SUM(P6:P19) -> 309963770
A23: LIABILITIES AND FUND BALANCES
B24: Liabilities:
C25: Accounts payable | K25: 1461786 | L25: 306028 | M25: 244155 | N25: 1048785 | O25: 3024293 | P25: =SUM(K25:O25) -> 6085047
C26: Accrued liabilities | K26: 244277 | L26: 187080 | M26: 112619 | O26: 261884 | P26: =SUM(K26:O26) -> 805860
C27: Intergovernmental payable | K27: 73382 | L27: 826 | O27: 304917 | P27: =SUM(K27:O27) -> 379125
C28: Due to other funds | K28: 58606 | O28: 1987476 | P28: =SUM(K28:O28) -> 2046082
C29: Due to component units | L29: 3494 | O29: 173042 | P29: =SUM(K29:O29) -> 176536
C30: Unearned revenue | O30: 1097584 | P30: =SUM(K30:O30) -> 1097584
C31: Retainage payable | L31: 12532 | M31: 5780 | N31: 978108 | O31: 248817 | P31: =SUM(K31:O31) -> 1245237
C32: Enterprise zone rebate liability | L32: 394200 | P32: =SUM(K32:O32) -> 394200
C33: Other liabilities | K33: 86366 | L33: 1120 | O33: 50315 | P33: =SUM(K33:O33) -> 137801
E35: Total liabilities: | K35: =SUM(K25:K33) -> 1924417 | L35: =SUM(L25:L33) -> 905280 | M35: =SUM(M25:M33) -> 362554 | N35: =SUM(N25:N33) -> 2026893 | O35: =SUM(O25:O33) -> 7148328 | P35: =SUM(P25:P33) -> 12367472
A37: DEFERRED INFLOWS OF RESOURCES
C38: Unavailable revenue | K38: 10947710 | M38: 9456106 | N38: 4785105 | O38: 22397566 | P38: =SUM(K38:O38) -> 47586487
E40: Total deferred inflows of resources | K40: =SUM(K38:K38) -> 10947710 | L40: =SUM(L38:L38) -> 0 | M40: =SUM(M38:M38) -> 9456106 | N40: =SUM(N38:N38) -> 4785105 | O40: =SUM(O38:O38) -> 22397566 | P40: =SUM(P38:P38) -> 47586487
B42: Fund Balances
C43: Nonspendable:
D44: Prepaid items | K44: 201 | O44: 64214 | P44: =SUM(K44:O44) -> 64415
D45: Inventories | L45: 726865 | O45: 365836 | P45: =SUM(K45:O45) -> 1092701
D46: Component unit - long term receivable | K46: 26195 | P46: =SUM(K46:O46) -> 26195
D47: Loans receivable | K47: 33189 | P47: =SUM(K47:O47) -> 33189
...

Sheet Caldwell
D1: Caldwell Combined Balance Sheet
D2: Issued: December 31, 2013
K5: General | L5: Road Maintenance | M5: Recreation | N5: Solid Waste | O5: Blacktop Road | P5: Bayou Dechene Reservoir | Q5: LCDBG | R5: Other Governmental Funds | S5: Total Governmental Funds
A6: Assets:
B7: Cash and equivalents | K7: 1153518 | L7: 257017 | M7: 600892 | N7: 1820469 | O7: 1304493 | P7: 47545 | Q7: 40 | R7: 1298113 | S7: =SUM(K7:R7) -> 6482087
B8: Receivables | K8: 411401 | L8: 541089 | M8: 312565 | N8: 113245 | R8: 600285 | S8: =SUM(K8:R8) -> 1978585
B9: Due from other funds | K9: 2700 | L9: 25652 | R9: 36402 | S9: =SUM(K9:R9) -> 64754
E11: Total Assets: | K11: =SUM(K7:K9) -> 1567619 | L11: =SUM(L7:L9) -> 823758 | M11: =SUM(M7:M9) -> 913457 | N11: =SUM(N7:N9) -> 1933714 | O11: =SUM(O7:O9) -> 1304493 | P11: =SUM(P7:P9) -> 47545 | Q11: =SUM(Q7:Q9) -> 40 | R11: =SUM(R7:R9) -> 1934800 | S11: =SUM(S7:S9) -> 8525426
A13: LIABILITIES AND FUND BALANCES
B14: Liabilities:
C15: Accounts payable | K15: 39554 | L15: 21784 | M15: 15326 | O15: 12251 | R15: 28567 | S15: =SUM(K15:R15) -> 117482
C16: Salaries and related payable | K16: 14464 | L16: 12121 | M16: 1913 | R16: 6581 | S16: =SUM(K16:R16) -> 35079
C17: Due to other agencies | K17: 57698 | S17: =SUM(K17:R17) -> 57698
C18: Due to other funds | K18: 62054 | L18: 2700 | S18: =SUM(K18:R18) -> 64754
E20: Total liabilities: | K20: =SUM(K15:K18) -> 173770 | L20: =SUM(L15:L18) -> 36605 | M20: =SUM(M15:M18) -> 17239 | N20: =SUM(N15:N18) -> 0 | O20: =SUM(O15:O18) -> 12251 | P20: =SUM(P15:P18) -> 0 | Q20: =SUM(Q15:Q18) -> 0 | R20: =SUM(R15:R18) -> 35148 | S20: =SUM(S15:S18) -> 275013
B22: Fund Balances
C23: Unassigned | K23: 1393849 | S23: =SUM(K23:R23) -> 1393849
C24: Restricted | L24: 787153 | M24: 896218 | N24: 1933714 | O24: 1292242 | P24: 47545 | Q24: 40 | R24: 1899652 | S24: =SUM(K24:R24) -> 6856564
E26: Total fund balance: | K26: =SUM(K23:K24) -> 1393849 | L26: =SUM(L23:L24) -> 787153 | M26: =SUM(M23:M24) -> 896218 | N26: =SUM(N23:N24) -> 1933714 | O26: =SUM(O23:O24) -> 1292242 | P26: =SUM(P23:P24) -> 47545 | Q26: =SUM(Q23:Q24) -> 40 | R26: =SUM(R23:R24) -> 1899652 | S26: =SUM(S23:S24) -> 8250413
E28: Total liabilities and fund balances: | K28: =SUM(K26,K20) -> 1567619 | L28: =SUM(L20,L26) -> 823758 | M28: =SUM(M20,M26) -> 913457 | N28: =SUM(N20,N26) -> 1933714 | O28: =SUM(O26+O20) -> 1304493 | P28: =SUM(P26+P20) -> 47545 | Q28: =SUM(Q26+Q20) -> 40 | R28: =SUM(R26+R20) -> 1934800 | S28: =SUM(S26+S20) -> 8525426

Sheet Cameron
D1: Cameron Combined Balance Sheet
D2: Issued: December 31, 2013
K4: General Fund | L4: Road and Bridge Maintenance | M4: Long-Term Community Recovery | N4: Other Governmental Funds | O4: Total Governmental Funds
A5: Assets:
B6: Cash | K6: 10742848 | L6: -13706 | M6: 100 | N6: 17366412 | O6: =SUM(K6:N6) -> 28095654
B7: Receivables, net | K7: 11324586 | L7: 1613896 | M7: 2989883 | N7: 4002464 | O7: =SUM(K7:N7) -> 19930829
B8: Inventory, at cost | K8: 1793767 | L8: 45788 | O8: =SUM(K8:N8) -> 1839555
B9: Other assets | K9: 21195 | L9: 40364 | N9: 23595 | O9: =SUM(K9:N9) -> 85154
B10: Interfund receivables | K10: 5596860 | L10: 534197 | N10: 4120692 | O10: =SUM(K10:N10) -> 10251749
E12: Total assets: | K12: =SUM(K6:K10) -> 29479256 | L12: =SUM(L6:L10) -> 2220539 | M12: =SUM(M6:M10) -> 2989983 | N12: =SUM(N6:N10) -> 25513163 | O12: =SUM(O6:O10) -> 60202941
A14: DEFERRED OUTFLOWS OF RESOURCES
A16: LIABILITIES AND FUND BALANCES
B17: Liabilities:
C18: Accounts, salaries, and other payables | K18: 1493747 | L18: 136088 | M18: 2682682 | N18: 298003 | O18: =SUM(K18:N18) -> 4610520
C19: Due to other agencies | K19: 3695066 | O19: =SUM(K19:N19) -> 3695066
C20: Unearned revenues | K20: 7413 | M20: 9818 | O20: =SUM(K20:N20) -> 17231
C21: Interfund payables | K21: 4654889 | M21: 2073564 | N21: 3523296 | O21: =SUM(K21:N21) -> 10251749
E23: Total liabilities: | K23: =SUM(K18:K21) -> 9851115 | L23: =SUM(L18:L21) -> 136088 | M23: =SUM(M18:M21) -> 4766064 | N23: =SUM(N18:N21) -> 3821299 | O23: =SUM(O18:O21) -> 18574566
A25: DEFERRED INFLOWS OF RESOURCES
B27: Fund Balances:
C28: Nonspendable:
D29: Inventories | K29: 1793767 | L29: 45788 | O29: =SUM(K29:N29) -> 1839555
D30: Prepaid expenses | K30: 21195 | L30: 40364 | N30: 2593 | O30: =SUM(K30:N30) -> 64152
C31: Restricted for: | O31: =SUM(K31:N31) -> 0
D32: Judicial | N32: 6377 | O32: =SUM(K32:N32) -> 6377
D33: Debt service | N33: 1468574 | O33: =SUM(K33:N33) -> 1468574
D34: Tourism development | N34: 35404 | O34: =SUM(K34:N34) -> 35404
C35: Committed to: | O35: =SUM(K35:N35) -> 0
D36: Infrastructure maintenance | L36: 1977480 | O36: =SUM(K36:N36) -> 1977480
D37: Culture and recreation | N37: 5971020 | O37: =SUM(K37:N37) -> 5971020
D38: Public safety | N38: 4389545 | O38: =SUM(K38:N38) -> 4389545
D39: Judicial | N39: 3353389 | O39: =SUM(K39:N39) -> 3353389
D40: Health and welfare | N40: 5926056 | O40: =SUM(K40:N40) -> 5926056
D41: Law enforcement building construction | N41: 208078 | O41: =SUM(K41:N41) -> 208078
D42: Library construction | N42: 42777 | O42: =SUM(K42:N42) -> 42777
D43: Administrative building construction | N43: 171838 | O43: =SUM(K43:N43) -> 171838
D44: Other capital projects | L44: 20819 | N44: -38000 | O44: =SUM(K44:N44) -> -17181
D45: Other purposes | K45: 221320 | O45: =SUM(K45:N45) -> 221320
C46: Assigned: | O46: =SUM(K46:N46) -> 0
D47: Judicial | N47: 4676 | O47: =SUM(K47:N47) -> 4676
...

Sheet Catahoula
D1: Catahoula Combined Balance Sheet
D2: Issued: December 31, 2013
K4: General | L4: Road and Bridge | M4: Hard Surfacing | N4: Sanitation | O4: Library | P4: Health Unit | Q4: Other Governmental Funds | R4: Total Governmental Funds
A5: Assets:
B6: Cash and Cash Equivalents | K6: 634725 | L6: 116054 | M6: 210606 | N6: 296413 | O6: 246720 | P6: 317490 | Q6: 86971 | R6: =SUM(K6:Q6) -> 1908979
B7: Cash restricted for debt service | Q7: 26325
B8: Investments | R8: =SUM(K8:Q8) -> 0
B9: Receivables | K9: 870802 | L9: 44113 | M9: 48137 | N9: 30086 | O9: 285043 | P9: 71122 | Q9: 62183 | R9: =SUM(K9:Q9) -> 1411486
B10: Due from other funds | R10: =SUM(K10:Q10) -> 0
B11: Due from inmates
B12: Capital assets, net of accumulated depreciation
B13: Other assets | K13: 33515 | L13: 16553 | M13: 25177 | P13: 2805 | Q13: 3716 | R13: =SUM(K13:Q13) -> 81766
E15: Total assets: | K15: =SUM(K6:K13) -> 1539042 | L15: =SUM(L6:L13) -> 176720 | M15: =SUM(M6:M13) -> 283920 | N15: =SUM(N6:N13) -> 326499 | O15: =SUM(O6:O13) -> 531763 | P15: =SUM(P6:P13) -> 391417 | Q15: =SUM(Q6:Q13) -> 179195 | R15: =SUM(R6:R13) -> 3402231
A17: LIABILITIES AND FUND BALANCES
B18: Liabilities:
C19: Accounts payable | K19: 461676 | L19: 6380 | M19: 6509 | N19: 36750 | O19: 15313 | P19: 5266 | Q19: 5348 | R19: =SUM(K19:Q19) -> 537242
C20: Salaries and related payables | K20: 2814 | L20: 5948 | M20: 2966 | Q20: 2824 | R20: =SUM(K20:Q20) -> 14552
E22: Total liabilities: | K22: =SUM(K19:K20) -> 464490 | L22: =SUM(L19:L20) -> 12328 | M22: =SUM(M19:M20) -> 9475 | N22: =SUM(N19:N20) -> 36750 | O22: =SUM(O19:O20) -> 15313 | P22: =SUM(P19:P20) -> 5266 | Q22: =SUM(Q19:Q20) -> 8172 | R22: =SUM(R19:R20) -> 551794
B24: Deferred inflows:
C25: Ad valorem taxes - unavailable | K25: 54080 | O25: 41790 | P25: 10448 | Q25: 6787 | R25: =SUM(K25:Q25) -> 113105
C26: Grant revenue - pending | Q26: 14777 | R26: =SUM(K26:Q26) -> 14777
E28: Total deferred inflows: | K28: =SUM(K25:K26) -> 54080 | L28: =SUM(L25:L26) -> 0 | M28: =SUM(M25:M26) -> 0 | N28: =SUM(N25:N26) -> 0 | O28: =SUM(O25:O26) -> 41790 | P28: =SUM(P25:P26) -> 10448 | Q28: =SUM(Q25:Q26) -> 21564 | R28: =SUM(R25:R26) -> 127882
B30: Fund Balances
C31: Nonspendable | K31: 33515 | L31: 16553 | M31: 25177 | P31: 2805 | Q31: 3716 | R31: =SUM(K31:Q31) -> 81766
C32: Restricted | K32: 69325 | L32: 147839 | M32: 249268 | N32: 289749 | O32: 474660 | P32: 372898 | Q32: 161066 | R32: =SUM(K32:Q32) -> 1764805
C33: Unassigned | K33: 917632 | Q33: -15323 | R33: =SUM(K33:Q33) -> 902309
E35: Total fund balance: | K35: =SUM(K31:K33) -> 1020472 | L35: =SUM(L31:L33) -> 164392 | M35: =SUM(M31:M33) -> 274445 | N35: =SUM(N31:N33) -> 289749 | O35: =SUM(O31:O33) -> 474660 | P35: =SUM(P31:P33) -> 375703 | Q35: =SUM(Q31:Q33) -> 149459 | R35: =SUM(R31:R33) -> 2748880
E37: Total liabilities and fund balances: | K37: =K35+K28+K22 -> 1539042 | L37: =L35+L28+L22 -> 176720 | M37: =M35+M28+M22 -> 283920 | N37: =N35+N28+N22 -> 326499 | O37: =O35+O28+O22 -> 531763 | P37: =P35+P28+P22 -> 391417 | Q37: =Q35+Q28+Q22 -> 179195 | R37: =R35+R28+R22 -> 3428556

Sheet Claiborne
D1: Claiborne Combined Balance Sheet
D2: Issued: December 31, 2013
K4: General | L4: Parish Road | M4: Library Maintenance | N4: Sales Tax | O4: Criminal Court | P4: Section 8 | Q4: Other Governmental Funds | R4: Total Governmental Funds
A5: Assets:
B6: Cash and Cash Equivalents | K6: 3274232 | L6: 93857 | M6: 1895670 | N6: 1335641 | O6: 23194 | P6: 61114 | Q6: 863403 | R6: =SUM(K6:Q6) -> 7547111
B7: Investments | K7: 7643 | L7: 3040 | M7: 6248 | N7: 5374 | Q7: 5777 | R7: =SUM(K7:Q7) -> 28082
B8: Receivables | K8: 622061 | L8: 1090093 | M8: 755820 | N8: 74617 | O8: 8595 | Q8: 664142 | R8: =SUM(K8:Q8) -> 3215328
B9: Due from other funds | K9: 1094 | R9: =SUM(K9:Q9) -> 1094
B10: Deferred charges | K10: 113163 | R10: =SUM(K10:Q10) -> 113163
E12: Total assets: | K12: =SUM(K6:K10) -> 4018193 | L12: =SUM(L6:L10) -> 1186990 | M12: =SUM(M6:M10) -> 2657738 | N12: =SUM(N6:N10) -> 1415632 | O12: =SUM(O6:O10) -> 31789 | P12: =SUM(P6:P10) -> 61114 | Q12: =SUM(Q6:Q10) -> 1533322 | R12: =SUM(R6:R10) -> 10904778
A14: LIABILITIES AND FUND BALANCES
B15: Liabilities:
C16: Accounts, salaries and other payables | K16: 205075 | L16: 59446 | M16: 266802 | N16: 53982 | O16: 32187 | Q16: 26079 | R16: =SUM(K16:Q16) -> 643571
C17: Due to other funds | L17: 538 | M17: 456 | Q17: 100 | R17: =SUM(K17:Q17) -> 1094
C18: Due to other agencies | K18: 2343 | P18: 14025 | R18: =SUM(K18:Q18) -> 16368
E20: Total liabilities: | K20: =SUM(K16:K18) -> 207418 | L20: =SUM(L16:L18) -> 59984 | M20: =SUM(M16:M18) -> 267258 | N20: =SUM(N16:N18) -> 53982 | O20: =SUM(O16:O18) -> 32187 | P20: =SUM(P16:P18) -> 14025 | Q20: =SUM(Q16:Q18) -> 26179 | R20: =SUM(R16:R18) -> 661033
B22: Deferred inflows:
C23: Unavailable ad valorem tax revenue | K23: 68100 | L23: 131125 | M23: 87380 | P23: 15626 | Q23: 80639 | R23: =SUM(K23:Q23) -> 382870
E25: Total deferred inflows: | K25: =SUM(K23:K23) -> 68100 | L25: =SUM(L23:L23) -> 131125 | M25: =SUM(M23:M23) -> 87380 | N25: =SUM(N23:N23) -> 0 | O25: =SUM(O23:O23) -> 0 | P25: =SUM(P23:P23) -> 15626 | Q25: =SUM(Q23:Q23) -> 80639 | R25: =SUM(R23:R23) -> 382870
B27: Fund Balances
C28: Restricted fund balances | K28: 592115 | L28: 995881 | M28: 2303100 | N28: 1361650 | O28: -398 | P28: 31463 | Q28: 1426504 | R28: =SUM(K28:Q28) -> 6710315
C29: Unassigned fund balances | K29: 3150560 | R29: =SUM(K29:Q29) -> 3150560
E31: Total fund balance: | K31: =SUM(K28:K29) -> 3742675 | L31: =SUM(L28:L29) -> 995881 | M31: =SUM(M28:M29) -> 2303100 | N31: =SUM(N28:N29) -> 1361650 | O31: =SUM(O28:O29) -> -398 | P31: =SUM(P28:P29) -> 31463 | Q31: =SUM(Q28:Q29) -> 1426504 | R31: =SUM(R28:R29) -> 9860875
E33: Total liabilities and fund balances: | K33: =K31+K25+K20 -> 4018193 | L33: =L31+L25+L20 -> 1186990 | M33: =M31+M25+M20 -> 2657738 | N33: =N31+N25+N20 -> 1415632 | O33: =O31+O25+O20 -> 31789 | P33: =P31+P25+P20 -> 61114 | Q33: =Q31+Q25+Q20 -> 1533322 | R33: =R31+R25+R20 -> 10904778

Sheet Concordia
D1: Concordia Combined Balance Sheet
D2: Issued: December 31, 2013
K5: General Fund | L5: Drainage Fund | M5: Sales Tax Fund | N5: Road Debt Service Fund | O5: Solid Waste Fund | P5: Public Health Fund | Q5: Other Governmental Funds | R5: Total Governmental Funds
A6: Assets:
B7: Cash and cash equivalents | K7: 2454254 | L7: 810545 | M7: 1412343 | O7: 85520 | P7: 304584 | Q7: 486878 | R7: =SUM(K7:Q7) -> 5554124
B8: Cash - restricted for debt service | N8: 2396243 | R8: =SUM(K8:Q8) -> 2396243
B9: Receivables | K9: 767695 | L9: 845413 | M9: 271185 | P9: 207025 | Q9: 33745 | R9: =SUM(K9:Q9) -> 2125063
B10: Accrued interest | K10: 1904 | L10: 325 | M10: 376 | R10: =SUM(K10:Q10) -> 2605
E12: Total Assets: | K12: =SUM(K7:K10) -> 3223853 | L12: =SUM(L7:L10) -> 1656283 | M12: =SUM(M7:M10) -> 1683904 | N12: =SUM(N7:N10) -> 2396243 | O12: =SUM(O7:O10) -> 85520 | P12: =SUM(P7:P10) -> 511609 | Q12: =SUM(Q7:Q10) -> 520623 | R12: =SUM(R7:R10) -> 10078035
A14: LIABILITIES AND FUND BALANCES
B15: Liabilities:
C16: Account, salaries, and payable | K16: 38787 | L16: 18461 | O16: 29483 | P16: 1723 | Q16: 13639 | R16: =SUM(K16:Q16) -> 102093
E18: Total liabilities: | K18: =SUM(K16:K16) -> 38787 | L18: =SUM(L16:L16) -> 18461 | M18: =SUM(M16:M16) -> 0 | N18: =SUM(N16:N16) -> 0 | O18: =SUM(O16:O16) -> 29483 | P18: =SUM(P16:P16) -> 1723 | Q18: =SUM(Q16:Q16) -> 13639 | R18: =SUM(R16:R16) -> 102093
B20: Fund Balances:
C21: Restricted for:
D22: Debt Service | N22: 2396243 | R22: =SUM(K22:Q22) -> 2396243
C23: Committed for:
D24: Special revenue projects | L24: 1637822 | M24: 1683904 | O24: 56037 | P24: 509886 | Q24: 506984 | R24: =SUM(K24:Q24) -> 4394633
C25: Unassigned, reported in: | R25: =SUM(K25:Q25) -> 0
D26: General | K26: 3185066 | R26: =SUM(K26:Q26) -> 3185066
E28: Total fund balance: | K28: =SUM(K22:K26) -> 3185066 | L28: =SUM(L22:L26) -> 1637822 | M28: =SUM(M22:M26) -> 1683904 | N28: =SUM(N22:N26) -> 2396243 | O28: =SUM(O22:O26) -> 56037 | P28: =SUM(P22:P26) -> 509886 | Q28: =SUM(Q22:Q26) -> 506984 | R28: =SUM(R22:R26) -> 9975942
E30: Total liabilities and fund balances: | K30: =SUM(K28,K18,) -> 3223853 | L30: =SUM(L28,L18,) -> 1656283 | M30: =SUM(M28,M18,) -> 1683904 | N30: =SUM(N28,N18,) -> 2396243 | O30: =SUM(O28,O18,) -> 85520 | P30: =SUM(P28,P18,) -> 511609 | Q30: =SUM(Q28,Q18,) -> 520623 | R30: =SUM(R28,R18,) -> 10078035

Sheet DeSoto
D1: DeSoto Combined Balance Sheet
D2: Issued: December 31, 2013
K4: General Fund | L4: Solid Waste Fund | M4: Road Fund | N4: Airport Fund | O4: Jail Fund | P4: Sales Tax | Q4: Criminal Court Fund | R4: Other Governmental Funds | S4: Total Governmental Funds
A5: Assets:
B6: Cash and cash equivalents | K6: 1330631 | L6: 2288828 | M6: 94129 | N6: 606834 | O6: 4639231 | P6: 3000 | Q6: 1447841 | R6: 803131 | S6: =SUM(K6:R6) -> 11213625
B7: Investments | K7: 5807752 | L7: 6347657 | M7: 10696 | N7: 7735241 | S7: =SUM(K7:R7) -> 19901346
B8: Receivables (net of allowance for uncollectibles) | K8: 4018916 | L8: 4079786 | M8: 3950744 | N8: 91183 | O8: 296 | P8: 1051370 | Q8: 98843 | R8: 236842 | S8: =SUM(K8:R8) -> 13527980
B9: Inventory | N9: 40185 | S9: =SUM(K9:R9) -> 40185
B10: Due from other governments | K10: 2650 | S10: =SUM(K10:R10) -> 2650
B11: Due from other funds | K11: 1367048 | L11: 156097 | M11: 520322 | O11: 104065 | S11: =SUM(K11:R11) -> 2147532
B12: Noncurrent receivable | M12: 55000 | S12: =SUM(K12:R12) -> 55000
E14: Total assets: | K14: =SUM(K6:K12) -> 12526997 | L14: =SUM(L6:L12) -> 12872368 | M14: =SUM(M6:M12) -> 4630891 | N14: =SUM(N6:N12) -> 8473443 | O14: =SUM(O6:O12) -> 4743592 | P14: =SUM(P6:P12) -> 1054370 | Q14: =SUM(Q6:Q12) -> 1546684 | R14: =SUM(R6:R12) -> 1039973 | S14: =SUM(S6:S12) -> 46888318
A16: LIABILITIES AND FUND BALANCES
B17: Liabilities:
C18: Accounts payable | K18: 270768 | L18: 329947 | M18: 226143 | N18: 70987 | O18: 35469 | P18: 10723 | Q18: 140911 | R18: 88810 | S18: =SUM(K18:R18) -> 1173758
C19: Due to other funds | N19: 1000000 | P19: 783485 | Q19: 98447 | R19: 265600 | S19: =SUM(K19:R19) -> 2147532
C20: Master bank overdrafts | K20: 31222 | Q20: 1208876 | R20: 182703 | S20: =SUM(K20:R20) -> 1422801
C21: Due to other governments | K21: 4 | P21: 260162 | S21: =SUM(K21:R21) -> 260166
C22: Advance from grantors | R22: 67825 | S22: =SUM(K22:R22) -> 67825
C23: Deposits | K23: 1100 | S23: =SUM(K23:R23) -> 1100
E25: Total liabilities: | K25: =SUM(K18:K23) -> 303094 | L25: =SUM(L18:L23) -> 329947 | M25: =SUM(M18:M23) -> 226143 | N25: =SUM(N18:N23) -> 1070987 | O25: =SUM(O18:O23) -> 35469 | P25: =SUM(P18:P23) -> 1054370 | Q25: =SUM(Q18:Q23) -> 1448234 | R25: =SUM(R18:R23) -> 604938 | S25: =SUM(S18:S23) -> 5073182
A27: DEFERRED INFLOWS OF RESOURCES
B28: Unavailable property taxes | K28: 168000 | L28: 123521 | M28: 171568 | S28: =SUM(K28:R28) -> 463089
E30: Total deferred inflows: | K30: =SUM(K28:K28) -> 168000 | L30: =SUM(L28:L28) -> 123521 | M30: =SUM(M28:M28) -> 171568 | N30: =SUM(N28:N28) -> 0 | O30: =SUM(O28:O28) -> 0 | P30: =SUM(P28:P28) -> 0 | Q30: =SUM(Q28:Q28) -> 0 | R30: =SUM(R28:R28) -> 0 | S30: =SUM(S28:S28) -> 463089
B32: Fund Balances:
C33: Nonspendable:
D34: Inventory | N34: 40185 | S34: =SUM(K34:R34) -> 40185
C35: Restricted for:
D36: Airport | N36: 7362271 | S36: =SUM(K36:R36) -> 7362271
D37: Judicial | Q37: 98450 | S37: =SUM(K37:R37) -> 98450
D38: Public safety | O38: 4708123 | R38: 22724 | S38: =SUM(K38:R38) -> 4730847
D39: Roads | M39: 4233180 | S39: =SUM(K39:R39) -> 4233180
D40: Sanitation | L40: 12418900 | S40: =SUM(K40:R40) -> 12418900
D41: Health and welfare | R41: 6995 | S41: =SUM(K41:R41) -> 6995
D42: Witness and juror fees | R42: 394991 | S42: =SUM(K42:R42) -> 394991
C43: Assigned to:
D44: Animal control | R44: 10325 | S44: =SUM(K44:R44) -> 10325
C45: Unassigned | K45: 12055903 | S45: =SUM(K45:R45) -> 12055903
E47: Total fund balance: | K47: =SUM(K33:K45) -> 12055903 | L47: =SUM(L33:L45) -> 12418900 | M47: =SUM(M33:M45) -> 4233180 | N47: =SUM(N33:N45) -> 7402456 | O47: =SUM(O33:O45) -> 4708123 | P47: =SUM(P33:P45) -> 0 | Q47: =SUM(Q33:Q45) -> 98450 | R47: =SUM(R33:R45) -> 435035 | S47: =SUM(S33:S45) -> 41352047
E49: Total liabilities and fund balances: | K49: =K47+K30+K25 -> 12526997 | L49: =L47+L30+L25 -> 12872368 | M49: =M47+M30+M25 -> 4630891 | N49: =N47+N30+N25 -> 8473443 | O49: =O47+O30+O25 -> 4743592 | P49: =P47+P30+P25 -> 1054370 | Q49: =Q47+Q30+Q25 -> 1546684 | R49: =R47+R30+R25 -> 1039973 | S49: =S47+S30+S25 -> 46888318

Sheet East Baton Rouge
D1: East Baton Rouge Combined Balance Sheet
D2: Issued: October 31, 2013
K4: General Fund | L4: Library Board of Control | M4: Grants | N4: Capital Projects Fund | O4: Other Governmental Funds | P4: Total Governmental Funds
A5: Assets:
B6: Cash and cash equivalents | K6: 52185904 | L6: 34081246 | M6: 2949710 | N6: 57614513 | O6: 38610250 | P6: =SUM(K6:O6) -> 185441623
B7: Investments | K7: 54315942 | L7: 35472317 | M7: 3070106 | N7: 57738466 | O7: 29741176 | P7: =SUM(K7:O7) -> 180338007
B8: Property taxes receivable - net | K8: 6004073 | L8: 8670001 | O8: 6877280 | P8: =SUM(K8:O8) -> 21551354
B9: Gross receipts business taxes receivable | K9: 4393186 | P9: =SUM(K9:O9) -> 4393186
B10: Sales taxes receivable | K10: 17089481 | N10: 2665986 | O10: 1502072 | P10: =SUM(K10:O10) -> 21257539
B11: Interest and penalties receivable on taxes | K11: 78595 | P11: =SUM(K11:O11) -> 78595
B12: Accounts receivable - net | K12: 1977504 | L12: 20578 | N12: 365864 | O12: 2096353 | P12: =SUM(K12:O12) -> 4460299
B13: Accrued interest receivable | K13: 47675 | L13: 36246 | M13: 3105 | N13: 51473 | O13: 24400 | P13: =SUM(K13:O13) -> 162899
B14: Due from other funds | K14: 7976168 | N14: 36255347 | P14: =SUM(K14:O14) -> 44231515
B15: Due from other governments | K15: 20133213 | L15: 29501049 | M15: 7535120 | N15: 2973657 | O15: 22237571 | P15: =SUM(K15:O15) -> 82380610
B16: Loans receivable | K16: 596224 | M16: 2934399 | P16: =SUM(K16:O16) -> 3530623
B17: Inventory | K17: 615439 | P17: =SUM(K17:O17) -> 615439
E19: Total assets: | K19: =SUM(K6:K17) -> 165413404 | L19: =SUM(L6:L17) -> 107781437 | M19: =SUM(M6:M17) -> 16492440 | N19: =SUM(N6:N17) -> 157665306 | O19: =SUM(O6:O17) -> 101089102 | P19: =SUM(P6:P17) -> 548441689
A21: LIABILITIES AND FUND BALANCES
B22: Liabilities:
C23: Accounts and contracts payable | K23: 16075632 | L23: 1875231 | M23: 3337321 | N23: 11702869 | O23: 3275049 | P23: =SUM(K23:O23) -> 36266102
C24: Due to other funds | L24: 35678938 | O24: 8552577 | P24: =SUM(K24:O24) -> 44231515
C25: Due to other governments | K25: 7095596 | O25: 294934 | P25: =SUM(K25:O25) -> 7390530
C26: Accrued payables | K26: 7064989 | L26: 797116 | M26: 650639 | N26: 11927 | O26: 1299271 | P26: =SUM(K26:O26) -> 9823942
C27: Unearned revenue | K27: 13000 | M27: 707137 | N27: 988957 | P27: =SUM(K27:O27) -> 1709094
C28: Deposits and escrow accounts | K28: 22364573 | M28: 138981 | P28: =SUM(K28:O28) -> 22503554
E30: Total liabilities: | K30: =SUM(K23:K28) -> 52613790 | L30: =SUM(L23:L28) -> 38351285 | M30: =SUM(M23:M28) -> 4834078 | N30: =SUM(N23:N28) -> 12703753 | O30: =SUM(O23:O28) -> 13421831 | P30: =SUM(P23:P28) -> 121924737
A32: DEFERRED INFLOWS OF RESOURCES
C33: Unavailable revenue - property taxes | K33: 793073 | L33: 1074827 | O33: 897168 | P33: =SUM(K33:O33) -> 2765068
C34: Unavailable revenue - revenue sharing | K34: 659910 | O34: 78110 | P34: =SUM(K34:O34) -> 738020
C35: Resources received before time requirements | M35: 526276 | P35: =SUM(K35:O35) -> 526276
E37: Total deferred inflows of resources: | K37: =SUM(K33:K35) -> 1452983 | L37: =SUM(L33:L35) -> 1074827 | M37: =SUM(M33:M35) -> 526276 | N37: =SUM(N33:N35) -> 0 | O37: =SUM(O33:O35) -> 975278 | P37: =SUM(P33:P35) -> 4029364
B39: Fund Balances
C40: Nonspendable | K40: 615439 | P40: =SUM(K40:O40) -> 615439
C41: Restricted | K41: 705538 | L41: 68355325 | M41: 11132086 | N41: 124171658 | O41: 78810662 | P41: =SUM(K41:O41) -> 283175269
C42: Committed | K42: 64390991 | N42: 20789895 | O42: 7881331 | P42: =SUM(K42:O42) -> 93062217
C43: Assigned | K43: 29980644 | P43: =SUM(K43:O43) -> 29980644
C44: Unrestricted | K44: 15654019 | P44: =SUM(K44:O44) -> 15654019
E46: Total fund balance: | K46: =SUM(K40:K44) -> 111346631 | L46: =SUM(L40:L44) -> 68355325 | M46: =SUM(M40:M44) -> 11132086 | N46: =SUM(N40:N44) -> 144961553 | O46: =SUM(O40:O44) -> 86691993 | P46: =SUM(P40:P44) -> 422487588
E48: Total liabilities and fund balances: | K48: =SUM(K46,K30,K37) -> 165413404 | L48: =SUM(L46,L30,L37) -> 107781437 | M48: =SUM(M46,M30,M37) -> 16492440 | N48: =SUM(N46,N30,N37) -> 157665306 | O48: =SUM(O46,O30,O37) -> 101089102 | P48: =SUM(P46,P30,P37) -> 548441689

Sheet East Carroll
D1: East Carroll Combined Balance Sheet
D2: Issued: December 31, 2013
K4: General | L4: Road Maintenance and Construction | M4: Garbage District No. 1 | N4: Library | O4: Drainage Maintenance | P4: Criminal Court | Q4: Nonmajor Governmental | R4: Total Governmental Funds
A5: Assets:
B6: Cash and Cash Equivalents | K6: 336645 | L6: 905539 | M6: 230383 | N6: 113864 | O6: 462268 | P6: 7775 | Q6: 698457 | R6: =SUM(K6:Q6) -> 2754931
B7: Investments | L7: 191528 | M7: 272650 | N7: 211580 | O7: 61659 | Q7: 99439 | R7: =SUM(K7:Q7) -> 836856
B8: Receivables | K8: 684348 | L8: 345819 | M8: 295021 | N8: 256164 | O8: 271292 | P8: 15584 | Q8: 376537 | R8: =SUM(K8:Q8) -> 2244765
B9: Interfund receivables | K9: 149037 | N9: 9383 | R9: =SUM(K9:Q9) -> 158420
E11: Total assets: | K11: =SUM(K6:K9) -> 1170030 | L11: =SUM(L6:L9) -> 1442886 | M11: =SUM(M6:M9) -> 798054 | N11: =SUM(N6:N9) -> 590991 | O11: =SUM(O6:O9) -> 795219 | P11: =SUM(P6:P9) -> 23359 | Q11: =SUM(Q6:Q9) -> 1174433 | R11: =SUM(R6:R9) -> 5994972
A13: LIABILITIES AND FUND BALANCES
B14: Liabilities:
C15: Accounts payable | K15: 189268 | L15: 2426 | M15: 6627 | N15: 24 | P15: 20344 | Q15: 214 | R15: =SUM(K15:Q15) -> 218903
C16: Interfund payables | K16: 9383 | P16: 149037 | R16: =SUM(K16:Q16) -> 158420
E18: Total liabilities: | K18: =SUM(K15:K16) -> 198651 | L18: =SUM(L15:L16) -> 2426 | M18: =SUM(M15:M16) -> 6627 | N18: =SUM(N15:N16) -> 24 | O18: =SUM(O15:O16) -> 0 | P18: =SUM(P15:P16) -> 169381 | Q18: =SUM(Q15:Q16) -> 214 | R18: =SUM(R15:R16) -> 377323
B20: Fund Balances
C21: Restricted | L21: 1440460 | M21: 791427 | N21: 590967 | O21: 795219 | Q21: 1174219 | R21: =SUM(K21:Q21) -> 4792292
C22: Unassigned | K22: 971379 | P22: -146022 | R22: =SUM(K22:Q22) -> 825357
E24: Total fund balance: | K24: =SUM(K21:K22) -> 971379 | L24: =SUM(L21:L22) -> 1440460 | M24: =SUM(M21:M22) -> 791427 | N24: =SUM(N21:N22) -> 590967 | O24: =SUM(O21:O22) -> 795219 | P24: =SUM(P21:P22) -> -146022 | Q24: =SUM(Q21:Q22) -> 1174219 | R24: =SUM(R21:R22) -> 5617649
E26: Total liabilities and fund balances: | K26: =K24+K18 -> 1170030 | L26: =L24+L18 -> 1442886 | M26: =M24+M18 -> 798054 | N26: =N24+N18 -> 590991 | O26: =O24+O18 -> 795219 | P26: =P24+P18 -> 23359 | Q26: =Q24+Q18 -> 1174433 | R26: =R24+R18 -> 5994972

Sheet East Feliciana
D1: East Feliciana Combined Balance Sheet
D2: Issued: December 31, 2013
K4: General Fund | L4: Roads and Bridges | M4: Solid Waste | N4: Other Governmental Funds | O4: Total Governmental Funds
A5: Assets:
B6: Cash and cash equivalents | K6: 1090218.1 | L6: 2214339.9 | M6: 2062588 | N6: 146265.77 | O6: =SUM(K6:N6) -> 5513411.8
B7: Receivables, net:
C8: Accounts | K8: 2996.99 | N8: 6961.2 | O8: =SUM(K8:N8) -> 9958.19
C9: Taxes | K9: 345031.11 | M9: 112599.85 | N9: 370612.95 | O9: =SUM(K9:N9) -> 828243.91
B10: Due from other funds | K10: 207683.02 | L10: 115077 | M10: 1275000 | O10: =SUM(K10:N10) -> 1597760
B11: Due from other govt agencies | K11: 57338.6 | L11: 23723.36 | N11: 41871 | O11: =SUM(K11:N11) -> 122932.96
E13: Total assets: | K13: =SUM(K6:K11) -> 1703267.8 | L13: =SUM(L6:L11) -> 2353140.3 | M13: =SUM(M6:M11) -> 3450187.9 | N13: =SUM(N6:N11) -> 565710.92 | O13: =SUM(O6:O11) -> 8072306.8
A15: LIABILITIES AND FUND BALANCES
B16: Liabilities:
C17: Accounts payable | K17: 60416.02 | L17: 88163.13 | M17: 84757.3 | N17: 2605.57 | O17: =SUM(K17:N17) -> 235942.02
C18: Due to other funds | L18: 1275000 | M18: 22920.89 | N18: 154480.04 | O18: =SUM(K18:N18) -> 1452400.9
C19: Due to other govt agencies | N19: 12350.44 | O19: =SUM(K19:N19) -> 12350.44
E21: Total liabilities: | K21: =SUM(K17:K19) -> 60416.02 | L21: =SUM(L17:L19) -> 1363163.1 | M21: =SUM(M17:M19) -> 107678.19 | N21: =SUM(N17:N19) -> 169436.05 | O21: =SUM(O17:O19) -> 1700693.4
B23: Fund Balances (Deficit):
C24: Restricted for: | O24: =SUM(K24:N24) -> 0
D25: Health unit oper/maintenance | N25: 532497.89 | O25: =SUM(K25:N25) -> 532497.89
D26: Homeland security | K26: 49454.42 | O26: =SUM(K26:N26) -> 49454.42
D27: Solid waste management | M27: 3342509.7 | O27: =SUM(K27:N27) -> 3342509.7
C28: Committed to:
D29: Debt service | K29: 8131.4 | O29: =SUM(K29:N29) -> 8131.4
D30: Road improvements | L30: 989977.15 | O30: =SUM(K30:N30) -> 989977.15
D31: Coroner/court operations | N31: -136223.02 | O31: =SUM(K31:N31) -> -136223.02
D32: Claims and judgements | K32: 152370.09 | O32: =SUM(K32:N32) -> 152370.09
C33: Unassigned | K33: 1432895.9 | O33: =SUM(K33:N33) -> 1432895.9
