Workbook

Sheet Acadia
C1: Acadia Parish 2014 Statement of Net Assets
D2: Issued: December 31, 2014
H4: Primary Government | I4: Component Units
A5: ASSETS
B6: Cash | H6: 8972007 | I6: 37066
B7: Investments | H7: 7896569
B8: Taxes receivable | H8: 497168
B9: Special assessments receivable | H9: 18188
B10: Other receivables | H10: 56204
B11: Due from other governmental entities | H11: 6041763 | I11: 33659
B12: Due from component units | H12: 20249
B13: Capital assets:
C14: Non-depreciable | H14: 1945511
C15: Depreciable, net | H15: 51047200
C17: Total Assets | H17: =SUM(H6:H15) -> 76494859 | I17: =SUM(I6:I15) -> 70725
A19: Deferred Outflows of Resources
B20: Deferred loss on refunding | H20: 24822
C22: Total assets and deferred outflows of resources | H22: =H17+H20 -> 76519681 | I22: =I17+I20 -> 70725
A24: Liabilities
B25: Accounts payable | H25: 871484 | I25: 10260
B26: Retainage payable | H26: 7879
B27: Accured liabilites and other payables | H27: 606926
B28: Unearned revenues | H28: 45000
B29: Accrued interest payable | H29: 69355
B30: Due to primary government | I30: 20249
B31: Long-term liabilities
C32: Portion due or payable within one year-
D33: Bonds payable | H33: 1542435
D34: Compensated absences | H34: 187122
C35: Portion due or payable after one year-
D36: Bonds payable | H36: 11233348
D37: Compensated absences | H37: 187122
D38: Landfill closure and postclosure care
E39: costs liability | H39: 7158993
D42: Total Liabilities | H42: =SUM(H25:H39) -> 21909664 | I42: =SUM(I25:I39) -> 30509
A44: Deferred Outflows of Resources
B45: Unavailable revenue- special assessments | H45: 18188
A48: NET ASSETS
B49: Investment in capital assets | H49: 40241750
B50: Restricted for:
...

Sheet Allen
C1: Allen Parish 2014 Statement of Net Assets
C2: Issued: December 31, 2014
G4: Governmental Activities
A5: ASSETS
B6: Cash and cash equivalents | G6: 14858366
B7: Receivables | G7: 6484761
B8: Due from other governments | G8: 313803
B9: Inventory
B10: Prepaid assets | G10: 806735
B11: Capital assets, net of accumulated depreciation | G11: 9930994
B13: Total Assets | G13: =SUM(G6:G11) -> 32394659
A15: LIABILITIES
B16: Accounts payable | G16: 626637
B17: Accrued interest payable | G17: 1476
B18: Unearned revenue | G18: 48703
B19: Bonds payable - due within one year | G19: 62000
B20: Compensated absences payable - due
C21: within one year | G21: 26940
B22: OPEB obligations - due in more
C23: than one year | G23: 1149691
B24: Bonds payable - due in more than one year | G24: 148000
C26: Total Liabilities | G26: =SUM(G16:G24) -> 2063447
A28: NET ASSETS
B29: Invested in capital assets, net of related debt | G29: 27191700
B30: Restricted for:
C31: Inventory | G31: 313803
C32: Equipment purchases | G32: 324072
C33: Public safety | G33: 1810976
C34: Public works | G34: 6392675
C35: Health and welfare | G35: 2463098
C36: Culture and recreation | G36: 607692
C37: Sanitation | G37: 3275003
C38: Other general government | G38: 136917
C39: Capital projects | G39: 1275201
C40: Debt service | G40: 166216
B41: Unrestricted | G41: 3848367
B43: Total Net Assets | G43: =SUM(G29:G41) -> 47805720
B45: Total Liabilities and Net Assets | G45: =SUM(G26+G43) -> 49869167

Sheet Ascension
D1: Ascension Parish 2014 Statement of Net Assets
D2: Issued: December 31, 2014
I4: Primary Government | L4: Component Unit
I5: Governmental Activities | J5: Business-type Activities | K5: Total | L5: Governmental Activities | M5: Business-type Activities
A6: ASSETS
B7: Current Assets
C8: Cash and cash equivalents | I8: 42404828 | J8: 3686409 | K8: =SUM(I8:J8) -> 46091237 | L8: 30169983 | M8: 457571
C9: Investments | I9: 93691087 | J9: 4127466 | K9: =SUM(I9:J9) -> 97818553 | L9: 4943491 | M9: 9681370
C10: Accounts receivable, net | I10: 31751994 | J10: 211156 | K10: =SUM(I10:J10) -> 31963150 | L10: 3767692 | M10: 1153256
C11: Due from other governments | I11: 5021470 | J11: 104475 | K11: =SUM(I11:J11) -> 5125945 | L11: 1125619
C12: Internal balances | I12: 5 | J12: -5 | K12: =SUM(I12:J12) -> 0
C13: Prepaid assets | I13: 1008407 | J13: 281 | K13: =SUM(I13:J13) -> 1008688 | L13: 173484
C14: Inventory | J14: 22147 | K14: =SUM(I14:J14) -> 22147 | M14: 240233
C15: Restricted assets | J15: 36464 | K15: =SUM(I15:J15) -> 36464 | L15: 709316 | M15: 548502
C16: Other assets | I16: 97173 | K16: =SUM(I16:J16) -> 97173 | L16: 6681 | M16: 116241
C17: Capital assets:
E18: Nondepreciable | I18: 73100022 | J18: 941205 | K18: =SUM(I18:J18) -> 74041227 | L18: 1945991 | M18: 110902
E19: Depreciable, net | I19: 136464488 | J19: 9952083 | K19: =SUM(I19:J19) -> 146416571 | L19: 11921812 | M19: 11753708
C21: Total Assets | I21: =SUM(I8:I19) -> 383539474 | J21: =SUM(J8:J19) -> 19081681 | K21: =SUM(K8:K19) -> 402621155 | L21: =SUM(L8:L19) -> 54764069 | M21: =SUM(M7:M19) -> 24061783
A23: Deferred Outflows of Resources
B24: Deferred loss on refunding bonds, net | I24: 294404 | J24: 0 | K24: =SUM(I24:J24) -> 294404 | L24: 0 | M24: 0
C26: Total assets and deferred outflows of resources | I26: =SUM(I24+I21) -> 383833878 | J26: =J21 -> 19081681 | K26: =K24+K21 -> 402915559 | L26: =L21 -> 54764069 | M26: =M21 -> 24061783
A28: LIABILITIES
C29: Accounts payable and accrued liabilities | I29: 3198900 | J29: 565558 | K29: =SUM(I29:J29) -> 3764458 | L29: 3210186 | M29: 352605
C30: Contracts payable | I30: 3980044 | K30: =SUM(I30:J30) -> 3980044
C31: Due to other goevernments | I31: 269707 | K31: =SUM(I31:J31) -> 269707 | L31: 1136146
C32: Accrued payroll | I32: 540668 | J32: 28220 | K32: =SUM(I32:J32) -> 568888
C33: Customer deposits | J33: 36464 | K33: =SUM(I33:J33) -> 36464 | M33: 43501
C34: Sales tax rebate reserve | I34: 4524981 | K34: =SUM(I34:J34) -> 4524981
C35: Claims reserve | K35: =SUM(I35:J35) -> 0
D36: Due within one year | I36: 235409 | K36: =SUM(I36:J36) -> 235409
D37: Due in more than one year | I37: 667416 | K37: =SUM(I37:J37) -> 667416
C38: Long-term payable | K38: =SUM(I38:J38) -> 0
D39: Due within one year | I39: 4335000 | K39: =SUM(I39:J39) -> 4335000 | L39: 551031 | M39: 176485
D40: Due in more than one year | I40: 80612569 | K40: =SUM(I40:J40) -> 80612569 | L40: 6694058 | M40: 4766994
D42: Total Liabilities | I42: =SUM(I29:I40) -> 98364694 | J42: =SUM(J29:J40) -> 630242 | K42: =SUM(K29:K40) -> 98994936 | L42: =SUM(L29:L40) -> 11591421 | M42: =SUM(M29:M40) -> 5339585
A44: Deferred Inflows of Resources
B45: Grant Advances | I45: 629856 | J45: 0 | K45: =SUM(I45:J45) -> 629856 | L45: 0 | M45: 0
B46: Unearned Revenue | I46: 0 | J46: 18770 | K46: =SUM(I46:J46) -> 18770 | L46: 0 | M46: 0
D48: Total deferred inflows of resources | I48: =SUM(I45:I46) -> 629856 | J48: =SUM(J45:J46) -> 18770 | K48: =SUM(K45:K46) -> 648626 | L48: 0 | M48: 0
...

Sheet Assumption
D1: Assumption Parish 2014 Statement of Net Assets
D2: Issued: December 31, 2014
H4: Primary Government | I4: Component Units
A5: ASSETS
B6: Current Assets
C7: Cash and cash equivalents | H7: 2824757 | I7: 1215826
C8: Investments | H8: 18123491 | I8: 3932994
C9: Receivables | H9: 5769470 | I9: 1510860
C10: Other assets | I10: 260463
C11: Restricted investments | I11: 3899610
C12: Net investment in capital assets | H12: 42293964 | I12: 15878625
C14: Total Assets | H14: =SUM(H7:H12) -> 69011682 | I14: =SUM(I7:I12) -> 26698378
A16: LIABILITIES AND NET POSITION
B17: Liabilities
C18: Accounts payable | H18: 554277 | I18: 704225
C19: Salaries payable | H19: 129885 | I19: 11722
C20: Compensated absences payable | H20: 163079 | I20: 29149
C21: Other post-employment benefits payable | H21: 868870 | I21: 888799
C22: Other liabilities | H22: 422634 | I22: 335861
C23: Long-term liabilities:
D24: Due within one year | I24: 510000
D25: Due in more than one year | I25: 4800000
D27: Total Liabilities | H27: =SUM(H18:H25) -> 2138745 | I27: =SUM(I18:I25) -> 7279756
A29: NET ASSETS
B30: Invested in capital assets, net of related debt | H30: 42293964 | I30: 10568623
B31: Restricted for revenue bond debt service and contingencies | I31: 3899380
B32: Unrestricted | H32: 24582973 | I32: 4950619
C34: Total Net Assets | H34: =SUM(H30:H32) -> 66876937 | I34: =SUM(I29:I32) -> 19418622
C36: Total Liabilities and Net Assets | H36: =SUM(H27+H34) -> 69015682 | I36: =SUM(I27+I34) -> 26698378

Sheet Avoyelles
D1: Avoyelles Parish 2014 Statement of Net Assets
D2: Issued: December 31, 2014
H4: Primary Government
A5: ASSETS
B6: Current Assets
C7: Cash and interest-bearing deposits | H7: 9443859
C8: Receivables, net | H8: 56433
C9: Due from other governmental units | H9: 2631894
C10: Prepaid items | H10: 148720
C12: Total Current Assets | H12: =SUM(H7:H10) -> 12280906
B14: Non-current Assets:
C15: Land and construction in progress | H15: 590548
C16: Capital assets, net | H16: 4599312
C18: Total Non-current Assets | H18: =SUM(H14:H16) -> 5189860
C20: Total Assets | H20: =SUM(H12+H18) -> 17470766
A22: LIABILITIES
B23: Current Liabilities:
C24: Accounts, salaries and other payables | H24: 712402
C25: Unearned revenue | H25: 36260
D27: Total Current Liabilities | H27: =SUM(H24:H25) -> 748662
B29: Non-current Liabilities
C30: Compensated absences payable | H30: 99940
D32: Total Liabilities | H32: =H30+H27 -> 848602
A34: NET ASSETS
B35: Net investment in capital assets | H35: 5189860
B36: Unrestricted | H36: 11432304
C38: Total Net Assets | H38: =SUM(H35:H36) -> 16622164
C40: Total Liabilities and Net Assets | H40: =H38+H32 -> 17470766

Sheet Beauregard
C1: Beauregard Parish 2014 Statement of Net Assets
C2: Issued: December 31, 2014
G4: Governmental Activities
A5: ASSETS
B6: Cash and cash equivalents | G6: 17545772
B7: Receivables | G7: 6974145
B8: Inventory | G8: 204510
B9: Capital assets (net of accumulated depreciation):
C10: Land | G10: 688379
C11: Buildings and improvements | G11: 9185546
C12: Furniture and equipment | G12: 4096339
C13: Infrastructure | G13: 15391434
C14: Construction in progress | G14: 2175228
B16: Total Assets | G16: =SUM(G6:G14) -> 56261353
A18: LIABILITIES
B19: Accounts, salaries, and other payables | G19: 1028338
B20: Interest payable | G20: 25763
B21: Long-term liabilities:
C22: Due within one year | G22: 553200
C23: Due in more than one year | G23: 4845000
C25: Total Liabilities | G25: =SUM(G19:G23) -> 6452301
A27: NET ASSETS
B28: Invested in capital assets, net of related debt | G28: 26350226
B29: Restricted for:
C30: Inventory | G30: 204510
C31: Equipment purchases | G31: 306908
C32: Public safety | G32: 1932609
C33: Public works | G33: 6543000
C34: Health and welfare | G34: 2551297
C35: Culture and recreation | G35: 536904
C36: Sanitation | G36: 4491195
C37: Other general government | G37: 151475
C38: Capital projects | G38: 3820546
C39: Debt service | G39: 149912
B40: Unrestricted | G40: 2770770
B42: Total Net Assets | G42: =SUM(G28:G40) -> 49809352
B44: Total Liabilities and Net Assets | G44: =SUM(G25+G42) -> 56261653

Sheet Bienville
C1: Bienville Parish 2014 Statement of Net Assets
C2: Issued: December 31, 2014
G4: Governmental Activities
A5: ASSETS
B6: Cash and cash equivalents | G6: 17166902
B7: Receivables | G7: 5274448
B8: Capital assets, net | G8: 22504607
B10: Total Assets | G10: =SUM(G6:G8) -> 44945957
A12: LIABILITIES
B13: Accounts payable | G13: 210615
B14: Wages and related payable | G14: 30252
B15: Interest payable | G15: 136529
B16: Bonds payable | G16: 10365000
B17: Premium on bonds | G17: 274509
B18: Deferred revenues | G18: 70000
B19: Compensated absences payable | G19: 80615
B20: Other post-employment benefits | G20: 1751911
C22: Total Liabilities | G22: =SUM(G13:G20) -> 12919431
A24: NET ASSETS
B25: Invested in capital assets, net of related debt | G25: 12139607
B26: Unrestricted | G26: 19886919
B28: Total Net Assets | G28: =SUM(G25:G26) -> 32026526
B30: Total Liabilities and Net Assets | G30: =SUM(G22+G28) -> 44945957

Sheet Bossier
D1: Bossier Parish 2014 Statement of Net Assets
D2: Issued: December 31, 2014
H5: Governmental Activities | I5: Business-Type Activities | J5: Total
A6: ASSETS
C7: Cash and cash equivalents | H7: 40504142 | I7: 258697 | J7: =SUM(H7:I7) -> 40762839
C8: Restricted cash | H8: 4879227 | I8: 1081529 | J8: =SUM(H8:I8) -> 5960756
C9: Investments | H9: 170335 | J9: =SUM(H9:I9) -> 170335
C10: Receivables | H10: 23074512 | I10: 224210 | J10: =SUM(H10:I10) -> 23298722
C11: Prepaid expenses | H11: 922606 | I11: 38252 | J11: =SUM(H11:I11) -> 960858
C12: Capital assets, net:
D13: Non-depreciable | H13: 19244357 | I13: 16269418 | J13: =SUM(H13:I13) -> 35513775
D14: Depreciable (net) | H14: 265881743 | I14: 4609925 | J14: =SUM(H14:I14) -> 270491668
C15: Internal balances | H15: 8243332 | I15: -8243332 | J15: =SUM(H15:I15) -> 0
C17: Total Assets | H17: =SUM(H7:H15) -> 362920254 | I17: =SUM(I7:I15) -> 14238699 | J17: =SUM(J7:J15) -> 377158953
A19: LIABILITIES
B20: Current
C21: Accounts payable and accrued expenses | H21: 5670884 | I21: 316283 | J21: =SUM(H21:I21) -> 5987167
C22: Payable from restricted assets:
D23: Customer deposits | I23: 112887 | J23: =SUM(H23:I23) -> 112887
B24: Noncurrent liabilities
C25: Due within one year | H25: 4998865 | I25: 80000 | J25: =SUM(H25:I25) -> 5078865
C26: Due in more than one year | H26: 56933777 | I26: 1662385 | J26: =SUM(H26:I26) -> 58596162
D28: Total Liabilities | H28: =SUM(H21+H23+H25+H26) -> 67603526 | I28: =SUM(I21+I23+I25+I26) -> 2171555 | J28: =SUM(J21+J23+J25+J26) -> 69775081
A30: Deferred Inflows of Resouces
C31: Unavailable revenue- property taxes | H31: 15065078 | J31: =SUM(H31:I31) -> 15065078
A33: NET ASSETS
B34: Net investment in capital assets | H34: 234828358 | I34: 10893626 | J34: =SUM(H34:I34) -> 245721984
B35: Restricted for:
C36: Capital projects | H36: 10572534 | J36: =SUM(H36:I36) -> 10572534
C37: Public works | H37: 1299267 | J37: =SUM(H37:I37) -> 1299267
C38: Public safety | H38: 1000587 | J38: =SUM(H38:I38) -> 1000587
C39: Economic development | H39: 110911 | J39: =SUM(H39) -> 110911
C40: Culture and recreation | H40: 5359731 | J40: =SUM(H40) -> 5359731
C41: Debt service | H41: 3470999 | J41: =SUM(H41) -> 3470999
C42: Health and welfare | H42: 2174851 | J42: =SUM(H42) -> 2174851
C43: Sewer operations | H43: 360910 | J43: =SUM(H43:I43) -> 360910
B44: Unrestricted | H44: 21073502 | I44: 1173518 | J44: =SUM(H44:I44) -> 22247020
C46: Total Net Assets | H46: =SUM(H34:H44) -> 280251650 | I46: =SUM(I34:I44) -> 12067144 | J46: =SUM(J34:J44) -> 292318794
C48: Total Liabilities and Net Assets | H48: =SUM(H46+H31+H28) -> 362920254 | I48: =SUM(I46+I31+I28) -> 14238699 | J48: =SUM(J46+J31+J28) -> 377158953

Sheet Caddo
D1: Caddo Parish 2014 Statement of Net Assets
D2: Issued: December 31, 2014
H5: Primary government | I5: Component Units
A6: ASSETS
C7: Cash and cash equivalents | H7: 15950171 | I7: 13698250
C8: Investments | H8: 119354639 | I8: 5477656
C9: Receivables, net | H9: 56915285 | I9: 15284875
C10: Due from other governments | H10: 3504844 | I10: 847274
C11: Due from primary government | I11: 571302
C12: Inventories | H12: 97808 | I12: 364398
C13: Other assets | H13: 116149 | I13: 9975946
C14: Capital assets:
D15: Land and construction in progress | H15: 20514314 | I15: 7473191
D16: Other capital assets, net of depreciation | H16: 183428797 | I16: 35403414
C18: Total Assets | H18: =SUM(H7:H16) -> 399882007 | I18: =SUM(I7:I16) -> 89096306
A20: DEFERRED OUTFLOWS OF RESOURCES
C21: Deferred loss on refunding bonds, net | H21: 146667 | I21: 151285
E23: Total assets and deferred outlfows of resources | H23: =H21+H18 -> 400028674 | I23: =I21+I18 -> 89247591
A25: LIABILITIES
C26: Accounts payable | H26: 2890397 | I26: 3145936
C27: Accrued liabilities | H27: 918576 | I27: 1171920
C28: Accrued interest payable | H28: 489926 | I28: 29614
C29: Retainage payable | H29: 353334
C30: Accrued insurance claims payable | H30: 641458 | I30: 414000
C31: Due to component units | H31: 520956
C32: Due to other governmental agencies | H32: 118146 | I32: 368089
C33: Unearned revenue | H33: 35478 | I33: 49709
C34: Noncurrent liabilities:
D35: Due within one year | H35: 3114529 | I35: 3334350
D36: Due in more than one year | H36: 40226768 | I36: 28163537
D38: Total Liabilities | H38: =SUM(H26:H36) -> 49309568 | I38: =SUM(I26:I36) -> 36677155
A40: Deferred inflows of Resources
C41: Unavailable revenue- property taxes and assessments- service charges | I41: 1787930
D43: Total liabilities and deferred inflows of resources | H43: =SUM(H41+H38) -> 49309568 | I43: =SUM(I41+I38) -> 38465085
A44: NET ASSETS
B45: Net investment in capital assets | H45: 172306406 | I45: 24635594
B46: Restricted for:
C47: Criminal justice | H47: 14884859
C48: Health and welfare | H48: 4844635
C49: Highways, streets and drainage | H49: 31807558
...

Sheet Caldwell
C1: Caldwell Parish 2014 Statement of Net Assets
C2: Issued: December 31, 2014
G4: Governmental Activities
A5: ASSETS
B6: Cash and cash equivalents | G6: 7860568
B7: Receivables | G7: 1821397
B8: Capital assets, net of accumulated depreciation | G8: 14109112
B10: Total Assets | G10: =SUM(G6:G8) -> 23791077
A12: LIABILITIES
B13: Accounts, salaries, and other payables | G13: 244089
B14: Due to other agencies | G14: 57698
B15: Compensated absences payable | G15: 119522
C17: Total Liabilities | G17: =SUM(G13:G15) -> 421309
A19: NET ASSETS
B20: Net investment in capital assets | G20: 14109112
B21: Restricted | G21: 6856564
B22: Unrestricted | G22: 2404092
B24: Total Net Assets | G24: =SUM(G20:G22) -> 23369768
B26: Total Liabilities and Net Assets | G26: =SUM(G17+G24) -> 23791077

Sheet Catahoula
D1: Catahoula Parish 2014 Statement of Net Assets
D2: Issued: December 31, 2014
I4: Component Units
H5: Governmental Activities | I5: Fire District No. 1 Maintenance
A6: ASSETS
C7: Cash and cash equivalents | H7: 2290596 | I7: 104637
C8: Cash restricted for debt service | H8: 26325
C9: Cash restricted for capital project
C10: Receivables | H10: 1411486 | I10: 14594
C11: Other assets | H11: 81766
C12: Capital assets, net of accumulated depreciation | H12: 5862816 | I12: 88616
C14: Total Assets | H14: =SUM(H7:H12) -> 9672989 | I14: =SUM(I7:I12) -> 207847
A16: LIABILITIES
C17: Accounts, salaries, and other payables | H17: 144719 | I17: 526
C18: Compensated absences | H18: 32033
C19: Certificates of indebtedness due within one year | H19: 104000
C20: Certificates of indebtedness due in more than one | H20: 272000
D22: Total Liabilities | H22: =SUM(H17:H20) -> 552752 | I22: =SUM(I17:I20) -> 526
A24: DEFERRED INFLOWS
C25: Grant revenues pending | H25: 14777
A27: NET ASSETS
B28: Net investment in capital assets | H28: 5750215 | I28: 88616
B29: Unrestricted net position | H29: 3220628 | I29: 118705
C31: Total Net Assets | H31: =SUM(H28:H29) -> 8970843 | I31: =SUM(I28:I29) -> 207321
C33: Total Liabilities and Net Assets | H33: =SUM(H22+H31+H25) -> 9538372 | I33: =SUM(I31+I22) -> 207847

Sheet Calcasieu
D1: Calcasieu Parish 2014 Statement of Net Assets
D2: Issued: December 31, 2014
H4: Primary Government
H5: Governmental Activities | I5: Business-Type Activities | J5: Total | K5: Component Unit
A6: ASSETS
C7: Cash and cash equivalents | H7: 58437555 | I7: 313815 | J7: =SUM(H7:I7) -> 58751370 | K7: 43640254
C8: Investments | H8: 208827036 | I8: 971149 | J8: =SUM(H8:I8) -> 209798185 | K8: 48040669
C9: Receivables (net of allowance for uncollectibles) | H9: 54814781 | I9: 458456 | J9: =SUM(H9:I9) -> 55273237 | K9: 64038752
C10: Intergovernmental receivable | H10: 2785381 | J10: =SUM(H10:I10) -> 2785381 | K10: 1774669
C11: Due from component units | H11: 27125 | I11: 52541 | J11: =SUM(H11:I11) -> 79666
C12: Due from primary government | J12: =SUM(H12:I12) -> 0 | K12: 58216
C13: Loan receivable | H13: 33189 | J13: =SUM(H13:I13) -> 33189
C14: Prepaid items | H14: 236100 | I14: 20099 | J14: =SUM(H14:I14) -> 256199 | K14: 1756410
C15: Inventory | H15: 1175401 | J15: =SUM(H15:I15) -> 1175401 | K15: 1940603
C16: Other assets | I16: 320 | J16: =SUM(H16:I16) -> 320 | K16: 222243
C17: Restricted assets:
D18: Cash and cash equivalents | I18: 11173 | J18: =SUM(H18:I18) -> 11173 | K18: 5437563
D19: Investments | I19: 222206 | J19: =SUM(H19:I19) -> 222206 | K19: 7040297
D20: Receivables - net | I20: 189350 | J20: =SUM(H20:I20) -> 189350 | K20: 3013281
C21: Capital assets:
D22: Non-depreciable | H22: 420818629 | I22: 252770 | J22: =SUM(H22:I22) -> 421071399 | K22: 38320566
D23: Depreciable, net | H23: 97989562 | I23: 8819750 | J23: =SUM(H23:I23) -> 106809312 | K23: 210376526
C25: Total Assets | H25: =SUM(H7:H23) -> 845144759 | I25: =SUM(I7:I23) -> 11311629 | J25: =SUM(J7:J23) -> 856456388 | K25: =SUM(K7:K23) -> 425660049
A27: DEFERRED OUTFLOWS OF RESOURCES
C28: Deferred amount on refunding | K28: 65281
A30: LIABILITIES
C31: Accounts payable and other accrued liabilities | H31: 7910576 | I31: 103090 | J31: =SUM(H31:I31) -> 8013666 | K31: 10957145
C32: Intergovernmental payable | H32: 3573549 | J32: =SUM(H32:I32) -> 3573549 | K32: 1128353
C33: Due to primary government | J33: =SUM(H33:I33) -> 0 | K33: 79666
C34: Due to component units | H34: 58216 | J34: =SUM(H34:I34) -> 58216
C35: Unearned revenue | H35: 1089097 | J35: =SUM(H35:I35) -> 1089097 | K35: 105362
C36: Other liabilities | H36: 371818 | J36: =SUM(H36:I36) -> 371818 | K36: 326547
C37: Liabilities payable from restricted assets | I37: 122470 | J37: =SUM(H37:I37) -> 122470 | K37: 791128
C38: Noncurrent liabilities:
D39: Due within one year | H39: 2707932 | I39: 41626 | J39: =SUM(H39:I39) -> 2749558 | K39: 8459117
D40: Due in more than one year | H40: 7467672 | I40: 274460 | J40: =SUM(H40:I40) -> 7742132 | K40: 50270434
D42: Total Liabilities | H42: =SUM(H31:H40) -> 23178860 | I42: =SUM(I31:I40) -> 541646 | J42: =SUM(J31:J40) -> 23720506 | K42: =SUM(K31:K40) -> 72117752
A44: DEFERRED INFLOWS OF RESOURCES
C45: Property taxes levied for the next fiscal year | H45: 47096091 | J45: =SUM(H45:I45) -> 47096091 | K45: 21173199
A47: NET ASSETS
...

Sheet Cameron
C1: Cameron Parish 2014 Statement of Net Assets
C2: Issued: December 31, 2014
G4: Governmental Activities
A5: ASSETS
B6: Cash | G6: 28467308
B7: Receivables, net | G7: 16614795
B8: Inventory, at cost | G8: 1822766
B9: Other | G9: 146710
B10: Capital assets, net of accumulated depreciation | G10: 123967765
B12: Total Assets | G12: =SUM(G6:G10) -> 171019344
A14: LIABILITIES
B15: Accounts, salaries, and other payables | G15: 3869415
B16: Due to other agencies | G16: 2623074
B17: Unearned revenue | G17: 17231
B18: Interest payable | G18: 72342
B19: Long-term liabilities:
C20: Due within one year | G20: 1420448
C21: Due after one year | G21: 4202746
C23: Total Liabilities | G23: =SUM(G15:G21) -> 12205256
A25: DEFERRED INFLOWS OF RESOURCES
A27: NET ASSETS
B28: Net investment in capital assets | G28: 118625621
B29: Net position - restricted for:
C30: Judicial | G30: 58817
C31: Debt service | G31: 999067
C32: Tourism development | G32: 39983
C33: Inventories | G33: 1822766
C34: Prepaid expenses | G34: 146710
B35: Net position - unrestricted | G35: 37121124
B37: Total Net Assets | G37: =SUM(G28:G35) -> 158814088
B39: Total Liabilities and Net Assets | G39: =SUM(G23+G37) -> 171019344

Sheet Claiborne
C1: Claiborne Parish 2014 Statement of Net Assets
C2: Issued: December 31, 2014
G4: Governmental Activities
A5: ASSETS
B6: Cash and cash equivalents | G6: 6269126
B7: Investments | G7: 797211
B8: Receivables | G8: 3084505
B9: Due from other agencies | G9: 22416
B10: Deferred charges | G10: 107283
B11: Capital assets, net of accumulated depreciation | G11: 8219499
B13: Total Assets | G13: =SUM(G6:G11) -> 18500040
A15: LIABILITIES
B16: Accounts, salaries, and other payables | G16: 446867
B17: Due to other agencies | G17: 14025
B18: Deferred revenue | G18: 15626
B19: Compensated absences payable | G19: 57248
B20: Bonds payable within one year | G20: 155000
B21: Bonds payable in more than one year | G21: 1545000
C23: Total Liabilities | G23: =SUM(G16:G21) -> 2233766
A25: NET ASSETS
B26: Net investment in capital assets | G26: 6362770
B27: Restricted for:
C28: General government | G28: 471359
C29: General government - judicial | G29: 165209
C30: Public works | G30: 2721807
C31: Public safety | G31: 273907
C32: Health and welfare | G32: 257550
C33: Culture and recreation | G33: 1394279
B34: Unrestricted | G34: 4619394
B36: Total Net Assets | G36: =SUM(G26:G34) -> 16266275
B38: Total Liabilities and Net Assets | G38: =SUM(G23+G36) -> 18500041

Sheet Concodria
C1: Concordia Parish 2014 Statement of Net Assets
C2: Issued: December 31, 2014
G4: Governmental Activities
A5: ASSETS
B6: Current Assets
B7: Cash and cash equivalents | G7: 7138217
B8: Cash and cash equivalents - restricted | G8: 2563431
B9: Acounts Receivable | G9: 167238
B10: Ad valorem taxes receivable, net | G10: 1599471
B11: Sales and use taxes receivable | G11: 257934
B12: Severance taxes receivable | G12: 143713
B14: Total Assets | G14: =SUM(G7:G12) -> 11870004
B16: Capital Assets
B17: Proptery and equipment, net | G17: 10215629
G18: =SUM(G14+G17) -> 22085633
A20: LIABILITIES
B21: Current liabilities:
C22: Accounts payable | G22: 175950
C23: Interest payable | G23: 237717
C24: Accured payroll and benefits | G24: 83974
C25: Sales tax bonds- due within one year | G25: 390767
G26: =SUM(G22:G25) -> 888408
B28: Noncurrent liabilities:
C29: Sales tax bonds | G29: 9013491
C31: Total Liabilities | G31: =SUM(G29+G26) -> 9901899
A33: NET ASSETS
B34: Net investment in capital assets | G34: 1120455
B35: Restricted for:
C36: Debt service | G36: 2643431
C37: Special projects | G37: 5376698
B38: Unrestricted | G38: 3043150
B40: Total Net Assets | G40: =SUM(G34:G38) -> 12183734
B42: Total Liabilities and Net Assets | G42: =SUM(G31+G40) -> 22085633

Sheet DeSoto
D1: DeSoto Parish 2014 Statement of Net Assets
D2: Issued: December 31, 2014
H4: Primary Government
H5: Governmental Activities | I5: Business-Type Activities | J5: Total
A6: ASSETS
C7: Cash and cash equivalents | H7: 13162797 | I7: 228 | J7: =SUM(H7:I7) -> 13163025
C8: Investments | H8: 20355526 | J8: =SUM(H8:I8) -> 20355526
C9: Receivables (net of allowance for uncollectibles) | H9: 13659168 | I9: 3256 | J9: =SUM(H9:I9) -> 13662424
C10: Inventory | H10: 38185 | J10: =SUM(H10:I10) -> 38185
C11: Capital assets, net | H11: 73781725 | I11: 10175 | J11: =SUM(H11:I11) -> 73791900
C13: Total Assets | H13: =SUM(H7:H11) -> 120997401 | I13: =SUM(I7:I11) -> 13659 | J13: =SUM(J7:J11) -> 121011060
A15: LIABILITIES
C16: Accounts payable | H16: 1106355 | I16: 1500 | J16: =SUM(H16:I16) -> 1107855
C17: Master Bank Overdrafts | H17: 55314 | J17: =SUM(H17:I17) -> 55314
C18: Deposit balances | H18: 1800 | I18: 270 | J18: =SUM(H18:I18) -> 2070
C19: Advance from grantors | H19: 22885 | J19: =SUM(H19:I19) -> 22885
C20: Due to other governments | H20: 207897 | J20: =SUM(H20:I20) -> 207897
C21: Landfill post closure liability | H21: 2298127 | J21: =SUM(H21:I21) -> 2298127
C22: Compensated absences | H22: 307960 | J22: =SUM(H22:I22) -> 307960
C23: Other postemployment benefit obligation | H23: 2932408 | J23: =SUM(H23:I23) -> 2932408
C24: Long-term liabilities:
D25: Due within one year | H25: 5326 | J25: =SUM(H25:I25) -> 5326
D26: Due in more than one year | H26: 450 | J26: =SUM(H26:I26) -> 450
D28: Total Liabilities | H28: =SUM(H16:H26) -> 6938522 | I28: =SUM(I16:I26) -> 1770 | J28: =SUM(J16:J26) -> 6940292
A30: NET ASSETS
B31: Net investment in capital assets | H31: 73775949 | I31: 10175 | J31: =SUM(H31:I31) -> 73786124
B32: Restricted for Debt Service | H32: 5776 | J32: =SUM(H32:I32) -> 5776
B33: Unrestricted | H33: 40277154 | I33: 1714 | J33: =SUM(H33:I33) -> 40278868
C35: Total Net Assets | H35: =SUM(H31:H33) -> 114058879 | I35: =SUM(I31:I33) -> 11889 | J35: =SUM(J31:J33) -> 114070768
C37: Total Liabilities and Net Assets | H37: =SUM(H35+H28) -> 120997401 | I37: =SUM(I35+I28) -> 13659 | J37: =SUM(J35+J28) -> 121011060

Sheet East Baton Rouge
D1: East Baton Rouge Parish 2014 Statement of Net Assets
D2: Issued: December 31, 2014
H4: Primary Government
H5: Governmental Activities | I5: Business-Type Activities | J5: Total | K5: Component Unit
A6: ASSETS
B7: Current Assets
C8: Cash and cash equivalents (note 3) | H8: 192939199 | I8: 88246830 | J8: =SUM(H8:I8) -> 281186029 | K8: 20082173
C9: Investments (note 3) | H9: 188791227 | I9: 98538697 | J9: =SUM(H9:I9) -> 287329924
C10: Receivables--net (note 13) | H10: 53255487 | I10: 16172998 | J10: =SUM(H10:I10) -> 69428485 | K10: 17183849
C11: Due from other governments (note 11) | H11: 84764697 | I11: 5304530 | J11: =SUM(H11:I11) -> 90069227 | K11: 2446711
C12: Prepaid items | H12: 681554 | I12: 255888 | J12: =SUM(H12:I12) -> 937442 | K12: 172487
C13: Loans receivable | H13: 3614676 | J13: =SUM(H13:I13) -> 3614676 | K13: 1719373
C14: Inventory | H14: 833178 | I14: 118566 | J14: =SUM(H14:I14) -> 951744 | K14: 5335339
C15: Net pension asset | K15: 456737
C16: Other assets
C17: Restricted assets:
D18: Cash and cash equivalents (note 3) | I18: 215032849 | J18: =SUM(H18:I18) -> 215032849 | K18: 11958469
D19: Investments (note 3) | I19: 277525563 | J19: =SUM(H19:I19) -> 277525563
D20: Receivables--net (note 13) | I20: 280765 | J20: =SUM(H20:I20) -> 280765
D21: Prepaid items | I21: 6637 | J21: =SUM(H21:I21) -> 6637
C22: Capital assets:
D23: Non-depreciable | H23: 208882220 | I23: 264648985 | J23: =SUM(H23:I23) -> 473531205 | K23: 350523
D24: Depreciable, net | H24: 669766158 | I24: 1515753639 | J24: =SUM(H24:I24) -> 2185519797 | K24: 109555466
C26: Total Assets | H26: =SUM(H8:H24) -> 1403528396 | I26: =SUM(I8:I24) -> 2481885947 | J26: =SUM(J8:J24) -> 3885414343 | K26: =SUM(K8:K24) -> 169261127
A28: Deferred Outflows of Resources
B29: Deferred amount on refunding | H29: 5548137 | I29: 42943956 | J29: =SUM(H29:I29) -> 48492093 | K29: 0
B30: Deferred outflows on derivative instruments | H30: 15294792 | I30: 87643226 | J30: =SUM(H30:I30) -> 102938018 | K30: 0
B31: Deferred outflow for pension | K31: 239993
C33: Total deferred outflows of resources | H33: =SUM(H29:H31) -> 20842929 | I33: =SUM(I29:I31) -> 130587182 | J33: =SUM(J29:J31) -> 151430111 | K33: =SUM(K29:K31) -> 239993
A35: LIABILITIES
C36: Accounts payable and other current liabilities | H36: 43709310 | I36: 54839795 | J36: =SUM(H36:I36) -> 98549105 | K36: 2603986
C37: Due to other governments | H37: 7697870 | J37: =SUM(H37:I37) -> 7697870 | K37: 189696
C38: Accrued payables | H38: 16640784 | I38: 23230251 | J38: =SUM(H38:I38) -> 39871035 | K38: 2738092
C39: Unearned revenue | H39: 1063162 | I39: 1321484 | J39: =SUM(H39:I39) -> 2384646
C40: Deposits and escrow accounts | H40: 18143567 | J40: =SUM(H40:I40) -> 18143567
C41: Other liabilities | K41: 67022
C42: Noncurrent liabilities (note 10):
D43: Due within one year | H43: 30338476 | I43: 14982026 | J43: =SUM(H43:I43) -> 45320502 | K43: 3321919
D44: Due in more than one year | H44: 698794643 | I44: 1634951737 | J44: =SUM(H44:I44) -> 2333746380 | K44: 118067670
D46: Total Liabilities | H46: =SUM(H36:H44) -> 816387812 | I46: =SUM(I36:I44) -> 1729325293 | J46: =SUM(J36:J44) -> 2545713105 | K46: =SUM(K36:K44) -> 126988385
...

Sheet East Carroll
D1: East Carroll Parish 2014 Statement of Net Assets
D2: Issued: December 31, 2014
H4: Primary Government
H5: Governmental Activities | I5: Business-Type Activities | J5: Total
A6: ASSETS
C7: Cash and cash equivalents | H7: 2275206 | I7: 21246 | J7: =SUM(H7:I7) -> 2296452
C8: Investments | H8: 773667 | J8: =SUM(H8:I8) -> 773667
C9: Receivables | H9: 2551513 | I9: 997 | J9: =SUM(H9:I9) -> 2552510
C10: Prepaid items | I10: 1903 | J10: =SUM(H10:I10) -> 1903
C11: Cash and cash equivalents - restricted | I11: 9119 | J11: =SUM(H11:I11) -> 9119
C12: Capital assets not being depreciated | H12: 2573398 | J12: =SUM(H12:I12) -> 2573398
C13: Capital assets, net of accumulated depreciation | H13: 3785585 | J13: =SUM(H13:I13) -> 3785585
C15: Total Assets | H15: =SUM(H7:H13) -> 11959369 | I15: =SUM(I7:I13) -> 33265 | J15: =SUM(J7:J13) -> 11992634
A17: LIABILITIES
C18: Accounts payable | H18: 207657 | I18: 676 | J18: =SUM(H18:I18) -> 208333
C19: Interest payable | H19: 5987 | J19: =SUM(H19:I19) -> 5987
C20: Long-term liabilities:
D21: Due within one year | H21: 154753 | I21: 275 | J21: =SUM(H21:I21) -> 155028
D22: Due in more than one year | H22: 457009 | J22: =SUM(H22:I22) -> 457009
D24: Total Liabilities | H24: =SUM(H18:H22) -> 825406 | I24: =SUM(I18:I22) -> 951 | J24: =SUM(J18:J22) -> 826357
A26: NET ASSETS
B27: Net investment in capital assets | H27: 5755524 | J27: =SUM(H27:I27) -> 5755524
B28: Restricted for:
C29: Debt service | H29: 95165 | J29: =SUM(H29:I29) -> 95165
C30: Road maintenance | H30: 1372893 | J30: =SUM(H30:I30) -> 1372893
C31: Garbage | H31: 537606 | J31: =SUM(H31:I31) -> 537606
C32: Library | H32: 618729 | J32: =SUM(H32:I32) -> 618729
C33: Drainage | H33: 681845 | J33: =SUM(H33:I33) -> 681845
C34: Rural fire protection | H34: 425053 | J34: =SUM(H34:I34) -> 425053
C35: LSU/SU Extension | H35: 200984 | J35: =SUM(H35:I35) -> 200984
C36: Health unit | H36: 604006 | J36: =SUM(H36:I36) -> 604006
C37: Criminal Court | H37: 28298 | J37: =SUM(H37:I37) -> 28298
C38: Housing assistance payments | I38: 9119 | J38: =SUM(H38:I38) -> 9119
B39: Unrestricted | H39: 813860 | I39: 23195 | J39: =SUM(H39:I39) -> 837055
C41: Total Net Assets | H41: =SUM(H27:H39) -> 11133963 | I41: =SUM(I27:I39) -> 32314 | J41: =SUM(J27:J39) -> 11166277
C43: Total Liabilities and Net Assets | H43: =SUM(H41+H24) -> 11959369 | I43: =SUM(I41+I24) -> 33265 | J43: =SUM(J41+J24) -> 11992634

Sheet East Feliciana
C1: East Feliciana Parish 2014 Statement of Net Assets
C2: Issued: December 31, 2014
G4: Governmental Activities
A5: ASSETS
B6: Cash and cash equivalents | G6: 5002609.6
B7: Receivables, net | G7: 1124824.8
B8: Due from other funds | G8: 1831042.5
B9: Due from other governmental agencies | G9: 91971.96
B10: Capital assets, net | G10: 12861749
B12: Total Assets | G12: =SUM(G6:G10) -> 20912198
A14: DEFERRED OUTFLOWS OF RESOURCES
A17: LIABILITIES
B18: Accounts payable | G18: 735676.08
B19: Due to other funds | G19: 1464267.6
B20: Due to other governmental agencies | G20: 2729.05
B21: Compensated absences | G21: 13428
C23: Total Liabilities | G23: =SUM(G18:G21) -> 2216100.7
A25: DEFERRED OUTFLOWS OF RESOURCES
A28: NET ASSETS
B29: Net investment in capital assets | G29: 12861749
B30: Restricted for:
C31: Health unit operations/maintenance | G31: 872066
C32: Homeland security/emergency preparedness | G32: 47484.38
C33: Solid waste management | G33: 3938014
B34: Unrestricted | G34: 976786.83
B36: Total Net Assets | G36: =SUM(G29:G34) -> 18696100
B38: Total Liabilities and Net Assets | G38: =G36+G23 -> 20912201

Sheet Evangeline
D1: Evangeline Parish 2014 Statement of Net Assets
D2: Issued: December 31, 2014
H4: Primary Government
H5: Governmental Activities | I5: Business-Type Activities | J5: Total
A6: ASSETS
C7: Cash and interest-bearing deposits | H7: 11515168 | I7: 85541 | J7: =SUM(H7:I7) -> 11600709
C8: Receivables, net | H8: 12345 | I8: 18998 | J8: =SUM(H8:I8) -> 31343
C9: Due from other governmental units | H9: 6225622 | J9: =SUM(H9:I9) -> 6225622
C10: Other assets | H10: 5000 | J10: =SUM(H10:I10) -> 5000
C11: Restricted assets:
D12: Cash and interest-bearing deposits | I12: 20844 | J12: =SUM(I12) -> 20844
D13: Investments | H13: 28105054 | J13: =SUM(H13:I13) -> 28105054
C14: Capital assets, net | H14: 25647365 | I14: 261965 | J14: =SUM(H14:I14) -> 25909330
C16: Total Assets | H16: =SUM(H7:H14) -> 71510554 | I16: =SUM(I7:I14) -> 387348 | J16: =SUM(J7:J14) -> 71897902
A18: LIABILITIES
C19: Cash overdraft | H19: 7145 | J19: =SUM(H19:I19) -> 7145
C20: Accounts and other payables | H20: 2809470 | I20: 10998 | J20: =SUM(H20:I20) -> 2820468
C21: Accrued interest | H21: 114296 | J21: =SUM(H21:I21) -> 114296
C22: Performance bonds payable | H22: 307818 | J22: =SUM(H22:I22) -> 307818
C23: Unearned revenue | H23: 329789 | I23: 1438 | J23: =SUM(H23:I23) -> 331227
C24: Noncurrent liabilities:
D25: Portion due within one year:
E26: Compensated absences payable | H26: 2955 | J26: =SUM(H26:I26) -> 2955
E27: Capital lease payable | H27: 2338 | J27: =SUM(H27:I27) -> 2338
E28: Bonds and certificates payable | H28: 234000 | I28: 1916 | J28: =SUM(H28:I28) -> 235916
D29: Portion due after one year:
E30: Sewer deposits payable | H30: 11062 | I30: 11700 | J30: =SUM(H30:I30) -> 22762
E31: Compensated absences payable | H31: 68625 | J31: =SUM(H31:I31) -> 68625
E32: Bonds and certificates payable | H32: 31605866 | I32: 57806 | J32: =SUM(H32:I32) -> 31663672
D34: Total Liabilities | H34: =SUM(H19:H32) -> 35493364 | I34: =SUM(I19:I32) -> 83858 | J34: =SUM(J19:J32) -> 35577222
A36: NET ASSETS
B37: Net investment in capital assets | H37: 22677823 | I37: 204159 | J37: =SUM(H37:I37) -> 22881982
B38: Restricted for debt service | H38: 126351 | I38: 7228 | J38: =SUM(H38:I38) -> 133579
B39: Unrestricted | H39: 13213016 | I39: 92103 | J39: =SUM(H39:I39) -> 13305119
C41: Total Net Assets | H41: =SUM(H37:H39) -> 36017190 | I41: =SUM(I37:I39) -> 303490 | J41: =SUM(J37:J39) -> 36320680
C43: Total Liabilities and Net Assets | H43: =SUM(H41+H34) -> 71510554 | I43: =SUM(I41+I34) -> 387348 | J43: =SUM(J41+J34) -> 71897902

Sheet Franklin
C1: Franklin Parish 2014 Statement of Net Assets
C2: Issued: December 31, 2014
G4: Governmental Activities
A5: ASSETS
B6: Cash and cash equivalents | G6: 8560372
B7: Receivables | G7: 3796748
B8: Capital assets (net) | G8: 18743780
B10: Total Assets | G10: =SUM(G6:G8) -> 31100900
A12: LIABILITIES
B13: Accounts payable | G13: 497630
B14: Payroll withholding payable | G14: 67733
B15: Compensated absences payable | G15: 103567
B16: Capital leases payable | G16: 70000
B17: Due to others (damage deposit) | G17: 132000
B18: Net OPEB obligation | G18: 1433906
C20: Total Liabilities | G20: =SUM(G13:G18) -> 2304836
A22: NET ASSETS
B23: Invested in capital assets, net of related debt | G23: 18541780
B24: Unrestricted | G24: 10254284
B26: Total Net Assets | G26: =SUM(G23:G24) -> 28796064
B28: Total Liabilities and Net Assets | G28: =SUM(G20+G26) -> 31100900

Sheet Grant
D1: Grant Parish 2014 Statement of Net Assets
D2: Issued: December 31, 2014
H4: Primary Government
H5: Governmental Activities | I5: Business-Type Activities | J5: Total
A6: ASSETS
C7: Cash and cash equivalents | H7: 1797180 | I7: 466152 | J7: =SUM(H7:I7) -> 2263332
C8: Receivables (net) | H8: 1472672 | I8: 88420 | J8: =SUM(H8:I8) -> 1561092
C9: Capital assets:
D10: Non depreciable capital assets
E11: Construction in progress | H11: 60410 | J11: =SUM(H11:I11) -> 60410
E12: Land | H12: 203250 | J12: =SUM(H12:I12) -> 203250
D13: Depreciable capital assets, net | H13: 5577373 | I13: 349237 | J13: =SUM(H13:I13) -> 5926610
C15: Total Assets | H15: =SUM(H7:H13) -> 9110885 | I15: =SUM(I7:I13) -> 903809 | J15: =SUM(J7:J13) -> 10014694
A17: LIABILITIES
C18: Accounts and other payables | H18: 527147 | I18: 41378 | J18: =SUM(H18:I18) -> 568525
C19: Deposits due others | I19: 77981 | J19: =SUM(H19:I19) -> 77981
C20: Unearned revenues | H20: 17112 | J20: =SUM(H20:I20) -> 17112
C21: Long-term liabilities:
D22: Compensated absences | H22: 44833 | I22: 9609 | J22: =SUM(H22:I22) -> 54442
D23: Notes payable:
E24: Due within one year | H24: 95211 | J24: =SUM(H24:I24) -> 95211
E25: Due in more than one year | H25: 247461 | J25: =SUM(H25:I25) -> 247461
D27: Total Liabilities | H27: 931764 | I27: =SUM(I18:I25) -> 128968 | J27: =SUM(J18:J25) -> 1060732
A29: NET ASSETS
B30: Invested in capital assets, net of related debt | H30: 5498361 | I30: 349237 | J30: =SUM(H30:I30) -> 5847598
B31: Restricted:
C32: Maintenance | H32: 1839813 | J32: =SUM(H32:I32) -> 1839813
C33: Judicial | H33: 25525 | J33: =SUM(H33:I33) -> 25525
C34: Construction | H34: 51676 | J34: =SUM(H34:I34) -> 51676
B35: Unrestricted | H35: 763746 | I35: 425604 | J35: =SUM(H35:I35) -> 1189350
C37: Total Net Assets | H37: =SUM(H30:H35) -> 8179121 | I37: =SUM(I30:I35) -> 774841 | J37: =SUM(J30:J35) -> 8953962
C39: Total Liabilities and Net Assets | H39: =SUM(H37+H27) -> 9110885 | I39: =SUM(I37+I27) -> 903809 | J39: =SUM(J37+J27) -> 10014694

Sheet Iberia
D1: Iberia Parish 2014 Statement of Net Assets
D2: Issued: December 31, 2014
H4: Primary Government
H5: Governmental Activities | I5: Component Units
A6: ASSETS
C7: Cash and interest-bearing deposits | H7: 41860020 | I7: 50012752
C8: Investments | H8: 72229
C9: Receivables, net | H9: 8148320 | I9: 10661648
C10: Advance to component unit | H10: 1813645
C11: Due from other governmental agencies | H11: 3826329 | I11: 1109307
C12: Due from primary government | I12: 699043
C13: Inventories | I13: 1829268
C14: Prepaid items | I14: 690228
C15: Investments in joint ventures | I15: 343738
C16: Restricted assets | I16: 3604141
C17: Capital assets:
D18: Non-depreciable | H18: 7506786 | I18: 10114835
D19: Depreciable, net | H19: 86713962 | I19: 67336603
C21: Total Assets | H21: =SUM(H7:H19) -> 149941291 | I21: =SUM(I7:I19) -> 146401563
A23: DEFERRED OUTFLOWS OF RESOURCES
B24: Prepaid bond insurance
A26: LIABILITIES
C27: Accounts payable | H27: 970975 | I27: 2757772
C28: Accrued expenses | H28: 221930 | I28: 7088119
C29: Contracts and retainage payable | H29: 567425 | I29: 520118
C30: Due to other governmental agencies | H30: 361954 | I30: 204273
C31: Due to component unit | H31: 699043
C32: Advance from primary government | I32: 1813645
C33: Advances from grantors and others | H33: 126545 | I33: 92170
C34: Deposits | I34: 329200
C35: Accrued interest payable | H35: 38674 | I35: 238123
C36: Long-term liabilities:
D37: Other post employment benefits payable | H37: 4495880 | I37: 1872648
D38: Due within one year | H38: 1680344 | I38: 3633893
D39: Due in more than one year | H39: 8169937 | I39: 41369087
D41: Total Liabilities | H41: =SUM(H27:H39) -> 17332707 | I41: =SUM(I27:I39) -> 59919048
A43: NET ASSETS
B44: Net investment in capital assets | H44: 83346072 | I44: 55003983
B45: Restricted
C46: Nonexpendable | H46: 68863
...

Sheet Iberville
D1: Iberville Parish 2014 Statement of Net Assets
D2: Issued: December 31, 2014
H4: Primary Government | K4: Total Component Units
H5: Governmental Activities | I5: Business-Type Activities | J5: Total | K5: Governmental Activities | L5: Business-type Activities
A6: ASSETS
B7: Current Assets
C8: Cash and cash equivalents | H8: 23827413 | I8: 2675951 | J8: =SUM(H8:I8) -> 26503364 | K8: 1886128 | L8: 631857
C9: Receivables (net of allowance for uncollectibles) | H9: 10119866 | I9: 1016909 | J9: =SUM(H9:I9) -> 11136775 | K9: 3523868 | L9: 194625
C10: Inventories | I10: 135857 | J10: =SUM(H10:I10) -> 135857
C11: Prepaid items | H11: 560586 | J11: =SUM(H11:I11) -> 560586 | L11: 15379
C12: Other assets | H12: 48880 | I12: 336524 | J12: =SUM(H12:I12) -> 385404 | K12: 103379 | L12: 35161
C13: Restricted assets
D14: Cash and cash equivalents | H14: 100000 | I14: 542690 | J14: =SUM(H14:I14) -> 642690 | L14: 728625
C15: Capital assets (net of accumulated depreciation)
D16: Land | H16: 3105380 | I16: 193511 | J16: =SUM(H16:I16) -> 3298891 | K16: 435740
D17: Building and system | H17: 30995324 | I17: 9708202 | J17: =SUM(H17:I17) -> 40703526 | K17: 934316 | L17: 1718008
D18: Improvemetns other than building | H18: 55191369 | J18: =SUM(H18:I18) -> 55191369 | K18: 409009 | L18: 3304798
D19: Machinery and equipment | H19: 3776825 | I19: 336997 | J19: =SUM(H19:I19) -> 4113822 | K19: 378370 | L19: 1283032
D20: Construction in progress | H20: 22208945 | I20: 687059 | J20: =SUM(H20:I20) -> 22896004
C22: Total Assets | H22: =SUM(H8:H20) -> 149934588 | I22: =SUM(I8:I20) -> 15633700 | J22: =SUM(J8:J20) -> 165568288 | K22: =SUM(K8:K20) -> 7670810 | L22: =SUM(L8:L20) -> 7911485
A24: LIABILITIES
C25: Accounts payable and other current liabilities | H25: 2819108 | I25: 523848 | J25: =SUM(H25:I25) -> 3342956 | K25: 110341 | L25: 68945
C26: Matured bonds and interest payable | J26: =SUM(H26:I26) -> 0
C27: Accrued interest payable | J27: =SUM(H27:I27) -> 0
C28: Bank overdraft liability | J28: =SUM(H28:I28) -> 0
C29: Other payables | H29: 1220993 | J29: =SUM(H29:I29) -> 1220993 | K29: 204216
C30: Liabilities payable from restricted assets | I30: 291777 | J30: =SUM(H30:I30) -> 291777 | L30: 217963
C31: Noncurrent liabilities:
D32: Other post employment benefits | H32: 535622 | J32: =SUM(H32:I32) -> 535622 | K32: 79851
D33: Due in one year | H33: 1104609 | I33: 55000 | J33: =SUM(H33:I33) -> 1159609 | K33: 9000
D34: Due in more than one year | H34: 16076384 | I34: 490000 | J34: =SUM(H34:I34) -> 16566384 | K34: 297042 | L34: 3260174
D36: Total Liabilities | H36: =SUM(H25:H34) -> 21756716 | I36: =SUM(I25:I34) -> 1360625 | J36: =SUM(J25:J34) -> 23117341 | K36: =SUM(K25:K34) -> 700450 | L36: =SUM(L25:L34) -> 3547082
A38: NET ASSETS
B39: Invested in capital assets, net of related debt | H39: 97712719 | I39: 10380769 | J39: =SUM(H39:I39) -> 108093488 | K39: 2121508 | L39: 2986823
B40: Restricted for:
C41: Public building maintenance | H41: 2046146 | J41: =SUM(H41:I41) -> 2046146
C42: Drainage | H42: 3209288 | J42: =SUM(H42:I42) -> 3209288
C43: Solid waste | H43: 3474754 | J43: =SUM(H43:I43) -> 3474754
C44: Fire protection | H44: 3015608 | J44: =SUM(H44:I44) -> 3015608
C45: Emergency services | H45: 579675 | J45: =SUM(H45:I45) -> 579675
...

Sheet Jackson 
C1: Jackson Parish 2014 Statement of Net Assets
C2: Issued: December 31, 2014
G4: Governmental Activities
A5: ASSETS
B6: Cash and cash equivalents | G6: 9298920
B7: Receivables | G7: 4981192
B8: Prepaid items | G8: 75502
B9: Capital assets:
C10: Land and construction in progress | G10: 459821
C11: Capital assets, net of depreciation | G11: 15991533
B13: Total Assets | G13: =SUM(G6:G11) -> 30806968
A15: LIABILITIES
B16: Accounts, salaries, and other payables | G16: 310576
B17: Security deposits | G17: 30799
B18: Long-term liabilities:
C19: Due within one year | G19: 110115
C20: Due in more than one year | G20: 491865
C22: Total Liabilities | G22: =SUM(G16:G20) -> 943355
A24: NET ASSETS
B25: Net investment in capital assets | G25: 16451354
B26: Restricted for:
C27: Road maintenance (Road, Sales tax and asphalt funds) | G27: 5981278
C28: Waste management | G28: 1368834
C29: Library | G29: 1955864
C30: Health unit | G30: 232347
C31: Tourism | G31: 58802
C32: Landfill closure | G32: 551480
C33: Grant funds | G33: 31741
C34: Grand jury and witness fees | G34: 10559
B35: Unrestricted | G35: 3188354
B37: Total Net Assets | G37: =SUM(G25:G35) -> 29830613
B39: Total Liabilities and Net Assets | G39: =SUM(G22+G37) -> 30773968

Sheet Jefferson Davis
C1: Jefferson Davis Parish 2014 Statement of Net Assets
C2: Issued: December 31, 2014
G4: Governmental Activities
A5: ASSETS
B6: Cash and cash equivalents | G6: 19914802
B7: Investments | G7: 2112204
B8: Receivables | G8: 1464881
B9: Prepaid items | G9: 78534
B10: Restricted cash and cash equivalents | G10: 2707659
B11: Capital assets (net) | G11: 33983534
B13: Total Assets | G13: =SUM(G6:G11) -> 60261614
A15: DEFERRED OUTFLOWS OF RESOURCES
B16: Deferred bond issuance costs | G16: 71146
A18: LIABILITIES
B19: Accounts, salaries, and other payables | G19: 619781
B20: Contracts payable | G20: 161303
B21: Deposits due others | G21: 550500
B22: Other liabilities | G22: 140
B23: Accrued interest payable | G23: 282268
B24: Liability for other post-employment benefits | G24: 2078060
B25: Current portion of bonds payable | G25: 956000
B26: Current portion of capital leases payable | G26: 141267
B27: Capital leases payable | G27: 784193
B28: Bonds payable | G28: 14714000
C30: Total Liabilities | G30: =SUM(G19:G28) -> 20287512
A32: DEFERRED INFLOWS OF RESOURCES
B33: Deferred revenues | G33: 509597
A35: NET ASSETS
B36: Net investment in capital assets | G36: 17105806
B37: Restricted for:
C38: Public safety | G38: 4888543
C39: Public works | G39: 8158420
C40: Health and welfare | G40: 376920
C41: Debt service | G41: 2657652
C42: Other general government | G42: 1340505
B43: Unrestricted | G43: 5007805
B45: Total Net Assets | G45: =SUM(G36:G43) -> 39535651
B47: Total Liabilities and Net Assets | G47: =SUM(G30+G45+G33) -> 60332760

Sheet Jefferson
D1: Jefferson Parish 2014 Statement of Net Assets
D2: Issued: December 31, 2014
G3: (amounts in thousands)
H5: Primary Government
H6: Governmental Activities | I6: Business-Type Activities | J6: Total | K6: Component Unit
A7: ASSETS
B8: Current Assets
C9: Cash and cash equivalents | H9: 4986 | I9: 2624 | J9: =SUM(H9:I9) -> 7610 | K9: 22493
C10: Investments | H10: 73761 | J10: =SUM(H10:I10) -> 73761 | K10: 94049
C11: Share of pooled assets | H11: 503630 | I11: 18337 | J11: =SUM(H11:I11) -> 521967
C12: Receivables, net of allowances for
D13: estimated uncollectibles:
D14: Interest | H14: 51 | J14: =SUM(H14:I14) -> 51 | K14: 202
D15: Ad valorem tax | H15: 196362 | I15: 9233 | J15: =SUM(H15:I15) -> 205595
D16: Accounts | H16: 5362 | I16: 6026 | J16: =SUM(H16:I16) -> 11388 | K16: 88844
D17: Notes | K17: 7991
D18: Mortgage loans
D19: Intergovernmental | H19: 62965 | I19: 13 | J19: =SUM(H19:I19) -> 62978 | K19: 1607
D20: Other | K20: 11541
C21: Inventories | H21: 3423 | I21: 7883 | J21: =SUM(H21:I21) -> 11306 | K21: 16484
C22: Prepaid items | K22: 19821
C23: Restricted assets:
D24: Cash and cash equivalents | I24: 2275 | J24: =SUM(I24) -> 2275
D25: Investments | I25: 15687 | J25: =SUM(H25:I25) -> 15687 | K25: 206184
D26: Share of pooled assets | I26: 50475 | J26: =SUM(H26:I26) -> 50475
D27: Receivables | I27: 13495 | J27: =SUM(H27:I27) -> 13495
C29: Total Current Assets | H29: =SUM(H9:H27) -> 850540 | I29: =SUM(I9:I27) -> 126048 | J29: =SUM(J9:J27) -> 976588 | K29: =SUM(K9:K27) -> 469216
B31: Noncurrent Assets
C32: Restricted assets:
D33: Deposits and other assets | H33: 8427 | J33: =SUM(H33:I33) -> 8427 | K33: 26025
C34: Mortgage loans receivable | J34: =SUM(H34:I34) -> 0 | K34: 48456
C35: Capital assets not being depreciated | H35: 233702 | I35: 19347 | J35: =SUM(H35:I35) -> 253049
C36: Capital assets being depreciated, net | H36: 992761 | I36: 527411 | J36: =SUM(H36:I36) -> 1520172 | K36: 379084
C38: Total Noncurrent Assets | H38: =SUM(H31:H36) -> 1234890 | I38: =SUM(I31:I36) -> 546758 | J38: =SUM(J31:J36) -> 1781648 | K38: =SUM(K31:K36) -> 453565
C40: Total Assets | H40: =SUM(H38+H29) -> 2085430 | I40: =SUM(I38+I29) -> 672806 | J40: =SUM(J29+J38) -> 2758236 | K40: =SUM(K29+K38) -> 922781
B42: Deferred outflows of resources
C43: Deferred charges on bond issuance costs | H43: 8143 | J43: =SUM(H43:I43) -> 8143
C45: Total Deferred Outflows of Resources | H45: =H43 -> 8143 | I45: =I43 -> 0 | J45: =J43 -> 8143 | K45: =K43 -> 0
A47: LIABILITIES
B48: Current liabilities
...

Sheet Lafayette
D1: Lafayete Parish 2014 Statement of Net Assets
D2: Issued: December 31, 2014
H4: Primary Government
H5: Governmental Activities | I5: Business-Type Activities | J5: Total | K5: Component Unit
A6: ASSETS
C7: Cash and interest-bearing deposits | H7: 7721845 | I7: 2848461 | J7: =SUM(H7:I7) -> 10570306 | K7: 50132926
C8: Investments | H8: 278852022 | I8: 16027117 | J8: =SUM(H8:I8) -> 294879139 | K8: 16338139
C9: Receivables, net | H9: 2270885 | I9: 27658362 | J9: =SUM(H9:I9) -> 29929247 | K9: 2002495
C10: Internal balances | H10: 3559213 | I10: -3559213 | J10: =SUM(H10:I10) -> 0
C11: Due from primary government | J11: =SUM(H11:I11) -> 0 | K11: 73188
C12: Due from component units | H12: 177735 | I12: 1879 | J12: =SUM(H12:I12) -> 179614
C13: Due from other governmental agencies | H13: 18499918 | I13: 3456198 | J13: =SUM(H13:I13) -> 21956116 | K13: 7986272
C14: Inventories, net | H14: 419825 | I14: 31932260 | J14: =SUM(H14:I14) -> 32352085 | K14: 218586
C15: Prepaid items | H15: 149592 | I15: 293411 | J15: =SUM(H15:I15) -> 443003 | K15: 378702
C16: Other assets | K16: 1346182
C17: Restricted assets:
D18: Cash | I18: 8101700 | J18: =SUM(H18:I18) -> 8101700 | K18: 3981944
D19: Investments | I19: 209339409 | J19: 209339409 | K19: 20708601
D20: Receivables | I20: 111938 | J20: =SUM(H20:I20) -> 111938 | K20: 44820
C21: Unamortized start-up costs | I21: 1960661 | J21: =SUM(H21:I21) -> 1960661
C22: Capital assets:
D23: Non-depreciable | H23: 70197995 | I23: 66232170 | J23: =SUM(H23:I23) -> 136430165 | K23: 29146560
D24: Depreciable,net | H24: 517241758 | I24: 662632316 | J24: =SUM(H24:I24) -> 1179874074 | K24: 90812166
C26: Total Assets | H26: =SUM(H7:H24) -> 899090788 | I26: =SUM(I7:I24) -> 1027036669 | J26: =SUM(J7:J24) -> 1926127457 | K26: =SUM(K7:K24) -> 223170581
A28: DEFERRED OUTFLOWS OF RESOURCES
B29: Deferred loss on bond refunding | H29: 10285862 | I29: 11427508 | J29: =SUM(H29:I29) -> 21713370 | K29: 24771
A31: LIABILITIES
C32: Accounts and other payables | H32: 3505182 | I32: 6433320 | J32: =SUM(H32:I32) -> 9938502 | K32: 4651833
C33: Due to primary government | J33: =SUM(H33:I33) -> 0 | K33: 179614
C34: Due to component units | H34: 73188 | J34: =SUM(H34:I34) -> 73188
C35: Due to other governmental agencies | H35: 714973 | J35: =SUM(H35:I35) -> 714973 | K35: 4507
C36: Unearned revenue | H36: 281108 | I36: 2989 | J36: =SUM(H36:I36) -> 284097 | K36: 2513461
C37: Customer deposits | I37: 8151514 | J37: =SUM(H37:I37) -> 8151514 | K37: 101171
C38: Long-term liabilities:
D39: Portion due or payable within one year | H39: 34417905 | I39: 5045582 | J39: =SUM(H39:I39) -> 39463487 | K39: 7960162
D40: Portion due or payable after one year | H40: 409431497 | I40: 494865322 | J40: =SUM(H40:I40) -> 904296819 | K40: 22626084
D42: Total Liabilities | H42: =SUM(H32:H40) -> 448423853 | I42: =SUM(I32:I40) -> 514498727 | J42: =SUM(J32:J40) -> 962922580 | K42: =SUM(K32:K40) -> 38036832
A44: DEFERRED INFLOWS OF RESOURCES
A45: Property taxes | K45: 2008404
A47: NET ASSETS
...

Sheet Lafourche
D1: Lafourche Parish 2014 Statement of Net Assets
D2: Issued: December 31, 2014
H4: Primary Government | K4: Component Unit
H5: Governmental Activities | I5: Business-Type Activities | J5: Total | K5: Total
A6: ASSETS
C7: Cash | H7: 20213397 | J7: =SUM(H7:I7) -> 20213397 | K7: 213552743
C8: Investments | H8: 22534040 | J8: =SUM(H8:I8) -> 22534040 | K8: 21165841
C9: Receivables | H9: 2766041 | I9: 18174 | J9: =SUM(H9:I9) -> 2784215 | K9: 36339765
C10: Due from other governmental units | H10: 30663568 | J10: =SUM(H10:I10) -> 30663568
C11: Prepaids and other assets | H11: 2779853 | J11: =SUM(H11:I11) -> 2779853 | K11: 20080601
C12: Capital assets:
D13: Non-depreciable | H13: 39812853 | J13: =SUM(H13:I13) -> 39812853 | K13: 29927075
D14: Depreciable | H14: 56399643 | I14: 2762073 | J14: =SUM(H14:I14) -> 59161716 | K14: 211712535
C16: Total Assets | H16: =SUM(H7:H14) -> 175169395 | I16: =SUM(I7:I14) -> 2780247 | J16: =SUM(J7:J14) -> 177949642 | K16: =SUM(K7:K14) -> 532778560
B18: Deferred outflows of resources
C19: Deferred charge on refunding | H19: 998036 | J19: =SUM(H19:I19) -> 998036
C21: Total Deferred Outflows of Resources | H21: =H19 -> 998036 | I21: =I19 -> 0 | J21: =J19 -> 998036 | K21: =K19 -> 0
A23: LIABILITIES
C24: Accounts payable and accrued expenses | H24: 5646947 | I24: 27127 | J24: =SUM(H24:I24) -> 5674074 | K24: 18113211
C25: Other current liabilities | H25: 468146 | J25: =SUM(H25:I25) -> 468146 | K25: 4632620
C26: Accrued interest payable | H26: 595935 | J26: =SUM(H26:I26) -> 595935
C27: Due to other governmental units | H27: 933144 | I27: 211687 | J27: =SUM(H27:I27) -> 1144831
C28: Long-term liabilities | J28: =SUM(H28:I28) -> 0
D29: Due within one year | H29: 2495013 | J29: =SUM(H29:I29) -> 2495013 | K29: 2854918
D30: Due in more than one year | H30: 43892757 | J30: =SUM(H30:I30) -> 43892757 | K30: 26120342
D32: Total Liabilities | H32: =SUM(H24:H30) -> 54031942 | I32: =SUM(I24:I30) -> 238814 | J32: =SUM(J24:J30) -> 54270756 | K32: =SUM(K24:K30) -> 51721091
A34: NET ASSETS
B35: Net invested in capital assets | H35: 40588502 | I35: 2762073 | J35: =SUM(H35:I35) -> 43350575 | K35: 215082552
B36: Restricted for:
C37: Capital projects | H37: 12449084 | J37: =SUM(H37:I37) -> 12449084 | K37: 4158197
C38: Debt service | H38: 6338397 | J38: =SUM(H38:I38) -> 6338397 | K38: 3622326
B39: Unrestricted (deficit) | H39: 62759506 | I39: -220640 | J39: =SUM(H39:I39) -> 62538866 | K39: 258194394
C41: Total Net Assets | H41: =SUM(H35:H39) -> 122135489 | I41: =SUM(I35:I39) -> 2541433 | J41: =SUM(J35:J39) -> 124676922 | K41: =SUM(K34:K39) -> 481057469
C43: Total Liabilities and Net Assets | H43: =SUM(H41+H32) -> 176167431 | I43: =SUM(I32+I41) -> 2780247 | J43: =SUM(J32+J41) -> 178947678 | K43: =SUM(K41+K32) -> 532778560

Sheet LaSalle
C1: LaSalle Parish 2014 Statement of Net Assets
C2: Issued: December 31, 2014
G4: Governmental Activities
A5: ASSETS
B6: Cash and cash equivalents | G6: 2562628
B7: Receivables | G7: 4667182
B8: Prepaid lease payments | G8: 12440
B9: Capital assets (net) | G9: 7095343
B11: Total Assets | G11: =SUM(G6:G9) -> 14337593
A13: LIABILITIES
B14: Cash overdraft | G14: 733382
B15: Accounts payable | G15: 1157501
B16: Payroll payable | G16: 49332
B17: Net OPEB obligations | G17: 88421
B18: Long term liabilities:
C19: Due within one year | G19: 113744
C20: Due in more than one year | G20: 300699
C22: Total Liabilities | G22: =SUM(G14:G20) -> 2443079
A24: NET ASSETS
B25: Invested in capital assets, net of related debt | G25: 6680900
B26: Unrestricted | G26: 5213614
B28: Total Net Assets | G28: =SUM(G25:G26) -> 11894514
B30: Total Liabilities and Net Assets | G30: =SUM(G22+G28) -> 14337593

Sheet Lincoln
C1: Lincoln Parish 2014 Statement of Net Assets
C2: Issued: December 31, 2014
G4: Governmental Activities
A5: ASSETS
B6: Cash | G6: 9467885
B7: Investments | G7: 22471496
B8: Accounts receivable | G8: 7666006
B9: Due from other entities | G9: 813998
B10: Inventory | G10: 11582
B11: Capital assets:
C12: Non-Depreciable | G12: 1775786
C13: Depreciable | G13: 21184623
B15: Total Assets | G15: =SUM(G6:G13) -> 63391376
A17: DEFERRED OUTFLOWS OF RESOURCES
B18: Prepaid expenses | G18: 7819
A20: LIABILITIES
B21: Accounts payable | G21: 1255073
B22: Due to other entities | G22: 720960
B23: Noncurrent liabilities:
C24: Due within one year:
D25: Bonds payable | G25: 487000
C26: Due in more than one year:
D27: Compensated absences | G27: 107370
D28: Bonds payable | G28: 2989000
C29: Unfunded postretirement:
D30: Benefit plan obligations | G30: 1677068
C32: Total Liabilities | G32: =SUM(G21:G30) -> 7236471
A34: NET ASSETS
B35: Net investment in capital assets | G35: 22960409
B36: Restricted for:
C37: Capital projects | G37: 1987642
C38: Debt service | G38: 1022397
B39: Unrestricted | G39: 30192276
B41: Total Net Assets | G41: =SUM(G35:G39) -> 56162724
B43: Total Liabilities and Net Assets | G43: =SUM(G32+G41) -> 63399195

Sheet Livingston
D1: Livingston Parish 2014 Statement of Net Assets
D2: Issued: December 31, 2014
H4: Governmental Activities | I4: Business-Type Activities | J4: Total
A5: ASSETS
C6: Cash and cash equivalents | H6: 9725487 | I6: 270166 | J6: =SUM(H6:I6) -> 9995653
C7: Investments | H7: 3408123 | J7: =SUM(H7:I7) -> 3408123
C8: Receivables, Net of Allowance | H8: 913933 | I8: 12935 | J8: =SUM(H8:I8) -> 926868
C9: Inventory | H9: 227265 | J9: =SUM(H9:I9) -> 227265
C10: Internal balances | H10: 22383 | I10: -22383 | J10: =SUM(H10:I10) -> 0
C11: Due from other governments | H11: 11547592 | J11: =SUM(H11:I11) -> 11547592
C12: Due from component unit | H12: 1116951 | J12: =SUM(H12:I12) -> 1116951
C13: Unamortized bond insurance premiums | H13: 348050 | J13: =SUM(H13:I13) -> 348050
C14: Prepaid items | H14: 440288 | I14: 670 | J14: =SUM(H14:I14) -> 440958
C15: Restricted assets
D16: Cash | H16: 8774594 | I16: 92481 | J16: =SUM(H16:I16) -> 8867075
C17: Capital assets
D18: Non-depreciable | H18: 11551218 | I18: 64362 | J18: =SUM(H18:I18) -> 11615580
D19: Depreciable-net | H19: 131785254 | I19: 7811640 | J19: =SUM(H19:I19) -> 139596894
C21: Total Assets | H21: =SUM(H6:H19) -> 179861138 | I21: =SUM(I6:I19) -> 8229871 | J21: =SUM(J6:J19) -> 188091009
B23: Deferred Outflows of Resources
C24: Deferred Amount on Refunding of Debt | H24: 4057845 | J24: =SUM(H24:I24) -> 4057845
E26: Total Assets and Deferred Outflows | H26: =SUM(H24) -> 4057845 | I26: =SUM(I24) -> 0 | J26: =SUM(J24) -> 4057845
A28: LIABILITIES
C29: Accounts payable and accrued expenses | H29: 3799345 | I29: 23046 | J29: =SUM(H29:I29) -> 3822391
C30: Due to other governments | H30: 503302 | J30: =SUM(H30:I30) -> 503302
