Workbook

Sheet Acadia
D1: Acadia Parish 2015 Statement of Net Assets
D2: Issued: December 31, 2015
H4: Primary Government
H5: Governmental Activities | I5: Component Unit
A6: ASSETS
B7: Current Assets
C8: Cash and cash equivalents | H8: 9195544 | I8: 79400
C9: Investments | H9: 7939036
C10: Taxes receivable | H10: 6542496
C11: Special assessments receivable | H11: 16996
C12: Other receivables | H12: 10094
C13: Due from other governmental entities | H13: 550460
C14: Due from component units | H14: 20177
C15: Capital assets:
D16: Non-depreciable | H16: 1704568
D17: Depreciable, net | H17: 50254249
C19: Total Assets | H19: =SUM(H8:H17) -> 76233620 | I19: =SUM(I8:I17) -> 79400
A21: DEFERRED OUTFLOWS OF RESOURCES
C22: Deferred loss on refunding | H22: 9122
C23: Pension related | H23: 656278 | I23: 105698
D24: Total deferred outflows | H24: =SUM(H22:H23) -> 665400 | I24: =SUM(I22:I23) -> 105698
A27: LIABILITIES
C28: Accounts payable | H28: 1295353 | I28: 9083
C29: Retainage payable
C30: Accrued liabilities and other payables | H30: 650540
C31: Unearned revenue | H31: 62997
C32: Accrued interest payable | H32: 57734
C33: Due to primary government | I33: 20177
C34: Long-term liabilities:
D35: Portion due or payable within one year:
E36: Bonds payable | H36: 1587435
E37: Compensated absences | H37: 176145
D38: Portion due or payable after one year:
E39: Bonds payable | H39: 9865913
E40: Compensated absences | H40: 158899
E41: Net pension liability | H41: 411100 | I41: 23082
E42: Landfill closure and postclosure care costs liability | H42: 5054233
D44: Total Liabilities | H44: =SUM(H28:H42) -> 19320349 | I44: =SUM(I28:I42) -> 52342
A46: DEFERRED INFLOWS OF RESOURCES
C47: Pension related | H47: 178983 | I47: 19678
...

Sheet Allen
C1: Allen Parish 2015 Statement of Net Assets
C2: Issued: December 31, 2015
G4: Governmental Activities
A5: ASSETS
B6: Cash | G6: 4069562
B7: Receivables | G7: 2833111
B8: Due from other governments | G8: 762395
B9: Inventory | G9: 45179
B10: Prepaid assets | G10: 7432
B11: Capital assets, net of accumulated depreciation | G11: 23777069
B13: Total Assets | G13: =SUM(G6:G11) -> 31494748
A15: DEFERRED OUTFLOWS OF RESOURCES RELATED TO PENSIONS | G15: 276783
B16: Total assets and deferred outflows | G16: =SUM(G15+G13) -> 31771531
A18: LIABILITIES
B19: Accounts payable | G19: 824559
B20: Accrued interest payable | G20: 5628
B21: Unearned revenue | G21: 48703
B22: Bonds payable - due within one year | G22: 254000
B23: Compensated absences payable-
C24: due within one year | G24: 29759
B25: OPEB obligations - due in more
C26: than one year | G26: 1311282
B27: Pension liability- due in more than one year | G27: 54246
B28: Bonds payable - due in more than one year | G28: 1394000
C30: Total Liabilities | G30: =SUM(G19:G28) -> 3922177
A32: DEFERRED INFLOWS OF RESOURCES RELATED TO PENSIONS | G32: 24855
A34: NET ASSETS
B35: Net Investmend in capital assets | G35: 22129069
B36: Restricted for:
C37: Inventory | G37: 45179
C38: Judicial | G38: 611041
C39: Other general government | G39: 634469
C40: Public works | G40: 3501405
C41: Sanitation | G41: 479982
C42: Capital projects | G42: 390551
C43: Debt service | G43: 53723
B44: Unrestricted | G44: -20920
B46: Total Net Assets | G46: =SUM(G35:G44) -> 27824499
B48: Total Liabilities, deferred inflows, and Net Assets | G48: =SUM(G30+G46+G32) -> 31771531

Sheet Ascension
D1: Ascension Parish 2015 Statement of Net Assets
D2: Issued: December 31, 2015
I4: Primary Government | L4: Component Unit
I5: Governmental Activities | J5: Business-type Activities | K5: Total | L5: Governmental Activities | M5: Business-type Activities
A6: ASSETS
B7: Current Assets
C8: Cash and cash equivalents | I8: 32250738 | J8: 3967892 | K8: =SUM(I8:J8) -> 36218630 | L8: 32916630 | M8: 1196210
C9: Investments | I9: 135507608 | J9: 10561966 | K9: =SUM(I9:J9) -> 146069574 | L9: 5694111 | M9: 14060003
C10: Accounts receivable, net | I10: 35732327 | J10: 257762 | K10: =SUM(I10:J10) -> 35990089 | L10: 4072629 | M10: 1536049
C11: Due from other governments | I11: 5417238 | J11: 51244 | K11: =SUM(I11:J11) -> 5468482 | L11: 2280280
C12: Internal balances | I12: 5 | J12: -5 | K12: =SUM(I12:J12) -> 0
C13: Prepaid and other assets | I13: 251833 | J13: 250281 | K13: =SUM(I13:J13) -> 502114 | L13: 207600 | M13: 146137
C14: Inventory | J14: 25935 | K14: 25935 | M14: 206469
C15: Restricted assets | J15: 37019 | K15: =SUM(I15:J15) -> 37019 | L15: 718443 | M15: 597235
C16: Capital assets:
D17: Nondepreciable | I17: 46116046 | J17: 1655313 | K17: =SUM(I17:J17) -> 47771359 | L17: 3500494 | M17: 110902
D18: Depreciable, net | I18: 181199117 | J18: 9634710 | K18: =SUM(I18:J18) -> 190833827 | L18: 12535508 | M18: 11104401
C20: Total Assets | I20: =SUM(I8:I18) -> 436474912 | J20: =SUM(J8:J18) -> 26442117 | K20: =SUM(K8:K18) -> 462917029 | L20: =SUM(L8:L18) -> 61925695 | M20: =SUM(M7:M18) -> 28957406
A22: Deferred Outflows of Resources
B23: Pension liability | I23: 3835629 | J23: 75110 | K23: =SUM(I23:J23) -> 3910739 | L23: 4763789 | M23: 27020
B24: Deferred loss on debt refunding | I24: 6506451 | J24: 0 | K24: 6506451 | L24: 0 | M24: 0
C26: Total deferred outflows of resources | I26: =SUM(I23:I24) -> 10342080 | J26: =SUM(J23:J24) -> 75110 | K26: =SUM(K23:K24) -> 10417190 | L26: =SUM(L23:L24) -> 4763789 | M26: =SUM(M23:M24) -> 27020
C28: Total assets and deferred outflows of resources | I28: =I26+I20 -> 446816992 | J28: =J26+J20 -> 26517227 | K28: =K26+K20 -> 473334219 | L28: =L26+L20 -> 66689484 | M28: =M26+M20 -> 28984426
A30: LIABILITIES
C31: Accounts payable and accrued liabilities | I31: 3140132 | J31: 733139 | K31: =SUM(I31:J31) -> 3873271 | L31: 2037934 | M31: 606412
C32: Contracts payable | I32: 5106697 | K32: =SUM(I32:J32) -> 5106697
C33: Due to other governments | I33: 472207 | K33: =SUM(I33:J33) -> 472207 | L33: 934476
C34: Accrued payroll | I34: 736585 | J34: 31614 | K34: =SUM(I34:J34) -> 768199
C35: Customer deposits | J35: 37019 | K35: =SUM(I35:J35) -> 37019 | M35: 45946
C36: Sales tax rebate reserve | I36: 4759700 | K36: =SUM(I36:J36) -> 4759700
C37: Unearned revenue | I37: 414404 | J37: 42364 | K37: =SUM(I37:J37) -> 456768
C38: Claims reserve | K38: =SUM(I38:J38) -> 0
D39: Due within one year | I39: 354297 | K39: =SUM(I39:J39) -> 354297
D40: Due in more than one year | I40: 904237 | K40: =SUM(I40:J40) -> 904237
C41: Long-term payable | K41: =SUM(I41:J41) -> 0
D42: Due within one year | I42: 5546774 | K42: =SUM(I42:J42) -> 5546774 | L42: 601691 | M42: 182363
D43: Due within more than one year | I43: 77209825 | K43: =SUM(I43:J43) -> 77209825 | L43: 2680740 | M43: 4394107
D44: Other post-employment benefits | I44: 659115 | K44: =SUM(I44:J44) -> 659115 | L44: 7147074
D45: Net pension liability | I45: 3360215 | J45: 1607 | K45: =SUM(I45:J45) -> 3361822 | L45: 14902076 | M45: 578
D47: Total Liabilities | I47: =SUM(I31:I45) -> 102664188 | J47: =SUM(J31:J45) -> 845743 | K47: =SUM(K31:K45) -> 103509931 | L47: =SUM(L31:L45) -> 28303991 | M47: =SUM(M31:M45) -> 5229406
...

Sheet Assumption
D1: Assumption Parish 2015 Statement of Net Assets
D2: Issued: December 31, 2015
H4: Primary Government | I4: Component Units
A5: ASSETS
B6: Current Assets
C7: Cash and cash equivalents | H7: 5055668 | I7: 2111958
C8: Investments | H8: 14723668 | I8: 4748511
C9: Receivables | H9: 5990950 | I9: 1476612
C10: Other assets | H10: 139035 | I10: 252635
C11: Restricted investments | I11: 3417634
C12: Net investment in capital assets | H12: 44674146 | I12: 16188968
C14: Total Assets | H14: =SUM(H7:H12) -> 70583467 | I14: =SUM(I7:I12) -> 28196318
A16: DEFERRED OUTFLOWS OF RESOURCES
B17: Pension related | H17: 546760 | I17: 473091
C18: TOTAL DEFERRED OUTFLOWS OF RESOURCES | H18: =H17 -> 546760 | I18: =I17 -> 473091
A20: LIABILITIES AND NET POSITION
B21: Liabilities
C22: Accounts payable | H22: 1677434 | I22: 87422
C23: Salaries payable | H23: 44380 | I23: 16770
C24: Compensated absences payable | H24: 165805 | I24: 29149
C25: Other post-employment benefits payable | H25: 1072694 | I25: 1854099
C26: Other liabilities | H26: 707891 | I26: 336749
C27: Long-term liabilities:
D28: Due within one year | I28: 530000
D29: Due in more than one year | I29: 4270000
D30: Net pension liability | H30: 137545 | I30: 993483
D32: Total Liabilities | H32: =SUM(H22:H30) -> 3805749 | I32: =SUM(I22:I30) -> 8117672
A34: DEFERRED INFLOWS OF RESOURCES
B35: Pension related | H35: 70848 | I35: 315637
D36: TOTAL DEFERRED INFLOWS OF RESOURCES | H36: =H35 -> 70848 | I36: =I35 -> 315637
A38: NET ASSETS
B39: Invested in capital assets, net of related debt | H39: 44674146 | I39: 11388968
B40: Restricted for revenue bond debt service and contingencies | I40: 3417553
B41: Unrestricted | H41: 22579484 | I41: 5429579
C43: Total Net Assets | H43: =SUM(H39:H41) -> 67253630 | I43: =SUM(I38:I41) -> 20236100
C45: Total Liabilities and Net Assets | H45: =SUM(H32+H43+H36) -> 71130227 | I45: =SUM(I32+I43+I36) -> 28669409

Sheet Avoyelles
D1: Avoyelles Parish 2015 Statement of Net Assets
D2: Issued: December 31, 2015
H4: Primary Government
A5: ASSETS
B6: Current Assets
C7: Cash and interest-bearing deposits | H7: 10522207
C8: Receivables, net | H8: 33789
C9: Due from other governmental units | H9: 2575929
C10: Prepaid items | H10: 108830
C11: Land and contruction in progress | H11: 1775946
C12: Capital assets, net | H12: 4318512
C14: Total Assets | H14: =SUM(H7:H12) -> 19335213
B16: Deferred outflows of resources related to pensions | H16: 192033
A18: LIABILITIES
C19: Accounts, salaries and other payables | H19: 689137
C20: Unearned revenue | H20: 36260
C21: Due to other governmental units | H21: 66004
C22: Long-term liabilities:
D23: Portion due within one year | H23: 30149
D24: Portion due after one year | H24: 64772
C25: Net pension liability | H25: 79068
D27: Total Liabilities | H27: =SUM(H19:H25) -> 965390
B29: Deferred inflows of resources related to pensions | H29: 51851
A31: NET ASSETS
B32: Net investment in capital assets | H32: 6094458
B33: Unrestricted | H33: 12415547
C35: Total Net Assets | H35: =SUM(H32:H33) -> 18510005
C37: Total Liabilities and Net Assets | H37: =H35+H27 -> 19475395

Sheet Beauregard
C1: Beauregard Parish 2015 Statement of Net Assets
C2: Issued: December 31, 2015
G4: Governmental Activities
A5: ASSETS
B6: Cash and cash equivalents | G6: 25520552
B7: Receivables | G7: 6425452
B8: Inventory | G8: 334682
B9: Prepaid expenses | G9: 226353
B10: Capital assets (net of accumulated depreciation):
C11: Land | G11: 698779
C12: Buildings and improvements | G12: 11668437
C13: Furniture and equipment | G13: 3697372
C14: Infrastructure | G14: 14276186
C15: Construction in progress | G15: 5640233
B17: Total Assets | G17: =SUM(G6:G15) -> 68488046
A19: Deferred Outflows of Resources
B20: Pension-related deferrals | G20: 587818
A22: LIABILITIES
B23: Accounts, salaries, and other payables | G23: 1531644
B24: Interest payable | G24: 33384
B25: Net pension liability | G25: 148204
B26: Long-term liabilities:
C27: Due within one year | G27: 1256668
C28: Due in more than one year | G28: 13691999
C30: Total Liabilities | G30: =SUM(G23:G28) -> 16661899
A32: Deferred Inflows of Resources
B33: Pension-related deferrals | G33: 99372
A35: NET ASSETS
B36: Invested in capital assets, net of related debt | G36: 21141007
B37: Restricted for:
C38: Inventory | G38: 334682
C39: Equipment purchases | G39: 744819
C40: Public safety | G40: 1932609
C41: Public works | G41: 5856335
C42: Health and welfare | G42: 2576641
C43: Culture and recreation | G43: 865917
C44: Sanitation | G44: 5074980
C45: Other general government | G45: 325299
C46: Capital projects | G46: 11558772
C47: Debt service | G47: 166333
...

Sheet Bienville
C1: Bienville Parish 2015 Statement of Net Assets
C2: Issued: December 31, 2015
G4: Governmental Activities
A5: ASSETS
B6: Cash and cash equivalents | G6: 16858491
B7: Receivables | G7: 4654602
B8: Capital assets, net | G8: 22261869
B10: Total Assets | G10: =SUM(G6:G8) -> 43774962
A12: Deferred Outflow of Resources
B13: Pension related | G13: 134448
B14: Total Assets and Deferred Outflow of Resources | G14: =G13 -> 134448
A16: LIABILITIES
B17: Accounts payable | G17: 216581
B18: Wages and related payable | G18: 33526
B19: Interest payable | G19: 130263
B20: Bonds payable | G20: 9895000
B21: Premium on bonds | G21: 259109
B22: Deferred revenues | G22: 70000
B23: Compensated absences payable | G23: 87473
B24: Net pensioni liability | G24: 186811
B25: Net OPEB obligation | G25: 1756770
C27: Total Liabilities | G27: =SUM(G17:G25) -> 12635533
A29: Deferred Inflows of Resources
B30: Pension related | G30: 46967
A32: NET ASSETS
B33: Invested in capital assets, net of related debt | G33: 12366869
B34: Unrestricted | G34: 18860041
B36: Total Net Assets | G36: =SUM(G33:G34) -> 31226910
B38: Total Liabilities and Net Assets | G38: =SUM(G27+G36+G30) -> 43909410

Sheet Bossier
D1: Bossier Parish 2015 Statement of Net Assets
D2: Issued: December 31, 2015
H5: Governmental Activities | I5: Business-Type Activities | J5: Total
A6: ASSETS
C7: Cash and cash equivalents | H7: 41742235 | J7: =SUM(H7:I7) -> 41742235
C8: Restricted cash | H8: 4378132 | I8: 1257137 | J8: =SUM(H8:I8) -> 5635269
C9: Investments | H9: 2525000 | J9: =SUM(H9:I9) -> 2525000
C10: Restricted Investments | H10: 11092426 | J10: =SUM(H10:I10) -> 11092426
C11: Receivables | H11: 18410937 | I11: 308664 | J11: =SUM(H11:I11) -> 18719601
C12: Prepaid expenses | H12: 922640 | I12: 116888 | J12: =SUM(H12:I12) -> 1039528
C13: Capital assets, net: | J13: =SUM(H13:I13) -> 0
D14: Non-depreciable | H14: 21139166 | I14: 36078080 | J14: =SUM(H14:I14) -> 57217246
D15: Depreciable (net) | H15: 266323459 | I15: 4557975 | J15: =SUM(H15:I15) -> 270881434
C16: Internal balances | H16: 8176744 | I16: -8176744 | J16: =SUM(H16:I16) -> 0
C18: Total Assets | H18: =SUM(H7:H16) -> 374710739 | I18: =SUM(I7:I16) -> 34142000 | J18: =SUM(J7:J16) -> 408852739
A20: Deferred Outflows of Resources
C21: Pension related | H21: 2017962 | I21: 62411 | J21: =SUM(H21:I21) -> 2080373
A23: LIABILITIES
B24: Current
C25: Accounts payable and accrued expenses | H25: 3040969 | I25: 1147352 | J25: =SUM(H25:I25) -> 4188321
C26: Payable from restricted assets:
D27: Customer deposits | I27: 125647 | J27: =SUM(H27:I27) -> 125647
B28: Noncurrent liabilities
C29: Due within one year | H29: 4779068 | I29: 492000 | J29: 5271068
C30: Due in more than one year | H30: 65724929 | I30: 17765150 | J30: =SUM(H30:I30) -> 83490079
D32: Total Liabilities | H32: =SUM(H25+H27+H29+H30) -> 73544966 | I32: =SUM(I25+I27+I29+I30) -> 19530149 | J32: =SUM(J25+J27+J29+J30) -> 93075115
A34: Deferred Inflows of Resouces
C35: Unavailable revenue
E36: Property taxes | H36: 15056302 | J36: =SUM(H36:I36) -> 15056302
D37: Pension related | H37: 173586 | I37: 5369 | J37: =SUM(H37:I37) -> 178955
C38: Total Deferred Inflows of Resources | H38: =SUM(H36:H37) -> 15229888 | I38: =SUM(I36:I37) -> 5369 | J38: =SUM(H38:I38) -> 15235257
A40: NET ASSETS
B41: Net investment in capital assets | H41: 241133940 | I41: 14213969 | J41: =SUM(H41:I41) -> 255347909
B42: Restricted for:
C43: Capital projects | H43: 10311163 | J43: =SUM(H43:I43) -> 10311163
C44: Public works | H44: 743268 | J44: =SUM(H44:I44) -> 743268
C45: Public safety | H45: 1228154 | J45: =SUM(H45:I45) -> 1228154
C46: Economic development | H46: 37213 | J46: =SUM(H46) -> 37213
C47: Culture and recreation | H47: 6758072 | J47: =SUM(H47) -> 6758072
C48: Debt service | H48: 1722767 | J48: =SUM(H48) -> 1722767
...

Sheet Caddo
D1: Caddo Parish 2015 Statement of Net Assets
D2: Issued: December 31, 2015
H5: Primary government | I5: Component Units
A6: ASSETS
C7: Cash and cash equivalents | H7: 5950999 | I7: 15245486
C8: Investments | H8: 124633857 | I8: 5095867
C9: Receivables, net | H9: 44347039 | I9: 16115808
C10: Due from other governments | H10: 2274558 | I10: 817834
C11: Due from primary government | I11: 692410
C12: Inventories | H12: 115369 | I12: 450463
C13: Other assets | H13: 19512 | I13: 9942089
C14: Capital assets:
D15: Land and construction in progress | H15: 9700709 | I15: 1603135
D16: Other capital assets, net of depreciation | H16: 151921031 | I16: 50887863
C18: Total Assets | H18: =SUM(H7:H16) -> 338963074 | I18: =SUM(I7:I16) -> 100850955
A20: DEFERRED OUTFLOWS OF RESOURCES
C21: Deferred outflows related to pensions | H21: 3279211 | I21: 6079574
C22: Deferred loss on refunding bonds, net | H22: 73334 | I22: 139786
E24: Total assets and deferred outlfows of resources | H24: =H21+H18 -> 342242285 | I24: =I21+I18 -> 106930529
A26: LIABILITIES
C27: Accounts payable | H27: 2998886 | I27: 4389663
C28: Accrued liabilities | H28: 223000 | I28: 1523876
C29: Accrued interest payable | H29: 453794 | I29: 19447
C30: Retainage payable | H30: 405543
C31: Accrued insurance claims payable | H31: 1214564 | I31: 334504
C32: Due to component units | H32: 893500
C33: Due to other governmental agencies | H33: 282960 | I33: 113287
C34: Unearned revenue | H34: 34466 | I34: 53585
C35: Noncurrent liabilities:
D36: Due within one year | H36: 3181419 | I36: 3595406
D37: Due in more than one year | H37: 34939843 | I37: 25755110
C38: Net pension liability | H38: 622014 | I38: 20794724
C39: Net other post-employment benefit obligation | H39: 4436978 | I39: 12583599
D41: Total Liabilities | H41: =SUM(H27:H39) -> 49686967 | I41: =SUM(I27:I39) -> 69163201
A43: Deferred inflows of Resources
C44: Unavailable revenue- property taxes and assessments- service charges | I44: 2156050
C45: Deferred gain on refunding bonds, net | H45: 190000
C46: Deferred inflows related to pensions | H46: 300293 | I46: 7176874
D48: Total deferred inflows of resources | H48: =SUM(H44:H46) -> 490293 | I48: =SUM(I44:I46) -> 9332924
A50: NET ASSETS
...

Sheet Calcasieu
D1: Calcasieu Parish 2015 Statement of Net Assets
D2: Issued: December 31, 2015
H4: Primary Government
H5: Governmental Activities | I5: Business-Type Activities | J5: Total | K5: Component Unit
A6: ASSETS
C7: Cash and cash equivalents | H7: 47833925 | I7: 323060 | J7: =SUM(H7:I7) -> 48156985 | K7: 43385785
C8: Investments | H8: 254012189 | I8: 1534237 | J8: =SUM(H8:I8) -> 255546426 | K8: 50541626
C9: Receivables (net of allowance for uncollectibles) | H9: 62053802 | I9: 550844 | J9: =SUM(H9:I9) -> 62604646 | K9: 79442776
C10: Intergovernmental receivable | H10: 2771729 | I10: 33551 | J10: =SUM(H10:I10) -> 2805280 | K10: 1283024
C11: Internal balances | H11: 4408 | I11: -4408 | J11: =SUM(H11:I11) -> 0
C12: Due from primary government | J12: =SUM(H12:I12) -> 0 | K12: 60846
C13: Loan receivable | H13: 25764 | J13: =SUM(H13:I13) -> 25764
C14: Prepaid items | H14: 488700 | I14: 26741 | J14: =SUM(H14:I14) -> 515441 | K14: 2012295
C15: Inventory | H15: 998047 | J15: =SUM(H15:I15) -> 998047 | K15: 1939692
C16: Other assets | I16: 320 | J16: =SUM(H16:I16) -> 320 | K16: 1041703
C17: Restricted assets: | J17: =SUM(H17:I17) -> 0
D18: Cash and cash equivalents | I18: 11882 | J18: =SUM(H18:I18) -> 11882 | K18: 4435646
D19: Investments | I19: 288173 | J19: =SUM(H19:I19) -> 288173 | K19: 7590803
D20: Receivables - net | I20: 153051 | J20: =SUM(H20:I20) -> 153051 | K20: 2713172
C21: Capital assets: | J21: =SUM(H21:I21) -> 0
D22: Non-depreciable | H22: 427965041 | I22: 227920 | J22: =SUM(H22:I22) -> 428192961 | K22: 42292522
D23: Depreciable, net | H23: 102872425 | I23: 9680095 | J23: =SUM(H23:I23) -> 112552520 | K23: 215355582
C25: Total Assets | H25: =SUM(H7:H23) -> 899026030 | I25: =SUM(I7:I23) -> 12825466 | J25: =SUM(J7:J23) -> 911851496 | K25: =SUM(K7:K23) -> 452095472
A27: DEFERRED OUTFLOWS OF RESOURCES
C28: Deferred amount on refunding | J28: =SUM(H28:I28) -> 0 | K28: 59374
C29: Deferred outflows- other | J29: =SUM(H29:I29) -> 0 | K29: 10668000
C30: Pension related deferred inflows of resources | H30: 5963331 | J30: =SUM(H30:I30) -> 5963331 | K30: 10209540
C31: Total deferred inflows of resouces | H31: =SUM(H28:H30) -> 5963331 | I31: =SUM(I28:I30) -> 0 | J31: =SUM(J28:J30) -> 5963331 | K31: =SUM(K28:K30) -> 20936914
A33: LIABILITIES
C34: Accounts payable and other accrued liabilities | H34: 8118541 | I34: 188157 | J34: =SUM(H34:I34) -> 8306698 | K34: 11455655
C35: Intergovernmental payable | H35: 4132661 | J35: =SUM(H35:I35) -> 4132661 | K35: 10064354
C36: Due to component units | H36: 60846 | J36: =SUM(H36:I36) -> 60846
C37: Unearned revenue | H37: 3382097 | J37: =SUM(H37:I37) -> 3382097 | K37: 1600562
C38: Other liabilities | H38: 172537 | J38: =SUM(H38:I38) -> 172537 | K38: 327849
C39: Liabilities payable from restricted assets | I39: 169443 | J39: =SUM(H39:I39) -> 169443 | K39: 894726
C40: Noncurrent liabilities: | J40: =SUM(H40:I40) -> 0
D41: Due within one year | H41: 2926865 | I41: 42456 | J41: =SUM(H41:I41) -> 2969321 | K41: 10956289
D42: Due in more than one year | H42: 9767208 | I42: 232004 | J42: =SUM(H42:I42) -> 9999212 | K42: 62595999
D44: Total Liabilities | H44: =SUM(H34:H42) -> 28560755 | I44: =SUM(I34:I42) -> 632060 | J44: =SUM(J34:J42) -> 29192815 | K44: =SUM(K34:K42) -> 97895434
A46: DEFERRED INFLOWS OF RESOURCES
...

Sheet Caldwell
C1: Caldwell Parish 2015 Statement of Net Assets
C2: Issued: December 31, 2015
G4: Governmental Activities
A5: ASSETS
B6: Cash and cash equivalents | G6: 7400441
B7: Receivables | G7: 1902779
B8: Capital assets, net of accumulated depreciation | G8: 16886347
B10: Total Assets | G10: =SUM(G6:G8) -> 26189567
A12: DEFERRED OUTFLOWS
B13: Pension related | G13: 85830
A15: LIABILITIES
B16: Cash overdraft
B17: Accounts, salaries, and other payables | G17: 436806
B18: Due to other agencies | G18: 57698
B19: Compensated absences payable | G19: 102079
B20: Net pension liability | G20: 86662
C22: Total Liabilities | G22: =SUM(G17:G20) -> 683245
A24: DEFERRED INFLOWS
B25: Pension related | G25: 35166
A27: NET ASSETS
B28: Net investment in capital assets | G28: 16886347
B29: Restricted | G29: 8172641
B30: Unrestricted | G30: 497998
B32: Total Net Assets | G32: =SUM(G28:G30) -> 25556986
B34: Total Liabilities and Net Assets | G34: =SUM(G22+G32+G25) -> 26275397

Sheet Catahoula
D1: Catahoula Parish 2015 Statement of Net Assets
D2: Issued: December 31, 2015
I4: Component Units
H5: Governmental Activities | I5: Fire District No. 1 Maintenance
A6: ASSETS
C7: Cash and cash equivalents | H7: 2146227 | I7: 116852
C8: Cash restricted for debt service | H8: 27472
C9: Cash restricted for capital project | H9: 38193
C10: Receivables | H10: 1487134 | I10: 14895
C11: Other assets | H11: 83326
C12: Capital assets, net of accumulated depreciation | H12: 6900530 | I12: 92646
C14: Total Assets | H14: =SUM(H7:H12) -> 10682882 | I14: =SUM(I7:I12) -> 224393
A16: DEFERRED OUTFLOWS
B17: Deferred outflows- pension related | H17: 54981
A19: LIABILITIES
C20: Accounts, salaries, and other payables | H20: 656405 | I20: 522
C21: Compensated absences | H21: 36269
C22: Certificates of indebtedness due within one year | H22: 107000
C23: Certificates of indebtedness due in more than one | H23: 165000
C24: Net pension liability | H24: 26562
D26: Total Liabilities | H26: =SUM(H20:H24) -> 991236 | I26: =SUM(I20:I24) -> 522
A28: DEFERRED INFLOWS
C29: Deferred inflows- pension related | H29: 12106
C30: Grant revenues pending | H30: 14776
D31: Total deferred inflows | H31: =SUM(H29:H30) -> 26882 | I31: =SUM(I29:I30) -> 0
A33: NET ASSETS
B34: Net investment in capital assets | H34: 6900530 | I34: 92646
B35: Restricted net position | H35: 2035217 | I35: 131225
B36: Unrestricted net position | H36: 783998
C38: Total Net Assets | H38: =SUM(H34:H36) -> 9719745 | I38: =SUM(I34:I36) -> 223871
C40: Total Liabilities and Net Assets | H40: =SUM(H26+H38+H31) -> 10737863 | I40: =SUM(I26+I38+I31) -> 224393

Sheet Cameron
C1: Cameron Parish 2015 Statement of Net Assets
C2: Issued: December 31, 2015
G4: Governmental Activities
A5: ASSETS
B6: Cash | G6: 16575500
B7: Investments | G7: 11477630
B8: Receivables, net | G8: 13918620
B9: Inventory, at cost | G9: 1858050
B10: Other | G10: 197269
B11: Capital assets, net of accumulated depreciation | G11: 123784927
B13: Total Assets | G13: =SUM(G6:G11) -> 167811996
A15: DEFERRED OUTFLOWS OF RESOURCES | G15: 1016716
A17: LIABILITIES
B18: Accounts, salaries, and other payables | G18: 1999259
B19: Due to other agencies | G19: 2551196
B20: Unearned revenue | G20: 17231
B21: Interest payable | G21: 22491
B22: Long-term liabilities:
C23: Due within one year | G23: 1183863
C24: Due after one year | G24: 3075083
C26: Total Liabilities | G26: =SUM(G18:G24) -> 8849123
A28: DEFERRED INFLOWS OF RESOURCES | G28: 1986478
A30: NET ASSETS
B31: Net investment in capital assets | G31: 121538091
B32: Net position - restricted for:
C33: Judicial | G33: 48266
C34: Debt service | G34: 646986
C35: Tourism development | G35: 44880
C36: Inventories | G36: 1909983
C37: Prepaid expenses | G37: 145336
B38: Net position - unrestricted | G38: 33659569
B40: Total Net Assets | G40: =SUM(G31:G38) -> 157993111
B42: Total Liabilities and Net Assets | G42: =SUM(G26+G40+G28) -> 168828712

Sheet Claiborne
C1: Claiborne Parish 2015 Statement of Net Assets
C2: Issued: December 31, 2015
G4: Governmental Activities
A5: ASSETS
B6: Cash and cash equivalents | G6: 6780670
B7: Investments | G7: 793544
B8: Receivables | G8: 3238498
B9: Due from other agencies | G9: 26080
B10: Deferred charges | G10: 106117
B11: Capital assets, net of accumulated depreciation | G11: 8351695
B13: Total Assets | G13: =SUM(G6:G11) -> 19296604
A15: DEFERRED OUTFLOWS
B16: Deferred outflow- pension related | G16: 129494
A18: LIABILITIES
B19: Accounts, salaries, and other payables | G19: 547636
B20: Due to other agencies | G20: 14025
B21: Deferred revenue | G21: 15626
B22: Compensated absences payable | G22: 70564
B23: Bonds payable within one year | G23: 155000
B24: Bonds payable in more than one year | G24: 1390000
B25: Net pension liability | G25: 87240
C27: Total Liabilities | G27: =SUM(G19:G25) -> 2280091
A29: DEFERRED INFLOWS
B30: Deferred inflows- pension related | G30: 33504
A32: NET ASSETS
B33: Net investment in capital assets | G33: 6806695
B34: Restricted for:
C35: General government | G35: 587824
C36: General government - judicial | G36: 162333
C37: Public works | G37: 2871650
C38: Public safety | G38: 266061
C39: Health and welfare | G39: 244831
C40: Culture and recreation | G40: 1395262
B41: Unrestricted | G41: 4777847
B43: Total Net Assets | G43: =SUM(G33:G41) -> 17112503
B45: Total Liabilities and Net Assets | G45: =SUM(G27+G43+G30) -> 19426098

Sheet Concodria
C1: Concordia Parish 2015 Statement of Net Assets
C2: Issued: December 31, 2015
G4: Governmental Activities
A5: ASSETS
B6: Current Assets
B7: Cash and cash equivalents | G7: 8008253
B8: Cash and cash equivalents - restricted | G8: 2542427
B9: Acounts Receivable | G9: 131838
B10: Ad valorem taxes receivable, net | G10: 1569088
B11: Sales and use taxes receivable | G11: 167250
B12: Severance taxes receivable | G12: 183685
B14: Total Assets | G14: =SUM(G7:G12) -> 12602541
B16: Capital Assets
B17: Proptery and equipment, net | G17: 10080096
G18: =SUM(G14+G17) -> 22682637
B20: Deferred Outflows of Resources
B21: Deferred outflows of pension resources | G21: 234703
G22: =G21+G18 -> 22917340
A24: LIABILITIES, DEFERRED INFLOWS OF RESOURCES, AND NET POSITION
B25: Current liabilities:
C26: Accounts payable | G26: 216980
C27: Accured payroll and benefits | G27: 92325
C28: Interest payable | G28: 217504
C29: Sales tax bonds- due within one year | G29: 413369
G30: =SUM(G26:G29) -> 940178
B32: Noncurrent liabilities:
C33: General obligation bonds | G33: 8419519
C34: Net pension liability | G34: 76459
G35: =SUM(G33:G34) -> 8495978
C37: Total Liabilities | G37: =G35+G30 -> 9436156
A39: Deferred Inflows of Resources
B40: Deferred inflows related to pensions | G40: 34846
A42: NET ASSETS
B43: Net investment in capital assets | G43: 1247208
B44: Restricted for:
C45: Debt service | G45: 3206009
C46: Special projects | G46: 5041759
B47: Unrestricted | G47: 3951362
B49: Total Net Assets | G49: =SUM(G43:G47) -> 13446338
B51: Total Liabilities and Net Assets | G51: =SUM(G37+G49+G40) -> 22917340

Sheet DeSoto
D1: DeSoto Parish 2015 Statement of Net Assets
D2: Issued: December 31, 2015
H4: Primary Government
H5: Governmental Activities | I5: Business-Type Activities | J5: Total
A6: ASSETS
C7: Cash and cash equivalents | H7: 8494984 | I7: 36131 | J7: =SUM(H7:I7) -> 8531115
C8: Investments | H8: 20852796 | J8: =SUM(H8:I8) -> 20852796
C9: Receivables (net of allowance for uncollectibles) | H9: 13253156 | I9: 2154 | J9: =SUM(H9:I9) -> 13255310
C10: Inventory | H10: 26264 | J10: =SUM(H10:I10) -> 26264
C11: Capital assets, net | H11: 76265772 | I11: 21965 | J11: =SUM(H11:I11) -> 76287737
C13: Total Assets | H13: =SUM(H7:H11) -> 118892972 | I13: =SUM(I7:I11) -> 60250 | J13: =SUM(J7:J11) -> 118953222
A15: Deferred Outflows of Resources | H15: 594521 | J15: =SUM(H15:I15) -> 594521
A18: LIABILITIES
C19: Accounts payable | H19: 1358547 | I19: 1538 | J19: =SUM(H19:I19) -> 1360085
C20: Master Bank Overdrafts | H20: 50957 | J20: =SUM(H20:I20) -> 50957
C21: Deposit balances | H21: 300 | I21: 270 | J21: =SUM(H21:I21) -> 570
C22: Advance from grantors | H22: 18938 | J22: =SUM(H22:I22) -> 18938
C23: Due to other governments | H23: 154306 | J23: =SUM(H23:I23) -> 154306
C24: Landfill post closure liability | H24: 2402514 | J24: =SUM(H24:I24) -> 2402514
C25: Compensated absences | H25: 323506 | J25: =SUM(H25:I25) -> 323506
C26: Other postemployment benefit obligation | H26: 3391372 | J26: =SUM(H26:I26) -> 3391372
C27: Net pension liability | H27: 76675 | J27: =SUM(H27:I27) -> 76675
C28: Long-term liabilities:
D29: Due within one year | H29: 449 | J29: =SUM(H29:I29) -> 449
D31: Total Liabilities | H31: =SUM(H19:H29) -> 7777564 | I31: =SUM(I19:I29) -> 1808 | J31: =SUM(J19:J29) -> 7779372
A33: Deferred Inflows of Resources | H33: 165486 | J33: =SUM(H33:I33) -> 165486
A35: NET ASSETS
B36: Net investment in capital assets | H36: 76265323 | I36: 21965 | J36: =SUM(H36:I36) -> 76287288
B37: Restricted for Debt Service | H37: 449 | J37: =SUM(H37:I37) -> 449
B38: Unrestricted | H38: 35278671 | I38: 36477 | J38: =SUM(H38:I38) -> 35315148
C40: Total Net Assets | H40: =SUM(H36:H38) -> 111544443 | I40: =SUM(I36:I38) -> 58442 | J40: =SUM(J36:J38) -> 111602885
C42: Total Liabilities and Net Assets | H42: =SUM(H40+H31) -> 119322007 | I42: =SUM(I40+I31) -> 60250 | J42: =SUM(J40+J31) -> 119382257

Sheet East Baton Rouge
D1: East Baton Rouge Parish 2015 Statement of Net Assets
D2: Issued: December 31, 2015
H4: Primary Government
H5: Governmental Activities | I5: Business-Type Activities | J5: Total | K5: Component Unit
A6: ASSETS
B7: Current Assets
C8: Cash and cash equivalents (note 3) | H8: 166127175 | I8: 79289820 | J8: =SUM(H8:I8) -> 245416995 | K8: 16982146
C9: Investments (note 3) | H9: 211759186 | I9: 118482692 | J9: =SUM(H9:I9) -> 330241878
C10: Receivables--net (note 13) | H10: 52535997 | I10: 16288427 | J10: =SUM(H10:I10) -> 68824424 | K10: 16655099
C11: Due from other governments (note 11) | H11: 84333564 | I11: 2817878 | J11: =SUM(H11:I11) -> 87151442 | K11: 1994449
C12: Prepaid items | H12: 383370 | I12: 207466 | J12: =SUM(H12:I12) -> 590836 | K12: 79566
C13: Loans receivable | H13: 4115590 | J13: =SUM(H13:I13) -> 4115590 | K13: 2138660
C14: Inventory | H14: 896044 | I14: 93352 | J14: =SUM(H14:I14) -> 989396 | K14: 5295059
C15: Other assets | K15: 404912
C16: Restricted assets:
D17: Cash and cash equivalents (note 3) | I17: 135635134 | J17: =SUM(H17:I17) -> 135635134 | K17: 13552638
D18: Investments (note 3) | I18: 232187796 | J18: =SUM(H18:I18) -> 232187796
D19: Receivables--net (note 13) | I19: 423264 | J19: =SUM(H19:I19) -> 423264
D20: Prepaid items | I20: 5880 | J20: =SUM(H20:I20) -> 5880
C21: Capital assets:
D22: Non-depreciable | H22: 198991410 | I22: 349628460 | J22: =SUM(H22:I22) -> 548619870
D23: Depreciable, net | H23: 692284458 | I23: 1530952497 | J23: =SUM(H23:I23) -> 2223236955 | K23: 105830990
C25: Total Assets | H25: =SUM(H8:H23) -> 1411426794 | I25: =SUM(I8:I23) -> 2466012666 | J25: =SUM(J8:J23) -> 3877439460 | K25: =SUM(K8:K23) -> 162933519
A27: Deferred Outflows of Resources
B28: Deferred amount on refunding | H28: 14606047 | I28: 39737972 | J28: =SUM(H28:I28) -> 54344019 | K28: 0
B29: Deferred outflows on derivative instruments | H29: 14755836 | I29: 92452209 | J29: =SUM(H29:I29) -> 107208045 | K29: 0
B30: Deferred outflow for pension | H30: 66874233 | I30: 5853183 | J30: =SUM(H30:I30) -> 72727416 | K30: 9366140
C32: Total deferred outflows of resources | H32: =SUM(H28:H30) -> 96236116 | I32: =SUM(I28:I30) -> 138043364 | J32: =SUM(J28:J30) -> 234279480 | K32: =SUM(K28:K30) -> 9366140
A34: LIABILITIES
C35: Accounts payable and other current liabilities | H35: 27771571 | I35: 50174496 | J35: =SUM(H35:I35) -> 77946067 | K35: 2709410
C36: Internal balances (Note 11) | H36: -1418884 | I36: 1418884
C37: Due to other governments | H37: 490429 | J37: =SUM(H37:I37) -> 490429 | K37: 189168
C38: Accrued payables | H38: 9680296 | I38: 28401015 | J38: =SUM(H38:I38) -> 38081311 | K38: 1490511
C39: Unearned revenue | H39: 1095601 | I39: 1767570 | J39: =SUM(H39:I39) -> 2863171
C40: Deposits and escrow accounts | H40: 1095601 | I40: 1767570 | J40: 11480091
C41: Other liabilities | H41: 11480091 | K41: 59366
C42: Noncurrent liabilities (note 10):
D43: Due within one year | H43: 35509330 | I43: 14070175 | J43: =SUM(H43:I43) -> 49579505 | K43: 3611296
D44: Due in more than one year | H44: 1236678992 | I44: 1683809809 | J44: =SUM(H44:I44) -> 2920488801 | K44: 154960366
D46: Total Liabilities | H46: =SUM(H35:H44) -> 1322383027 | I46: =SUM(I35:I44) -> 1781409519 | J46: =SUM(H46:I46) -> 3103792546 | K46: =SUM(K35:K44) -> 163020117
...

Sheet East Carroll
D1: East Carroll Parish 2015 Statement of Net Assets
D2: Issued: December 31, 2015
H4: Primary Government
H5: Governmental Activities | I5: Business-Type Activities | J5: Total
A6: ASSETS
C7: Cash and cash equivalents | H7: 1995746 | I7: 35311 | J7: =SUM(H7:I7) -> 2031057
C8: Investments | H8: 719027 | J8: =SUM(H8:I8) -> 719027
C9: Receivables | H9: 2907365 | I9: 2197 | J9: =SUM(H9:I9) -> 2909562
C10: Prepaid items | I10: 1189 | J10: =SUM(H10:I10) -> 1189
C11: Cash and cash equivalents - restricted | I11: 10050 | J11: =SUM(H11:I11) -> 10050
C12: Capital assets not being depreciated | H12: 695896 | J12: =SUM(H12:I12) -> 695896
C13: Capital assets, net of accumulated depreciation | H13: 5462550 | J13: =SUM(H13:I13) -> 5462550
C15: Total Assets | H15: =SUM(H7:H13) -> 11780584 | I15: =SUM(I7:I13) -> 48747 | J15: =SUM(J7:J13) -> 11829331
A17: DEFERRED OUTFLOWS OF RESOURCES
B18: Deferred outflows related to pensions | H18: 287208 | I18: 6937 | J18: =SUM(H18:I18) -> 294145
C19: TOTAL DEFERRED OUTFLOWS OF RESOURCES | H19: =SUM(H18) -> 287208 | I19: =SUM(I18) -> 6937 | J19: =SUM(H19:I19) -> 294145
A21: LIABILITIES
C22: Accounts payable | H22: 111679 | I22: 339 | J22: =SUM(H22:I22) -> 112018
C23: Interest payable | H23: 5987 | J23: =SUM(H23:I23) -> 5987
C24: Long-term liabilities:
D25: Due within one year | H25: 213975 | I25: 489 | J25: =SUM(H25:I25) -> 214464
D26: Due in more than one year | H26: 310647 | I26: 1431 | J26: =SUM(H26:I26) -> 312078
D28: Total Liabilities | H28: =SUM(H22:H26) -> 642288 | I28: =SUM(I22:I26) -> 2259 | J28: =SUM(J22:J26) -> 644547
A30: DEFERRED INFLOWS OF RESOURCES
B31: Deferred outflows related to pensions | H31: 39401 | I31: 952 | J31: =SUM(H31:I31) -> 40353
D32: TOTAL DEFERRED INFLOWS OF RESOURCES | H32: =H31 -> 39401 | I32: =I31 -> 952 | J32: =SUM(H32:I32) -> 40353
A34: NET ASSETS
B35: Net investment in capital assets | H35: 5701437 | J35: =SUM(H35:I35) -> 5701437
B36: Restricted for:
C37: Road maintenance | H37: 1374444 | J37: =SUM(H37:I37) -> 1374444
C38: Garbage | H38: 547996 | J38: =SUM(H38:I38) -> 547996
C39: Library | H39: 682205 | J39: =SUM(H39:I39) -> 682205
C40: Drainage | H40: 631962 | J40: =SUM(H40:I40) -> 631962
C41: Health unit | H41: 715989 | J41: =SUM(H41:I41) -> 715989
C42: Criminal Court | H42: 12682 | J42: =SUM(H42:I42) -> 12682
C43: Debt service | H43: 97837 | J43: =SUM(H43:I43) -> 97837
C44: Rural Fire Protection | H44: 490894 | J44: =SUM(H44:I44) -> 490894
C45: LSU/SU Extension | H45: 221548 | J45: =SUM(H45:I45) -> 221548
C46: Housing Assistance Payments | I46: 10050 | J46: =SUM(H46:I46) -> 10050
B47: Unrestricted | H47: 909109 | I47: 42423 | J47: =SUM(H47:I47) -> 951532
...

Sheet East Feliciana
C1: East Feliciana Parish 2015 Statement of Net Assets
C2: Issued: December 31, 2015
G4: Governmental Activities
A5: ASSETS
B6: Cash and cash equivalents | G6: 4577606
B7: Receivables, net | G7: 1201051
B8: Due from other funds | G8: 1889509
B9: Due from other governmental agencies | G9: 70258
B10: Capital assets, net | G10: 14087861
B12: Total Assets | G12: =SUM(G6:G10) -> 21826285
A14: DEFERRED OUTFLOWS OF RESOURCES
B15: Pensions | G15: 132270
B16: Total Deferred Outflows of Resources | G16: =G15 -> 132270
A18: LIABILITIES
B19: Accounts payable | G19: 98217
B20: Due to other funds | G20: 1417178
B21: Due to other governmental agencies
B22: Net pension liability | G22: 66241
B23: Compensated absences | G23: 8736
C25: Total Liabilities | G25: =SUM(G19:G23) -> 1590372
A27: DEFERRED OUTFLOWS OF RESOURCES
B28: Pensions | G28: 23363
B29: Total Deferred Outflows of Resources | G29: =G28 -> 23363
A31: NET ASSETS
B32: Net investment in capital assets | G32: 14087861
B33: Restricted for:
C34: Health unit operations/maintenance | G34: 698574
C35: Homeland security/emergency preparedness | G35: 30194
C36: Solid waste management | G36: 4205435
B37: Unrestricted | G37: 1322756
B39: Total Net Assets | G39: =SUM(G32:G37) -> 20344820
B41: Total Liabilities and Net Assets | G41: =G39+G25+G29 -> 21958555

Sheet Evangeline
D1: Evangeline Parish 2015 Statement of Net Assets
D2: Issued: December 31, 2015
H4: Primary Government
H5: Governmental Activities | I5: Business-Type Activities | J5: Total
A6: ASSETS
C7: Cash and interest-bearing deposits | H7: 9976548 | I7: 120763 | J7: =SUM(H7:I7) -> 10097311
C8: Receivables, net | H8: 7163 | I8: 13593 | J8: =SUM(H8:I8) -> 20756
C9: Due from other governmental units | H9: 6075704 | J9: =SUM(H9:I9) -> 6075704
C10: Other assets | H10: 46456 | J10: =SUM(H10:I10) -> 46456
C11: Restricted assets:
D12: Cash and interest-bearing deposits | I12: 20858 | J12: =SUM(I12) -> 20858
D13: Investments | H13: 7198420 | J13: =SUM(H13:I13) -> 7198420
C14: Capital assets, net | H14: 47031804 | I14: 233558 | J14: =SUM(H14:I14) -> 47265362
C16: Total Assets | H16: =SUM(H7:H14) -> 70336095 | I16: =SUM(I7:I14) -> 388772 | J16: =SUM(J7:J14) -> 70724867
A18: Deferred outflows of resources | H18: 560010 | I18: 3029 | J18: =SUM(H18:I18) -> 563039
A21: LIABILITIES
C22: Accounts and other payables | H22: 2822672 | I22: 795 | J22: =SUM(H22:I22) -> 2823467
C23: Accrued interest | H23: 96408 | J23: =SUM(H23:I23) -> 96408
C24: Unearned revenue | H24: 300318 | J24: =SUM(H24:I24) -> 300318
C25: Performance bonds payable | H25: 249333 | I25: 1065 | J25: =SUM(H25:I25) -> 250398
C26: Unearned revenue | H26: 12297 | I26: 12349 | J26: =SUM(H26:I26) -> 24646
C27: Deposits payable | J27: =SUM(H27:I27) -> 0
C28: Long-term liabilities: | J28: =SUM(H28:I28) -> 0
D29: Portion due within one year | H29: 1889000 | I29: 1926 | J29: =SUM(H29:I29) -> 1890926
D30: Portion due after one year | H30: 28115103 | I30: 55870 | J30: =SUM(H30:I30) -> 28170973
C31: Net pension liability | H31: 214778 | I31: 563 | J31: =SUM(H31:I31) -> 215341
D33: Total Liabilities | H33: =SUM(H22:H31) -> 33699909 | I33: =SUM(I22:I31) -> 72568 | J33: =SUM(J22:J31) -> 33772477
A35: Deferred inflows of resources | H35: 82697 | I35: 307 | J35: =SUM(H35:I35) -> 83004
A37: NET ASSETS
B38: Net investment in capital assets | H38: 24827361 | I38: 177688 | J38: =SUM(H38:I38) -> 25005049
B39: Restricted for debt service | H39: 144210 | I39: 6583 | J39: =SUM(H39:I39) -> 150793
B40: Unrestricted | H40: 12141928 | I40: 134655 | J40: =SUM(H40:I40) -> 12276583
C42: Total Net Assets | H42: =SUM(H38:H40) -> 37113499 | I42: =SUM(I38:I40) -> 318926 | J42: =SUM(J38:J40) -> 37432425
C44: Total Liabilities and Net Assets | H44: =SUM(H42+H33) -> 70813408 | I44: =SUM(I42+I33) -> 391494 | J44: =SUM(J42+J33) -> 71204902

Sheet Franklin
C1: Franklin Parish 2015 Statement of Net Assets
C2: Issued: December 31, 2015
G4: Governmental Activities
A5: ASSETS
B6: Cash and cash equivalents | G6: 9845125
B7: Receivables | G7: 3565030
B8: Capital assets (net) | G8: 19315782
B10: Total Assets | G10: =SUM(G6:G8) -> 32725937
A12: DEFERRED OUTFLOWS OF RESOURCES
B13: Pension related | G13: 114200
B14: Total assests and deferred outflow of resources | G14: =G13+G10 -> 32840137
A16: LIABILITIES
B17: Accounts payable | G17: 410724
B18: Payroll withholding payable | G18: 73784
B19: Compensated absences payable | G19: 97918
B20: Capital leases payable | G20: 42662
B21: Long-term liabilities:
C22: Due within one year | G22: 31000
C23: Due in more than one year | G23: 72000
B24: Net pension liability | G24: 72472
B25: Net OPEB obligation | G25: 1566426
C27: Total Liabilities | G27: =SUM(G17:G25) -> 2366986
A29: DEFERRED INFLOWS OF RESOURCES
B30: Pension related | G30: 28927
A32: NET ASSETS
B33: Invested in capital assets, net of related debt | G33: 19170120
B34: Unrestricted | G34: 11271104
B36: Total Net Assets | G36: =SUM(G33:G34) -> 30441224
B38: Total Liabilities, Deferred inflows of Resources, and Net Assets | G38: =SUM(G27+G36+G30) -> 32837137

Sheet Grant
D1: Grant Parish 2015 Statement of Net Assets
D2: Issued: December 31, 2015
H4: Primary Government
H5: Governmental Activities | I5: Business-Type Activities | J5: Total
A6: ASSETS
C7: Cash and cash equivalents | H7: 1607559 | I7: 448494 | J7: =SUM(H7:I7) -> 2056053
C8: Receivables (net) | H8: 1476524 | I8: 52934 | J8: =SUM(H8:I8) -> 1529458
C9: Capital assets:
D10: Non depreciable capital assets
E11: Construction in progress | H11: 410009 | I11: 20000 | J11: =SUM(H11:I11) -> 430009
E12: Land | H12: 203250 | J12: =SUM(H12:I12) -> 203250
D13: Depreciable capital assets, net | H13: 5503118 | I13: 312597 | J13: =SUM(H13:I13) -> 5815715
C15: Total Assets | H15: =SUM(H7:H13) -> 9200460 | I15: =SUM(I7:I13) -> 834025 | J15: =SUM(J7:J13) -> 10034485
C17: DEFERRED OUTFLOWS | H17: 327152 | I17: 39770 | J17: =SUM(H17:I17) -> 366922
A19: LIABILITIES
C20: Accounts and other payables | H20: 481261 | I20: 22337 | J20: =SUM(H20:I20) -> 503598
C21: Retainage Payable | H21: 32870 | J21: =SUM(H21:I21) -> 32870
C22: Deposits due others | I22: 79146 | J22: =SUM(H22:I22) -> 79146
C23: Unearned revenues | J23: =SUM(H23:I23) -> 0
C24: Long-term liabilities: | J24: =SUM(H24:I24) -> 0
D25: Compensated absences | H25: 48059 | I25: 12224 | J25: =SUM(H25:I25) -> 60283
D26: Notes payable: | J26: =SUM(H26:I26) -> 0
E27: Due within one year | H27: 97605 | J27: =SUM(H27:I27) -> 97605
E28: Due in more than one year | H28: 149857 | J28: =SUM(H28:I28) -> 149857
D29: Aggregate Net Pension Liability | H29: 95921 | I29: 7854 | J29: =SUM(H29:I29) -> 103775
D31: Total Liabilities | H31: =SUM(H20:H29) -> 905573 | I31: =SUM(I20:I29) -> 121561 | J31: =SUM(J20:J29) -> 1027134
C33: DEFERRED INFLOWS | H33: 101227 | I33: 3497 | J33: =SUM(H33:I33) -> 104724
A35: NET ASSETS
B36: Invested in capital assets, net of related debt | H36: 5836045 | I36: 332597 | J36: =SUM(H36:I36) -> 6168642
B37: Restricted:
C38: Maintenance | H38: 1732973 | J38: =SUM(H38:I38) -> 1732973
C39: Judicial | H39: 30664 | J39: =SUM(H39:I39) -> 30664
C40: Construction | H40: 51728 | J40: =SUM(H40:I40) -> 51728
B41: Unrestricted | H41: 869402 | I41: 416140 | J41: =SUM(H41:I41) -> 1285542
C43: Total Net Assets | H43: =SUM(H36:H41) -> 8520812 | I43: =SUM(I36:I41) -> 748737 | J43: =SUM(J36:J41) -> 9269549
C45: Total Liabilities and Net Assets | H45: =SUM(H43+H31+H33) -> 9527612 | I45: =SUM(I43+I31+I33) -> 873795 | J45: =SUM(J43+J31+J33) -> 10401407

Sheet Iberia
D1: Iberia Parish 2015 Statement of Net Assets
D2: Issued: December 31, 2015
H4: Primary Government
H5: Governmental Activities | I5: Component Units
A6: ASSETS
C7: Cash and interest-bearing deposits | H7: 46860646 | I7: 41977434
C8: Investments | H8: 63081
C9: Receivables, net | H9: 7717579 | I9: 10093684
C10: Advance to component unit | H10: 1989685
C11: Due from other governmental agencies | H11: 3219065 | I11: 813304
C12: Due from primary government | I12: 614357
C13: Inventories | I13: 1727422
C14: Prepaid items | I14: 707184
C15: Goodwill | I15: 282536
C16: Investments in joint ventures | I16: 501439
C17: Restricted assets | I17: 3890720
C18: Capital assets:
D19: Non-depreciable | H19: 8523433 | I19: 13973493
D20: Depreciable, net | H20: 85605502 | I20: 67696703
C22: Total Assets | H22: =SUM(H7:H20) -> 153978991 | I22: =SUM(I7:I20) -> 142278276
A24: DEFERRED OUTFLOWS OF RESOURCES
B25: Pension related | H25: 1266943 | I25: 5503380
B26: Prepaid bond insurance | I26: 80687
C27: Total deferred outflows of resources | H27: =SUM(H25:H26) -> 1266943 | I27: =SUM(I25:I26) -> 5584067
A29: LIABILITIES
C30: Accounts payable | H30: 1304798 | I30: 2567682
C31: Accrued expenses | H31: 233319 | I31: 6224024
C32: Contracts and retainage payable | H32: 860129 | I32: 1227829
C33: Due to other governmental agencies | H33: 364569 | I33: 234180
C34: Due to component unit | H34: 614357
C35: Advance from primary government | I35: 1989685
C36: Advances from grantors and others | H36: 89950 | I36: 66735
C37: Deposits | I37: 371027
C38: Accrued interest payable | H38: 23641 | I38: 221554
C39: Long-term liabilities:
D40: Tenant deposits | I40: 12311
D41: Other post employment benefits payable | H41: 5571987 | I41: 2214306
D42: Net pension liability | H42: 245699 | I42: 3734210
D43: Due within one year | H43: 1825318 | I43: 3726878
D44: Due in more than one year | H44: 13093322 | I44: 37757138
...

Sheet Iberville
D1: Iberville Parish 2015 Statement of Net Assets
D2: Issued: December 31, 2015
H4: Primary Government | K4: Total Component Units
H5: Governmental Activities | I5: Business-Type Activities | J5: Total | K5: Governmental Activities | L5: Business-type Activities
A6: ASSETS
B7: Current Assets
C8: Cash and cash equivalents | H8: 30313280 | I8: 3497391 | J8: =SUM(H8:I8) -> 33810671 | K8: 1884797 | L8: 546127
C9: Investments | J9: =SUM(H9:I9) -> 0 | K9: 299697
C10: Receivables (net of allowance for uncollectibles) | H10: 9106856 | I10: 705101 | J10: =SUM(H10:I10) -> 9811957 | K10: 3893015 | L10: 193352
C11: Inventories | I11: 177220 | J11: =SUM(H11:I11) -> 177220
C12: Prepaid items | H12: 5222 | J12: =SUM(H12:I12) -> 5222 | L12: 15379
C13: Other assets | H13: 1217886 | I13: 62274 | J13: =SUM(H13:I13) -> 1280160 | K13: 38380 | L13: 35137
C14: Restricted assets
D15: Cash and cash equivalents | H15: 100000 | I15: 303573 | J15: =SUM(H15:I15) -> 403573 | L15: 750238
C16: Capital assets (net of accumulated depreciation)
D17: Land | H17: 3232380 | I17: 193511 | J17: =SUM(H17:I17) -> 3425891 | K17: 435740
D18: Building and system | H18: 52248412 | I18: 10523122 | J18: =SUM(H18:I18) -> 62771534 | K18: 869565 | L18: 1722119
D19: Improvemetns other than building | H19: 54880429 | J19: =SUM(H19:I19) -> 54880429 | K19: 484925 | L19: 3204005
D20: Machinery and equipment | H20: 6118075 | I20: 486014 | J20: =SUM(H20:I20) -> 6604089 | K20: 433565 | L20: 1150084
D21: Construction in progress | H21: 1222654 | J21: =SUM(H21:I21) -> 1222654 | K21: 220857 | L21: 73167
C23: Total Assets | H23: =SUM(H8:H21) -> 158445194 | I23: =SUM(I8:I21) -> 15948206 | J23: =SUM(J8:J21) -> 174393400 | K23: =SUM(K8:K21) -> 8560541 | L23: =SUM(L8:L21) -> 7689608
A25: DEFERRED OUTFLOWS OF RESOURCES
B26: Pension | H26: 1111407 | I26: 209614 | J26: =SUM(H26:I26) -> 1321021 | K26: 308042
A28: LIABILITIES
C29: Accounts payable and other current liabilities | H29: 3426953 | I29: 517330 | J29: =SUM(H29:I29) -> 3944283 | L29: 71599
C30: Matured bonds and interest payable | J30: =SUM(H30:I30) -> 0
C31: Accrued interest payable | J31: =SUM(H31:I31) -> 0
C32: Bank overdraft liability | J32: =SUM(H32:I32) -> 0
C33: Other payables | H33: 885850 | I33: 3348 | J33: =SUM(H33:I33) -> 889198 | K33: 282113
C34: Liabilities payable from restricted assets | I34: 300298 | J34: =SUM(H34:I34) -> 300298 | K34: 189454 | L34: 124376
C35: Noncurrent liabilities: | J35: =SUM(H35:I35) -> 0
D36: Pension | H36: 204798 | I36: 38625 | J36: =SUM(H36:I36) -> 243423 | K36: 57273
D37: Other post employment benefits | H37: 585479 | J37: =SUM(H37:I37) -> 585479 | K37: 89936
D38: Due in one year | H38: 1415089 | I38: 55000 | J38: =SUM(H38:I38) -> 1470089 | L38: 97891
D39: Due in more than one year | H39: 18163086 | I39: 435000 | J39: =SUM(H39:I39) -> 18598086 | K39: 312344 | L39: 3160978
D41: Total Liabilities | H41: =SUM(H29:H39) -> 24681255 | I41: =SUM(I29:I39) -> 1349601 | J41: =SUM(J29:J39) -> 26030856 | K41: =SUM(K29:K39) -> 931120 | L41: =SUM(L29:L39) -> 3454844
A43: DEFERRED INFLOWS OF RESOURCES
B44: Pension | H44: 97127 | I44: 18318 | J44: =SUM(H44:I44) -> 115445 | K44: 27415
A46: NET ASSETS
B47: Net Investment in Capital Assets | H47: 99077563 | I47: 10712647 | J47: =SUM(H47:I47) -> 109790210 | K47: 2444652 | L47: 3023534
...

Sheet Jackson 
C1: Jackson Parish 2015 Statement of Net Assets
C2: Issued: December 31, 2015
G4: Governmental Activities
A5: ASSETS
B6: Cash and cash equivalents | G6: 10715548
B7: Receivables | G7: 5708768
B8: Prepaid items | G8: 43519
B9: Capital assets:
C10: Land and construction in progress | G10: 433912
C11: Capital assets, net of depreciation | G11: 16798841
B13: Total Assets | G13: =SUM(G6:G11) -> 33700588
A15: DEFERRED OUTFLOWS OF RESOURCES
B16: Deferred outflows related to pensions | G16: 425617
B17: TOTAL DEFERRED OUTFLOWS OF RESOURCES | G17: =G16 -> 425617
A19: LIABILITIES
B20: Accounts, salaries, and other payables | G20: 491701
B21: Security deposits | G21: 25321
B22: Long-term liabilities:
C23: Due within one year | G23: 372241
C24: Due in more than one year | G24: 3340963
C26: Total Liabilities | G26: =SUM(G20:G24) -> 4230226
A28: DEFERRED INFLOWS OF RESOURCES
B29: Deferred outflows related to pensions | G29: 64691
B30: TOTAL DEFERRED OUTFLOWS OF RESOURCES | G30: =G29 -> 64691
A32: NET ASSETS
B33: Net investment in capital assets | G33: 14791909
B34: Restricted for:
C35: Road maintenance (Road, Sales tax and asphalt funds) | G35: 6733177
C36: Waste management | G36: 1158237
C37: Library | G37: 2469276
C38: Health unit | G38: 286867
C39: Tourism | G39: 50860
C40: Landfill closure | G40: 555594
C41: Pavillion/Riding Arena | G41: 251024
C42: Grant funds | G42: 35419
C43: Grand jury and witness fees | G43: 15158
C44: Debt service | G44: 190913
B45: Unrestricted | G45: 3292854
B47: Total Net Assets | G47: =SUM(G33:G45) -> 29831288
B49: Total Liabilities and Net Assets | G49: =SUM(G26+G47+G30) -> 34126205

Sheet Jefferson
D1: Jefferson Parish 2015 Statement of Net Assets
D2: Issued: December 31, 2015
G3: (amounts in thousands)
H5: Primary Government
H6: Governmental Activities | I6: Business-Type Activities | J6: Total | K6: Component Unit
A7: ASSETS
B8: Current Assets
C9: Cash and cash equivalents | H9: 5540 | I9: 4796 | J9: =SUM(H9:I9) -> 10336 | K9: 15882
C10: Investments | H10: 73132 | J10: =SUM(H10:I10) -> 73132 | K10: 90512
C11: Share of pooled assets | H11: 558920 | I11: 15040 | J11: =SUM(H11:I11) -> 573960
C12: Receivables, net of allowances for
D13: estimated uncollectibles:
D14: Interest | H14: 214 | J14: =SUM(H14:I14) -> 214 | K14: 180
D15: Ad valorem tax | H15: 200503 | I15: 9211 | J15: =SUM(H15:I15) -> 209714
D16: Accounts | H16: 5688 | I16: 5439 | J16: =SUM(H16:I16) -> 11127 | K16: 51143
D17: Notes | K17: 7625
D18: Mortgage loans
D19: Intergovernmental | H19: 62084 | I19: 21 | J19: =SUM(H19:I19) -> 62105 | K19: 58
D20: Other | J20: =SUM(H20:I20) -> 0 | K20: 6239
C21: Inventories | H21: 3414 | I21: 7786 | J21: =SUM(H21:I21) -> 11200 | K21: 10061
C22: Prepaid items | I22: 398 | J22: =SUM(H22:I22) -> 398 | K22: 7818
C23: Restricted assets: | J23: =SUM(H23:I23) -> 0
D24: Cash and cash equivalents | I24: 27743 | J24: =SUM(H24:I24) -> 27743 | K24: 10881
D25: Investments | I25: 106509 | J25: =SUM(H25:I25) -> 106509 | K25: 83923
D26: Share of pooled assets | I26: 57307 | J26: =SUM(H26:I26) -> 57307
D27: Receivables | I27: 13488 | J27: =SUM(H27:I27) -> 13488
C29: Total Current Assets | H29: =SUM(H9:H27) -> 909495 | I29: =SUM(I9:I27) -> 247738 | J29: =SUM(J9:J27) -> 1157233 | K29: =SUM(K9:K27) -> 284322
B31: Noncurrent Assets
C32: Restricted assets:
D33: Deposits and other assets | H33: 7817 | J33: =SUM(H33:I33) -> 7817 | K33: 7698
C34: Mortgage loans receivable | J34: =SUM(H34:I34) -> 0 | K34: 40572
C35: Capital assets not being depreciated | H35: 202984 | I35: 50606 | J35: =SUM(H35:I35) -> 253590
C36: Capital assets being depreciated, net | H36: 1112858 | I36: 639120 | J36: =SUM(H36:I36) -> 1751978 | K36: 221050
C38: Total Noncurrent Assets | H38: =SUM(H31:H36) -> 1323659 | I38: =SUM(I31:I36) -> 689726 | J38: =SUM(J31:J36) -> 2013385 | K38: =SUM(K31:K36) -> 269320
C40: Total Assets | H40: =SUM(H38+H29) -> 2233154 | I40: =SUM(I38+I29) -> 937464 | J40: =SUM(J29+J38) -> 3170618 | K40: =SUM(K29+K38) -> 553642
B42: Deferred outflows of resources
C43: Deferred charges on debt refunding | H43: 9616 | J43: =SUM(H43:I43) -> 9616
C44: Deferred charges acquisition costs | I44: 3362 | J44: =SUM(H44:I44) -> 3362
C45: Pension-relate deferred outflows | H45: 35056 | I45: 8197 | J45: =SUM(H45:I45) -> 43253 | K45: 4090
C47: Total Deferred Outflows of Resources | H47: =SUM(H43:H45) -> 44672 | I47: =SUM(I43:I45) -> 11559 | J47: =SUM(J43:J45) -> 56231 | K47: =SUM(K43:K45) -> 4090
...

Sheet Jefferson Davis
C1: Jefferson Davis Parish 2015 Statement of Net Assets
C2: Issued: December 31, 2015
G4: Governmental Activities
A5: ASSETS
B6: Cash and cash equivalents | G6: 22295246
B7: Investments | G7: 2118764
B8: Receivables | G8: 2190018
B9: Prepaid items | G9: 79428
B10: Restricted cash and cash equivalents | G10: 2678453
B11: Capital assets (net) | G11: 34263814
B13: Total Assets | G13: =SUM(G6:G11) -> 63625723
A15: DEFERRED OUTFLOWS OF RESOURCES
B16: Pension related deferrals | G16: 327109
B17: Deferred bond issuance costs | G17: 57099
B18: TOTAL DEFERRED OUTFLOWS OF RESOURCES | G18: =SUM(G16:G17) -> 384208
A20: LIABILITIES
B21: Accounts, salaries, and other payables | G21: 827526
B22: Contracts payable | G22: 43790
B23: Deposits due others | G23: 567800
B24: Accrued interest payable | G24: 262428
B25: Liability for other post-employment benefits | G25: 2453168
B26: Current portion of bonds payable | G26: 984000
B27: Current portion of capital leases payable | G27: 144783
B28: Capital leases payable | G28: 639410
B29: Bonds payable | G29: 13730000
B30: Net pension liability | G30: 273215
C32: Total Liabilities | G32: =SUM(G21:G30) -> 19926120
A34: DEFERRED INFLOWS OF RESOURCES
B35: Pension related deferrals | G35: 78329
B36: Deferred revenues | G36: 177663
B37: TOTAL DEFERRED INFLOWS OF RESOURCES | G37: =SUM(G35:G36) -> 255992
A39: NET ASSETS
B40: Net investment in capital assets | G40: 18503193
B41: Restricted for:
C42: Public safety | G42: 7352490
C43: Public works | G43: 8777284
C44: Health and welfare | G44: 407444
C45: Debt service | G45: 2675500
C46: Other general government | G46: 1503341
B47: Unrestricted | G47: 4608567
...

Sheet Lafayette
D1: Lafayete Parish 2015 Statement of Net Assets
D2: Issued: December 31, 2015
H4: Primary Government
H5: Governmental Activities | I5: Business-Type Activities | J5: Total | K5: Component Unit
A6: ASSETS
C7: Cash and interest-bearing deposits | H7: 16641210 | I7: 5283189 | J7: =SUM(H7:I7) -> 21924399 | K7: 52538532
C8: Investments | H8: 271226470 | I8: 28061815 | J8: =SUM(H8:I8) -> 299288285 | K8: 18134974
C9: Receivables, net | H9: 5368379 | I9: 23844975 | J9: =SUM(H9:I9) -> 29213354 | K9: 9343950
C10: Internal balances | H10: 1545353 | I10: -1545353 | J10: =SUM(H10:I10) -> 0
C11: Due from primary government | J11: =SUM(H11:I11) -> 0 | K11: 92392
C12: Due from other governmental agencies | H12: 19498802 | I12: 2460768 | J12: =SUM(H12:I12) -> 21959570 | K12: 4672050
C13: Inventories, net | H13: 479070 | I13: 19979155 | J13: =SUM(H13:I13) -> 20458225 | K13: 226786
C14: Prepaid items | H14: 311348 | I14: 603948 | J14: =SUM(H14:I14) -> 915296 | K14: 460338
C15: Other assets | H15: 775000 | J15: =SUM(H15:I15) -> 775000 | K15: 2339940
C16: Restricted assets: | J16: =SUM(H16:I16) -> 0
D17: Cash | I17: 4557261 | J17: =SUM(H17:I17) -> 4557261 | K17: 3590811
D18: Investments | I18: 158334857 | J18: =SUM(H18:I18) -> 158334857 | K18: 12248459
D19: Receivables | I19: 156557 | J19: =SUM(H19:I19) -> 156557 | K19: 24899
C20: Unamortized start-up costs | I20: 1753603 | J20: =SUM(H20:I20) -> 1753603
C21: Capital assets: | J21: =SUM(H21:I21) -> 0
D22: Non-depreciable | H22: 69787539 | I22: 103348893 | J22: =SUM(H22:I22) -> 173136432 | K22: 21843992
D23: Depreciable,net | H23: 529713470 | I23: 668422936 | J23: =SUM(H23:I23) -> 1198136406 | K23: 103294800
C25: Total Assets | H25: =SUM(H7:H23) -> 915346641 | I25: =SUM(I7:I23) -> 1015262604 | J25: =SUM(J7:J23) -> 1930609245 | K25: =SUM(K7:K23) -> 228811923
A27: DEFERRED OUTFLOWS OF RESOURCES
B28: Deferred loss on bond refunding | H28: 8782907 | I28: 16251537 | J28: =SUM(H28:I28) -> 25034444 | K28: 21454
B29: Deferred outflows related to pensions | H29: 28818871 | I29: 10704356 | J29: =SUM(H29:I29) -> 39523227 | K29: 1313649
C30: Total deferred outflows of resources | H30: =SUM(H28:H29) -> 37601778 | I30: =SUM(I28:I29) -> 26955893 | J30: =SUM(J28:J29) -> 64557671 | K30: =SUM(K28:K29) -> 1335103
A33: LIABILITIES
C34: Accounts and other payables | H34: 11527783 | I34: 9718935 | J34: =SUM(H34:I34) -> 21246718 | K34: 1997015
C35: Due to component units | H35: 92392 | J35: =SUM(H35:I35) -> 92392
C36: Due to other governmental agencies | H36: 262270 | J36: =SUM(H36:I36) -> 262270 | K36: 10939
C37: Unearned revenue | H37: 210423 | I37: 10621 | J37: =SUM(H37:I37) -> 221044 | K37: 1676684
C38: Customer deposits | I38: 8700206 | J38: =SUM(H38:I38) -> 8700206 | K38: 233936
C39: Long-term liabilities:
D40: Portion due or payable within one year | H40: 33728815 | I40: 2363943 | J40: =SUM(H40:I40) -> 36092758 | K40: 3203565
D41: Portion due or payable after one year | H41: 368165568 | I41: 472682900 | J41: =SUM(H41:I41) -> 840848468 | K41: 16264846
C42: Other post-employment benefits | H42: 3280148 | J42: =SUM(H42:I42) -> 3280148 | K42: 12820
C43: Net pension liability | H43: 105952178 | I43: 28220360 | J43: =SUM(H43:I43) -> 134172538 | K43: 3791169
D45: Total Liabilities | H45: =SUM(H34:H43) -> 523219577 | I45: =SUM(I34:I43) -> 521696965 | J45: =SUM(J34:J43) -> 1044916542 | K45: =SUM(K34:K43) -> 27190974
A47: DEFERRED INFLOWS OF RESOURCES
...

Sheet Lafourche
D1: Lafourche Parish 2015 Statement of Net Assets
D2: Issued: December 31, 2015
H4: Primary Government | K4: Component Unit
H5: Governmental Activities | I5: Business-Type Activities | J5: Total | K5: Total
A6: ASSETS
C7: Cash | H7: 17684263 | J7: =SUM(H7:I7) -> 17684263 | K7: 194871525
C8: Investments | H8: 27443994 | J8: =SUM(H8:I8) -> 27443994 | K8: 21272286
C9: Receivables | H9: 1414026 | I9: 15905 | J9: =SUM(H9:I9) -> 1429931 | K9: 42193102
C10: Due from other governmental units | H10: 33698714 | J10: =SUM(H10:I10) -> 33698714
C11: Prepaids and other assets | H11: 2261412 | J11: =SUM(H11:I11) -> 2261412 | K11: 9542611
C12: Capital assets: | K12: 1401858
D13: Non-depreciable | H13: 15216799 | J13: =SUM(H13:I13) -> 15216799 | K13: 29927075
D14: Depreciable | H14: 86570530 | I14: 2477397 | J14: =SUM(H14:I14) -> 89047927 | K14: 251936313
C16: Total Assets | H16: =SUM(H7:H14) -> 184289738 | I16: =SUM(I7:I14) -> 2493302 | J16: =SUM(J7:J14) -> 186783040 | K16: =SUM(K7:K14) -> 551144770
B18: Deferred outflows of resources
C19: Deferred charge on refunding | H19: 918193 | J19: =SUM(H19:I19) -> 918193
C20: Deferred outflows- pension contributions | H20: 5797 | J20: =SUM(H20:I20) -> 5797 | K20: 905123
C21: Deferred outflows- pension other | H21: 15475 | J21: =SUM(H21:I21) -> 15475
