Workbook

Sheet Acadia
D1: Acadia PARISH POLICE JURY
D2: Capital Assets
D3: For the Year Ended December 31, 2015
G5: Beginning Balance | H5: Increases | I5: Decreases | J5: Ending Balance | K5: Cross Sectional
A7: Governmental Activities:
B8: Capital assets, not being depreciated:
C9: Land | G9: 1329008 | J9: =SUM(G9:I9) -> 1329008 | K9: =SUM(J9) -> 1329008
C10: Construction in progress | G10: 616503 | H10: 1825499 | I10: -2066442 | J10: =SUM(G10:I10) -> 375560 | K10: =SUM(J10) -> 375560
D12: Total capital assets, not being depreciated | G12: =SUM(G8:G11) -> 1945511 | H12: =SUM(H8:H11) -> 1825499 | I12: =SUM(I8:I11) -> -2066442 | J12: =SUM(J8:J11) -> 1704568
A14: Capital assets being depreciated:
B15: Buildings and improvements | G15: 23688240 | H15: 54286 | I15: -5973 | J15: =SUM(G15:I15) -> 23736553
B16: Machinery and equipment | G16: 12080397 | H16: 1258934 | I16: -1963756 | J16: =SUM(G16:I16) -> 11375575
B17: Improvements, other than buildings | G17: 773911 | J17: =SUM(G17:I17) -> 773911
B18: Infrastructure | G18: 48425719 | H18: 2244538 | I18: -94604 | J18: =SUM(G18:I18) -> 50575653
D20: Total capital assets being depreciated | G20: =SUM(G15:G19) -> 84968267 | H20: =SUM(H15:H19) -> 3557758 | I20: =SUM(I15:I19) -> -2064333 | J20: =SUM(J15:J19) -> 86461692
A22: Less accumulated depreciation for:
B23: Buildings and improvements | G23: -7150978 | H23: -448517 | I23: 5437 | J23: =SUM(G23:I23) -> -7594058 | K23: =J15+J23 -> 16142495
B24: Machinery and equipment | G24: -7128864 | H24: -746121 | I24: 1530246 | J24: =SUM(G24:I24) -> -6344739 | K24: =J16+J24 -> 5030836
B25: Improvements, other than buildings | G25: -414655 | H25: -9777 | J25: =SUM(G25:I25) -> -424432 | K25: =J17+J25 -> 349479
B26: Infrastructure | G26: -19905142 | H26: -2021531 | I26: 82459 | J26: =SUM(G26:I26) -> -21844214 | K26: =J18+J26 -> 28731439
D28: Total accumulated depreciation | G28: =SUM(G23:G27) -> -34599639 | H28: =SUM(H23:H27) -> -3225946 | I28: =SUM(I23:I27) -> 1618142 | J28: =SUM(J23:J27) -> -36207443
B30: Total capital assets being depreciated, net | G30: =G20+G28 -> 50368628 | H30: =H20+H28 -> 331812 | I30: =I20+I28 -> -446191 | J30: =J20+J28 -> 50254249
B32: Governmental activities capital assets, net | G32: =G30+G12 -> 52314139 | H32: =H30+H12 -> 2157311 | I32: =I30+I12 -> -2512633 | J32: =J30+J12 -> 51958817 | K32: =SUM(K23:K26,K9:K10) -> 51958817

Sheet Allen
D1: Acadia PARISH POLICE JURY
D2: Capital Assets
D3: 5For the Year Ended December 31, 2015
G5: Beginning Balance | H5: Increases | I5: Decreases | J5: Ending Balance | K5: Cross Sectional
A7: Governmental Activities:
B8: Capital assets, not being depreciated:
C9: Construction in progress | G9: 98703 | H9: 733474 | J9: =SUM(G9:I9) -> 832177 | K9: =J9 -> 832177
C10: Land | G10: 572300 | J10: =SUM(G10:I10) -> 572300 | K10: =J10 -> 572300
J11: =SUM(G11:I11) -> 0
D12: Total capital assets, not being depreciated | G12: =SUM(G9:G10) -> 671003 | H12: =SUM(H9:H10) -> 733474 | I12: =SUM(I9:I10) -> 0 | J12: =SUM(J9:J10) -> 1404477
A14: Capital assets being depreciated:
B15: Buildings | G15: 4595339 | J15: =SUM(G15:I15) -> 4595339
B16: Improvements, other than buildings | G16: 5855585 | J16: =SUM(G16:I16) -> 5855585
B17: Furniture and fixtures | G17: 431836 | J17: =SUM(G17:I17) -> 431836
B18: Vehicles | G18: 824249 | J18: =SUM(G18:I18) -> 824249
B19: Machinery and equipment | G19: 3482205 | H19: 229473 | I19: -37240 | J19: =SUM(G19:I19) -> 3674438
B20: Infrastructure | G20: 28219912 | J20: =SUM(G20:I20) -> 28219912
D21: Total capital assets being depreciated | G21: =SUM(G15:G20) -> 43409126 | H21: =SUM(H15:H20) -> 229473 | I21: =SUM(I15:I20) -> -37240 | J21: =SUM(J15:J20) -> 43601359
A23: Less accumulated depreciation for:
B24: Buildings | G24: 1889518 | H24: 102571 | J24: =SUM(G24:I24) -> 1992089 | K24: =SUM(J15-J24) -> 2603250
B25: Improvements, other than buildings | G25: 2376805 | H25: 171245 | J25: =SUM(G25:I25) -> 2548050 | K25: =SUM(J16-J25) -> 3307535
B26: Furniture and fixtures | G26: 343425 | H26: 33565 | J26: =SUM(G26:I26) -> 376990 | K26: =SUM(J17-J26) -> 54846
B27: Vehicles | G27: 667485 | H27: 48766 | J27: =SUM(G27:I27) -> 716251 | K27: =SUM(J18-J27) -> 107998
B28: Machinery and equipment | G28: 2382902 | H28: 203919 | I28: -22014 | J28: =SUM(G28:I28) -> 2564807 | K28: =SUM(J19-J28) -> 1109631
B29: Infrastructure | G29: 12446165 | H29: 584415 | J29: =SUM(G29:I29) -> 13030580 | K29: =SUM(J20-J29) -> 15189332
D30: Total accumulated depreciation | G30: =SUM(G24:G29) -> 20106300 | H30: =SUM(H24:H29) -> 1144481 | I30: =SUM(I24:I29) -> -22014 | J30: =SUM(J24:J29) -> 21228767
B32: Total capital assets being depreciated, net | G32: =G21-G30 -> 23302826 | H32: =H21-H30 -> -915008 | I32: =I21-I30 -> -15226 | J32: =SUM(G32:I32) -> 22372592
B35: Governmental activities capital assets, net | G35: =SUM(G32+G12) -> 23973829 | H35: =SUM(H32+H12) -> -181534 | I35: =SUM(I32+I12) -> -15226 | J35: =SUM(G35:I35) -> 23777069

Sheet Ascension
D1: ASCENSION PARISH POLICE JURY
D2: Capital Assets
D3: For the Year Ended December 31, 2015
I5: Beginning Balance | J5: Increases | K5: Decreases | L5: Ending Balance | M5: Cross Sectional
A7: Governmental Activities:
B8: Capital assets, not being depreciated:
C9: Land | I9: 17327 | L9: =SUM(I9:K9) -> 17327 | M9: =SUM(L9) -> 17327
C10: Construction in progress | I10: 15500 | J10: 23678 | K10: -10389 | L10: =SUM(I10:K10) -> 28789 | M10: =SUM(L10) -> 28789
D12: Total capital assets, not being depreciated | I12: =SUM(I8:I11) -> 32827 | J12: =SUM(J8:J11) -> 23678 | K12: =SUM(K8:K11) -> -10389 | L12: =SUM(L8:L11) -> 46116
A14: Capital assets being depreciated:
B15: Buildings | I15: 103230 | J15: 10128 | L15: =SUM(I15:K15) -> 113358
B16: Vehicles | I16: 13844 | J16: 866 | K16: -65 | L16: =SUM(I16:K16) -> 14645
B17: Equipment | I17: 13441 | J17: 2019 | K17: -34 | L17: =SUM(I17:K17) -> 15426
B18: Furniture and fixtures | I18: 1121 | J18: 405 | L18: =SUM(I18:K18) -> 1526
B19: Library materials | I19: 2478 | J19: 486 | K19: -571 | L19: =SUM(I19:K19) -> 2393
B20: Infrastructure | I20: 228723 | J20: 2695 | L20: =SUM(I20:K20) -> 231418
D22: Total capital assets being depreciated | I22: =SUM(I15:I21) -> 362837 | J22: =SUM(J15:J21) -> 16599 | K22: =SUM(K15:K21) -> -670 | L22: =SUM(L15:L20) -> 378766
A24: Less accumulated depreciation for:
B25: Buildings | I25: -23538 | J25: -3382 | L25: =SUM(I25:K25) -> -26920 | M25: =SUM(L25,L15) -> 86438
B26: Vehicles | I26: -8853 | J26: -749 | K26: 65 | L26: =SUM(I26:K26) -> -9537 | M26: =SUM(L26,L16) -> 5108
B27: Equipment | I27: -9933 | J27: -1039 | K27: 34 | L27: =SUM(I27:K27) -> -10938 | M27: =SUM(L27,L17) -> 4488
B28: Furniture and fixtures | I28: -724 | J28: -82 | L28: =SUM(I28:K28) -> -806 | M28: =SUM(L28,L18) -> 720
B29: Library materials | I29: -1555 | J29: -479 | K29: 571 | L29: =SUM(I29:K29) -> -1463 | M29: =SUM(L29,L19) -> 930
B30: Infrastructure | I30: -137255 | J30: -10648 | L30: =SUM(I30:K30) -> -147903 | M30: =SUM(L30,L20) -> 83515
D32: Total accumulated depreciation | I32: =SUM(I25:I31) -> -181858 | J32: =SUM(J25:J31) -> -16379 | K32: =SUM(K25:K31) -> 670 | L32: =SUM(L25:L31) -> -197567
B34: Total capital assets being depreciated, net | I34: =I22+I32 -> 180979 | J34: =J22+J32 -> 220 | K34: =K22+K32 -> 0 | L34: =L22+L32 -> 181199
B36: Governmental activities capital assets, net | I36: =I32+I22+I12 -> 213806 | J36: =J32+J22+J12 -> 23898 | K36: =K32+K22+K12 -> -10389 | L36: =L32+L22+L12 -> 227315 | M36: =SUM(M25:M30,M9:M10) -> 227315
I39: Beginning Balance | J39: Increases | K39: Decreases | L39: Ending Balance
A40: Business-Type Activities:
B41: Capital assets, not being depreciated:
C42: Land | I42: 670 | L42: =SUM(I42:K42) -> 670 | M42: =SUM(L42) -> 670
C43: Construction in progress | I43: 1007 | J43: 237 | K43: -259 | L43: =SUM(I43:K43) -> 985 | M43: =SUM(L43) -> 985
D45: Total capital assets, not being depreciated | I45: =SUM(I41:I44) -> 1677 | J45: =SUM(J41:J44) -> 237 | K45: =SUM(K41:K44) -> -259 | L45: =SUM(L41:L44) -> 1655
B47: Capital assets, depreciable:
C48: Sewer systems | I48: 5779 | L48: =SUM(I48:K48) -> 5779
C49: Water systems | I49: 765 | L49: =SUM(I49:K49) -> 765
C50: Machinery & Equipment | I50: 181 | J50: 84 | K50: -16 | L50: =SUM(I50:K50) -> 249
C51: Lamar Dixon Expo Center | I51: 8107 | J51: 230 | L51: =SUM(I51:K51) -> 8337
D53: Total capital assets, depreciable | I53: =SUM(I47:I51) -> 14832 | J53: =SUM(J47:J51) -> 314 | K53: =SUM(K47:K51) -> -16 | L53: =SUM(L47:L51) -> 15130
B55: Less accumulated depreciation for:
...

Sheet Assumption
D1: Assumption PARISH POLICE JURY
D2: Capital Assets
D3: For the Year Ended December 31, 2015
I5: Balance 12/31/2014 | J5: 2015 Additions | K5: 2015 Deletions | L5: 2015 Reclassifications | M5: Balance 12/31/2015 | N5: Cross Sectional
A7: Primary Government
A8: Government Activities:
B9: Land | I9: 2334193 | J9: 93366 | K9: -1600 | M9: =SUM(I9:K9) -> 2425959 | N9: =M9 -> 2425959
B10: Buildings | I10: 23864600 | J10: 85276 | K10: -1100 | L10: 25577 | M10: =SUM(I10:K10) -> 23948776 | N10: =M10 -> 23948776
B11: Improvements other than buildings | I11: 11757126 | J11: 206249 | K11: -34717 | L11: 371937 | M11: =SUM(I11:K11) -> 11928658
B12: Roads | I12: 16226076 | J12: 491740 | K12: -8001 | M12: =SUM(I12:K12) -> 16709815
B13: Bridges | I13: 588844 | M13: =SUM(I13:K13) -> 588844
B14: Equipmet and other | I14: 7306012 | J14: 692596 | K14: -275906 | M14: =SUM(I14:K14) -> 7722702
B15: Construction in progress | I15: 701781 | J15: 3421482 | K15: -80927 | L15: -397514 | M15: =SUM(I15:K15) -> 4042336
C16: Totals | I16: =SUM(I9:I15) -> 62778632 | J16: =SUM(J9:J15) -> 4990709 | K16: =SUM(K9:K15) -> -402251 | L16: =SUM(L9:L15) -> 0 | M16: =SUM(M9:M15) -> 67367090
D18: Total accumulated depreciation | I18: -20484668 | J18: -2397781 | K18: 189505 | M18: =SUM(I18:L18) -> -22692944 | N18: only shows total accumulated depreciation
A20: Governmental activities, capital assets, net | I20: =SUM(I16+I18) -> 42293964 | J20: =SUM(J16+J18) -> 2592928 | K20: =SUM(K16+K18) -> -212746 | L20: =SUM(L16+L18) -> 0 | M20: =SUM(M16+M18) -> 44674146 | N20: =SUM(N9:N17) -> 26374735

Sheet Avoyelles
D1: AVOYELLES PARISH POLICE JURY
D2: Capital Assets
D3: For the Year Ended December 31, 2015
G5: Balance 01/01/14 | H5: Additions | I5: Decreases | J5: Balance 12/31/14 | K5: Cross Sectional
A7: Governmental Activities:
B8: Capital assets, not being depreciated:
C9: Land | G9: 590548 | J9: =SUM(G9:I9) -> 590548 | K9: =SUM(J9) -> 590548
C10: Construction in progress | H10: 1185398 | J10: =SUM(G10:I10) -> 1185398 | K10: =SUM(J10) -> 1185398
D12: Total capital assets, not being depreciated | G12: =SUM(G8:G11) -> 590548 | H12: =SUM(H8:H11) -> 1185398 | I12: =SUM(I8:I11) -> 0 | J12: =SUM(J8:J11) -> 1775946
A14: Capital assets being depreciated:
B15: Buildings and improvements | G15: 5369883 | J15: =SUM(G15:I15) -> 5369883
B16: Equipment, furniture and fixtures | G16: 624821 | H16: 22110 | I16: -3717 | J16: =SUM(G16:I16) -> 643214
B17: Infrastructure | G17: 78140 | J17: =SUM(G17:I17) -> 78140
B18: Heavy equipment | G18: 3436008 | H18: 81907 | I18: -35726 | J18: =SUM(G18:I18) -> 3482189
D20: Total capital assets being depreciated | G20: =SUM(G18+G17+G16+G15+G12) -> 10099400 | H20: =SUM(H18+H17+H16+H15+H12) -> 1289415 | I20: =SUM(I18+I17+I16+I15+I12) -> -39443 | J20: =SUM(J18+J17+J16+J15+J12) -> 11349372
A22: Less accumulated depreciation for:
B23: Buildings and improvements | G23: 1637135 | H23: 200275 | J23: =SUM(G23:I23) -> 1837410 | K23: =J15-J23 -> 3532473
B24: Equipment, furniture and fixtures | G24: 550732 | H24: 21545 | I24: -3717 | J24: =SUM(G24:I24) -> 568560 | K24: =J16-J24 -> 74654
B25: Infrastructure | G25: 40698 | H25: 6213 | J25: =SUM(G25:I25) -> 46911 | K25: =J17-J25 -> 31229
B26: Heavy equipment | G26: 2680975 | H26: 143981 | I26: -22923 | J26: =SUM(G26:I26) -> 2802033 | K26: =J18-J26 -> 680156
D28: Total accumulated depreciation | G28: =SUM(G23:G26) -> 4909540 | H28: =SUM(H23:H27) -> 372014 | I28: =SUM(I23:I27) -> -26640 | J28: =SUM(J23:J27) -> 5254914
B30: Governmental activities capital assets, net | G30: =SUM(G20-G28) -> 5189860 | H30: =SUM(H20-H28) -> 917401 | I30: =SUM(I20-I28) -> -12803 | J30: =SUM(J20-J28) -> 6094458 | K30: =SUM(K23:K26,K9:K10) -> 6094458

Sheet Beauregard
D1: BEAUREGARD PARISH POLICE JURY
D2: Capital Assets
D3: For the Year Ended December 31, 2015
I5: Beginning Balance | J5: Additions | K5: Deletions | L5: Transfers | M5: Ending Balance | N5: Cross Sectional
A7: Government Activities:
A8: Capital assets, not being depreciated:
B9: Land | I9: 688379 | J9: 10400 | M9: =SUM(I9:L9) -> 698779 | N9: =SUM(M9) -> 698779
B10: Construction in progress | I10: 2175229 | J10: 6501660 | L10: -3036656 | M10: =SUM(I10:L10) -> 5640233 | N10: =SUM(M10) -> 5640233
C11: Total assets not being depreciated | I11: =SUM(I9:I10) -> 2863608 | J11: =SUM(J9:J10) -> 6512060 | K11: =SUM(K9:K10) -> 0 | L11: =SUM(L9:L10) -> -3036656 | M11: =SUM(M9:M10) -> 6339012
A13: Capital assets being depreciated:
B14: Buildings and improvements | I14: 17820827 | J14: 9759 | L14: 3036656 | M14: =SUM(I14:L14) -> 20867242
B15: Infrastructure | I15: 42862850 | M15: =SUM(I15:L15) -> 42862850
B16: Furniture and equipment | I16: 12511676 | J16: 441044 | M16: =SUM(I16:L16) -> 12952720
C17: Total capital assets being depreciated | I17: =SUM(I14:I16) -> 73195353 | J17: =SUM(J14:J16) -> 450803 | K17: =SUM(K14:K16) -> 0 | L17: =SUM(L14:L16) -> 3036656 | M17: =SUM(M14:M16) -> 76682812
A19: Less accumulated depreciation for:
B20: Buildings and improvements | I20: -8634982 | J20: -563822 | M20: =SUM(I20:L20) -> -9198804 | N20: =SUM(M20,M14) -> 11668438
B21: Infrastructure | I21: -27471416 | J21: -1115249 | M21: =SUM(I21:L21) -> -28586665 | N21: =SUM(M21,M15) -> 14276185
B22: Furniture and equipment | I22: -8415337 | J22: -840011 | M22: =SUM(I22:L22) -> -9255348 | N22: =M16+M22 -> 3697372
C23: Total accumulated depreciation | I23: =SUM(I20:I22) -> -44521735 | J23: =SUM(J20:J22) -> -2519082 | K23: =SUM(K20:K22) -> 0 | L23: =SUM(L20:L22) -> 0 | M23: =SUM(M20:M22) -> -47040817
B24: Total capital assets being depreciated, net | I24: =I23+I17 -> 28673618 | J24: =J23+J17 -> -2068279 | K24: =K23+K17 -> 0 | L24: =L23+L17 -> 3036656 | M24: =M23+M17 -> 29641995
B25: Governmental activities capital assets, net | I25: =I11+I24 -> 31537226 | J25: =J11+J24 -> 4443781 | K25: =K11+K24 -> 0 | L25: =L11+L24 -> 0 | M25: =M11+M24 -> 35981007 | N25: =SUM(N20:N22,N9:N10) -> 35981007

Sheet Bienville
D1: BIENVILLE PARISH POLICE JURY
D2: Capital Assets
D3: For the Year Ended December 31, 2015
I5: Beginning Balance | J5: Increases | K5: Decreases | L5: Ending Balance | M5: Cross Sectional
A7: Governmental Activities:
B8: Capital assets, not being depreciated:
C9: Land | I9: 660250 | L9: =SUM(I9:K9) -> 660250 | M9: =SUM(L9) -> 660250
D11: Total capital assets, not being depreciated | I11: =SUM(I8:I9) -> 660250 | J11: =SUM(J8:J9) -> 0 | K11: =SUM(K8:K9) -> 0 | L11: =SUM(L8:L9) -> 660250
M12: =SUM(L12) -> 0
A13: Capital assets being depreciated: | M13: =SUM(L13) -> 0
B14: Infrastructure | M14: =SUM(L14) -> 0
C15: Roads | I15: 22192672 | J15: 1170771 | L15: =SUM(I15:K15) -> 23363443
C16: Bridges | I16: 2537698 | L16: =SUM(I16:K16) -> 2537698
B17: Buildings and Improvements | I17: 16851833 | J17: 140528 | L17: =SUM(I17:K17) -> 16992361
B18: Office furniture and equipment | I18: 541664 | L18: =SUM(I18:K18) -> 541664
B19: Heavy Equipment | I19: 1773268 | J19: 285150 | K19: -196548 | L19: =SUM(I19:K19) -> 1861870
B20: Vehicles | I20: 1301447 | L20: =SUM(I20:K20) -> 1301447
B21: Miscellaneous equipment | I21: 514738 | J21: 2950 | L21: =SUM(I21:K21) -> 517688
D23: Total capital assets being depreciated | I23: =SUM(I14:I21) -> 45713320 | J23: =SUM(J14:J21) -> 1599399 | K23: =SUM(K14:K21) -> -196548 | L23: =SUM(L14:L21) -> 47116171
A25: Less accumulated depreciation for:
B26: Infrastructure
C27: Roads | I27: -16676946 | J27: -1106600 | L27: =SUM(I27:K27) -> -17783546 | M27: =SUM(L27,L15) -> 5579897
C28: Bridges | I28: -1358294 | J28: -39480 | L28: =SUM(I28:K28) -> -1397774 | M28: =SUM(L28,L16) -> 1139924
B29: Buildings and Improvements | I29: -3296507 | J29: -369027 | L29: =SUM(I29:K29) -> -3665534 | M29: =SUM(L29,L17) -> 13326827
B30: Office furniture and equipment | I30: -230177 | J30: -103829 | L30: =SUM(I30:K30) -> -334006 | M30: =SUM(L30,L18) -> 207658
B31: Heavy Equipment | I31: -1207999 | J31: -126234 | K31: 196548 | L31: =SUM(I31:K31) -> -1137685 | M31: =SUM(L31,L19) -> 724185
B32: Vehicles | I32: -702086 | J32: -85483 | L32: =SUM(I32:K32) -> -787569 | M32: =SUM(L32,L20) -> 513878
B33: Miscellaneous equipment | I33: -388568 | J33: -19870 | L33: =SUM(I33:K33) -> -408438 | M33: =SUM(L33,L21) -> 109250
M34: =SUM(L34,L22) -> 0
D35: Total accumulated depreciation | I35: =SUM(I26:I33) -> -23860577 | J35: =SUM(J26:J33) -> -1850523 | K35: =SUM(K26:K33) -> 196548 | L35: =SUM(L27:L33) -> -25514552
B37: Total capital assets being depreciated, net | I37: =I23+I35 -> 21852743 | J37: =J23+J35 -> -251124 | K37: =K23+K35 -> 0 | L37: =L23+L35 -> 21601619
M38: =SUM(L38,L26) -> 0
B39: Total capital assets (net) | I39: =I35+I23+I11 -> 22512993 | J39: =J35+J23+J11 -> -251124 | K39: =K35+K23+K11 -> 0 | L39: =L35+L23+L11 -> 22261869 | M39: =SUM(M9:M33) -> 22261869

Sheet Bossier
D1: BOSSIER PARISH POLICE JURY
D2: Capital Assets
D3: For the Year Ended December 31, 2015
I5: Beginning Balance | J5: Transfers | K5: Additions | L5: Deletions | M5: Ending Balance | N5: Cross Sectional
A7: Primary Government
A8: Government Activities:
A9: Capital assets, not being depreciated:
B10: Land | I10: 12972258 | K10: 959710 | L10: -18021 | M10: =SUM(I10:L10) -> 13913947 | N10: =SUM(M10) -> 13913947
B11: Construction in progress | I11: 6272099 | J11: -2635042 | K11: 3588162 | M11: =SUM(I11:L11) -> 7225219 | N11: =SUM(M11) -> 7225219
C12: Total assets not being depreciated | I12: =SUM(I10:I11) -> 19244357 | J12: =SUM(J10:J11) -> -2635042 | K12: =SUM(K10:K11) -> 4547872 | L12: =SUM(L10:L11) -> -18021 | M12: =SUM(M10:M11) -> 21139166
A14: Capital assets being depreciated:
B15: Buildings and improvements | I15: 108272538 | J15: 2260863 | K15: 1606894 | M15: =SUM(I15:L15) -> 112140295
B16: Infrastructure | I16: 231447108 | J16: 374179 | K16: 4838518 | M16: =SUM(I16:L16) -> 236659805
B17: Furniture, equipment and vehicles | I17: 10918840 | J17: -27873 | K17: 598807 | L17: -9900 | M17: =SUM(I17:L17) -> 11479874
B18: Library books and information material | I18: 5191486 | K18: 700039 | M18: =SUM(I18:L18) -> 5891525
C19: Total capital assets being depreciated | I19: =SUM(I15:I18) -> 355829972 | J19: =SUM(J15:J18) -> 2607169 | K19: =SUM(K15:K18) -> 7744258 | L19: =SUM(L15:L18) -> -9900 | M19: =SUM(M15:M18) -> 366171499
A21: Less accumulated depreciation for:
B22: Buildings and improvements | I22: -26669928 | K22: -2910297 | M22: =SUM(I22:L22) -> -29580225 | N22: =SUM(M22,M15) -> 82560070
B23: Infrastructure | I23: -52405834 | K23: -5850138 | M23: =SUM(I23:L23) -> -58255972 | N23: =SUM(M23,M16) -> 178403833
B24: Furniture, equipment and vehicles | I24: -6891385 | J24: 27873 | K24: -731836 | L24: 9900 | M24: =SUM(I24:L24) -> -7585448 | N24: =SUM(M24,M17) -> 3894426
B25: Library books and information material | I25: -3981082 | K25: -445313 | M25: =SUM(I25:L25) -> -4426395 | N25: =M18+M25 -> 1465130
C26: Total accumulated depreciation | I26: =SUM(I22:I25) -> -89948229 | J26: =SUM(J22:J25) -> 27873 | K26: =SUM(K22:K25) -> -9937584 | L26: =SUM(L22:L25) -> 9900 | M26: =SUM(M22:M25) -> -99848040
B28: Total capital assets being depreciated, net | I28: =I26+I19 -> 265881743 | J28: =J26+J19 -> 2635042 | K28: =K26+K19 -> -2193326 | L28: =L26+L19 -> 0 | M28: =M26+M19 -> 266323459
B30: Governmental activities capital assets, net | I30: =I12+I28 -> 285126100 | J30: =J12+J28 -> 0 | K30: =K12+K28 -> 2354546 | L30: =L12+L28 -> -18021 | M30: =M12+M28 -> 287462625 | N30: =SUM(N22:N25,N10:N11) -> 287462625
I33: Beginning Balance | J33: Transfers | K33: Additions | L33: Deletions | M33: Ending Balance
A35: Business-type Activities:
A36: Capital assets not being depreciated:
B37: Land | I37: 1411812 | K37: 46557 | M37: =SUM(I37:L37) -> 1458369 | N37: =SUM(M37) -> 1458369
B38: Goodwill | I38: 1226000 | M38: =SUM(I38:L38) -> 1226000 | N38: =SUM(M38) -> 1226000
B39: Construction in progress | I39: 13631606 | K39: 19762105 | M39: =SUM(I39:L39) -> 33393711 | N39: =SUM(M39) -> 33393711
C40: Total assets not being depreciated | I40: =SUM(I37:I39) -> 16269418 | J40: =SUM(J37:J39) -> 0 | K40: =SUM(K37:K39) -> 19808662 | L40: =SUM(L37:L39) -> 0 | M40: =SUM(M37:M39) -> 36078080
A42: Capital assets being depreciated:
B43: Furniture, equipment and vehicles | I43: 197481 | J43: 27873 | K43: 176236 | M43: =SUM(I43:L43) -> 401590
B44: Buildings and improvements | I44: 4953684 | M44: =SUM(I44:L44) -> 4953684
C45: Total capital assets being depreciated | I45: =SUM(I43:I44) -> 5151165 | J45: =SUM(J43:J44) -> 27873 | K45: =SUM(K43:K44) -> 176236 | L45: =SUM(L43:L44) -> 0 | M45: =SUM(M43:M44) -> 5355274
A47: Less accumulated depreciation for:
B48: Furniture, equipment and vehicles | I48: -5355 | J48: -27873 | K48: -19179 | L48: 0 | M48: =SUM(I48:L48) -> -52407 | N48: =SUM(M48,M43) -> 349183
B49: Buildings and improvements | I49: -535885 | K49: -209007 | L49: 0 | M49: =SUM(I49:L49) -> -744892 | N49: =SUM(M49,M44) -> 4208792
C50: Total accumulated depreciation | I50: =SUM(I48:I49) -> -541240 | J50: =SUM(J48:J49) -> -27873 | K50: =SUM(K48:K49) -> -228186 | L50: =SUM(L48:L49) -> 0 | M50: =SUM(M48:M49) -> -797299
B52: Total capital assets being depreciated, net | I52: =SUM(I50,I45) -> 4609925 | J52: =SUM(J50,J45) -> 0 | K52: =SUM(K50,K45) -> -51950 | L52: =SUM(L50,L45) -> 0 | M52: =SUM(M50,M45) -> 4557975
...

Sheet Caddo
D1: CADDO PARISH POLICE JURY
D2: Capital Assets
D3: For the Year Ended December 31, 2015
I5: Balance December 31, 2014 | J5: Prior Period Adjustment | K5: Additions | L5: Reductions | M5: Balance December 31, 2015 | N5: Cross Sectional
A7: Government Activities:
A8: Capital assets, not being depreciated:
B9: Land and land improvements | I9: 14578409 | J9: -5261444 | K9: 4758 | M9: =SUM(I9:L9) -> 9321723 | N9: =SUM(M9) -> 9321723
B10: Construction in progress | I10: 5935905 | J10: -4879118 | K10: 694345 | L10: -1372146 | M10: =SUM(I10:L10) -> 378986 | N10: =M10 -> 378986
C11: Total capital assets not being depreciated | I11: =SUM(I9:I10) -> 20514314 | J11: =SUM(J9:J10) -> -10140562 | L11: =SUM(L9:L10) -> -1372146 | M11: =SUM(M9:M10) -> 9700709
A13: Capital assets being depreciated:
B14: Buildings and structures | I14: 101006420 | J14: -27419780 | K14: 1461633 | L14: 1935739 | M14: =SUM(I14:L14) -> 76984012
B15: Equipment and vehicles | I15: 40622356 | J15: -20482923 | K15: 1027653 | L15: -742750 | M15: =SUM(I15:L15) -> 20424336
B16: Infrastructure | I16: 389831937 | K16: 4640426 | L16: -349409 | M16: =SUM(I16:L16) -> 394122954
C17: Total capital assets being depreciated | I17: =SUM(I14:I16) -> 531460713 | J17: =SUM(J14:J16) -> -47902703 | L17: =SUM(L14:L16) -> 843580 | M17: =SUM(M14:M16) -> 491531302
A19: Less accumulated depreciation for:
B20: Buildings and structures | I20: -39428268 | J20: 8104099 | K20: -1887048 | L20: 354964 | M20: =SUM(I20:L20) -> -32856253 | N20: =SUM(M20,M14) -> 44127759
B21: Equipment and vehicles | I21: -28334316 | J21: 16004144 | K21: -1443065 | L21: 741472 | M21: =SUM(I21:L21) -> -13031765 | N21: =SUM(M21,M15) -> 7392571
B22: Infrastructure | I22: -280269332 | K22: -9895425 | L22: 313982 | M22: =SUM(I22:L22) -> -289850775 | N22: =M16+M22 -> 104272179
C23: Total accumulated depreciation | I23: =SUM(I20:I22) -> -348031916 | J23: =SUM(J20:J22) -> 24108243 | L23: =SUM(L20:L22) -> 1410418 | M23: =SUM(M20:M22) -> -335738793
B24: Total capital assets being depreciated, net | I24: =I23+I17 -> 183428797 | J24: =J23+J17 -> -23794460 | L24: =L23+L17 -> 2253998 | M24: =M23+M17 -> 155792509
B25: Capital assets, net | I25: =I11+I24 -> 203943111 | J25: =J11+J24 -> -33935022 | L25: =L11+L24 -> 881852 | M25: =M11+M24 -> 165493218 | N25: =SUM(N20:N22,N9:N10) -> 165493218

Sheet Calcasieu
D1: CALCASIEU PARISH POLICE JURY
D2: Capital Assets
D3: For the Year Ended December 31, 2015
I5: Beginning Balance | J5: Increases | K5: Decreases | L5: Ending Balance | M5: Cross Sectional
A7: Governmental Activities:
B8: Capital assets, not being depreciated:
C9: Land and Right of Ways | I9: 18022266 | J9: 1631096 | L9: =SUM(I9:K9) -> 19653362 | M9: =SUM(L9) -> 19653362
C10: Construction in progress | I10: 7601504 | J10: 11679044 | K10: -6386293 | L10: =SUM(I10:K10) -> 12894255 | M10: =SUM(L10) -> 12894255
C11: Roads | I11: 395417424 | L11: =SUM(I11:K11) -> 395417424 | M11: =SUM(L11) -> 395417424
D13: Total capital assets, not being depreciated | I13: =SUM(I8:I11) -> 421041194 | J13: =SUM(J8:J11) -> 13310140 | K13: =SUM(K8:K11) -> -6386293 | L13: =SUM(L8:L11) -> 427965041
A15: Capital assets being depreciated:
B16: Buildings and Improvements | I16: 133128418 | J16: 8180797 | L16: =SUM(I16:K16) -> 141309215
B17: Machinery and Equipment | I17: 34157047 | J17: 3839777 | K17: -2582340 | L17: =SUM(I17:K17) -> 35414484
B18: Bridges ++ | I18: 14332967 | L18: =SUM(I18:K18) -> 14332967
D20: Total capital assets being depreciated | I20: =SUM(I16:I19) -> 181618432 | J20: =SUM(J16:J19) -> 12020574 | K20: =SUM(K16:K19) -> -2582340 | L20: =SUM(L16:L18) -> 191056666
A22: Less accumulated depreciation for:
B23: Buildings and Improvements | I23: -58486576 | J23: -3664784 | L23: =SUM(I23:K23) -> -62151360 | M23: =SUM(L23,L16) -> 79157855
B24: Machinery and Equipment | I24: -20960602 | J24: -2964284 | K24: 2447325 | L24: =SUM(I24:K24) -> -21477561 | M24: =SUM(L24,L17) -> 13936923
B25: Bridges ++ | I25: -4227106 | J25: -328214 | L25: =SUM(I25:K25) -> -4555320 | M25: =SUM(L25,L18) -> 9777647
D27: Total accumulated depreciation | I27: =SUM(I23:I26) -> -83674284 | J27: =SUM(J23:J26) -> -6957282 | K27: =SUM(K23:K26) -> 2447325 | L27: =SUM(L23:L26) -> -88184241
B29: Total capital assets being depreciated, net | I29: =I20+I27 -> 97944148 | J29: =J20+J27 -> 5063292 | K29: =K20+K27 -> -135015 | L29: =L20+L27 -> 102872425
B31: Governmental activities capital assets, net | I31: =I27+I20+I13 -> 518985342 | J31: =J27+J20+J13 -> 18373432 | K31: =K27+K20+K13 -> -6521308 | L31: =L27+L20+L13 -> 530837466 | M31: =SUM(L31, L22) -> 530837466
I33: Beginning Balance | J33: Increases | K33: Decreases | L33: Ending Balance
A34: Business-Type Activities:
B35: Capital assets, not being depreciated:
C36: Land and Right of Ways | I36: 227920 | L36: =SUM(I36:K36) -> 227920 | M36: =SUM(L36) -> 227920
C37: Construction in progress | I37: 24850 | K37: -24850 | L37: =SUM(I37:K37) -> 0 | M37: =SUM(L37) -> 0
D39: Total capital assets, not being depreciated | I39: =SUM(I35:I38) -> 252770 | J39: =SUM(J35:J38) -> 0 | K39: =SUM(K35:K38) -> -24850 | L39: =SUM(L35:L38) -> 227920
B41: Capital assets, depreciable:
C42: Non-Building Improvements | I42: 11861515 | J42: 490556 | L42: =SUM(I42:K42) -> 12352071 | M42: The numbers are wrong in the source audit
C43: Building and Improvements | I43: 152215 | J43: 7700 | L43: =SUM(I43:K43) -> 159915
C44: Infrastructure | I44: 3862766 | J44: 173256 | K44: -17857 | L44: =SUM(I44:K44) -> 4018165
C45: Machinery and Equipment | I45: 281112 | J45: 17243 | K45: -45239 | L45: =SUM(I45:K45) -> 253116
D47: Total capital assets, depreciable | I47: =SUM(I41:I45) -> 16157608 | J47: =SUM(J41:J45) -> 688755 | K47: =SUM(K41:K45) -> -63096 | L47: =SUM(L41:L45) -> 16783267
B49: Less accumulated depreciation for:
C50: Non-Building Improvements | I50: -4427162 | J50: -345923 | L50: =SUM(I50:K50) -> -4773085 | M50: =SUM(L50,L42) -> 7578986
C51: Building and Improvements | I51: -134097 | J51: -2184 | L51: =SUM(I51:K51) -> -136281 | M51: =SUM(L51,L43) -> 23634
C52: Infrastructure | I52: -1899622 | J52: -132613 | K52: 17857 | L52: =SUM(I52:K52) -> -2014378 | M52: =SUM(L52,L44) -> 2003787
C53: Machinery and Equipment | I53: -212606 | J53: -12061 | K53: 45239 | L53: =SUM(I53:K53) -> -179428 | M53: =SUM(L53,L45) -> 73688
D55: Total accumulated depreciation | I55: =SUM(I50:I53) -> -6673487 | J55: =SUM(J50:J53) -> -492781 | K55: =SUM(K50:K53) -> 63096 | L55: =SUM(L50:L53) -> -7103172
...

Sheet Caldwell
D1: CALDWELL PARISH POLICE JURY
D2: Capital Assets
D3: For the Year Ended December 31, 2015
I5: Beginning Balance | J5: Transfers | K5: Additions | L5: Deletions | M5: Ending Balance | N5: Cross Sectional
A7: Primary Government
A8: Government Activities:
A9: Capital assets, not being depreciated:
B10: Land | I10: 420095 | M10: =SUM(I10:L10) -> 420095 | N10: =SUM(M10) -> 420095
B11: Construction in progress | I11: 10535878 | K11: 2280297 | L11: -64210 | M11: =SUM(I11:L11) -> 12751965 | N11: =SUM(M11) -> 12751965
C12: Total assets not being depreciated | I12: =SUM(I10:I11) -> 10955973 | J12: =SUM(J10:J11) -> 0 | K12: =SUM(K10:K11) -> 2280297 | L12: =SUM(L10:L11) -> -64210 | M12: =SUM(M10:M11) -> 13172060
A14: Capital assets being depreciated:
B15: Infrastructure
C16: Roads | I16: 47897858 | K16: 752065 | M16: =SUM(I16:L16) -> 48649923
C17: Bridges | I17: 642997 | K17: 20000 | M17: =SUM(I17:L17) -> 662997
B18: Buildings and improvements | I18: 2983905 | K18: 100141 | M18: =SUM(I18:L18) -> 3084046
B19: Land improvements | I19: 716214 | M19: =SUM(I19:L19) -> 716214
B20: Heavy equipment | I20: 1497882 | K20: 45000 | M20: =SUM(I20:L20) -> 1542882
B21: Vehicles | I21: 1187227 | M21: =SUM(I21:L21) -> 1187227
B22: Public works equipment | I22: 285706 | K22: 3767 | M22: =SUM(I22:L22) -> 289473
B23: Office furniture and equipment | I23: 681048 | M23: =SUM(I23:L23) -> 681048
C24: Total capital assets being depreciated | I24: =SUM(I16:I23) -> 55892837 | J24: =SUM(J16:J23) -> 0 | K24: =SUM(K16:K23) -> 920973 | L24: =SUM(L16:L23) -> 0 | M24: =SUM(M16:M23) -> 56813810
A26: Less accumulated depreciation for:
B27: Infrastructure
C28: Roads | I28: -46301262 | K28: -147599 | M28: =SUM(I28:L28) -> -46448861 | N28: =SUM(M28,M16) -> 2201062
C29: Bridges | I29: -642110 | K29: -1554 | M29: =SUM(I29:L29) -> -643664 | N29: =SUM(M29,M17) -> 19333
B30: Buildings and improvements | I30: -2619326 | K30: -23570 | M30: =SUM(I30:L30) -> -2642896 | N30: =SUM(M30,M18) -> 441150
B31: Land improvements | I31: -217293 | K31: -30808 | M31: =SUM(I31:L31) -> -248101 | N31: =SUM(M31,M19) -> 468113
B32: Heavy equipment | I32: -1223555 | K32: -53443 | M32: =SUM(I32:L32) -> -1276998 | N32: =SUM(M32,M20) -> 265884
B33: Vehicles | I33: -1114933 | K33: -30076 | M33: =SUM(I33:L33) -> -1145009 | N33: =SUM(M33,M21) -> 42218
B34: Public works equipment | I34: -129191 | K34: -24085 | M34: =SUM(I34:L34) -> -153276 | N34: =SUM(M34,M22) -> 136197
B35: Office furniture and equipment | I35: -492028 | K35: -48690 | M35: =SUM(I35:L35) -> -540718 | N35: =SUM(M35,M23) -> 140330
C36: Total accumulated depreciation | I36: =SUM(I27:I35) -> -52739698 | J36: =SUM(J27:J35) -> 0 | K36: =SUM(K27:K35) -> -359825 | L36: =SUM(L27:L35) -> 0 | M36: =SUM(M27:M35) -> -53099523
B38: Total capital assets being depreciated, net | I38: =I36+I24 -> 3153139 | J38: =J36+J24 -> 0 | K38: =K36+K24 -> 561148 | L38: =L36+L24 -> 0 | M38: =M36+M24 -> 3714287
B40: Governmental activities capital assets, net | I40: =I12+I38 -> 14109112 | J40: =J12+J38 -> 0 | K40: =K12+K38 -> 2841445 | L40: =L12+L38 -> -64210 | M40: =M12+M38 -> 16886347 | N40: =SUM(N27:N35,N10:N11) -> 16886347

Sheet Cameron
D1: Cameron PARISH POLICE JURY
D2: Capital Assets
D3: For the Year Ended December 31, 2015
I5: Beginning Balance | J5: Additions | K5: Deletions | L5: Ending Balance | M5: Cross Sectional
A7: Primary Government
A8: Government Activities:
B10: Land | L10: =SUM(I10:K10) -> 0 | M10: =SUM(L10) -> 0
B11: Construction in progress | L11: =SUM(I11:K11) -> 0 | M11: =SUM(L11) -> 0
B12: Building and improvements | L12: =SUM(I12:K12) -> 0
B13: Books and videos | L13: =SUM(I13:K13) -> 0
B14: Equipment and furniture | L14: =SUM(I14:K14) -> 0
B15: Infrastructure | L15: =SUM(I15:K15) -> 0
C16: Total capital assets at historical costs | I16: =SUM(I10:I15) -> 0 | J16: =SUM(J10:J15) -> 0 | K16: =SUM(K10:K15) -> 0 | L16: =SUM(L10:L15) -> 0
A18: Capital Assets being Depreciated
B19: Building and improvements | L19: =SUM(I19:K19) -> 0
B20: Books and videos | L20: =SUM(I20:K20) -> 0
B21: Equipment and furniture | L21: =SUM(I21:K21) -> 0
B22: Infrastructure | L22: =SUM(I22:K22) -> 0
C23: Total Capital being Depreciated | I23: =SUM(I17:I22) -> 0 | J23: =SUM(J17:J22) -> 0 | K23: =SUM(K17:K22) -> 0 | L23: =SUM(L17:L22) -> 0 | O23: =SUM(O19:O22) -> 0
L24: =SUM(L18:L23) -> 0
A25: Accumulated Depreciation | L25: =SUM(L19:L24) -> 0
B26: Building and improvements | L26: =SUM(L20:L25) -> 0 | M26: =L19+L26 -> 0
B27: Books and videos | L27: =SUM(L21:L26) -> 0 | M27: =L20+L27 -> 0
B28: Equipment and furniture | L28: =SUM(L22:L27) -> 0 | M28: =L21+L28 -> 0
B29: Infrastructure | L29: =SUM(L23:L28) -> 0 | M29: =L22+L29 -> 0
C30: Total Accumulated Depreciation | I30: =SUM(I25:I29) -> 0 | J30: =SUM(J25:J29) -> 0 | K30: =SUM(K25:K29) -> 0 | L30: =SUM(L25:L29) -> 0
C32: Less accumulated depreciation | L32: =SUM(I32:K32) -> 0
C34: Total capital assets, net | I34: =SUM(I16,I32) -> 0 | J34: =SUM(J16,J32) -> 0 | K34: =K16-K32 -> 0 | L34: =SUM(L16,L32) -> 0 | M34: =SUM(M10:M29) -> 0

Sheet Catahoula
D1: CATAHOULA PARISH POLICE JURY
D2: Capital Assets
D3: For the Year Ended December 31, 2015
I5: Beginning Balance | J5: Adjustments | K5: Additions | L5: Deletions | M5: Ending Balance | N5: Cross Sectional
A7: Primary Government
A8: Government Activities:
A9: Capital assets, not being depreciated:
B10: Land | I10: 112200 | M10: =SUM(I10:L10) -> 112200 | N10: =SUM(M10) -> 112200
B11: Construction in progress | I11: 33780 | K11: 1386372 | M11: =SUM(I11:L11) -> 1420152 | N11: =SUM(M11) -> 1420152
C12: Total assets not being depreciated | I12: =SUM(I10:I11) -> 145980 | J12: =SUM(J10:J11) -> 0 | K12: =SUM(K10:K11) -> 1386372 | L12: =SUM(L10:L11) -> 0 | M12: =SUM(M10:M11) -> 1532352
A14: Capital assets being depreciated:
B15: Infrastructure-roads and bridges | I15: 11514532 | K15: 60445 | M15: =SUM(I15:L15) -> 11574977
B16: Buildings | I16: 2996844 | K16: 6778 | M16: =SUM(I16:L16) -> 3003622
B17: Improvements | I17: 1543519 | K17: 12840 | M17: =SUM(I17:L17) -> 1556359
B18: Equipment | I18: 1416128 | K18: 14033 | M18: =SUM(I18:L18) -> 1430161
B19: Heavy equipment | I19: 991480 | M19: =SUM(I19:L19) -> 991480
B20: Vehicles | I20: 549424 | K20: 29606 | M20: =SUM(I20:L20) -> 579030
B21: Books and periodicals | I21: 710868 | K21: 34889 | L21: -21046 | M21: =SUM(I21:L21) -> 724711
C22: Total capital assets being depreciated | I22: =SUM(I15:I21) -> 19722795 | J22: =SUM(J15:J21) -> 0 | K22: =SUM(K15:K21) -> 158591 | L22: =SUM(L15:L21) -> -21046 | M22: =SUM(M15:M21) -> 19860340
A24: Less accumulated depreciation for:
B25: Infrastructure - roads and bridges | I25: 8482039 | K25: 112330 | M25: =SUM(I25:L25) -> 8594369 | N25: =M15-M25 -> 2980608
B26: Buildings | I26: 2571739 | K26: 18632 | M26: =SUM(I26:L26) -> 2590371 | N26: =M16-M26 -> 413251
B27: Improvements | I27: 262987 | K27: 61740 | M27: =SUM(I27:L27) -> 324727 | N27: =M17-M27 -> 1231632
B28: Equipment | I28: 1164822 | K28: 52303 | M28: =SUM(I28:L28) -> 1217125 | N28: =M18-M28 -> 213036
B29: Heavy equipment | I29: 681467 | K29: 54023 | M29: =SUM(I29:L29) -> 735490 | N29: =M19-M29 -> 255990
B30: Vehicles | I30: 347870 | K30: 42525 | M30: =SUM(I30:L30) -> 390395 | N30: =M20-M30 -> 188635
B31: Books and periodicals | I31: 626802 | K31: 33929 | L31: -21046 | M31: =SUM(I31:L31) -> 639685 | N31: =M21-M31 -> 85026
C32: Total accumulated depreciation | I32: =SUM(I25:I31) -> 14137726 | J32: =SUM(J25:J31) -> 0 | K32: =SUM(K25:K31) -> 375482 | L32: =SUM(L25:L31) -> -21046 | M32: =SUM(M25:M31) -> 14492162
B34: Total capital assets being depreciated, net | I34: =I22-I32 -> 5585069 | J34: =J22-J32 -> 0 | K34: =K22-K32 -> -216891 | L34: =L22-L32 -> 0 | M34: =M22-M32 -> 5368178
B36: Governmental activities capital assets, net | I36: =I12+I34 -> 5731049 | J36: =J12+J34 -> 0 | K36: =K12+K34 -> 1169481 | L36: =L12+L34 -> 0 | M36: =M12+M34 -> 6900530 | N36: =SUM(N25:N31, N10:N12) -> 6900530

Sheet Claiborne
D1: CLAIBORNE PARISH POLICE JURY
D2: Capital Assets
D3: For the Year Ended December 31, 2015
I5: Beginning Balance | J5: Transfers | K5: Additions | L5: Deletions | M5: Ending Balance | N5: Cross Sectional
A7: Primary Government
A8: Government Activities:
A9: Capital assets, not being depreciated:
B10: Land
C11: Police Jury | I11: 220570 | M11: =SUM(I11:L11) -> 220570 | N11: =SUM(M11) -> 220570
C12: Library | I12: 3580 | M12: =SUM(I12:L12) -> 3580 | N12: =SUM(M12) -> 3580
C13: Office of Community Service | I13: 30000 | M13: =SUM(I13:L13) -> 30000 | N13: =SUM(M13) -> 30000
C14: Adjudicated property | I14: 16638 | K14: 3729 | L14: -667 | M14: =SUM(I14:L14) -> 19700 | N14: =SUM(M14) -> 19700
B15: Construction in progress | I15: 43262 | K15: 318842 | L15: -52985 | M15: =SUM(I15:L15) -> 309119 | N15: =SUM(M15) -> 309119
C16: Total assets not being depreciated | I16: =SUM(I10:I15) -> 314050 | J16: =SUM(J10:J15) -> 0 | K16: =SUM(K10:K15) -> 322571 | L16: =SUM(L10:L15) -> -53652 | M16: =SUM(M10:M15) -> 582969
A18: Capital assets being depreciated:
B19: Infrastructure
C20: Roads | I20: 15517189 | M20: =SUM(I20:L20) -> 15517189
C21: Bridges | I21: 1912668 | M21: =SUM(I21:L21) -> 1912668
B22: Land improvements | I22: 15995 | M22: =SUM(I22:L22) -> 15995
B23: Buildings and improvements | I23: 2590565 | K23: 164257 | M23: =SUM(I23:L23) -> 2754822
B24: Public works heavy equipment | I24: 2859173 | K24: 85134 | L24: -44815 | M24: =SUM(I24:L24) -> 2899492
B25: Public works other equipment | I25: 64075 | M25: =SUM(I25:L25) -> 64075
B26: Vehicles | I26: 218079 | K26: 34038 | M26: =SUM(I26:L26) -> 252117
B27: Other furniture and equipment | I27: 250841 | M27: =SUM(I27:L27) -> 250841
B28: Office of Emergency Preparedness and Homeland Security: | M28: =SUM(I28:L28) -> 0
C29: Vehicles | I29: 67031 | L29: -17907 | M29: =SUM(I29:L29) -> 49124
C30: Office furniture and equipment | I30: 50506 | M30: =SUM(I30:L30) -> 50506
C31: Buildings and improvements | I31: 13205 | M31: =SUM(I31:L31) -> 13205
B32: Office of Community Service | M32: =SUM(I32:L32) -> 0
C33: Land improvements | I33: 7800 | M33: =SUM(I33:L33) -> 7800
C34: Buildings and improvements | I34: 62156 | M34: =SUM(I34:L34) -> 62156
C35: Vehicles | I35: 382847 | K35: 57596 | L35: -67690 | M35: =SUM(I35:L35) -> 372753
C36: Office furniture and equipment | I36: 116327 | M36: =SUM(I36:L36) -> 116327
B37: Library | M37: =SUM(I37:L37) -> 0
C38: Building and improvement | I38: 3855244 | M38: =SUM(I38:L38) -> 3855244
C39: Vehicles | I39: 49901 | M39: =SUM(I39:L39) -> 49901
C40: Furniture and equipment | I40: 327121 | M40: =SUM(I40:L40) -> 327121
C41: Books and videos | I41: 737204 | K41: 43077 | L41: -45212 | M41: =SUM(I41:L41) -> 735069
C42: Total capital assets being depreciated | I42: =SUM(I19:I41) -> 29097927 | J42: =SUM(J19:J41) -> 0 | K42: =SUM(K19:K41) -> 384102 | L42: =SUM(L19:L41) -> -175624 | M42: =SUM(M19:M41) -> 29306405
A44: Less accumulated depreciation for:
...

Sheet Concordia
D1: Concordia PARISH POLICE JURY
D2: Capital Assets
D3: For the Year Ended December 31, 2015
I5: Beginning Balance | J5: Additions | K5: Dispositions | L5: Balance 12/31/15 | M5: Cross Sectional
A7: Governmental Activities:
B8: Capital assets, not being depreciated:
C9: Land | I9: 7038 | L9: =SUM(I9:K9) -> 7038 | M9: =SUM(L9) -> 7038
C10: Construction in progress | I10: 12250 | J10: 355613 | L10: =SUM(I10:K10) -> 367863 | M10: =SUM(L10) -> 367863
D11: Total capital assets, not being depreciated | I11: =SUM(I8:I10) -> 19288 | J11: =SUM(J8:J10) -> 355613 | K11: =SUM(K8:K9) -> 0 | L11: =SUM(L9:L10) -> 374901
M12: =SUM(L12) -> 0
A13: Capital assets being depreciated: | M13: =SUM(L13) -> 0
B14: Buildings and Improvements | I14: 5994190 | J14: 263926 | L14: =SUM(I14:K14) -> 6258116 | N14: missing Less Accumulated depreciation for each
B15: Furniture and fixtures | I15: 436844 | L15: =SUM(I15:K15) -> 436844 | N15: capital asset, only shows total accumulated
B16: Machinery and equipment | I16: 2572694 | J16: 88584 | L16: =SUM(I16:K16) -> 2661278 | N16: depreciation
B17: Transportation equipment | I17: 1049687 | L17: =SUM(I17:K17) -> 1049687
B18: Roads and bridges | I18: 12195458 | L18: =SUM(I18:K18) -> 12195458
M19: =SUM(L19) -> 0
D20: Total capital assets being depreciated | I20: =SUM(I14:I18) -> 22248873 | J20: =SUM(J14:J18) -> 352510 | K20: =SUM(K14:K18) -> 0 | L20: =SUM(L14:L18) -> 22601383
A22: Accumulated depreciation | I22: -12052532 | J22: -843656 | L22: =SUM(I22:K22) -> -12896188
B24: Total capital assets being depreciated, net | I24: =SUM(I22+I20) -> 10196341 | J24: =SUM(J22+J20) -> -491146 | K24: =SUM(K22+K20) -> 0 | L24: =SUM(L22+L20) -> 9705195
B26: Total capital assets (net) | I26: =I22+I20+I11 -> 10215629 | J26: =J22+J20+J11 -> -135533 | K26: =K22+K20+K11 -> 0 | L26: =L22+L20+L11 -> 10080096 | M26: =SUM(M9:M22) -> 374901

Sheet DeSoto
D1: DeSoto PARISH POLICE JURY
D2: Capital Assets
D3: For the Year Ended December 31, 2015
I5: Beginning Balance | J5: Additions | K5: Deletions | L5: Ending Balance | M5: Cross Sectional
A7: Primary Government
A8: Government Activities:
A9: Capital assets, not being depreciated:
B10: Land | I10: 1979943 | L10: =SUM(I10:K10) -> 1979943 | M10: =SUM(L10) -> 1979943
B11: Construction in progress | I11: 1040897 | J11: 3193524 | K11: -581402 | L11: =SUM(I11:K11) -> 3653019 | M11: =SUM(L11) -> 3653019
C12: Total assets not being depreciated | I12: =SUM(I10:I11) -> 3020840 | J12: =SUM(J10:J11) -> 3193524 | K12: =SUM(K10:K11) -> -581402 | L12: =SUM(L10:L11) -> 5632962
A14: Capital assets being depreciated:
B15: Buildings and improvements | I15: 26374042 | J15: 487809 | L15: =SUM(I15:K15) -> 26861851
B16: Land improvements - structures | I16: 6273341 | J16: 643786 | L16: =SUM(I16:K16) -> 6917127
B17: Furniture and equipment | I17: 13524501 | J17: 1301926 | K17: -627908 | L17: =SUM(I17:K17) -> 14198519
B18: Infrastructure | I18: 219055673 | J18: 1445830 | K18: -8276 | L18: =SUM(I18:K18) -> 220493227
C19: Total capital assets being depreciated | I19: =SUM(I15:I18) -> 265227557 | J19: =SUM(J15:J18) -> 3879351 | K19: =SUM(K15:K18) -> -636184 | L19: =SUM(L15:L18) -> 268470724
A21: Less accumulated depreciation for:
B22: Buildings and improvements | I22: 12433851 | J22: 668535 | L22: =SUM(I22:K22) -> 13102386 | M22: =SUM(L15-L22) -> 13759465
B23: Land improvements - structures | I23: 632589 | J23: 325983 | L23: =SUM(I23:K23) -> 958572 | M23: =SUM(L16-L23) -> 5958555
B24: Furniture and equipment | I24: 8155928 | J24: 1093304 | K24: -603778 | L24: =SUM(I24:K24) -> 8645454 | M24: =SUM(L17-L24) -> 5553065
B25: Infrastructure | I25: 173244304 | J25: 1887198 | L25: =SUM(I25:K25) -> 175131502 | M25: =SUM(L18-L25) -> 45361725
C26: Total accumulated depreciation | I26: =SUM(I22:I25) -> 194466672 | J26: =SUM(J22:J25) -> 3975020 | K26: =SUM(K22:K25) -> -603778 | L26: =SUM(L22:L25) -> 197837914
B28: Total capital assets being depreciated, net | I28: =I19-I26 -> 70760885 | J28: =J19-J26 -> -95669 | K28: =K19-K26 -> -32406 | L28: =L19-L26 -> 70632810
B30: Governmental activities capital assets, net | I30: =I12+I28 -> 73781725 | J30: =J12+J28 -> 3097855 | K30: =K12+K28 -> -613808 | L30: =L12+L28 -> 76265772 | M30: =SUM(M9:M29) -> 76265772
I32: Beginning Balance | J32: Increases | K32: Decreases | L32: Ending Balance
A33: Business-Type Activities:
B34: Capital assets, not being depreciated:
C35: Land | I35: 10175 | L35: =SUM(I35:K35) -> 10175 | M35: =SUM(L35) -> 10175
B37: Capital assets, depreciable:
C38: Sewer system | I38: 373375 | L38: =SUM(I38:K38) -> 373375
C39: Treatment plant | I39: 101180 | L39: =SUM(I39:K39) -> 101180
D41: Total capital assets, depreciable | I41: =SUM(I37:I39) -> 474555 | J41: =SUM(J37:J39) -> 0 | K41: =SUM(K37:K39) -> 0 | L41: =SUM(L37:L39) -> 474555
B43: Less accumulated depreciation for:
C44: Sewer system | I44: 373375 | L44: =SUM(I44:K44) -> 373375 | M44: =L38-L44 -> 0
C45: Treatment plant | I45: 101180 | L45: =SUM(I45:K45) -> 101180 | M45: =L39-L45 -> 0
D47: Total accumulated depreciation | I47: =SUM(I44:I45) -> 474555 | J47: =SUM(J44:J45) -> 0 | K47: =SUM(K44:K45) -> 0 | L47: =SUM(L44:L45) -> 474555
D49: Total capital assets - net | I49: =I35+I41-I47 -> 10175 | J49: =J35+J41-J47 -> 0 | K49: =K35+K41-K47 -> 0 | L49: =SUM(I49:K49) -> 10175 | M49: =SUM(J49:L49) -> 10175

Sheet East Baton Rouge
D1: East Baton Rouge PARISH POLICE JURY
D2: Capital Assets
D3: For the Year Ended December 31, 2015
I5: Balance 1/1/2015 | J5: Increases | K5: Decreases | L5: Adjustments | M5: Balance 12/31/2015 | N5: Cross Sectional
A7: Primary Government
A8: Government Activities:
A9: Capital assets, not being depreciated:
B10: Land and right-of-way | I10: 160234370 | J10: 1275882 | L10: 589754 | M10: =SUM(I10:L10) -> 162100006 | N10: =SUM(M10) -> 162100006
B11: Construction work in progress | I11: 48647850 | J11: 15844784 | L11: -27601230 | M11: =SUM(I11:L11) -> 36891404 | N11: =SUM(M11) -> 36891404
C12: Total assets not being depreciated | I12: =SUM(I10:I11) -> 208882220 | J12: =SUM(J10:J11) -> 17120666 | K12: =SUM(K10:K11) -> 0 | L12: =SUM(L10:L11) -> -27011476 | M12: =SUM(M10:M11) -> 198991410
A14: Capital assets being depreciated:
B15: Buildings | I15: 294781300 | J15: 3310495 | K15: -17370 | L15: 3029128 | M15: =SUM(I15:L15) -> 301103553
B16: Improvements (other than buildings)
C17: and infrastructure | I17: 925358411 | J17: 24876550 | L17: 27169558 | M17: =SUM(I17:L17) -> 977404519
B18: Equipment and equipment under lease | I18: 125057714 | J18: 9414357 | K18: -1902165 | M18: =SUM(I18:L18) -> 132569906
C19: Total capital assets being depreciated | I19: =SUM(I15:I18) -> 1345197425 | J19: =SUM(J15:J18) -> 37601402 | K19: =SUM(K15:K18) -> -1919535 | L19: =SUM(L15:L18) -> 30198686 | M19: =SUM(M15:M18) -> 1411077978
A21: Less accumulated depreciation for:
B22: Buildings | I22: -160400815 | J22: -6871899 | K22: 17370 | L22: 0 | M22: =SUM(I22:L22) -> -167255344 | N22: =SUM(M22,M15) -> 133848209
B23: Improvements (other than buildings) | L23: 0
C24: and infrastructure | I24: -414853563 | J24: -29618025 | L24: 0 | M24: =SUM(I24:L24) -> -444471588 | N24: =SUM(M24,M17) -> 532932931
B25: Equipment and equipment under lease | I25: -100176889 | J25: -8774917 | K25: 1885218 | L25: 0 | M25: =SUM(I25:L25) -> -107066588 | N25: =M18+M25 -> 25503318
C26: Total accumulated depreciation | I26: =SUM(I22:I25) -> -675431267 | J26: =SUM(J22:J25) -> -45264841 | K26: =SUM(K22:K25) -> 1902588 | L26: =SUM(L22:L25) -> 0 | M26: =SUM(M22:M25) -> -718793520
B28: Total capital assets being depreciated, net | I28: =I26+I19 -> 669766158 | J28: =J26+J19 -> -7663439 | K28: =K26+K19 -> -16947 | L28: =L26+L19 -> 30198686 | M28: =M26+M19 -> 692284458
B30: Governmental activities capital assets, net | I30: =I12+I28 -> 878648378 | J30: =J12+J28 -> 9457227 | K30: =K12+K28 -> -16947 | L30: =L12+L28 -> 3187210 | M30: =M12+M28 -> 891275868 | N30: =SUM(N10:N25) -> 891275868
I33: Beginning Balance | J33: Transfers | K33: Additions | L33: Deletions | M33: Ending Balance
A35: Business-type Activities:
A36: Capital assets not being depreciated:
B37: Land and right-of-way | I37: 91492232 | J37: 3021918 | L37: 21757 | M37: =SUM(I37:L37) -> 94535907 | N37: =SUM(M37) -> 94535907
B38: Noise mitigation | I38: 58392539 | M38: =SUM(I38:L38) -> 58392539 | N38: =SUM(M38) -> 58392539
B39: Construction work in progress | I39: 119514214 | J39: 102253246 | K39: -806075 | L39: -24261371 | M39: =SUM(I39:L39) -> 196700014 | N39: =SUM(M39) -> 196700014
C40: Total assets not being depreciated | I40: =SUM(I37:I39) -> 269398985 | J40: =SUM(J37:J39) -> 105275164 | K40: =SUM(K37:K39) -> -806075 | L40: =SUM(L37:L39) -> -24239614 | M40: =SUM(M37:M39) -> 349628460
A42: Capital assets being depreciated:
B43: Buildings | I43: 234674097 | J43: 2074825 | L43: 230033 | M43: =SUM(I43:L43) -> 236978955
B44: Improvements (other than buildings)
C45: and infrastructure | I45: 2076900538 | J45: 71376600 | K45: -2032363 | L45: 24711433 | M45: =SUM(I45:L45) -> 2170956208
B46: Equipment | I46: 9889878 | J46: 1035921 | K46: -610775 | M46: =SUM(I46:L46) -> 10315024
C47: Total capital assets being depreciated | I47: =SUM(I43:I46) -> 2321464513 | J47: =SUM(J43:J46) -> 74487346 | K47: =SUM(K43:K46) -> -2643138 | L47: =SUM(L43:L46) -> 24941466 | M47: =SUM(M43:M46) -> 2418250187
A49: Less accumulated depreciation for:
B50: Buildings | I50: -117563006 | J50: -9149192 | L50: 0 | M50: =SUM(I50:L50) -> -126712198 | N50: =SUM(M50,M43) -> 110266757
B51: Improvements (other than buildings) | L51: 0 | M51: =SUM(I51:L51) -> 0 | N51: =SUM(M51,M44) -> 0
...

Sheet East Carroll
D1: East Carroll PARISH POLICE JURY
D2: Capital Assets
D3: For the Year Ended December 31, 2015
A5: Governmental Activites | I5: Beginning Balance | J5: Additions | K5: Deletions | L5: Ending Balance | M5: Cross Sectional
A6: Nondepreciable capital assets:
B7: Land | I7: 274665 | L7: =SUM(I7:K7) -> 274665 | M7: =SUM(L7) -> 274665
B8: Airport Land | I8: 101000 | L8: =SUM(I8:K8) -> 101000 | M8: =SUM(L8) -> 101000
B9: Construction in progress | I9: 265027 | J9: 55204 | L9: =SUM(I9:K9) -> 320231 | M9: =SUM(L9) -> 320231
C10: Total assets not being depreciated | I10: =SUM(I7:I9) -> 640692 | J10: =SUM(J7:J9) -> 55204 | K10: =SUM(K7:K9) -> 0 | L10: =SUM(L7:L9) -> 695896
A12: Depreciable capital assets
B13: Buildings | I13: 2645963 | L13: =SUM(I13:K13) -> 2645963
B14: Office equipment | I14: 312527 | L14: =SUM(I14:K14) -> 312527
B15: Furniture & fixtures | I15: 67399 | L15: =SUM(I15:K15) -> 67399
B16: Construction equipment | I16: 1932706 | J16: 160074 | L16: =SUM(I16:K16) -> 2092780
B17: Vehicles | I17: 2961374 | J17: 115423 | L17: =SUM(I17:K17) -> 3076797
B18: Books, periodicals & law books | I18: 342548 | L18: =SUM(I18:K18) -> 342548
B19: Infrastructure | L19: =SUM(I19:K19) -> 0
C20: Airport hangars | I20: 25000 | L20: =SUM(I20:K20) -> 25000
C21: Airport runway | I21: 1130666 | L21: =SUM(I21:K21) -> 1130666
C22: Road right-of-way | I22: 558234 | L22: =SUM(I22:K22) -> 558234 | M22: =SUM(J22:L22) -> 558234
C23: Road surface | I23: 9140845 | L23: =SUM(I23:K23) -> 9140845
C24: Bridges | I24: 1759091 | L24: =SUM(I24:K24) -> 1759091
C25: Total capital assets being depreciated | I25: =SUM(I13:I24) -> 20876353 | J25: =SUM(J13:J24) -> 275497 | K25: =SUM(K13:K24) -> 0 | L25: =SUM(L13:L24) -> 21151850
A27: Less accumulated depreciation for:
B28: Buildings | I28: 1637164 | J28: 48794 | L28: =SUM(I28:K28) -> 1685958 | M28: =SUM(L13-L28) -> 960005
B29: Office equipment | I29: 258438 | J29: 21858 | L29: =SUM(I29:K29) -> 280296 | M29: =SUM(L14-L29) -> 32231
B30: Furniture & fixtures | I30: 38879 | J30: 6254 | L30: =SUM(I30:K30) -> 45133 | M30: =SUM(L15-L30) -> 22266
B31: Construction equipment | I31: 873317 | J31: 172361 | L31: =SUM(I31:K31) -> 1045678 | M31: =SUM(L16-L31) -> 1047102
B32: Vehicles | I32: 2086373 | J32: 190015 | L32: =SUM(I32:K32) -> 2276388 | M32: =SUM(L17-L32) -> 800409
B33: Books, periodicals & law books | I33: 342548 | L33: =SUM(I33:K33) -> 342548 | M33: =SUM(L18-L33) -> 0
B34: Infrastructure | L34: =SUM(I34:K34) -> 0 | M34: =SUM(L19-L34) -> 0
C35: Airport hangars | I35: 24688 | J35: 312 | L35: =SUM(I35:K35) -> 25000 | M35: =SUM(L20-L35) -> 0
C36: Airport runway | I36: 233307 | J36: 28266 | L36: =SUM(I36:K36) -> 261573 | M36: =SUM(L21-L36) -> 869093
C37: Road surface | I37: 8468531 | J37: 35595 | L37: =SUM(I37:K37) -> 8504126 | M37: =SUM(L23-L37) -> 636719
C38: Bridges | I38: 1194817 | J38: 27783 | L38: =SUM(I38:K38) -> 1222600 | M38: =SUM(L24-L38) -> 536491
C39: Total accumulated depreciation | I39: =SUM(I28:I38) -> 15158062 | J39: =SUM(J28:J38) -> 531238 | K39: =SUM(K28:K38) -> 0 | L39: =SUM(L28:L38) -> 15689300
B41: Total capital assets being depreciated, net | I41: =SUM(I25-I39) -> 5718291 | J41: =SUM(J25-J39) -> -255741 | K41: =SUM(K25-K39) -> 0 | L41: =SUM(L25-L39) -> 5462550
B43: Governmental activities capital assets, net | I43: =I10+I41 -> 6358983 | J43: =J10+J41 -> -200537 | K43: =K10+K41 -> 0 | L43: =L10+L41 -> 6158446 | M43: =SUM(M7:M38) -> 6158446

Sheet East Feliciana
D1: EAST FELICIANA PARISH POLICE JURY
D2: Capital Assets
D3: For the Year Ended December 31, 2015
I5: Beginning Balance | J5: Additions | K5: Deletions | L5: Ending Balance | M5: Cross Sectional
A7: Governmental Activities:
B8: Capital assets, not being depreciated:
C9: Land | I9: 259230 | L9: =SUM(I9:K9) -> 259230 | M9: =L9 -> 259230
D10: Total capital assets, not being depreciated | I10: =SUM(I9) -> 259230 | J10: =SUM(J9) -> 0 | K10: =SUM(K9) -> 0 | L10: =SUM(L9) -> 259230
A12: Capital assets being depreciated:
B13: Buildings | I13: 9943571 | L13: =SUM(I13:J13) -> 9943571
B14: Less: accumulated depreciation | I14: -4568786 | J14: -207415 | L14: =SUM(I14:J14) -> -4776201
D15: Net Buildings | I15: =SUM(I13:I14) -> 5374785 | J15: =SUM(J13:J14) -> -207415 | K15: =SUM(K13:K14) -> 0 | L15: =SUM(L13:L14) -> 5167370 | M15: =SUM(L13:L14) -> 5167370
B17: Equipment/Vehicles | I17: 4554913 | J17: 26880 | K17: -345795 | L17: =SUM(I17:K17) -> 4235998
B18: Less: accumulated depreciation | I18: -2546365 | J18: -200401 | K18: 345795 | L18: =SUM(I18:K18) -> -2400971
D19: Net Equipment/vehicles | I19: =SUM(I17:I18) -> 2008548 | J19: =SUM(J17:J18) -> -173521 | K19: =SUM(K17:K18) -> 0 | L19: =SUM(L17:L18) -> 1835027 | M19: =SUM(L17:L18) -> 1835027
B21: Streets/Bridges | I21: 5904195 | J21: 2007111 | L21: =SUM(I21:J21) -> 7911306
B22: Less: accumulated depreciation | I22: -685009 | J22: -400064 | L22: =SUM(I22:J22) -> -1085073
D23: Net Furniture and fixtures | I23: =SUM(I21:I22) -> 5219186 | J23: =SUM(J21:J22) -> 1607047 | K23: =SUM(K21:K22) -> 0 | L23: =SUM(I23:J23) -> 6826233 | M23: =SUM(L21:L22) -> 6826233
B24: Capital assets, being depreciated, net | I24: =SUM(I15+I19+I23) -> 12602519 | J24: =SUM(J15+J19+J23) -> 1226111 | K24: =SUM(K15+K19+K23) -> 0 | L24: =SUM(L15+L19+L23) -> 13828630
B25: Capital assets, net | I25: =SUM(I10+I24) -> 12861749 | J25: =SUM(J10+J24) -> 1226111 | K25: =SUM(K10+K24) -> 0 | L25: =SUM(L10+L24) -> 14087860 | M25: =SUM(M9:M23) -> 14087860

Sheet Evangeline
D1: Evangeline PARISH POLICE JURY
D2: Capital Assets
D3: For the Year Ended December 31, 2015
I5: Beginning Balance | J5: Additions | K5: Deletions | L5: Ending Balance | M5: Cross Sectional
A7: Primary Government
A8: Government Activities:
A9: Capital assets, not being depreciated:
B10: Land | I10: 876298 | J10: 5000 | L10: =SUM(I10:K10) -> 881298 | M10: =SUM(L10) -> 881298
B11: Construction in progress | I11: 3632280 | J11: 22622676 | K11: -336299 | L11: =SUM(I11:K11) -> 25918657 | M11: =SUM(L11) -> 25918657
A12: Other capital assets:
B13: Buildings and improvements | I13: 13449894 | L13: =SUM(I13:K13) -> 13449894
B14: Infrastructure | I14: 21491821 | J14: 680445 | L14: =SUM(I14:K14) -> 22172266
B15: Vehicles | I15: 704276 | L15: =SUM(I15:K15) -> 704276
B16: Equipment, furniture and fixtures | I16: 6398790 | J16: 299345 | K16: -65049 | L16: =SUM(I16:K16) -> 6633086
C17: Total capital assets | I17: =SUM(I10:I16) -> 46553359 | J17: =SUM(J10:J16) -> 23607466 | K17: =SUM(K10:K16) -> -401348 | L17: =SUM(L10:L16) -> 69759477
A19: Less accumulated depreciation for:
B20: Buildings | I20: 4808668 | J20: 375776 | L20: =SUM(I20:K20) -> 5184444 | M20: =L13-L20 -> 8265450
B21: Infrastructure | I21: 11081230 | J21: 1065788 | L21: =SUM(I21:K21) -> 12147018 | M21: =L14-L21 -> 10025248
B22: Vehicles | I22: 625080 | J22: 42729 | L22: =SUM(I22:K22) -> 667809 | M22: =L15-L22 -> 36467
B23: Equipment, furniture and fixtures | I23: 4391016 | J23: 398640 | K23: -61254 | L23: =SUM(I23:K23) -> 4728402 | M23: =L16-L23 -> 1904684
C24: Total accumulated depreciation | I24: =SUM(I20:I23) -> 20905994 | J24: =SUM(J20:J23) -> 1882933 | K24: =SUM(K20:K23) -> -61254 | L24: =SUM(L20:L23) -> 22727673
B26: Governmental activities capital assets, net | I26: =I17-I24 -> 25647365 | J26: =J17-J24 -> 21724533 | K26: =K17-K24 -> -340094 | L26: =L17-L24 -> 47031804 | M26: =SUM(M10:M23) -> 47031804
I29: Beginning Balance | J29: Additions | K29: Deletions | L29: Ending Balance | M29: Cross Sectional
A31: Business-type Activities:
A32: Capital assets being depreciated:
B33: Sewer System | I33: 828812 | L33: =SUM(I33:K33) -> 828812
B34: Equipment, furniture and fixtures | I34: 19769 | L34: =SUM(I34:K34) -> 19769
C35: Total capital assets | I35: =SUM(I33:I34) -> 848581 | J35: =SUM(J33:J34) -> 0 | K35: =SUM(K33:K34) -> 0 | L35: =SUM(L33:L34) -> 848581
A37: Less accumulated depreciation for:
B38: Sewer System | L38: =SUM(I38:K38) -> 0 | M38: =L33-L38 -> 828812 | N38: Wrong on audit
B39: Equipment, furniture and fixtures | L39: =SUM(I39:K39) -> 0 | M39: =L34-L39 -> 19769
C40: Total accumulated depreciation | I40: =SUM(I38:I39) -> 0 | J40: =SUM(J38:J39) -> 0 | K40: =SUM(K38:K39) -> 0 | L40: =SUM(I40:K40) -> 0
B43: Business-type activities capital assets, net | I43: =SUM(I35+I40) -> 848581 | J43: =SUM(J35-J40) -> 0 | K43: =SUM(K35-K40) -> 0 | L43: =SUM(L35-L40) -> 848581 | M43: =SUM(M33:M34:M40) -> 848581

Sheet Franklin
D1: Franklin PARISH POLICE JURY
D2: Capital Assets
D3: For the Year Ended December 31, 2015
I5: Balance January 1,2015 | J5: Additions | K5: Deletions | L5: Balance December 31,2015 | M5: Cross Sectional
A7: Primary Government
A8: Government Activities:
A9: Capital assets, not being depreciated:
B10: Land | I10: 390416 | L10: =SUM(I10:K10) -> 390416 | M10: =L10 -> 390416
B11: Construction in progess | I11: 2087938 | J11: 872809 | K11: -1762753 | L11: =SUM(I11:K11) -> 1197994 | M11: =L11 -> 1197994
B12: Assets under Capital Lease | I12: 70000 | L12: =SUM(I12:K12) -> 70000 | M12: =L12 -> 70000
C13: Total capital assets not being depreciated | I13: =SUM(I10:I12) -> 2548354 | J13: =SUM(J10:J12) -> 872809 | K13: =SUM(K10:K12) -> -1762753 | L13: =SUM(L10:L12) -> 1658410
A15: Capital assets being depreciated:
B16: Infrastructure - roads | I16: 87396267 | J16: 399629 | L16: =SUM(I16:K16) -> 87795896
B17: Infrastructure - bridges | I17: 3366140 | L17: =SUM(I17:K17) -> 3366140
B18: Buildings and improvements | I18: 4772535 | J18: 1762753 | L18: =SUM(I18:K18) -> 6535288
B19: Improvements other than buildings | I19: 2593516 | J19: 256799 | L19: =SUM(I19:K19) -> 2850315
B20: Office furniture and equipment | I20: 63648 | L20: =SUM(I20:K20) -> 63648
B21: Heavy equipment | I21: 1773388 | J21: 209900 | K21: -145903 | L21: =SUM(I21:K21) -> 1837385
B22: Other equipment | I22: 495797 | J22: 162692 | K22: -5800 | L22: =SUM(I22:K22) -> 652689
B23: Vehicles | I23: 1223973 | J23: 29022 | K23: -29051 | L23: =SUM(I23:K23) -> 1223944
C24: Total capital assets being depreciated | I24: =SUM(I16:I23) -> 101685264 | J24: =SUM(J16:J23) -> 2820795 | K24: =SUM(K16:K23) -> -180754 | L24: =SUM(L16:L23) -> 104325305
A26: Less accumulated depreciation for:
B27: Infrastructure - roads | I27: -75900253 | J27: -755040 | L27: =SUM(I27:K27) -> -76655293 | M27: =SUM(L16+L27) -> 11140603
B28: Infrastructure - bridges | I28: -1666388 | J28: -43749 | L28: =SUM(I28:K28) -> -1710137 | M28: =SUM(L17+L28) -> 1656003
B29: Buildings and improvements | I29: -3576477 | J29: -149069 | L29: =SUM(I29:K29) -> -3725546 | M29: =SUM(L18+L29) -> 2809742
B30: Improvements other than buildings | I30: -1780273 | J30: -119590 | L30: =SUM(I30:K30) -> -1899863 | M30: =SUM(L19+L30) -> 950452
B31: Office furniture and equipment | I31: -60134 | J31: -1119 | L31: =SUM(I31:K31) -> -61253 | M31: =SUM(L20+L31) -> 2395
B32: Heavy equipment | I32: -986622 | J32: -129446 | K32: 114764 | L32: =SUM(I32:K32) -> -1001304 | M32: =SUM(L21+L32) -> 836081
B33: Other equipment | I33: -387104 | J33: -63299 | K33: 5800 | L33: =SUM(I33:K33) -> -444603 | M33: =SUM(L22+L33) -> 208086
B34: Vehicles | I34: -1146699 | J34: -52286 | K34: 29051 | L34: =SUM(I34:K34) -> -1169934 | M34: =SUM(L23+L34) -> 54010
C35: Total accumulated depreciation | I35: =SUM(I27:I34) -> -85503950 | J35: =SUM(J27:J34) -> -1313598 | K35: =SUM(K27:K34) -> 149615 | L35: =SUM(L27:L34) -> -86667933
