Workbook

Sheet Acadia
D1: Acadia Combined Balance Sheet
D2: Issued: December 31, 2015
K4: General Fund | L4: Parish Road Fund | M4: Sales Tax Fund | N4: 1% Sales Tax District No. 2 Fund | O4: Other Governmental Funds | P4: Total Governmental Funds
A5: Assets:
B6: Cash | K6: 594846 | L6: 1442181 | M6: 1777092 | N6: 349485 | O6: 5031940 | P6: =SUM(K6:O6) -> 9195544
B7: Investments | K7: 627565 | L7: 12742 | M7: 4074584 | N7: 137018 | O7: 3087127 | P7: =SUM(K7:O7) -> 7939036
B8: Tax Receivable | K8: 1827046 | L8: 1117278 | M8: 1457991 | N8: 477857 | O8: 1662324 | P8: =SUM(K8:O8) -> 6542496
B9: Special assessments receivable | O9: 16996 | P9: =SUM(K9:O9) -> 16996
B10: Other receivables | K10: 8444 | O10: 1650 | P10: =SUM(K10:O10) -> 10094
B11: Due from other governmental entities, net of allowance
C12: for doubtful accounts | K12: 359090 | L12: 45485 | M12: 21150 | O12: 124735 | P12: =SUM(K12:O12) -> 550460
B13: Due from other funds | K13: 95052 | P13: =SUM(K13:O13) -> 95052
B14: Due from component units | K14: 20177 | P14: =SUM(K14:O14) -> 20177
E16: Total assets: | K16: =SUM(K6:K14) -> 3532220 | L16: =SUM(L6:L14) -> 2617686 | M16: =SUM(M6:M14) -> 7330817 | N16: =SUM(N6:N14) -> 964360 | O16: =SUM(O6:O14) -> 9924772 | P16: =SUM(K16:O16) -> 24369855
A18: LIABILITIES AND FUND BALANCES
B19: Liabilities:
C20: Accounts payable | K20: 661040 | L20: 16126 | M20: 385236 | N20: 6349 | O20: 249209 | P20: =SUM(K20:O20) -> 1317960
C21: Retainage payable | P21: =SUM(K21:O21) -> 0
C22: Accrued liabilities and other payables | K22: 519374 | L22: 41289 | M22: 12218 | O22: 55052 | P22: =SUM(K22:O22) -> 627933
C23: Unearned revenue | L23: 46000 | P23: =SUM(K23:O23) -> 46000
C24: Due to other funds | L24: 42381 | M24: 36357 | O24: 16314 | P24: =SUM(K24:O24) -> 95052
E26: Total liabilities: | K26: =SUM(K20:K24) -> 1180414 | L26: =SUM(L20:L24) -> 145796 | M26: =SUM(M20:M24) -> 433811 | N26: =SUM(N20:N24) -> 6349 | O26: =SUM(O20:O24) -> 320575 | P26: =SUM(P20:P24) -> 2086945
A28: DEFERRED INFLOWS OF RESOURCES
C29: Unavailable revenue- special assessments | O29: 16997 | P29: =SUM(K29:O29) -> 16997
E31: Total deferred inflows of resources | K31: =SUM(K29:K29) -> 0 | L31: =SUM(L29:L29) -> 0 | M31: =SUM(M29:M29) -> 0 | N31: =SUM(N29:N29) -> 0 | O31: =SUM(O29:O29) -> 16997 | P31: =SUM(P29:P29) -> 16997
B33: Fund Balances
C34: Restricted for:
D35: Property tax dedication for council on aging | K35: 482052 | P35: =SUM(K35:O35) -> 482052
D36: Property tax and sales tax dedication for
E37: constructing and maintaining solid
E38: waste, facilities, roads and bridges | L38: 2471890 | M38: 6897006 | N38: 958011 | P38: =SUM(K38:O38) -> 10326907
D39: Debt retirement | O39: 1669655 | P39: =SUM(K39:O39) -> 1669655
D40: Mosquito control | O40: 2126616 | P40: =SUM(K40:O40) -> 2126616
D41: Cooperative extension operation and maintenance | O41: 1667432 | P41: =SUM(K41:O41) -> 1667432
D42: Road maintenance and construction | O42: 1129541 | P42: =SUM(K42:O42) -> 1129541
C43: Committed to:
D44: Health unit operation and maintenance | O44: 1707620 | P44: =SUM(K44:O44) -> 1707620
D45: Rice Arena operation and maintenance | O45: 1061885 | P45: =SUM(K45:O45) -> 1061885
C46: Assigned: | P46: =SUM(K46:O46) -> 0
D47: Capital projects | O47: 1916 | P47: =SUM(K47:O47) -> 1916
...

Sheet Allen
D1: Allen Combined Balance Sheet
D2: Issued: December 31, 2015
K5: General | L5: Solid Waste Fund | M5: Road District #2 Mtc. Fund | N5: Road District #3 Mtc. Fund | O5: Library Capital Projects Fund | P5: North Drainage Capital Projects Fund | Q5: Nonmajor Governmental Funds | R5: Total Governmental Funds
A6: Assets:
B7: Cash | K7: 132295 | L7: 477668 | M7: 469617 | N7: 864081 | O7: 493056 | Q7: 1632845 | R7: =SUM(K7:Q7) -> 4069562
B8: Receivables | K8: 234323 | M8: 596200 | N8: 630435 | Q8: 1372153 | R8: =SUM(K8:Q8) -> 2833111
B9: Due from other governments | K9: 280033 | L9: 135294 | P9: 268581 | Q9: 78487 | R9: =SUM(K9:Q9) -> 762395
B10: Inventory | Q10: 45179 | R10: =SUM(K10:Q10) -> 45179
B11: Prepaid assets | K11: 4443 | Q11: 2989 | R11: =SUM(K11:Q11) -> 7432
E13: Total Assets: | K13: =SUM(K7:K11) -> 651094 | L13: =SUM(L7:L11) -> 612962 | M13: =SUM(M7:M11) -> 1065817 | N13: =SUM(N7:N11) -> 1494516 | O13: =SUM(O7:O11) -> 493056 | P13: =SUM(P7:P11) -> 268581 | Q13: =SUM(Q7:Q11) -> 3131653 | R13: =SUM(R7:R11) -> 7717679
A15: LIABILITIES AND FUND BALANCES
B16: Liabilities:
C17: Accounts payable | K17: 43891 | L17: 132980 | M17: 48187 | N17: 58319 | O17: 102505 | P17: 268581 | Q17: 170096 | R17: =SUM(K17:Q17) -> 824559
C18: Unearned revenue | Q18: 48703 | R18: =SUM(K18:Q18) -> 48703
E20: Total liabilities: | K20: =SUM(K17:K18) -> 43891 | L20: =SUM(L17:L18) -> 132980 | M20: =SUM(M17:M18) -> 48187 | N20: =SUM(N17:N18) -> 58319 | O20: =SUM(O17:O18) -> 102505 | P20: =SUM(P17:P18) -> 268581 | Q20: =SUM(Q17:Q18) -> 218799 | R20: =SUM(R17:R18) -> 873262
A22: DEFERRED INFLOWS OF RESROUCES
C23: Unavailable revenue | K23: 29082 | M23: 50116 | N23: 59851 | Q23: 206210 | R23: =SUM(K23:Q23) -> 345259
E25: Total deferred inflows of resources | K25: =SUM(K23:K23) -> 29082 | L25: =SUM(L23:L23) -> 0 | M25: =SUM(M23:M23) -> 50116 | N25: =SUM(N23:N23) -> 59851 | O25: =SUM(O23:O23) -> 0 | P25: =SUM(P23:P23) -> 0 | Q25: =SUM(Q23:Q23) -> 206210 | R25: =SUM(R23:R23) -> 345259
B27: Fund Balances
C28: Nonspendable - prepaids | K28: 4443 | Q28: 2989 | R28: =SUM(K28:Q28) -> 7432
C29: Nonspendable- inventroy | Q29: 45179 | R29: =SUM(K29:Q29) -> 45179
C30: Restricted:
D31: Judicial | Q31: 611041 | R31: =SUM(K31:Q31) -> 611041
D32: Other general government | Q32: 634469 | R32: =SUM(K32:Q32) -> 634469
D33: Public works | M33: 967514 | N33: 1376346 | Q33: 1157545 | R33: =SUM(K33:Q33) -> 3501405
D34: Economic development | L34: 479982 | R34: =SUM(K34:Q34) -> 479982
D35: Sanitation | O35: 390551 | R35: =SUM(K35:Q35) -> 390551
D36: Capital projects | Q36: 53723 | R36: =SUM(K36:Q36) -> 53723
D37: Debt service | R37: =SUM(K37:Q37) -> 0
C38: Committed: | R38: =SUM(K38:Q38) -> 0
D39: Other general government | R39: =SUM(K39:Q39) -> 0
C40: Assigned: | R40: =SUM(K40:Q40) -> 0
D41: Other general government | R41: =SUM(K41:Q41) -> 0
D42: Public works | R42: =SUM(K42:Q42) -> 0
C43: Negative unassigned | R43: =SUM(K43:Q43) -> 0
C44: Unassigned | K44: 573678 | Q44: 201698 | R44: =SUM(K44:Q44) -> 775376
E46: Total fund balance: | K46: =SUM(K28:K44) -> 578121 | L46: =SUM(L28:L44) -> 479982 | M46: =SUM(M28:M44) -> 967514 | N46: =SUM(N28:N44) -> 1376346 | O46: =SUM(O28:O44) -> 390551 | P46: =SUM(P28:P44) -> 0 | Q46: =SUM(Q28:Q44) -> 2706644 | R46: =SUM(R28:R44) -> 6499158
E48: Total liabilities, deffered inflows of resources and fund balances: | K48: =K46+K25+K20 -> 651094 | L48: =L46+L25+L20 -> 612962 | M48: =M46+M25+M20 -> 1065817 | N48: =N46+N25+N20 -> 1494516 | O48: =O46+O25+O20 -> 493056 | P48: =P46+P25+P20 -> 268581 | Q48: =Q46+Q25+Q20 -> 3131653 | R48: =R46+R25+R20 -> 7717679

Sheet Ascension
D1: Ascension Combined Balance Sheet
D2: Issued: December 31, 2015
K4: General Fund | L4: East Ascension Drainage | M4: Road Project | N4: East Ascension Drainage Project | O4: Nonmajor Governmental Funds | P4: Total Governmental Funds
A5: Assets:
B6: Cash and cash equivalents | K6: 5648893 | L6: 5955781 | M6: 3389546 | N6: 2002929 | O6: 14260482 | P6: =SUM(K6:O6) -> 31257631
B7: Investments | K7: 28724249 | L7: 28865877 | M7: 16841615 | N7: 26025996 | O7: 30077557 | P7: =SUM(K7:O7) -> 130535294
B8: Accounts receivable, net
C9: Ad valorem taxes | K9: 4324287 | L9: 5376980 | O9: 20255720 | P9: =SUM(K9:O9) -> 29956987
C10: Sales and use taxes | K10: 3556195 | L10: 1122416 | P10: =SUM(K10:O10) -> 4678611
C11: Other | K11: 597421 | L11: 86292 | M11: 46714 | N11: 27604 | O11: 325909 | P11: =SUM(K11:O11) -> 1083940
B12: Due from other governments
C13: LA - State revenue sharing | K13: 89772 | L13: 156822 | O13: 642656 | P13: =SUM(K13:O13) -> 889250
C14: LA -Severence | K14: 21378 | P14: =SUM(K14:O14) -> 21378
C15: LA - Beer and Parish Transportation | K15: 18569 | P15: =SUM(K15:O15) -> 18569
C16: Grants | K16: 1096579 | L16: 244823 | M16: 52620 | O16: 3016465 | P16: =SUM(K16:O16) -> 4410487
B17: Due from other funds | K17: 10 | L17: 117437 | M17: 653664 | O17: 1067499 | P17: =SUM(K17:O17) -> 1838610
B18: Prepaid and other assets | K18: 500 | O18: 94092 | P18: =SUM(K18:O18) -> 94592
E20: Total assets: | K20: =SUM(K6:K18) -> 44077853 | L20: =SUM(L6:L18) -> 41926428 | M20: =SUM(M6:M18) -> 20984159 | N20: =SUM(N6:N18) -> 28056529 | O20: =SUM(O6:O18) -> 69740380 | P20: =SUM(P6:P18) -> 204785349
A22: LIABILITIES, DEFERRED INFLOWS OF RESOURCES, AND FUND BALANCE
B23: Liabilities:
C24: Accounts payable | K24: 591306 | L24: 298191 | O24: 637675 | P24: =SUM(K24:O24) -> 1527172
C25: Contracts payable | K25: 40170 | L25: 146229 | M25: 1403928 | N25: 1304357 | O25: 2212013 | P25: =SUM(K25:O25) -> 5106697
C26: Accrued payroll | K26: 276060 | L26: 97188 | O26: 302062 | P26: =SUM(K26:O26) -> 675310
C27: Deductions from ad valorem taxes: | P27: =SUM(K27:O27) -> 0
D28: Contribution to retirement system | K28: 142818 | L28: 177439 | O28: 670974 | P28: =SUM(K28:O28) -> 991231
C29: Due to other funds | K29: 1838600 | O29: 5 | P29: =SUM(K29:O29) -> 1838605
C30: Due to other governments | K30: 2500 | L30: 269707 | O30: 200000 | P30: =SUM(K30:O30) -> 472207
C31: Sales tax rebate escrow | K31: 4759700 | P31: =SUM(K31:O31) -> 4759700
C32: Unearned revenue | O32: 414404 | P32: =SUM(K32:O32) -> 414404
E34: Total liabilities: | K34: =SUM(K24:K32) -> 7651154 | L34: =SUM(L24:L32) -> 988754 | M34: =SUM(M24:M32) -> 1403928 | N34: =SUM(N24:N32) -> 1304357 | O34: =SUM(O24:O32) -> 4437133 | P34: =SUM(P24:P32) -> 15785326
A36: DEFERRED INFLOWS OF RESOURCES
B37: Unavailable revenue | K37: 209419 | L37: 304 | M37: 52620 | O37: 1489747 | P37: =SUM(K37:O37) -> 1752090
E39: Total deferred inflows: | K39: =SUM(K37:K37) -> 209419 | L39: =SUM(L37:L37) -> 304 | M39: =SUM(M37:M37) -> 52620 | N39: =SUM(N37:N37) -> 0 | O39: =SUM(O37:O37) -> 1489747 | P39: =SUM(P37:P37) -> 1752090
B41: Fund Balances:
C42: Nonspendable: | O42: 94092 | P42: =SUM(K42:O42) -> 94092
C43: Restricted for:
D44: Construction of capital assets | M44: 2986717 | N44: 26752172 | O44: 9535502 | P44: =SUM(K44:O44) -> 39274391
D45: Debt service | O45: 2528147 | P45: =SUM(K45:O45) -> 2528147
D46: Fire protection | O46: 19779144 | P46: =SUM(K46:O46) -> 19779144
D47: Drainage maintenance | L47: 36090453 | O47: 1534322 | P47: =SUM(K47:O47) -> 37624775
...

Sheet Assumption
D1: Assumption Combined Balance Sheet
D2: Issued: December 31, 2015
K4: General Fund | L4: Sales and Use Tax | M4: Solid Waste | N4: Section Eight Housing | O4: Community Development Block Grant | P4: LCDBG Disaster Recovery Program | Q4: Road Improvement Tax Fund | R4: Other Non-major Governmental Funds | S4: Total Governmental Funds
A5: Assets:
B6: Cash and cash equivalents | K6: 3105425 | L6: 236494 | M6: 136686 | N6: 12532 | Q6: 135336 | R6: 1429195 | S6: =SUM(K6:R6) -> 5055668
B7: Investments | K7: 3327782 | L7: 1765594 | M7: 1015459 | Q7: 1030309 | R7: 7584524 | S7: =SUM(K7:R7) -> 14723668
B8: Receivables | K8: 1007456 | L8: 250245 | M8: 185991 | N8: 594 | O8: 729295 | P8: 733546 | Q8: 80858 | R8: 3002965 | S8: =SUM(K8:R8) -> 5990950
B9: Due from other funds | K9: 633553 | R9: 14012 | S9: =SUM(K9:R9) -> 647565
B10: Other assets | P10: 135412 | R10: 3623 | S10: =SUM(K10:R10) -> 139035
E12: Total assets: | K12: =SUM(K6:K10) -> 8074216 | L12: =SUM(L6:L10) -> 2252333 | M12: =SUM(M6:M10) -> 1338136 | N12: =SUM(N6:N10) -> 13126 | P12: =SUM(P6:P10) -> 868958 | S12: =SUM(S6:S10) -> 26556886
A14: LIABILITIES AND FUND BALANCES
B15: Liabilities:
C16: Accounts payable | K16: 63575 | L16: 14599 | M16: 206 | N16: 66 | O16: 138919 | P16: 725072 | R16: 734997 | S16: =SUM(K16:R16) -> 1677434
C17: Salaries payable | K17: 5640 | L17: 6338 | R17: 32402 | S17: =SUM(K17:R17) -> 44380
C18: Due to other funds | K18: 4612 | L18: 2996 | O18: 590376 | P18: 8474 | R18: 41107 | S18: =SUM(K18:R18) -> 647565
C19: Other liabilities | K19: 240044 | L19: 14320 | P19: 135412 | Q19: 101898 | R19: 216217 | S19: =SUM(K19:R19) -> 707891
E21: Total liabilities: | K21: =SUM(K16:K19) -> 313871 | L21: =SUM(L16:L19) -> 38253 | M21: =SUM(M16:M19) -> 206 | N21: =SUM(N16:N19) -> 66 | O21: =SUM(O16:O19) -> 729295 | P21: =SUM(P16:P19) -> 868958 | Q21: =SUM(Q16:Q19) -> 101898 | R21: =SUM(R16:R19) -> 1024723 | S21: =SUM(S16:S19) -> 3077270
B23: Fund Balances
C24: Restricted | L24: 2214080 | N24: 23 | Q24: 1144605 | R24: 10133638 | S24: =SUM(K24:R24) -> 13492346
C25: Assigned | K25: 40645 | M25: 1337930 | N25: 13037 | R25: 875958 | S25: =SUM(K25:R25) -> 2267570
C26: Unassigned | K26: 7719700 | S26: =SUM(K26:R26) -> 7719700
E28: Total fund balance: | K28: =SUM(K24:K26) -> 7760345 | L28: =SUM(L24:L26) -> 2214080 | M28: =SUM(M24:M26) -> 1337930 | N28: =SUM(N24:N26) -> 13060 | O28: =SUM(O24:O26) -> 0 | P28: =SUM(P24:P26) -> 0 | Q28: =SUM(Q24:Q26) -> 1144605 | R28: =SUM(R24:R26) -> 11009596 | S28: =SUM(S24:S26) -> 23479616
E30: Total liabilities and fund balances: | K30: =SUM(K28,K21) -> 8074216 | L30: =SUM(L28,L21) -> 2252333 | M30: =SUM(M28,M21) -> 1338136 | N30: =SUM(N28,N21) -> 13126 | O30: =SUM(O28,O21) -> 729295 | P30: =SUM(P28,P21) -> 868958 | Q30: =SUM(Q28,Q21) -> 1246503 | R30: =SUM(R28,R21) -> 12034319 | S30: =SUM(S28,S21) -> 26556886

Sheet Avoyelles
D1: Avoyelles Combined Balance Sheet
D2: Issued: December 31, 2015
K4: General | L4: Road & Bridge | M4: Solid Waste | N4: Drainage | O4: Health Unit | P4: Library | Q4: Section 8 | R4: LCDBG Ike Gustav | S4: Other Governmental Funds | T4: Total Governmental Funds
A5: Assets:
B6: Cash and interest-bearing deposits | K6: 855612 | L6: 1028184 | M6: 4191293 | N6: 621908 | O6: 2058472 | P6: 1272452 | Q6: 213029 | R6: 319 | S6: 280938 | T6: =SUM(K6:S6) -> 10522207
B7: Receivables, net | K7: 18000 | Q7: 6998 | S7: 8791 | T7: =SUM(K7:S7) -> 33789
B8: Due from other governmental units | K8: 406664 | L8: 131384 | M8: 284617 | N8: 410957 | O8: 469734 | P8: 727864 | R8: 140655 | S8: 4054 | T8: =SUM(K8:S8) -> 2575929
B9: Due from other funds | S9: 3376 | T9: =SUM(K9:S9) -> 3376
B10: Prepaid items | K10: 15525 | L10: 20690 | M10: 22959 | N10: 17285 | O10: 8719 | P10: 19924 | Q10: 60 | S10: 3668 | T10: =SUM(K10:S10) -> 108830
E12: Total Assets: | K12: =SUM(K6:K10) -> 1295801 | L12: =SUM(L6:L10) -> 1180258 | M12: =SUM(M6:M10) -> 4498869 | N12: =SUM(N6:N10) -> 1050150 | O12: =SUM(O6:O10) -> 2536925 | P12: =SUM(P6:P10) -> 2020240 | Q12: =SUM(Q6:Q10) -> 220087 | R12: =SUM(R6:R10) -> 140974 | ... T12: =SUM(T6:T10) -> 13244131
A14: LIABILITIES, DEFERRED INFLOWS OF RESOURCES AND FUND BALANCES
B16: Liabilities:
C17: Accounts, salaries, and other payables | K17: 124365 | L17: 110779 | M17: 188005 | N17: 23002 | O17: 22806 | P17: 56159 | Q17: 2798 | R17: 140655 | S17: 20568 | T17: =SUM(K17:S17) -> 689137
C18: Unearned revenue | Q18: 36260 | T18: =SUM(K18:S18) -> 36260
C19: Due to other funds | K19: 1546 | S19: 1830 | T19: =SUM(K19:S19) -> 3376
C20: Due to other governments | K20: 59537 | L20: 6467 | T20: =SUM(K20:S20) -> 66004
E22: Total liabilities: | K22: =SUM(K17:K20) -> 185448 | L22: =SUM(L17:L20) -> 117246 | M22: =SUM(M17:M20) -> 188005 | N22: =SUM(N17:N21) -> 23002 | O22: =SUM(O17:O20) -> 22806 | P22: =SUM(P17:P20) -> 56159 | Q22: =SUM(Q17:Q20) -> 39058 | R22: =SUM(R17:R20) -> 140655 | S22: =SUM(S17:S20) -> 22398 | T22: =SUM(T17:T20) -> 794777
A24: DEFERRED INFLOWS OF RESOURCES
C25: Unavailable revenue | K25: 43264 | N25: 70453 | O25: 80648 | P25: 124787 | T25: =SUM(K25:S25) -> 319152
B27: Fund Balances
C28: Nonspendable | K28: 15525 | L28: 20690 | M28: 22959 | N28: 17285 | O28: 8719 | P28: 19924 | Q28: 60 | S28: 3668 | T28: =SUM(K28:S28) -> 108830
C29: Restricted | T29: =SUM(K29:S29) -> 0
D30: Public safety | S30: 7063 | T30: =SUM(K30:S30) -> 7063
D31: Public works | L31: 1042322 | M31: 4287905 | N31: 939410 | R31: 319 | S31: 74541 | T31: =SUM(K31:S31) -> 6344497
D32: Health and welfare | O32: 2424752 | Q32: 180969 | T32: =SUM(K32:S32) -> 2605721
D33: Culture and recreation | P33: 1819370 | T33: =SUM(K33:S33) -> 1819370
D34: Economic development | S34: 204739 | T34: =SUM(K34:S34) -> 204739
C35: Unassigned (deficit) | K35: 1051564 | S35: -11582 | T35: =SUM(K35:S35) -> 1039982
E37: Total fund balance: | K37: =SUM(K28:K36) -> 1067089 | L37: =SUM(L28:L35) -> 1063012 | M37: =SUM(M28:M35) -> 4310864 | N37: =SUM(N28:N35) -> 956695 | O37: =SUM(O28:O35) -> 2433471 | P37: =SUM(P28:P35) -> 1839294 | Q37: =SUM(Q28:Q35) -> 181029 | R37: =SUM(R28:R35) -> 319 | S37: =SUM(S28:S35) -> 278429 | T37: =SUM(T28:T35) -> 12130202
E39: Total liabilities and fund balances: | K39: =SUM(K37+K25+K22) -> 1295801 | L39: =SUM(L37+L25+L22) -> 1180258 | M39: =SUM(M37+M25+M22) -> 4498869 | N39: =SUM(N37+N25+N22) -> 1050150 | O39: =SUM(O37+O25+O22) -> 2536925 | P39: =SUM(P37+P25+P22) -> 2020240 | Q39: =SUM(Q37+Q25+Q22) -> 220087 | R39: =SUM(R37+R25+R22) -> 140974 | ... T39: =SUM(T37+T25+T22) -> 13244131

Sheet Beauregard
D1: Beauregard Combined Balance Sheet
D2: Issued: December 31, 2015
K4: General Fund | L4: Parishwide Road Special Revenue | M4: Road District No. 6 Special Revenue | N4: Sales Tax District No. 1 Special Revenue | O4: Health Unit Special Revenue | P4: South Beau. Rec. Dist. No. 2 Special Revenue | Q4: Courthouse Sales Tax Special Revenue | R4: Courthouse Renovation Capital Project | S4: Nonmajor Governmental Funds | T4: Total Governmental Funds
A5: Assets:
B6: Equity in pooled cash | K6: 145177 | L6: 1569627 | M6: 393160 | N6: 4774356 | O6: 2121897 | Q6: 2634695 | R6: 9164133 | S6: 4717507 | T6: =SUM(K6:S6) -> 25520552
B7: Receivables | K7: 1222735 | L7: 36204 | M7: 968633 | N7: 428863 | O7: 515610 | P7: 531092 | Q7: 129309 | S7: 2593006 | T7: =SUM(K7:S7) -> 6425452
B8: Interfund receivable | K8: 107332 | L8: 11404 | T8: =SUM(K8:S8) -> 118736
B9: Inventory | M9: 54053 | S9: 280629 | T9: =SUM(K9:S9) -> 334682
B10: Prepaid iterms | K10: 226353 | T10: =SUM(K10:S10) -> 226353
E12: Total assets: | K12: =SUM(K6:K10) -> 1701597 | L12: =SUM(L6:L10) -> 1617235 | M12: =SUM(M6:M10) -> 1415846 | N12: =SUM(N6:N10) -> 5203219 | O12: =SUM(O6:O10) -> 2637507 | P12: =SUM(P6:P10) -> 531092 | Q12: =SUM(Q6:Q10) -> 2764004 | R12: =SUM(R6:R10) -> 9164133 | ... T12: =SUM(T6:T10) -> 32625775
A14: LIABILITIES
B15: Liabilities:
C16: Accounts payable | K16: 273323 | L16: 29583 | M16: 20059 | N16: 128239 | O16: 535 | P16: 67905 | Q16: 3671 | R16: 472197 | S16: 103737 | T16: =SUM(K16:S16) -> 1099249
C17: Contracts payable | M17: 77583 | R17: 153725 | T17: =SUM(K17:S17) -> 231308
C18: Payroll liabilities | K18: 201087 | T18: =SUM(K18:S18) -> 201087
C19: Interfund payable | P19: 92033 | S19: 26703 | T19: =SUM(K19:S19) -> 118736
E21: Total liabilities: | K21: =SUM(K16:K19) -> 474410 | L21: =SUM(L16:L19) -> 29583 | M21: =SUM(M16:M19) -> 97642 | N21: =SUM(N16:N19) -> 128239 | O21: =SUM(O16:O19) -> 535 | P21: =SUM(P16:P19) -> 159938 | Q21: =SUM(Q16:Q19) -> 3671 | R21: =SUM(R16:R19) -> 625922 | ... T21: =SUM(T16:T19) -> 1650380
A23: DEFERRED INFLOWS OF RESOURCES
B24: Unavailable revenue | K24: 117403 | M24: 57515 | O24: 60331 | P24: 28866 | S24: 165109 | T24: =SUM(K24:S24) -> 429224
C25: Total deferred inflows of resources | K25: =K24 -> 117403 | L25: =L24 -> 0 | M25: =M24 -> 57515 | N25: =N24 -> 0 | O25: =O24 -> 60331 | P25: =P24 -> 28866 | Q25: =Q24 -> 0 | R25: =R24 -> 0 | ... T25: =T24 -> 429224
B27: Fund Balances:
C28: Nonspendable - inventory | M28: 54053 | S28: 280629 | T28: =SUM(K28:S28) -> 334682
C29: Restricted:
D30: Purchases of equipment | L30: 744819 | T30: =SUM(K30:S30) -> 744819
D31: Public safety | S31: 1932609 | T31: =SUM(K31:S31) -> 1932609
D32: Public works | L32: 842833 | M32: 1206636 | S32: 3806866 | T32: =SUM(K32:S32) -> 5856335
D33: Health and welfare | O33: 2576641 | T33: =SUM(K33:S33) -> 2576641
D34: Culture and recreation | P34: 342288 | S34: 523629 | T34: =SUM(K34:S34) -> 865917
D35: Sanitation | N35: 5074980 | T35: =SUM(K35:S35) -> 5074980
D36: Other general government | S36: 325299 | T36: =SUM(K36:S36) -> 325299
D37: Capital projects | Q37: 2760333 | R37: 8538211 | S37: 260228 | T37: =SUM(K37:S37) -> 11558772
D38: Debt service | S38: 166333 | T38: =SUM(K38:S38) -> 166333
C39: Unassigned | K39: 1109784 | T39: =SUM(K39:S39) -> 1109784
E41: Total fund balance: | K41: =SUM(K28:K39) -> 1109784 | L41: =SUM(L28:L39) -> 1587652 | M41: =SUM(M28:M39) -> 1260689 | N41: =SUM(N28:N39) -> 5074980 | O41: =SUM(O28:O39) -> 2576641 | P41: =SUM(P28:P39) -> 342288 | Q41: =SUM(Q28:Q39) -> 2760333 | R41: =SUM(R28:R39) -> 8538211 | ... T41: =SUM(T28:T39) -> 30546171
E43: Total liabilities, deferred inflows of resources, and fund balances: | K43: =K41+K24+K21 -> 1701597 | L43: =L41+L24+L21 -> 1617235 | M43: =M41+M24+M21 -> 1415846 | N43: =N41+N24+N21 -> 5203219 | O43: =O41+O24+O21 -> 2637507 | P43: =P41+P24+P21 -> 531092 | Q43: =Q41+Q24+Q21 -> 2764004 | R43: =R41+R24+R21 -> 9164133 | ... T43: =T41+T24+T21 -> 32625775

Sheet Bienville
D1: Bienville Combined Balance Sheet
D2: Issued: December 31, 2015
K4: General Fund | L4: Road Maintenance | M4: Solid Waste | N4: Debt Service Fund | O4: Other Governmental Funds | P4: Total
A5: Assets:
B6: Cash and cash equivalents | K6: 4817035 | L6: 6752352 | M6: 3759965 | N6: 1249258 | O6: 279881 | P6: =SUM(K6:O6) -> 16858491
B7: Receivables | K7: 1762003 | L7: 1885884 | M7: 79106 | N7: 920773 | O7: 6836 | P7: =SUM(K7:O7) -> 4654602
E9: Total assets: | K9: =SUM(K6:K7) -> 6579038 | L9: =SUM(L6:L7) -> 8638236 | M9: =SUM(M6:M7) -> 3839071 | N9: =SUM(N6:N7) -> 2170031 | O9: =SUM(O6:O7) -> 286717 | P9: =SUM(P6:P7) -> 21513093
A11: LIABILITIES AND FUND BALANCES
B12: Liabilities:
C13: Accounts payable | K13: 92298 | L13: 25688 | M13: 97995 | O13: 600 | P13: =SUM(K13:O13) -> 216581
C14: Salaries and related payable | K14: 9398 | L14: 24128 | P14: =SUM(K14:O14) -> 33526
C15: Deferred revenues | K15: 70000 | P15: =SUM(K15:O15) -> 70000
E17: Total liabilities: | K17: =SUM(K13:K15) -> 171696 | L17: =SUM(L13:L15) -> 49816 | M17: =SUM(M13:M15) -> 97995 | N17: =SUM(N13:N15) -> 0 | O17: =SUM(O13:O15) -> 600 | P17: =SUM(P13:P15) -> 320107
B19: Fund Balances
C20: Non spendable | O20: 16 | P20: =SUM(K20:O20) -> 16
C21: Restricted | P21: =SUM(K21:O21) -> 0
D22: Other general government | O22: 175730 | P22: =SUM(K22:O22) -> 175730
D23: Public works | L23: 8558420 | M23: 3741076 | O23: 14471 | P23: =SUM(K23:O23) -> 12313967
D24: Health and welfare | O24: 57002 | P24: =SUM(K24:O24) -> 57002
D25: Economic development | O25: 36521 | P25: =SUM(K25:O25) -> 36521
C26: Assigned | N26: 2170031 | O26: 2377 | P26: =SUM(K26:O26) -> 2172408
C27: Unassigned | K27: 6407342 | P27: =SUM(K27:O27) -> 6407342
E29: Total fund balance: | K29: =SUM(K21:K27) -> 6407342 | L29: =SUM(L21:L27) -> 8558420 | M29: =SUM(M21:M27) -> 3741076 | N29: =SUM(N21:N27) -> 2170031 | O29: =SUM(O20:O27) -> 286117 | P29: =SUM(P20:P27) -> 21162986
E31: Total liabilities and fund balances: | K31: =SUM(K29,K17) -> 6579038 | L31: =SUM(L29,L17) -> 8608236 | M31: =SUM(M29,M17) -> 3839071 | N31: =SUM(N29,N17) -> 2170031 | O31: =SUM(O29,O17) -> 286717 | P31: =SUM(P29,P17) -> 21483093

Sheet Bossier
D1: Bossier Combined Balance Sheet
D2: Issued: December 31, 2015
K5: General | L5: HIghway | M5: Library | N5: Capital Improvement | O5: Corrections | P5: LCDA Sewer Construction | Q5: LCDA Sinking Fund | R5: Other Governmental Funds | S5: Total Governmental Funds
A6: Assets:
B7: Cash and cash equivalents | K7: 3995100 | L7: 4321821 | M7: 12346953 | N7: 8439777 | O7: 3069476 | P7: 210716 | Q7: 229 | R7: 9358163 | S7: =SUM(K7:R7) -> 41742235
B8: Investments | N8: 1470000 | R8: 1055000 | S8: =SUM(K8:R8) -> 2525000
B9: Receivables | K9: 2766939 | L9: 3234515 | M9: 7025554 | N9: 972382 | O9: 2832702 | R9: 1578845 | S9: =SUM(K9:R9) -> 18410937
B10: Restricted cash | P10: 2540249 | Q10: 115116 | R10: 1722767 | S10: =SUM(K10:R10) -> 4378132
B11: Restricted investment | Q11: 11092426 | S11: =SUM(K11:R11) -> 11092426
B12: Due from other funds | K12: 76015 | R12: 6373 | S12: =SUM(K12:R12) -> 82388
B13: Advance to waterworks/sewer district | P13: 8176744 | S13: =SUM(K13:R13) -> 8176744
E15: Total Assets: | K15: =SUM(K7:K13) -> 6838054 | L15: =SUM(L7:L13) -> 7556336 | M15: =SUM(M7:M13) -> 19372507 | N15: =SUM(N7:N13) -> 10882159 | O15: =SUM(O7:O13) -> 5902178 | P15: =SUM(P7:P13) -> 10927709 | Q15: =SUM(Q7:Q13) -> 11207771 | R15: =SUM(R7:R13) -> 13721148 | S15: =SUM(S7:S13) -> 86407862
A17: LIABILITIES, DEFERRED INFLOWS OF RESOURCES, AND FUND BALANCES
B18: Liabilities:
C19: Accounts payable | K19: 313294 | L19: 594891 | M19: 451210 | N19: 394648 | O19: 283180 | R19: 473789 | S19: =SUM(K19:R19) -> 2511012
C20: Due to other funds | L20: 55782 | N20: 11300 | R20: 15306 | S20: =SUM(K20:R20) -> 82388
E22: Total liabilities: | K22: =SUM(K19:K20) -> 313294 | L22: =SUM(L19:L20) -> 650673 | M22: =SUM(M19:M20) -> 451210 | N22: =SUM(N19:N20) -> 405948 | O22: =SUM(O19:O20) -> 283180 | P22: =SUM(P19:P20) -> 0 | Q22: =SUM(Q19:Q20) -> 0 | R22: =SUM(R19:R20) -> 489095 | S22: =SUM(S19:S20) -> 2593400
A24: DEFERRED INFLOWS OF RESROUCES
B25: Unavailable revenue
C26: Property taxes | K26: 1936976 | L26: 1966410 | M26: 7405923 | O26: 2934970 | R26: 812023 | S26: =SUM(K26:R26) -> 15056302
C27: Other | K27: 13218 | L27: 177171 | M27: 6609 | R27: 35073 | S27: =SUM(K27:R27) -> 232071
E29: Total deferred inflows of resources | K29: =SUM(K25:K27) -> 1950194 | L29: =SUM(L25:L27) -> 2143581 | M29: =SUM(M25:M27) -> 7412532 | N29: =SUM(N25:N27) -> 0 | O29: =SUM(O25:O27) -> 2934970 | P29: =SUM(P25:P27) -> 0 | Q29: =SUM(Q25:Q27) -> 0 | R29: =SUM(R25:R27) -> 847096 | S29: =SUM(S25:S27) -> 15288373
B31: Fund Balances
C32: Nonspendable | P32: 8176744 | S32: =SUM(K32:R32) -> 8176744
C33: Restricted | M33: 9460640 | N33: 10324362 | O33: 944556 | P33: 2750965 | Q33: 11207771 | R33: 4401935 | S33: =SUM(K33:R33) -> 39090229
C34: Assigned | K34: 1570876 | L34: 4762082 | M34: 2048125 | N34: 151849 | O34: 1739472 | R34: 7983022 | S34: =SUM(K34:R34) -> 18255426
C35: Unassigned | K35: 3003690 | S35: =SUM(K35:R35) -> 3003690
E37: Total fund balance: | K37: =SUM(K32:K35) -> 4574566 | L37: =SUM(L32:L35) -> 4762082 | M37: =SUM(M32:M35) -> 11508765 | N37: =SUM(N32:N35) -> 10476211 | O37: =SUM(O32:O35) -> 2684028 | P37: =SUM(P32:P35) -> 10927709 | Q37: =SUM(Q32:Q35) -> 11207771 | R37: =SUM(R32:R35) -> 12384957 | S37: =SUM(S32:S35) -> 68526089
E39: Total liabilities, deffered inflows of resources and fund balances: | K39: =SUM(K22+K29+K37) -> 6838054 | L39: =SUM(L22+L29+L37) -> 7556336 | M39: =SUM(M22+M29+M37) -> 19372507 | N39: =SUM(N22+N29+N37) -> 10882159 | O39: =SUM(O22+O29+O37) -> 5902178 | P39: =SUM(P22+P29+P37) -> 10927709 | Q39: =SUM(Q22+Q29+Q37) -> 11207771 | R39: =SUM(R22+R29+R37) -> 13721148 | S39: =SUM(S22+S29+S37) -> 86407862

Sheet Caddo
D1: Caddo Combined Balance Sheet
D2: Issued: December 31, 2015
K4: General Fund | L4: Detention Facilities Fund | M4: Solid Waste Disposal Fund | N4: Public Works Fund | O4: Head Start Fund | P4: Biomedical Fund | Q4: Capital Outlay Fund | R4: Criminal Justice Fund | S4: Other Governmental Funds | T4: Total Governmental Funds
A5: Assets:
B6: Cash and cash equivalents | K6: 2165963 | L6: 31620 | M6: 1001500 | N6: 684819 | Q6: 623277 | S6: 168362 | T6: =SUM(K6:S6) -> 4675541
B7: Investments | K7: 43345664 | L7: 667041 | M7: 20981526 | N7: 14336882 | Q7: 13060286 | S7: 24471578 | T7: =SUM(K7:S7) -> 116862977
B8: Receivables, net:
C9: Ad valorem taxes | K9: 6502121 | L9: 8255761 | N9: 6453859 | P9: 2737122 | R9: 5027031 | S9: 14267311 | T9: =SUM(K9:S9) -> 43243205
C10: Paving assessments | N10: 151647 | T10: =SUM(K10:S10) -> 151647
C11: Other | K11: 9693 | L11: 247 | M11: 6556 | S11: 174972 | T11: =SUM(K11:S11) -> 191468
C12: Accrued interest | K12: 139030 | L12: 2030 | M12: 64285 | N12: 43949 | Q12: 40007 | S12: 74978 | T12: =SUM(K12:S12) -> 364279
B13: Due from other funds | K13: 1202730 | L13: 60455 | M13: 545051 | N13: 428333 | Q13: 400320 | S13: 1283979 | T13: =SUM(K13:S13) -> 3920868
B14: Due from other governments | K14: 194831 | L14: 159204 | M14: 280350 | N14: 934684 | P14: 45356 | R14: 81957 | S14: 578176 | T14: =SUM(K14:S14) -> 2274558
B15: Inventories | N15: 115369 | T15: =SUM(K15:S15) -> 115369
B16: Other assets | N16: 19512 | T16: =SUM(K16:S16) -> 19512
E18: Total assets: | K18: =SUM(K6:K16) -> 53560032 | L18: =SUM(L6:L16) -> 9176358 | M18: =SUM(M6:M16) -> 22879268 | N18: =SUM(N6:N16) -> 23169054 | O18: =SUM(O6:O16) -> 0 | P18: =SUM(P6:P16) -> 2782478 | Q18: =SUM(Q6:Q16) -> 14123890 | R18: =SUM(R6:R16) -> 5108988 | ... T18: =SUM(T6:T16) -> 171819424
A20: LIABILITIES AND FUND BALANCES
B21: Liabilities:
C22: Accounts payable | K22: 53144 | L22: 89303 | M22: 167196 | N22: 368299 | P22: 659281 | Q22: 1225550 | S22: 411239 | T22: =SUM(K22:S22) -> 2974012
C23: Accrued liabilities | K23: 32433 | L23: 8945 | M23: 16978 | N23: 47058 | S23: 117586 | T23: =SUM(K23:S23) -> 223000
C24: Retainage payable | Q24: 405543 | T24: =SUM(K24:S24) -> 405543
C25: Due to other funds | P25: 1519906 | R25: 2732500 | T25: =SUM(K25:S25) -> 4252406
C26: Unearned revenue | K26: 34465 | T26: =SUM(K26:S26) -> 34465
C27: Due to component units | L27: 893500 | T27: =SUM(K27:S27) -> 893500
C28: Due to other governments | K28: 15014 | M28: 3460 | N28: 7822 | R28: 161984 | S28: 94680 | T28: =SUM(K28:S28) -> 282960
E30: Total liabilities: | K30: =SUM(K22:K28) -> 135056 | L30: =SUM(L22:L28) -> 991748 | M30: =SUM(M22:M28) -> 187634 | N30: =SUM(N22:N28) -> 423179 | O30: =SUM(O22:O28) -> 0 | P30: =SUM(P22:P28) -> 2179187 | Q30: =SUM(Q22:Q28) -> 1631093 | R30: =SUM(R22:R28) -> 2894484 | ... T30: =SUM(T22:T28) -> 9065886
A32: DEFERRED INFLOWS OF RESOURCES
B33: Unavailable revenue - property taxes | K33: 47879 | L33: 62643 | N33: 39798 | P33: 10584 | R33: 22127 | S33: 84863 | T33: =SUM(K33:S33) -> 267894
B34: Unavailable revenue - special assessments | N34: 56265 | T34: =SUM(K34:S34) -> 56265
E36: Total deferred inflows: | K36: =SUM(K33:K34) -> 47879 | L36: =SUM(L33:L34) -> 62643 | M36: =SUM(M33:M34) -> 0 | N36: =SUM(N33:N34) -> 96063 | O36: =SUM(O33:O34) -> 0 | P36: =SUM(P33:P34) -> 10584 | Q36: =SUM(Q33:Q34) -> 0 | R36: =SUM(R33:R34) -> 22127 | ... T36: =SUM(T33:T34) -> 324159
B38: Fund Balances:
C39: Restricted for:
D40: Criminal justice | L40: 7419892 | R40: 2164345 | S40: 4115816 | T40: =SUM(K40:S40) -> 13700053
D41: Health and welfare | S41: 4598423 | T41: =SUM(K41:S41) -> 4598423
D42: Highways, streets and drainage | N42: 17760128 | T42: =SUM(K42:S42) -> 17760128
D43: Building facilities | S43: 8149857 | T43: =SUM(K43:S43) -> 8149857
D44: Sanitation | M44: 21151391 | T44: =SUM(K44:S44) -> 21151391
D45: Culture and recreation | S45: 3114732 | T45: =SUM(K45:S45) -> 3114732
D46: Economic development | P46: 213504 | T46: =SUM(K46:S46) -> 213504
D47: Debt service | S47: 3161513 | T47: =SUM(K47:S47) -> 3161513
...

Sheet Calcasieu
D1: Calcasieu Combined Balance Sheet
D2: Issued: December 31, 2015
K4: General Fund | L4: Public Works Operating Fund | M4: Office of Juvenille Justice Services Fund | N4: Calcasieu Parish Library Fund | O4: Road Capital Improvement Fund | P4: Nonmajor Governmental Funds | Q4: Total Governmental Funds
A5: Assets:
B6: Cash and Cash Equivalents | K6: 10931817 | L6: 4523372 | M6: 1232339 | N6: 1126793 | O6: 21177168 | P6: 7630364 | Q6: =SUM(K6:P6) -> 46621853
B7: Investments | K7: 56198681 | L7: 23764364 | M7: 6771928 | N7: 6183676 | O7: 117512490 | P7: 37003077 | Q7: =SUM(K7:P7) -> 247434216
B8: Receivable (net of allowance for uncollectibles):
C9: Property taxes | K9: 12319577 | M9: 6271772 | N9: 10372119 | O9: 6296084 | P9: 14249394 | Q9: =SUM(K9:P9) -> 49508946
C10: Sales taxes | L10: 1454093 | O10: 3180894 | P10: 566667 | Q10: =SUM(K10:P10) -> 5201654
C11: Franchise taxes | K11: 315760 | Q11: =SUM(K11:P11) -> 315760
B12: Interest receivable | K12: 98232 | L12: 39585 | M12: 12418 | N12: 11939 | O12: 193032 | P12: 64767 | Q12: =SUM(K12:P12) -> 419973
B13: Other receivables | K13: 3858732 | L13: 50000 | M13: 20587 | N13: 29 | O13: 2000000 | P13: 28047 | Q13: =SUM(K13:P13) -> 5957395
B14: Intergovernmental receivable | K14: 395131 | L14: 3780 | M14: 242578 | O14: 120780 | P14: 1952057 | Q14: =SUM(K14:P14) -> 2714326
B15: Due from other funds | K15: 524717 | L15: 9305 | P15: 74639 | Q15: =SUM(K15:P15) -> 608661
B16: Loans receivable | K16: 25764 | Q16: =SUM(K16:P16) -> 25764
B17: Prepaid items | K17: 1226 | L17: 575 | M17: 31675 | N17: 465 | P17: 278562 | Q17: =SUM(K17:P17) -> 312503
B18: Inventory | L18: 695170 | P18: 302877 | Q18: =SUM(K18:P18) -> 998047
E20: Total assets: | K20: =SUM(K6:K18) -> 84669637 | L20: =SUM(L6:L18) -> 30540244 | M20: =SUM(M6:M18) -> 14583297 | N20: =SUM(N6:N18) -> 17695021 | O20: =SUM(O6:O18) -> 150480448 | P20: =SUM(P6:P18) -> 62150451 | Q20: =SUM(Q6:Q18) -> 360119098
A22: LIABILITIES AND FUND BALANCES
B23: Liabilities:
C24: Accounts payable | K24: 1653550 | L24: 371543 | M24: 88725 | N24: 195730 | O24: 818981 | P24: 2621682 | Q24: =SUM(K24:P24) -> 5750211
C25: Accrued liabilities | K25: 351520 | L25: 261852 | M25: 132532 | N25: 162727 | P25: 135832 | Q25: =SUM(K25:P25) -> 1044463
C26: Intergovernmental payable | K26: 20000 | P26: 43080 | Q26: =SUM(K26:P26) -> 63080
C27: Due to other funds | K27: 92794 | M27: 4009 | O27: 4897 | P27: 527756 | Q27: =SUM(K27:P27) -> 629456
C28: Due to component units | K28: 12963 | L28: 13228 | P28: 34655 | Q28: =SUM(K28:P28) -> 60846
C29: Unearned revenue | K29: 157739 | O29: 2071450 | P29: 1152908 | Q29: =SUM(K29:P29) -> 3382097
C30: Retainage payable | O30: 248052 | P30: 366741 | Q30: =SUM(K30:P30) -> 614793
C31: Other liabilities | K31: 89099 | L31: 1770 | P31: 81668 | Q31: =SUM(K31:P31) -> 172537
C32: Enterprize zone rebate liability | L32: 314038 | Q32: =SUM(K32:P32) -> 314038
E34: Total liabilities: | K34: =SUM(K24:K31) -> 2377665 | L34: =SUM(L24:L32) -> 962431 | M34: =SUM(M24:M32) -> 225266 | N34: =SUM(N24:N31) -> 358457 | O34: =SUM(O24:O31) -> 3143380 | P34: =SUM(P24:P31) -> 4964322 | Q34: =SUM(Q24:Q32) -> 12031521
A36: DEFERRED INFLOWS OF RESOURCES
C37: Property taxes levied for the next fiscal year | K37: 12373150 | M37: 6314426 | N37: 10442515 | O37: 6345696 | P37: 14343941 | Q37: =SUM(K37:P37) -> 49819728
C38: Unavailable revenue | L38: 105934 | O38: 132844 | Q38: =SUM(K38:P38) -> 238778
E40: Total deferred inflows of resources | K40: =SUM(K37:K38) -> 12373150 | L40: =SUM(L37:L38) -> 105934 | M40: =SUM(M37:M38) -> 6314426 | N40: =SUM(N37:N38) -> 10442515 | O40: =SUM(O37:O38) -> 6478540 | P40: =SUM(P37:P38) -> 14343941 | Q40: =SUM(Q37:Q38) -> 50058506
B42: Fund Balances
C43: Nonspendable:
D44: Prepaid items | K44: 1226 | L44: 575 | M44: 31675 | N44: 465 | P44: 278562 | Q44: =SUM(K44:P44) -> 312503
D45: Inventories | L45: 695170 | P45: 302877 | Q45: =SUM(K45:P45) -> 998047
D46: Loans receivable | K46: 25764 | Q46: =SUM(K46:P46) -> 25764
C47: Restricted:
...

Sheet Caldwell
D1: Caldwell Combined Balance Sheet
D2: Issued: December 31, 2015
K4: General Fund | L4: Road Maintenance | M4: Recreation | N4: Solid Waste | O4: Blacktop Road | P4: Bayou Dechere Resevoir | Q4: LCDBG | R4: Other Governmental Funds | S4: Total Governmental Funds
A5: Assets:
B6: Cash and Cash Equivalents | K6: 1192998 | L6: 561744 | M6: 794466 | N6: 1010200 | O6: 2077705 | P6: 97678 | Q6: 40 | R6: 1665610 | S6: =SUM(K6:R6) -> 7400441
B7: Investments | K7: 366187 | L7: 515816 | M7: 308950 | N7: 109632 | S7: =SUM(K7:R7) -> 1300585
B8: Due from other funds | K8: 2700 | L8: 25652 | R8: 36402 | S8: =SUM(K8:R8) -> 64754
E10: Total assets: | K10: =SUM(K6:K8) -> 1561885 | L10: =SUM(L6:L8) -> 1103212 | M10: =SUM(M6:M8) -> 1103416 | N10: =SUM(N6:N8) -> 1119832 | O10: =SUM(O6:O8) -> 2077705 | P10: =SUM(P6:P8) -> 97678 | Q10: =SUM(Q6:Q8) -> 40 | R10: =SUM(R6:R8) -> 1702012 | S10: =SUM(S6:S8) -> 8765780
A12: LIABILITIES AND FUND BALANCES
B13: Liabilities:
C14: Accounts payable | K14: 13881 | L14: 31237 | M14: 19448 | N14: 45919 | O14: 260584 | R14: 29588 | S14: =SUM(K14:R14) -> 400657
C15: Saleries and related payables | K15: 10661 | L15: 15263 | M15: 2241 | R15: 7980 | S15: =SUM(K15:R15) -> 36145
C16: Due to other agencies | K16: 57698 | S16: =SUM(K16:R16) -> 57698
C17: Due to other funds | K17: 62054 | L17: 2700 | S17: =SUM(K17:R17) -> 64754
E19: Total liabilities: | K19: =SUM(K14:K17) -> 144294 | L19: =SUM(L14:L17) -> 49200 | M19: =SUM(M14:M17) -> 21689 | N19: =SUM(N14:N17) -> 45919 | O19: =SUM(O14:O17) -> 260584 | P19: =SUM(P14:P17) -> 0 | Q19: =SUM(Q14:Q17) -> 0 | R19: =SUM(R14:R17) -> 37568 | S19: =SUM(S14:S17) -> 559254
B21: Fund Balances
C22: Unassigned | K22: 1417591 | S22: =SUM(K22:P22) -> 1417591
C23: Restricted | L23: 1054012 | M23: 1081727 | N23: 1073913 | O23: 1817121 | P23: 97678 | Q23: 40 | R23: 2266638 | S23: =SUM(K23:R23) -> 7391129
E25: Total fund balances: | K25: =SUM(K22:K23) -> 1417591 | L25: =SUM(L22:L23) -> 1054012 | M25: =SUM(M22:M23) -> 1081727 | N25: =SUM(N22:N23) -> 1073913 | O25: =SUM(O22:O23) -> 1817121 | P25: =SUM(P22:P23) -> 97678 | Q25: =SUM(Q22:Q23) -> 40 | R25: =SUM(R22:R23) -> 2266638 | S25: =SUM(S22:S23) -> 8808720
E27: Total liabilities and fund balances: | K27: =SUM(K25+K19) -> 1561885 | L27: =SUM(L25+L19) -> 1103212 | M27: =SUM(M25+M19) -> 1103416 | N27: =SUM(N25+N19) -> 1119832 | O27: =SUM(O25+O19) -> 2077705 | P27: =SUM(P25+P19) -> 97678 | Q27: =SUM(Q25+Q19) -> 40 | R27: =SUM(R25+R19) -> 2304206 | S27: =SUM(S25+S19) -> 9367974

Sheet Cameron
D1: Cameron Combined Balance Sheet
D2: Issued: December 31, 2015
K4: General Fund | L4: Road & Bridge Maintenance | M4: Long-Term Community Recovery | N4: Library | O4: Non-Major | P4: Total
A5: Assets:
B6: Cash | K6: 11043177 | L6: 401 | M6: 100 | N6: 1271296 | O6: 4260526 | P6: =SUM(K6:O6) -> 16575500
B7: Investments | K7: 2209031 | N7: 2113254 | O7: 7155345 | P7: =SUM(K7:O7) -> 11477630
B8: Receivables, net | K8: 7299605 | L8: 1815429 | M8: 566609 | N8: 954049 | O8: 3282928 | P8: =SUM(K8:O8) -> 13918620
B9: Inventory, at cost | K9: 1793767 | L9: 64283 | P9: =SUM(K9:O9) -> 1858050
B10: Other | K10: 72523 | L10: 48633 | N10: 51933 | O10: 24180 | P10: =SUM(K10:O10) -> 197269
B11: Interfund receivables | K11: 2366061 | L11: 234428 | N11: 842246 | O11: 1798954 | P11: =SUM(K11:O11) -> 5241689
A13: DEFERRED OUTFLOWS OF RESOURCES
E15: Total assets and deferred outflows of resources: | K15: =SUM(K6:K11) -> 24784164 | L15: =SUM(L6:L11) -> 2163174 | M15: =SUM(M6:M11) -> 566709 | N15: =SUM(N6:N11) -> 5232778 | O15: =SUM(O6:O11) -> 16521933 | P15: =SUM(P6:P11) -> 49268758
A17: LIABILITIES AND FUND BALANCES
B18: Liabilities:
C19: Accounts, salaries, and other payables | K19: 1171350 | L19: 39535 | M19: 562446 | N19: 68069 | O19: 157859 | P19: =SUM(K19:O19) -> 1999259
C20: Due to other agencies | K20: 2551196 | P20: =SUM(K20:O20) -> 2551196
C21: Unearned revenue | K21: 7413 | M21: 9818 | P21: =SUM(K21:O21) -> 17231
C22: Interfund payables | K22: 2871381 | M22: 66214 | O22: 2304094 | P22: =SUM(K22:O22) -> 5241689
E24: Total liabilities: | K24: =SUM(K19:K22) -> 6601340 | L24: =SUM(L19:L22) -> 39535 | M24: =SUM(M19:M22) -> 638478 | O24: =SUM(O19:O22) -> 2461953 | P24: =SUM(P19:P22) -> 9809375
A26: DEFERRED INFLOWS OF RESOURCES | K26: 1793767 | P26: =SUM(K26:O26) -> 1793767
E28: Total deferred inflows of resources | K28: =SUM(K26) -> 1793767 | L28: =SUM(L26) -> 0 | M28: =SUM(M26) -> 0 | N28: =SUM(N26) -> 0 | O28: =SUM(O26) -> 0 | P28: =SUM(P26) -> 1793767
B30: Fund Balances
C31: Nonspendable:
D32: Inventories | K32: 1793767 | L32: 64283 | N32: 51933 | P32: =SUM(K32:O32) -> 1909983
D33: Prepaid expenses | K33: 72523 | L33: 48633 | O33: 24180 | P33: =SUM(K33:O33) -> 145336
C34: Restricted:
D35: Judicial | O35: 48266 | P35: =SUM(K35:O35) -> 48266
D36: Debt service | O36: 646986 | P36: =SUM(K36:O36) -> 646986
D37: Tourism development | O37: 44880 | P37: =SUM(K37:O37) -> 44880
C38: Commited to:
D39: Infrastructure maintenance | L39: 2010723 | P39: =SUM(K39:O39) -> 2010723
D40: Culture and recreation | N40: 5089637 | P40: =SUM(K40:O40) -> 5089637
D41: Public safety | O41: 4611317 | P41: =SUM(K41:O41) -> 4611317
D42: Judicial | O42: 3430605 | P42: =SUM(K42:O42) -> 3430605
D43: Health and welfare | O43: 5101344 | P43: =SUM(K43:O43) -> 5101344
D44: Other purposes | K44: 343354 | P44: =SUM(K44:O44) -> 343354
C45: Assigned:
D46: Judicial | O46: 11057 | P46: =SUM(K46:O46) -> 11057
D47: Health and welfare | O47: 24648 | P47: =SUM(K47:O47) -> 24648
D48: Public safety | O48: 116697 | P48: =SUM(K48:O48) -> 116697
...

Sheet Catahoula
D1: Catahoula Combined Balance Sheet
D2: Issued: December 31, 2015
K5: General | L5: Road and Bridge | M5: Hard Surfacing | N5: Sanitation | O5: Library | P5: Heatlh Unit | Q5: Courthouse Roof Rehabilitation | R5: Other Governmental Funds | S5: Total Governmental Funds
A6: Assets:
B7: Cash and cash equivalents | K7: 643284 | L7: 93544 | M7: 230590 | N7: 394127 | O7: 281429 | P7: 384230 | R7: 119023 | S7: =SUM(K7:R7) -> 2146227
B8: Cash restricted for debt service | R8: 27472 | S8: =SUM(K8:R8) -> 27472
B9: Cash restricted for capital project | Q9: 38193 | S9: =SUM(K9:R9) -> 38193
B10: Receivables | K10: 728877 | L10: 70383 | M10: 53608 | N10: 33505 | O10: 328111 | P10: 81893 | Q10: 120994 | R10: 69763 | S10: =SUM(K10:R10) -> 1487134
B11: Other assets | K11: 34157 | L11: 16870 | M11: 25655 | P11: 2858 | R11: 3786 | S11: =SUM(K11:R11) -> 83326
E13: Total Assets: | K13: =SUM(K7:K11) -> 1406318 | L13: =SUM(L7:L11) -> 180797 | M13: =SUM(M7:M11) -> 309853 | N13: =SUM(N7:N11) -> 427632 | O13: =SUM(O7:O11) -> 609540 | P13: =SUM(P7:P11) -> 468981 | Q13: =SUM(Q7:Q11) -> 159187 | R13: =SUM(R7:R11) -> 220044 | S13: =SUM(K13:R13) -> 3782352
A15: LIABILITIES, DEFERRED INFLOWS OF RESOURCES, AND FUND BALANCES
B16: Liabilities:
C17: Accounts payable | K17: 275889 | L17: 16405 | M17: 16403 | N17: 53004 | O17: 19547 | P17: 3719 | Q17: 252509 | R17: 3732 | S17: =SUM(K17:R17) -> 641208
C18: Salaries and related payables | K18: 3126 | L18: 5334 | M18: 4695 | R18: 2042 | S18: =SUM(K18:R18) -> 15197
E20: Total liabilities: | K20: =SUM(K17:K18) -> 279015 | L20: =SUM(L17:L18) -> 21739 | M20: =SUM(M17:M18) -> 21098 | N20: =SUM(N17:N18) -> 53004 | O20: =SUM(O17:O18) -> 19547 | P20: =SUM(P17:P18) -> 3719 | R20: =SUM(R17:R18) -> 5774 | S20: =SUM(S17:S18) -> 656405
A22: DEFERRED INFLOWS OF RESROUCES
B23: Ad valorem taxes and state revenue sharing - unavailable | K23: 39308 | O23: 30472 | P23: 7618 | R23: 18659 | S23: =SUM(K23:R23) -> 96057
E25: Total deferred inflows of resources | K25: =SUM(K23:K23) -> 39308 | L25: =SUM(L23:L23) -> 0 | M25: =SUM(M23:M23) -> 0 | N25: =SUM(N23:N23) -> 0 | O25: =SUM(O23:O23) -> 30472 | P25: =SUM(P23:P23) -> 7618 | R25: =SUM(R23:R23) -> 18659 | S25: =SUM(S23:S23) -> 96057
B27: Fund Balances
C28: Restricted | L28: 159058 | M28: 288755 | N28: 374628 | O28: 559521 | P28: 457644 | R28: 195611 | S28: =SUM(K28:R28) -> 2035217
C29: Unassigned | K29: 1087995 | Q29: -93322 | S29: =SUM(K29:R29) -> 994673
E31: Total fund balance: | K31: =SUM(K28:K29) -> 1087995 | L31: =SUM(L28:L29) -> 159058 | M31: =SUM(M28:M29) -> 288755 | N31: =SUM(N28:N29) -> 374628 | O31: =SUM(O28:O29) -> 559521 | P31: =SUM(P28:P29) -> 457644 | R31: =SUM(R28:R29) -> 195611 | S31: =SUM(S28:S29) -> 3029890
E33: Total liabilities, deffered inflows of resources and fund balances: | K33: =K20+K25+K31 -> 1406318 | L33: =L20+L25+L31 -> 180797 | M33: =M20+M25+M31 -> 309853 | N33: =N20+N25+N31 -> 427632 | O33: =O20+O25+O31 -> 609540 | P33: =P20+P25+P31 -> 468981 | R33: =R20+R25+R31 -> 220044 | S33: =S20+S25+S31 -> 3782352

Sheet Claiborne
D1: Claiborne Combined Balance Sheet
D2: Issued: December 31, 2015
K5: General | L5: Parish Road | M5: Library Maintenance | N5: Sales Tax | O5: Criminal Court | P5: Section 8 | Q5: Other Governmental Funds | R5: Total Governmental Funds
A6: Assets:
B7: Cash and cash equivalents | K7: 3626950 | L7: 91142 | M7: 756727 | N7: 955910 | O7: 76321 | P7: 60565 | Q7: 1213056 | R7: =SUM(K7:Q7) -> 6780671
B8: Investments | K8: 434153 | L8: 3042 | M8: 6252 | N8: 344316 | Q8: 5781 | R8: =SUM(K8:Q8) -> 793544
B9: Receivables | K9: 657929 | L9: 1065213 | M9: 744284 | N9: 57637 | Q9: 713435 | R9: =SUM(K9:Q9) -> 3238498
B10: Due from other funds | K10: 1094 | R10: =SUM(K10:Q10) -> 1094
B11: Due from other agencies | K11: 26079 | R11: =SUM(K11:Q11) -> 26079
B12: Deferred charges | K12: 106117 | R12: =SUM(K12:Q12) -> 106117
E14: Total Assets: | K14: =SUM(K7:K12) -> 4852322 | L14: =SUM(L7:L12) -> 1159397 | M14: =SUM(M7:M12) -> 1507263 | N14: =SUM(N7:N12) -> 1357863 | O14: =SUM(O7:O12) -> 76321 | P14: =SUM(P7:P12) -> 60565 | Q14: =SUM(Q7:Q12) -> 1932272 | R14: =SUM(R7:R12) -> 10946003
A16: LIABILITIES, DEFERRED INFLOWS OF RESOURCES, AND FUND BALANCES
B17: Liabilities:
C18: Accounts, salaries and other payables | K18: 210775 | L18: 148647 | M18: 56521 | N18: 55004 | O18: 24911 | Q18: 51778 | R18: =SUM(K18:Q18) -> 547636
C19: Due to other funds | L19: 538 | M19: 456 | Q19: 100 | R19: =SUM(K19:Q19) -> 1094
C20: Due to other agencies | P20: 14025 | R20: =SUM(K20:Q20) -> 14025
E22: Total liabilities: | K22: =SUM(K18:K20) -> 210775 | L22: =SUM(L18:L20) -> 149185 | M22: =SUM(M18:M20) -> 56977 | N22: =SUM(N18:N20) -> 55004 | O22: =SUM(O18:O20) -> 24911 | P22: =SUM(P18:P20) -> 14025 | Q22: =SUM(Q18:Q20) -> 51878 | R22: =SUM(R18:R20) -> 562755
A24: DEFERRED INFLOWS OF RESROUCES
B25: Unavailable ad valorem tax revenue | K25: 43701 | L25: 86001 | M25: 55024 | P25: 15626 | Q25: 57089 | R25: =SUM(K25:Q25) -> 257441
E27: Total deferred inflows of resources | K27: =SUM(K25:K25) -> 43701 | L27: =SUM(L25:L25) -> 86001 | M27: =SUM(M25:M25) -> 55024 | N27: =SUM(N25:N25) -> 0 | O27: =SUM(O25:O25) -> 0 | P27: =SUM(P25:P25) -> 15626 | Q27: =SUM(Q25:Q25) -> 57089 | R27: =SUM(R25:R25) -> 257441
B29: Fund Balances
C30: Restricted fund balances | K30: 369605 | L30: 924211 | M30: 1395262 | N30: 1302859 | O30: 51410 | P30: 30914 | Q30: 1823305 | R30: =SUM(K30:Q30) -> 5897566
C31: Unassigned fund balances | K31: 4228241 | R31: =SUM(K31:Q31) -> 4228241
E33: Total fund balance: | K33: =SUM(K30:K31) -> 4597846 | L33: =SUM(L30:L31) -> 924211 | M33: =SUM(M30:M31) -> 1395262 | N33: =SUM(N30:N31) -> 1302859 | O33: =SUM(O30:O31) -> 51410 | P33: =SUM(P30:P31) -> 30914 | Q33: =SUM(Q30:Q31) -> 1823305 | R33: =SUM(R30:R31) -> 10125807
E35: Total liabilities, deffered inflows of resources and fund balances: | K35: =SUM(K22+K27+K33) -> 4852322 | L35: =SUM(L22+L27+L33) -> 1159397 | M35: =SUM(M22+M27+M33) -> 1507263 | N35: =SUM(N22+N27+N33) -> 1357863 | O35: =SUM(O22+O27+O33) -> 76321 | P35: =SUM(P22+P27+P33) -> 60565 | Q35: =SUM(Q22+Q27+Q33) -> 1932272 | R35: =SUM(R22+R27+R33) -> 10946003

Sheet Concordia
D1: Concordia Combined Balance Sheet
D2: Issued: December 31, 2015
M4: Major Funds
K5: General Fund | L5: Drainage Fund | M5: Sales Tax Fund | N5: Road Debt Service Fund | O5: Highway Maintenance Fund | P5: Nonmajor Governmental Funds | Q5: Total
A6: Assets:
B7: Cash and cash equivalents | K7: 3045095 | L7: 1247237 | M7: 2053953 | O7: 552356 | P7: 997776 | Q7: =SUM(K7:P7) -> 7896417
B8: Cash and cash equivalents - restricted | N8: 2542427 | Q8: =SUM(K8:P8) -> 2542427
B9: Accounts recievable | K9: 48252 | L9: 25193 | O9: 39804 | P9: 16718 | Q9: =SUM(K9:P9) -> 129967
B10: Ad valorem taxes receivable, net | K10: 252973 | L10: 1114404 | P10: 201711 | Q10: =SUM(K10:P10) -> 1569088
B11: Sales and use taxes recievable | M11: 167250 | Q11: =SUM(K11:P11) -> 167250
B12: Severancetaxes receivable | K12: 183685 | Q12: =SUM(K12:P12) -> 183685
B13: Due from other funds | K13: 90748 | L13: 9300 | N13: 72000 | O13: 28000 | P13: 49529 | Q13: =SUM(K13:P13) -> 249577
E15: Total Assets: | K15: =SUM(K7:K13) -> 3620753 | L15: =SUM(L7:L13) -> 2396134 | M15: =SUM(M7:M13) -> 2221203 | N15: =SUM(N7:N13) -> 2614427 | O15: =SUM(O7:O13) -> 620160 | P15: =SUM(P7:P13) -> 1265734 | Q15: =SUM(Q7:Q13) -> 12738411
A17: LIABILITIES
C18: Accounts payable | K18: 31115 | L18: 1009 | M18: 26599 | O18: 9547 | P18: 148708 | Q18: =SUM(K18:P18) -> 216978
C19: Accrued payroll and benefits | K19: 45503 | L19: 25436 | O19: 14205 | P19: 7181 | Q19: =SUM(K19:P19) -> 92325
C20: Due to other funds | K20: 3729 | M20: 245848 | Q20: =SUM(K20:P20) -> 249577
E22: Total liabilities: | K22: =SUM(K18:K20) -> 80347 | L22: =SUM(L18:L20) -> 26445 | M22: =SUM(M18:M20) -> 272447 | N22: =SUM(N18:N20) -> 0 | O22: =SUM(O18:O20) -> 23752 | P22: =SUM(P18:P20) -> 155889 | Q22: =SUM(Q18:Q20) -> 558880
A24: DEFERRED INFLOWS OF RESROUCES
B25: Unavailable ad valorem taxes | K25: 12924 | L25: 56933 | P25: 10305 | Q25: =SUM(K25:P25) -> 80162
E27: Total deferred inflows of resources | K27: =SUM(K25:K25) -> 12924 | L27: =SUM(L25:L25) -> 56933 | M27: =SUM(M25:M25) -> 0 | N27: =SUM(N25:N25) -> 0 | O27: =SUM(O25:O25) -> 0 | P27: =SUM(P25:P25) -> 10305 | Q27: =SUM(Q25:Q25) -> 80162
A29: Fund Balances
C30: Restricted | L30: 2312756 | M30: 1948756 | N30: 2614427 | O30: 596408 | P30: 1019664 | Q30: =SUM(K30:P30) -> 8492011
C31: Unassigned | K31: 3527482 | P31: 79876 | Q31: =SUM(K31:P31) -> 3607358
E33: Total fund balance: | K33: =SUM(K30:K31) -> 3527482 | L33: =SUM(L30:L31) -> 2312756 | M33: =SUM(M30:M31) -> 1948756 | N33: =SUM(N30:N31) -> 2614427 | O33: =SUM(O30:O31) -> 596408 | P33: =SUM(P30:P31) -> 1099540 | Q33: =SUM(Q30:Q31) -> 12099369
E35: Total liabilities, deffered inflows of resources and fund balances: | K35: =SUM(K22+K27+K33) -> 3620753 | L35: =SUM(L22+L27+L33) -> 2396134 | M35: =SUM(M22+M27+M33) -> 2221203 | N35: =SUM(N22+N27+N33) -> 2614427 | O35: =SUM(O22+O27+O33) -> 620160 | P35: =SUM(P22+P27+P33) -> 1265734 | Q35: =SUM(Q22+Q27+Q33) -> 12738411

Sheet DeSoto
D1: DeSoto Combined Balance Sheet
D2: Issued: December 31, 2015
K4: General Fund | L4: Solid Waste Fund | M4: Road Fund | N4: Airport Fund | O4: Jail Fund | P4: Sales Tax | Q4: Other Governmental Funds | R4: Total Governmental Funds
A5: Assets:
B6: Cash and Cash Equivalents | K6: 2168096 | L6: 562724 | M6: 111109 | N6: 145874 | O6: 4729998 | P6: 3000 | Q6: 774183 | R6: =SUM(K6:Q6) -> 8494984
B7: Investments | K7: 7150213 | L7: 6744260 | M7: 10706 | N7: 6947617 | R7: =SUM(K7:Q7) -> 20852796
B8: Revenue Receivables | K8: 4095689 | L8: 4234560 | M8: 4052326 | N8: 121379 | O8: 379 | P8: 629370 | Q8: 77453 | R8: =SUM(K8:Q8) -> 13211156
B9: Inventory | N9: 26264 | R9: =SUM(K9:Q9) -> 26264
B10: Due from Other Funds | K10: 103000 | L10: 92584 | M10: 360118 | O10: 61722 | R10: =SUM(K10:Q10) -> 617424
B11: Noncurrent Receivable | M11: 42000 | R11: =SUM(K11:Q11) -> 42000
E13: Total assets: | K13: =SUM(K6:K11) -> 13516998 | L13: =SUM(L6:L11) -> 11634128 | M13: =SUM(M6:M11) -> 4576259 | N13: =SUM(N6:N11) -> 7241134 | O13: =SUM(O6:O11) -> 4792099 | P13: =SUM(P6:P11) -> 632370 | Q13: =SUM(Q6:Q11) -> 851636 | R13: =SUM(R6:R11) -> 43244624
A15: LIABILITIES AND FUND BALANCES
B16: Liabilities:
C17: Accounts payable | K17: 389042 | L17: 386303 | M17: 377047 | N17: 11112 | O17: 26107 | P17: 12147 | Q17: 156789 | R17: =SUM(K17:Q17) -> 1358547
C18: Due to other funds | K18: 22496 | L18: 29011 | P18: 465917 | Q18: 100000 | R18: =SUM(K18:Q18) -> 617424
C19: Master bank Overdrafts | N19: 50957 | R19: =SUM(K19:Q19) -> 50957
C20: Due to other governments | P20: 154306 | R20: =SUM(K20:Q20) -> 154306
C21: Advance from grantors | Q21: 18938 | R21: =SUM(K21:Q21) -> 18938
C22: Deposits | K22: 300 | R22: =SUM(K22:Q22) -> 300
E24: Total liabilities: | K24: =SUM(K17:K22) -> 411838 | L24: =SUM(L17:L22) -> 415314 | M24: =SUM(M17:M22) -> 377047 | N24: =SUM(N17:N22) -> 62069 | O24: =SUM(O17:O22) -> 26107 | P24: =SUM(P17:P22) -> 632370 | Q24: =SUM(Q17:Q22) -> 275727 | R24: =SUM(R17:R22) -> 2200472
A26: DEFERRED INFLOWS OF RESOURCES
C27: Unavailable Property Taxes | K27: 321345 | L27: 285935 | M27: 268405 | R27: =SUM(K27:Q27) -> 875685
E29: Total deferred inflows of resources | K29: =SUM(K27:K27) -> 321345 | L29: =SUM(L27:L27) -> 285935 | M29: =SUM(M27:M27) -> 268405 | N29: =SUM(N27:N27) -> 0 | O29: =SUM(O27:O27) -> 0 | P29: =SUM(P27:P27) -> 0 | Q29: =SUM(Q27:Q27) -> 0 | R29: =SUM(R27:R27) -> 875685
B31: Fund Balances
C32: Nonspendable:
D33: Inventory | N33: 26264 | R33: =SUM(K33:Q33) -> 26264
C34: Restricted: | R34: =SUM(K34:Q34) -> 0
D35: Airport | N35: 7152801 | R35: =SUM(K35:Q35) -> 7152801
D36: Judicial | Q36: 487 | R36: =SUM(K36:Q36) -> 487
D37: Public Safety | O37: 4765992 | R37: =SUM(K37:Q37) -> 4765992
D38: Roads | M38: 3930807 | R38: =SUM(K38:Q38) -> 3930807
D39: Sanitation | L39: 10932879 | R39: =SUM(K39:Q39) -> 10932879
D40: Health & Welfare | Q40: 72684 | R40: =SUM(K40:Q40) -> 72684
D41: Witness & Juror Fees | Q41: 422295 | R41: =SUM(K41:Q41) -> 422295
C42: Assigned: | R42: =SUM(K42:Q42) -> 0
D43: Animal Control | Q43: 80443 | R43: =SUM(K43:Q43) -> 80443
C44: Unassigned | K44: 12783815 | R44: =SUM(K44:Q44) -> 12783815
E46: Total fund balances: | K46: =SUM(K33:K44) -> 12783815 | L46: =SUM(L33:L44) -> 10932879 | M46: =SUM(M33:M44) -> 3930807 | N46: =SUM(N33:N44) -> 7179065 | O46: =SUM(O33:O44) -> 4765992 | P46: =SUM(P33:P44) -> 0 | Q46: =SUM(Q33:Q44) -> 575909 | R46: =SUM(R33:R44) -> 40168467
E48: Total liabilities and fund balances: | K48: =SUM(K46,K24,K29) -> 13516998 | L48: =SUM(L46,L24,L29) -> 11634128 | M48: =SUM(M46,M24,M29) -> 4576259 | N48: =SUM(N46,N24,N29) -> 7241134 | O48: =SUM(O46,O24,O29) -> 4792099 | P48: =SUM(P46,P24,P29) -> 632370 | Q48: =SUM(Q46,Q24,Q29) -> 851636 | R48: =SUM(R46,R24,R29) -> 43244624

Sheet East Baton Rouge
D1: East Baton Rouge Combined Balance Sheet
D2: Issued: December 31, 2015
K5: General Fund | L5: Library Board of Control | M5: Grants | N5: Capital Projects | O5: Other Governmental Funds | P5: Total Governmental Funds
A6: Assets:
B7: Cash and cash equivalents (note 3) | K7: 29552975 | L7: 28706421 | M7: 3722634 | N7: 55732890 | O7: 41188097 | P7: =SUM(K7:O7) -> 158903017
B8: Investments (note 3) | K8: 40811250 | L8: 39642201 | M8: 5140781 | N8: 76046568 | O8: 40142167 | P8: =SUM(K8:O8) -> 201782967
B9: Property taxes receivable - net (note 4) | K9: 6227741 | L9: 8851423 | O9: 7173814 | P9: =SUM(K9:O9) -> 22252978
B10: Gross receipts business taxes receivable | K10: 4106161 | P10: =SUM(K10:O10) -> 4106161
B11: Sales taxes receivable | K11: 17539310 | N11: 2595295 | O11: 1652437 | P11: =SUM(K11:O11) -> 21787042
B12: Interest and penalties receivable on taxes | K12: 98251 | P12: =SUM(K12:O12) -> 98251
B13: Accounts receivable - net (note 13) | K13: 1609221 | L13: 718 | M13: 2642 | N13: 60870 | O13: 2271963 | P13: =SUM(K13:O13) -> 3945414
B14: Accrued interest receivable | K14: 80788 | L14: 57925 | M14: 6593 | N14: 102824 | O14: 47178 | P14: =SUM(K14:O14) -> 295308
B15: Due from other funds (Note 11) | K15: 9472834 | N15: 37818068 | P15: =SUM(K15:O15) -> 47290902
B16: Due from other governments (Note 11) | K16: 20961465 | L16: 31408708 | M16: 6202760 | N16: 1828373 | O16: 23092159 | P16: =SUM(K16:O16) -> 83493465
B17: Loans receivable | M17: 4115590 | P17: =SUM(K17:O17) -> 4115590
B18: Inventory | K18: 656653 | P18: =SUM(K18:O18) -> 656653
E20: Total Assets: | K20: =SUM(K7:K18) -> 131116649 | L20: =SUM(L7:L18) -> 108667396 | M20: =SUM(M7:M18) -> 19191000 | N20: =SUM(N7:N18) -> 174184888 | O20: =SUM(O7:O18) -> 115567815 | P20: =SUM(P7:P18) -> 548727748
A22: LIABILITIES, DEFERRED INFLOWS OF RESOURCES, AND FUND BALANCES
B23: Liabilities:
C24: Accounts and contracts payable | K24: 13921373 | L24: 1745687 | M24: 3690951 | N24: 4433058 | O24: 2545180 | P24: =SUM(K24:O24) -> 26336249
C25: Due to other funds (Note 11) | L25: 27796921 | O25: 18075097 | P25: =SUM(K25:O25) -> 45872018
C26: Due to other governments | K26: 167662 | O26: 322767 | P26: =SUM(K26:O26) -> 490429
C27: Accrued payables | K27: 2914916 | L27: 298014 | M27: 218814 | N27: 4094 | O27: 475835 | P27: =SUM(K27:O27) -> 3911673
C28: Unearned revenue | M28: 697022 | N28: 398579 | P28: =SUM(K28:O28) -> 1095601
C29: Deposits and escrow accounts | K29: 11142962 | M29: 337129 | P29: =SUM(K29:O29) -> 11480091
E31: Total liabilities: | K31: =SUM(K24:K29) -> 28146913 | L31: =SUM(L24:L30) -> 29840622 | M31: =SUM(M24:M30) -> 4943916 | N31: =SUM(N24:N30) -> 4835731 | O31: =SUM(O24:O30) -> 21418879 | P31: =SUM(P24:P30) -> 89186061
A33: DEFERRED INFLOWS OF RESROUCES
B34: Unavailable revenue- property taxes | K34: 552818 | L34: 726595 | O34: 675093 | P34: =SUM(K34:O34) -> 1954506
B35: Unavailable revenue- revenue sharing | K35: 613417 | O35: 71042 | P35: =SUM(K35:O35) -> 684459
B36: Resources recieved before time requirements | M36: 668996 | P36: =SUM(K36:O36) -> 668996
E38: Total deferred inflows of resources | K38: =SUM(K34:K36) -> 1166235 | L38: =SUM(L34:L36) -> 726595 | M38: =SUM(M34:M36) -> 668996 | N38: =SUM(N34:N36) -> 0 | O38: =SUM(O34:O36) -> 746135 | P38: =SUM(P34:P36) -> 3307961
B40: Fund Balances
C41: Nonspendable | K41: 656653 | P41: =SUM(K41:O41) -> 656653
C42: Restricted | K42: 517487 | L42: 78100179 | M42: 13578088 | N42: 145151310 | O42: 84686576 | P42: =SUM(K42:O42) -> 322033640
C43: Committed | K43: 59144527 | N43: 24197847 | O43: 8716225 | P43: =SUM(K43:O43) -> 92058599
C44: Assigned | K44: 28346341 | P44: =SUM(K44:O44) -> 28346341
C45: Unassigned | K45: 13138493 | P45: =SUM(K45:O45) -> 13138493
E47: Total fund balance: | K47: =SUM(K41:K45) -> 101803501 | L47: =SUM(L41:L45) -> 78100179 | M47: =SUM(M41:M45) -> 13578088 | N47: =SUM(N41:N45) -> 169349157 | O47: =SUM(O41:O45) -> 93402801 | P47: =SUM(P41:P45) -> 456233726
E49: Total liabilities, deffered inflows of resources and fund balances: | K49: =SUM(K31+K38+K47) -> 131116649 | L49: =SUM(L31+L38+L47) -> 108667396 | M49: =SUM(M31+M38+M47) -> 19191000 | N49: =SUM(N31+N38+N47) -> 174184888 | O49: =SUM(O31+O38+O47) -> 115567815 | P49: =SUM(P31+P38+P47) -> 548727748

Sheet East Carroll
D1: East Carroll Combined Balance Sheet
D2: Issued: December 31, 2015
K4: General | L4: Road Maintenance and Construction | M4: Garbage District No. 1 | N4: Library | O4: Drainage Maintenance | P4: Health Unit | Q4: Criminal Court | R4: Nonmajor Governmental | S4: Total
A5: Assets:
B6: Cash and Cash Equivalents | K6: 173636 | L6: 701013 | M6: 4545 | N6: 136346 | O6: 25091 | P6: 494493 | Q6: 1000 | R6: 459622 | S6: =SUM(K6:R6) -> 1995746
B7: Investments | L7: 191686 | M7: 154475 | N7: 211637 | O7: 61709 | P7: 28789 | R7: 70731 | S7: =SUM(K7:R7) -> 719027
B8: Receivables | K8: 643711 | L8: 499843 | M8: 393954 | N8: 334222 | O8: 545162 | P8: 192728 | Q8: 11723 | R8: 286022 | S8: =SUM(K8:R8) -> 2907365
E10: Total assets: | K10: =SUM(K6:K8) -> 817347 | L10: =SUM(L6:L8) -> 1392542 | M10: =SUM(M6:M8) -> 552974 | N10: =SUM(N6:N8) -> 682205 | O10: =SUM(O6:O8) -> 631962 | P10: =SUM(P6:P8) -> 716010 | Q10: =SUM(Q6:Q8) -> 12723 | R10: =SUM(R6:R8) -> 816375 | S10: =SUM(K10:R10) -> 5622138
A12: LIABILITIES, DEFERRED INFLOWS OF RESOURCES, AND FUND BALANCES
B13: Liabilities:
C14: Accounts payable | K14: 88432 | L14: 18098 | M14: 4978 | P14: 21 | Q14: 41 | R14: 109 | S14: =SUM(K14:R14) -> 111679
E16: Total liabilities: | K16: =SUM(K14:K14) -> 88432 | L16: =SUM(L14:L14) -> 18098 | M16: =SUM(M14:M14) -> 4978 | N16: =SUM(N14:N14) -> 0 | O16: =SUM(O14:O14) -> 0 | P16: =SUM(P14:P14) -> 21 | R16: =SUM(R14:R14) -> 109 | S16: =SUM(S14:S14) -> 111679
A18: Deferred Inflows of Resources
B19: Unavailable revenue- property taxes | K19: 34053 | L19: 30733 | M19: 36771 | N19: 30658 | O19: 30733 | P19: 17679 | R19: 26573 | S19: =SUM(K19:R19) -> 207200
E21: Total deferred inflows of resources | K21: =SUM(K17:K19) -> 34053 | L21: =SUM(L17:L19) -> 30733 | M21: =SUM(M17:M19) -> 36771 | N21: =SUM(N17:N19) -> 30658 | O21: =SUM(O17:O19) -> 30733 | P21: =SUM(P17:P19) -> 17679 | R21: =SUM(R17:R19) -> 26573 | S21: =SUM(S17:S19) -> 207200 | T21: =SUM(T17:T19) -> 0 | U21: =SUM(U17:U19) -> 0 | V21: =SUM(V17:V19) -> 0 | W21: =SUM(W17:W19) -> 0 | X21: =SUM(X17:X19) -> 0 | Y21: =SUM(Y17:Y19) -> 0 | ... AA21: =SUM(AA17:AA19) -> 0
A23: Fund Balances
C24: Restricted | L24: 1343711 | M24: 511225 | N24: 651547 | O24: 601229 | P24: 698310 | Q24: 12682 | R24: 789693 | S24: =SUM(K24:R24) -> 4608397
C25: Unassigned | K25: 694862 | S25: =SUM(K25:R25) -> 694862
