Workbook

Sheet Acadia
D1: Acadia Combined Balance Sheet
D2: Issued: December 31, 2014
K4: General Fund | L4: Parish Road Fund | M4: Sales Tax Fund | N4: 1% Sales Tax District No. 2 Fund | O4: Other Governmental Funds | P4: Total Governmental Funds
A5: Assets:
B6: Cash | K6: 540140 | L6: 1236744 | M6: 2071316 | N6: 402027 | O6: 4721780 | P6: =SUM(K6:O6) -> 8972007
B7: Investments | K7: 146420 | L7: 12735 | M7: 4012797 | N7: 137096 | O7: 3587521 | P7: =SUM(K7:O7) -> 7896569
B8: Tax Receivable | K8: 205441 | L8: 125026 | O8: 166701 | P8: =SUM(K8:O8) -> 497168
B9: Special assessments receivable | O9: 18188 | P9: =SUM(K9:O9) -> 18188
B10: Other receivables | K10: 53983 | O10: 2221 | P10: =SUM(K10:O10) -> 56204
B11: Due from other governmental entities, net of allowance | P11: =SUM(K11:O11) -> 0
C12: for doubtful accounts | K12: 1976300 | L12: 1115492 | M12: 596161 | N12: 169936 | O12: 1503096 | P12: =SUM(K12:O12) -> 5360985
B13: Due from other funds | K13: 92143 | P13: =SUM(K13:O13) -> 92143
B14: Due from component units | K14: 20249 | P14: =SUM(K14:O14) -> 20249
E16: Total assets: | K16: =SUM(K6:K14) -> 3034676 | L16: =SUM(L6:L14) -> 2489997 | M16: =SUM(M6:M14) -> 6680274 | N16: =SUM(N6:N14) -> 709059 | O16: =SUM(O6:O14) -> 9999507 | P16: =SUM(P6:P14) -> 22913513
A18: LIABILITIES AND FUND BALANCES
B19: Liabilities:
C20: Accounts payable | K20: 296256 | L20: 30127 | M20: 363174 | N20: 7842 | O20: 174085 | P20: =SUM(K20:O20) -> 871484
C21: Retainage payable | M21: 7879 | P21: =SUM(K21:O21) -> 7879
C22: Accrued liabilities and other payables | K22: 509448 | L22: 41776 | O22: 55702 | P22: =SUM(K22:O22) -> 606926
C23: Unearned revenue | L23: 45000 | P23: =SUM(K23:O23) -> 45000
C24: Due to other funds | L24: 45977 | M24: 30914 | O24: 15252 | P24: =SUM(K24:O24) -> 92143
E26: Total liabilities: | K26: =SUM(K20:K24) -> 805704 | L26: =SUM(L20:L24) -> 162880 | M26: =SUM(M20:M24) -> 401967 | N26: =SUM(N20:N24) -> 7842 | O26: =SUM(O20:O24) -> 245039 | P26: =SUM(P20:P24) -> 1623432
A28: DEFERRED INFLOWS OF RESOURCES
C29: Unavailable revenue- special assessments | O29: 18188 | P29: =SUM(K29:O29) -> 18188
E31: Total deferred inflows of resources | K31: =SUM(K29:K29) -> 0 | L31: =SUM(L29:L29) -> 0 | M31: =SUM(M29:M29) -> 0 | N31: =SUM(N29:N29) -> 0 | O31: =SUM(O29:O29) -> 18188 | P31: =SUM(P29:P29) -> 18188
B33: Fund Balances
C34: Restricted for:
D35: Property tax dedication | K35: 523200 | L35: 2327117 | P35: 2850317
D36: Sales tax dedication | M36: 6278307 | N36: 701217 | P36: 6979524
D37: Debt retirement | O37: 1657465 | P37: 1657465
D38: Mosquito control | O38: 1920316 | P38: 1920316
D39: Cooperative extension operation and maintenance | O39: 1537845 | P39: 1537845
C40: Committed to:
D41: Road maintenance and construction | O41: 978527 | P41: 978527
D42: Health unit operation and maintenance | O42: 1581065 | P42: 1581065
D43: Rice Arena operation and maintenance | O43: 840917 | P43: 840917
C44: Assigned:
D45: Capital projects | O45: 267910 | P45: =SUM(K45:O45) -> 267910
D46: Economic development | O46: 632064 | P46: =SUM(K46:O46) -> 632064
D47: Airport | O47: 276955 | P47: =SUM(K47:O47) -> 276955
...

Sheet Allen
D1: Allen Combined Balance Sheet
D2: Issued: December 31, 2014
K5: General | L5: Solid Waste Fund | M5: Hospital Retrofit Fund | N5: Compact Fund | O5: Parish Road Fund | P5: Road District #2 Mtc. Fund | Q5: Road District #3 Mtc. Fund | R5: Nonmajor Governmental Funds | S5: Total Governmental Funds
A6: Assets:
B7: Cash | K7: 240932 | L7: 547105 | M7: 187 | N7: 294855 | O7: 11995 | P7: 832228 | Q7: 1631244 | R7: 1305121 | S7: =SUM(K7:R7) -> 4863667
B8: Receivables | K8: 234039 | N8: 98228 | P8: 602271 | Q8: 534089 | R8: 1330446 | S8: =SUM(K8:R8) -> 2799073
B9: Due from other governments | K9: 281570 | L9: 131093 | O9: 32096 | R9: 142310 | S9: =SUM(K9:R9) -> 587069
B10: Inventory | R10: 45179 | S10: =SUM(K10:R10) -> 45179
B11: Due from other funds | K11: 41502 | P11: 224 | Q11: 626 | R11: 20107 | S11: =SUM(K11:R11) -> 62459
B12: Prepaid assets | N12: 2989 | S12: =SUM(K12:R12) -> 2989
E14: Total Assets: | K14: =SUM(K7:K12) -> 798043 | L14: =SUM(L7:L12) -> 678198 | M14: =SUM(M7:M12) -> 187 | N14: =SUM(N7:N12) -> 396072 | O14: =SUM(O7:O12) -> 44091 | P14: =SUM(P7:P12) -> 1434723 | Q14: =SUM(Q7:Q12) -> 2165959 | R14: =SUM(R7:R12) -> 2843163 | S14: =SUM(S7:S12) -> 8360436
A16: LIABILITIES AND FUND BALANCES
B17: Liabilities:
C18: Accounts payable | K18: 76705 | L18: 131565 | N18: 11830 | O18: 52130 | P18: 35637 | Q18: 34224 | R18: 284546 | S18: =SUM(K18:R18) -> 626637
C19: Unearned revenue | R19: 48703 | S19: =SUM(K19:R19) -> 48703
C20: Due to other funds | K20: 4923 | N20: 3715 | O20: 24829 | R20: 28992 | S20: =SUM(K20:R20) -> 62459
E22: Total liabilities: | K22: =SUM(K18:K20) -> 81628 | L22: =SUM(L18:L20) -> 131565 | M22: =SUM(M18:M20) -> 0 | N22: =SUM(N18:N20) -> 15545 | O22: =SUM(O18:O20) -> 76959 | P22: =SUM(P18:P20) -> 35637 | Q22: =SUM(Q18:Q20) -> 34224 | R22: =SUM(R18:R20) -> 362241 | S22: =SUM(S18:S20) -> 737799
A24: DEFERRED INFLOWS OF RESROUCES
C25: Unavailable revenue | K25: 20863 | P25: 51888 | Q25: 36961 | R25: 143440 | S25: =SUM(K25:R25) -> 253152
E27: Total deferred inflows of resources | K27: =SUM(K25:K25) -> 20863 | L27: =SUM(L25:L25) -> 0 | M27: =SUM(M25:M25) -> 0 | N27: =SUM(N25:N25) -> 0 | O27: =SUM(O25:O25) -> 0 | P27: =SUM(P25:P25) -> 51888 | Q27: =SUM(Q25:Q25) -> 36961 | R27: =SUM(R25:R25) -> 143440 | S27: =SUM(S25:S25) -> 253152
B29: Fund Balances
C30: Nonspendable - prepaids | N30: 2989 | S30: =SUM(K30:R30) -> 2989
C31: Nonspendable- inventroy | R31: 45179 | S31: =SUM(K31:R31) -> 45179
C32: Restricted: | S32: =SUM(K32:R32) -> 0
D33: Judicial | R33: 707217 | S33: =SUM(K33:R33) -> 707217
D34: Other general government | N34: 377538 | S34: =SUM(K34:R34) -> 377538
D35: Public safety | R35: 874 | S35: =SUM(K35:R35) -> 874
D36: Public works | O36: 32096 | P36: 1347198 | Q36: 2094774 | R36: 1404273 | S36: =SUM(K36:R36) -> 4878341
D37: Economic development | R37: 29735 | S37: =SUM(K37:R37) -> 29735
D38: Sanitation | L38: 546633 | S38: =SUM(K38:R38) -> 546633
D39: Capital projects | M39: 187 | R39: 120650 | S39: =SUM(K39:R39) -> 120837
D40: Debt service | R40: 256 | S40: =SUM(K40:R40) -> 256
C41: Committed: | S41: =SUM(K41:R41) -> 0
D42: Other general government | R42: 1142 | S42: =SUM(K42:R42) -> 1142
C43: Assigned: | S43: =SUM(K43:R43) -> 0
D44: Other general government | R44: 20767 | S44: =SUM(K44:R44) -> 20767
D45: Public works | R45: 8713 | S45: =SUM(K45:R45) -> 8713
C46: Negative unassigned | O46: -64964 | R46: -1324 | S46: =SUM(K46:R46) -> -66288
C47: Unassigned | K47: 695552 | S47: =SUM(K47:R47) -> 695552
E49: Total fund balance: | K49: =SUM(K30:K47) -> 695552 | L49: =SUM(L30:L47) -> 546633 | M49: =SUM(M30:M47) -> 187 | N49: =SUM(N30:N47) -> 380527 | O49: =SUM(O30:O47) -> -32868 | P49: =SUM(P30:P47) -> 1347198 | Q49: =SUM(Q30:Q47) -> 2094774 | R49: =SUM(R30:R47) -> 2337482 | S49: =SUM(S30:S47) -> 7369485
...

Sheet Assumption
D1: Assumption Combined Balance Sheet
D2: Issued: December 31, 2014
K4: General Fund | L4: Sales and Use Tax | M4: Solid Waste | N4: Section Eight Housing | O4: Other Governmental Funds | P4: Total
A5: Assets:
B6: Cash and cash equivalents | K6: 868790 | L6: 198524 | M6: 129671 | N6: 13058 | O6: 1614714 | P6: =SUM(K6:O6) -> 2824757
B7: Investments | K7: 6190618 | L7: 1663083 | M7: 1065776 | O7: 9204014 | P7: =SUM(K7:O7) -> 18123491
B8: Receivables | K8: 1286511 | L8: 300205 | M8: 192531 | N8: 2782 | O8: 3987441 | P8: =SUM(K8:O8) -> 5769470
B9: Due from other funds | K9: 4395 | O9: 55062 | P9: =SUM(K9:O9) -> 59457
E11: Total assets: | K11: =SUM(K6:K9) -> 8350314 | L11: =SUM(L6:L9) -> 2161812 | M11: =SUM(M6:M9) -> 1387978 | N11: =SUM(N6:N9) -> 15840 | O11: =SUM(O6:O9) -> 14861231 | P11: =SUM(P6:P9) -> 26777175
A13: LIABILITIES AND FUND BALANCES
B14: Liabilities:
C15: Accounts payable | K15: 43061 | L15: 17906 | M15: 224 | N15: -1476 | O15: 494562 | P15: =SUM(K15:O15) -> 554277
C16: Salaries payable | K16: 16882 | L16: 20227 | O16: 92776 | P16: =SUM(K16:O16) -> 129885
C17: Due to other funds | K17: 49146 | L17: 3097 | O17: 7214 | P17: =SUM(K17:O17) -> 59457
C18: Other liabilities | K18: 217186 | L18: 11144 | N18: 2144 | O18: 192160 | P18: =SUM(K18:O18) -> 422634
E20: Total liabilities: | K20: =SUM(K15:K18) -> 326275 | L20: =SUM(L15:L18) -> 52374 | M20: =SUM(M15:M18) -> 224 | N20: =SUM(N15:N18) -> 668 | O20: =SUM(O15:O18) -> 786712 | P20: =SUM(P15:P18) -> 1166253
B22: Fund Balances
C23: Restricted | L23: 2109438 | N23: 6673 | O23: 13173048 | P23: =SUM(K23:O23) -> 15289159
C24: Assigned | K24: 36555 | M24: 1387754 | N24: 8499 | O24: 901471 | P24: =SUM(K24:O24) -> 2334279
C25: Unassigned | K25: 7987484 | P25: =SUM(K25:O25) -> 7987484
E27: Total fund balance: | K27: =SUM(K23:K25) -> 8024039 | L27: =SUM(L23:L25) -> 2109438 | M27: =SUM(M23:M25) -> 1387754 | N27: =SUM(N23:N25) -> 15172 | O27: =SUM(O23:O25) -> 14074519 | P27: =SUM(P23:P25) -> 25610922
E29: Total liabilities and fund balances: | K29: =SUM(K27,K20) -> 8350314 | L29: =SUM(L27,L20) -> 2161812 | M29: =SUM(M27,M20) -> 1387978 | N29: =SUM(N27,N20) -> 15840 | O29: =SUM(O27,O20) -> 14861231 | P29: =SUM(P27,P20) -> 26777175

Sheet Avoyelles
D1: Avoyelles Combined Balance Sheet
D2: Issued: December 31, 2014
K4: General | L4: Road & Bridge | M4: Solid Waste | N4: Drainage | O4: Health Unit | P4: Library | Q4: Section 8 | R4: Brudd Construction LCDBG | S4: Other Governmental Funds | T4: Total Governmental Funds
A5: Assets:
B6: Cash and interest-bearing deposits | K6: 858064 | L6: 1095076 | M6: 3825801 | N6: 463470 | O6: 1699451 | P6: 983701 | Q6: 207348 | R6: 33 | S6: 310915 | T6: =SUM(K6:S6) -> 9443859
B7: Receivables | K7: 54360 | Q7: 1299 | S7: 774 | T7: =SUM(K7:S7) -> 56433
B8: Due from other governmental units | K8: 366301 | L8: 182785 | M8: 274162 | N8: 418315 | O8: 479260 | P8: 740903 | R8: 149799 | S8: 20369 | T8: =SUM(K8:S8) -> 2631894
B9: Due from other funds | S9: 2153 | T9: =SUM(K9:S9) -> 2153
B10: Prepaid items | K10: 38135 | L10: 29523 | M10: 22694 | N10: 15137 | O10: 8637 | P10: 29863 | Q10: 1109 | S10: 3622 | T10: =SUM(K10:S10) -> 148720
E12: Total Assets: | K12: =SUM(K6:K10) -> 1316860 | L12: =SUM(L6:L10) -> 1307384 | M12: =SUM(M6:M10) -> 4122657 | N12: =SUM(N6:N10) -> 896922 | O12: =SUM(O6:O10) -> 2187348 | P12: =SUM(P6:P10) -> 1754467 | Q12: =SUM(Q6:Q10) -> 209756 | R12: =SUM(R6:R10) -> 149832 | ... T12: =SUM(T6:T10) -> 12283059
A14: LIABILITIES, DEFERRED INFLOWS OF RESOURCES AND FUND BALANCES
B16: Liabilities:
C17: Accounts, salaries, and other payables | K17: 122570 | L17: 57110 | M17: 259132 | N17: 29119 | O17: 23273 | P17: 53739 | Q17: 1638 | R17: 149799 | S17: 16022 | T17: =SUM(K17:S17) -> 712402
C18: Unearned revenue | Q18: 36260 | T18: =SUM(K18:S18) -> 36260
C19: Due to other funds | K19: 2153 | T19: =SUM(K19:S19) -> 2153
E21: Total liabilities: | K21: =SUM(K17:K19) -> 124723 | L21: =SUM(L17:L19) -> 57110 | M21: =SUM(M17:M19) -> 259132 | N21: =SUM(N17:N20) -> 29119 | O21: =SUM(O17:O19) -> 23273 | P21: =SUM(P17:P19) -> 53739 | Q21: =SUM(Q17:Q19) -> 37898 | R21: =SUM(R17:R19) -> 149799 | S21: =SUM(S17:S19) -> 16022 | T21: =SUM(T17:T19) -> 750815
A23: DEFERRED INFLOWS OF RESOURCES
C24: Unavailable revenue | K24: 78528 | N24: 62869 | O24: 71834 | P24: 111343 | T24: =SUM(K24:S24) -> 324574
B26: Fund Balances
C27: Nonspendable | K27: 38135 | L27: 29523 | M27: 22694 | N27: 15137 | O27: 8637 | P27: 29863 | Q27: 1109 | S27: 3622 | T27: =SUM(K27:S27) -> 148720
C28: Restricted | T28: =SUM(K28:S28) -> 0
D29: Public safety | S29: 24786 | T29: =SUM(K29:S29) -> 24786
D30: Public works | L30: 1220751 | M30: 3840831 | N30: 789797 | R30: 33 | S30: 74395 | T30: =SUM(K30:S30) -> 5925807
D31: Health and welfare | O31: 2083604 | Q31: 170749 | T31: =SUM(K31:S31) -> 2254353
D32: Culture and recreation | P32: 1559522 | T32: =SUM(K32:S32) -> 1559522
D33: Economic development | S33: 222948 | T33: =SUM(K33:S33) -> 222948
C34: Unassigned (deficit) | K34: 1075474 | S34: -3940 | T34: =SUM(K34:S34) -> 1071534
E36: Total fund balance: | K36: =SUM(K27:K35) -> 1113609 | L36: =SUM(L27:L34) -> 1250274 | M36: =SUM(M27:M34) -> 3863525 | N36: =SUM(N27:N34) -> 804934 | O36: =SUM(O27:O34) -> 2092241 | P36: =SUM(P27:P34) -> 1589385 | Q36: =SUM(Q27:Q34) -> 171858 | R36: =SUM(R27:R34) -> 33 | S36: =SUM(S27:S34) -> 321811 | T36: =SUM(T27:T34) -> 11207670
E38: Total liabilities and fund balances: | K38: =SUM(K36+K24+K21) -> 1316860 | L38: =SUM(L36+L24+L21) -> 1307384 | M38: =SUM(M36+M24+M21) -> 4122657 | N38: =SUM(N36+N24+N21) -> 896922 | O38: =SUM(O36+O24+O21) -> 2187348 | P38: =SUM(P36+P24+P21) -> 1754467 | Q38: =SUM(Q36+Q24+Q21) -> 209756 | R38: =SUM(R36+R24+R21) -> 149832 | ... T38: =SUM(T36+T24+T21) -> 12283059

Sheet Beauregard
D1: Beauregard Combined Balance Sheet
D2: Issued: December 31, 2014
K4: General Fund | L4: Parishwide Road Special Revenue | M4: Road District No. 6 Special Revenue | N4: Sales Tax District No. 1 Special Revenue | O4: Health Unit Special Revenue | P4: Criminal Court Special Revenue | Q4: South Beau. Rec. Dist. No. 2 Special Revenue | R4: South Beau. Rec. Dist. No. 2 Capital Projects | S4: Nonmajor Governmental Funds | T4: Total Governmental Funds
A5: Assets:
B6: Equity in pooled cash | K6: 558156 | L6: 964630 | M6: 789100 | N6: 3863482 | O6: 2026435 | P6: 24397 | Q6: 868165 | R6: 227293 | S6: 8224114 | T6: =SUM(K6:S6) -> 17545772
B7: Receivables | K7: 1052346 | L7: 44561 | M7: 955138 | N7: 753419 | O7: 562752 | P7: 51243 | Q7: 534125 | S7: 3020561 | T7: =SUM(K7:S7) -> 6974145
B8: Interfund receivable | K8: 23950 | L8: 11404 | R8: 75510 | T8: =SUM(K8:S8) -> 110864
B9: Inventory | M9: 31579 | S9: 172931 | T9: =SUM(K9:S9) -> 204510
E11: Total assets: | K11: =SUM(K6:K9) -> 1634452 | L11: =SUM(L6:L9) -> 1020595 | M11: =SUM(M6:M9) -> 1775817 | N11: =SUM(N6:N9) -> 4616901 | O11: =SUM(O6:O9) -> 2589187 | P11: =SUM(P6:P9) -> 75640 | Q11: =SUM(Q6:Q9) -> 1402290 | R11: =SUM(R6:R9) -> 302803 | ... T11: =SUM(T6:T9) -> 24835291
A13: LIABILITIES
B14: Liabilities:
C15: Accounts payable | K15: 147115 | L15: 9960 | M15: 106431 | N15: 125706 | O15: 20011 | P15: 24755 | Q15: 19134 | R15: 169925 | S15: 225745 | T15: =SUM(K15:S15) -> 848782
C16: Payroll liabilities | K16: 179556 | T16: =SUM(K16:S16) -> 179556
C17: Interfund payable | S17: 110864 | T17: =SUM(K17:S17) -> 110864
E19: Total liabilities: | K19: =SUM(K15:K17) -> 326671 | L19: =SUM(L15:L17) -> 9960 | M19: =SUM(M15:M17) -> 106431 | N19: =SUM(N15:N17) -> 125706 | O19: =SUM(O15:O17) -> 20011 | P19: =SUM(P15:P17) -> 24755 | Q19: =SUM(Q15:Q17) -> 19134 | R19: =SUM(R15:R17) -> 169925 | ... T19: =SUM(T15:T17) -> 1139202
A21: DEFERRED INFLOWS OF RESOURCES
B22: Unavailable revenue | K22: 142282 | M22: 18968 | O22: 17879 | Q22: 6802 | S22: 96186 | T22: =SUM(K22:S22) -> 282117
C23: Total deferred inflows of resources | K23: =K22 -> 142282 | L23: =L22 -> 0 | M23: =M22 -> 18968 | N23: =N22 -> 0 | O23: =O22 -> 17879 | P23: =P22 -> 0 | Q23: =Q22 -> 6802 | R23: =R22 -> 0 | ... T23: =T22 -> 282117
B25: Fund Balances:
C26: Nonspendable - inventory | M26: 31579 | S26: 172931 | T26: =SUM(K26:S26) -> 204510
C27: Restricted:
D28: Purchases of equipment | L28: 306908 | T28: =SUM(K28:S28) -> 306908
D29: Public safety | S29: 1932609 | T29: =SUM(K29:S29) -> 1932609
D30: Public works | L30: 703727 | M30: 1618839 | S30: 4220434 | T30: =SUM(K30:S30) -> 6543000
D31: Health and welfare | O31: 2551297 | T31: =SUM(K31:S31) -> 2551297
D32: Culture and recreation | S32: 536904 | T32: =SUM(K32:S32) -> 536904
D33: Sanitation | N33: 4491195 | T33: =SUM(K33:S33) -> 4491195
D34: Other general government | S34: 151475 | T34: =SUM(K34:S34) -> 151475
D35: Capital projects | S35: 3820546 | T35: =SUM(K35:S35) -> 3820546
D36: Debt service | S36: 149912 | T36: =SUM(K36:S36) -> 149912
C37: Unassigned | K37: 1165499 | P37: 50885 | Q37: 1376354 | R37: 132878 | T37: =SUM(K37:S37) -> 2725616
E39: Total fund balance: | K39: =SUM(K26:K37) -> 1165499 | L39: =SUM(L26:L37) -> 1010635 | M39: =SUM(M26:M37) -> 1650418 | N39: =SUM(N26:N37) -> 4491195 | O39: =SUM(O26:O37) -> 2551297 | P39: =SUM(P26:P37) -> 50885 | Q39: =SUM(Q26:Q37) -> 1376354 | R39: =SUM(R26:R37) -> 132878 | ... T39: =SUM(T26:T37) -> 23413972
E41: Total liabilities, deferred inflows of resources, and fund balances: | K41: =K39+K22+K19 -> 1634452 | L41: =L39+L22+L19 -> 1020595 | M41: =M39+M22+M19 -> 1775817 | N41: =N39+N22+N19 -> 4616901 | O41: =O39+O22+O19 -> 2589187 | P41: =P39+P22+P19 -> 75640 | Q41: =Q39+Q22+Q19 -> 1402290 | R41: =R39+R22+R19 -> 302803 | ... T41: =T39+T22+T19 -> 24835291

Sheet Bienville
D1: Bienville Combined Balance Sheet
D2: Issued: December 31, 2014
K4: General Fund | L4: Road Maintenance | M4: Solid Waste | N4: Debt Service Fund | O4: Other Governmental Funds | P4: Total
A5: Assets:
B6: Cash and cash equivalents | K6: 4705355 | L6: 7519393 | M6: 3666093 | N6: 1027431 | O6: 248630 | P6: =SUM(K6:O6) -> 17166902
B7: Receivables | K7: 1810762 | L7: 1957619 | M7: 367810 | N7: 1131815 | O7: 6442 | P7: =SUM(K7:O7) -> 5274448
E9: Total assets: | K9: =SUM(K6:K7) -> 6516117 | L9: =SUM(L6:L7) -> 9477012 | M9: =SUM(M6:M7) -> 4033903 | N9: =SUM(N6:N7) -> 2159246 | O9: =SUM(O6:O7) -> 255072 | P9: =SUM(P6:P7) -> 22441350
A11: LIABILITIES AND FUND BALANCES
B12: Liabilities:
C13: Accounts payable | K13: 93421 | L13: 21716 | M13: 95478 | P13: =SUM(K13:O13) -> 210615
C14: Salaries and related payable | K14: 7411 | L14: 22841 | P14: =SUM(K14:O14) -> 30252
C15: Deferred revenues | K15: 70000 | P15: =SUM(K15:O15) -> 70000
E17: Total liabilities: | K17: =SUM(K13:K15) -> 170832 | L17: =SUM(L13:L15) -> 44557 | M17: =SUM(M13:M15) -> 95478 | N17: =SUM(N13:N15) -> 0 | O17: =SUM(O13:O15) -> 0 | P17: =SUM(P13:P15) -> 310867
B19: Fund Balances
C20: Non spendable | O20: 16 | P20: =SUM(K20:O20) -> 16
C21: Restricted | P21: =SUM(K21:O21) -> 0
D22: Other general government | O22: 146447 | P22: =SUM(K22:O22) -> 146447
D23: Public works | L23: 9432455 | M23: 3938425 | O23: 14464 | P23: =SUM(K23:O23) -> 13385344
D24: Health and welfare | O24: 57744 | P24: =SUM(K24:O24) -> 57744
D25: Economic development | O25: 34025 | P25: =SUM(K25:O25) -> 34025
C26: Assigned | N26: 2159246 | O26: 2376 | P26: =SUM(K26:O26) -> 2161622
C27: Unassigned | K27: 6345285 | P27: =SUM(K27:O27) -> 6345285
E29: Total fund balance: | K29: =SUM(K21:K27) -> 6345285 | L29: =SUM(L21:L27) -> 9432455 | M29: =SUM(M21:M27) -> 3938425 | N29: =SUM(N21:N27) -> 2159246 | O29: =SUM(O20:O27) -> 255072 | P29: =SUM(P20:P27) -> 22130483
E31: Total liabilities and fund balances: | K31: =SUM(K29,K17) -> 6516117 | L31: =SUM(L29,L17) -> 9477012 | M31: =SUM(M29,M17) -> 4033903 | N31: =SUM(N29,N17) -> 2159246 | O31: =SUM(O29,O17) -> 255072 | P31: =SUM(P29,P17) -> 22441350

Sheet Bossier
D1: Bossier Combined Balance Sheet
D2: Issued: December 31, 2014
K5: General | L5: HIghway | M5: Library | N5: Capital Improvement | O5: LCDA Sewer Construction | P5: Corrections | Q5: LCDA Public Improvements | R5: Other Governmental Funds | S5: Total Governmental Funds
A6: Assets:
B7: Cash and cash equivalents | K7: 4175695 | L7: 5369423 | M7: 8807171 | N7: 8191172 | O7: 66569 | P7: 2403514 | Q7: 1542077 | R7: 9948521 | S7: =SUM(K7:R7) -> 40504142
B8: Investments | K8: 170335 | S8: =SUM(K8:R8) -> 170335
B9: Receivables | K9: 2966234 | L9: 4354103 | M9: 7367030 | N9: 1053726 | P9: 2971772 | Q9: 3324947 | R9: 1036700 | S9: =SUM(K9:R9) -> 23074512
B10: Restricted cash | M10: 21875 | O10: 3037776 | R10: 1819576 | S10: =SUM(K10:R10) -> 4879227
B11: Due from other funds | K11: 69371 | R11: 6373 | S11: =SUM(K11:R11) -> 75744
B12: Advance to waterworks/sewer district | O12: 8243332 | S12: =SUM(K12:R12) -> 8243332
E14: Total Assets: | K14: =SUM(K7:K12) -> 7381635 | L14: =SUM(L7:L12) -> 9723526 | M14: =SUM(M7:M12) -> 16196076 | N14: =SUM(N7:N12) -> 9244898 | O14: =SUM(O7:O12) -> 11347677 | P14: =SUM(P7:P12) -> 5375286 | Q14: =SUM(Q7:Q12) -> 4867024 | R14: =SUM(R7:R12) -> 12811170 | S14: =SUM(S7:S12) -> 76947292
A16: LIABILITIES, DEFERRED INFLOWS OF RESOURCES, AND FUND BALANCES
B17: Liabilities:
C18: Accounts payable | K18: 353048 | L18: 526769 | M18: 384043 | N18: 56514 | P18: 248149 | Q18: 3324947 | R18: 223062 | S18: =SUM(K18:R18) -> 5116532
C19: Due to other funds | L19: 55782 | N19: 11300 | R19: 8662 | S19: =SUM(K19:R19) -> 75744
E21: Total liabilities: | K21: =SUM(K18:K19) -> 353048 | L21: =SUM(L18:L19) -> 582551 | M21: =SUM(M18:M19) -> 384043 | N21: =SUM(N18:N19) -> 67814 | O21: =SUM(O18:O19) -> 0 | P21: =SUM(P18:P19) -> 248149 | Q21: =SUM(Q18:Q19) -> 3324947 | R21: =SUM(R18:R19) -> 231724 | S21: =SUM(S18:S19) -> 5192276
A23: DEFERRED INFLOWS OF RESROUCES
B24: Unavailable revenue
C25: Property taxes | K25: 1948025 | L25: 1966068 | M25: 7404640 | P25: 2934461 | R25: 811884 | S25: =SUM(K25:R25) -> 15065078
C26: Other | K26: 73369 | L26: 450013 | M26: 5117 | N26: 16695 | P26: 4747 | Q26: 113041 | R26: 6963 | S26: =SUM(K26:R26) -> 669945
E28: Total deferred inflows of resources | K28: =SUM(K24:K26) -> 2021394 | L28: =SUM(L24:L26) -> 2416081 | M28: =SUM(M24:M26) -> 7409757 | N28: =SUM(N24:N26) -> 16695 | O28: =SUM(O24:O26) -> 0 | P28: =SUM(P24:P26) -> 2939208 | Q28: =SUM(Q24:Q26) -> 113041 | R28: =SUM(R24:R26) -> 818847 | S28: =SUM(S24:S26) -> 15735023
B30: Fund Balances
C31: Nonspendable | O31: 8243332 | S31: =SUM(K31:R31) -> 8243332
C32: Restricted | M32: 8009313 | N32: 9022454 | O32: 3104345 | P32: 748940 | R32: 6720965 | S32: =SUM(K32:R32) -> 27606017
C33: Assigned | K33: 3087683 | L33: 6724894 | M33: 392963 | N33: 137935 | P33: 1438989 | Q33: 1429036 | R33: 5039634 | S33: =SUM(K33:R33) -> 18251134
C34: Unassigned | K34: 1919510 | S34: =SUM(K34:R34) -> 1919510
E36: Total fund balance: | K36: =SUM(K31:K34) -> 5007193 | L36: =SUM(L31:L34) -> 6724894 | M36: =SUM(M31:M34) -> 8402276 | N36: =SUM(N31:N34) -> 9160389 | O36: =SUM(O31:O34) -> 11347677 | P36: =SUM(P31:P34) -> 2187929 | Q36: =SUM(Q31:Q34) -> 1429036 | R36: =SUM(R31:R34) -> 11760599 | S36: =SUM(S31:S34) -> 56019993
E38: Total liabilities, deffered inflows of resources and fund balances: | K38: =SUM(K21+K28+K36) -> 7381635 | L38: =SUM(L21+L28+L36) -> 9723526 | M38: =SUM(M21+M28+M36) -> 16196076 | N38: =SUM(N21+N28+N36) -> 9244898 | O38: =SUM(O21+O28+O36) -> 11347677 | P38: =SUM(P21+P28+P36) -> 5375286 | Q38: =SUM(Q21+Q28+Q36) -> 4867024 | R38: =SUM(R21+R28+R36) -> 12811170 | S38: =SUM(S21+S28+S36) -> 76947292

Sheet Caddo
D1: Caddo Combined Balance Sheet
D2: Issued: December 31, 2014
K4: General Fund | L4: Shreve Memorial Library Fund | M4: Detention Facilities Fund | N4: Solid Waste Disposal Fund | O4: Public Works Fund | P4: Head Start Fund | Q4: Biomedical Fund | R4: Capital Outlay Fund | S4: Criminal Justice Fund | T4: Other Governmental Funds | U4: Total Governmental Funds
A5: Assets:
B6: Cash and cash equivalents | K6: 4050798 | L6: 4652337 | M6: 74242 | N6: 1836315 | O6: 1161308 | R6: 1278346 | T6: 2423536 | U6: =SUM(K6:T6) -> 15476882
B7: Investments | K7: 42798639 | M7: 790823 | N7: 19398481 | O7: 12267698 | R7: 13509976 | T7: 25597710 | U7: =SUM(K7:T7) -> 114363327
B8: Receivables, net:
C9: Ad valorem taxes | K9: 6259610 | L9: 14004529 | M9: 7984497 | O9: 6242739 | Q9: 2647217 | S9: 4861016 | T9: 13798567 | U9: =SUM(K9:T9) -> 55798175
C10: Paving assessments | O10: 210777 | U10: =SUM(K10:T10) -> 210777
C11: Other | K11: 64493 | M11: 208 | N11: 10948 | T11: 215445 | U11: =SUM(K11:T11) -> 291094
C12: Accrued interest | K12: 133264 | M12: 2442 | N12: 60412 | O12: 38201 | R12: 42055 | T12: 79722 | U12: =SUM(K12:T12) -> 356096
B13: Due from other funds | K13: 1191129 | L13: 223421 | M13: 110701 | N13: 530502 | O13: 432651 | R13: 455926 | T13: 1284047 | U13: =SUM(K13:T13) -> 4228377
B14: Due from other governments | K14: 158300 | L14: 259508 | M14: 181778 | N14: 554903 | O14: 1615801 | Q14: 49200 | S14: 89329 | T14: 596025 | U14: =SUM(K14:T14) -> 3504844
B15: Inventories | O15: 97808 | U15: =SUM(K15:T15) -> 97808
B16: Other assets | L16: 116149 | U16: =SUM(K16:T16) -> 116149
E18: Total assets: | K18: =SUM(K6:K16) -> 54656233 | L18: =SUM(L6:L16) -> 19255944 | M18: =SUM(M6:M16) -> 9144691 | N18: =SUM(N6:N16) -> 22391561 | O18: =SUM(O6:O16) -> 22066983 | P18: =SUM(P6:P16) -> 0 | Q18: =SUM(Q6:Q16) -> 2696417 | R18: =SUM(R6:R16) -> 15286303 | ... U18: =SUM(U6:U16) -> 194443529
A20: LIABILITIES AND FUND BALANCES
B21: Liabilities:
C22: Accounts payable | K22: 117176 | L22: 223421 | M22: 167064 | N22: 282200 | O22: 556181 | Q22: 230614 | R22: 632951 | T22: 626010 | U22: =SUM(K22:T22) -> 2835617
C23: Accrued liabilities | K23: 154394 | L23: 155575 | M23: 29305 | N23: 54604 | O23: 153622 | T23: 371076 | U23: =SUM(K23:T23) -> 918576
C24: Retainage payable | R24: 353334 | U24: =SUM(K24:T24) -> 353334
C25: Due to other funds | Q25: 1539057 | S25: 2813006 | T25: 223421 | U25: =SUM(K25:T25) -> 4575484
C26: Unearned revenue | K26: 35478 | U26: =SUM(K26:T26) -> 35478
C27: Due to component units | M27: 520956 | U27: =SUM(K27:T27) -> 520956
C28: Due to other governments | K28: 14769 | N28: 3202 | O28: 12845 | S28: 78154 | T28: 9176 | U28: =SUM(K28:T28) -> 118146
E30: Total liabilities: | K30: =SUM(K22:K28) -> 321817 | L30: =SUM(L22:L28) -> 378996 | M30: =SUM(M22:M28) -> 717325 | N30: =SUM(N22:N28) -> 340006 | O30: =SUM(O22:O28) -> 722648 | P30: =SUM(P22:P28) -> 0 | Q30: =SUM(Q22:Q28) -> 1769671 | R30: =SUM(R22:R28) -> 986285 | ... U30: =SUM(U22:U28) -> 9357591
A32: DEFERRED INFLOWS OF RESOURCES
B33: Unavailable revenue - property taxes | K33: 66472 | L33: 123269 | M33: 76073 | O33: 52029 | Q33: 15517 | S33: 21548 | T33: 119337 | U33: =SUM(K33:T33) -> 474245
B34: Unavailable revenue - special assessments | O34: 106570 | U34: =SUM(K34:T34) -> 106570
E36: Total deferred inflows: | K36: =SUM(K33:K34) -> 66472 | L36: =SUM(L33:L34) -> 123269 | M36: =SUM(M33:M34) -> 76073 | N36: =SUM(N33:N34) -> 0 | O36: =SUM(O33:O34) -> 158599 | P36: =SUM(P33:P34) -> 0 | Q36: =SUM(Q33:Q34) -> 15517 | R36: =SUM(R33:R34) -> 0 | ... U36: =SUM(U33:U34) -> 580815
B38: Fund Balances:
C39: Nonspendable:
D40: Prepaid expenses | L40: 116149 | U40: =SUM(K40:T40) -> 116149
C41: Restricted for:
D42: Criminal justice | M42: 8121127 | S42: 1999865 | T42: 3624174 | U42: =SUM(K42:T42) -> 13745166
D43: Health and welfare | T43: 4552822 | U43: =SUM(K43:T43) -> 4552822
D44: Highways, streets and drainage | O44: 19345933 | U44: =SUM(K44:T44) -> 19345933
D45: Building facilities | T45: 7739454 | U45: =SUM(K45:T45) -> 7739454
D46: Sanitation | N46: 21744403 | U46: =SUM(K46:T46) -> 21744403
D47: Culture and recreation | L47: 18637530 | T47: 3065257 | U47: =SUM(K47:T47) -> 21702787
...

Sheet Calcasieu
D1: Calcasieu Combined Balance Sheet
D2: Issued: December 31, 2014
K4: General Fund | L4: Public Works Operating Fund | M4: Office of Juvenille Justice Services Fund | N4: Calcasieu Parish Library Fund | O4: Road Capital Improvement Fund | P4: Nonmajor Governmental Funds | Q4: Total Governmental Funds
A5: Assets:
B6: Cash and Cash Equivalents | K6: 13551446 | L6: 6565108 | M6: 1654498 | N6: 1265610 | O6: 24111044 | P6: 9718103 | Q6: =SUM(K6:P6) -> 56865809
B7: Investments | K7: 47934238 | L7: 24075466 | M7: 6045826 | N7: 4625424 | O7: 88207759 | P7: 32237731 | Q7: =SUM(K7:P7) -> 203126444
B8: Receivable (net of allowance for uncollectibles):
C9: Property taxes | K9: 11445770 | M9: 5978869 | N9: 9886992 | O9: 5955341 | P9: 13393692 | Q9: =SUM(K9:P9) -> 46660664
C10: Sales taxes | L10: 883373 | O10: 1664193 | P10: 611253 | Q10: =SUM(K10:P10) -> 3158819
C11: Franchise taxes | K11: 306693 | Q11: =SUM(K11:P11) -> 306693
B12: Interest receivable | K12: 87255 | L12: 40812 | M12: 11252 | N12: 9545 | O12: 149696 | P12: 56962 | Q12: =SUM(K12:P12) -> 355522
B13: Other receivables | K13: 3963032 | M13: 25357 | N13: 29 | P13: 93232 | Q13: 4081650
B14: Intergovernmental receivable | K14: 252131 | L14: 4460 | M14: 223705 | O14: 322310 | P14: 1194029 | Q14: =SUM(K14:P14) -> 1996635
B15: Due from other funds | K15: 547460 | M15: 1505 | N15: 4456 | P15: 169048 | Q15: =SUM(K15:P15) -> 722469
B16: Due from component units | K16: 26195 | P16: 930 | Q16: =SUM(K16:P16) -> 27125
B17: Loans receivable | K17: 33189 | Q17: =SUM(K17:P17) -> 33189
B18: Prepaid items | M18: 30746 | P18: 35170 | Q18: =SUM(K18:P18) -> 65916
B19: Inventory | L19: 747312 | P19: 428089 | Q19: =SUM(K19:P19) -> 1175401
E21: Total assets: | K21: =SUM(K6:K19) -> 78147409 | L21: =SUM(L6:L19) -> 32316531 | M21: =SUM(M6:M19) -> 13971758 | N21: =SUM(N6:N19) -> 15792056 | O21: =SUM(O6:O19) -> 120410343 | P21: =SUM(P6:P19) -> 57938239 | Q21: =SUM(Q6:Q19) -> 318576336
A23: LIABILITIES AND FUND BALANCES
B24: Liabilities:
C25: Accounts payable | K25: 1530460 | L25: 1066469 | M25: 132234 | N25: 104967 | O25: 1416409 | P25: 1285041 | Q25: =SUM(K25:P25) -> 5535580
C26: Accrued liabilities | K26: 297380 | L26: 235919 | M26: 109926 | N26: 140146 | P26: 116324 | Q26: =SUM(K26:P26) -> 899695
C27: Intergovernmental payable | P27: 292884 | Q27: =SUM(K27:P27) -> 292884
C28: Due to other funds | K28: 175076 | P28: 563212 | Q28: =SUM(K28:P28) -> 738288
C29: Due to component units | K29: 26439 | L29: 308 | P29: 29834 | Q29: =SUM(K29:P29) -> 56581
C30: Unearned revenue | K30: 2292 | M30: 29765 | P30: 1054250 | Q30: =SUM(K30:P30) -> 1086307
C31: Retainage payable | K31: 34899 | L31: 26341 | N31: 4456 | O31: 175177 | P31: 255072 | Q31: =SUM(K31:P31) -> 495945
C32: Other liabilities | K32: 92400 | L32: 86320 | P32: 38598 | Q32: =SUM(K32:P32) -> 217318
C33: Enterprize zone rebate liability | L33: 154500 | Q33: 154500
E35: Total liabilities: | K35: =SUM(K25:K32) -> 2158946 | L35: =SUM(L25:L33) -> 1569857 | M35: =SUM(M25:M33) -> 271925 | N35: =SUM(N25:N32) -> 249569 | O35: =SUM(O25:O32) -> 1591586 | P35: =SUM(P25:P32) -> 3635215 | Q35: =SUM(Q25:Q33) -> 9477098
A37: DEFERRED INFLOWS OF RESOURCES
C38: Property taxes levied for the next fiscal year | K38: 11531978 | M38: 6037189 | N38: 9982988 | O38: 6023191 | P38: 13520745 | Q38: 47096091
C39: Unavailable revenue | M39: 8532 | P39: 17026 | Q39: =SUM(K39:P39) -> 25558
E41: Total deferred inflows of resources | K41: =SUM(K38:K39) -> 11531978 | L41: =SUM(L38:L39) -> 0 | M41: =SUM(M38:M39) -> 6045721 | N41: =SUM(N38:N39) -> 9982988 | O41: =SUM(O38:O39) -> 6023191 | P41: =SUM(P38:P39) -> 13537771 | Q41: =SUM(Q38:Q39) -> 47121649
B43: Fund Balances
C44: Nonspendable:
D45: Prepaid items | M45: 30746 | P45: 35170 | Q45: =SUM(K45:P45) -> 65916
D46: Inventories | L46: 747312 | P46: 428089 | Q46: =SUM(K46:P46) -> 1175401
D47: Loans receivable | K47: 25764 | Q47: =SUM(K47:P47) -> 25764
...

Sheet Caldwell
D1: Caldwell Combined Balance Sheet
D2: Issued: December 31, 2014
K4: General Fund | L4: Road Maintenance | M4: Recreation | N4: Solid Waste | O4: Blacktop Road | P4: Bayou Dechere Resevoir | Q4: LCDBG | R4: Other Governmental Funds | S4: Total Governmental Funds
A5: Assets:
B6: Cash and Cash Equivalents | K6: 1128303 | L6: 392947 | M6: 695339 | N6: 2048365 | O6: 1975178 | P6: 115740 | Q6: 40 | R6: 1504656 | S6: =SUM(K6:R6) -> 7860568
B7: Investments | K7: 292218 | L7: 520897 | M7: 309967 | N7: 103678 | R7: 594637 | S7: =SUM(K7:R7) -> 1821397
B8: Due from other funds | K8: 2700 | L8: 25652 | R8: 36402 | S8: =SUM(K8:R8) -> 64754
E10: Total assets: | K10: =SUM(K6:K8) -> 1423221 | L10: =SUM(L6:L8) -> 939496 | M10: =SUM(M6:M8) -> 1005306 | N10: =SUM(N6:N8) -> 2152043 | O10: =SUM(O6:O8) -> 1975178 | P10: =SUM(P6:P8) -> 115740 | Q10: =SUM(Q6:Q8) -> 40 | R10: =SUM(R6:R8) -> 2135695 | S10: =SUM(S6:S8) -> 9746719
A12: LIABILITIES AND FUND BALANCES
B13: Liabilities:
C14: Accounts payable | K14: 80438 | L14: 20492 | M14: 19501 | N14: 44917 | O14: 3162 | R14: 37335 | S14: =SUM(K14:R14) -> 205845
C15: Saleries and related payables | K15: 15497 | L15: 13849 | M15: 1787 | R15: 7111 | S15: =SUM(K15:R15) -> 38244
C16: Due to other agencies | K16: 57698 | S16: =SUM(K16:R16) -> 57698
C17: Due to other funds | K17: 62054 | L17: 2700 | S17: =SUM(K17:R17) -> 64754
E19: Total liabilities: | K19: =SUM(K14:K17) -> 215687 | L19: =SUM(L14:L17) -> 37041 | M19: =SUM(M14:M17) -> 21288 | N19: =SUM(N14:N17) -> 44917 | O19: =SUM(O14:O17) -> 3162 | P19: =SUM(P14:P17) -> 0 | Q19: =SUM(Q14:Q17) -> 0 | R19: =SUM(R14:R17) -> 44446 | S19: =SUM(S14:S17) -> 366541
B21: Fund Balances
C22: Unassigned | K22: 1207534 | S22: =SUM(K22:P22) -> 1207534
C23: Restricted | L23: 902455 | M23: 984018 | N23: 2107126 | O23: 1972016 | P23: 115740 | Q23: 40 | R23: 2091249 | S23: =SUM(K23:R23) -> 8172644
E25: Total fund balances: | K25: =SUM(K22:K23) -> 1207534 | L25: =SUM(L22:L23) -> 902455 | M25: =SUM(M22:M23) -> 984018 | N25: =SUM(N22:N23) -> 2107126 | O25: =SUM(O22:O23) -> 1972016 | P25: =SUM(P22:P23) -> 115740 | Q25: =SUM(Q22:Q23) -> 40 | R25: =SUM(R22:R23) -> 2091249 | S25: =SUM(S22:S23) -> 9380178
E27: Total liabilities and fund balances: | K27: =SUM(K25+K19) -> 1423221 | L27: =SUM(L25+L19) -> 939496 | M27: =SUM(M25+M19) -> 1005306 | N27: =SUM(N25+N19) -> 2152043 | O27: =SUM(O25+O19) -> 1975178 | P27: =SUM(P25+P19) -> 115740 | Q27: =SUM(Q25+Q19) -> 40 | R27: =SUM(R25+R19) -> 2135695 | S27: =SUM(S25+S19) -> 9746719

Sheet Cameron
D1: Cameron Combined Balance Sheet
D2: Issued: December 31, 2014
K4: General Fund | L4: Road & Bridge Maintenance | M4: Long-Term Community Recovery | N4: Non-Major | O4: Total Governmental Funds
A5: Assets:
B6: Cash | K6: 11614255 | L6: 30849 | M6: 100 | N6: 16822104 | O6: =SUM(K6:N6) -> 28467308
B7: Receivables, net | K7: 7957122 | L7: 1862489 | M7: 1691825 | N7: 5103359 | O7: =SUM(K7:N7) -> 16614795
B8: Inventory, at cost | K8: 1793767 | L8: 28999 | O8: =SUM(K8:N8) -> 1822766
B9: Other | K9: 66729 | L9: 46475 | N9: 33506 | O9: 4081650
B10: Interfund receivables | K10: 2631117 | L10: 402547 | N10: 2742552 | O10: =SUM(K10:N10) -> 5776216
E12: Total assets: | K12: =SUM(K6:K10) -> 24062990 | L12: =SUM(L6:L10) -> 2371359 | M12: =SUM(M6:M10) -> 1691925 | N12: =SUM(N6:N10) -> 24701521 | O12: =SUM(O6:O10) -> 56762735
A14: LIABILITIES AND FUND BALANCES
B15: Liabilities:
C16: Accounts, salaries, and other payables | K16: 397951 | L16: 50177 | M16: 2367492 | N16: 1053795 | O16: =SUM(K16:N16) -> 3869415
C17: Due to other agencies | K17: 2623074 | O17: =SUM(K17:N17) -> 2623074
C18: Unearned revenue | K18: 7413 | M18: 9818 | O18: =SUM(K18:N18) -> 17231
C19: Interfund payables | K19: 3145100 | M19: 380933 | N19: 2250183 | O19: =SUM(K19:N19) -> 5776216
E21: Total liabilities: | K21: =SUM(K16:K19) -> 6173538 | L21: =SUM(L16:L19) -> 50177 | M21: =SUM(M16:M19) -> 2758243 | N21: =SUM(N16:N19) -> 3303978 | O21: =SUM(O16:O19) -> 12285936
A23: DEFERRED INFLOWS OF RESOURCES
E25: Total deferred inflows of resources | K25: =SUM(K24) -> 0 | L25: =SUM(L24) -> 0 | M25: =SUM(M24) -> 0 | N25: =SUM(N24) -> 0 | O25: =SUM(O24) -> 0
B27: Fund Balances
C28: Nonspendable:
D29: Inventories | K29: 1793767 | L29: 28999 | O29: =SUM(K29:N29) -> 1822766
D30: Prepaid expenses | K30: 66729 | L30: 46475 | N30: 33508 | O30: =SUM(K30:N30) -> 146712
C31: Restricted:
D32: Judicial | N32: 58817 | O32: =SUM(K32:N32) -> 58817
D33: Debt service | N33: 999067 | O33: =SUM(K33:N33) -> 999067
D34: Tourism development | N34: 39983 | O34: =SUM(K34:N34) -> 39983
C35: Commited to: | O35: =SUM(K35:N35) -> 0
D36: Infrastructure maintenance | L36: 2224889 | O36: =SUM(K36:N36) -> 2224889
D37: Culture and recreation | N37: 5560799 | O37: =SUM(K37:N37) -> 5560799
D38: Public safety | N38: 5114106 | O38: =SUM(K38:N38) -> 5114106
D39: Judicial | N39: 3509737 | O39: =SUM(K39:N39) -> 3509737
D40: Health and welfare | N40: 5585323 | O40: =SUM(K40:N40) -> 5585323
D41: Law enforcement building construction | N41: 208078 | O41: =SUM(K41:N41) -> 208078
D42: Library construction | N42: 42777 | O42: =SUM(K42:N42) -> 42777
D43: Administrative building construction | N43: 171986 | O43: =SUM(K43:N43) -> 171986
D44: Other capital projects | L44: 20819 | N44: -119317 | O44: =SUM(K44:N44) -> -98498
D45: Other purposes | K45: 130576 | O45: =SUM(K45:N45) -> 130576
C46: Assigned: | O46: =SUM(K46:N46) -> 0
D47: judicial | N47: 7483 | O47: =SUM(K47:N47) -> 7483
...

Sheet Catahoula
D1: Catahoula Combined Balance Sheet
D2: Issued: December 31, 2014
K5: General | L5: Road and Bridge | M5: Hard Surfacing | N5: Sanitation | O5: Library | P5: Heatlh Unit | Q5: Other Governmental Funds | R5: Total Governmental Funds
A6: Assets:
B7: Cash and cash equivalents | K7: 629573 | L7: 114529 | M7: 375026 | N7: 433150 | O7: 284606 | P7: 352292 | Q7: 101420 | R7: =SUM(K7:Q7) -> 2290596
B8: Cash restricted for debt service | Q8: 26910 | R8: =SUM(K8:Q8) -> 26910
B9: Cash restricted for capital project | Q9: 293899 | R9: =SUM(K9:Q9) -> 293899
B10: Receivables | K10: 519222 | L10: 46606 | M10: 62020 | N10: 38762 | O10: 309409 | P10: 76875 | Q10: 63443 | R10: =SUM(K10:Q10) -> 1116337
B11: Other assets | K11: 32620 | L11: 16112 | M11: 24500 | P11: 2732 | Q11: 3617 | R11: =SUM(K11:Q11) -> 79581
E13: Total Assets: | K13: =SUM(K7:K11) -> 1181415 | L13: =SUM(L7:L11) -> 177247 | M13: =SUM(M7:M11) -> 461546 | N13: =SUM(N7:N11) -> 471912 | O13: =SUM(O7:O11) -> 594015 | P13: =SUM(P7:P11) -> 431899 | Q13: =SUM(Q7:Q11) -> 489289 | R13: =SUM(R7:R11) -> 3807323
A15: LIABILITIES, DEFERRED INFLOWS OF RESOURCES, AND FUND BALANCES
B16: Liabilities:
C17: Accounts payable | K17: 50383 | L17: 7667 | M17: 6412 | N17: 36962 | O17: 16867 | P17: 5531 | Q17: 5814 | R17: =SUM(K17:Q17) -> 129636
C18: Salaries and related payables | K18: 3126 | L18: 5837 | M18: 2983 | Q18: 3137 | R18: =SUM(K18:Q18) -> 15083
E20: Total liabilities: | K20: =SUM(K17:K18) -> 53509 | L20: =SUM(L17:L18) -> 13504 | M20: =SUM(M17:M18) -> 9395 | N20: =SUM(N17:N18) -> 36962 | O20: =SUM(O17:O18) -> 16867 | P20: =SUM(P17:P18) -> 5531 | Q20: =SUM(Q17:Q18) -> 8951 | R20: =SUM(R17:R18) -> 144719
A22: DEFERRED INFLOWS OF RESROUCES
B23: Ad valorem taxes and state revenue sharing - unavailable | K23: 59384 | O23: 43715 | P23: 10929 | Q23: 20284 | R23: =SUM(K23:Q23) -> 134312
E25: Total deferred inflows of resources | K25: =SUM(K23:K23) -> 59384 | L25: =SUM(L23:L23) -> 0 | M25: =SUM(M23:M23) -> 0 | N25: =SUM(N23:N23) -> 0 | O25: =SUM(O23:O23) -> 43715 | P25: =SUM(P23:P23) -> 10929 | Q25: =SUM(Q23:Q23) -> 20284 | R25: =SUM(R23:R23) -> 134312
B27: Fund Balances
C28: Restricted | L28: 163743 | M28: 452151 | N28: 434950 | O28: 533433 | P28: 415439 | Q28: 460054 | R28: =SUM(K28:Q28) -> 2459770
C29: Unassigned | K29: 1068522 | R29: =SUM(K29:Q29) -> 1068522
E31: Total fund balance: | K31: =SUM(K28:K29) -> 1068522 | L31: =SUM(L28:L29) -> 163743 | M31: =SUM(M28:M29) -> 452151 | N31: =SUM(N28:N29) -> 434950 | O31: =SUM(O28:O29) -> 533433 | P31: =SUM(P28:P29) -> 415439 | Q31: =SUM(Q28:Q29) -> 460054 | R31: =SUM(R28:R29) -> 3528292
E33: Total liabilities, deffered inflows of resources and fund balances: | K33: =K20+K25+K31 -> 1181415 | L33: =L20+L25+L31 -> 177247 | M33: =M20+M25+M31 -> 461546 | N33: =N20+N25+N31 -> 471912 | O33: =O20+O25+O31 -> 594015 | P33: =P20+P25+P31 -> 431899 | Q33: =Q20+Q25+Q31 -> 489289 | R33: =R20+R25+R31 -> 3807323

Sheet Claiborne
D1: Claiborne Combined Balance Sheet
D2: Issued: December 31, 2014
K5: General | L5: Parish Road | M5: Library Maintenance | N5: Sales Tax | O5: Criminal Court | P5: Section 8 | Q5: Other Governmental Funds | R5: Total Governmental Funds
A6: Assets:
B7: Cash and cash equivalents | K7: 3314766 | L7: 132318 | M7: 763700 | N7: 946574 | O7: 79956 | P7: 57110 | Q7: 974702 | R7: =SUM(K7:Q7) -> 6269126
B8: Investments | K8: 443112 | L8: 3040 | M8: 6249 | N8: 339032 | Q8: 5778 | R8: =SUM(K8:Q8) -> 797211
B9: Receivables | K9: 618190 | L9: 1008728 | M9: 709657 | N9: 74185 | Q9: 673745 | R9: =SUM(K9:Q9) -> 3084505
B10: Due from other funds | K10: 1094 | R10: =SUM(K10:Q10) -> 1094
B11: Due from other agencies | K11: 22416 | R11: =SUM(K11:Q11) -> 22416
B12: Deferred charges | K12: 107283 | R12: =SUM(K12:Q12) -> 107283
E14: Total Assets: | K14: =SUM(K7:K12) -> 4506861 | L14: =SUM(L7:L12) -> 1144086 | M14: =SUM(M7:M12) -> 1479606 | N14: =SUM(N7:N12) -> 1359791 | O14: =SUM(O7:O12) -> 79956 | P14: =SUM(P7:P12) -> 57110 | Q14: =SUM(Q7:Q12) -> 1654225 | R14: =SUM(R7:R12) -> 10281635
A16: LIABILITIES, DEFERRED INFLOWS OF RESOURCES, AND FUND BALANCES
B17: Liabilities:
C18: Accounts, salaries and other payables | K18: 224147 | L18: 98585 | M18: 16827 | N18: 55004 | O18: 25785 | P18: 300 | Q18: 26219 | R18: =SUM(K18:Q18) -> 446867
C19: Due to other funds | L19: 538 | M19: 456 | Q19: 100 | R19: =SUM(K19:Q19) -> 1094
C20: Due to other agencies | P20: 14025 | R20: =SUM(K20:Q20) -> 14025
E22: Total liabilities: | K22: =SUM(K18:K20) -> 224147 | L22: =SUM(L18:L20) -> 99123 | M22: =SUM(M18:M20) -> 17283 | N22: =SUM(N18:N20) -> 55004 | O22: =SUM(O18:O20) -> 25785 | P22: =SUM(P18:P20) -> 14325 | Q22: =SUM(Q18:Q20) -> 26319 | R22: =SUM(R18:R20) -> 461986
A24: DEFERRED INFLOWS OF RESROUCES
B25: Unavailable ad valorem tax revenue | K25: 54472 | L25: 104733 | M25: 68044 | P25: 15626 | Q25: 64421 | R25: =SUM(K25:Q25) -> 307296
E27: Total deferred inflows of resources | K27: =SUM(K25:K25) -> 54472 | L27: =SUM(L25:L25) -> 104733 | M27: =SUM(M25:M25) -> 68044 | N27: =SUM(N25:N25) -> 0 | O27: =SUM(O25:O25) -> 0 | P27: =SUM(P25:P25) -> 15626 | Q27: =SUM(Q25:Q25) -> 64421 | R27: =SUM(R25:R25) -> 307296
B29: Fund Balances
C30: Restricted fund balances | K30: 485567 | L30: 940230 | M30: 1394279 | N30: 1304787 | O30: 54171 | P30: 27159 | Q30: 1563485 | R30: =SUM(K30:Q30) -> 5769678
C31: Unassigned fund balances | K31: 3742675 | R31: =SUM(K31:Q31) -> 3742675
E33: Total fund balance: | K33: =SUM(K30:K31) -> 4228242 | L33: =SUM(L30:L31) -> 940230 | M33: =SUM(M30:M31) -> 1394279 | N33: =SUM(N30:N31) -> 1304787 | O33: =SUM(O30:O31) -> 54171 | P33: =SUM(P30:P31) -> 27159 | Q33: =SUM(Q30:Q31) -> 1563485 | R33: =SUM(R30:R31) -> 9512353
E35: Total liabilities, deffered inflows of resources and fund balances: | K35: =SUM(K22+K27+K33) -> 4506861 | L35: =SUM(L22+L27+L33) -> 1144086 | M35: =SUM(M22+M27+M33) -> 1479606 | N35: =SUM(N22+N27+N33) -> 1359791 | O35: =SUM(O22+O27+O33) -> 79956 | P35: =SUM(P22+P27+P33) -> 57110 | Q35: =SUM(Q22+Q27+Q33) -> 1654225 | R35: =SUM(R22+R27+R33) -> 10281635

Sheet Concordia
D1: Concordia Combined Balance Sheet
D2: Issued: December 31, 2014
M4: Major Funds
K5: General Fund | L5: Drainage Fund | M5: Sales Tax Fund | N5: Road Debt Service Fund | O5: Public Health Fund | P5: Other Governmental Funds | Q5: Total Governmental Funds
A6: Assets:
B7: Cash and cash equivalents | K7: 3075673 | L7: 1018003 | M7: 1748390 | O7: 441379 | P7: 750518 | Q7: =SUM(K7:P7) -> 7033963
B8: Cash and cash equivalents - restricted | N8: 2563431 | Q8: =SUM(K8:P8) -> 2563431
B9: Accounts recievable | K9: 47869 | L9: 12215 | O9: 35363 | P9: 120495 | Q9: =SUM(K9:P9) -> 215942
B10: Ad valorem taxes receivable, net | K10: 250020 | L10: 1101391 | O10: 199355 | Q10: =SUM(K10:P10) -> 1550766
B11: Sales and use taxes recievable | M11: 257934 | Q11: =SUM(K11:P11) -> 257934
B12: Severancetaxes receivable | K12: 143713 | Q12: =SUM(K12:P12) -> 143713
B13: State revenue sharing receivable | Q13: =SUM(K13:P13) -> 0
B14: Due from other funds | K14: 12550 | L14: 12000 | N14: 80000 | P14: 74200 | Q14: =SUM(K14:P14) -> 178750
E16: Total Assets: | K16: =SUM(K7:K14) -> 3529825 | L16: =SUM(L7:L14) -> 2143609 | M16: =SUM(M7:M14) -> 2006324 | N16: =SUM(N7:N14) -> 2643431 | O16: =SUM(O7:O14) -> 676097 | P16: =SUM(P7:P14) -> 945213 | Q16: =SUM(Q7:Q14) -> 11944499
A18: LIABILITIES
C19: Accounts payable | K19: 69082 | M19: 21581 | O19: 35363 | P19: 49925 | Q19: =SUM(K19:P19) -> 175951
C20: Accrued payroll and benefits | K20: 36195 | L20: 26322 | P20: 21455 | Q20: =SUM(K20:P20) -> 83972
C21: Due to other funds | M21: 178750 | Q21: =SUM(K21:P21) -> 178750
E23: Total liabilities: | K23: =SUM(K19:K21) -> 105277 | L23: =SUM(L19:L21) -> 26322 | M23: =SUM(M19:M21) -> 200331 | N23: =SUM(N19:N21) -> 0 | O23: =SUM(O19:O21) -> 35363 | P23: =SUM(P19:P21) -> 71380 | Q23: =SUM(Q19:Q21) -> 438673
A25: DEFERRED INFLOWS OF RESROUCES
B26: Unavailable ad valorem taxes | K26: 11753 | L26: 51777 | O26: 9372 | Q26: =SUM(K26:P26) -> 72902
E28: Total deferred inflows of resources | K28: =SUM(K26:K26) -> 11753 | L28: =SUM(L26:L26) -> 51777 | M28: =SUM(M26:M26) -> 0 | N28: =SUM(N26:N26) -> 0 | O28: =SUM(O26:O26) -> 9372 | P28: =SUM(P26:P26) -> 0 | Q28: =SUM(Q26:Q26) -> 72902
A30: Fund Balances
C31: Restricted | Q31: =SUM(K31:P31) -> 0
D32: Debt service | N32: 2643431 | Q32: =SUM(K32:P32) -> 2643431
C33: Committed | Q33: =SUM(K33:P33) -> 0
D34: Special reverse projects | L34: 2065510 | M34: 1805993 | O34: 631362 | P34: 873833 | Q34: =SUM(K34:P34) -> 5376698
C35: Unassigned | K35: 3412795 | Q35: =SUM(K35:P35) -> 3412795
E37: Total fund balance: | K37: =SUM(K31:K35) -> 3412795 | L37: =SUM(L31:L35) -> 2065510 | M37: =SUM(M31:M35) -> 1805993 | N37: =SUM(N31:N35) -> 2643431 | O37: =SUM(O31:O35) -> 631362 | P37: =SUM(P31:P35) -> 873833 | Q37: =SUM(Q31:Q35) -> 11432924
E39: Total liabilities, deffered inflows of resources and fund balances: | K39: =SUM(K23+K28+K37) -> 3529825 | L39: =SUM(L23+L28+L37) -> 2143609 | M39: =SUM(M23+M28+M37) -> 2006324 | N39: =SUM(N23+N28+N37) -> 2643431 | O39: =SUM(O23+O28+O37) -> 676097 | P39: =SUM(P23+P28+P37) -> 945213 | Q39: =SUM(Q23+Q28+Q37) -> 11944499

Sheet DeSoto
D1: DeSoto Combined Balance Sheet
D2: Issued: December 31, 2014
K4: General Fund | L4: Solid Waste Fund | M4: Road Fund | N4: Airport Fund | O4: Jail Fund | P4: Sales Tax | Q4: Other Governmental Funds | R4: Total Governmental Funds
A5: Assets:
B6: Cash and Cash Equivalents | K6: 1781428 | L6: 3599880 | M6: 1648535 | N6: 345044 | O6: 4820618 | P6: 3000 | Q6: 964292 | R6: =SUM(K6:Q6) -> 13162797
B7: Investments | K7: 7067168 | L7: 6352258 | M7: 10699 | N7: 6925401 | P7: 0 | Q7: 0 | R7: =SUM(K7:Q7) -> 20355526
B8: Revenue Receivables | K8: 4148243 | L8: 4276536 | M8: 4141732 | N8: 65057 | P8: 805224 | Q8: 178376 | R8: =SUM(K8:Q8) -> 13615168
B9: Inventory | K9: 0 | M9: 0 | N9: 38185 | P9: 0 | Q9: 0 | R9: =SUM(K9:Q9) -> 38185
B10: Due from Other Funds | K10: 201448 | L10: 119358 | M10: 397861 | O10: 79572 | P10: 0 | Q10: 0 | R10: =SUM(K10:Q10) -> 798239
B11: Noncurrent Receivable | K11: 0 | M11: 44000 | P11: 0 | Q11: 0 | R11: =SUM(K11:Q11) -> 44000
E13: Total assets: | K13: =SUM(K6:K11) -> 13198287 | L13: =SUM(L6:L11) -> 14348032 | M13: =SUM(M6:M11) -> 6242827 | N13: =SUM(N6:N11) -> 7373687 | O13: =SUM(O6:O11) -> 4900190 | P13: =SUM(P6:P11) -> 808224 | Q13: =SUM(Q6:Q11) -> 1142668 | R13: =SUM(R6:R11) -> 48013915
A15: LIABILITIES AND FUND BALANCES
B16: Liabilities:
C17: Accounts payable | K17: 296375 | L17: 245861 | M17: 345433 | N17: 7088 | O17: 22052 | P17: 9502 | Q17: 180044 | R17: =SUM(K17:Q17) -> 1106355
C18: Due to other funds | K18: 0 | P18: 599791 | Q18: 198448 | R18: =SUM(K18:Q18) -> 798239
C19: Master bank Overdrafts | K19: 0 | P19: 0 | Q19: 55314 | R19: =SUM(K19:Q19) -> 55314
C20: Due to other governments | K20: 8966 | P20: 198931 | Q20: 0 | R20: =SUM(K20:Q20) -> 207897
C21: Advance from grantors | K21: 0 | P21: 0 | Q21: 22885 | R21: =SUM(K21:Q21) -> 22885
C22: Deposits | K22: 1800 | P22: 0 | Q22: 0 | R22: =SUM(K22:Q22) -> 1800
E24: Total liabilities: | K24: =SUM(K17:K22) -> 307141 | L24: =SUM(L17:L22) -> 245861 | M24: =SUM(M17:M22) -> 345433 | N24: =SUM(N17:N22) -> 7088 | O24: =SUM(O17:O22) -> 22052 | P24: =SUM(P17:P22) -> 808224 | Q24: =SUM(Q17:Q22) -> 456691 | R24: =SUM(R17:R22) -> 2192490
A26: DEFERRED INFLOWS OF RESOURCES
C27: Unavailable Property Taxes | K27: 236806 | L27: 195922 | M27: 175995 | Q27: 0 | R27: =SUM(K27:Q27) -> 608723
E29: Total deferred inflows of resources | K29: =SUM(K27:K27) -> 236806 | L29: =SUM(L27:L27) -> 195922 | M29: =SUM(M27:M27) -> 175995 | N29: =SUM(N27:N27) -> 0 | O29: =SUM(O27:O27) -> 0 | P29: =SUM(P27:P27) -> 0 | Q29: =SUM(Q27:Q27) -> 0 | R29: =SUM(R27:R27) -> 608723
B31: Fund Balances
C32: Nonspendable:
D33: Inventories | K33: 0 | N33: 38185 | R33: =SUM(K33:Q33) -> 38185
C34: Restricted: | R34: =SUM(K34:Q34) -> 0
D35: Airport | K35: 0 | N35: 7328414 | R35: =SUM(K35:Q35) -> 7328414
D36: Judicial | K36: 0 | Q36: 69 | R36: =SUM(K36:Q36) -> 69
D37: Public Safety | K37: 0 | O37: 4878138 | R37: =SUM(K37:Q37) -> 4878138
D38: Roads | K38: 0 | M38: 5721399 | R38: =SUM(K38:Q38) -> 5721399
D39: Sanitation | K39: 0 | L39: 13906249 | R39: =SUM(K39:Q39) -> 13906249
D40: Health & Welfare | K40: 0 | Q40: 52581 | R40: =SUM(K40:Q40) -> 52581
D41: Witness & Juror Fees | K41: 0 | Q41: 458392 | R41: =SUM(K41:Q41) -> 458392
C42: Assigned: | R42: =SUM(K42:Q42) -> 0
D43: Self-Insured Premiums | K43: 13809 | R43: =SUM(K43:Q43) -> 13809
D44: Animal Control | K44: 0 | Q44: 174935 | R44: =SUM(K44:Q44) -> 174935
C45: Unassigned | K45: 12640531 | R45: =SUM(K45:Q45) -> 12640531
E47: Total fund balances: | K47: =SUM(K33:K45) -> 12654340 | L47: =SUM(L33:L45) -> 13906249 | M47: =SUM(M33:M45) -> 5721399 | N47: =SUM(N33:N45) -> 7366599 | O47: =SUM(O33:O45) -> 4878138 | P47: =SUM(P33:P45) -> 0 | Q47: =SUM(Q33:Q45) -> 685977 | R47: =SUM(R33:R45) -> 45212702
E49: Total liabilities and fund balances: | K49: =SUM(K47,K24,K29) -> 13198287 | L49: =SUM(L47,L24,L29) -> 14348032 | M49: =SUM(M47,M24,M29) -> 6242827 | N49: =SUM(N47,N24,N29) -> 7373687 | O49: =SUM(O47,O24,O29) -> 4900190 | P49: =SUM(P47,P24,P29) -> 808224 | Q49: =SUM(Q47,Q24,Q29) -> 1142668 | R49: =SUM(R47,R24,R29) -> 48013915

Sheet East Baton Rouge
D1: East Baton Rouge Combined Balance Sheet
D2: Issued: December 31, 2014
K5: General Fund | L5: Library Board of Control | M5: Grants | N5: Capital Projects | O5: Other Governmental Funds | P5: Total Governmental Funds
A6: Assets:
B7: Cash and cash equivalents (note 3) | K7: 49746105 | L7: 31703021 | M7: 2858777 | N7: 56478568 | O7: 35307663 | P7: =SUM(K7:O7) -> 176094134
B8: Investments (note 3) | K8: 56096672 | L8: 35750216 | M8: 3223727 | N8: 63774265 | O8: 29946347 | P8: =SUM(K8:O8) -> 188791227
B9: Property taxes receivable - net (note 4) | K9: 6313250 | L9: 9316072 | O9: 7242340 | P9: =SUM(K9:O9) -> 22871662
B10: Gross receipts business taxes receivable | K10: 4472777 | P10: =SUM(K10:O10) -> 4472777
B11: Sales taxes receivable | K11: 16926471 | N11: 2655398 | O11: 1649370 | P11: =SUM(K11:O11) -> 21231239
B12: Interest and penalties receivable on taxes | K12: 86002 | P12: =SUM(K12:O12) -> 86002
B13: Accounts receivable - net (note 13) | K13: 1884952 | L13: 5458 | M13: 12954 | N13: 191521 | O13: 2248970 | P13: =SUM(K13:O13) -> 4343855
B14: Accrued interest receivable | K14: 34764 | L14: 23692 | M14: 2411 | N14: 35738 | O14: 18477 | P14: =SUM(K14:O14) -> 115082
B15: Due from other funds (Note 11) | K15: 8229078 | N15: 31211723 | P15: =SUM(K15:O15) -> 39440801
B16: Due from other governments (Note 11) | K16: 20692325 | L16: 30188558 | M16: 7115771 | N16: 3687777 | O16: 22850519 | P16: =SUM(K16:O16) -> 84534950
B17: Loans receivable | K17: 427500 | M17: 3187176 | P17: =SUM(K17:O17) -> 3614676
B18: Inventory | K18: 556855 | P18: 556855
E19: Total Assets: | K19: =SUM(K7:K18) -> 165466751 | L19: =SUM(L7:L18) -> 106987017 | M19: =SUM(M7:M18) -> 16400816 | N19: =SUM(N7:N18) -> 158034990 | O19: =SUM(O7:O18) -> 99263686 | P19: =SUM(P7:P18) -> 546153260
A21: LIABILITIES, DEFERRED INFLOWS OF RESOURCES, AND FUND BALANCES
B22: Liabilities:
C23: Accounts and contracts payable | K23: 18371016 | L23: 1315828 | M23: 3533271 | N23: 15798123 | O23: 3326142 | P23: =SUM(K23:O23) -> 42344380
C24: Due to other funds (Note 11) | L24: 30652157 | O24: 8788644 | P24: =SUM(K24:O24) -> 39440801
C25: Due to other governments | K25: 7384834 | O25: 313036 | P25: =SUM(K25:O25) -> 7697870
C26: Accrued payables | K26: 7975572 | L26: 897065 | M26: 686821 | N26: 13967 | O26: 1592600 | P26: =SUM(K26:O26) -> 11166025
C27: Unearned revenue | M27: 664583 | N27: 398579 | P27: =SUM(K27:O27) -> 1063162
C28: Deposits and escrow accounts | K28: 18011657 | M28: 131910 | P28: =SUM(K28:O28) -> 18143567
E30: Total liabilities: | K30: =SUM(K23:K28) -> 51743079 | L30: =SUM(L23:L29) -> 32865050 | M30: =SUM(M23:M29) -> 5016585 | N30: =SUM(N23:N29) -> 16210669 | O30: =SUM(O23:O29) -> 14020422 | P30: =SUM(P23:P29) -> 119855805
A32: DEFERRED INFLOWS OF RESROUCES
B33: Unavailable revenue- property taxes | K33: 733458 | L33: 900636 | O33: 834079 | P33: =SUM(K33:O33) -> 2468173
B34: Unavailable revenue- revenue sharing | K34: 657671 | O34: 77028 | P34: =SUM(K34:O34) -> 734699
B35: Resources recieved before time requirements | M35: 351292 | P35: =SUM(K35:O35) -> 351292
E37: Total deferred inflows of resources | K37: =SUM(K33:K35) -> 1391129 | L37: =SUM(L33:L35) -> 900636 | M37: =SUM(M33:M35) -> 351292 | N37: =SUM(N33:N35) -> 0 | O37: =SUM(O33:O35) -> 911107 | P37: =SUM(P33:P35) -> 3554164
B39: Fund Balances
C40: Nonspendable | K40: 556855 | P40: =SUM(K40:O40) -> 556855
C41: Restricted | K41: 1256695 | L41: 73221331 | M41: 11032939 | P41: =SUM(K41:O41) -> 85510965
C42: Committed | K42: 62492744 | N42: 119656017 | O42: 76376834 | P42: =SUM(K42:O42) -> 258525595
C43: Assigned | K43: 32590252 | N43: 22168304 | O43: 7955323 | P43: =SUM(K43:O43) -> 62713879
C44: Unassigned | K44: 15435997 | P44: =SUM(K44:O44) -> 15435997
E46: Total fund balance: | K46: =SUM(K40:K44) -> 112332543 | L46: =SUM(L40:L44) -> 73221331 | M46: =SUM(M40:M44) -> 11032939 | N46: =SUM(N40:N44) -> 141824321 | O46: =SUM(O40:O44) -> 84332157 | P46: =SUM(P40:P44) -> 422743291
E48: Total liabilities, deffered inflows of resources and fund balances: | K48: =SUM(K30+K37+K46) -> 165466751 | L48: =SUM(L30+L37+L46) -> 106987017 | M48: =SUM(M30+M37+M46) -> 16400816 | N48: =SUM(N30+N37+N46) -> 158034990 | O48: =SUM(O30+O37+O46) -> 99263686 | P48: =SUM(P30+P37+P46) -> 546153260

Sheet East Carroll
D1: East Carroll Combined Balance Sheet
D2: Issued: December 31, 2014
K4: General | L4: Road Maintenance and Construction | M4: Garbage District No. 1 | N4: Library | O4: Drainage Maintenance | P4: Health Unit | Q4: Nonmajor Governmental | R4: Total
A5: Assets:
B6: Cash and Cash Equivalents | K6: 228072 | L6: 775488 | M6: 45691 | N6: 162492 | O6: 195861 | P6: 430539 | Q6: 437063 | R6: =SUM(K6:Q6) -> 2275206
B7: Investments | L7: 191576 | M7: 209365 | N7: 211588 | O7: 61674 | P7: 28773 | Q7: 70691 | R7: =SUM(K7:Q7) -> 773667
B8: Receivables | K8: 649311 | L8: 431856 | M8: 320248 | N8: 272180 | O8: 448705 | P8: 156950 | Q8: 272263 | R8: =SUM(K8:Q8) -> 2551513
B9: Interfund receivables | K9: 6218 | L9: 3670 | R9: =SUM(K9:Q9) -> 9888
E11: Total assets: | K11: =SUM(K6:K9) -> 883601 | L11: =SUM(L6:L9) -> 1402590 | M11: =SUM(M6:M9) -> 575304 | N11: =SUM(N6:N9) -> 646260 | O11: =SUM(O6:O9) -> 706240 | P11: =SUM(P6:P9) -> 616262 | Q11: =SUM(Q6:Q9) -> 780017 | R11: =SUM(R6:R9) -> 5610274
A13: LIABILITIES, DEFERRED INFLOWS OF RESOURCES, AND FUND BALANCES
B14: Liabilities:
C15: Accounts payable | K15: 172155 | L15: 6614 | M15: 9807 | N15: 3076 | O15: 3149 | P15: 35 | Q15: 12821 | R15: =SUM(K15:Q15) -> 207657
C16: Interfund payables | L16: 1837 | M16: 4790 | N16: 3261 | R16: =SUM(K16:Q16) -> 9888
E18: Total liabilities: | K18: =SUM(K15:K16) -> 172155 | L18: =SUM(L15:L16) -> 8451 | M18: =SUM(M15:M16) -> 14597 | N18: =SUM(N15:N16) -> 6337 | O18: =SUM(O15:O16) -> 3149 | P18: =SUM(P15:P16) -> 35 | Q18: =SUM(Q15:Q16) -> 12821 | R18: =SUM(R15:R16) -> 217545
A20: Deferred Inflows of Resources
B21: Unavailable revenue- property taxes | K21: 23541 | L21: 21246 | M21: 23101 | N21: 21194 | O21: 21246 | P21: 12221 | Q21: 17696 | R21: =SUM(K21:Q21) -> 140245
E23: Total deferred inflows of resources | K23: =SUM(K19:K21) -> 23541 | L23: =SUM(L19:L21) -> 21246 | M23: =SUM(M19:M21) -> 23101 | N23: =SUM(N19:N21) -> 21194 | O23: =SUM(O19:O21) -> 21246 | P23: =SUM(P19:P21) -> 12221 | Q23: =SUM(Q19:Q21) -> 17696 | R23: =SUM(R19:R21) -> 140245 | ... Z23: =SUM(Z19:Z21) -> 0
A25: Fund Balances
C26: Restricted | L26: 1372893 | M26: 537606 | N26: 618729 | O26: 681845 | P26: 604006 | Q26: 749500 | R26: =SUM(K26:Q26) -> 4564579
C27: Unassigned | K27: 687905 | R27: =SUM(K27:Q27) -> 687905
E29: Total fund balance: | K29: =SUM(K26:K27) -> 687905 | L29: =SUM(L26:L27) -> 1372893 | M29: =SUM(M26:M27) -> 537606 | N29: =SUM(N26:N27) -> 618729 | O29: =SUM(O26:O27) -> 681845 | P29: =SUM(P26:P27) -> 604006 | Q29: =SUM(Q26:Q27) -> 749500 | R29: =SUM(R26:R27) -> 5252484
E31: Total liabilities, deferred inflows of resources, and fund balances: | K31: =SUM(K29+K23+K18) -> 883601 | L31: =SUM(L29+L23+L18) -> 1402590 | M31: =SUM(M29+M23+M18) -> 575304 | N31: =SUM(N29+N23+N18) -> 646260 | O31: =SUM(O29+O23+O18) -> 706240 | P31: =SUM(P29+P23+P18) -> 616262 | Q31: =SUM(Q29+Q23+Q18) -> 780017 | R31: =SUM(R29+R23+R18) -> 5610274

Sheet East Feliciana
D1: East Feliciana Combined Balance Sheet
D2: Issued: December 31, 2014
K4: General Fund | L4: Roads and Bridges | M4: Solid Waste | N4: Other Governmental Funds | O4: Total Governmental Funds
A5: Assets:
B6: Cash and cash equivalents | K6: 810939.55 | L6: 1278350 | M6: 2485602.7 | N6: 427717.31 | O6: =SUM(K6:N6) -> 5002609.6
B7: Receivables, net:
C8: Accounts | N8: 12336.64 | O8: =SUM(K8:N8) -> 12336.64
C9: Taxes | K9: 396124.82 | M9: 284115.73 | N9: 432247.63 | O9: =SUM(K9:N9) -> 1112488.2
B10: Due from other funds | K10: 268988.48 | L10: 287054.02 | M10: 1275000 | O10: =SUM(K10:N10) -> 1831042.5
B11: Due from other govt agencies | K11: 19747 | L11: 44917.96 | N11: 27307 | O11: =SUM(K11:N11) -> 91971.96
E13: Total assets: | K13: =SUM(K6:K11) -> 1495799.9 | L13: =SUM(L6:L11) -> 1610322 | M13: =SUM(M6:M11) -> 4044718.5 | N13: =SUM(N6:N11) -> 899608.58 | O13: =SUM(O6:O11) -> 8050448.9
A15: LIABILITIES AND FUND BALANCES
B16: Liabilities:
C17: Accounts payable | K17: 69255.2 | L17: 581663.58 | M17: 84757.3 | O17: =SUM(K17:N17) -> 735676.08
C18: Due to other funds | K18: 14435.04 | L18: 1275000 | M18: 21947.19 | N18: 152885.34 | O18: =SUM(K18:N18) -> 1464267.6
C19: Due to other govt agencies | N19: 2729.05 | O19: =SUM(K19:N19) -> 2729.05
E21: Total liabilities: | K21: =SUM(K17:K19) -> 83690.24 | L21: =SUM(L17:L19) -> 1856663.6 | M21: =SUM(M17:M19) -> 106704.49 | N21: =SUM(N17:N19) -> 155614.39 | O21: =SUM(O17:O19) -> 2202672.7
A23: Deferred inflows of resources:
B24: Unavailable revenue | K24: 47055.21 | N24: 26280.13 | O24: =SUM(K24:N24) -> 73335.34
A26: Fund Balances (Deficit):
C27: Restricted for: | O27: =SUM(K27:N27) -> 0
D28: Health unit oper/maintenance | N28: 845785.87 | O28: =SUM(K28:N28) -> 845785.87
D29: Homeland security | K29: 45514.34 | O29: =SUM(K29:N29) -> 45514.34
D30: Solid waste management | M30: 3938014 | O30: =SUM(K30:N30) -> 3938014
C31: Committed to:
D32: Debt service | L32: -246341.59 | O32: =SUM(K32:N32) -> -246341.59
D33: Road improvements | N33: -128071.81 | O33: =SUM(K33:N33) -> -128071.81
D34: Coroner/court operations | O34: =SUM(K34:N34) -> 0
D35: Claims and judgements | K35: 45500 | O35: =SUM(K35:N35) -> 45500
C36: Unassigned | K36: 1274040.1 | O36: =SUM(K36:N36) -> 1274040.1
E38: Total fund balance: | K38: =SUM(K28:K36) -> 1365054.4 | L38: =SUM(L28:L36) -> -246341.59 | M38: =SUM(M28:M36) -> 3938014 | N38: =SUM(N28:N36) -> 717714.06 | O38: =SUM(O28:O36) -> 5774440.8
E40: Total liabilities, deferred inflows of resources, and fund balances: | K40: =SUM(K38+K24+K21) -> 1495799.9 | L40: =SUM(L38+L24+L21) -> 1610322 | M40: =SUM(M38+M24+M21) -> 4044718.5 | N40: =SUM(N38+N24+N21) -> 899608.58 | O40: =SUM(O38+O24+O21) -> 8050448.9

Sheet Evangeline
D1: Evangeline Combined Balance Sheet
D2: Issued: December 31, 2014
K4: Parish Road Fund | L4: Criminal Court Fund | M4: Industrial District No. 1 | N4: Crooked Creek Recreation Fund | O4: Reddell Sewer System Maintenance Fund | P4: Cemetery District Maintenance Fund | Q4: Country Estate Sewer System Fund | R4: Eugene Subdivision Sewer System Fund | S4: Health Unit Maintenance | T4: Total
A5: Assets:
B6: Cash and interest-bearing deposits | K6: 587936 | L6: 11062 | M6: 269504 | O6: 32563 | P6: 1014924 | Q6: 6974 | R6: 2368 | S6: 1126328 | T6: =SUM(K6:S6) -> 3051659
B7: Receivables, net | O7: 1579 | Q7: 860 | R7: 587 | T7: =SUM(K7:S7) -> 3026
B8: Due from other gonvernmental units | K8: 81043 | L8: 24120 | P8: 391077 | S8: 516485 | T8: =SUM(K8:S8) -> 1012725
B9: Other assets | M9: 5000 | T9: =SUM(K9:S9) -> 5000
