Workbook

Sheet Acadia
J1: Acadia County 2014 Statement of Activities
J2: Issued: December 31, 2014
M4: NET (EXPENSE) REVENUE AND CHANGE IN NET ASSETS
J5: PROGRAM REVENUES | M5: PRIMARY GOVERNMENT
A6: FUNCTIONS/PROGRAMS | I6: Expenses | J6: Charges for Services | K6: Operating Grants and Contributions | L6: Capital Grants and Contributions | M6: Total Governmental Activities | N6: Component Units
A7: Primary Government:
B8: Government Activities:
C9: General government | I9: -3174139 | J9: 90048 | L9: 9155 | M9: =SUM(I9:L9) -> -3074936
C10: Public safety | I10: -1842385 | J10: 20664 | K10: 133860 | L10: 204990 | M10: =SUM(I10:L10) -> -1482871
C11: Public works | I11: -5893248 | K11: 610860 | L11: 42195 | M11: =SUM(I11:L11) -> -5240193
C12: Economic development and assistance | I12: -574712 | J12: 8414 | L12: 324518 | M12: =SUM(I12:L12) -> -241780
C13: Health and welfare | I13: -7186309 | J13: 5880 | K13: 246456 | L13: 514892 | M13: =SUM(I13:L13) -> -6419081
C14: Culture and recreation | I14: -340726 | J14: 82248 | M14: =SUM(I14:L14) -> -258478
C15: Interest on long-term debt | I15: -394773 | M15: =SUM(I15:L15) -> -394773
E17: Total Government Activities | I17: =SUM(I9:I15) -> -19406292 | J17: =SUM(J9:J15) -> 207254 | K17: =SUM(K9:K15) -> 991176 | L17: =SUM(L9:L15) -> 1095750 | M17: =SUM(M9:M15) -> -17112112
A19: Component units:
B20: Acadia Parish District Criminal Court | I20: -751832 | J20: 174579 | K20: 63659 | L20: 0 | N20: =SUM(I20:M20) -> -513594
G22: General Revenues:
H23: Taxes:
I24: Property | M24: 4784714
I25: Sales | M25: 11822706
I26: Severance | M26: 1006729
I27: Fire insurance premiums | M27: 251271
I28: Occupational and insurance | M28: 486902
I29: Other | M29: 285866
H30: Grants and contributions not restricted to specific programs | M30: 443266
H31: Investment income gains (losses) | M31: 122176
H32: Loss on disposal of capital assets | M32: -44090
H33: Miscellaneous | M33: 437977
H34: Transfers | M34: -515000 | N34: 515000
H36: Total General Revenues | M36: =SUM(M24:M34) -> 19082517 | N36: =SUM(N24:N34) -> 515000
H38: Change in Net Assets | M38: =SUM(M17,M36) -> 1970405 | N38: =N36+N20 -> 1406
E41: Net Assets- Beginning | M41: 52621424 | N41: 38809
E43: Net Assets- Ending | M43: 54591829 | N43: =N41+N38 -> 40215

Sheet Allen
J1: Allen County 2014 Statement of Activities
J2: Issued: December 31, 2014
M4: NET (EXPENSE) REVENUE AND CHANGE IN NET POSITIONS
J5: PROGRAM REVENUES | M5: PRIMARY GOVERNMENT
A6: FUNCTIONS/PROGRAMS | I6: Expenses | J6: Charges for Services | K6: Operating Grants and Contributions | L6: Capital Grants and Contributions | M6: Total Governmental Activities
A7: Primary Government:
B8: Government Activities:
C9: General government | I9: -2194302 | J9: 230115 | K9: 16150 | M9: =SUM(I9:L9) -> -1948037
C10: Public safety | I10: -592121 | K10: 513 | M10: =SUM(I10:L10) -> -591608
C11: Public works | I11: -6135280 | K11: 374203 | M11: =SUM(I11:L11) -> -5761077
C12: Economic development | I12: -302516 | J12: 73693 | K12: 66854 | L12: 128448 | M12: =SUM(I12:L12) -> -33521
C13: Other governments | I13: -719358 | K13: 755647 | M13: =SUM(I13:L13) -> 36289
C14: Interest on long-term debt | I14: -4853 | M14: =SUM(I14:L14) -> -4853
E16: Total Government Activities | I16: =SUM(I9:I14) -> -9948430 | J16: =SUM(J9:J14) -> 303808 | K16: =SUM(K9:K14) -> 1213367 | L16: =SUM(L9:L14) -> 128448 | M16: =SUM(M9:M14) -> -8302807
G19: General Revenues:
H20: Taxes:
I21: Ad valorem | M21: 3151619
I22: Sales and use | M22: 1871684
I23: Severance | M23: 1135569
I24: Other | M24: 354
H25: State revenue sharing | M25: 175817
H26: All other revenues | M26: 1276190
H27: Investment earnings | M27: 14301
H28: Special items:
I29: Gain on disposal of assets | M29: 1252
H31: Total General Revenues | M31: =SUM(M21:M29) -> 7626786
H33: Change in Net Position | M33: =SUM(M16,M31) -> -676021
E35: Net Assets- Beginning of Year | M35: 30884380
E37: Net Assets- End of Year | M37: =SUM(M33,M35) -> 30208359

Sheet Assumption
J1: East Carroll County 2014 Statement of Activities
J2: Issued: December 31, 2014
L4: NET (EXPENSE) REVENUE AND CHANGES IN NET ASSETS
J5: PROGRAM REVENUES | L5: PRIMARY GOVERNMENT
A6: FUNCTIONS/PROGRAMS | I6: Expenses | J6: Charges for Services | K6: Operating Grants and Contributions | L6: Governmental Activities | M6: Component Units | N6: Total
A7: Primary Government:
B8: Government Activities:
C9: General government:
D10: Legislative | I10: 583006 | L10: -583006 | N10: =SUM(L10:M10) -> -583006
D11: Judicial | I11: 970822 | J11: 85720 | L11: -885102 | N11: =SUM(L11:M11) -> -885102
D12: Elections | I12: 51593 | L12: -51593 | N12: =SUM(L12:M12) -> -51593
D13: Finance and administrative | I13: 351185 | L13: -351185 | N13: =SUM(L13:M13) -> -351185
D14: Other general government | I14: 167869 | L14: -167869 | N14: =SUM(L14:M14) -> -167869
C15: Public safety | I15: 3430554 | J15: 705549 | K15: 191140 | L15: -2533865 | N15: =SUM(L15:M15) -> -2533865
C16: Public works | I16: 5847342 | J16: 2204841 | K16: 85615 | L16: -3556996 | N16: =SUM(L16:M16) -> -3556996
C17: Public utilities
C18: Health and welfare | I18: 2470140 | J18: 195714 | K18: 1161181 | L18: -1113245 | N18: =SUM(L18:M18) -> -1113245
C19: Culture and recreation | I19: 1276963 | J19: 10590 | K19: 742 | L19: -1265631 | N19: =SUM(L19:M19) -> -1265631
C20: Economic development and assistance | I20: 221560 | J20: 2405 | L20: -219155 | N20: =SUM(L20:M20) -> -219155
C21: Interest on long-term debt
E23: Total primary government | I23: =SUM(I10:I20) -> 15371034 | J23: =SUM(J10:J20) -> 3204819 | K23: =SUM(K10:K20) -> 1438678 | L23: =SUM(L10:L20) -> -10727647 | N23: =SUM(N10:N20) -> -10727647
B25: Buisness-type Activities:
C26: Sewer and water | I26: 3587268 | J26: 4437297 | M26: 850029 | N26: =SUM(L26:M26) -> 850029
E28: Total component units | I28: =SUM(I26:I26) -> 3587268 | J28: =SUM(J26:J26) -> 4437297 | K28: =SUM(K26:K26) -> 0 | L28: =SUM(L26:L26) -> 0 | M28: =SUM(M26:M26) -> 850029 | N28: =SUM(N26:N26) -> 850029
G31: Local sources
H32: Taxes:
I33: Ad valorem | L33: 4643634 | N33: =SUM(L33:M33) -> 4643634
I34: Sales and use taxes | L34: 4564298 | N34: =SUM(L34:M34) -> 4564298
I35: Other taxes | L35: 1071008 | N35: =SUM(L35:M35) -> 1071008
I36: Other revenue | L36: 1890578 | N36: =SUM(L36:M36) -> 1890578
H37: State sources | N37: =SUM(L37:M37) -> 0
I38: Unrestricted revenue | L38: 882766 | N38: =SUM(L38:M38) -> 882766
H40: Total General Revenues | L40: =SUM(L33:L38) -> 13052284 | M40: =SUM(M33:M38) -> 0 | N40: =SUM(N33:N38) -> 13052284
H42: Excess of revenues and special items | L42: 2278985 | M42: 1121196 | N42: =N40 -> 13052284
E44: Net Assets- Beginning of Year | L44: 64597952 | M44: 18297426 | N44: =SUM(L44:M44) -> 82895378
E46: Net Assets- End of Year | L46: =SUM(L42,L44) -> 66876937 | M46: =M44+M42 -> 19418622 | N46: =N44+N42 -> 95947662

Sheet Avoyelles
J1: Avoyelles County 2014 Statement of Activities
J2: Issued: December 31, 2014
M4: NET (EXPENSE) REVENUE AND CHANGE IN NET ASSETS
J5: PROGRAM REVENUES | M5: Governmental Activities
A6: FUNCTIONS/PROGRAMS | I6: Expenses | J6: Fees, Fines, and Charges for Services | K6: Operating Grants and Contributions | L6: Capital Grants and Contributions | M6: Governmental Activities | N6: Component Units
B7: Government Activities:
C8: General government | I8: -1411958 | J8: 84619 | L8: 62255 | M8: =SUM(I8:L8) -> -1265084
C9: Public safety | I9: -1006255 | J9: 592631 | K9: 88011 | M9: =SUM(I9:L9) -> -325613
C10: Public works | I10: -4651624 | J10: 1527 | K10: 492067 | L10: 478231 | M10: =SUM(I10:L10) -> -3679799
C11: Health and welfare | I11: -831081 | K11: 544620 | M11: =SUM(I11:L11) -> -286461
C12: Culture and recreation | I12: -629145 | J12: 14658 | M12: =SUM(I12:L12) -> -614487
C13: Economic development | I13: -296694 | K13: 25000 | M13: =SUM(I13:L13) -> -271694
E15: Total Government Activities | I15: =SUM(I8:I13) -> -8826757 | J15: =SUM(J8:J13) -> 693435 | K15: =SUM(K8:K13) -> 1149698 | L15: =SUM(L8:L13) -> 540486 | M15: =SUM(M8:M13) -> -6443138
G17: General Revenues:
H18: Taxes:
I19: Property taxes, levied for general purposes | M19: 2107549
I20: Sales and use taxes, levied for general purposes | M20: 4528838
H21: Grants and contributions not restricted to specific programs:
I22: State revenue sharing | M22: 206873
I23: Parish equalization | M23: 299658
I24: State grants | M24: 519014
I25: Casino revenue | M25: 28899
H26: Interest and investment earnings | M26: 27870
H27: Miscellaneous | M27: 67030
H28: Special item- Gain on disposal of assets | M28: 1525
H30: Total General Revenues | M30: =SUM(M19:M28) -> 7787256 | N30: =SUM(N19:N27) -> 0
H32: Change in Net Assets | M32: =SUM(M15,M30) -> 1344118 | N32: =N30 -> 0
E34: Net Assets- Beginning of Year | M34: 15278046
E36: Net Assets- End of Year | M36: =SUM(M32,M34) -> 16622164 | N36: =N34+N32 -> 0

Sheet Beauregard
J1: Beauregard County 2014 Statement of Activities
J2: Issued: December 31, 2014
J4: PROGRAM REVENUES
A5: FUNCTIONS/PROGRAMS | I5: Expenses | J5: Charges for Services | K5: Operating Grants and Contributions | L5: Capital Grants and Contributions | M5: Governmental Activities- Net (Expense) Revenue in Changes in Net Assets
A6: Primary Government:
B7: Government Activities:
C8: General government
D9: Legislative | I9: -244689 | M9: =SUM(I9:L9) -> -244689
D10: Judicial | I10: -1065401 | J10: 844291 | K10: 8400 | M10: =SUM(I10:L10) -> -212710
D11: Elections | I11: -77658 | M11: =SUM(I11:L11) -> -77658
D12: Financial and administrative | I12: -474076 | J12: 206908 | M12: =SUM(I12:L12) -> -267168
D13: Other general government activities | I13: -793563 | J13: 190115 | M13: =SUM(I13:L13) -> -603448
C14: Public safety | I14: -2444391 | K14: 78824 | M14: =SUM(I14:L14) -> -2365567
C15: Public works | I15: -8964712 | J15: 19000 | K15: 523576 | L15: 833328 | M15: =SUM(I15:L15) -> -7588808
C16: Health and welfare | I16: -530539 | K16: 31919 | M16: =SUM(I16:L16) -> -498620
C17: Culture and recreation | I17: -1412319 | K17: 88847 | M17: =SUM(I17:L17) -> -1323472
C18: Sanitation | I18: -1509263 | J18: 61968 | M18: =SUM(I18:L18) -> -1447295
C19: Other activities | I19: -121343 | M19: =SUM(I19:L19) -> -121343
C20: Interest on long-term debt | I20: -75859 | M20: =SUM(I20:L20) -> -75859
E22: Total Government Activities | I22: =SUM(I9:I20) -> -17713813 | J22: =SUM(J9:J20) -> 1322282 | K22: =SUM(K9:K20) -> 731566 | L22: =SUM(L9:L20) -> 833328 | M22: =SUM(M9:M20) -> -14826637
G24: General Revenues:
H25: Taxes:
I26: Ad valorem taxes | M26: 5571237
I27: Severance taxes | M27: 1604653
I28: Sales taxes | M28: 8947813
I29: State revenue sharing, unrestricted | M29: 125274
I30: Other taxes | M30: 179369
H31: Interest and investment earnings | M31: 15640
H32: Special items:
I33: Miscellaneous | M33: 440381
I34: Gain on disposal of assets | M34: -54099
H36: Total General Revenues and special items | M36: =SUM(M26:M34) -> 16830268
H38: Change in Net Assets | M38: =M36+M22 -> 2003631
E40: Net Assets- Beginning of Year | M40: 47805721
E42: Net Assets- End of Year | M42: =SUM(M38,M40) -> 49809352

Sheet Bienville
J1: Allen County 2014 Statement of Activities
J2: Issued: December 31, 2014
M4: NET (EXPENSE) REVENUE AND CHANGE IN NET POSITIONS
J5: PROGRAM REVENUES | M5: PRIMARY GOVERNMENT
A6: FUNCTIONS/PROGRAMS | I6: Expenses | J6: Charges for Services | K6: Operating Grants and Contributions | L6: Capital Grants and Contributions | M6: Total Governmental Activities
A7: Primary Government:
B8: Government Activities:
C9: General government | I9: -2320292 | J9: 30957 | K9: 84139 | M9: =SUM(I9:L9) -> -2205196
C10: Public safety | I10: -672115 | K10: 94203 | M10: =SUM(I10:L10) -> -577912
C11: Public works | I11: -6139111 | K11: 60383 | L11: 327795 | M11: =SUM(I11:L11) -> -5750933
C12: Health and welfare | I12: -541954 | K12: 442763 | M12: =SUM(I12:L12) -> -99191
C13: Conservation of natural resources | I13: -30848 | M13: =SUM(I13:L13) -> -30848
C14: Economic development and assistance | I14: -64978 | K14: 8567 | M14: =SUM(I14:L14) -> -56411
C15: Debt service | I15: -396683 | M15: =SUM(I15:L15) -> -396683
E17: Total Government Activities | I17: =SUM(I9:I15) -> -10165981 | J17: =SUM(J9:J15) -> 30957 | K17: =SUM(K9:K15) -> 690055 | L17: =SUM(L9:L15) -> 327795 | M17: =SUM(M9:M15) -> -9117174
G20: General Revenues:
H21: Taxes:
I22: Property taxes levied for general purposes | M22: 1536450
I23: Property taxes levied for public works | M23: 1813814
I24: Property taxes levied for debt service | M24: 1094758
I25: Sales & use taxes levied for public works | M25: 2345499
H26: Other taxes, penalties, and interest | M26: 32162
H27: Grants and contributions not restricted to specific programs | M27: 1512686
H28: Licenses and permits | M28: 82708
H29: Unrestricted investment earnings | M29: 127199
H30: Special item - gain (loss) on disposal of assets | M30: 23210
H32: Total General Revenues | M32: =SUM(M22:M30) -> 8568486
H34: Change in Net Position | M34: =SUM(M17,M32) -> -548688
E36: Net Assets- Beginning of Year | M36: 32575214
E38: Net Assets- End of Year | M38: =SUM(M34,M36) -> 32026526

Sheet Bossier
J1: Bossier 2014 Statement of Activities
J2: Issued: December 31, 2014
M3: Primary government
M4: Governmental activities
J5: PROGRAM REVENUES | M5: Net (Expenses) Revenue and Changes in Net Assets
A6: FUNCTIONS/PROGRAMS | I6: Expenses | J6: Charges for Services | K6: Operating Grants and Contributions | L6: Capital Grants and Contributions | M6: Governmental activities | N6: Buisness-type Activities | O6: Total
A7: Primary Government: Governmental Activities
C8: General government
D9: Legislative | I9: -545378 | K9: - | M9: =SUM(I9+J9) -> -545378 | O9: =SUM(M9:N9) -> -545378
D10: Judicial | I10: -3210443 | J10: 1124204 | K10: - | M10: =SUM(I10:L10) -> -2086239 | O10: =SUM(M10:N10) -> -2086239
D11: Elections | I11: -256229 | J11: - | K11: - | L11: - | M11: =SUM(I11:L11) -> -256229 | O11: =SUM(M11:N11) -> -256229
D12: Finance and administrative | I12: -1698947 | J12: 20700 | L12: - | M12: =SUM(I12:L12) -> -1678247 | O12: =SUM(M12:N12) -> -1678247
D13: Other | I13: -3276854 | J13: 236673 | K13: 609 | L13: - | M13: =SUM(I13:L13) -> -3039572 | O13: =SUM(M13:N13) -> -3039572
C14: Public safety | I14: -5879127 | J14: 343141 | K14: 44090 | M14: =SUM(I14:L14) -> -5491896 | O14: =SUM(M14:N14) -> -5491896
C15: Public works | I15: -16737152 | J15: 367165 | K15: 168188 | L15: 19662577 | M15: =SUM(I15:L15) -> 3460778 | O15: =SUM(M15:N15) -> 3460778
C16: Public utilities | I16: -61824 | M16: =SUM(I16:L16) -> -61824 | O16: =SUM(M16:N16) -> -61824
C17: Health and welfare | I17: -4799126 | J17: - | K17: 3894996 | M17: =SUM(I17:L17) -> -904130 | O17: =SUM(M17:N17) -> -904130
C18: Culture and recreation | I18: -5061207 | J18: 73887 | K18: 22892 | L18: - | M18: =SUM(I18:L18) -> -4964428 | O18: =SUM(M18:N18) -> -4964428
C19: Economic development | I19: -1887534 | J19: - | K19: - | L19: - | M19: =SUM(I19:L19) -> -1887534 | O19: =SUM(M19:N19) -> -1887534
C20: Interest on long-term debt | I20: -2064894 | J20: - | K20: - | L20: - | M20: =SUM(I20:L20) -> -2064894 | O20: =SUM(M20:N20) -> -2064894
E22: Total Government Activities | I22: =SUM(I9:I20) -> -45478715 | J22: =SUM(J8:J19) -> 2165770 | K22: =SUM(K8:K19) -> 4130775 | L22: =SUM(L8:L19) -> 19662577 | M22: =SUM(M9:M20) -> -19519593 | N22: =SUM(N9:N20) -> 0 | O22: =SUM(O9:O20) -> -19519593
B24: Business-type Activities:
C25: Sewer and water | I25: -1116728 | J25: 1769201 | K25: - | M25: - | N25: 652473 | O25: =SUM(M25:N25) -> 652473
O26: =SUM(I26:N26) -> 0
E27: Total business-type Activities | I27: =SUM(I25) -> -1116728 | J27: =SUM(J25) -> 1769201 | K27: =SUM(K25) -> 0 | L27: =SUM(L25) -> 0 | M27: =SUM(M25) -> 0 | N27: =SUM(N25) -> 652473 | O27: =SUM(O25) -> 652473
E29: Total | I29: =SUM(I22+I27) -> -46595443 | J29: =SUM(J22+J27) -> 3934971 | K29: =SUM(K22+K27) -> 4130775 | L29: =SUM(L22+L27) -> 19662577 | M29: =SUM(M22+M27) -> -19519593 | N29: =SUM(N22+N27) -> 652473 | O29: =SUM(O22+O27) -> -18867120
G32: General Revenues:
H33: Taxes:
I34: Ad valorem taxes | M34: 14361439 | O34: =SUM(M34:N34) -> 14361439
I35: Sales taxes | M35: 17506962 | O35: =SUM(M35:N35) -> 17506962
I36: Gaming tax revenues | M36: 4265533 | O36: =SUM(M36:N36) -> 4265533
I37: Franchise taxes | M37: 514614 | O37: =SUM(M37:N37) -> 514614
I38: Other taxes | M38: 1099386 | O38: =SUM(M38:N38) -> 1099386
I39: Investment earnings | M39: 65382 | N39: 2804 | O39: =SUM(M39:N39) -> 68186
I40: State revenue sharing | M40: 547857 | O40: =SUM(M40:N40) -> 547857
I41: Miscellaneous | M41: 2822201 | N41: 496 | O41: =SUM(M41:N41) -> 2822697
I42: Gain of sale of property | M42: 184504 | O42: =SUM(M42:N42) -> 184504
I43: Transfers | M43: -8676072 | N43: 8676072 | O43: =SUM(M43:N43) -> 0
H44: Total General Revenues | M44: =SUM(M34:M43) -> 32691806 | N44: =SUM(N34:N43) -> 8679372 | O44: =SUM(O34:O43) -> 41371178
H46: Change in Net Assets | M46: =SUM(M29+M44) -> 13172213 | N46: =SUM(N29+N44) -> 9331845 | O46: =SUM(O29+O44) -> 22504058
...

Sheet Caddo
J1: Caddo County 2014 Statement of Activities
J2: Issued: December 31, 2014
J5: PROGRAM REVENUES | M5: NET (EXPENSE) REVENUE AND CHANGES IN NET ASSETS
A6: FUNCTIONS/PROGRAMS | I6: Expenses | J6: Charges for Services | K6: Operating Grants and Contributions | L6: Capital Grants and Contributions | M6: Primary Government | N6: Component Units
A7: Primary Government:
B8: Government Activities:
C9: General government | I9: -9616443 | J9: 3172380 | K9: 281149 | L9: 200560 | M9: =SUM(I9:L9) -> -5962354
C10: Criminal justice | I10: -22965185 | J10: 30283 | K10: 1330598 | M10: =SUM(I10:L10) -> -21604304
C11: Health and welfare | I11: -15373363 | J11: 168282 | K11: 11286901 | L11: 319671 | M11: =SUM(I11:L11) -> -3598509
C12: Highways, streets, and drainage | I12: -23738530 | J12: 481901 | K12: 2323462 | M12: =SUM(I12:L12) -> -20933167
C13: Building facilities | I13: -6178313 | K13: 114638 | M13: =SUM(I13:K13) -> -6063675
C14: Sanitation | I14: -2620248 | M14: =SUM(I14:K14) -> -2620248
C15: Culture and recreation | I15: -15957204 | J15: 113615 | K15: 425193 | M15: =SUM(I15:K15) -> -15418396
C16: Economic development | I16: -4221537 | K16: 73851 | M16: =SUM(I16:K16) -> -4147686
C17: Interest and fees on long-term debt | I17: -2126069 | M17: =SUM(I17:K17) -> -2126069
E19: Total Government Activities | I19: =SUM(I9:I17) -> -102796892 | J19: =SUM(J9:J17) -> 3966461 | K19: =SUM(K9:K17) -> 15835792 | L19: =SUM(L9:L17) -> 520231 | M19: =SUM(M9:M17) -> -82474408
A21: Component units:
B22: Judicial services | I22: -8479315 | J22: 1131910 | K22: 6608097 | N22: =SUM(I22:M22) -> -739308
B23: Economic development | I23: -339932 | N23: =SUM(I23:M23) -> -339932
B24: Public safety | I24: -39691975 | J24: 14223855 | N24: =SUM(I24:M24) -> -25468120
B25: Fire protection services | I25: -11455942 | J25: 2883925 | K25: 3500 | L25: 134347 | N25: =SUM(I25:M25) -> -8434170
B26: Sewerage services | I26: -1215183 | J26: 1065134 | N26: =SUM(I26:M26) -> -150049
B27: Water services | I27: -1917255 | J27: 2027286 | N27: =SUM(I27:M27) -> 110031
B28: Hospital services | I28: -18299617 | J28: 15503099 | K28: 1531826 | L28: 240946 | N28: =SUM(I28:M28) -> -1023746
E30: Total component units | I30: =SUM(I22:I28) -> -81399219 | J30: =SUM(J22:J28) -> 36835209 | K30: =SUM(K22:K28) -> 8143423 | L30: =SUM(L22:L28) -> 375293 | M30: =SUM(M22:M28) -> 0 | N30: =SUM(N22:N28) -> -36045294
G32: General Revenues:
H33: Taxes:
I34: Property taxes levied for general purposes | M34: 57040935 | N34: 8149198
I35: Property taxes levied for debt service | M35: 2519914
I36: Sales taxes | M36: 13851983 | N36: 16191048
I37: Franchise taxes | M37: 220613
I38: Telephone tariff | N38: 3595485
H39: State revenue sharing and supplemental pay | N39: 503031
H40: Gaming | M40: 1791430
H41: Grants and contributions not restricted to specific programs | M41: 1273355
H42: Oil and gas leases | M42: 853285
H43: Investment earnings | M43: 930818 | N43: 118393
H44: Inmate work release revenue | N44: 1423038
H45: Fire insurance rebate | N45: 212799
H46: Miscellaneous | M46: 936432 | N46: 2437636
...

Sheet Calcasieu
J1: Calcasieu Parish 2014 Statement of Activities
J2: Issued: December 31, 2014
M4: NET (EXPENSE) REVENUE AND CHANGE IN NET ASSETS
J5: PROGRAM REVENUES | M5: PRIMARY GOVERNMENT
A6: FUNCTIONS/PROGRAMS | I6: Expenses | J6: Charges for Services | K6: Operating Grants and Contributions | L6: Capital Grants and Contributions | M6: Governmental Activities | N6: Business-type Activities | O6: Total | P6: Component Units
A7: Primary Government:
B8: Government Activities:
C9: General government | I9: -23801813 | J9: 11462762 | K9: 361194 | L9: 260240 | M9: =SUM(I9:L9) -> -11717617 | O9: =SUM(M9:N9) -> -11717617
C10: Public safety | I10: -15334942 | J10: 974246 | K10: 1990481 | L10: 23348 | M10: =SUM(I10:L10) -> -12346867 | O10: =SUM(M10:N10) -> -12346867
C11: Public works | I11: -39564313 | J11: 755722 | K11: 4226657 | L11: 2138548 | M11: =SUM(I11:L11) -> -32443386 | O11: =SUM(M11:N11) -> -32443386
C12: Sanitation | I12: -6993188 | J12: 183 | K12: 1205 | M12: =SUM(I12:L12) -> -6991800 | O12: =SUM(M12:N12) -> -6991800
C13: Health and welfare | I13: -14834996 | J13: 140126 | K13: 7820536 | M13: =SUM(I13:L13) -> -6874334 | O13: =SUM(M13:N13) -> -6874334
C14: Culture and recreation | I14: -15996312 | J14: 1478785 | K14: 26675 | L14: 1548664 | M14: =SUM(I14:L14) -> -12942188 | O14: =SUM(M14:N14) -> -12942188
C15: Economic development | I15: -3883483 | J15: 1425178 | K15: 89559 | M15: =SUM(I15:L15) -> -2368746 | O15: =SUM(M15:N15) -> -2368746
E17: Total Government Activities | I17: =SUM(I9:I15) -> -120409047 | J17: =SUM(J9:J15) -> 16237002 | K17: =SUM(K9:K15) -> 14516307 | L17: =SUM(L9:L15) -> 3970800 | M17: =SUM(M9:M15) -> -85684938 | O17: =SUM(O9:O15) -> -85684938 | P17: =SUM(P9:P15) -> 0
B19: Business-type Activities:
C20: Water | I20: 703323 | J20: 711779 | N20: 8456 | O20: =N20 -> 8456
C21: Sewer | I21: 873402 | J21: 292967 | N21: -580435 | O21: =N21 -> -580435
E23: Total business-type Activities | I23: =SUM(I20:I21) -> 1576725 | J23: =SUM(J20:J21) -> 1004746 | K23: =SUM(K20:K21) -> 0 | L23: =SUM(L20:L21) -> 0 | M23: =SUM(M20:M21) -> 0 | N23: =SUM(N20:N21) -> -571979 | O23: =SUM(O20:O21) -> -571979
E25: Total primary government | I25: =I23+I17 -> -118832322 | J25: =J23+J17 -> 17241748 | K25: =K23+K17 -> 14516307 | L25: =L23+L17 -> 3970800 | M25: =M23+M17 -> -85684938 | N25: =N23+N17 -> -571979 | O25: =O23+O17 -> -86256917 | P25: =P23+P17 -> 0
A27: Component units:
B28: West Calcasieu Cameron Hospital | I28: -76872289 | J28: 65019753 | K28: 4077 | P28: =SUM(I28:L28) -> -11848459
B29: Sulphur Parks and Recreation | I29: -5737059 | J29: 2228194 | P29: =SUM(I29:L29) -> -3508865
B30: Gravity Drainage District No. 5 of Ward 4 | I30: -2473270 | J30: 98420 | P30: =SUM(I30:L30) -> -2374850
B31: Gravity Drainage District No. 4 of Ward 3 | I31: -2745645 | L31: 17490 | P31: =SUM(I31:L31) -> -2728155
B32: Airport Authority District No. 1 | I32: -4158495 | J32: 2095038 | K32: 204566 | L32: 3696733 | P32: =SUM(I32:L32) -> 1837842
B33: Other component units | I33: -45669669 | J33: 17745600 | K33: 4576744 | L33: 1693292 | P33: =SUM(I33:L33) -> -21654033
E35: Total component units | I35: =SUM(I28:I33) -> -137656427 | J35: =SUM(J28:J33) -> 87187005 | K35: =SUM(K28:K33) -> 4785387 | L35: =SUM(L28:L33) -> 5407515 | M35: =SUM(M28:M33) -> 0 | N35: =SUM(N28:N33) -> 0 | O35: =SUM(O28:O33) -> 0 | P35: =SUM(P28:P33) -> -40276520
G37: General Revenues:
H38: Taxes:
I39: Property | M39: 44934024 | N39: 366670 | O39: 45300694 | P39: 48130460
I40: Sales | M40: 42716206 | O40: 42716206
I41: Franchise | M41: 963051 | O41: =SUM(M41:N41) -> 963051
H42: Gaming revnues | M42: 11894569 | O42: 11894569
H43: Grants and contributions not restricted to specific programs | M43: 3123894 | O43: 3123894 | P43: 849588
H44: Investment earnings | M44: 2715152 | N44: 21576 | O44: 2736728 | P44: 489961
H45: Gain on sale of capital assets | M45: 250745 | O45: 250745 | P45: 1323256
H46: Gain on forgiveness of debt | P46: 348623
H47: Miscellaneous | M47: 42067 | N47: 600 | O47: 42667 | P47: 1736222
H48: Special items - transfer of operations | M48: 29057 | O48: 29057 | P48: -29057
...

Sheet Caldwell
J1: Caldwell County 2014 Statement of Activities
J2: Issued: December 31, 2014
J5: PROGRAM REVENUES
A6: FUNCTIONS | I6: Expenses | J6: Charges for Services | K6: Operating Grants and Contributions | L6: Capital Grants and Contributions | M6: NET (EXPENSE) REVENUE AND CHANGES IN NET ASSETS
C7: General government | I7: -974157 | J7: 161203 | K7: 168079 | M7: =SUM(I7:L7) -> -644875
C8: Public safety | I8: -534651 | J8: 106913 | K8: 171957 | L8: 67128 | M8: =SUM(I8:L8) -> -188653
C9: Public works | I9: -2017407 | J9: 103039 | K9: 204609 | L9: 203397 | M9: =SUM(I9:L9) -> -1506362
C10: Health and welfare | I10: -147216 | K10: 70834 | M10: =SUM(I10:L10) -> -76382
C11: Culture and recreation | I11: -218065 | J11: 14422 | K11: 15367 | L11: 3423044 | M11: =SUM(I11:L11) -> 3234768
C12: Economic development and assistance | I12: -232966 | M12: =SUM(I12:L12) -> -232966
C13: Transportation | I13: -5820 | J13: 4114 | M13: =SUM(I13:L13) -> -1706
E15: Total Government Activities | I15: =SUM(I7:I13) -> -4130282 | J15: =SUM(J7:J13) -> 389691 | K15: =SUM(K7:K13) -> 630846 | L15: =SUM(L7:L13) -> 3693569 | M15: =SUM(M7:M13) -> 583824
A17: General Revenues:
A18: Property taxes levied for:
B19: General purposes | M19: 772517
B20: Public works | M20: 510944
B21: Health and welfare | M21: 127013
B22: Culture and recreation
B23: Economic development and assistance | M23: 326618
A24: Sales and use taxes levied for:
B25: General purposes | M25: 266445
B26: Public works | M26: 1686092
A27: Other taxes, penalties and interest | M27: 9870
A28: Unrestricted investment earnings | M28: 28075
A29: Other revenues | M29: 5885
E31: Total general revenues | M31: =SUM(M19:M29) -> 3733459
E33: Change in net position | M33: =SUM(M15,M31) -> 4317283
E35: Net position at beginning of year, related | M35: 19052485
E37: Net position at the end of the year | M37: =SUM(M33,M35) -> 23369768

Sheet Cameron
I1: Cameron County 2014 Statement of Activities
J2: Issued: December 31, 2014
J5: Program Revenues | L5: NET REVENUES (EXPENSES) AND CHANGES IN NET POSITION
A6: FUNCTIONS/PROGRAMS | I6: Expenses | J6: Operating Grants and Contributions | K6: Capital Grants and Contributions | L6: Governmental Activities
A7: Primary Government:
B8: Government Activities:
B9: General government:
C10: Legislative | I10: -232074 | L10: =SUM(I10:K10) -> -232074
C11: Judicial | I11: -1318873 | L11: =SUM(I11:K11) -> -1318873
C12: Elections | I12: -6843 | L12: =SUM(I12:K12) -> -6843
C13: Finance and administrative | I13: -1601427 | J13: 2930 | L13: =SUM(I13:K13) -> -1598497
C14: Other general government | I14: -2668369 | L14: =SUM(I14:K14) -> -2668369
C15: Interest on long-term debt | I15: -105744 | L15: =SUM(I15:K15) -> -105744
C16: Public safety | I16: -2803731 | J16: 2645 | K16: 2550478 | L16: =SUM(I16:K16) -> -250608
C17: Public works | I17: -6533293 | J17: 4943 | K17: 2455307 | L17: =SUM(I17:K17) -> -4073043
C18: Culture and recreation | I18: -1924589 | L18: =SUM(I18:K18) -> -1924589
C19: Health and welfare | I19: -512083 | L19: =SUM(I19:K19) -> -512083
C20: Economic development | I20: -1848271 | J20: 12474217 | L20: =SUM(I20:K20) -> 10625946
E22: Total Government Activities | I22: =SUM(I10:I20) -> -19555297 | J22: =SUM(J10:J20) -> 12484735 | K22: =SUM(K10:K20) -> 5005785 | L22: =SUM(L10:L20) -> -2064777
G24: General Revenues:
H25: Taxes:
I26: Property taxes, levied for general purposes | L26: 7216305
I27: Other taxes for general purposes | L27: 994588
H28: Licenses and permits | L28: 383734
H29: Fines, forfeitures, and court costs | L29: 144837
H30: Intergovernmental:
I31: State | L31: 5217490
I32: Local | L32: 40173
H33: Gain (loss) on disposal of capital assets | L33: 521126
H34: Interest earnings | L34: 32491
H35: Other | L35: 134116
H37: Total General Revenues | L37: =SUM(L26:L35) -> 14684860
H39: Change in Net Position | L39: =SUM(L22,L37) -> 12620083
E41: Net Assets- Beginning of Year | L41: 146194005
E43: Net Assets- End of Year | L43: =SUM(L39+L41) -> 158814088

Sheet Catahoula
J1: Catahoula County 2014 Statement of Activities
J2: Issued: December 31, 2014
J5: PROGRAM REVENUES
A6: FUNCTIONS/PROGRAMS | I6: Expenses | J6: Charges for Services | K6: Operating Grants and Contributions | L6: Capital Grants and Contributions | M6: NET (EXPENSE) REVENUE AND CHANGES IN NET ASSETS
B7: Government Activities:
C8: General government | I8: -722386 | J8: 113558 | K8: 25405 | M8: =SUM(I8:L8) -> -583423
C9: Public safety | I9: -405469 | K9: 349662 | M9: =SUM(I9:L9) -> -55807
C10: Public works | I10: -1875439 | J10: 937 | K10: 181846 | L10: 64800 | M10: =SUM(I10:L10) -> -1627856
C11: Health and welfare | I11: -240465 | K11: 291827 | M11: =SUM(I11:L11) -> 51362
C12: Culture and recreation | I12: -352181 | J12: 5648 | K12: 44756 | M12: =SUM(I12:L12) -> -301777
C13: Economic development and assistance | I13: -2792 | M13: =SUM(I13:L13) -> -2792
C14: Interest expense | I14: -4485 | M14: =SUM(I14:L14) -> -4485
E16: Total Government Activities | I16: =SUM(I8:I14) -> -3603217 | J16: =SUM(J8:J14) -> 120143 | K16: =SUM(K8:K14) -> 893496 | L16: =SUM(L8:L14) -> 64800 | M16: =SUM(M8:M14) -> -2524778
G18: General Revenues:
H19: Property taxes | M19: 864032
H20: Sales and use taxes | M20: 1753095
H21: Other taxes, penalties and interest | M21: 5214
H22: Grants and contributions not restricted to specific programs | M22: 337458
H23: Unrestricted investment earnings | M23: 6434
H24: Gain (loss) on sale of capital assets | M24: -18786
H25: Other | M25: 21987
H27: Total General Revenues | M27: =SUM(M19:M25) -> 2969434
H29: Change in Net Position | M29: =SUM(M16,M27) -> 444656
E31: Net Assets- Beginning of Year | M31: 8526187
E33: Net Assets- End of Year | M33: =SUM(M29,M31) -> 8970843

Sheet Claiborne
J1: Claiborne County 2014 Statement of Activities
J2: Issued: December 31, 2014
J4: PROGRAM REVENUES
A5: FUNCTIONS- GOVERNMENTAL ACTIVITIES | I5: Expenses | J5: Charges for Services | K5: Operating Grants and Contributions | L5: Capital Grants and Contributions | M5: NET (EXPENSE) REVENUE AND CHANGES IN NET ASSETS
B6: Government Activities:
C7: General government | I7: -1522797 | J7: 482299 | M7: =SUM(I7:L7) -> -1040498
C8: Public safety | I8: -317573 | K8: 124395 | L8: 53242 | M8: =SUM(I8:L8) -> -139936
C9: Public works | I9: -3489014 | K9: 598941 | M9: =SUM(I9:L9) -> -2890073
C10: Health and welfare | I10: -643674 | J10: 7005 | K10: 460878 | M10: =SUM(I10:L10) -> -175791
C11: Culture and recreation | I11: -676727 | J11: 3110 | K11: 27474 | M11: =SUM(I11:L11) -> -646143
C12: Economic development and assistance | I12: -60013 | M12: =SUM(I12:L12) -> -60013
C13: Conservation | I13: -5200 | M13: =SUM(I13:L13) -> -5200
C14: Interest expense | I14: -41425 | M14: =SUM(I14:L14) -> -41425
E16: Total Government Activities | I16: =SUM(I7:I14) -> -6756423 | J16: =SUM(J7:J14) -> 492414 | K16: =SUM(K7:K14) -> 1211688 | L16: =SUM(L7:L14) -> 53242 | M16: =SUM(M7:M14) -> -4999079
G18: General Revenues:
H19: Property taxes levied for:
I20: General purposes | M20: 919359
I21: Public works | M21: 1374532
I22: Culture and recreation | M22: 791597
H23: Sales and use taxes levied for public works | M23: 870929
H24: Other taxes, penalties and interest | M24: 8821
H25: Grants and contributions not restricted to specific programs | M25: 1613286
H26: Unrestricted investment earnings | M26: 129994
H27: Net increase (decreaase) in the fair value of investments | M27: 23125
H28: Gain on sale of capital assets | M28: 42509
H29: Contributions from private sources | M29: 5500
H30: Other | M30: 103549
H32: Total General Revenues and transfers | M32: =SUM(M20:M30) -> 5883201
H34: Change in Net Position | M34: =SUM(M16,M32) -> 884122
E36: Net Assets- Beginning of Year | M36: 15382153
E38: Net Assets- End of Year | M38: =SUM(M34,M36) -> 16266275

Sheet Concordia
J1: Concordia County 2014 Statement of Activities
J2: Issued: December 31, 2014
J4: PROGRAM REVENUES
A5: FUNCTIONS/PROGRAMS | I5: Expenses | J5: Charges for Services | K5: Operating Grants and Contributions | L5: Capital Grants and Contributions | M5: NET REVENUE (EXPENSE) AND CHANGES IN NET ASSETS
A6: Primary Government:
B7: Government Activities:
B8: General government:
C9: Legislative | I9: -236369 | M9: =SUM(I9:L9) -> -236369
C10: Judicial | I10: -635894 | M10: =SUM(I10:L10) -> -635894
C11: Elections | I11: -45930 | M11: =SUM(I11:L11) -> -45930
C12: Finance | I12: -337662 | M12: =SUM(I12:L12) -> -337662
C13: Other general | I13: -774236 | L13: 20505 | M13: =SUM(I13:L13) -> -753731
B14: Public safety | I14: -197180 | J14: 155840 | K14: 40326 | M14: =SUM(I14:L14) -> -1014
B15: Public works | I15: -3094988 | L15: 190512 | M15: =SUM(I15:L15) -> -2904476
B16: Health and welfare | I16: -275734 | K16: 123153 | L16: 35363 | M16: =SUM(I16:L16) -> -117218
B17: Economic development | I17: -94869 | M17: =SUM(I17:L17) -> -94869
B18: Interest | I18: -384541 | M18: =SUM(I18:L18) -> -384541
E20: Total Government Activities | I20: =SUM(I9:I18) -> -6077403 | J20: =SUM(J9:J18) -> 155840 | K20: =SUM(K9:K18) -> 163479 | L20: =SUM(L9:L18) -> 246380 | M20: =SUM(M9:M18) -> -5511704
G22: General Revenues:
H23: Taxes:
I24: Ad valorem taxes | M24: 1785913
I25: Sales taxes | M25: 2856287
I26: Other taxes | M26: 35256
H27: Intergovernmental revenues
I28: State revenue sharing | M28: 107518
I29: Severance taxes | M29: 1011692
I30: Parish transportation | M30: 320993
I31: Fire insurance premium tax | M31: 83499
I32: Parish royalty | M32: 42329
H33: Licenses and permits | M33: 266261
H34: Interest | M34: 25953
H35: Other general revenues | M35: 241635
H37: Total general revenues | M37: =SUM(M24:M35) -> 6777336
H39: Change in Net Position | M39: =SUM(M20+M37) -> 1265632
E41: Net Assets- Beginning of Year | M41: 10918102
E43: Net Assets- End of Year | M43: =SUM(M41+M39) -> 12183734

Sheet DeSoto
J1: Desoto County 2014 Statement of Activities
J2: Issued: December 31, 2014
J5: PROGRAM REVENUES | M5: NET (EXPENSES) REVENUES AND CHANGES IN NET POSITION
A6: Program Activities | I6: Expenses | J6: Fees, Fines and Charges for Services | K6: Operating Grants and Contributions | L6: Capital Grants and Contributions | M6: Governmental Activities | N6: Business-type Activities | O6: Total
A7: Primary Government:
B8: Government Activities:
B9: General government:
C10: Legislative | I10: -400475 | M10: =SUM(I10:L10) -> -400475 | O10: =SUM(M10:N10) -> -400475
C11: Judicial | I11: -2693579 | J11: 1016052 | M11: =SUM(I11:L11) -> -1677527 | O11: =SUM(M11:N11) -> -1677527
C12: Elections | I12: -101110 | M12: =SUM(I12:L12) -> -101110 | O12: =SUM(M12:N12) -> -101110
C13: Finance and administration | I13: -2029058 | J13: 312381 | K13: 11382 | M13: =SUM(I13:L13) -> -1705295 | O13: =SUM(M13:N13) -> -1705295
C14: Other | I14: -854448 | M14: =SUM(I14:L14) -> -854448 | O14: =SUM(M14:N14) -> -854448
C15: Public safety | I15: -1096246 | K15: 111066 | M15: =SUM(I15:L15) -> -985180 | O15: =SUM(M15:N15) -> -985180
C16: Public works | I16: -10446041 | J16: 197301 | L16: 398964 | M16: =SUM(I16:L16) -> -9849776 | O16: =SUM(M16:N16) -> -9849776
C17: Sanitation | I17: -4058906 | J17: 946774 | M17: =SUM(I17:L17) -> -3112132 | O17: =SUM(M17:N17) -> -3112132
C18: Culture and recreation | I18: -279817 | M18: =SUM(I18:L18) -> -279817 | O18: =SUM(M18:N18) -> -279817
C19: Health and welfare | I19: -2206951 | K19: 1605452 | M19: =SUM(I19:L19) -> -601499 | O19: =SUM(M19:N19) -> -601499
C20: Economic development | I20: -3299353 | K20: 2689861 | M20: =SUM(I20:L20) -> -609492 | O20: =SUM(M20:N20) -> -609492
C21: Transportation | I21: -814370 | J21: 242760 | K21: 160493 | M21: =SUM(I21:L21) -> -411117 | O21: =SUM(M21:N21) -> -411117
C22: Animal control | I22: -345903 | J22: 22434 | K22: 700 | M22: =SUM(I22:L22) -> -322769 | O22: =SUM(M22:N22) -> -322769
C23: Interest on long-term debt | I23: -255 | M23: =SUM(I23:L23) -> -255 | O23: =SUM(M23:N23) -> -255
E25: Total Government Activities | I25: =SUM(I10:I23) -> -28626512 | J25: =SUM(J10:J23) -> 2737702 | K25: =SUM(K10:K23) -> 4578954 | L25: =SUM(L10:L23) -> 398964 | M25: =SUM(M10:M23) -> -20910892 | O25: =SUM(O10:O23) -> -20910892
B27: Business-type Activities:
C28: Eastside sewer | I28: -33209 | J28: 13837 | N28: =SUM(I28:L28) -> -19372 | O28: =N28 -> -19372
E30: Total Government | I30: =I28+I25 -> -28659721 | J30: =J28+J25 -> 2751539 | K30: =K28+K25 -> 4578954 | L30: =L28+L25 -> 398964 | M30: =M28+M25 -> -20910892 | N30: =N28+N25 -> -19372 | O30: =O28+O25 -> -20930264
G32: General Revenues:
G33: Taxes-
H34: Ad valorem | M34: 12327537 | O34: =SUM(M34:N34) -> 12327537
H35: Sales & use | M35: 7344797 | O35: =SUM(M35:N35) -> 7344797
H36: Severance | M36: 1233958 | O36: =SUM(M36:N36) -> 1233958
H37: Tourism | M37: 104653 | O37: =SUM(M37:N37) -> 104653
H38: Video poker | M38: 137400 | O38: =SUM(M38:N38) -> 137400
H39: Investment earnings | M39: 483798 | O39: =SUM(M39:N39) -> 483798
H40: State revenue sharing | M40: 51600 | O40: =SUM(M40:N40) -> 51600
H41: Rentals, leases and royalties | M41: 624592 | O41: =SUM(M41:N41) -> 624592
H42: Other miscellaneous | M42: 421020 | O42: =SUM(M42:N42) -> 421020
H43: Transfers | M43: -19350 | N43: 19350 | O43: =SUM(M43:N43) -> 0
H45: Total General Revenues & Transfers | M45: =SUM(M34:M43) -> 22710005 | N45: =SUM(N34:N43) -> 19350 | O45: =SUM(O34:O43) -> 22729355
H47: Change in Net Position | M47: =M45+M30 -> 1799113 | N47: =N45+N30 -> -22 | O47: =O45+O30 -> 1799091
E49: Net Assets- Beginning of Year | M49: 112259766 | N49: 11911 | O49: 112271677
...

Sheet East Baton Rouge
J1: East Baton Rouge County 2014 Statement of Activities
J2: Issued: December 31, 2014
M4: NET (EXPENSE) REVENUE AND CHANGES IN NET POSITION
J5: PROGRAM REVENUES | M5: PRIMARY GOVERNMENT
A6: FUNCTIONS/PROGRAMS | I6: Expenses | J6: Charges for Services | K6: Operating Grants and Contributions | L6: Capital Grants and Contributions | M6: Governmental Activities | N6: Business-type Activities | O6: Total | P6: Component Units
A7: Primary Government:
B8: Government Activities:
C9: General government | I9: -99148612 | J9: 22795703 | K9: 320097 | M9: =SUM(I9:L9) -> -76032812 | O9: =SUM(M9:N9) -> -76032812
C10: Public safety | I10: -233011923 | J10: 27006901 | K10: 10769916 | L10: 321868 | M10: =SUM(I10:L10) -> -194913238 | O10: =SUM(M10:N10) -> -194913238
C11: Transportation | I11: -66920723 | J11: 216379 | K11: 571666 | L11: 23610909 | M11: =SUM(I11:L11) -> -42521769 | O11: =SUM(M11:N11) -> -42521769
C12: Sanitation | I12: -5790 | J12: 51270 | M12: =SUM(I12:L12) -> 45480 | O12: =SUM(M12:N12) -> 45480
C13: Health and welfare | I13: -9796865 | J13: 800646 | K13: 299188 | M13: =SUM(I13:L13) -> -8697031 | O13: =SUM(M13:N13) -> -8697031
C14: Culture and recreation | I14: -43762277 | J14: 298515 | K14: 1106189 | M14: =SUM(I14:L14) -> -42357573 | O14: =SUM(M14:N14) -> -42357573
C15: Conservation and development | I15: -46084260 | J15: 3520513 | K15: 31193540 | L15: 470640 | M15: =SUM(I15:L15) -> -10899567 | O15: =SUM(M15:N15) -> -10899567
C16: Interest and fiscal charges on long-term debt | I16: -13413000 | M16: =SUM(I16:L16) -> -13413000 | O16: =SUM(M16:N16) -> -13413000
E18: Total Government Activities | I18: =SUM(I9:I16) -> -512143450 | J18: =SUM(J9:J16) -> 54689927 | K18: =SUM(K9:K16) -> 44260596 | L18: =SUM(L9:L16) -> 24403417 | M18: =SUM(M9:M16) -> -388789510 | N18: =SUM(N9:N16) -> 0 | O18: =SUM(O9:O16) -> -388789510 | P18: =SUM(P9:P16) -> 0
B20: Business-type Activities:
C21: Airport | I21: -28541998 | J21: 17237125 | K21: 560556 | L21: 2620425 | N21: =SUM(I21:L21) -> -8123892 | O21: =SUM(M21:N21) -> -8123892
C22: Sewer | I22: -156351603 | J22: 75419472 | K22: 6819819 | L22: 5748809 | N22: =SUM(I22:L22) -> -68363503 | O22: =SUM(M22:N22) -> -68363503
C23: Solid waste collection and disposal | I23: -40892829 | J23: 37589552 | N23: =SUM(I23:K23) -> -3303277 | O23: =SUM(M23:N23) -> -3303277
C24: Convention center | I24: -13381809 | J24: 6491539 | K24: 331905 | L24: 1983034 | N24: =SUM(I24:L24) -> -4575331 | O24: =SUM(M24:N24) -> -4575331
C25: Parking facilities | I25: -2745073 | J25: 852633 | N25: =SUM(I25:K25) -> -1892440 | O25: =SUM(M25:N25) -> -1892440
E27: Total Business-type Activities | I27: =SUM(I21:I25) -> -241913312 | J27: =SUM(J21:J25) -> 137590321 | K27: =SUM(K21:K25) -> 7712280 | L27: =SUM(L21:L25) -> 10352268 | M27: =SUM(M21:M25) -> 0 | N27: =SUM(N21:N25) -> -86258443 | O27: =SUM(O21:O25) -> -86258443 | P27: =SUM(P15:P25) -> 0
E29: Total primary government | I29: =I27+I18 -> -754056762 | J29: =J27+J18 -> 192280248 | K29: =SUM(K18+K27) -> 51972876 | L29: =SUM(L18+L27) -> 34755685 | M29: =M27+M18 -> -388789510 | N29: =N27+N18 -> -86258443 | O29: =O27+O18 -> -475047953 | P29: =SUM(P17:P27) -> 0
A31: Component units:
B32: Judicial court services | I32: -58983934 | J32: 24052298 | K32: 24105511 | P32: =SUM(I32:M32) -> -10826125
B33: Economic development districts | I33: -3783707 | J33: 468858 | K33: 671397 | L33: 1825000 | P33: =SUM(I33:M33) -> -818452
B34: Mass transit | I34: -25275010 | J34: 2103473 | L34: 5460644 | P34: =SUM(I34:M34) -> -17710893
E36: Total component units | I36: =SUM(I32:I34) -> -88042651 | J36: =SUM(J32:J34) -> 26624629 | K36: =SUM(K32:K34) -> 24776908 | M36: =SUM(M32:M34) -> 0 | N36: =SUM(N32:N34) -> 0 | O36: =SUM(O32:O34) -> 0 | P36: =SUM(P32:P34) -> -29355470
G38: General Revenues:
H39: Taxes:
I40: Property | M40: 98252896 | O40: =SUM(M40:N40) -> 98252896 | P40: 16417996
I41: Gross receipts business | M41: 24761520 | O41: =SUM(M41:N41) -> 24761520
I42: Sales | M42: 223779923 | N42: 43583023 | O42: =SUM(M42:N42) -> 267362946
I43: Occupancy | M43: 2211310 | O43: =SUM(M43:N43) -> 2211310 | P43: 2246904
I44: Occupational | M44: 10664408 | O44: =SUM(M44:N44) -> 10664408
I45: Insurance premium | M45: 3734350 | O45: =SUM(M45:N45) -> 3734350
I46: Gaming admissions | M46: 9218503 | O46: =SUM(M46:N46) -> 9218503
I47: Interest and penalties - delinquent taxes | M47: 1483091 | O47: =SUM(M47:N47) -> 1483091
H48: Miscellaneous | M48: 17480 | O48: =SUM(M48:N48) -> 17480
...

Sheet East Carroll
J1: East Carroll County 2014 Statement of Activities
J2: Issued: December 31, 2014
J5: PROGRAM REVENUES | M5: NET (EXPENSE) REVENUE AND CHANGES IN NET POSITION
A6: FUNCTIONS/PROGRAMS | I6: Expenses | J6: Charges for Services | K6: Operating Grants and Contributions | L6: Capital Grants and Contributions | M6: Governmental Activities | N6: Business-type Activities | O6: Total
A7: Primary Government:
B8: Government Activities:
C9: General government:
D10: Legislative | I10: -39938 | M10: =SUM(I10:L10) -> -39938 | O10: =SUM(M10:N10) -> -39938
D11: Judicial | I11: -613097 | J11: 442209 | K11: 1200 | M11: =SUM(I11:L11) -> -169688 | O11: =SUM(M11:N11) -> -169688
D12: Elections | I12: -52551 | M12: =SUM(I12:L12) -> -52551 | O12: =SUM(M12:N12) -> -52551
D13: Finance and administrative | I13: -219715 | M13: =SUM(I13:L13) -> -219715 | O13: =SUM(M13:N13) -> -219715
D14: Other general government | I14: -1092292 | K14: 294206 | M14: =SUM(I14:L14) -> -798086 | O14: =SUM(M14:N14) -> -798086
C15: Public safety | I15: -452380 | K15: 113082 | L15: 450626 | M15: =SUM(I15:L15) -> 111328 | O15: =SUM(M15:N15) -> 111328
C16: Public works | I16: -1558407 | J16: 101241 | K16: 264287 | M16: =SUM(I16:L16) -> -1192879 | O16: =SUM(M16:N16) -> -1192879
C17: Health and welfare | I17: -136634 | M17: =SUM(I17:L17) -> -136634 | O17: =SUM(M17:N17) -> -136634
C18: Culture and recreation | I18: -349005 | J18: 11585 | K18: 23045 | M18: =SUM(I18:L18) -> -314375 | O18: =SUM(M18:N18) -> -314375
C19: Economic development and assistance | I19: -6860 | M19: =SUM(I19:L19) -> -6860 | O19: =SUM(M19:N19) -> -6860
C20: Transportation | I20: -31501 | M20: =SUM(I20:L20) -> -31501 | O20: =SUM(M20:N20) -> -31501
C21: Interest on long-term debt | I21: -19777 | M21: =SUM(I21:L21) -> -19777 | O21: =SUM(M21:N21) -> -19777
E23: Total Government Activities | I23: =SUM(I10:I21) -> -4572157 | J23: =SUM(J10:J21) -> 555035 | K23: =SUM(K10:K21) -> 695820 | L23: =SUM(L10:L21) -> 450626 | M23: =SUM(M10:M21) -> -2870676 | O23: =SUM(O10:O21) -> -2870676
B25: Business-type Activities:
C26: Health and welfare | I26: -630500 | J26: 3388 | K26: 631807 | L26: 0 | N26: =SUM(I26:L26) -> 4695 | O26: =SUM(M26:N26) -> 4695
E28: Total Component Units | I28: =SUM(I26:I26) -> -630500 | J28: =SUM(J26:J26) -> 3388 | K28: =SUM(K26:K26) -> 631807 | L28: =SUM(L26:L26) -> 0 | M28: =SUM(M26:M26) -> 0 | N28: =SUM(N26:N26) -> 4695 | O28: =SUM(O26:O26) -> 4695
G30: General Revenues:
H31: Taxes:
I32: Property taxes, levied for general purposes | M32: 2230477 | O32: =SUM(M32:N32) -> 2230477
I33: Property taxes, levied for debt services | M33: 72199 | O33: =SUM(M33:N33) -> 72199
I34: Sales taxes, levied for general purposes | M34: 657398 | O34: =SUM(M34:N34) -> 657398
H35: State revenue sharing | M35: 47309 | O35: =SUM(M35:N35) -> 47309
H36: Other taxes | M36: 34249 | O36: =SUM(M36:N36) -> 34249
H37: Grants and contributions not restricted to specific programs | M37: 60182 | O37: =SUM(M37:N37) -> 60182
H38: Licenses and permits | M38: 148989 | O38: =SUM(M38:N38) -> 148989
H39: Interest and investment earnings | M39: 4176 | N39: 280 | O39: =SUM(M39:N39) -> 4456
H40: Miscellaneous | M40: 127335 | O40: =SUM(M40:N40) -> 127335
H42: Total General Revenues | M42: =SUM(M32:M40) -> 3382314 | N42: =SUM(N32:N40) -> 280 | O42: =SUM(O32:O40) -> 3382594
H44: Change in Net Position | M44: =SUM(M23+M28+M42) -> 511638 | N44: =SUM(N23+N28+N42) -> 4975 | O44: =SUM(O23+O28+O42) -> 516613
E46: Net Position- Beginning of Year | M46: 10622325 | N46: 27339 | O46: =SUM(M46:N46) -> 10649664
E48: Net Position- End of Year | M48: =SUM(M44,M46) -> 11133963 | N48: =N46+N44 -> 32314 | O48: =O46+O44 -> 11166277

Sheet East Feliciana
J1: East Feliciana County 2014 Statement of Activities
J2: Issued: December 31, 2014
J5: PROGRAM REVENUES
A6: FUNCTIONS/PROGRAMS | I6: Expenses | J6: Charges for Services | K6: Operating Grants and Contributions | L6: Capital Grants and Contributions | M6: NET REVENUES (EXPENSES)
B7: Government Activities:
C8: General government | I8: -950109.55 | J8: 9207.11 | K8: 6729.26 | M8: =SUM(I8:L8) -> -934173.18
C9: Culture and recreation | I9: -4586.94 | M9: =SUM(I9:L9) -> -4586.94
C10: Economic development | I10: -9587.67 | M10: =SUM(I10:L10) -> -9587.67
C11: Health and welfare | I11: -329817.02 | K11: 132152 | M11: =SUM(I11:L11) -> -197665.02
C12: Public safety | I12: -1169097.2 | J12: 146700.56 | K12: 137752.09 | L12: 259734.7 | M12: =SUM(I12:L12) -> -624909.89
C13: Public works | I13: -2638111.1 | L13: 2136459.2 | M13: =SUM(I13:L13) -> -501651.87
E15: Total Government Activities/Primary government | I15: =SUM(I8:I13) -> -5101309.5 | J15: =SUM(J8:J13) -> 155907.67 | K15: =SUM(K8:K13) -> 276633.35 | L15: =SUM(L8:L13) -> 2396193.9 | M15: =SUM(M8:M13) -> -2272574.6
G17: General Revenues and Transfers:
H18: Intergovernmental revenues | M18: 406135.5
H19: Taxes:
I20: Ad valorem | M20: 836005.3
I21: Severance | M21: 420876.36
I22: Sales | M22: 4076159.5
H23: Franchise fees | M23: 10173.51
H24: Insurance rebates | M24: 85614.52
H25: Licenses and permits | M25: 300353.89
H26: Fines and forfeitures | M26: 85501.98
H27: Rents and other fees | M27: 99708.18
H28: Interest earned | M28: 1095.07
H29: Other revenues | M29: -7665.45
H31: Total General Revenues and Transfers | M31: =SUM(M18:M29) -> 6313958.4
H33: Change in Net Position | M33: =SUM(M15,M31) -> 4041383.8
E35: Net Assets- Beginning of Year | M35: 14654714
E37: Net Assets- End of Year | M37: =SUM(M33,M35) -> 18696097

Sheet Evangeline
J1: Evangeline County 2014 Statement of Activities
J2: Issued: December 31, 2014
J4: PROGRAM REVENUES | M4: NET (EXPENSE) REVENUE AND CHANGE IN NET ASSETS
I5: Expenses | J5: Fees, Fines, and Charges for Services | K5: Operating Grants and Contributions | L5: Capital Grants and Contributions | M5: Governmental Activities | N5: Business-type Activities | O5: Total
A6: Primary Government:
B7: Government Activities:
C8: General government | I8: -2303564 | J8: 650407 | M8: =SUM(I8:L8) -> -1653157 | O8: =SUM(M8:N8) -> -1653157
C9: Public safety | I9: -844114 | K9: 93919 | M9: =SUM(I9:L9) -> -750195 | O9: =SUM(M9:N9) -> -750195
C10: Public works | I10: -7176279 | J10: 125770 | K10: 462208 | L10: 533621 | M10: =SUM(I10:L10) -> -6054680 | O10: =SUM(M10:N10) -> -6054680
C11: Health and welfare | I11: -483095 | M11: =SUM(I11:L11) -> -483095 | O11: =SUM(M11:N11) -> -483095
C12: Culture and recreation | I12: -1293548 | J12: 237288 | K12: 26748 | M12: =SUM(I12:L12) -> -1029512 | O12: =SUM(M12:N12) -> -1029512
C13: Economic development | I13: -213035 | M13: =SUM(I13:L13) -> -213035 | O13: =SUM(M13:N13) -> -213035
C14: Interest on long-term debt | I14: -1087451 | M14: =SUM(I14:L14) -> -1087451 | O14: =SUM(M14:N14) -> -1087451
E16: Total Government Activities | I16: =SUM(I8:I14) -> -13401086 | J16: =SUM(J8:J14) -> 1013465 | K16: =SUM(K8:K14) -> 582875 | L16: =SUM(L8:L14) -> 533621 | M16: =SUM(M8:M14) -> -11271125 | O16: =SUM(O8:O14) -> -11271125
B18: Business-type Activities:
C19: Ward One sewer system | I19: -57232 | J19: 38890 | N19: =SUM(I19:L19) -> -18342 | O19: =N19 -> -18342
C20: Section 8 housing program | I20: -554475 | K20: 525342 | N20: =SUM(I20:L20) -> -29133 | O20: =N20 -> -29133
E22: Total business-type Activities | I22: =SUM(I19:I20) -> -611707 | J22: =SUM(J19:J20) -> 38890 | K22: =SUM(K19:K20) -> 525342 | L22: =SUM(L19:L20) -> 0 | M22: =SUM(M19:M20) -> 0 | N22: =SUM(N19:N20) -> -47475 | O22: =SUM(O19:O20) -> -47475
E24: Total primary government | I24: =I22+I16 -> -14012793 | J24: =J22+J16 -> 1052355 | K24: =K22+K16 -> 1108217 | L24: =L22+L16 -> 533621 | M24: =M22+M16 -> -11271125 | N24: =N22+N16 -> -47475 | O24: =O22+O16 -> -11318600
G26: General Revenues:
H27: Taxes:
I28: Property taxes, levied for general purposes | M28: 5857491 | O28: =SUM(M28:N28) -> 5857491
I29: Sales and use taxes, levied for general purposes | M29: 3282902 | O29: =SUM(M29:N29) -> 3282902
H30: Grants and contributions not restricted to specific programs:
I31: Beer taxes | M31: 5024 | O31: =SUM(M31:N31) -> 5024
I32: State revenue sharing | M32: 233286 | O32: =SUM(M32:N32) -> 233286
I33: Parish equalization | M33: 1180378 | O33: =SUM(M33:N33) -> 1180378
I34: Other state grants | M34: 201048 | O34: =SUM(M34:N34) -> 201048
H35: Interest and investment earnings | M35: 85138 | N35: 161 | O35: =SUM(M35:N35) -> 85299
H36: Miscellaneous | M36: 589263 | O36: =SUM(M36:N36) -> 589263
H38: Total General Revenues | M38: =SUM(M28:M36) -> 11434530 | N38: =SUM(N28:N36) -> 161 | O38: =SUM(O28:O36) -> 11434691
H40: Change in Net Position | M40: =M38+M24 -> 163405 | N40: =N38+N24 -> -47314 | O40: =O38+O24 -> 116091
E42: Net Position- January 1, 2014, as restated | M42: 35853785 | N42: 350804 | O42: =SUM(M42:N42) -> 36204589
E44: Net Position- December 31, 2014 | M44: =SUM(M40,M42) -> 36017190 | N44: =N42+N40 -> 303490 | O44: =O42+O40 -> 36320680

Sheet Franklin
J1: Franklin County 2014 Statement of Activities
J2: Issued: December 31, 2014
J5: PROGRAM REVENUES
A6: FUNCTIONS | I6: Expenses | J6: Charges for Services | K6: Operating Grants and Contributions | L6: Capital Grants and Contributions | M6: NET (EXPENSE) REVENUE AND CHANGES IN NET POSITION
B7: Government Activities:
C8: General government | I8: -781880 | J8: 109310 | K8: 176110 | M8: =SUM(I8:L8) -> -496460
C9: Public safety | I9: -453160 | J9: 34418 | M9: =SUM(I9:L9) -> -418742
C10: Public works | I10: -6091341 | J10: 6506 | K10: 518477 | L10: 1607679 | M10: =SUM(I10:L10) -> -3958679
C11: Health and welfare | I11: -601056 | K11: 52016 | M11: =SUM(I11:L11) -> -549040
C12: Culture and recreation | I12: -132615 | M12: =SUM(I12:L12) -> -132615
C13: Economic development and assistance | I13: -4065049 | J13: 29773 | K13: 3831571 | L13: 66198 | M13: =SUM(I13:L13) -> -137507
E15: Total Government Activities | I15: =SUM(I8:I13) -> -12125101 | J15: =SUM(J8:J13) -> 180007 | K15: =SUM(K8:K13) -> 4578174 | L15: =SUM(L8:L13) -> 1673877 | M15: =SUM(M8:M13) -> -5693043
G17: General Revenues:
H18: Taxes:
I19: Ad valorem | M19: 3303526
I20: Sales taxes | M20: 3817919
I21: State revenue sharing | M21: 176711
I22: Fire insurance rebate | M22: 85569
I23: Other taxes, penalties, and interest | M23: 10965
H24: Grants and contributions not restricted to specific programs | M24: 36450
H25: Licenses and permits | M25: 158503
H26: Unrestricted investment earnings | M26: 86215
H27: Proceeds from lease | M27: 70000
H28: Gain (loss) on disposal of assets | M28: -38951
H30: Total General Revenues | M30: =SUM(M19:M28) -> 7706907
H32: Change in Net Position | M32: =SUM(M15,M30) -> 2013864
E34: Net Assets- Beginning of Year | M34: 26782200
E36: Net Assets- End of Year | M36: =SUM(M32,M34) -> 28796064

Sheet Grant 
J1: Grant County 2014 Statement of Activities
J2: Issued: December 31, 2014
J4: PROGRAM REVENUES
A5: FUNCTIONS/PROGRAMS | I5: Expenses | J5: Charges for Services | K5: Operating Grants and Contributions | L5: Capital Grants and Contributions | M5: Net (Expenses) Revenue | N5: Governmental Activities | O5: Business-type Activities | P5: Total
A6: Primary Government:
B7: Government Activities:
C8: General government:
D9: Legislative | I9: -213011 | M9: =SUM(I9:L9) -> -213011 | P9: =SUM(O9:O9) -> 0
D10: Judicial | I10: -606967 | J10: 191523 | K10: 168396 | M10: =SUM(I10:L10) -> -247048 | P10: =SUM(O10:O10) -> 0
D11: Finance and administrative | I11: -235770 | M11: =SUM(I11:L11) -> -235770 | P11: =SUM(O11:O11) -> 0
D12: Other general government | I12: -279567 | L12: 22510 | M12: =SUM(I12:L12) -> -257057 | P12: =SUM(O12:O12) -> 0
C13: Public safety | I13: -328726 | K13: 36921 | M13: =SUM(I13:L13) -> -291805 | P13: =SUM(O13:O13) -> 0
C14: Public works | M14: =SUM(I14:L14) -> 0
D15: Road maintenance | I15: -1524011 | J15: 5549 | K15: 734652 | M15: =SUM(I15:L15) -> -783810 | P15: =SUM(O15:O15) -> 0
D16: Landfill maintenance | I16: -1080776 | J16: 81692 | K16: 17830 | M16: =SUM(I16:L16) -> -981254 | P16: =SUM(O16:O16) -> 0
D17: CDBG South Grant Sewer System | M17: =SUM(I17:L17) -> 0
D18: CDBG Herman Park Sewer System | I18: -238689 | K18: 174816 | M18: =SUM(I18:L18) -> -63873 | P18: =SUM(O18:O18) -> 0
D19: Other public works | I19: -48193 | K19: 48193 | M19: =SUM(I19:L19) -> 0 | P19: =SUM(O19:O19) -> 0
C20: Economic development | I20: -34600 | K20: 28200 | M20: =SUM(I20:L20) -> -6400 | P20: =SUM(O20:O20) -> 0
C21: Health and welfare | I21: -102862 | M21: =SUM(I21:L21) -> -102862 | P21: =SUM(O21:O21) -> 0
C22: Culture and recreation | I22: -11066 | J22: 14695 | M22: =SUM(I22:L22) -> 3629 | P22: =SUM(O22:O22) -> 0
E24: Total Government Activities | I24: =SUM(I9:I22) -> -4704238 | J24: =SUM(J9:J22) -> 293459 | K24: =SUM(K9:K22) -> 1209008 | L24: =SUM(L9:L22) -> 22510 | M24: =SUM(M9:M22) -> -3179261 | N24: =SUM(N9:N22) -> 0 | O24: =SUM(O9:O22) -> 0 | P24: =SUM(P9:P22) -> 0
B26: Business-type Activities:
C27: Utility system | I27: 598048 | J27: 660955 | M27: 62907 | P27: =SUM(O27:O27) -> 0
E29: Total business-type Activities | I29: =SUM(I27:I27) -> 598048 | J29: =SUM(J27:J27) -> 660955 | K29: =SUM(K27:K27) -> 0 | L29: =SUM(L27:L27) -> 0 | M29: =SUM(M27:M27) -> 62907 | N29: =SUM(N27:N27) -> 0 | O29: =SUM(O27:O27) -> 0 | P29: =SUM(P27:P27) -> 0
E31: Total government | I31: =I29+I24 -> -4106190 | J31: =J29+J24 -> 954414 | K31: =K29+K24 -> 1209008 | L31: =L29+L24 -> 22510 | M31: =SUM(M24+M29) -> -3116354 | N31: =N29+N24 -> 0 | O31: =O29+O24 -> 0 | P31: =P29+P24 -> 0
G33: Net (Expense) Revenue | N33: -3179261 | O33: 62907 | P33: =SUM(N33:O33) -> -3116354
G35: General Revenues:
H36: Taxes:
I37: Ad valorem | N37: 889307 | P37: =SUM(N37:O37) -> 889307
I38: Sales | N38: 1159486 | P38: =SUM(N38:O38) -> 1159486
I39: Severance | N39: 538280 | P39: =SUM(N39:O39) -> 538280
I40: Other | N40: 159990 | P40: =SUM(N40:O40) -> 159990
H41: Revenue sharing | N41: 79114 | P41: =SUM(N41:O41) -> 79114
H42: Other | N42: 124581 | O42: 3884 | P42: =SUM(N42:O42) -> 128465
H44: Total General Revenues | N44: =SUM(N37:N42) -> 2950758 | O44: =SUM(O37:O42) -> 3884 | P44: =SUM(P37:P42) -> 2954642
H46: Change in Net Assets | N46: =SUM(N44+N33) -> -228503 | O46: =SUM(O44+O33) -> 66791 | P46: =SUM(P44+P33) -> -161712
E49: Net Assets- Beginning of Year | N49: 8394999 | O49: 708050 | P49: =SUM(N49:O49) -> 9103049
E50: As Originally Reported Prior Period Adjustment | N50: 12625 | P50: =SUM(N50:O50) -> 12625
E51: As Restated | N51: 8407624 | O51: 708050 | P51: =SUM(N51:O51) -> 9115674
...

Sheet Iberia
J1: Iberia County 2014 Statement of Activities
J2: Issued: December 31, 2014
J5: PROGRAM REVENUES | M5: NET (EXPENSE) REVENUE AND CHANGE IN NET ASSETS
A6: FUNCTIONS/PROGRAMS | I6: Expenses | J6: Fees, Fines, and Charges for Services | K6: Operating Grants and Contributions | L6: Capital Grants and Contributions | M6: PRIMARY GOVERNMENT | N6: Component Units
A7: Primary Government:
B8: Government Activities:
C9: General government | I9: -5786600 | J9: 897956 | K9: 98114 | M9: =SUM(I9:L9) -> -4790530
C10: Public safety | I10: -4622943 | J10: 549799 | K10: 180534 | L10: 42717 | M10: =SUM(I10:L10) -> -3849893
C11: Public works | I11: -12090667 | J11: 6876 | K11: 1621734 | L11: 4599488 | M11: =SUM(I11:L11) -> -5862569
C12: Health and welfare | I12: -6611112 | J12: 137935 | K12: 6264139 | M12: =SUM(I12:L12) -> -209038
C13: Culture and recreation | I13: -2835116 | K13: 21875 | M13: =SUM(I13:L13) -> -2813241
C14: Urban redevelopment and housing | I14: -852741 | K14: 692019 | M14: =SUM(I14:L14) -> -160722
C15: Economic development and assistance | I15: -425794 | K15: 43819 | M15: =SUM(I15:L15) -> -381975
C16: Unallocated depreciation | I16: -3343755 | M16: =SUM(I16:L16) -> -3343755
C17: Interest on long-term debt | I17: -359539 | M17: =SUM(I17:L17) -> -359539
E19: Total Primary government | I19: =SUM(I9:I17) -> -36928267 | J19: =SUM(J9:J17) -> 1592566 | K19: =SUM(K9:K17) -> 8922234 | L19: =SUM(L9:L17) -> 4642205 | M19: =SUM(M9:M17) -> -21771262 | N19: =SUM(N9:N17) -> 0
E21: Component units | I21: -80150485 | J21: 67700153 | K21: 4625753 | L21: 2339692 | M21: 0 | N21: -5484887
G23: General Revenues:
H24: Taxes:
I25: Property taxes | M25: 10403521 | N25: 2856136
I26: Sales and use taxes | M26: 7111581 | N26: 4696057
I27: Hotel/motel taxes | M27: 274084 | N27: 274352
I28: Severance taxes | M28: 1136974
I29: Fire insurance rebate | N29: 139315
I30: Occupational licenses | M30: 934101
H31: Grants and contributions not restricted to specific programs:
I32: State revenue sharing | M32: 443269 | N32: 437727
H33: Interest and investment earnings | M33: 320883 | N33: 328937
H34: Miscellaneous | M34: 223601 | N34: 510960
H36: Total General Revenues | M36: =SUM(M25:M34) -> 20848014 | N36: =SUM(N25:N34) -> 9243484
H38: Change in Net Position | M38: =M36+M19 -> -923248 | N38: =N36+N21 -> 3758597
E40: Net Assets- Beginning of Year, as restated | M40: 133531832 | N40: 82809047
E42: Net Assets- End of Year | M42: =SUM(M38,M40) -> 132608584 | N42: =N40+N38 -> 86567644

Sheet Iberville
J1: Iberville County 2014 Statement of Activities
J2: Issued: December 31, 2014
M4: NET (EXPENSE) REVENUE AND CHANGE IN NET POSITION
J5: PROGRAM REVENUES | M5: PRIMARY GOVERNMENT | P5: COMPONENT UNITS
A6: FUNCTIONS/PROGRAMS | I6: Expenses | J6: Charges for Services | K6: Operating Grants and Contributions | L6: Capital Grants and Contributions | M6: Governmental Activities | N6: Business-type Activities | O6: Total | P6: Governmental Activities | Q6: Business-type Activities
A7: Primary Government:
B8: Government Activities:
C9: General government | I9: -21155383 | J9: 527692 | K9: 164589 | L9: 14400 | M9: =SUM(I9:L9) -> -20448702 | O9: =SUM(M9:N9) -> -20448702
C10: Public safety | I10: -4093206 | J10: 697956 | K10: 330982 | M10: =SUM(I10:L10) -> -3064268 | O10: =SUM(M10:N10) -> -3064268
C11: Public works | I11: -12246757 | J11: 1610 | K11: 744394 | L11: 29720407 | M11: =SUM(I11:L11) -> 18219654 | O11: =SUM(M11:N11) -> 18219654
