Workbook

Sheet Acadia
D1: Acadia PARISH POLICE JURY
D2: Capital Assets
D3: For the Year Ended December 31, 2014
G5: Beginning Balance | H5: Increases | I5: Decreases | J5: Ending Balance | K5: Cross Sectional
A7: Governmental Activities:
B8: Capital assets, not being depreciated:
C9: Land | G9: 1329008 | J9: =SUM(G9:I9) -> 1329008 | K9: =SUM(J9) -> 1329008
C10: Construction in progress | G10: 10247945 | H10: 1234905 | I10: -10866347 | J10: =SUM(G10:I10) -> 616503 | K10: =SUM(J10) -> 616503
D12: Total capital assets, not being depreciated | G12: =SUM(G8:G11) -> 11576953 | H12: =SUM(H8:H11) -> 1234905 | I12: =SUM(I8:I11) -> -10866347 | J12: =SUM(J8:J11) -> 1945511
A14: Capital assets being depreciated:
B15: Buildings and improvements | G15: 24424668 | H15: 334646 | I15: -3155 | J15: =SUM(G15:I15) -> 24756159
B16: Machinery and equipment | G16: 12027545 | H16: 319975 | I16: -267123 | J16: =SUM(G16:I16) -> 12080397
B17: Improvements, other than buildings | G17: 764577 | H17: 9334 | J17: =SUM(G17:I17) -> 773911
B18: Infrastructure | G18: 37801628 | H18: 10763793 | I18: -139702 | J18: =SUM(G18:I18) -> 48425719
D20: Total capital assets being depreciated | G20: =SUM(G15:G19) -> 75018418 | H20: =SUM(H15:H19) -> 11427748 | I20: =SUM(I15:I19) -> -409980 | J20: =SUM(J15:J19) -> 86036186
A22: Less accumulated depreciation for:
B23: Buildings and improvements | G23: -6749388 | H23: -794092 | I23: 3155 | J23: =SUM(G23:I23) -> -7540325 | K23: =J15+J23 -> 17215834
B24: Machinery and equipment | G24: -6555117 | H24: -803154 | I24: 229407 | J24: =SUM(G24:I24) -> -7128864 | K24: =J16+J24 -> 4951533
B25: Improvements, other than buildings | G25: -405220 | H25: -9435 | J25: =SUM(G25:I25) -> -414655 | K25: =J17+J25 -> 359256
B26: Infrastructure | G26: -18415360 | H26: -1606267 | I26: 116485 | J26: =SUM(G26:I26) -> -19905142 | K26: =J18+J26 -> 28520577
D28: Total accumulated depreciation | G28: =SUM(G23:G27) -> -32125085 | H28: =SUM(H23:H27) -> -3212948 | I28: =SUM(I23:I27) -> 349047 | J28: =SUM(J23:J27) -> -34988986
B30: Total capital assets being depreciated, net | G30: =G20+G28 -> 42893333 | H30: =H20+H28 -> 8214800 | I30: =I20+I28 -> -60933 | J30: =J20+J28 -> 51047200
B32: Governmental activities capital assets, net | G32: =G30+G12 -> 54470286 | H32: =H30+H12 -> 9449705 | I32: =I30+I12 -> -10927280 | J32: =J30+J12 -> 52992711 | K32: =SUM(K23:K26,K9:K10) -> 52992711

Sheet Allen
D1: Acadia PARISH POLICE JURY
D2: Capital Assets
D3: For the Year Ended December 31, 2014
G5: Beginning Balance | H5: Increases | I5: Decreases | J5: Ending Balance | K5: Cross Sectional
A7: Governmental Activities:
B8: Capital assets, not being depreciated:
C9: Construction in progress | H9: 98703 | J9: 98703 | K9: =J9 -> 98703
C10: Land | G10: 572300 | J10: 572300 | K10: =J10 -> 572300
D12: Total capital assets, not being depreciated | G12: =SUM(G9:G10) -> 572300 | H12: =SUM(H9:H10) -> 98703 | I12: =SUM(I9:I10) -> 0 | J12: =SUM(J9:J10) -> 671003
A14: Capital assets being depreciated:
B15: Buildings | G15: 4547339 | H15: 48000 | J15: =SUM(G15:I15) -> 4595339
B16: Improvements, other than buildings | G16: 5853055 | H16: 2530 | J16: =SUM(G16:I16) -> 5855585
B17: Furniture and fixtures | G17: 390033 | H17: 41803 | J17: =SUM(G17:I17) -> 431836
B18: Vehicles | G18: 819449 | H18: 4800 | J18: =SUM(G18:I18) -> 824249
B19: Machinery and equipment | G19: 3254223 | H19: 266982 | I19: -39000 | J19: =SUM(G19:I19) -> 3482205
B20: Infrastructure | G20: 28219912 | J20: =SUM(G20:I20) -> 28219912
D21: Total capital assets being depreciated | G21: =SUM(G15:G20) -> 43084011 | H21: =SUM(H15:H20) -> 364115 | I21: =SUM(I15:I20) -> -39000 | J21: =SUM(J15:J20) -> 43409126
A23: Less accumulated depreciation for:
B24: Buildings | G24: 1787109 | H24: 102409 | J24: =SUM(G24:I24) -> 1889518 | K24: =SUM(J15-J24) -> 2705821
B25: Improvements, other than buildings | G25: 2181213 | H25: 195592 | J25: =SUM(G25:I25) -> 2376805 | K25: =SUM(J16-J25) -> 3478780
B26: Furniture and fixtures | G26: 311630 | H26: 31795 | J26: =SUM(G26:I26) -> 343425 | K26: =SUM(J17-J26) -> 88411
B27: Vehicles | G27: 618959 | H27: 48526 | J27: =SUM(G27:I27) -> 667485 | K27: =SUM(J18-J27) -> 156764
B28: Machinery and equipment | G28: 2229894 | H28: 192008 | I28: -39000 | J28: =SUM(G28:I28) -> 2382902 | K28: =SUM(J19-J28) -> 1099303
B29: Infrastructure | G29: 11861750 | H29: 584415 | J29: =SUM(G29:I29) -> 12446165 | K29: =SUM(J20-J29) -> 15773747
D30: Total accumulated depreciation | G30: =SUM(G24:G29) -> 18990555 | H30: =SUM(H24:H29) -> 1154745 | I30: =SUM(I24:I29) -> -39000 | J30: =SUM(J24:J29) -> 20106300
B32: Total capital assets being depreciated, net | G32: 24093456 | H32: -790630 | J32: 23302826
B35: Governmental activities capital assets, net | G35: =SUM(G32+G12) -> 24665756 | H35: =SUM(H32+H12) -> -691927 | I35: =SUM(I32+I12) -> 0 | J35: =SUM(J32+J12) -> 23973829 | K35: =SUM(K9:K29) -> 23973829

Sheet Ascension
D1: ASCENSION PARISH POLICE JURY
D2: Capital Assets
D3: For the Year Ended December 31, 2014
I5: Beginning Balance | J5: Increases | K5: Decreases | L5: Ending Balance | M5: Cross Sectional
A7: Governmental Activities:
B8: Capital assets, not being depreciated:
C9: Land | I9: 17314 | J9: 54 | K9: -41 | L9: =SUM(I9:K9) -> 17327 | M9: =SUM(L9) -> 17327
C10: Construction in progress | I10: 55786 | J10: 9349 | K10: -49635 | L10: =SUM(I10:K10) -> 15500 | M10: =SUM(L10) -> 15500
D12: Total capital assets, not being depreciated | I12: =SUM(I8:I11) -> 73100 | J12: =SUM(J8:J11) -> 9403 | K12: =SUM(K8:K11) -> -49676 | L12: =SUM(L8:L11) -> 32827
A14: Capital assets being depreciated:
B15: Buildings | I15: 62699 | J15: 41022 | K15: -491 | L15: =SUM(I15:K15) -> 103230
B16: Vehicles | I16: 13162 | J16: 1566 | K16: -884 | L16: =SUM(I16:K16) -> 13844
B17: Equipment | I17: 12086 | J17: 1795 | K17: -440 | L17: =SUM(I17:K17) -> 13441
B18: Furniture and fixtures | I18: 1127 | K18: -6 | L18: =SUM(I18:K18) -> 1121
B19: Library materials | I19: 2791 | J19: 453 | K19: -766 | L19: =SUM(I19:K19) -> 2478
B20: Infrastructure | I20: 216285 | J20: 16109 | K20: -3671 | L20: =SUM(I20:K20) -> 228723
D22: Total capital assets being depreciated | I22: =SUM(I15:I21) -> 308150 | J22: =SUM(J15:J21) -> 60945 | K22: =SUM(K15:K21) -> -6258 | L22: =SUM(L15:L20) -> 362837
A24: Less accumulated depreciation for:
B25: Buildings | I25: -20896 | J25: -2642 | K25: 0 | L25: =SUM(I25:K25) -> -23538 | M25: =SUM(L25,L15) -> 79692
B26: Vehicles | I26: -8988 | J26: -691 | K26: 826 | L26: =SUM(I26:K26) -> -8853 | M26: =SUM(L26,L16) -> 4991
B27: Equipment | I27: -9409 | J27: -939 | K27: 415 | L27: =SUM(I27:K27) -> -9933 | M27: =SUM(L27,L17) -> 3508
B28: Furniture and fixtures | I28: -645 | J28: -85 | K28: 6 | L28: =SUM(I28:K28) -> -724 | M28: =SUM(L28,L18) -> 397
B29: Library materials | I29: -1825 | J29: -496 | K29: 766 | L29: =SUM(I29:K29) -> -1555 | M29: =SUM(L29,L19) -> 923
B30: Infrastructure | I30: -129923 | J30: -10934 | K30: 3602 | L30: =SUM(I30:K30) -> -137255 | M30: =SUM(L30,L20) -> 91468
D32: Total accumulated depreciation | I32: =SUM(I25:I31) -> -171686 | J32: =SUM(J25:J31) -> -15787 | K32: =SUM(K25:K31) -> 5615 | L32: =SUM(L25:L31) -> -181858
B34: Total capital assets being depreciated, net | I34: =I22+I32 -> 136464 | J34: =J22+J32 -> 45158 | K34: =K22+K32 -> -643 | L34: =L22+L32 -> 180979
B36: Governmental activities capital assets, net | I36: =I32+I22+I12 -> 209564 | J36: =J32+J22+J12 -> 54561 | K36: =K32+K22+K12 -> -50319 | L36: =L32+L22+L12 -> 213806 | M36: =SUM(M25:M30,M9:M10) -> 213806
I39: Beginning Balance | J39: Increases | K39: Decreases | L39: Ending Balance
A40: Business-Type Activities:
B41: Capital assets, not being depreciated:
C42: Land | I42: 670 | J42: 0 | K42: 0 | L42: =SUM(I42:K42) -> 670 | M42: =SUM(L42) -> 670
C43: Construction in progress | I43: 271 | J43: 736 | K43: 0 | L43: =SUM(I43:K43) -> 1007 | M43: =SUM(L43) -> 1007
D45: Total capital assets, not being depreciated | I45: =SUM(I41:I44) -> 941 | J45: =SUM(J41:J44) -> 736 | K45: =SUM(K41:K44) -> 0 | L45: =SUM(L41:L44) -> 1677
B47: Capital assets, depreciable:
C48: Sewer systems | I48: 5779 | J48: 0 | K48: 0 | L48: =SUM(I48:K48) -> 5779
C49: Water systems | I49: 765 | K49: 0 | L49: =SUM(I49:K49) -> 765
C50: Machinery & Equipment | I50: 141 | J50: 40 | L50: =SUM(I50:K50) -> 181
C51: Lamar Dixon Expo Center | I51: 7299 | J51: 832 | K51: -24 | L51: =SUM(I51:K51) -> 8107
D53: Total capital assets, depreciable | I53: =SUM(I47:I51) -> 13984 | J53: =SUM(J47:J51) -> 872 | K53: =SUM(K47:K51) -> -24 | L53: =SUM(L47:L51) -> 14832
B55: Less accumulated depreciation for:
...

Sheet Assumption
D1: Assumption PARISH POLICE JURY
D2: Capital Assets
D3: For the Year Ended December 31, 2014
I5: Beginning Balance | J5: Additions | K5: Deletions | L5: Reclassifications | M5: Balance | N5: Cross Sectional
A7: Primary Government
A8: Government Activities:
A9: Capital assets
B10: Land | I10: 2213381 | J10: 120812 | L10: 0 | M10: =SUM(I10:L10) -> 2334193 | N10: =M10 -> 2334193
B11: Buildings | I11: 20795365 | J11: 17305421 | K11: 11888135 | L11: 8283 | M11: 23864600
B12: Improvements other than buildings | I12: 11684883 | J12: 72243 | M12: 11757126
B13: Roads | I13: 16109402 | J13: 116674 | M13: 16226076
B14: Bridges | I14: 588844 | M14: 588844
B15: Equipments & other | I15: 7250922 | J15: 369706 | K15: -314616 | M15: 7306012
B16: Construction in progress | I16: 488571 | J16: 245918 | K16: -24425 | L16: -8283 | M16: 701781 | N16: =M16 -> 701781
C17: Total capital assets | I17: =SUM(I10:I16) -> 59131368 | J17: =SUM(J10:J16) -> 18230774 | K17: =SUM(K10:K16) -> 11549094 | L17: =SUM(L10:L16) -> 0 | M17: =SUM(M10:M16) -> 62778632
A19: Capital Assets being Depreciated | O19: % of capital assets being depreciated
B20: Buildings | I20: 20795365 | J20: 17305421 | K20: 11888135 | L20: 8283 | M20: 23864600 | O20: =M20/M25 -> 0.39945662
B21: Improvements other than buildings | I21: 11684883 | J21: 72243 | M21: 11757126 | O21: =M21/M25 -> 0.19679617
B22: Roads | I22: 16109402 | J22: 116674 | M22: 16226076 | O22: =M22/M25 -> 0.2715995
B23: Bridges | I23: 588844 | M23: 588844 | O23: =M23/M25 -> 0.0098563408
B24: Equipments & other | I24: 7250922 | J24: 369706 | K24: -314616 | M24: 7306012 | O24: =M24/M25 -> 0.12229138
C25: Total capital assets being Depreciated | M25: =SUM(M20:M24) -> 59742658 | O25: =SUM(O20:O24) -> 1
A27: Accumulated Depreciation
B28: Buildings | M28: =M34*O20 -> -8182736.2 | N28: =M20+M28 -> 15681864
B29: Improvements other than buildings | M29: =M34*O21 -> -4031304.1 | N29: =M21+M29 -> 7725821.9
B30: Roads | M30: =M34*O22 -> -5563625.6 | N30: =M22+M30 -> 10662450
B31: Bridges | M31: =M34*O23 -> -201903.87 | N31: =M23+M31 -> 386940.13
B32: Equipments & other | M32: =M34*O24 -> -2505098.3 | N32: =M24+M32 -> 4800913.7
A33: Accumulated Depreciation | M33: =SUM(M28:M32) -> -20484668
A34: Accumulated Depreciation | I34: -18320031 | J34: -2384701 | K34: 220064 | M34: -20484668
I36: =SUM(I17+I34) -> 40811337 | J36: =SUM(J17+J34) -> 15846073 | K36: =SUM(K17+K34) -> 11769158 | L36: =SUM(L17+L34) -> 0 | M36: =SUM(M17+M34) -> 42293964 | N36: =SUM(N10:N32) -> 42293964

Sheet Avoyelles
D1: AVOYELLES PARISH POLICE JURY
D2: Capital Assets
D3: For the Year Ended December 31, 2014
G5: Balance 01/01/14 | H5: Additions | I5: Decreases | J5: Balance 12/31/14 | K5: Cross Sectional
A7: Governmental Activities:
B8: Capital assets, not being depreciated:
C9: Land | G9: 584787 | H9: 29761 | I9: -24000 | J9: =SUM(G9:I9) -> 590548 | K9: =SUM(J9) -> 590548
C10: Construction in progress | G10: 1083069 | I10: -1083069 | J10: =SUM(G10:I10) -> 0 | K10: =SUM(J10) -> 0
D12: Total capital assets, not being depreciated | G12: =SUM(G8:G11) -> 1667856 | H12: =SUM(H8:H11) -> 29761 | I12: =SUM(I8:I11) -> -1107069 | J12: =SUM(J8:J11) -> 590548
A14: Capital assets being depreciated:
B15: Buildings and improvements | G15: 4177096 | H15: 1192787 | I15: 0 | J15: =SUM(G15:I15) -> 5369883
B16: Equipment, furniture and fixtures | G16: 644791 | I16: -19970 | J16: =SUM(G16:I16) -> 624821
B17: Infrastructure | G17: 75128 | H17: 3012 | J17: =SUM(G17:I17) -> 78140
B18: Heavy equipment | G18: 3265524 | H18: 177984 | I18: -7500 | J18: =SUM(G18:I18) -> 3436008
D20: Total capital assets being depreciated | G20: =SUM(G18+G17+G16+G15+G12) -> 9830395 | H20: =SUM(H18+H17+H16+H15+H12) -> 1403544 | I20: =SUM(I18+I17+I16+I15+I12) -> -1134539 | J20: =SUM(J18+J17+J16+J15+J12) -> 10099400
A22: Less accumulated depreciation for:
B23: Buildings and improvements | G23: 1448131 | H23: 189004 | I23: 0 | J23: =SUM(G23:I23) -> 1637135 | K23: =J15-J23 -> 3732748
B24: Equipment, furniture and fixtures | G24: 548224 | H24: 22478 | I24: -19970 | J24: =SUM(G24:I24) -> 550732 | K24: =J16-J24 -> 74089
B25: Infrastructure | G25: 31327 | H25: 9371 | J25: =SUM(G25:I25) -> 40698 | K25: =J17-J25 -> 37442
B26: Heavy equipment | G26: 2545493 | H26: 142982 | I26: -7500 | J26: =SUM(G26:I26) -> 2680975 | K26: =J18-J26 -> 755033
D28: Total accumulated depreciation | G28: =SUM(G23:G27) -> 4573175 | H28: =SUM(H23:H27) -> 363835 | I28: =SUM(I23:I27) -> -27470 | J28: =SUM(J23:J27) -> 4909540
B30: Governmental activities capital assets, net | G30: =SUM(G20-G28) -> 5257220 | H30: =SUM(H20-H28) -> 1039709 | I30: =SUM(I20-I28) -> -1107069 | J30: =SUM(J20-J28) -> 5189860 | K30: =SUM(K23:K26,K9:K10) -> 5189860

Sheet Beauregard
D1: BEAUREGARD PARISH POLICE JURY
D2: Capital Assets
D3: For the Year Ended December 31, 2014
I5: Beginning Balance | J5: Additions | K5: Deletions | L5: Transfers | M5: Ending Balance | N5: Cross Sectional
A7: Government Activities:
A8: Capital assets, not being depreciated:
B9: Land | I9: 688379 | M9: =SUM(I9:L9) -> 688379 | N9: =SUM(M9) -> 688379
B10: Construction in progress | I10: 790379 | J10: 2045679 | L10: -660829 | M10: =SUM(I10:L10) -> 2175229 | N10: =SUM(M10) -> 2175229
C11: Total assets not being depreciated | I11: =SUM(I9:I10) -> 1478758 | J11: =SUM(J9:J10) -> 2045679 | K11: =SUM(K9:K10) -> 0 | L11: =SUM(L9:L10) -> -660829 | M11: =SUM(M9:M10) -> 2863608
A13: Capital assets being depreciated:
B14: Buildings and improvements | I14: 17159998 | L14: 660829 | M14: =SUM(I14:L14) -> 17820827
B15: Infrastructure | I15: 42862850 | M15: =SUM(I15:L15) -> 42862850
B16: Furniture and equipment | I16: 11863318 | J16: 1053553 | K16: -405195 | M16: =SUM(I16:L16) -> 12511676
C17: Total capital assets being depreciated | I17: =SUM(I14:I16) -> 71886166 | J17: =SUM(J14:J16) -> 1053553 | K17: =SUM(K14:K16) -> -405195 | L17: =SUM(L14:L16) -> 660829 | M17: =SUM(M14:M16) -> 73195353
A19: Less accumulated depreciation for:
B20: Buildings and improvements | I20: -8136454 | J20: -498528 | M20: =SUM(I20:L20) -> -8634982 | N20: =SUM(M20,M14) -> 9185845
B21: Infrastructure | I21: -25807309 | J21: -1664107 | M21: =SUM(I21:L21) -> -27471416 | N21: =SUM(M21,M15) -> 15391434
B22: Furniture and equipment | I22: -7914003 | J22: -800319 | K22: 298985 | L22: 0 | M22: =SUM(I22:L22) -> -8415337 | N22: =M16+M22 -> 4096339
C23: Total accumulated depreciation | I23: =SUM(I20:I22) -> -41857766 | J23: =SUM(J20:J22) -> -2962954 | K23: =SUM(K20:K22) -> 298985 | L23: =SUM(L20:L22) -> 0 | M23: =SUM(M20:M22) -> -44521735
B24: Total capital assets being depreciated, net | I24: =I23+I17 -> 30028400 | J24: =J23+J17 -> -1909401 | K24: =K23+K17 -> -106210 | L24: =L23+L17 -> 660829 | M24: =M23+M17 -> 28673618
B25: Governmental activities capital assets, net | I25: =I11+I24 -> 31507158 | J25: =J11+J24 -> 136278 | K25: =K11+K24 -> -106210 | L25: =L11+L24 -> 0 | M25: =M11+M24 -> 31537226 | N25: =SUM(N20:N22,N9:N10) -> 31537226

Sheet Bienville
D1: BIENVILLE PARISH POLICE JURY
D2: Capital Assets
D3: For the Year Ended December 31, 2014
I5: Beginning Balance | J5: Increases | K5: Decreases | L5: Ending Balance | M5: Cross Sectional
A7: Governmental Activities:
B8: Capital assets, not being depreciated:
C9: Land | I9: 660250 | K9: 0 | L9: =SUM(I9:K9) -> 660250 | M9: =SUM(L9) -> 660250
D11: Total capital assets, not being depreciated | I11: =SUM(I8:I9) -> 660250 | J11: =SUM(J8:J9) -> 0 | K11: =SUM(K8:K9) -> 0 | L11: =SUM(L8:L9) -> 660250
M12: =SUM(L12) -> 0
A13: Capital assets being depreciated: | M13: =SUM(L13) -> 0
B14: Infrastructure | M14: =SUM(L14) -> 0
C15: Roads | I15: 21024140 | J15: 1168532 | L15: =SUM(I15:K15) -> 22192672
C16: Bridges | I16: 2537698 | L16: =SUM(I16:K16) -> 2537698
B17: Buildings and Improvements | I17: 16851833 | L17: =SUM(I17:K17) -> 16851833
B18: Office furniture and equipment | I18: 541664 | L18: =SUM(I18:K18) -> 541664
B19: Heavy Equipment | I19: 1577996 | J19: 232345 | K19: -37073 | L19: =SUM(I19:K19) -> 1773268
B20: Vehicles | I20: 1394770 | K20: -93323 | L20: =SUM(I20:K20) -> 1301447
B21: Miscellaneous equipment | I21: 514738 | L21: =SUM(I21:K21) -> 514738
D23: Total capital assets being depreciated | I23: =SUM(I14:I21) -> 44442839 | J23: =SUM(J14:J21) -> 1400877 | K23: =SUM(K14:K21) -> -130396 | L23: =SUM(L14:L21) -> 45713320
A25: Less accumulated depreciation for:
B26: Infrastructure
C27: Roads | I27: -15685746 | J27: -991200 | L27: =SUM(I27:K27) -> -16676946 | M27: =SUM(L27,L15) -> 5515726
C28: Bridges | I28: -1318814 | J28: -39480 | L28: =SUM(I28:K28) -> -1358294 | M28: =SUM(L28,L16) -> 1179404
B29: Buildings and Improvements | I29: -2930993 | J29: -365514 | L29: =SUM(I29:K29) -> -3296507 | M29: =SUM(L29,L17) -> 13555326
B30: Office furniture and equipment | I30: -126348 | J30: -103829 | L30: =SUM(I30:K30) -> -230177 | M30: =SUM(L30,L18) -> 311487
B31: Heavy Equipment | I31: -1150004 | J31: -95068 | K31: 37073 | L31: -1207999 | M31: =SUM(L31,L19) -> 565269
B32: Vehicles | I32: -709926 | J32: -92978 | K32: 93323 | L32: -709581 | M32: =SUM(L32,L20) -> 591866
B33: Miscellaneous equipment | I33: -367092 | J33: -22367 | L33: -389459 | M33: =SUM(L33,L21) -> 125279
M34: =SUM(L34,L22) -> 0
D35: Total accumulated depreciation | I35: =SUM(I26:I33) -> -22288923 | J35: =SUM(J26:J33) -> -1710436 | K35: =SUM(K26:K33) -> 130396 | L35: =SUM(L27:L33) -> -23868963
B37: Total capital assets being depreciated, net | I37: =I23+I35 -> 22153916 | J37: =J23+J35 -> -309559 | K37: =K23+K35 -> 0 | L37: =L23+L35 -> 21844357
M38: =SUM(L38,L26) -> 0
B39: Total capital assets (net) | I39: =I35+I23+I11 -> 22814166 | J39: =J35+J23+J11 -> -309559 | K39: =K35+K23+K11 -> 0 | L39: =L35+L23+L11 -> 22504607 | M39: =SUM(M9:M33) -> 22504607

Sheet Bossier
D1: BOSSIER PARISH POLICE JURY
D2: Capital Assets
D3: For the Year Ended December 31, 2014
I5: Beginning Balance | J5: Transfers | K5: Additions | L5: Deletions | M5: Ending Balance | N5: Cross Sectional
A7: Primary Government
A8: Government Activities:
A9: Capital assets, not being depreciated:
B10: Land | I10: 12207084 | J10: 0 | K10: 805670 | L10: -40496 | M10: =SUM(I10:L10) -> 12972258 | N10: =SUM(M10) -> 12972258
B11: Construction in progress | I11: 6042279 | J11: -3040380 | K11: 3270200 | M11: =SUM(I11:L11) -> 6272099 | N11: =SUM(M11) -> 6272099
C12: Total assets not being depreciated | I12: =SUM(I10:I11) -> 18249363 | J12: =SUM(J10:J11) -> -3040380 | K12: =SUM(K10:K11) -> 4075870 | L12: =SUM(L10:L11) -> -40496 | M12: =SUM(M10:M11) -> 19244357
A14: Capital assets being depreciated:
B15: Buildings and improvements | I15: 108060059 | J15: 67621 | K15: 144858 | M15: =SUM(I15:L15) -> 108272538
B16: Infrastructure | I16: 220251390 | J16: 2972759 | K16: 8222959 | M16: =SUM(I16:L16) -> 231447108
B17: Furniture, equipment and vehicles | I17: 10575576 | K17: 357500 | L17: -14236 | M17: =SUM(I17:L17) -> 10918840
B18: Library books and information material | I18: 4631676 | K18: 559810 | M18: =SUM(I18:L18) -> 5191486
C19: Total capital assets being depreciated | I19: =SUM(I15:I18) -> 343518701 | J19: =SUM(J15:J18) -> 3040380 | K19: =SUM(K15:K18) -> 9285127 | L19: =SUM(L15:L18) -> -14236 | M19: =SUM(M15:M18) -> 355829972
A21: Less accumulated depreciation for:
B22: Buildings and improvements | I22: -24025483 | K22: -2644445 | L22: 0 | M22: =SUM(I22:L22) -> -26669928 | N22: =SUM(M22,M15) -> 81602610
B23: Infrastructure | I23: -46703687 | K23: -5702147 | L23: 0 | M23: =SUM(I23:L23) -> -52405834 | N23: =SUM(M23,M16) -> 179041274
B24: Furniture, equipment and vehicles | I24: -6208523 | K24: -692827 | L24: 9965 | M24: =SUM(I24:L24) -> -6891385 | N24: =SUM(M24,M17) -> 4027455
B25: Library books and information material | I25: -3526904 | K25: -454178 | L25: 0 | M25: =SUM(I25:L25) -> -3981082 | N25: =M18+M25 -> 1210404
C26: Total accumulated depreciation | I26: =SUM(I22:I25) -> -80464597 | J26: =SUM(J22:J25) -> 0 | K26: =SUM(K22:K25) -> -9493597 | L26: =SUM(L22:L25) -> 9965 | M26: =SUM(M22:M25) -> -89948229
B28: Total capital assets being depreciated, net | I28: =I26+I19 -> 263054104 | J28: =J26+J19 -> 3040380 | K28: =K26+K19 -> -208470 | L28: =L26+L19 -> -4271 | M28: =M26+M19 -> 265881743
B30: Governmental activities capital assets, net | I30: =I12+I28 -> 281303467 | J30: =J12+J28 -> 0 | K30: =K12+K28 -> 3867400 | L30: =L12+L28 -> -44767 | M30: =M12+M28 -> 285126100 | N30: =SUM(N22:N25,N10:N11) -> 285126100
I33: Beginning Balance | J33: Transfers | K33: Additions | L33: Deletions | M33: Ending Balance
A35: Business-type Activities:
A36: Capital assets not being depreciated:
B37: Land | I37: 1301778 | J37: 0 | K37: 110034 | L37: 0 | M37: =SUM(I37:L37) -> 1411812 | N37: =SUM(M37) -> 1411812
B38: Goodwill | I38: 1226000 | M38: =SUM(I38:L38) -> 1226000 | N38: =M38 -> 1226000
B39: Construction in progress | I39: 3279798 | J39: -119742 | K39: 10471550 | M39: =SUM(I39:L39) -> 13631606 | N39: =SUM(M39) -> 13631606
C40: Total assets not being depreciated | I40: =SUM(I37:I39) -> 5807576 | J40: =SUM(J37:J39) -> -119742 | K40: =SUM(K37:K39) -> 10581584 | L40: =SUM(L37:L39) -> 0 | M40: =SUM(M37:M39) -> 16269418
A42: Capital assets being depreciated:
B43: Furniture, equipment and vehicles | I43: 34602 | J43: 119742 | K43: 43137 | L43: 0 | M43: =SUM(I43:L43) -> 197481
B44: Buildings and improvements | I44: 4953684 | L44: 0 | M44: =SUM(I44:L44) -> 4953684
C45: Total capital assets being depreciated | I45: =SUM(I43:I44) -> 4988286 | J45: =SUM(J43:J44) -> 119742 | K45: =SUM(K43:K44) -> 43137 | L45: =SUM(L43:L44) -> 0 | M45: =SUM(M43:M44) -> 5151165
A47: Less accumulated depreciation for:
B48: Furniture, equipment and vehicles | I48: -412 | K48: -4943 | L48: 0 | M48: =SUM(I48:L48) -> -5355 | N48: =SUM(M48,M43) -> 192126
B49: Buildings and improvements | I49: -333305 | K49: -202580 | L49: 0 | M49: =SUM(I49:L49) -> -535885 | N49: =SUM(M49,M44) -> 4417799
C50: Total accumulated depreciation | I50: =SUM(I48:I49) -> -333717 | J50: =SUM(J48:J49) -> 0 | K50: =SUM(K48:K49) -> -207523 | L50: =SUM(L48:L49) -> 0 | M50: =SUM(M48:M49) -> -541240
B52: Total capital assets being depreciated, net | I52: =SUM(I50,I45) -> 4654569 | J52: =SUM(J50,J45) -> 119742 | K52: =SUM(K50,K45) -> -164386 | L52: =SUM(L50,L45) -> 0 | M52: =SUM(M50,M45) -> 4609925
...

Sheet Caddo
D1: CADDO PARISH POLICE JURY
D2: Capital Assets
D3: For the Year Ended December 31, 2014
I5: Balance December 31, 2013 | J5: Additions | K5: Reductions | L5: Balance December 31, 2014 | M5: Cross Sectional
A7: Government Activities:
A8: Capital assets, not being depreciated:
B9: Land and land improvements | I9: 14578409 | L9: =SUM(I9:K9) -> 14578409 | M9: =SUM(L9) -> 14578409
B10: Construction in progress | I10: 13982884 | J10: 4339309 | K10: -12386288 | L10: =SUM(I10:K10) -> 5935905 | M10: =L10 -> 5935905
C11: Total capital assets not being depreciated | I11: =SUM(I9:I10) -> 28561293 | J11: =SUM(J9:J10) -> 4339309 | K11: =SUM(K9:K10) -> -12386288 | L11: =SUM(L9:L10) -> 20514314
A13: Capital assets being depreciated:
B14: Buildings and structures | I14: 89865209 | J14: 11141211 | L14: =SUM(I14:K14) -> 101006420
B15: Equipment and vehicles | I15: 38304592 | J15: 3248899 | K15: -931135 | L15: =SUM(I15:K15) -> 40622356
B16: Infrastructure | I16: 386642046 | J16: 3287628 | K16: -97737 | L16: =SUM(I16:K16) -> 389831937
C17: Total capital assets being depreciated | I17: =SUM(I14:I16) -> 514811847 | J17: =SUM(J14:J16) -> 17677738 | K17: =SUM(K14:K16) -> -1028872 | L17: =SUM(L14:L16) -> 531460713
A19: Less accumulated depreciation for:
B20: Buildings and structures | I20: -36975522 | J20: -2452746 | L20: =SUM(I20:K20) -> -39428268 | M20: =SUM(L20,L14) -> 61578152
B21: Equipment and vehicles | I21: -26452998 | J21: -2802700 | K21: 921382 | L21: =SUM(I21:K21) -> -28334316 | M21: =SUM(L21,L15) -> 12288040
B22: Infrastructure | I22: -269675695 | J22: -10691375 | K22: 97738 | L22: =SUM(I22:K22) -> -280269332 | M22: =L16+L22 -> 109562605
C23: Total accumulated depreciation | I23: =SUM(I20:I22) -> -333104215 | J23: =SUM(J20:J22) -> -15946821 | K23: =SUM(K20:K22) -> 1019120 | L23: =SUM(L20:L22) -> -348031916
B24: Total capital assets being depreciated, net | I24: =I23+I17 -> 181707632 | J24: =J23+J17 -> 1730917 | K24: =K23+K17 -> -9752 | L24: =L23+L17 -> 183428797
B25: Capital assets, net | I25: =I11+I24 -> 210268925 | J25: =J11+J24 -> 6070226 | K25: =K11+K24 -> -12396040 | L25: =L11+L24 -> 203943111 | M25: =SUM(M20:M22,M9:M10) -> 203943111

Sheet Calcasieu
D1: CALCASIEU PARISH POLICE JURY
D2: Capital Assets
D3: For the Year Ended December 31, 2014
I5: Beginning Balance | J5: Increases | K5: Decreases | L5: Ending Balance | M5: Cross Sectional
A7: Governmental Activities:
B8: Capital assets, not being depreciated:
C9: Land and Right of Ways | I9: 17550185 | J9: 472081 | K9: 0 | L9: =SUM(I9:K9) -> 18022266 | M9: =SUM(L9) -> 18022266
C10: Construction in progress | I10: 17829886 | J10: 10772487 | K10: -21223434 | L10: =SUM(I10:K10) -> 7378939 | M10: =SUM(L10) -> 7378939
C11: Roads ** | I11: 383317282 | J11: 12100142 | L11: 395417424 | M11: =SUM(L11) -> 395417424
D13: Total capital assets, not being depreciated | I13: =SUM(I8:I11) -> 418697353 | J13: =SUM(J8:J11) -> 23344710 | K13: =SUM(K8:K11) -> -21223434 | L13: =SUM(L8:L11) -> 420818629
A15: Capital assets being depreciated:
B16: Buildings and Improvements | I16: 127634796 | J16: 5493622 | K16: 0 | L16: =SUM(I16:K16) -> 133128418
B17: Machinery and Equipment | I17: 32517962 | J17: 4282860 | K17: -2479025 | L17: =SUM(I17:K17) -> 34321797
B18: Bridges ++ | I18: 11812642 | J18: 2520325 | L18: =SUM(I18:K18) -> 14332967
D20: Total capital assets being depreciated | I20: =SUM(I16:I19) -> 171965400 | J20: =SUM(J16:J19) -> 12296807 | K20: =SUM(K16:K19) -> -2479025 | L20: =SUM(L16:L18) -> 181783182
A22: Less accumulated depreciation for:
B23: Buildings and Improvements | I23: -55088300 | J23: -3398276 | K23: 0 | L23: =SUM(I23:K23) -> -58486576 | M23: =SUM(L23,L16) -> 74641842
B24: Machinery and Equipment | I24: -20643251 | J24: -2810525 | K24: 2373838 | L24: =SUM(I24:K24) -> -21079938 | M24: =SUM(L24,L17) -> 13241859
B25: Bridges ++ | I25: -3897003 | J25: -330103 | L25: =SUM(I25:K25) -> -4227106 | M25: =SUM(L25,L18) -> 10105861
D27: Total accumulated depreciation | I27: =SUM(I23:I26) -> -79628554 | J27: =SUM(J23:J26) -> -6538904 | K27: =SUM(K23:K26) -> 2373838 | L27: =SUM(L23:L26) -> -83793620
B29: Total capital assets being depreciated, net | I29: =I20+I27 -> 92336846 | J29: =J20+J27 -> 5757903 | K29: =K20+K27 -> -105187 | L29: =L20+L27 -> 97989562
B31: Governmental activities capital assets, net | I31: =I27+I20+I13 -> 511034199 | J31: =J27+J20+J13 -> 29102613 | K31: =K27+K20+K13 -> -21328621 | L31: =L27+L20+L13 -> 518808191 | M31: =SUM(L31, L22) -> 518808191
B33: ** As further discussed in Note 1-C, the Parish has adopted the modified approach for valuing its infiastructure of road systems.
B34: (++) The beginning balance of $510,443,445 was restated to $511,034,199 to properly reflect the following: (1) Land and Right of Ways beginning balance of$ 17,544,546 was increased by $5,639 to $17,550,185 to correct a formula error; (2) Construction in Progress beginning balance of $16,852,520 was increased by $977,366 to $17,829,886 to properly state five construction in progress projects fiom the prior year; (3) Buildings and Improvement beginning balance of $127,781,779 was decreased by $146,983 to $127,634,796 in order to remove the effects of a duplicate asset reporting while Accumulated Depreciation for Buildings and Improvements beginning balance of $55,102,925 was also reduced by $14,625 to $55,088,300 for the same reason; (4) Machinery and Equipment beginning balance of $33,068,532 was decreased by $550,570 to $32,517,962 in order to reclassify the assets of two discretely presented component units while Accumulated Depreciation for Machinery and Equipment beginning balance of $20,952,735 was decreased by $309,484 to $20,643,251 for the same reason; and (5) Bridges beginning balance of $11,887,348 was reduced by $74,706 to $11,812,642 to remove the costs of an intersection that is considered a State asset while Accumulated Depreciation for Bridges beginning balance of $3,952,903 was also reduced by $55,900 to $3,897,003 for the same reason. In2014, the Parish completed construction of a water and sewer collection system on an Interstate 10 frontage road in the amount of $1,857,735. Upon completion of that project and in accordance with a cooperative endeavor agreement executed with the City of Sulphur, the construction in progress amount was deleted and the asset was transferred to the City of Sulphur who will own and maintain the system.
I36: Beginning Balance | J36: Increases | K36: Decreases | L36: Ending Balance
A37: Business-Type Activities:
B38: Capital assets, not being depreciated:
C39: Land | I39: 227920 | J39: 0 | K39: 0 | L39: =SUM(I39:K39) -> 227920 | M39: =SUM(L39) -> 227920
C40: Construction in progress | I40: 718820 | J40: 24850 | K40: -718820 | L40: =SUM(I40:K40) -> 24850 | M40: =SUM(L40) -> 24850
D42: Total capital assets, not being depreciated | I42: =SUM(I38:I41) -> 946740 | J42: =SUM(J38:J41) -> 24850 | K42: =SUM(K38:K41) -> -718820 | L42: =SUM(L38:L41) -> 252770
B44: Capital assets, depreciable:
C45: Non-Building Improvements | I45: 10218419 | J45: 203342 | K45: 0 | L45: =SUM(I45:K45) -> 10421761
C46: Building and Improvements | I46: 103393 | K46: 0 | L46: =SUM(I46:K46) -> 103393
C47: Infrastructure | I47: 3120287 | J47: 742479 | K47: 0 | L47: =SUM(I47:K47) -> 3862766
C48: Machinery and Equipment | I48: 243565 | J48: 6451 | L48: 250016
D50: Total capital assets, depreciable | I50: =SUM(I44:I48) -> 13685664 | J50: =SUM(J44:J48) -> 952272 | K50: =SUM(K44:K47) -> 0 | L50: =SUM(L44:L48) -> 14637936
B52: Less accumulated depreciation for:
C53: Non-Building Improvements | I53: -3337586 | J53: -285648 | L53: =SUM(I53:K53) -> -3623234 | M53: =SUM(L53,L45) -> 6798527
C54: Building and Improvements | I54: -83073 | J54: -2202 | L54: =SUM(I54:K54) -> -85275 | M54: =SUM(L54,L46) -> 18118
C55: Infrastructure | I55: -1759643 | J55: -139980 | L55: =SUM(I55:K55) -> -1899623 | M55: =SUM(L55,L47) -> 1963143
...

Sheet Caldwell
D1: CALDWELL PARISH POLICE JURY
D2: Capital Assets
D3: For the Year Ended December 31, 2014
I5: Beginning Balance | J5: Transfers | K5: Additions | L5: Deletions | M5: Ending Balance | N5: Cross Sectional
A7: Primary Government
A8: Government Activities:
A9: Capital assets, not being depreciated:
B10: Land | I10: 420095 | J10: 0 | M10: =SUM(I10:L10) -> 420095 | N10: =SUM(M10) -> 420095
B11: Construction in progress | I11: 7932354 | J11: -797615 | K11: 3419059 | L11: -17920 | M11: =SUM(I11:L11) -> 10535878 | N11: =SUM(M11) -> 10535878
C12: Total assets not being depreciated | I12: 8352449 | J12: =SUM(J10:J11) -> -797615 | K12: =SUM(K10:K11) -> 3419059 | L12: =SUM(L10:L11) -> -17920 | M12: =SUM(M10:M11) -> 10955973
A14: Capital assets being depreciated:
B15: Infrastructure
C16: Roads | I16: 47897858 | M16: =SUM(I16:L16) -> 47897858
C17: Bridges | I17: 642997 | M17: =SUM(I17:L17) -> 642997
B18: Buildings and improvements | I18: 2977743 | K18: 6162 | M18: =SUM(I18:L18) -> 2983905
B19: Land improvements | I19: 716214 | M19: =SUM(I19:L19) -> 716214
B20: Heavy equipment | I20: 1460214 | K20: 37668 | M20: =SUM(I20:L20) -> 1497882
B21: Vehicles | I21: 1187227 | M21: =SUM(I21:L21) -> 1187227
B22: Public works equipment | I22: 285706 | M22: =SUM(I22:L22) -> 285706
B23: Office furniture and equipment | I23: 577716 | K23: 104432 | L23: -1100 | M23: =SUM(I23:L23) -> 681048
C24: Total capital assets being depreciated | I24: =SUM(I16:I23) -> 55745675 | J24: =SUM(J16:J23) -> 0 | K24: =SUM(K16:K23) -> 148262 | L24: =SUM(L16:L23) -> -1100 | M24: =SUM(M16:M23) -> 55892837
A26: Less accumulated depreciation for:
B27: Infrastructure
C28: Roads | I28: -46151263 | K28: -149999 | L28: 0 | M28: =SUM(I28:L28) -> -46301262 | N28: =SUM(M28,M16) -> 1596596
C29: Bridges | I29: -642062 | K29: -48 | M29: =SUM(I29:L29) -> -642110 | N29: =SUM(M29,M17) -> 887
B30: Buildings and improvements | I30: -2601609 | K30: -17717 | L30: 0 | M30: =SUM(I30:L30) -> -2619326 | N30: =SUM(M30,M18) -> 364579
B31: Land improvements | I31: -186334 | K31: -30959 | M31: =SUM(I31:L31) -> -217293 | N31: =SUM(M31,M19) -> 498921
B32: Heavy equipment | I32: -1169753 | K32: -53802 | M32: =SUM(I32:L32) -> -1223555 | N32: =SUM(M32,M20) -> 274327
B33: Vehicles | I33: -1073866 | K33: -41067 | M33: =SUM(I33:L33) -> -1114933 | N33: =SUM(M33,M21) -> 72294
B34: Public works equipment | I34: -105510 | K34: -23681 | M34: =SUM(I34:L34) -> -129191 | N34: =SUM(M34,M22) -> 156515
B35: Office furniture and equipment | I35: -448561 | K35: -44567 | L35: 1100 | M35: =SUM(I35:L35) -> -492028 | N35: =SUM(M35,M23) -> 189020
C36: Total accumulated depreciation | I36: =SUM(I27:I35) -> -52378958 | J36: =SUM(J27:J35) -> 0 | K36: =SUM(K27:K35) -> -361840 | L36: =SUM(L27:L35) -> 1100 | M36: =SUM(M27:M35) -> -52739698
B38: Total capital assets being depreciated, net | I38: =I36+I24 -> 3366717 | J38: =J36+J24 -> 0 | K38: =K36+K24 -> -213578 | L38: =L36+L24 -> 0 | M38: =M36+M24 -> 3153139
B40: Governmental activities capital assets, net | I40: =I12+I38 -> 11719166 | J40: =J12+J38 -> -797615 | K40: =K12+K38 -> 3205481 | L40: =L12+L38 -> -17920 | M40: =M12+M38 -> 14109112 | N40: =SUM(N27:N35,N10:N11) -> 14109112

Sheet Cameron
D1: Cameron PARISH POLICE JURY
D2: Capital Assets
D3: For the Year Ended December 31, 2014
I5: Beginning Balance | J5: Additions | K5: Deletions | L5: Ending Balance | M5: Cross Sectional
A7: Primary Government
A8: Government Activities:
B10: Land | I10: 1381390 | J10: 28000 | L10: =SUM(I10:K10) -> 1409390 | M10: =SUM(L10) -> 1409390
B11: Construction in progress | I11: 20795365 | J11: 17305421 | K11: -11888135 | L11: =SUM(I11:K11) -> 26212651 | M11: =SUM(L11) -> 26212651
B12: Building and improvements | I12: 35436534 | J12: 5051089 | K12: -1917928 | L12: =SUM(I12:K12) -> 38569695
B13: Books and videos | I13: 702647 | J13: 93863 | L13: =SUM(I13:K13) -> 796510
B14: Equipment and furniture | I14: 18144322 | J14: 1032315 | K14: -850576 | L14: =SUM(I14:K14) -> 18326061
B15: Infrastructure | I15: 54375215 | J15: 7071718 | L15: =SUM(I15:K15) -> 61446933
C16: Total capital assets at historical costs | I16: =SUM(I10:I15) -> 130835473 | J16: =SUM(J10:J15) -> 30582406 | K16: =SUM(K10:K15) -> -14656639 | L16: =SUM(L10:L15) -> 146761240
A18: Capital Assets being Depreciated | N18: % of Capital Assets being Depreciated | O18: Accumulated Depreciation
B19: Building and improvements | I19: 35436534 | J19: 5051089 | K19: -1917928 | L19: =SUM(I19:K19) -> 38569695 | N19: =L19/L23 -> 0.3237364 | O19: =L32*N19 -> -7379077.5
B20: Books and videos | I20: 702647 | J20: 93863 | L20: =SUM(I20:K20) -> 796510 | N20: =L20/L23 -> 0.006685541 | O20: =L32*N20 -> -152386.71
B21: Equipment and furniture | I21: 18144322 | J21: 1032315 | K21: -850576 | L21: =SUM(I21:K21) -> 18326061 | N21: =L21/L23 -> 0.15382058 | O21: =L32*N21 -> -3506105.6
B22: Infrastructure | I22: 54375215 | J22: 7071718 | L22: =SUM(I22:K22) -> 61446933 | N22: =L22/L23 -> 0.51575748 | O22: =L32*N22 -> -11755905
C23: Total Capital being Depreciated | I23: =SUM(I17:I22) -> 108658718 | J23: =SUM(J17:J22) -> 13248985 | K23: =SUM(K17:K22) -> -2768504 | L23: =SUM(L17:L22) -> 119139199 | N23: =SUM(N19:N22) -> 1 | O23: =SUM(O19:O22) -> -22793475
A25: Accumulated Depreciation
B26: Building and improvements | L26: -7379077 | M26: =L19+L26 -> 31190618
B27: Books and videos | L27: -152387 | M27: =L20+L27 -> 644123
B28: Equipment and furniture | L28: -3506106 | M28: =L21+L28 -> 14819955
B29: Infrastructure | L29: -11755905 | M29: =L22+L29 -> 49691028
C30: Total Accumulated Depreciation | L30: =SUM(L26:L29) -> -22793475
C32: Less accumulated depreciation | I32: -19081663 | J32: -4562388 | K32: -850576 | L32: -22793475
C34: Total capital assets, net | I34: =SUM(I16,I32) -> 111753810 | J34: =SUM(J16,J32) -> 26020018 | K34: =K16-K32 -> -13806063 | L34: =SUM(L16,L32) -> 123967765 | M34: =SUM(M10:M29) -> 123967765

Sheet Catahoula
D1: CATAHOULA PARISH POLICE JURY
D2: Capital Assets
D3: For the Year Ended December 31, 2014
I5: Beginning Balance | J5: Transfers | K5: Additions | L5: Deletions | M5: Ending Balance | N5: Cross Sectional
A7: Primary Government
A8: Government Activities:
A9: Capital assets, not being depreciated:
B10: Land | I10: 112200 | J10: 0 | M10: =SUM(I10:L10) -> 112200 | N10: =SUM(M10) -> 112200
B11: Construction in progress | K11: 33780 | M11: =SUM(I11:L11) -> 33780 | N11: =SUM(M11) -> 33780
C12: Total assets not being depreciated | I12: =SUM(I10:I11) -> 112200 | J12: =SUM(J10:J11) -> 0 | K12: =SUM(K10:K11) -> 33780 | L12: =SUM(L10:L11) -> 0 | M12: =SUM(M10:M11) -> 145980
A14: Capital assets being depreciated:
B15: Infrastructure | I15: 11389474 | K15: 125058 | M15: =SUM(I15:L15) -> 11514532
B16: Buildings | I16: 2983414 | K16: 13430 | M16: =SUM(I16:L16) -> 2996844
B17: Improvements | I17: 1558229 | L17: -14710 | M17: =SUM(I17:L17) -> 1543519
B18: Equipment | I18: 1471586 | K18: 9221 | L18: -64679 | M18: =SUM(I18:L18) -> 1416128
B19: Heavy equipment | I19: 926073 | K19: 65407 | M19: =SUM(I19:L19) -> 991480
B20: Vehicles | I20: 550399 | L20: -975 | M20: =SUM(I20:L20) -> 549424
B21: Books and periodicals | I21: 690885 | K21: 35230 | L21: -15247 | M21: =SUM(I21:L21) -> 710868
C22: Total capital assets being depreciated | I22: =SUM(I15:I21) -> 19570060 | J22: =SUM(J15:J21) -> 0 | K22: =SUM(K15:K21) -> 248346 | L22: =SUM(L15:L21) -> -95611 | M22: =SUM(M15:M21) -> 19722795
A24: Less accumulated depreciation for:
B25: Infrastructure - roads and bridges | I25: 8368120 | K25: 113919 | L25: 0 | M25: =SUM(I25:L25) -> 8482039 | N25: =M15-M25 -> 3032493
B26: Buildings | I26: 2553563 | K26: 18176 | L26: 0 | M26: =SUM(I26:L26) -> 2571739 | N26: =M16-M26 -> 425105
B27: Improvements | I27: 214205 | K27: 61531 | L27: -12749 | M27: =SUM(I27:L27) -> 262987 | N27: =M17-M27 -> 1280532
B28: Equipment | I28: 1140968 | J28: -80 | K28: 71408 | L28: -47474 | M28: =SUM(I28:L28) -> 1164822 | N28: =M18-M28 -> 251306
B29: Heavy equipment | I29: 630079 | K29: 51388 | M29: =SUM(I29:L29) -> 681467 | N29: =M19-M29 -> 310013
B30: Vehicles | I30: 300201 | J30: 80 | K30: 48564 | L30: -975 | M30: =SUM(I30:L30) -> 347870 | N30: =M20-M30 -> 201554
B31: Books and periodicals | I31: 612308 | K31: 29741 | L31: -15247 | M31: =SUM(I31:L31) -> 626802 | N31: =M21-M31 -> 84066
C32: Total accumulated depreciation | I32: =SUM(I25:I31) -> 13819444 | J32: =SUM(J25:J31) -> 0 | K32: =SUM(K25:K31) -> 394727 | L32: =SUM(L25:L31) -> -76445 | M32: =SUM(M25:M31) -> 14137726
B34: Total capital assets being depreciated, net | I34: =I22-I32 -> 5750616 | J34: =J22-J32 -> 0 | K34: =K22-K32 -> -146381 | L34: =L22-L32 -> -19166 | M34: =M22-M32 -> 5585069
B36: Governmental activities capital assets, net | I36: =I12+I34 -> 5862816 | J36: =J12+J34 -> 0 | K36: =K12+K34 -> -112601 | L36: =L12+L34 -> -19166 | M36: =M12+M34 -> 5731049 | N36: =SUM(N25:N31, N10:N12) -> 5731049

Sheet Claiborne
D1: CLAIBORNE PARISH POLICE JURY
D2: Capital Assets
D3: For the Year Ended December 31, 2014
I5: Beginning Balance | J5: Transfers | K5: Additions | L5: Deletions | M5: Ending Balance | N5: Cross Sectional
A7: Primary Government
A8: Government Activities:
A9: Capital assets, not being depreciated:
B10: Land
C11: Police Jury | I11: 49900 | K11: 170670 | M11: =SUM(I11:L11) -> 220570 | N11: =SUM(M11) -> 220570
C12: Library | I12: 3580 | M12: =SUM(I12:L12) -> 3580 | N12: =SUM(M12) -> 3580
C13: Office of Community Service | I13: 30000 | M13: =SUM(I13:L13) -> 30000 | N13: =SUM(M13) -> 30000
C14: Adjudicated property | I14: 15360 | J14: 2340 | K14: 667 | L14: -1729 | M14: =SUM(I14:L14) -> 16638 | N14: =SUM(M14) -> 16638
B15: Construction in progress | I15: 2341387 | K15: 845221 | L15: -3143346 | M15: =SUM(I15:L15) -> 43262 | N15: =SUM(M15) -> 43262
C16: Total assets not being depreciated | I16: =SUM(I10:I15) -> 2440227 | J16: =SUM(J10:J15) -> 2340 | K16: =SUM(K10:K15) -> 1016558 | L16: =SUM(L10:L15) -> -3145075 | M16: =SUM(M10:M15) -> 314050
A18: Capital assets being depreciated:
B19: Infrastructure
C20: Roads | I20: 15517189 | M20: =SUM(I20:L20) -> 15517189
C21: Bridges | I21: 1912668 | M21: =SUM(I21:L21) -> 1912668
B22: Land improvements | I22: 15995 | M22: =SUM(I22:L22) -> 15995
B23: Buildings and improvements | I23: 2549623 | K23: 240942 | L23: -200000 | M23: =SUM(I23:L23) -> 2590565
B24: Public works heavy equipment | I24: 2849685 | K24: 289996 | L24: -280508 | M24: =SUM(I24:L24) -> 2859173
B25: Public works other equipment | I25: 82575 | L25: -18500 | M25: =SUM(I25:L25) -> 64075
B26: Vehicles | I26: 232447 | L26: -14368 | M26: =SUM(I26:L26) -> 218079
B27: Other furniture and equipment | I27: 249691 | K27: 5650 | L27: -4500 | M27: =SUM(I27:L27) -> 250841
B28: Office of Emergency Preparedness and Homeland Security: | M28: =SUM(I28:L28) -> 0
C29: Vehicles | I29: 45517 | K29: 21514 | M29: =SUM(I29:L29) -> 67031
C30: Office of Community Service | I30: 50506 | M30: =SUM(I30:L30) -> 50506
C31: Buildings and improvements | I31: 13205 | M31: =SUM(I31:L31) -> 13205
B32: Office of Community Service | M32: =SUM(I32:L32) -> 0
C33: Land improvements | I33: 7800 | M33: =SUM(I33:L33) -> 7800
C34: Buildings and improvements | I34: 62156 | M34: =SUM(I34:L34) -> 62156
C35: Vehicles | I35: 452963 | L35: -70116 | M35: =SUM(I35:L35) -> 382847
C36: Office furniture and equipment | I36: 116327 | M36: =SUM(I36:L36) -> 116327
B37: Library | M37: =SUM(I37:L37) -> 0
C38: Building and improvement | I38: 790366 | K38: 3064878 | M38: =SUM(I38:L38) -> 3855244
C39: Vehicles | I39: 49901 | M39: =SUM(I39:L39) -> 49901
C40: Furniture and equipment | I40: 96154 | K40: 230967 | M40: =SUM(I40:L40) -> 327121
C41: Books and videos | I41: 759823 | K41: 40149 | L41: -62768 | M41: =SUM(I41:L41) -> 737204
C42: Total capital assets being depreciated | I42: =SUM(I19:I41) -> 25854591 | J42: =SUM(J19:J41) -> 0 | K42: =SUM(K19:K41) -> 3894096 | L42: =SUM(L19:L41) -> -650760 | M42: =SUM(M19:M41) -> 29097927
A44: Less accumulated depreciation for:
...

Sheet Concordia
D1: Concordia PARISH POLICE JURY
D2: Capital Assets
D3: For the Year Ended December 31, 2014
I5: Beginning Balance | J5: Increases | K5: Decreases | L5: Ending Balance | M5: Cross Sectional
A7: Governmental Activities:
B8: Capital assets, not being depreciated:
C9: Land | I9: 7038 | K9: 0 | L9: =SUM(I9:K9) -> 7038 | M9: =SUM(L9) -> 7038
D10: Total capital assets, not being depreciated | I10: =SUM(I8:I9) -> 7038 | J10: =SUM(J8:J9) -> 0 | K10: =SUM(K8:K9) -> 0 | L10: =SUM(L8:L9) -> 7038
M11: =SUM(L11) -> 0
A12: Capital assets being depreciated: | M12: =SUM(L12) -> 0
B13: Buildings and Improvements | I13: 5929150 | J13: 77290 | L13: =SUM(I13:K13) -> 6006440
B14: Furniture and fixtures | I14: 441519 | K14: -4675 | L14: =SUM(I14:K14) -> 436844
B15: Machinery and equipment | I15: 2505252 | J15: 68817 | K15: -1375 | L15: =SUM(I15:K15) -> 2572694
B16: Transportation equipment | I16: 1049687 | L16: =SUM(I16:K16) -> 1049687
B17: Roads and bridges | I17: 12195458 | L17: =SUM(I17:K17) -> 12195458
M18: =SUM(L18) -> 0
D19: Total capital assets being depreciated | I19: =SUM(I13:I17) -> 22121066 | J19: =SUM(J13:J17) -> 146107 | K19: =SUM(K13:K17) -> -6050 | L19: =SUM(L13:L17) -> 22261123
A21: Less accumulated depreciation for: | O21: % of Total CA being Depreciated | P21: Accumulated Depreciation
B22: Buildings and Improvements | L22: -3251983.8 | M22: =L13+L22 -> 2754456.2 | O22: =L13/L19 -> 0.26981748 | P22: =L28*O22 -> -3251983.8
B23: Furniture and fixtures | L23: -236514 | M23: =L14+L23 -> 200330 | O23: =L14/L19 -> 0.019623628 | P23: =L28*O23 -> -236514.41
B24: Machinery and equipment | L24: -1392898 | M24: =L15+L24 -> 1179796 | O24: =L15/L19 -> 0.11556892 | P24: =L28*O24 -> -1392898.1
B25: Transportation equipment | L25: -568318 | M25: =L16+L25 -> 481369 | O25: =L16/L19 -> 0.047153371 | P25: =L28*O25 -> -568317.52
B26: Roads and bridges | L26: -6602818 | M26: =L17+L26 -> 5592640 | O26: =L17/L19 -> 0.5478366 | P26: =L28*O26 -> -6602818.2
D28: Total accumulated depreciation | I28: -11207573 | J28: -851009 | K28: 6050 | L28: -12052532 | O28: =SUM(O22:O26) -> 1 | P28: =SUM(P22:P26) -> -12052532
M29: =SUM(L29,L20) -> 0
B30: Total capital assets being depreciated, net | I30: =I19+I28 -> 10913493 | J30: =J19+J28 -> -704902 | K30: =K19+K28 -> 0 | L30: =L19+L28 -> 10208591
B32: Total capital assets (net) | I32: =I28+I19+I10 -> 10920531 | J32: =J28+J19+J10 -> -704902 | K32: =K28+K19+K10 -> 0 | L32: =L30+L10 -> 10215629 | M32: =SUM(M9:M26) -> 10215629

Sheet DeSoto
D1: DeSoto PARISH POLICE JURY
D2: Capital Assets
D3: For the Year Ended December 31, 2014
I5: Beginning Balance | J5: Additions | K5: Deletions | L5: Ending Balance | M5: Cross Sectional
A7: Primary Government
A8: Government Activities:
A9: Capital assets, not being depreciated:
B10: Land | I10: 1979943 | L10: =SUM(I10:K10) -> 1979943 | M10: =SUM(L10) -> 1979943
B11: Construction in progress | I11: 498894 | J11: 542003 | L11: =SUM(I11:K11) -> 1040897 | M11: =SUM(L11) -> 1040897
C12: Total assets not being depreciated | I12: =SUM(I10:I11) -> 2478837 | J12: =SUM(J10:J11) -> 542003 | K12: =SUM(K10:K11) -> 0 | L12: =SUM(L10:L11) -> 3020840
A14: Capital assets being depreciated:
B15: Buildings and improvements | I15: 26363585 | J15: 10457 | L15: =SUM(I15:K15) -> 26374042
B16: Land improvements - structures | I16: 5826378 | J16: 446963 | L16: =SUM(I16:K16) -> 6273341
B17: Furniture and equipment | I17: 12204954 | J17: 1319547 | L17: =SUM(I17:K17) -> 13524501
B18: Infrastructure | I18: 219055672 | L18: =SUM(I18:K18) -> 219055672
C19: Total capital assets being depreciated | I19: =SUM(I15:I18) -> 263450589 | J19: =SUM(J15:J18) -> 1776967 | K19: =SUM(K15:K18) -> 0 | L19: =SUM(L15:L18) -> 265227556
A21: Less accumulated depreciation for:
B22: Buildings and improvements | I22: 11767270 | J22: 666580 | K22: 0 | L22: =SUM(I22:K22) -> 12433850 | M22: =SUM(L15-L22) -> 13940192
B23: Land improvements - structures | I23: 347548 | J23: 285041 | K23: 0 | L23: =SUM(I23:K23) -> 632589 | M23: =SUM(L16-L23) -> 5640752
B24: Furniture and equipment | I24: 7078348 | J24: 1077580 | L24: =SUM(I24:K24) -> 8155928 | M24: =SUM(L17-L24) -> 5368573
B25: Infrastructure | I25: 171364654 | J25: 1879650 | L25: =SUM(I25:K25) -> 173244304 | M25: =SUM(L18-L25) -> 45811368
C26: Total accumulated depreciation | I26: =SUM(I22:I25) -> 190557820 | J26: =SUM(J22:J25) -> 3908851 | K26: =SUM(K22:K25) -> 0 | L26: =SUM(L22:L25) -> 194466671
B28: Total capital assets being depreciated, net | I28: =I19-I26 -> 72892769 | J28: =J19-J26 -> -2131884 | K28: =K19-K26 -> 0 | L28: =L19-L26 -> 70760885
B30: Governmental activities capital assets, net | I30: =I12+I28 -> 75371606 | J30: =J12+J28 -> -1589881 | K30: =K12+K28 -> 0 | L30: =L12+L28 -> 73781725 | M30: =SUM(M9:M29) -> 73781725
I32: Beginning Balance | J32: Increases | K32: Decreases | L32: Ending Balance
A33: Business-Type Activities:
B34: Capital assets, not being depreciated:
C35: Land | I35: 10175 | J35: 0 | K35: 0 | L35: =SUM(I35:K35) -> 10175 | M35: =SUM(L35) -> 10175
B37: Capital assets, depreciable:
C38: Sewer system | I38: 373375 | K38: 0 | L38: =SUM(I38:K38) -> 373375
C39: Treatment plant | I39: 101180 | K39: 0 | L39: =SUM(I39:K39) -> 101180
D41: Total capital assets, depreciable | I41: =SUM(I37:I39) -> 474555 | J41: =SUM(J37:J39) -> 0 | K41: =SUM(K37:K39) -> 0 | L41: =SUM(L37:L39) -> 474555
B43: Less accumulated depreciation for:
C44: Sewer system | I44: -373375 | L44: =SUM(I44:K44) -> -373375 | M44: =SUM(L44+L38) -> 0
C45: Treatment plant | I45: -101180 | L45: =SUM(I45:K45) -> -101180 | M45: =SUM(L45+L39) -> 0
D47: Total accumulated depreciation | I47: =SUM(I44:I45) -> -474555 | J47: =SUM(J44:J45) -> 0 | K47: =SUM(K44:K45) -> 0 | L47: =SUM(L44:L45) -> -474555
D49: Total capital assets, depreciable, net | I49: =I41+I47 -> 0 | J49: =J41+J47 -> 0 | K49: =K41+K47 -> 0 | L49: =L41+L47 -> 0
D51: Business-type activities capital assets, net | I51: =SUM(I49+I35) -> 10175 | J51: =SUM(J49-J41) -> 0 | K51: =SUM(K49-K41) -> 0 | L51: =SUM(L35+L49) -> 10175 | M51: =SUM(M35:M50) -> 10175

Sheet East Baton Rouge
D1: East Baton Rouge PARISH POLICE JURY
D2: Capital Assets
D3: For the Year Ended December 31, 2014
I5: Beginning Balance | J5: Increases | K5: Decreases | L5: Adjustments | M5: Ending Balance | N5: Cross Sectional
A7: Primary Government
A8: Government Activities:
A9: Capital assets, not being depreciated:
B10: Land and right-of-way | I10: 156885714 | J10: 1665773 | K10: -84801 | L10: 1767684 | M10: =SUM(I10:L10) -> 160234370 | N10: =SUM(M10) -> 160234370
B11: Construction work in progress | I11: 36499343 | J11: 21437704 | K11: 3270200 | L11: -9289197 | M11: =SUM(I11:L11) -> 51918050 | N11: =SUM(M11) -> 51918050
C12: Total assets not being depreciated | I12: =SUM(I10:I11) -> 193385057 | J12: =SUM(J10:J11) -> 23103477 | K12: =SUM(K10:K11) -> 3185399 | L12: =SUM(L10:L11) -> -7521513 | M12: =SUM(M10:M11) -> 212152420
A14: Capital assets being depreciated:
B15: Buildings | I15: 108060059 | J15: 67621 | K15: 144858 | M15: =SUM(I15:L15) -> 108272538
B16: Improvements (other than buildings)
C17: and infrastructure | I17: 220251390 | J17: 2972759 | K17: 8222959 | M17: =SUM(I17:L17) -> 231447108
B18: Equipment and equipment under lease | I18: 4631676 | K18: 559810 | M18: =SUM(I18:L18) -> 5191486
C19: Total capital assets being depreciated | I19: =SUM(I15:I18) -> 332943125 | J19: =SUM(J15:J18) -> 3040380 | K19: =SUM(K15:K18) -> 8927627 | L19: =SUM(L15:L18) -> 0 | M19: =SUM(M15:M18) -> 344911132
A21: Less accumulated depreciation for:
B22: Buildings | I22: -24025483 | K22: -2644445 | L22: 0 | M22: =SUM(I22:L22) -> -26669928 | N22: =SUM(M22,M15) -> 81602610
B23: Improvements (other than buildings)
C24: and infrastructure | I24: -6208523 | K24: -692827 | L24: 9965 | M24: =SUM(I24:L24) -> -6891385 | N24: =SUM(M24,M17) -> 224555723
B25: Equipment and equipment under lease | I25: -3526904 | K25: -454178 | L25: 0 | M25: =SUM(I25:L25) -> -3981082 | N25: =M18+M25 -> 1210404
C26: Total accumulated depreciation | I26: =SUM(I22:I25) -> -33760910 | J26: =SUM(J22:J25) -> 0 | K26: =SUM(K22:K25) -> -3791450 | L26: =SUM(L22:L25) -> 9965 | M26: =SUM(M22:M25) -> -37542395
B28: Total capital assets being depreciated, net | I28: =I26+I19 -> 299182215 | J28: =J26+J19 -> 3040380 | K28: =K26+K19 -> 5136177 | L28: =L26+L19 -> 9965 | M28: =M26+M19 -> 307368737
B30: Governmental activities capital assets, net | I30: =I12+I28 -> 492567272 | J30: =J12+J28 -> 26143857 | K30: =K12+K28 -> 8321576 | L30: =L12+L28 -> -7511548 | M30: =M12+M28 -> 519521157 | N30: =SUM(N10:N25) -> 519521157
I33: Beginning Balance | J33: Transfers | K33: Additions | L33: Deletions | M33: Ending Balance
A35: Business-type Activities:
A36: Capital assets not being depreciated:
B37: Land and right-of-way | I37: 1301778 | J37: 0 | K37: 110034 | L37: 0 | M37: =SUM(I37:L37) -> 1411812 | N37: =SUM(M37) -> 1411812
B38: Noise mitigation | I38: 1226000 | M38: =SUM(I38:L38) -> 1226000 | N38: =M38 -> 1226000
B39: Construction work in progress | I39: 3279798 | J39: -119742 | K39: 10471550 | M39: =SUM(I39:L39) -> 13631606 | N39: =SUM(M39) -> 13631606
C40: Total assets not being depreciated | I40: =SUM(I37:I39) -> 5807576 | J40: =SUM(J37:J39) -> -119742 | K40: =SUM(K37:K39) -> 10581584 | L40: =SUM(L37:L39) -> 0 | M40: =SUM(M37:M39) -> 16269418
A42: Capital assets being depreciated:
B43: Buildings | I43: 34602 | J43: 119742 | K43: 43137 | L43: 0 | M43: =SUM(I43:L43) -> 197481
B44: Improvements (other than buildings) | I44: 4953684 | L44: 0 | M44: =SUM(I44:L44) -> 4953684
C45: and infrastructure
B46: Equipment
C47: Total capital assets being depreciated | I47: =SUM(I43:I44) -> 4988286 | J47: =SUM(J43:J44) -> 119742 | K47: =SUM(K43:K44) -> 43137 | L47: =SUM(L43:L44) -> 0 | M47: =SUM(M43:M44) -> 5151165
A49: Less accumulated depreciation for:
B50: Buildings | I50: -412 | K50: -4943 | L50: 0 | M50: =SUM(I50:L50) -> -5355 | N50: =SUM(M50,M43) -> 192126
B51: Improvements (other than buildings) | I51: -333305 | K51: -202580 | L51: 0 | M51: =SUM(I51:L51) -> -535885 | N51: =SUM(M51,M44) -> 4417799
...

Sheet East Carroll
D1: East Carroll PARISH POLICE JURY
D2: Capital Assets
D3: For the Year Ended December 31, 2014
I5: Beginning Balance | J5: Additions | K5: Deletions | L5: Ending Balance | M5: Cross Sectional
B7: Land | I7: 274665 | L7: =SUM(I7:K7) -> 274665 | M7: =SUM(L7) -> 274665
B8: Airport Land | I8: 101000 | L8: =SUM(I8:K8) -> 101000 | M8: =SUM(L8) -> 101000
B9: Construction in progress | I9: 261764 | J9: 3263 | L9: =SUM(I9:K9) -> 265027 | M9: =SUM(L9) -> 265027
C10: Total assets not being depreciated | I10: =SUM(I7:I9) -> 637429 | J10: =SUM(J7:J9) -> 3263 | K10: =SUM(K7:K9) -> 0 | L10: =SUM(L7:L9) -> 640692
B13: Buildings | I13: 2646828 | K13: -865 | L13: =SUM(I13:K13) -> 2645963
B14: Office equipment | I14: 427082 | J14: 4182 | K14: -118737 | L14: =SUM(I14:K14) -> 312527
B15: Furniture & fixtures | I15: 119551 | J15: 1200 | K15: -53352 | L15: =SUM(I15:K15) -> 67399
B16: Construction equipment | I16: 1727485 | J16: 673159 | K16: -467938 | L16: =SUM(I16:K16) -> 1932706
B17: Vehicles | I17: 2399424 | J17: 596645 | K17: -34695 | L17: =SUM(I17:K17) -> 2961374
B18: Books, periodicals & law books | I18: 342548 | L18: =SUM(I18:K18) -> 342548
B19: Infrastructure | L19: =SUM(I19:K19) -> 0
C20: Airport hangars | I20: 25000 | L20: =SUM(I20:K20) -> 25000
C21: Airport runway | I21: 1130666 | L21: =SUM(I21:K21) -> 1130666
C22: Road right-of-way | I22: 558234 | L22: =SUM(I22:K22) -> 558234
C23: Road surface | I23: 9140845 | L23: =SUM(I23:K23) -> 9140845
C24: Bridges | I24: 1759091 | L24: =SUM(I24:K24) -> 1759091
C25: Total capital assets being depreciated | I25: =SUM(I13:I24) -> 20276754 | J25: =SUM(J13:J24) -> 1275186 | K25: =SUM(K13:K24) -> -675587 | L25: =SUM(L13:L24) -> 20876353
A27: Less accumulated depreciation for:
B28: Buildings | I28: 1586519 | J28: 51488 | K28: -843 | L28: =SUM(I28:K28) -> 1637164 | M28: =SUM(L28,L13) -> 4283127
B29: Office equipment | I29: 349809 | J29: 25942 | K29: -117313 | L29: =SUM(I29:K29) -> 258438 | M29: =SUM(L29,L14) -> 570965
B30: Furniture & fixtures | I30: 84073 | J30: 6194 | K30: -51388 | L30: =SUM(I30:K30) -> 38879 | M30: =SUM(L30,L15) -> 106278
B31: Construction equipment | I31: 1199657 | J31: 140224 | K31: -466564 | L31: =SUM(I31:K31) -> 873317 | M31: =L16+L31 -> 2806023
B32: Vehicles | I32: 1969483 | J32: 148117 | K32: -31227 | L32: =SUM(I32:K32) -> 2086373 | M32: =L17+L32 -> 5047747
B33: Books, periodicals & law books | I33: 341650 | J33: 898 | L33: =SUM(I33:K33) -> 342548 | M33: =L18+L33 -> 685096
B34: Infrastructure | L34: =SUM(I34:K34) -> 0 | M34: =L19+L34 -> 0
C35: Airport hangars | I35: 24063 | J35: 625 | L35: =SUM(I35:K35) -> 24688 | M35: =L20+L35 -> 49688
C36: Airport runway | I36: 205040 | J36: 28267 | L36: =SUM(I36:K36) -> 233307 | M36: =L21+L36 -> 1363973
C37: Road surface | I37: 8432937 | J37: 35594 | L37: =SUM(I37:K37) -> 8468531 | M37: =L22+L37 -> 9026765
C38: Bridges | I38: 1166197 | J38: 28620 | L38: =SUM(I38:K38) -> 1194817 | M38: =L23+L38 -> 10335662
C39: Total accumulated depreciation | I39: =SUM(I28:I38) -> 15359428 | J39: =SUM(J28:J38) -> 465969 | K39: =SUM(K28:K38) -> -667335 | L39: =SUM(L28:L38) -> 15158062
B41: Total capital assets being depreciated, net | I41: =SUM(I25-I39) -> 4917326 | J41: =SUM(J25-J39) -> 809217 | K41: =SUM(K25-K39) -> -8252 | L41: =SUM(L25-L39) -> 5718291
B43: Governmental activities capital assets, net | I43: =I10+I41 -> 5554755 | J43: =J10+J41 -> 812480 | K43: =K10+K41 -> -8252 | L43: =L10+L41 -> 6358983 | M43: =SUM(M28:M38,M7:M9) -> 34916016
I46: Beginning Balance | J46: Additions | K46: Deletions | L46: Ending Balance
A48: Business-type Activities:
A49: Capital assets being depreciated:
B50: Office equipment | I50: 5810 | K50: -5810 | L50: =SUM(I50:K50) -> 0
...

Sheet East Feliciana
D1: EAST FELICIANA PARISH POLICE JURY
D2: Capital Assets
D3: For the Year Ended December 31, 2014
I5: Beginning Balance | J5: Additions | K5: Deletions | L5: Ending Balance | M5: Cross Sectional
A7: Governmental Activities:
B8: Capital assets, not being depreciated:
C9: Land | I9: 259230 | L9: 259230 | M9: 259230
D10: Total capital assets, not being depreciated | I10: =SUM(I9) -> 259230 | J10: =SUM(J9) -> 0 | K10: =SUM(K9) -> 0 | L10: =SUM(L9) -> 259230
A12: Capital assets being depreciated:
B13: Buildings | I13: 9627258.6 | J13: 316312.51 | L13: =SUM(I13:J13) -> 9943571.1
B14: Less: accumulated depreciation | I14: 4361370.5 | J14: 207415.32 | L14: =SUM(I14:J14) -> 4568785.8
D15: Net Buildings | I15: =SUM(I13-I14) -> 5265888.1 | J15: =SUM(J13-J14) -> 108897.19 | K15: =SUM(K13-K14) -> 0 | L15: =SUM(L13-L14) -> 5374785.3 | M15: =SUM(L13-L14) -> 5374785.3
B17: Equipment/Vehicles | I17: 4182495.3 | J17: 372417.55 | L17: =SUM(I17:J17) -> 4554912.8
B18: Less: accumulated depreciation | I18: 2351340 | J18: 195024.84 | L18: =SUM(I18:J18) -> 2546364.9
D19: Net Equipment/vehicles | I19: =SUM(I17-I18) -> 1831155.3 | J19: =SUM(J17-J18) -> 177392.71 | K19: =SUM(K17-K18) -> 0 | L19: =SUM(L17-L18) -> 2008548 | M19: =SUM(L17-L18) -> 2008548
B21: Streets/Bridges | I21: 1342103.2 | J21: 4562091.6 | L21: =SUM(I21:J21) -> 5904194.8
B22: Less: accumulated depreciation | I22: 385299.95 | J22: 299708.9 | L22: =SUM(I22:J22) -> 685008.85
D23: Net Furniture and fixtures | I23: =SUM(I21-I22) -> 956803.22 | J23: =SUM(J21-J22) -> 4262382.7 | K23: =SUM(K21-K22) -> 0 | L23: =SUM(L21-L22) -> 5219185.9 | M23: =SUM(L21-L22) -> 5219185.9
B24: Capital assets, being depreciated, net | I24: 8053846.6 | J24: 4548672.6 | L24: =SUM(I24:J24) -> 12602519
B25: Capital assets, net | I25: =SUM(I10+I24) -> 8313076.6 | J25: =SUM(J10+J24) -> 4548672.6 | K25: =SUM(K10+K24) -> 0 | L25: =SUM(L10+L24) -> 12861749 | M25: =SUM(M9:M23) -> 12861749

Sheet Evangeline
D1: Evangeline PARISH POLICE JURY
D2: Capital Assets
D3: For the Year Ended December 31, 2014
I5: Beginning Balance | J5: Additions | K5: Deletions | L5: Ending Balance | M5: Cross Sectional
A7: Primary Government
A8: Government Activities:
A9: Capital assets, not being depreciated:
B10: Land | I10: 876298 | L10: =SUM(I10:K10) -> 876298 | M10: =SUM(L10) -> 876298
B11: Construction in progress | I11: 3465939 | J11: 3717988 | K11: -3551647 | L11: =SUM(I11:K11) -> 3632280 | M11: =SUM(L11) -> 3632280
A12: Other capital assets: | L12: =SUM(I12:K12) -> 0 | M12: =SUM(L12) -> 0
B13: Buildings and improvements | I13: 11557845 | J13: 1892049 | L13: =SUM(I13:K13) -> 13449894
B14: Infrastructure | I14: 20765472 | J14: 726349 | L14: =SUM(I14:K14) -> 21491821
B15: Vehicles | I15: 704276 | L15: =SUM(I15:K15) -> 704276
B16: Equipment, furniture and fixtures | I16: 6383290 | J16: 15500 | L16: =SUM(I16:K16) -> 6398790
C17: Total capital assets | I17: =SUM(I10:I16) -> 43753120 | J17: =SUM(J10:J16) -> 6351886 | K17: =SUM(K10:K16) -> -3551647 | L17: =SUM(L10:L16) -> 46553359
A19: Less accumulated depreciation for:
B20: Buildings | I20: 4481261 | J20: 327407 | K20: 0 | L20: =SUM(I20:K20) -> 4808668 | M20: =L13-L20 -> 8641226
B21: Infrastructure | I21: 10056218 | J21: 1025012 | K21: 0 | L21: =SUM(I21:K21) -> 11081230 | M21: =L14-L21 -> 10410591
B22: Vehicles | I22: 579088 | J22: 45992 | L22: =SUM(I22:K22) -> 625080 | M22: =L15-L22 -> 79196
B23: Equipment, furniture and fixtures | I23: 3973056 | J23: 417960 | K23: 0 | L23: =SUM(I23:K23) -> 4391016 | M23: =L16-L23 -> 2007774
